schematic = {
	size = {x=13, y=16, z=13},
	yslice_prob = {
		{ypos=0, prob=254},
		{ypos=1, prob=254},
		{ypos=2, prob=254},
		{ypos=3, prob=254},
		{ypos=4, prob=254},
		{ypos=5, prob=254},
		{ypos=6, prob=254},
		{ypos=7, prob=254},
		{ypos=8, prob=254},
		{ypos=9, prob=254},
		{ypos=10, prob=254},
		{ypos=11, prob=254},
		{ypos=12, prob=254},
		{ypos=13, prob=254},
		{ypos=14, prob=254},
		{ypos=15, prob=254},
	},
	data = {
		{name="air", prob=0, param2=0},
		{name="air", prob=0, param2=0},
		{name="air", prob=0, param2=0},
		{name="air", prob=0, param2=0},
		{name="air", prob=0, param2=0},
		{name="air", prob=0, param2=0},
		{name="air", prob=0, param2=0},
		{name="air", prob=0, param2=0},
		{name="air", prob=0, param2=0},
		{name="air", prob=0, param2=0},
		{name="air", prob=0, param2=0},
		{name="air", prob=0, param2=0},
		{name="air", prob=0, param2=0},
		{name="air", prob=0, param2=0},
		{name="air", prob=0, param2=0},
		{name="air", prob=0, param2=0},
		{name="air", prob=0, param2=0},
		{name="air", prob=0, param2=0},
		{name="air", prob=0, param2=0},
		{name="air", prob=0, param2=0},
		{name="air", prob=0, param2=0},
		{name="air", prob=0, param2=0},
		{name="air", prob=0, param2=0},
		{name="air", prob=0, param2=0},
		{name="air", prob=0, param2=0},
		{name="air", prob=0, param2=0},
		{name="air", prob=0, param2=0},
		{name="air", prob=0, param2=0},
		{name="air", prob=0, param2=0},
		{name="air", prob=0, param2=0},
		{name="air", prob=0, param2=0},
		{name="air", prob=0, param2=0},
		{name="air", prob=0, param2=0},
		{name="air", prob=0, param2=0},
		{name="air", prob=0, param2=0},
		{name="air", prob=0, param2=0},
		{name="air", prob=0, param2=0},
		{name="air", prob=0, param2=0},
		{name="air", prob=0, param2=0},
		{name="air", prob=0, param2=0},
		{name="air", prob=0, param2=0},
		{name="air", prob=0, param2=0},
		{name="air", prob=0, param2=0},
		{name="air", prob=0, param2=0},
		{name="air", prob=0, param2=0},
		{name="air", prob=0, param2=0},
		{name="air", prob=0, param2=0},
		{name="air", prob=0, param2=0},
		{name="air", prob=0, param2=0},
		{name="air", prob=0, param2=0},
		{name="air", prob=0, param2=0},
		{name="air", prob=0, param2=0},
		{name="air", prob=0, param2=0},
		{name="air", prob=0, param2=0},
		{name="air", prob=0, param2=0},
		{name="air", prob=0, param2=0},
		{name="air", prob=0, param2=0},
		{name="air", prob=0, param2=0},
		{name="air", prob=0, param2=0},
		{name="air", prob=0, param2=0},
		{name="air", prob=0, param2=0},
		{name="air", prob=0, param2=0},
		{name="air", prob=0, param2=0},
		{name="air", prob=0, param2=0},
		{name="air", prob=0, param2=0},
		{name="air", prob=0, param2=0},
		{name="air", prob=0, param2=0},
		{name="air", prob=0, param2=0},
		{name="air", prob=0, param2=0},
		{name="air", prob=0, param2=0},
		{name="air", prob=0, param2=0},
		{name="air", prob=0, param2=0},
		{name="air", prob=0, param2=0},
		{name="air", prob=0, param2=0},
		{name="air", prob=0, param2=0},
		{name="air", prob=0, param2=0},
		{name="air", prob=0, param2=0},
		{name="air", prob=0, param2=0},
		{name="air", prob=0, param2=0},
		{name="air", prob=0, param2=0},
		{name="air", prob=0, param2=0},
		{name="air", prob=0, param2=0},
		{name="air", prob=0, param2=0},
		{name="air", prob=0, param2=0},
		{name="air", prob=0, param2=0},
		{name="air", prob=0, param2=0},
		{name="air", prob=0, param2=0},
		{name="air", prob=0, param2=0},
		{name="air", prob=0, param2=0},
		{name="air", prob=0, param2=0},
		{name="air", prob=0, param2=0},
		{name="air", prob=0, param2=0},
		{name="air", prob=0, param2=0},
		{name="air", prob=0, param2=0},
		{name="air", prob=0, param2=0},
		{name="everness:crystal_cobble", prob=254, param2=0},
		{name="everness:crystal_cobble", prob=254, param2=0},
		{name="everness:crystal_cobble", prob=254, param2=0},
		{name="everness:crystal_cobble", prob=254, param2=0},
		{name="everness:crystal_cobble", prob=254, param2=0},
		{name="air", prob=0, param2=0},
		{name="air", prob=0, param2=0},
		{name="air", prob=0, param2=0},
		{name="air", prob=0, param2=0},
		{name="air", prob=0, param2=0},
		{name="air", prob=0, param2=0},
		{name="air", prob=0, param2=0},
		{name="air", prob=0, param2=0},
		{name="everness:crystal_forest_deep_ocean_sand", prob=254, param2=0},
		{name="everness:crystal_sand", prob=254, param2=0},
		{name="everness:crystal_forest_deep_ocean_sand", prob=84, param2=0},
		{name="everness:crystal_forest_deep_ocean_sand", prob=254, param2=0},
		{name="everness:crystal_sand", prob=254, param2=0},
		{name="air", prob=0, param2=0},
		{name="air", prob=0, param2=0},
		{name="air", prob=0, param2=0},
		{name="air", prob=0, param2=0},
		{name="air", prob=0, param2=0},
		{name="air", prob=0, param2=0},
		{name="air", prob=0, param2=0},
		{name="air", prob=0, param2=0},
		{name="air", prob=0, param2=0},
		{name="air", prob=0, param2=0},
		{name="air", prob=0, param2=0},
		{name="air", prob=0, param2=0},
		{name="air", prob=0, param2=0},
		{name="air", prob=0, param2=0},
		{name="air", prob=0, param2=0},
		{name="air", prob=0, param2=0},
		{name="air", prob=0, param2=0},
		{name="air", prob=0, param2=0},
		{name="air", prob=0, param2=0},
		{name="air", prob=0, param2=0},
		{name="air", prob=0, param2=0},
		{name="air", prob=0, param2=0},
		{name="air", prob=254, param2=0},
		{name="air", prob=254, param2=0},
		{name="air", prob=254, param2=0},
		{name="air", prob=0, param2=0},
		{name="air", prob=0, param2=0},
		{name="air", prob=0, param2=0},
		{name="air", prob=0, param2=0},
		{name="air", prob=0, param2=0},
		{name="air", prob=0, param2=0},
		{name="air", prob=0, param2=0},
		{name="air", prob=0, param2=0},
		{name="air", prob=0, param2=0},
		{name="air", prob=0, param2=0},
		{name="air", prob=254, param2=0},
		{name="air", prob=254, param2=0},
		{name="air", prob=254, param2=0},
		{name="air", prob=0, param2=0},
		{name="air", prob=0, param2=0},
		{name="air", prob=0, param2=0},
		{name="air", prob=0, param2=0},
		{name="air", prob=0, param2=0},
		{name="air", prob=0, param2=0},
		{name="air", prob=0, param2=0},
		{name="air", prob=0, param2=0},
		{name="air", prob=0, param2=0},
		{name="air", prob=0, param2=0},
		{name="air", prob=254, param2=0},
		{name="air", prob=254, param2=0},
		{name="air", prob=254, param2=0},
		{name="air", prob=0, param2=0},
		{name="air", prob=0, param2=0},
		{name="air", prob=0, param2=0},
		{name="air", prob=0, param2=0},
		{name="air", prob=0, param2=0},
		{name="air", prob=0, param2=0},
		{name="air", prob=0, param2=0},
		{name="air", prob=0, param2=0},
		{name="air", prob=0, param2=0},
		{name="air", prob=0, param2=0},
		{name="air", prob=254, param2=0},
		{name="air", prob=254, param2=0},
		{name="air", prob=254, param2=0},
		{name="air", prob=0, param2=0},
		{name="air", prob=0, param2=0},
		{name="air", prob=0, param2=0},
		{name="air", prob=0, param2=0},
		{name="air", prob=0, param2=0},
		{name="air", prob=0, param2=0},
		{name="air", prob=0, param2=0},
		{name="air", prob=0, param2=0},
		{name="air", prob=0, param2=0},
		{name="air", prob=0, param2=0},
		{name="air", prob=0, param2=0},
		{name="air", prob=0, param2=0},
		{name="air", prob=0, param2=0},
		{name="air", prob=0, param2=0},
		{name="air", prob=0, param2=0},
		{name="air", prob=0, param2=0},
		{name="air", prob=0, param2=0},
		{name="air", prob=0, param2=0},
		{name="air", prob=0, param2=0},
		{name="air", prob=0, param2=0},
		{name="air", prob=0, param2=0},
		{name="air", prob=0, param2=0},
		{name="air", prob=0, param2=0},
		{name="air", prob=0, param2=0},
		{name="air", prob=0, param2=0},
		{name="air", prob=0, param2=0},
		{name="air", prob=0, param2=0},
		{name="air", prob=0, param2=0},
		{name="air", prob=0, param2=0},
		{name="air", prob=0, param2=0},
		{name="air", prob=0, param2=0},
		{name="air", prob=0, param2=0},
		{name="air", prob=0, param2=0},
		{name="air", prob=0, param2=0},
		{name="air", prob=0, param2=0},
		{name="everness:crystal_sandstone_chiseled", prob=254, param2=0},
		{name="everness:crystal_stone_brick", prob=254, param2=0},
		{name="everness:crystal_stone_brick", prob=254, param2=0},
		{name="everness:crystal_mossy_cobble", prob=254, param2=0},
		{name="everness:crystal_sandstone_brick", prob=254, param2=0},
		{name="air", prob=0, param2=0},
		{name="air", prob=0, param2=0},
		{name="air", prob=0, param2=0},
		{name="air", prob=0, param2=0},
		{name="air", prob=0, param2=0},
		{name="air", prob=0, param2=0},
		{name="air", prob=0, param2=0},
		{name="air", prob=0, param2=0},
		{name="everness:crystal_mossy_cobble", prob=254, param2=0},
		{name="everness:crystal_mossy_cobble", prob=254, param2=0},
		{name="everness:crystal_sandstone_brick", prob=254, param2=0},
		{name="everness:crystal_mossy_cobble", prob=254, param2=0},
		{name="everness:crystal_sandstone_chiseled", prob=254, param2=0},
		{name="air", prob=0, param2=0},
		{name="air", prob=0, param2=0},
		{name="air", prob=0, param2=0},
		{name="air", prob=0, param2=0},
		{name="air", prob=0, param2=0},
		{name="air", prob=0, param2=0},
		{name="air", prob=0, param2=0},
		{name="air", prob=0, param2=0},
		{name="everness:crystal_cobble", prob=254, param2=0},
		{name="everness:crystal_mossy_cobble", prob=254, param2=0},
		{name="everness:crystal_mossy_cobble", prob=254, param2=0},
		{name="everness:crystal_sandstone_chiseled", prob=254, param2=0},
		{name="everness:crystal_cobble", prob=254, param2=0},
		{name="air", prob=0, param2=0},
		{name="air", prob=0, param2=0},
		{name="air", prob=0, param2=0},
		{name="air", prob=0, param2=0},
		{name="air", prob=0, param2=0},
		{name="air", prob=0, param2=0},
		{name="air", prob=0, param2=0},
		{name="air", prob=0, param2=0},
		{name="everness:crystal_stone_brick", prob=254, param2=0},
		{name="everness:crystal_sandstone_brick", prob=254, param2=0},
		{name="everness:crystal_stone_brick", prob=254, param2=0},
		{name="everness:crystal_cobble", prob=254, param2=0},
		{name="everness:crystal_cobble", prob=254, param2=0},
		{name="air", prob=0, param2=0},
		{name="air", prob=0, param2=0},
		{name="air", prob=0, param2=0},
		{name="air", prob=0, param2=0},
		{name="air", prob=0, param2=0},
		{name="air", prob=0, param2=0},
		{name="air", prob=0, param2=0},
		{name="air", prob=0, param2=0},
		{name="everness:crystal_mossy_cobble", prob=254, param2=0},
		{name="everness:crystal_sandstone_brick", prob=254, param2=0},
		{name="everness:crystal_cobble", prob=254, param2=0},
		{name="everness:crystal_sandstone_brick", prob=254, param2=0},
		{name="everness:crystal_sandstone_brick", prob=254, param2=0},
		{name="air", prob=0, param2=0},
		{name="air", prob=0, param2=0},
		{name="air", prob=0, param2=0},
		{name="air", prob=0, param2=0},
		{name="air", prob=0, param2=0},
		{name="air", prob=0, param2=0},
		{name="air", prob=0, param2=0},
		{name="air", prob=0, param2=0},
		{name="everness:crystal_mossy_cobble", prob=254, param2=0},
		{name="everness:crystal_sandstone_brick", prob=254, param2=0},
		{name="everness:crystal_sandstone_brick", prob=254, param2=0},
		{name="everness:crystal_cobble", prob=254, param2=0},
		{name="everness:crystal_mossy_cobble", prob=254, param2=0},
		{name="air", prob=0, param2=0},
		{name="air", prob=0, param2=0},
		{name="air", prob=0, param2=0},
		{name="air", prob=0, param2=0},
		{name="air", prob=0, param2=0},
		{name="air", prob=0, param2=0},
		{name="air", prob=0, param2=0},
		{name="air", prob=0, param2=0},
		{name="everness:crystal_mossy_cobble", prob=254, param2=0},
		{name="everness:crystal_sandstone_chiseled", prob=254, param2=0},
		{name="everness:crystal_mossy_cobble", prob=254, param2=0},
		{name="everness:crystal_sandstone_brick", prob=254, param2=0},
		{name="everness:crystal_cobble", prob=254, param2=0},
		{name="air", prob=0, param2=0},
		{name="air", prob=0, param2=0},
		{name="air", prob=0, param2=0},
		{name="air", prob=0, param2=0},
		{name="air", prob=0, param2=0},
		{name="air", prob=0, param2=0},
		{name="air", prob=0, param2=0},
		{name="everness:crystal_cobble", prob=254, param2=0},
		{name="everness:crystal_stone_brick", prob=254, param2=0},
		{name="everness:crystal_mossy_cobble", prob=254, param2=0},
		{name="everness:pyrite_lantern", prob=254, param2=0},
		{name="everness:crystal_stone_brick", prob=254, param2=0},
		{name="everness:crystal_mossy_cobble", prob=254, param2=0},
		{name="everness:crystal_cobble", prob=254, param2=0},
		{name="air", prob=0, param2=0},
		{name="air", prob=0, param2=0},
		{name="air", prob=0, param2=0},
		{name="air", prob=0, param2=0},
		{name="air", prob=0, param2=0},
		{name="air", prob=0, param2=0},
		{name="everness:crystal_forest_deep_ocean_sand", prob=254, param2=0},
		{name="everness:crystal_sandstone_chiseled", prob=254, param2=0},
		{name="everness:crystal_sandstone_chiseled", prob=254, param2=0},
		{name="air", prob=254, param2=0},
		{name="everness:crystal_sandstone_brick", prob=254, param2=0},
		{name="everness:crystal_sandstone_chiseled", prob=254, param2=0},
		{name="everness:crystal_forest_deep_ocean_sand", prob=254, param2=0},
		{name="air", prob=0, param2=0},
		{name="air", prob=0, param2=0},
		{name="air", prob=0, param2=0},
		{name="air", prob=0, param2=0},
		{name="air", prob=0, param2=0},
		{name="air", prob=0, param2=0},
		{name="air", prob=0, param2=0},
		{name="everness:crystal_forest_deep_ocean_sand", prob=254, param2=0},
		{name="everness:crystal_forest_deep_ocean_sand", prob=254, param2=0},
		{name="everness:crystal_forest_deep_ocean_sandstone_block", prob=254, param2=0},
		{name="everness:crystal_sand", prob=254, param2=0},
		{name="everness:crystal_forest_deep_ocean_sand", prob=254, param2=0},
		{name="air", prob=0, param2=0},
		{name="air", prob=0, param2=0},
		{name="air", prob=0, param2=0},
		{name="air", prob=0, param2=0},
		{name="air", prob=0, param2=0},
		{name="air", prob=0, param2=0},
		{name="air", prob=0, param2=0},
		{name="air", prob=0, param2=0},
		{name="air", prob=0, param2=0},
		{name="air", prob=254, param2=0},
		{name="air", prob=254, param2=0},
		{name="air", prob=254, param2=0},
		{name="air", prob=0, param2=0},
		{name="air", prob=0, param2=0},
		{name="air", prob=0, param2=0},
		{name="air", prob=0, param2=0},
		{name="air", prob=0, param2=0},
		{name="air", prob=0, param2=0},
		{name="air", prob=0, param2=0},
		{name="air", prob=0, param2=0},
		{name="air", prob=0, param2=0},
		{name="air", prob=0, param2=0},
		{name="air", prob=254, param2=0},
		{name="air", prob=254, param2=0},
		{name="air", prob=254, param2=0},
		{name="air", prob=0, param2=0},
		{name="air", prob=0, param2=0},
		{name="air", prob=0, param2=0},
		{name="air", prob=0, param2=0},
		{name="air", prob=0, param2=0},
		{name="air", prob=0, param2=0},
		{name="air", prob=0, param2=0},
		{name="air", prob=0, param2=0},
		{name="air", prob=0, param2=0},
		{name="air", prob=0, param2=0},
		{name="air", prob=254, param2=0},
		{name="air", prob=254, param2=0},
		{name="air", prob=254, param2=0},
		{name="air", prob=0, param2=0},
		{name="air", prob=0, param2=0},
		{name="air", prob=0, param2=0},
		{name="air", prob=0, param2=0},
		{name="air", prob=0, param2=0},
		{name="air", prob=0, param2=0},
		{name="air", prob=0, param2=0},
		{name="air", prob=0, param2=0},
		{name="air", prob=0, param2=0},
		{name="air", prob=0, param2=0},
		{name="air", prob=254, param2=0},
		{name="air", prob=254, param2=0},
		{name="air", prob=254, param2=0},
		{name="air", prob=0, param2=0},
		{name="air", prob=0, param2=0},
		{name="air", prob=0, param2=0},
		{name="air", prob=0, param2=0},
		{name="air", prob=0, param2=0},
		{name="air", prob=0, param2=0},
		{name="air", prob=0, param2=0},
		{name="air", prob=0, param2=0},
		{name="air", prob=0, param2=0},
		{name="air", prob=0, param2=0},
		{name="air", prob=0, param2=0},
		{name="air", prob=0, param2=0},
		{name="air", prob=0, param2=0},
		{name="air", prob=0, param2=0},
		{name="air", prob=0, param2=0},
		{name="air", prob=0, param2=0},
		{name="air", prob=0, param2=0},
		{name="air", prob=0, param2=0},
		{name="air", prob=0, param2=0},
		{name="air", prob=0, param2=0},
		{name="air", prob=0, param2=0},
		{name="air", prob=0, param2=0},
		{name="air", prob=0, param2=0},
		{name="air", prob=0, param2=0},
		{name="air", prob=0, param2=0},
		{name="air", prob=0, param2=0},
		{name="air", prob=0, param2=0},
		{name="air", prob=0, param2=0},
		{name="air", prob=0, param2=0},
		{name="air", prob=0, param2=0},
		{name="air", prob=0, param2=0},
		{name="air", prob=0, param2=0},
		{name="air", prob=0, param2=0},
		{name="air", prob=0, param2=0},
		{name="everness:crystal_stone_brick", prob=254, param2=0},
		{name="everness:crystal_stone_brick", prob=254, param2=0},
		{name="everness:crystal_cobble", prob=254, param2=0},
		{name="everness:crystal_cobble", prob=254, param2=0},
		{name="everness:crystal_sandstone_chiseled", prob=254, param2=0},
		{name="everness:crystal_mossy_cobble", prob=254, param2=0},
		{name="everness:crystal_sandstone_brick", prob=254, param2=0},
		{name="air", prob=0, param2=0},
		{name="air", prob=0, param2=0},
		{name="air", prob=0, param2=0},
		{name="air", prob=0, param2=0},
		{name="air", prob=0, param2=0},
		{name="air", prob=0, param2=0},
		{name="everness:crystal_mossy_cobble", prob=254, param2=0},
		{name="everness:crystal_sandstone_chiseled", prob=254, param2=0},
		{name="everness:crystal_sand", prob=254, param2=0},
		{name="everness:crystal_forest_deep_ocean_sand", prob=254, param2=0},
		{name="everness:crystal_sand", prob=254, param2=0},
		{name="everness:crystal_mossy_cobble", prob=254, param2=0},
		{name="everness:crystal_sandstone_chiseled", prob=254, param2=0},
		{name="air", prob=0, param2=0},
		{name="air", prob=0, param2=0},
		{name="air", prob=0, param2=0},
		{name="air", prob=0, param2=0},
		{name="air", prob=0, param2=0},
		{name="air", prob=0, param2=0},
		{name="everness:crystal_cobble", prob=254, param2=0},
		{name="everness:crystal_cobble", prob=254, param2=0},
		{name="air", prob=254, param2=0},
		{name="air", prob=254, param2=0},
		{name="air", prob=254, param2=0},
		{name="everness:crystal_cobble", prob=254, param2=0},
		{name="everness:crystal_stone_brick", prob=254, param2=0},
		{name="air", prob=0, param2=0},
		{name="air", prob=0, param2=0},
		{name="air", prob=0, param2=0},
		{name="air", prob=0, param2=0},
		{name="air", prob=0, param2=0},
		{name="air", prob=0, param2=0},
		{name="everness:crystal_sandstone_brick", prob=254, param2=0},
		{name="everness:crystal_sandstone_chiseled", prob=254, param2=0},
		{name="air", prob=254, param2=0},
		{name="air", prob=254, param2=0},
		{name="air", prob=254, param2=0},
		{name="everness:crystal_cobble", prob=254, param2=0},
		{name="everness:crystal_sandstone_brick", prob=254, param2=0},
		{name="air", prob=0, param2=0},
		{name="air", prob=0, param2=0},
		{name="air", prob=0, param2=0},
		{name="air", prob=0, param2=0},
		{name="air", prob=0, param2=0},
		{name="air", prob=0, param2=0},
		{name="everness:crystal_sandstone_chiseled", prob=254, param2=0},
		{name="everness:pyrite_lantern", prob=254, param2=0},
		{name="air", prob=254, param2=0},
		{name="air", prob=254, param2=0},
		{name="air", prob=254, param2=0},
		{name="everness:crystal_sandstone_chiseled", prob=254, param2=0},
		{name="everness:crystal_mossy_cobble", prob=254, param2=0},
		{name="air", prob=0, param2=0},
		{name="air", prob=0, param2=0},
		{name="air", prob=0, param2=0},
		{name="air", prob=0, param2=0},
		{name="air", prob=0, param2=0},
		{name="air", prob=0, param2=0},
		{name="everness:crystal_sandstone_chiseled", prob=254, param2=0},
		{name="everness:crystal_sandstone_chiseled", prob=254, param2=0},
		{name="air", prob=254, param2=0},
		{name="air", prob=254, param2=0},
		{name="air", prob=254, param2=0},
		{name="everness:crystal_stone_brick", prob=254, param2=0},
		{name="everness:crystal_sandstone_chiseled", prob=254, param2=0},
		{name="air", prob=0, param2=0},
		{name="air", prob=0, param2=0},
		{name="air", prob=0, param2=0},
		{name="air", prob=0, param2=0},
		{name="air", prob=0, param2=0},
		{name="air", prob=0, param2=0},
		{name="everness:crystal_sandstone_chiseled", prob=254, param2=0},
		{name="everness:crystal_sandstone_brick", prob=254, param2=0},
		{name="air", prob=254, param2=0},
		{name="air", prob=254, param2=0},
		{name="air", prob=254, param2=0},
		{name="everness:crystal_sandstone_chiseled", prob=254, param2=0},
		{name="everness:crystal_sandstone_chiseled", prob=254, param2=0},
		{name="air", prob=0, param2=0},
		{name="air", prob=0, param2=0},
		{name="air", prob=0, param2=0},
		{name="air", prob=0, param2=0},
		{name="air", prob=0, param2=0},
		{name="everness:crystal_cobble", prob=254, param2=0},
		{name="everness:crystal_stone_brick", prob=254, param2=0},
		{name="everness:crystal_stone_brick", prob=254, param2=0},
		{name="air", prob=254, param2=0},
		{name="air", prob=254, param2=0},
		{name="air", prob=254, param2=0},
		{name="everness:crystal_sandstone_chiseled", prob=254, param2=0},
		{name="everness:crystal_cobble", prob=254, param2=0},
		{name="everness:crystal_cobble", prob=254, param2=0},
		{name="air", prob=0, param2=0},
		{name="air", prob=0, param2=0},
		{name="air", prob=0, param2=0},
		{name="air", prob=0, param2=0},
		{name="everness:crystal_forest_deep_ocean_sand", prob=254, param2=0},
		{name="everness:crystal_sandstone_chiseled", prob=254, param2=0},
		{name="everness:crystal_stone_brick", prob=254, param2=0},
		{name="air", prob=254, param2=0},
		{name="air", prob=254, param2=0},
		{name="air", prob=254, param2=0},
		{name="everness:crystal_sandstone_brick", prob=254, param2=0},
		{name="everness:crystal_stone_brick", prob=254, param2=0},
		{name="everness:crystal_forest_deep_ocean_sand", prob=254, param2=0},
		{name="air", prob=0, param2=0},
		{name="air", prob=0, param2=0},
		{name="air", prob=0, param2=0},
		{name="air", prob=0, param2=0},
		{name="air", prob=0, param2=0},
		{name="everness:crystal_sand", prob=254, param2=0},
		{name="everness:crystal_cobble", prob=254, param2=0},
		{name="everness:crystal_forest_deep_ocean_sandstone_block", prob=254, param2=0},
		{name="everness:crystal_forest_deep_ocean_sandstone_block", prob=254, param2=0},
		{name="everness:crystal_forest_deep_ocean_sandstone_block", prob=254, param2=0},
		{name="everness:crystal_cobble", prob=254, param2=0},
		{name="everness:crystal_sand", prob=254, param2=0},
		{name="air", prob=0, param2=0},
		{name="air", prob=0, param2=0},
		{name="air", prob=0, param2=0},
		{name="air", prob=0, param2=0},
		{name="air", prob=0, param2=0},
		{name="air", prob=0, param2=0},
		{name="air", prob=0, param2=0},
		{name="everness:crystal_forest_deep_ocean_sandstone_block", prob=254, param2=0},
		{name="air", prob=254, param2=0},
		{name="air", prob=254, param2=0},
		{name="air", prob=254, param2=0},
		{name="everness:crystal_forest_deep_ocean_sandstone_block", prob=254, param2=0},
		{name="air", prob=0, param2=0},
		{name="air", prob=0, param2=0},
		{name="air", prob=0, param2=0},
		{name="air", prob=0, param2=0},
		{name="air", prob=0, param2=0},
		{name="air", prob=0, param2=0},
		{name="air", prob=0, param2=0},
		{name="air", prob=0, param2=0},
		{name="everness:crystal_forest_deep_ocean_sandstone_brick", prob=254, param2=0},
		{name="air", prob=254, param2=0},
		{name="air", prob=254, param2=0},
		{name="air", prob=254, param2=0},
		{name="everness:crystal_forest_deep_ocean_sandstone_brick", prob=254, param2=0},
		{name="air", prob=0, param2=0},
		{name="air", prob=0, param2=0},
		{name="air", prob=0, param2=0},
		{name="air", prob=0, param2=0},
		{name="air", prob=0, param2=0},
		{name="air", prob=0, param2=0},
		{name="air", prob=0, param2=0},
		{name="air", prob=0, param2=0},
		{name="everness:crystal_forest_deep_ocean_sandstone_brick", prob=254, param2=0},
		{name="air", prob=254, param2=0},
		{name="air", prob=254, param2=0},
		{name="air", prob=254, param2=0},
		{name="everness:crystal_forest_deep_ocean_sandstone_brick", prob=254, param2=0},
		{name="air", prob=0, param2=0},
		{name="air", prob=0, param2=0},
		{name="air", prob=0, param2=0},
		{name="air", prob=0, param2=0},
		{name="air", prob=0, param2=0},
		{name="air", prob=0, param2=0},
		{name="air", prob=0, param2=0},
		{name="air", prob=0, param2=0},
		{name="everness:crystal_forest_deep_ocean_sandstone_brick", prob=254, param2=0},
		{name="air", prob=254, param2=0},
		{name="air", prob=254, param2=0},
		{name="air", prob=254, param2=0},
		{name="everness:crystal_forest_deep_ocean_sandstone_brick", prob=254, param2=0},
		{name="air", prob=0, param2=0},
		{name="air", prob=0, param2=0},
		{name="air", prob=0, param2=0},
		{name="air", prob=0, param2=0},
		{name="air", prob=0, param2=0},
		{name="air", prob=0, param2=0},
		{name="air", prob=0, param2=0},
		{name="stairs:stair_crystal_forest_deep_ocean_sandstone_block", prob=126, param2=23},
		{name="everness:crystal_forest_deep_ocean_sandstone_block", prob=254, param2=0},
		{name="everness:crystal_forest_deep_ocean_sandstone_block", prob=254, param2=0},
		{name="everness:crystal_forest_deep_ocean_sandstone_block", prob=254, param2=0},
		{name="everness:crystal_forest_deep_ocean_sandstone_block", prob=254, param2=0},
		{name="everness:crystal_forest_deep_ocean_sandstone_block", prob=254, param2=0},
		{name="stairs:stair_crystal_forest_deep_ocean_sandstone_block", prob=126, param2=21},
		{name="air", prob=0, param2=0},
		{name="air", prob=0, param2=0},
		{name="air", prob=0, param2=0},
		{name="air", prob=0, param2=0},
		{name="air", prob=0, param2=0},
		{name="air", prob=0, param2=0},
		{name="air", prob=0, param2=0},
		{name="air", prob=0, param2=0},
		{name="stairs:slab_crystal_forest_deep_ocean_sandstone_brick", prob=126, param2=0},
		{name="stairs:stair_crystal_forest_deep_ocean_sandstone_brick", prob=126, param2=0},
		{name="stairs:slab_crystal_forest_deep_ocean_sandstone_brick", prob=126, param2=0},
		{name="air", prob=0, param2=0},
		{name="air", prob=0, param2=0},
		{name="air", prob=0, param2=0},
		{name="air", prob=0, param2=0},
		{name="air", prob=0, param2=0},
		{name="air", prob=0, param2=0},
		{name="air", prob=0, param2=0},
		{name="everness:crystal_cobble", prob=254, param2=0},
		{name="everness:crystal_sandstone_chiseled", prob=254, param2=0},
		{name="everness:crystal_mossy_cobble", prob=254, param2=0},
		{name="everness:crystal_mossy_cobble", prob=254, param2=0},
		{name="everness:crystal_stone_brick", prob=254, param2=0},
		{name="everness:crystal_stone_brick", prob=254, param2=0},
		{name="everness:crystal_mossy_cobble", prob=254, param2=0},
		{name="everness:crystal_mossy_cobble", prob=254, param2=0},
		{name="everness:crystal_stone_brick", prob=254, param2=0},
		{name="air", prob=0, param2=0},
		{name="air", prob=0, param2=0},
		{name="air", prob=0, param2=0},
		{name="air", prob=0, param2=0},
		{name="everness:crystal_stone_brick", prob=254, param2=0},
		{name="everness:crystal_sand", prob=254, param2=0},
		{name="everness:crystal_sand", prob=254, param2=0},
		{name="everness:crystal_forest_deep_ocean_sand", prob=254, param2=0},
		{name="everness:crystal_forest_deep_ocean_sand", prob=254, param2=0},
		{name="everness:crystal_sand", prob=254, param2=0},
		{name="everness:crystal_forest_deep_ocean_sand", prob=254, param2=0},
		{name="everness:crystal_sand", prob=254, param2=0},
		{name="everness:crystal_sandstone_brick", prob=254, param2=0},
		{name="air", prob=0, param2=0},
		{name="air", prob=0, param2=0},
		{name="air", prob=0, param2=0},
		{name="air", prob=0, param2=0},
		{name="everness:crystal_cobble", prob=254, param2=0},
		{name="air", prob=254, param2=0},
		{name="air", prob=254, param2=0},
		{name="everness:crystal_forest_deep_ocean_sandstone_brick", prob=254, param2=0},
		{name="everness:crystal_forest_deep_ocean_sandstone_block", prob=254, param2=0},
		{name="everness:crystal_forest_deep_ocean_sandstone_brick", prob=254, param2=0},
		{name="air", prob=254, param2=0},
		{name="air", prob=254, param2=0},
		{name="everness:crystal_sandstone_brick", prob=254, param2=0},
		{name="air", prob=0, param2=0},
		{name="air", prob=0, param2=0},
		{name="air", prob=0, param2=0},
		{name="air", prob=0, param2=0},
		{name="everness:crystal_mossy_cobble", prob=254, param2=0},
		{name="air", prob=254, param2=0},
		{name="air", prob=254, param2=0},
		{name="air", prob=254, param2=0},
		{name="air", prob=254, param2=0},
		{name="air", prob=254, param2=0},
		{name="air", prob=254, param2=0},
		{name="air", prob=254, param2=0},
		{name="everness:crystal_sandstone_brick", prob=254, param2=0},
		{name="air", prob=0, param2=0},
		{name="air", prob=0, param2=0},
		{name="air", prob=0, param2=0},
		{name="air", prob=0, param2=0},
		{name="everness:crystal_sandstone_chiseled", prob=254, param2=0},
		{name="air", prob=254, param2=0},
		{name="air", prob=254, param2=0},
		{name="air", prob=254, param2=0},
		{name="air", prob=254, param2=0},
		{name="air", prob=254, param2=0},
		{name="air", prob=254, param2=0},
		{name="air", prob=254, param2=0},
		{name="everness:crystal_stone_brick", prob=254, param2=0},
		{name="air", prob=0, param2=0},
		{name="air", prob=0, param2=0},
		{name="air", prob=0, param2=0},
		{name="air", prob=0, param2=0},
		{name="everness:crystal_stone_brick", prob=254, param2=0},
		{name="air", prob=254, param2=0},
		{name="air", prob=254, param2=0},
		{name="air", prob=254, param2=0},
		{name="air", prob=254, param2=0},
		{name="air", prob=254, param2=0},
		{name="air", prob=254, param2=0},
		{name="air", prob=254, param2=0},
		{name="everness:crystal_sandstone_brick", prob=254, param2=0},
		{name="air", prob=0, param2=0},
		{name="air", prob=0, param2=0},
		{name="air", prob=0, param2=0},
		{name="air", prob=0, param2=0},
		{name="everness:crystal_sandstone_brick", prob=254, param2=0},
		{name="air", prob=254, param2=0},
		{name="air", prob=254, param2=0},
		{name="air", prob=254, param2=0},
		{name="air", prob=254, param2=0},
		{name="air", prob=254, param2=0},
		{name="air", prob=254, param2=0},
		{name="air", prob=254, param2=0},
		{name="everness:crystal_sandstone_chiseled", prob=254, param2=0},
		{name="air", prob=0, param2=0},
		{name="air", prob=0, param2=0},
		{name="air", prob=0, param2=0},
		{name="everness:crystal_cobble", prob=254, param2=0},
		{name="everness:crystal_sandstone_brick", prob=254, param2=0},
		{name="air", prob=254, param2=0},
		{name="air", prob=254, param2=0},
		{name="air", prob=254, param2=0},
		{name="air", prob=254, param2=0},
		{name="air", prob=254, param2=0},
		{name="air", prob=254, param2=0},
		{name="air", prob=254, param2=0},
		{name="everness:crystal_stone_brick", prob=254, param2=0},
		{name="everness:crystal_cobble", prob=254, param2=0},
		{name="air", prob=0, param2=0},
		{name="air", prob=0, param2=0},
		{name="everness:crystal_forest_deep_ocean_sand", prob=254, param2=0},
		{name="everness:crystal_sandstone_brick", prob=254, param2=0},
		{name="air", prob=254, param2=0},
		{name="air", prob=254, param2=0},
		{name="air", prob=254, param2=0},
		{name="air", prob=254, param2=0},
		{name="air", prob=254, param2=0},
		{name="air", prob=254, param2=0},
		{name="air", prob=254, param2=0},
		{name="everness:crystal_sandstone_brick", prob=254, param2=0},
		{name="everness:crystal_forest_deep_ocean_sand", prob=254, param2=0},
		{name="air", prob=0, param2=0},
		{name="air", prob=0, param2=0},
		{name="air", prob=0, param2=0},
		{name="everness:crystal_forest_deep_ocean_sand", prob=254, param2=0},
		{name="everness:crystal_forest_deep_ocean_sandstone_block", prob=254, param2=0},
		{name="everness:crystal_forest_deep_ocean_sandstone_block", prob=254, param2=0},
		{name="stairs:slab_crystal_forest_deep_ocean_sandstone_block", prob=254, param2=3},
		{name="stairs:slab_crystal_forest_deep_ocean_sandstone_block", prob=254, param2=3},
		{name="stairs:slab_crystal_forest_deep_ocean_sandstone_block", prob=254, param2=2},
		{name="everness:crystal_forest_deep_ocean_sandstone_block", prob=254, param2=0},
		{name="everness:crystal_forest_deep_ocean_sandstone_block", prob=254, param2=0},
		{name="everness:crystal_forest_deep_ocean_sand", prob=254, param2=0},
		{name="air", prob=0, param2=0},
		{name="air", prob=0, param2=0},
		{name="air", prob=0, param2=0},
		{name="air", prob=0, param2=0},
		{name="air", prob=0, param2=0},
		{name="air", prob=254, param2=0},
		{name="air", prob=254, param2=0},
		{name="air", prob=254, param2=0},
		{name="air", prob=254, param2=0},
		{name="air", prob=254, param2=0},
		{name="air", prob=254, param2=0},
		{name="air", prob=254, param2=0},
		{name="air", prob=0, param2=0},
		{name="air", prob=0, param2=0},
		{name="air", prob=0, param2=0},
		{name="air", prob=0, param2=0},
		{name="air", prob=0, param2=0},
		{name="air", prob=0, param2=0},
		{name="air", prob=254, param2=0},
		{name="air", prob=254, param2=0},
		{name="air", prob=254, param2=0},
		{name="air", prob=254, param2=0},
		{name="air", prob=254, param2=0},
		{name="air", prob=254, param2=0},
		{name="air", prob=254, param2=0},
		{name="air", prob=0, param2=0},
		{name="air", prob=0, param2=0},
		{name="air", prob=0, param2=0},
		{name="air", prob=0, param2=0},
		{name="air", prob=0, param2=0},
		{name="air", prob=0, param2=0},
		{name="air", prob=254, param2=0},
		{name="air", prob=254, param2=0},
		{name="air", prob=254, param2=0},
		{name="air", prob=254, param2=0},
		{name="air", prob=254, param2=0},
		{name="air", prob=254, param2=0},
		{name="air", prob=254, param2=0},
		{name="air", prob=0, param2=0},
		{name="air", prob=0, param2=0},
		{name="air", prob=0, param2=0},
		{name="air", prob=0, param2=0},
		{name="air", prob=0, param2=0},
		{name="stairs:stair_crystal_forest_deep_ocean_sandstone_block", prob=126, param2=20},
		{name="air", prob=254, param2=0},
		{name="air", prob=254, param2=0},
		{name="air", prob=254, param2=0},
		{name="air", prob=254, param2=0},
		{name="air", prob=254, param2=0},
		{name="air", prob=254, param2=0},
		{name="air", prob=254, param2=0},
		{name="stairs:stair_crystal_forest_deep_ocean_sandstone_block", prob=126, param2=20},
		{name="air", prob=0, param2=0},
		{name="air", prob=0, param2=0},
		{name="air", prob=0, param2=0},
		{name="air", prob=0, param2=0},
		{name="air", prob=0, param2=0},
		{name="air", prob=0, param2=0},
		{name="air", prob=0, param2=0},
		{name="air", prob=0, param2=0},
		{name="air", prob=0, param2=0},
		{name="air", prob=0, param2=0},
		{name="air", prob=0, param2=0},
		{name="air", prob=0, param2=0},
		{name="air", prob=0, param2=0},
		{name="air", prob=0, param2=0},
		{name="air", prob=0, param2=0},
		{name="air", prob=0, param2=0},
		{name="air", prob=0, param2=0},
		{name="air", prob=0, param2=0},
		{name="air", prob=0, param2=0},
		{name="air", prob=0, param2=0},
		{name="air", prob=0, param2=0},
		{name="air", prob=0, param2=0},
		{name="air", prob=0, param2=0},
		{name="air", prob=0, param2=0},
		{name="air", prob=0, param2=0},
		{name="air", prob=0, param2=0},
		{name="air", prob=0, param2=0},
		{name="air", prob=0, param2=0},
		{name="air", prob=0, param2=0},
		{name="everness:crystal_cobble", prob=254, param2=0},
		{name="everness:crystal_sandstone_chiseled", prob=254, param2=0},
		{name="everness:crystal_stone_brick", prob=254, param2=0},
		{name="everness:crystal_stone_brick", prob=254, param2=0},
		{name="everness:crystal_stone_brick", prob=254, param2=0},
		{name="everness:crystal_stone_brick", prob=254, param2=0},
		{name="everness:crystal_sandstone_chiseled", prob=254, param2=0},
		{name="everness:crystal_sandstone_brick", prob=254, param2=0},
		{name="everness:crystal_stone_brick", prob=254, param2=0},
		{name="everness:crystal_stone_brick", prob=254, param2=0},
		{name="everness:crystal_stone_brick", prob=254, param2=0},
		{name="air", prob=0, param2=0},
		{name="air", prob=0, param2=0},
		{name="everness:crystal_sandstone_chiseled", prob=254, param2=0},
		{name="everness:crystal_mossy_cobble", prob=254, param2=0},
		{name="everness:crystal_sand", prob=254, param2=0},
		{name="everness:crystal_forest_deep_ocean_sand", prob=254, param2=0},
		{name="everness:crystal_sand", prob=254, param2=0},
		{name="everness:crystal_forest_deep_ocean_sand", prob=254, param2=0},
		{name="everness:crystal_forest_deep_ocean_sand", prob=254, param2=0},
		{name="everness:crystal_forest_deep_ocean_sand", prob=254, param2=0},
		{name="everness:crystal_forest_deep_ocean_sand", prob=254, param2=0},
		{name="everness:crystal_sandstone_brick", prob=254, param2=0},
		{name="everness:crystal_sandstone_chiseled", prob=254, param2=0},
		{name="air", prob=0, param2=0},
		{name="air", prob=0, param2=0},
		{name="everness:crystal_cobble", prob=254, param2=0},
		{name="everness:crystal_mossy_cobble", prob=254, param2=0},
		{name="air", prob=254, param2=0},
		{name="air", prob=254, param2=0},
		{name="air", prob=254, param2=0},
		{name="air", prob=254, param2=0},
		{name="air", prob=254, param2=0},
		{name="air", prob=254, param2=0},
		{name="air", prob=254, param2=0},
		{name="everness:crystal_cobble", prob=254, param2=0},
		{name="everness:crystal_mossy_cobble", prob=254, param2=0},
		{name="air", prob=0, param2=0},
		{name="air", prob=0, param2=0},
		{name="everness:crystal_sandstone_brick", prob=254, param2=0},
		{name="everness:crystal_mossy_cobble", prob=254, param2=0},
		{name="air", prob=254, param2=0},
		{name="air", prob=254, param2=0},
		{name="air", prob=254, param2=0},
		{name="air", prob=254, param2=0},
		{name="air", prob=254, param2=0},
		{name="air", prob=254, param2=0},
		{name="air", prob=254, param2=0},
		{name="everness:crystal_mossy_cobble", prob=254, param2=0},
		{name="everness:crystal_sandstone_chiseled", prob=254, param2=0},
		{name="air", prob=0, param2=0},
		{name="air", prob=0, param2=0},
		{name="everness:crystal_stone_brick", prob=254, param2=0},
		{name="everness:crystal_mossy_cobble", prob=254, param2=0},
		{name="air", prob=254, param2=0},
		{name="air", prob=254, param2=0},
		{name="air", prob=254, param2=0},
		{name="air", prob=254, param2=0},
		{name="air", prob=254, param2=0},
		{name="air", prob=254, param2=0},
		{name="air", prob=254, param2=0},
		{name="everness:crystal_cobble", prob=254, param2=0},
		{name="everness:crystal_cobble", prob=254, param2=0},
		{name="air", prob=0, param2=0},
		{name="air", prob=0, param2=0},
		{name="everness:crystal_sandstone_brick", prob=254, param2=0},
		{name="everness:crystal_sandstone_chiseled", prob=254, param2=0},
		{name="air", prob=254, param2=0},
		{name="air", prob=254, param2=0},
		{name="air", prob=254, param2=0},
		{name="air", prob=254, param2=0},
		{name="air", prob=254, param2=0},
		{name="air", prob=254, param2=0},
		{name="air", prob=254, param2=0},
		{name="everness:crystal_cobble", prob=254, param2=0},
		{name="everness:crystal_sandstone_chiseled", prob=254, param2=0},
		{name="air", prob=0, param2=0},
		{name="air", prob=0, param2=0},
		{name="everness:crystal_stone_brick", prob=254, param2=0},
		{name="everness:crystal_sandstone_chiseled", prob=254, param2=0},
		{name="air", prob=254, param2=0},
		{name="air", prob=254, param2=0},
		{name="air", prob=254, param2=0},
		{name="air", prob=254, param2=0},
		{name="air", prob=254, param2=0},
		{name="air", prob=254, param2=0},
		{name="air", prob=254, param2=0},
		{name="everness:crystal_cobble", prob=254, param2=0},
		{name="everness:crystal_sandstone_chiseled", prob=254, param2=0},
		{name="air", prob=0, param2=0},
		{name="everness:crystal_cobble", prob=254, param2=0},
		{name="everness:crystal_sandstone_brick", prob=254, param2=0},
		{name="everness:crystal_cobble", prob=254, param2=0},
		{name="air", prob=254, param2=0},
		{name="air", prob=254, param2=0},
		{name="air", prob=254, param2=0},
		{name="air", prob=254, param2=0},
		{name="air", prob=254, param2=0},
		{name="air", prob=254, param2=0},
		{name="air", prob=254, param2=0},
		{name="everness:crystal_sandstone_brick", prob=254, param2=0},
		{name="everness:crystal_stone_brick", prob=254, param2=0},
		{name="everness:crystal_cobble", prob=254, param2=0},
		{name="everness:crystal_forest_deep_ocean_sand", prob=254, param2=0},
		{name="everness:crystal_stone_brick", prob=254, param2=0},
		{name="everness:crystal_mossy_cobble", prob=254, param2=0},
		{name="air", prob=254, param2=0},
		{name="air", prob=254, param2=0},
		{name="air", prob=254, param2=0},
		{name="air", prob=254, param2=0},
		{name="air", prob=254, param2=0},
		{name="air", prob=254, param2=0},
		{name="air", prob=254, param2=0},
		{name="everness:crystal_sandstone_chiseled", prob=254, param2=0},
		{name="everness:crystal_sandstone_chiseled", prob=254, param2=0},
		{name="everness:crystal_forest_deep_ocean_sand", prob=254, param2=0},
		{name="air", prob=0, param2=0},
		{name="everness:crystal_forest_deep_ocean_sand", prob=254, param2=0},
		{name="everness:crystal_sandstone_chiseled", prob=254, param2=0},
		{name="everness:crystal_forest_deep_ocean_sandstone_block", prob=254, param2=0},
		{name="stairs:slab_crystal_forest_deep_ocean_sandstone_block", prob=254, param2=3},
		{name="stairs:slab_crystal_forest_deep_ocean_sandstone_brick", prob=84, param2=3},
		{name="stairs:slab_crystal_forest_deep_ocean_sandstone_brick", prob=84, param2=3},
		{name="stairs:slab_crystal_forest_deep_ocean_sandstone_brick", prob=84, param2=2},
		{name="stairs:slab_crystal_forest_deep_ocean_sandstone_block", prob=254, param2=1},
		{name="everness:crystal_forest_deep_ocean_sandstone_block", prob=254, param2=0},
		{name="everness:crystal_stone_brick", prob=254, param2=0},
		{name="everness:crystal_sand", prob=254, param2=0},
		{name="air", prob=0, param2=0},
		{name="air", prob=0, param2=0},
		{name="air", prob=0, param2=0},
		{name="everness:crystal_forest_deep_ocean_sandstone_block", prob=254, param2=0},
		{name="air", prob=254, param2=0},
		{name="air", prob=254, param2=0},
		{name="air", prob=254, param2=0},
		{name="air", prob=254, param2=0},
		{name="air", prob=254, param2=0},
		{name="air", prob=254, param2=0},
		{name="air", prob=254, param2=0},
		{name="everness:crystal_forest_deep_ocean_sandstone_block", prob=254, param2=0},
		{name="air", prob=0, param2=0},
		{name="air", prob=0, param2=0},
		{name="air", prob=0, param2=0},
		{name="air", prob=0, param2=0},
		{name="everness:crystal_forest_deep_ocean_sandstone_brick", prob=254, param2=0},
		{name="air", prob=254, param2=0},
		{name="air", prob=254, param2=0},
		{name="air", prob=254, param2=0},
		{name="air", prob=254, param2=0},
		{name="air", prob=254, param2=0},
		{name="air", prob=254, param2=0},
		{name="air", prob=254, param2=0},
		{name="everness:crystal_forest_deep_ocean_sandstone_brick", prob=254, param2=0},
		{name="air", prob=0, param2=0},
		{name="air", prob=0, param2=0},
		{name="air", prob=0, param2=0},
		{name="air", prob=0, param2=0},
		{name="everness:crystal_forest_deep_ocean_sandstone_brick", prob=254, param2=0},
		{name="air", prob=254, param2=0},
		{name="air", prob=254, param2=0},
		{name="air", prob=254, param2=0},
		{name="air", prob=254, param2=0},
		{name="air", prob=254, param2=0},
		{name="air", prob=254, param2=0},
		{name="air", prob=254, param2=0},
		{name="everness:crystal_forest_deep_ocean_sandstone_brick", prob=254, param2=0},
		{name="air", prob=0, param2=0},
		{name="air", prob=0, param2=0},
		{name="air", prob=0, param2=0},
		{name="air", prob=0, param2=0},
		{name="everness:crystal_forest_deep_ocean_sandstone_block", prob=254, param2=0},
		{name="air", prob=254, param2=0},
		{name="air", prob=254, param2=0},
		{name="air", prob=254, param2=0},
		{name="air", prob=254, param2=0},
		{name="air", prob=254, param2=0},
		{name="air", prob=254, param2=0},
		{name="air", prob=254, param2=0},
		{name="everness:crystal_forest_deep_ocean_sandstone_block", prob=254, param2=0},
		{name="air", prob=0, param2=0},
		{name="air", prob=0, param2=0},
		{name="air", prob=0, param2=0},
		{name="air", prob=0, param2=0},
		{name="air", prob=0, param2=0},
		{name="air", prob=0, param2=0},
		{name="air", prob=0, param2=0},
		{name="air", prob=0, param2=0},
		{name="air", prob=0, param2=0},
		{name="air", prob=0, param2=0},
		{name="air", prob=0, param2=0},
		{name="air", prob=0, param2=0},
		{name="air", prob=0, param2=0},
		{name="air", prob=0, param2=0},
		{name="air", prob=0, param2=0},
		{name="air", prob=0, param2=0},
		{name="air", prob=0, param2=0},
		{name="air", prob=0, param2=0},
		{name="air", prob=0, param2=0},
		{name="air", prob=0, param2=0},
		{name="air", prob=0, param2=0},
		{name="air", prob=0, param2=0},
		{name="air", prob=0, param2=0},
		{name="air", prob=0, param2=0},
		{name="air", prob=0, param2=0},
		{name="air", prob=0, param2=0},
		{name="air", prob=0, param2=0},
		{name="air", prob=0, param2=0},
		{name="air", prob=0, param2=0},
		{name="everness:crystal_sandstone_chiseled", prob=254, param2=0},
		{name="everness:crystal_mossy_cobble", prob=254, param2=0},
		{name="everness:crystal_mossy_cobble", prob=254, param2=0},
		{name="everness:crystal_cobble", prob=254, param2=0},
		{name="everness:crystal_mossy_cobble", prob=254, param2=0},
		{name="everness:crystal_sandstone_chiseled", prob=254, param2=0},
		{name="everness:crystal_sandstone_chiseled", prob=254, param2=0},
		{name="everness:crystal_cobble", prob=254, param2=0},
		{name="everness:crystal_stone_brick", prob=254, param2=0},
		{name="everness:crystal_sandstone_chiseled", prob=254, param2=0},
		{name="everness:crystal_sandstone_chiseled", prob=254, param2=0},
		{name="air", prob=0, param2=0},
		{name="air", prob=0, param2=0},
		{name="everness:crystal_stone_brick", prob=254, param2=0},
		{name="everness:crystal_sand", prob=254, param2=0},
		{name="everness:crystal_sand", prob=254, param2=0},
		{name="everness:crystal_sand", prob=254, param2=0},
		{name="everness:crystal_forest_deep_ocean_sand", prob=254, param2=0},
		{name="everness:crystal_sand", prob=254, param2=0},
		{name="everness:crystal_forest_deep_ocean_sand", prob=254, param2=0},
		{name="everness:crystal_forest_deep_ocean_sand", prob=254, param2=0},
		{name="everness:crystal_sand", prob=254, param2=0},
		{name="everness:crystal_forest_deep_ocean_sand", prob=254, param2=0},
		{name="everness:crystal_sandstone_chiseled", prob=254, param2=0},
		{name="air", prob=0, param2=0},
		{name="air", prob=0, param2=0},
		{name="everness:crystal_mossy_cobble", prob=254, param2=0},
		{name="air", prob=254, param2=0},
		{name="everness:crystal_forest_deep_ocean_sandstone_block", prob=254, param2=0},
		{name="air", prob=254, param2=0},
		{name="air", prob=254, param2=0},
		{name="air", prob=254, param2=0},
		{name="air", prob=254, param2=0},
		{name="air", prob=254, param2=0},
		{name="everness:crystal_forest_deep_ocean_sandstone_block", prob=254, param2=0},
		{name="air", prob=254, param2=0},
		{name="everness:crystal_sandstone_brick", prob=254, param2=0},
		{name="air", prob=0, param2=0},
		{name="air", prob=0, param2=0},
		{name="everness:crystal_sandstone_chiseled", prob=254, param2=0},
		{name="air", prob=254, param2=0},
		{name="air", prob=254, param2=0},
		{name="air", prob=254, param2=0},
		{name="air", prob=254, param2=0},
		{name="air", prob=254, param2=0},
		{name="air", prob=254, param2=0},
		{name="air", prob=254, param2=0},
		{name="air", prob=254, param2=0},
		{name="air", prob=254, param2=0},
		{name="everness:crystal_mossy_cobble", prob=254, param2=0},
		{name="air", prob=0, param2=0},
		{name="air", prob=0, param2=0},
		{name="everness:crystal_stone_brick", prob=254, param2=0},
		{name="air", prob=254, param2=0},
		{name="air", prob=254, param2=0},
		{name="air", prob=254, param2=0},
		{name="air", prob=254, param2=0},
		{name="air", prob=254, param2=0},
		{name="air", prob=254, param2=0},
		{name="air", prob=254, param2=0},
		{name="air", prob=254, param2=0},
		{name="air", prob=254, param2=0},
		{name="everness:crystal_sandstone_brick", prob=254, param2=0},
		{name="air", prob=0, param2=0},
		{name="air", prob=0, param2=0},
		{name="everness:crystal_cobble", prob=254, param2=0},
		{name="air", prob=254, param2=0},
		{name="air", prob=254, param2=0},
		{name="air", prob=254, param2=0},
		{name="air", prob=254, param2=0},
		{name="air", prob=254, param2=0},
		{name="air", prob=254, param2=0},
		{name="air", prob=254, param2=0},
		{name="air", prob=254, param2=0},
		{name="air", prob=254, param2=0},
		{name="everness:crystal_mossy_cobble", prob=254, param2=0},
		{name="air", prob=0, param2=0},
		{name="air", prob=0, param2=0},
		{name="everness:crystal_sandstone_chiseled", prob=254, param2=0},
		{name="air", prob=254, param2=0},
		{name="air", prob=254, param2=0},
		{name="air", prob=254, param2=0},
		{name="air", prob=254, param2=0},
		{name="air", prob=254, param2=0},
		{name="air", prob=254, param2=0},
		{name="air", prob=254, param2=0},
		{name="air", prob=254, param2=0},
		{name="air", prob=254, param2=0},
		{name="everness:crystal_sandstone_chiseled", prob=254, param2=0},
		{name="air", prob=0, param2=0},
		{name="everness:crystal_cobble", prob=254, param2=0},
		{name="everness:crystal_cobble", prob=254, param2=0},
		{name="air", prob=254, param2=0},
		{name="air", prob=254, param2=0},
		{name="air", prob=254, param2=0},
		{name="air", prob=254, param2=0},
		{name="air", prob=254, param2=0},
		{name="air", prob=254, param2=0},
		{name="air", prob=254, param2=0},
		{name="air", prob=254, param2=0},
		{name="air", prob=254, param2=0},
		{name="everness:crystal_mossy_cobble", prob=254, param2=0},
		{name="everness:crystal_cobble", prob=254, param2=0},
		{name="everness:crystal_sand", prob=254, param2=0},
		{name="everness:crystal_mossy_cobble", prob=254, param2=0},
		{name="air", prob=254, param2=0},
		{name="air", prob=254, param2=0},
		{name="air", prob=254, param2=0},
		{name="air", prob=254, param2=0},
		{name="air", prob=254, param2=0},
		{name="air", prob=254, param2=0},
		{name="air", prob=254, param2=0},
		{name="air", prob=254, param2=0},
		{name="air", prob=254, param2=0},
		{name="everness:crystal_sandstone_chiseled", prob=254, param2=0},
		{name="everness:crystal_forest_deep_ocean_sand", prob=254, param2=0},
		{name="air", prob=0, param2=0},
		{name="everness:crystal_forest_deep_ocean_sand", prob=254, param2=0},
		{name="everness:crystal_forest_deep_ocean_sandstone_block", prob=254, param2=0},
		{name="stairs:slab_crystal_forest_deep_ocean_sandstone_block", prob=254, param2=3},
		{name="stairs:slab_crystal_forest_deep_ocean_sandstone_brick", prob=84, param2=3},
		{name="air", prob=254, param2=0},
		{name="air", prob=254, param2=0},
		{name="air", prob=254, param2=0},
		{name="stairs:slab_crystal_forest_deep_ocean_sandstone_brick", prob=84, param2=1},
		{name="stairs:slab_crystal_forest_deep_ocean_sandstone_block", prob=254, param2=1},
		{name="everness:crystal_forest_deep_ocean_sandstone_block", prob=254, param2=0},
		{name="everness:crystal_forest_deep_ocean_sand", prob=254, param2=0},
		{name="air", prob=0, param2=0},
		{name="air", prob=254, param2=0},
		{name="air", prob=254, param2=0},
		{name="air", prob=254, param2=0},
		{name="air", prob=254, param2=0},
		{name="air", prob=254, param2=0},
		{name="air", prob=254, param2=0},
		{name="air", prob=254, param2=0},
		{name="air", prob=254, param2=0},
		{name="air", prob=254, param2=0},
		{name="air", prob=254, param2=0},
		{name="air", prob=254, param2=0},
		{name="air", prob=254, param2=0},
		{name="air", prob=254, param2=0},
		{name="air", prob=254, param2=0},
		{name="air", prob=254, param2=0},
		{name="air", prob=254, param2=0},
		{name="air", prob=254, param2=0},
		{name="air", prob=254, param2=0},
		{name="air", prob=254, param2=0},
		{name="air", prob=254, param2=0},
		{name="air", prob=254, param2=0},
		{name="air", prob=254, param2=0},
		{name="air", prob=254, param2=0},
		{name="air", prob=254, param2=0},
		{name="air", prob=254, param2=0},
		{name="air", prob=254, param2=0},
		{name="air", prob=254, param2=0},
		{name="air", prob=254, param2=0},
		{name="air", prob=254, param2=0},
		{name="air", prob=254, param2=0},
		{name="air", prob=254, param2=0},
		{name="air", prob=254, param2=0},
		{name="air", prob=254, param2=0},
		{name="air", prob=254, param2=0},
		{name="air", prob=254, param2=0},
		{name="air", prob=254, param2=0},
		{name="air", prob=254, param2=0},
		{name="air", prob=254, param2=0},
		{name="air", prob=254, param2=0},
		{name="air", prob=0, param2=0},
		{name="air", prob=0, param2=0},
		{name="everness:crystal_forest_deep_ocean_sandstone_block", prob=254, param2=0},
		{name="air", prob=254, param2=0},
		{name="air", prob=254, param2=0},
		{name="air", prob=254, param2=0},
		{name="air", prob=254, param2=0},
		{name="air", prob=254, param2=0},
		{name="air", prob=254, param2=0},
		{name="air", prob=254, param2=0},
		{name="everness:crystal_forest_deep_ocean_sandstone_block", prob=254, param2=0},
		{name="air", prob=0, param2=0},
		{name="air", prob=0, param2=0},
		{name="air", prob=0, param2=0},
		{name="air", prob=0, param2=0},
		{name="stairs:slab_crystal_forest_deep_ocean_sandstone_brick", prob=126, param2=1},
		{name="air", prob=0, param2=0},
		{name="air", prob=0, param2=0},
		{name="air", prob=0, param2=0},
		{name="air", prob=0, param2=0},
		{name="air", prob=0, param2=0},
		{name="air", prob=0, param2=0},
		{name="air", prob=0, param2=0},
		{name="stairs:slab_crystal_forest_deep_ocean_sandstone_brick", prob=126, param2=3},
		{name="air", prob=0, param2=0},
		{name="air", prob=0, param2=0},
		{name="air", prob=0, param2=0},
		{name="air", prob=0, param2=0},
		{name="air", prob=0, param2=0},
		{name="air", prob=0, param2=0},
		{name="air", prob=0, param2=0},
		{name="air", prob=0, param2=0},
		{name="air", prob=0, param2=0},
		{name="air", prob=0, param2=0},
		{name="air", prob=0, param2=0},
		{name="air", prob=0, param2=0},
		{name="air", prob=0, param2=0},
		{name="air", prob=0, param2=0},
		{name="air", prob=0, param2=0},
		{name="air", prob=0, param2=0},
		{name="everness:crystal_sandstone_brick", prob=254, param2=0},
		{name="everness:crystal_sandstone_chiseled", prob=254, param2=0},
		{name="everness:crystal_mossy_cobble", prob=254, param2=0},
		{name="everness:crystal_sandstone_brick", prob=254, param2=0},
		{name="everness:crystal_mossy_cobble", prob=254, param2=0},
		{name="everness:crystal_sandstone_brick", prob=254, param2=0},
		{name="everness:crystal_stone_brick", prob=254, param2=0},
		{name="everness:crystal_stone_brick", prob=254, param2=0},
		{name="everness:crystal_sandstone_brick", prob=254, param2=0},
		{name="everness:crystal_sandstone_brick", prob=254, param2=0},
		{name="everness:crystal_sandstone_chiseled", prob=254, param2=0},
		{name="air", prob=0, param2=0},
		{name="air", prob=0, param2=0},
		{name="everness:crystal_cobble", prob=254, param2=0},
		{name="everness:crystal_forest_deep_ocean_sand", prob=254, param2=0},
		{name="everness:crystal_forest_deep_ocean_sand", prob=254, param2=0},
		{name="everness:crystal_sand", prob=254, param2=0},
		{name="everness:crystal_forest_deep_ocean_sand", prob=254, param2=0},
		{name="everness:crystal_forest_deep_ocean_sand", prob=254, param2=0},
		{name="everness:crystal_sand", prob=254, param2=0},
		{name="everness:crystal_sand", prob=254, param2=0},
		{name="everness:crystal_sand", prob=254, param2=0},
		{name="everness:crystal_forest_deep_ocean_sand", prob=254, param2=0},
		{name="everness:crystal_sandstone_chiseled", prob=254, param2=0},
		{name="air", prob=0, param2=0},
		{name="air", prob=0, param2=0},
		{name="everness:crystal_sandstone_brick", prob=254, param2=0},
		{name="air", prob=254, param2=0},
		{name="everness:crystal_forest_deep_ocean_sandstone_brick", prob=254, param2=0},
		{name="air", prob=254, param2=0},
		{name="air", prob=254, param2=0},
		{name="everness:chest", prob=254, param2=1},
		{name="air", prob=254, param2=0},
		{name="air", prob=254, param2=0},
		{name="everness:crystal_forest_deep_ocean_sandstone_brick", prob=254, param2=0},
		{name="air", prob=254, param2=0},
		{name="everness:crystal_sandstone_brick", prob=254, param2=0},
		{name="air", prob=0, param2=0},
		{name="air", prob=0, param2=0},
		{name="everness:crystal_sandstone_chiseled", prob=254, param2=0},
		{name="air", prob=254, param2=0},
		{name="air", prob=254, param2=0},
		{name="air", prob=254, param2=0},
		{name="air", prob=254, param2=0},
		{name="air", prob=254, param2=0},
		{name="air", prob=254, param2=0},
		{name="air", prob=254, param2=0},
		{name="air", prob=254, param2=0},
		{name="air", prob=254, param2=0},
		{name="everness:crystal_sandstone_brick", prob=254, param2=0},
		{name="air", prob=0, param2=0},
		{name="air", prob=0, param2=0},
		{name="everness:crystal_sandstone_brick", prob=254, param2=0},
		{name="air", prob=254, param2=0},
		{name="air", prob=254, param2=0},
		{name="air", prob=254, param2=0},
		{name="air", prob=254, param2=0},
		{name="air", prob=254, param2=0},
		{name="air", prob=254, param2=0},
		{name="air", prob=254, param2=0},
		{name="air", prob=254, param2=0},
		{name="air", prob=254, param2=0},
		{name="everness:crystal_stone_brick", prob=254, param2=0},
		{name="air", prob=0, param2=0},
		{name="air", prob=0, param2=0},
		{name="everness:pyrite_lantern", prob=254, param2=0},
		{name="air", prob=254, param2=0},
		{name="air", prob=254, param2=0},
		{name="air", prob=254, param2=0},
		{name="air", prob=254, param2=0},
		{name="air", prob=254, param2=0},
		{name="air", prob=254, param2=0},
		{name="air", prob=254, param2=0},
		{name="air", prob=254, param2=0},
		{name="air", prob=254, param2=0},
		{name="everness:crystal_mossy_cobble", prob=254, param2=0},
		{name="air", prob=0, param2=0},
		{name="air", prob=0, param2=0},
		{name="everness:crystal_cobble", prob=254, param2=0},
		{name="air", prob=254, param2=0},
		{name="air", prob=254, param2=0},
		{name="air", prob=254, param2=0},
		{name="air", prob=254, param2=0},
		{name="air", prob=254, param2=0},
		{name="air", prob=254, param2=0},
		{name="air", prob=254, param2=0},
		{name="air", prob=254, param2=0},
		{name="air", prob=254, param2=0},
		{name="everness:pyrite_lantern", prob=254, param2=0},
		{name="air", prob=0, param2=0},
		{name="everness:crystal_cobble", prob=254, param2=0},
		{name="everness:crystal_mossy_cobble", prob=254, param2=0},
		{name="air", prob=254, param2=0},
		{name="air", prob=254, param2=0},
		{name="air", prob=254, param2=0},
		{name="air", prob=254, param2=0},
		{name="air", prob=254, param2=0},
		{name="air", prob=254, param2=0},
		{name="air", prob=254, param2=0},
		{name="air", prob=254, param2=0},
		{name="air", prob=254, param2=0},
		{name="everness:crystal_sandstone_chiseled", prob=254, param2=0},
		{name="everness:crystal_cobble", prob=254, param2=0},
		{name="everness:crystal_forest_deep_ocean_sand", prob=84, param2=0},
		{name="air", prob=254, param2=0},
		{name="air", prob=254, param2=0},
		{name="air", prob=254, param2=0},
		{name="air", prob=254, param2=0},
		{name="air", prob=254, param2=0},
		{name="air", prob=254, param2=0},
		{name="air", prob=254, param2=0},
		{name="air", prob=254, param2=0},
		{name="air", prob=254, param2=0},
		{name="air", prob=254, param2=0},
		{name="air", prob=254, param2=0},
		{name="everness:crystal_forest_deep_ocean_sand", prob=84, param2=0},
		{name="air", prob=0, param2=0},
		{name="everness:crystal_forest_deep_ocean_sandstone_block", prob=254, param2=0},
		{name="everness:crystal_forest_deep_ocean_sandstone_block", prob=254, param2=0},
		{name="stairs:slab_crystal_forest_deep_ocean_sandstone_block", prob=254, param2=3},
		{name="stairs:slab_crystal_forest_deep_ocean_sandstone_brick", prob=84, param2=3},
		{name="air", prob=254, param2=0},
		{name="air", prob=254, param2=0},
		{name="air", prob=254, param2=0},
		{name="stairs:slab_crystal_forest_deep_ocean_sandstone_brick", prob=84, param2=1},
		{name="stairs:slab_crystal_forest_deep_ocean_sandstone_block", prob=254, param2=1},
		{name="everness:crystal_forest_deep_ocean_sandstone_block", prob=254, param2=0},
		{name="everness:crystal_forest_deep_ocean_sandstone_block", prob=254, param2=0},
		{name="air", prob=0, param2=0},
		{name="air", prob=254, param2=0},
		{name="air", prob=254, param2=0},
		{name="air", prob=254, param2=0},
		{name="air", prob=254, param2=0},
		{name="air", prob=254, param2=0},
		{name="air", prob=254, param2=0},
		{name="air", prob=254, param2=0},
		{name="air", prob=254, param2=0},
		{name="air", prob=254, param2=0},
		{name="air", prob=254, param2=0},
		{name="air", prob=254, param2=0},
		{name="air", prob=254, param2=0},
		{name="air", prob=254, param2=0},
		{name="air", prob=254, param2=0},
		{name="air", prob=254, param2=0},
		{name="air", prob=254, param2=0},
		{name="air", prob=254, param2=0},
		{name="air", prob=254, param2=0},
		{name="air", prob=254, param2=0},
		{name="air", prob=254, param2=0},
		{name="air", prob=254, param2=0},
		{name="air", prob=254, param2=0},
		{name="air", prob=254, param2=0},
		{name="air", prob=254, param2=0},
		{name="air", prob=254, param2=0},
		{name="air", prob=254, param2=0},
		{name="air", prob=254, param2=0},
		{name="air", prob=254, param2=0},
		{name="air", prob=254, param2=0},
		{name="air", prob=254, param2=0},
		{name="air", prob=254, param2=0},
		{name="air", prob=254, param2=0},
		{name="air", prob=254, param2=0},
		{name="air", prob=254, param2=0},
		{name="air", prob=254, param2=0},
		{name="air", prob=254, param2=0},
		{name="air", prob=254, param2=0},
		{name="air", prob=254, param2=0},
		{name="air", prob=254, param2=0},
		{name="air", prob=0, param2=0},
		{name="air", prob=0, param2=0},
		{name="everness:crystal_forest_deep_ocean_sandstone_block", prob=254, param2=0},
		{name="air", prob=254, param2=0},
		{name="air", prob=254, param2=0},
		{name="air", prob=254, param2=0},
		{name="air", prob=254, param2=0},
		{name="air", prob=254, param2=0},
		{name="air", prob=254, param2=0},
		{name="air", prob=254, param2=0},
		{name="everness:crystal_forest_deep_ocean_sandstone_block", prob=254, param2=0},
		{name="air", prob=0, param2=0},
		{name="air", prob=0, param2=0},
		{name="air", prob=0, param2=0},
		{name="air", prob=0, param2=0},
		{name="stairs:stair_crystal_forest_deep_ocean_sandstone_brick", prob=126, param2=1},
		{name="air", prob=0, param2=0},
		{name="air", prob=0, param2=0},
		{name="air", prob=0, param2=0},
		{name="air", prob=0, param2=0},
		{name="air", prob=0, param2=0},
		{name="air", prob=0, param2=0},
		{name="air", prob=0, param2=0},
		{name="stairs:stair_crystal_forest_deep_ocean_sandstone_brick", prob=126, param2=3},
		{name="air", prob=0, param2=0},
		{name="air", prob=0, param2=0},
		{name="air", prob=0, param2=0},
		{name="air", prob=0, param2=0},
		{name="air", prob=0, param2=0},
		{name="air", prob=0, param2=0},
		{name="air", prob=0, param2=0},
		{name="air", prob=0, param2=0},
		{name="air", prob=0, param2=0},
		{name="air", prob=0, param2=0},
		{name="air", prob=0, param2=0},
		{name="air", prob=0, param2=0},
		{name="air", prob=0, param2=0},
		{name="air", prob=0, param2=0},
		{name="air", prob=0, param2=0},
		{name="air", prob=0, param2=0},
		{name="everness:crystal_stone_brick", prob=254, param2=0},
		{name="everness:crystal_stone_brick", prob=254, param2=0},
		{name="everness:crystal_cobble", prob=254, param2=0},
		{name="everness:crystal_mossy_cobble", prob=254, param2=0},
		{name="everness:crystal_stone_brick", prob=254, param2=0},
		{name="everness:crystal_sandstone_chiseled", prob=254, param2=0},
		{name="everness:crystal_stone_brick", prob=254, param2=0},
		{name="everness:crystal_sandstone_brick", prob=254, param2=0},
		{name="everness:crystal_mossy_cobble", prob=254, param2=0},
		{name="everness:crystal_mossy_cobble", prob=254, param2=0},
		{name="everness:crystal_cobble", prob=254, param2=0},
		{name="air", prob=0, param2=0},
		{name="air", prob=0, param2=0},
		{name="everness:crystal_stone_brick", prob=254, param2=0},
		{name="everness:crystal_sand", prob=254, param2=0},
		{name="everness:crystal_forest_deep_ocean_sand", prob=254, param2=0},
		{name="everness:crystal_forest_deep_ocean_sand", prob=254, param2=0},
		{name="everness:crystal_forest_deep_ocean_sand", prob=254, param2=0},
		{name="everness:crystal_forest_deep_ocean_sand", prob=254, param2=0},
		{name="everness:crystal_sand", prob=254, param2=0},
		{name="everness:crystal_forest_deep_ocean_sand", prob=254, param2=0},
		{name="everness:crystal_sand", prob=254, param2=0},
		{name="everness:crystal_forest_deep_ocean_sand", prob=254, param2=0},
		{name="everness:crystal_cobble", prob=254, param2=0},
		{name="air", prob=0, param2=0},
		{name="air", prob=0, param2=0},
		{name="everness:crystal_sandstone_brick", prob=254, param2=0},
		{name="air", prob=254, param2=0},
		{name="everness:crystal_forest_deep_ocean_sandstone_block", prob=254, param2=0},
		{name="air", prob=254, param2=0},
		{name="air", prob=254, param2=0},
		{name="air", prob=254, param2=0},
		{name="air", prob=254, param2=0},
		{name="air", prob=254, param2=0},
		{name="everness:crystal_forest_deep_ocean_sandstone_block", prob=254, param2=0},
		{name="air", prob=254, param2=0},
		{name="everness:crystal_sandstone_chiseled", prob=254, param2=0},
		{name="air", prob=0, param2=0},
		{name="air", prob=0, param2=0},
		{name="everness:crystal_sandstone_brick", prob=254, param2=0},
		{name="air", prob=254, param2=0},
		{name="air", prob=254, param2=0},
		{name="air", prob=254, param2=0},
		{name="air", prob=254, param2=0},
		{name="air", prob=254, param2=0},
		{name="air", prob=254, param2=0},
		{name="air", prob=254, param2=0},
		{name="air", prob=254, param2=0},
		{name="air", prob=254, param2=0},
		{name="everness:crystal_sandstone_chiseled", prob=254, param2=0},
		{name="air", prob=0, param2=0},
		{name="air", prob=0, param2=0},
		{name="everness:crystal_cobble", prob=254, param2=0},
		{name="air", prob=254, param2=0},
		{name="air", prob=254, param2=0},
		{name="air", prob=254, param2=0},
		{name="air", prob=254, param2=0},
		{name="air", prob=254, param2=0},
		{name="air", prob=254, param2=0},
		{name="air", prob=254, param2=0},
		{name="air", prob=254, param2=0},
		{name="air", prob=254, param2=0},
		{name="everness:crystal_sandstone_chiseled", prob=254, param2=0},
		{name="air", prob=0, param2=0},
		{name="air", prob=0, param2=0},
		{name="everness:crystal_mossy_cobble", prob=254, param2=0},
		{name="air", prob=254, param2=0},
		{name="air", prob=254, param2=0},
		{name="air", prob=254, param2=0},
		{name="air", prob=254, param2=0},
		{name="air", prob=254, param2=0},
		{name="air", prob=254, param2=0},
		{name="air", prob=254, param2=0},
		{name="air", prob=254, param2=0},
		{name="air", prob=254, param2=0},
		{name="everness:crystal_stone_brick", prob=254, param2=0},
		{name="air", prob=0, param2=0},
		{name="air", prob=0, param2=0},
		{name="everness:crystal_cobble", prob=254, param2=0},
		{name="air", prob=254, param2=0},
		{name="air", prob=254, param2=0},
		{name="air", prob=254, param2=0},
		{name="air", prob=254, param2=0},
		{name="air", prob=254, param2=0},
		{name="air", prob=254, param2=0},
		{name="air", prob=254, param2=0},
		{name="air", prob=254, param2=0},
		{name="air", prob=254, param2=0},
		{name="everness:crystal_sandstone_chiseled", prob=254, param2=0},
		{name="air", prob=0, param2=0},
		{name="everness:crystal_cobble", prob=254, param2=0},
		{name="everness:crystal_cobble", prob=254, param2=0},
		{name="air", prob=254, param2=0},
		{name="air", prob=254, param2=0},
		{name="air", prob=254, param2=0},
		{name="air", prob=254, param2=0},
		{name="air", prob=254, param2=0},
		{name="air", prob=254, param2=0},
		{name="air", prob=254, param2=0},
		{name="air", prob=254, param2=0},
		{name="air", prob=254, param2=0},
		{name="everness:crystal_cobble", prob=254, param2=0},
		{name="everness:crystal_cobble", prob=254, param2=0},
		{name="everness:crystal_forest_deep_ocean_sand", prob=254, param2=0},
		{name="everness:crystal_stone_brick", prob=254, param2=0},
		{name="air", prob=254, param2=0},
		{name="air", prob=254, param2=0},
		{name="air", prob=254, param2=0},
		{name="air", prob=254, param2=0},
		{name="air", prob=254, param2=0},
		{name="air", prob=254, param2=0},
		{name="air", prob=254, param2=0},
		{name="air", prob=254, param2=0},
		{name="air", prob=254, param2=0},
		{name="everness:crystal_sandstone_brick", prob=254, param2=0},
		{name="everness:crystal_sand", prob=254, param2=0},
		{name="air", prob=0, param2=0},
		{name="everness:crystal_sand", prob=254, param2=0},
		{name="everness:crystal_forest_deep_ocean_sandstone_block", prob=254, param2=0},
		{name="stairs:slab_crystal_forest_deep_ocean_sandstone_block", prob=254, param2=3},
		{name="stairs:slab_crystal_forest_deep_ocean_sandstone_brick", prob=84, param2=3},
		{name="air", prob=254, param2=0},
		{name="air", prob=254, param2=0},
		{name="air", prob=254, param2=0},
		{name="stairs:slab_crystal_forest_deep_ocean_sandstone_brick", prob=84, param2=1},
		{name="stairs:slab_crystal_forest_deep_ocean_sandstone_block", prob=254, param2=1},
		{name="everness:crystal_forest_deep_ocean_sandstone_block", prob=254, param2=0},
		{name="everness:crystal_sand", prob=254, param2=0},
		{name="air", prob=0, param2=0},
		{name="air", prob=254, param2=0},
		{name="air", prob=254, param2=0},
		{name="air", prob=254, param2=0},
		{name="air", prob=254, param2=0},
		{name="air", prob=254, param2=0},
		{name="air", prob=254, param2=0},
		{name="air", prob=254, param2=0},
		{name="air", prob=254, param2=0},
		{name="air", prob=254, param2=0},
		{name="air", prob=254, param2=0},
		{name="air", prob=254, param2=0},
		{name="air", prob=254, param2=0},
		{name="air", prob=254, param2=0},
		{name="air", prob=254, param2=0},
		{name="air", prob=254, param2=0},
		{name="air", prob=254, param2=0},
		{name="air", prob=254, param2=0},
		{name="air", prob=254, param2=0},
		{name="air", prob=254, param2=0},
		{name="air", prob=254, param2=0},
		{name="air", prob=254, param2=0},
		{name="air", prob=254, param2=0},
		{name="air", prob=254, param2=0},
		{name="air", prob=254, param2=0},
		{name="air", prob=254, param2=0},
		{name="air", prob=254, param2=0},
		{name="air", prob=254, param2=0},
		{name="air", prob=254, param2=0},
		{name="air", prob=254, param2=0},
		{name="air", prob=254, param2=0},
		{name="air", prob=254, param2=0},
		{name="air", prob=254, param2=0},
		{name="air", prob=254, param2=0},
		{name="air", prob=254, param2=0},
		{name="air", prob=254, param2=0},
		{name="air", prob=254, param2=0},
		{name="air", prob=254, param2=0},
		{name="air", prob=254, param2=0},
		{name="air", prob=254, param2=0},
		{name="air", prob=0, param2=0},
		{name="air", prob=0, param2=0},
		{name="everness:crystal_forest_deep_ocean_sandstone_block", prob=254, param2=0},
		{name="air", prob=254, param2=0},
		{name="air", prob=254, param2=0},
		{name="air", prob=254, param2=0},
		{name="air", prob=254, param2=0},
		{name="air", prob=254, param2=0},
		{name="air", prob=254, param2=0},
		{name="air", prob=254, param2=0},
		{name="everness:crystal_forest_deep_ocean_sandstone_block", prob=254, param2=0},
		{name="air", prob=0, param2=0},
		{name="air", prob=0, param2=0},
		{name="air", prob=0, param2=0},
		{name="air", prob=0, param2=0},
		{name="stairs:slab_crystal_forest_deep_ocean_sandstone_brick", prob=126, param2=1},
		{name="air", prob=0, param2=0},
		{name="air", prob=0, param2=0},
		{name="air", prob=0, param2=0},
		{name="air", prob=0, param2=0},
		{name="air", prob=0, param2=0},
		{name="air", prob=0, param2=0},
		{name="air", prob=0, param2=0},
		{name="stairs:slab_crystal_forest_deep_ocean_sandstone_brick", prob=126, param2=3},
		{name="air", prob=0, param2=0},
		{name="air", prob=0, param2=0},
		{name="air", prob=0, param2=0},
		{name="air", prob=0, param2=0},
		{name="air", prob=0, param2=0},
		{name="air", prob=0, param2=0},
		{name="air", prob=0, param2=0},
		{name="air", prob=0, param2=0},
		{name="air", prob=0, param2=0},
		{name="air", prob=0, param2=0},
		{name="air", prob=0, param2=0},
		{name="air", prob=0, param2=0},
		{name="air", prob=0, param2=0},
		{name="air", prob=0, param2=0},
		{name="air", prob=0, param2=0},
		{name="air", prob=0, param2=0},
		{name="everness:crystal_mossy_cobble", prob=254, param2=0},
		{name="everness:crystal_cobble", prob=254, param2=0},
		{name="everness:crystal_stone_brick", prob=254, param2=0},
		{name="everness:crystal_stone_brick", prob=254, param2=0},
		{name="everness:crystal_sandstone_chiseled", prob=254, param2=0},
		{name="everness:crystal_sandstone_chiseled", prob=254, param2=0},
		{name="everness:crystal_stone_brick", prob=254, param2=0},
		{name="everness:crystal_sandstone_brick", prob=254, param2=0},
		{name="everness:crystal_sandstone_brick", prob=254, param2=0},
		{name="everness:crystal_stone_brick", prob=254, param2=0},
		{name="everness:crystal_stone_brick", prob=254, param2=0},
		{name="air", prob=0, param2=0},
		{name="air", prob=0, param2=0},
		{name="everness:crystal_sandstone_chiseled", prob=254, param2=0},
		{name="everness:crystal_cobble", prob=254, param2=0},
		{name="everness:crystal_sand", prob=254, param2=0},
		{name="everness:crystal_sand", prob=254, param2=0},
		{name="everness:crystal_forest_deep_ocean_sand", prob=254, param2=0},
		{name="everness:crystal_forest_deep_ocean_sand", prob=254, param2=0},
		{name="everness:crystal_forest_deep_ocean_sand", prob=254, param2=0},
		{name="everness:crystal_forest_deep_ocean_sand", prob=254, param2=0},
		{name="everness:crystal_sand", prob=254, param2=0},
		{name="everness:crystal_sandstone_brick", prob=254, param2=0},
		{name="everness:crystal_stone_brick", prob=254, param2=0},
		{name="air", prob=0, param2=0},
		{name="air", prob=0, param2=0},
		{name="everness:crystal_sandstone_chiseled", prob=254, param2=0},
		{name="everness:crystal_sandstone_chiseled", prob=254, param2=0},
		{name="air", prob=254, param2=0},
		{name="air", prob=254, param2=0},
		{name="air", prob=254, param2=0},
		{name="air", prob=254, param2=0},
		{name="air", prob=254, param2=0},
		{name="air", prob=254, param2=0},
		{name="air", prob=254, param2=0},
		{name="everness:crystal_sandstone_brick", prob=254, param2=0},
		{name="everness:crystal_stone_brick", prob=254, param2=0},
		{name="air", prob=0, param2=0},
		{name="air", prob=0, param2=0},
		{name="everness:crystal_stone_brick", prob=254, param2=0},
		{name="everness:crystal_sandstone_brick", prob=254, param2=0},
		{name="air", prob=254, param2=0},
		{name="air", prob=254, param2=0},
		{name="air", prob=254, param2=0},
		{name="air", prob=254, param2=0},
		{name="air", prob=254, param2=0},
		{name="air", prob=254, param2=0},
		{name="air", prob=254, param2=0},
		{name="everness:crystal_sandstone_brick", prob=254, param2=0},
		{name="everness:crystal_cobble", prob=254, param2=0},
		{name="air", prob=0, param2=0},
		{name="air", prob=0, param2=0},
		{name="everness:crystal_stone_brick", prob=254, param2=0},
		{name="everness:crystal_stone_brick", prob=254, param2=0},
		{name="air", prob=254, param2=0},
		{name="air", prob=254, param2=0},
		{name="air", prob=254, param2=0},
		{name="air", prob=254, param2=0},
		{name="air", prob=254, param2=0},
		{name="air", prob=254, param2=0},
		{name="air", prob=254, param2=0},
		{name="everness:crystal_sandstone_chiseled", prob=254, param2=0},
		{name="everness:crystal_sandstone_chiseled", prob=254, param2=0},
		{name="air", prob=0, param2=0},
		{name="air", prob=0, param2=0},
		{name="everness:crystal_stone_brick", prob=254, param2=0},
		{name="everness:crystal_cobble", prob=254, param2=0},
		{name="air", prob=254, param2=0},
		{name="air", prob=254, param2=0},
		{name="air", prob=254, param2=0},
		{name="air", prob=254, param2=0},
		{name="air", prob=254, param2=0},
		{name="air", prob=254, param2=0},
		{name="air", prob=254, param2=0},
		{name="everness:crystal_cobble", prob=254, param2=0},
		{name="everness:crystal_cobble", prob=254, param2=0},
		{name="air", prob=0, param2=0},
		{name="air", prob=0, param2=0},
		{name="everness:crystal_cobble", prob=254, param2=0},
		{name="everness:crystal_cobble", prob=254, param2=0},
		{name="air", prob=254, param2=0},
		{name="air", prob=254, param2=0},
		{name="air", prob=254, param2=0},
		{name="air", prob=254, param2=0},
		{name="air", prob=254, param2=0},
		{name="air", prob=254, param2=0},
		{name="air", prob=254, param2=0},
		{name="everness:crystal_sandstone_chiseled", prob=254, param2=0},
		{name="everness:crystal_stone_brick", prob=254, param2=0},
		{name="air", prob=0, param2=0},
		{name="everness:crystal_cobble", prob=254, param2=0},
		{name="everness:crystal_mossy_cobble", prob=254, param2=0},
		{name="everness:crystal_cobble", prob=254, param2=0},
		{name="air", prob=254, param2=0},
		{name="air", prob=254, param2=0},
		{name="air", prob=254, param2=0},
		{name="air", prob=254, param2=0},
		{name="air", prob=254, param2=0},
		{name="air", prob=254, param2=0},
		{name="air", prob=254, param2=0},
		{name="everness:crystal_mossy_cobble", prob=254, param2=0},
		{name="everness:crystal_sandstone_brick", prob=254, param2=0},
		{name="everness:crystal_cobble", prob=254, param2=0},
		{name="everness:crystal_sand", prob=254, param2=0},
		{name="everness:crystal_cobble", prob=254, param2=0},
		{name="everness:crystal_sandstone_brick", prob=254, param2=0},
		{name="air", prob=254, param2=0},
		{name="air", prob=254, param2=0},
		{name="air", prob=254, param2=0},
		{name="air", prob=254, param2=0},
		{name="air", prob=254, param2=0},
		{name="air", prob=254, param2=0},
		{name="air", prob=254, param2=0},
		{name="everness:crystal_stone_brick", prob=254, param2=0},
		{name="everness:crystal_mossy_cobble", prob=254, param2=0},
		{name="everness:crystal_sand", prob=254, param2=0},
		{name="air", prob=0, param2=0},
		{name="everness:crystal_forest_deep_ocean_sand", prob=254, param2=0},
		{name="everness:crystal_stone_brick", prob=254, param2=0},
		{name="everness:crystal_forest_deep_ocean_sandstone_block", prob=254, param2=0},
		{name="stairs:slab_crystal_forest_deep_ocean_sandstone_block", prob=254, param2=3},
		{name="stairs:slab_crystal_forest_deep_ocean_sandstone_brick", prob=84, param2=0},
		{name="stairs:slab_crystal_forest_deep_ocean_sandstone_brick", prob=84, param2=0},
		{name="stairs:slab_crystal_forest_deep_ocean_sandstone_brick", prob=84, param2=0},
		{name="stairs:slab_crystal_forest_deep_ocean_sandstone_block", prob=254, param2=0},
		{name="everness:crystal_forest_deep_ocean_sandstone_block", prob=254, param2=0},
		{name="everness:crystal_sandstone_brick", prob=254, param2=0},
		{name="everness:crystal_forest_deep_ocean_sand", prob=254, param2=0},
		{name="air", prob=0, param2=0},
		{name="air", prob=0, param2=0},
		{name="air", prob=0, param2=0},
		{name="everness:crystal_forest_deep_ocean_sandstone_block", prob=254, param2=0},
		{name="air", prob=254, param2=0},
		{name="air", prob=254, param2=0},
		{name="air", prob=254, param2=0},
		{name="air", prob=254, param2=0},
		{name="air", prob=254, param2=0},
		{name="air", prob=254, param2=0},
		{name="air", prob=254, param2=0},
		{name="everness:crystal_forest_deep_ocean_sandstone_block", prob=254, param2=0},
		{name="air", prob=0, param2=0},
		{name="air", prob=0, param2=0},
		{name="air", prob=0, param2=0},
		{name="air", prob=0, param2=0},
		{name="everness:crystal_forest_deep_ocean_sandstone_brick", prob=254, param2=0},
		{name="air", prob=254, param2=0},
		{name="air", prob=254, param2=0},
		{name="air", prob=254, param2=0},
		{name="air", prob=254, param2=0},
		{name="air", prob=254, param2=0},
		{name="air", prob=254, param2=0},
		{name="air", prob=254, param2=0},
		{name="everness:crystal_forest_deep_ocean_sandstone_brick", prob=254, param2=0},
		{name="air", prob=0, param2=0},
		{name="air", prob=0, param2=0},
		{name="air", prob=0, param2=0},
		{name="air", prob=0, param2=0},
		{name="everness:crystal_forest_deep_ocean_sandstone_brick", prob=254, param2=0},
		{name="air", prob=254, param2=0},
		{name="air", prob=254, param2=0},
		{name="air", prob=254, param2=0},
		{name="air", prob=254, param2=0},
		{name="air", prob=254, param2=0},
		{name="air", prob=254, param2=0},
		{name="air", prob=254, param2=0},
		{name="everness:crystal_forest_deep_ocean_sandstone_brick", prob=254, param2=0},
		{name="air", prob=0, param2=0},
		{name="air", prob=0, param2=0},
		{name="air", prob=0, param2=0},
		{name="air", prob=0, param2=0},
		{name="everness:crystal_forest_deep_ocean_sandstone_block", prob=254, param2=0},
		{name="air", prob=254, param2=0},
		{name="air", prob=254, param2=0},
		{name="air", prob=254, param2=0},
		{name="air", prob=254, param2=0},
		{name="air", prob=254, param2=0},
		{name="air", prob=254, param2=0},
		{name="air", prob=254, param2=0},
		{name="everness:crystal_forest_deep_ocean_sandstone_block", prob=254, param2=0},
		{name="air", prob=0, param2=0},
		{name="air", prob=0, param2=0},
		{name="air", prob=0, param2=0},
		{name="air", prob=0, param2=0},
		{name="air", prob=0, param2=0},
		{name="air", prob=0, param2=0},
		{name="air", prob=0, param2=0},
		{name="air", prob=0, param2=0},
		{name="air", prob=0, param2=0},
		{name="air", prob=0, param2=0},
		{name="air", prob=0, param2=0},
		{name="air", prob=0, param2=0},
		{name="air", prob=0, param2=0},
		{name="air", prob=0, param2=0},
		{name="air", prob=0, param2=0},
		{name="air", prob=0, param2=0},
		{name="air", prob=0, param2=0},
		{name="air", prob=0, param2=0},
		{name="air", prob=0, param2=0},
		{name="air", prob=0, param2=0},
		{name="air", prob=0, param2=0},
		{name="air", prob=0, param2=0},
		{name="air", prob=0, param2=0},
		{name="air", prob=0, param2=0},
		{name="air", prob=0, param2=0},
		{name="air", prob=0, param2=0},
		{name="air", prob=0, param2=0},
		{name="air", prob=0, param2=0},
		{name="air", prob=0, param2=0},
		{name="air", prob=0, param2=0},
		{name="everness:crystal_sandstone_brick", prob=254, param2=0},
		{name="everness:crystal_sandstone_brick", prob=254, param2=0},
		{name="everness:crystal_sandstone_brick", prob=254, param2=0},
		{name="everness:crystal_mossy_cobble", prob=254, param2=0},
		{name="everness:crystal_cobble", prob=254, param2=0},
		{name="everness:crystal_stone_brick", prob=254, param2=0},
		{name="everness:crystal_stone_brick", prob=254, param2=0},
		{name="everness:crystal_mossy_cobble", prob=254, param2=0},
		{name="everness:crystal_stone_brick", prob=254, param2=0},
		{name="air", prob=0, param2=0},
		{name="air", prob=0, param2=0},
		{name="air", prob=0, param2=0},
		{name="air", prob=0, param2=0},
		{name="everness:crystal_stone_brick", prob=254, param2=0},
		{name="everness:crystal_sand", prob=254, param2=0},
		{name="everness:crystal_forest_deep_ocean_sand", prob=254, param2=0},
		{name="everness:crystal_forest_deep_ocean_sand", prob=254, param2=0},
		{name="everness:crystal_sand", prob=254, param2=0},
		{name="everness:crystal_sand", prob=254, param2=0},
		{name="everness:crystal_forest_deep_ocean_sand", prob=254, param2=0},
		{name="everness:crystal_forest_deep_ocean_sand", prob=254, param2=0},
		{name="everness:crystal_mossy_cobble", prob=254, param2=0},
		{name="air", prob=0, param2=0},
		{name="air", prob=0, param2=0},
		{name="air", prob=0, param2=0},
		{name="air", prob=0, param2=0},
		{name="everness:crystal_cobble", prob=254, param2=0},
		{name="air", prob=254, param2=0},
		{name="air", prob=254, param2=0},
		{name="everness:crystal_forest_deep_ocean_sandstone_brick", prob=254, param2=0},
		{name="everness:crystal_forest_deep_ocean_sandstone_block", prob=254, param2=0},
		{name="everness:crystal_forest_deep_ocean_sandstone_brick", prob=254, param2=0},
		{name="air", prob=254, param2=0},
		{name="air", prob=254, param2=0},
		{name="everness:crystal_cobble", prob=254, param2=0},
		{name="air", prob=0, param2=0},
		{name="air", prob=0, param2=0},
		{name="air", prob=0, param2=0},
		{name="air", prob=0, param2=0},
		{name="everness:crystal_mossy_cobble", prob=254, param2=0},
		{name="air", prob=254, param2=0},
		{name="air", prob=254, param2=0},
		{name="air", prob=254, param2=0},
		{name="air", prob=254, param2=0},
		{name="air", prob=254, param2=0},
		{name="air", prob=254, param2=0},
		{name="air", prob=254, param2=0},
		{name="everness:crystal_stone_brick", prob=254, param2=0},
		{name="air", prob=0, param2=0},
		{name="air", prob=0, param2=0},
		{name="air", prob=0, param2=0},
		{name="air", prob=0, param2=0},
		{name="everness:crystal_mossy_cobble", prob=254, param2=0},
		{name="air", prob=254, param2=0},
		{name="air", prob=254, param2=0},
		{name="air", prob=254, param2=0},
		{name="air", prob=254, param2=0},
		{name="air", prob=254, param2=0},
		{name="air", prob=254, param2=0},
		{name="air", prob=254, param2=0},
		{name="everness:crystal_mossy_cobble", prob=254, param2=0},
		{name="air", prob=0, param2=0},
		{name="air", prob=0, param2=0},
		{name="air", prob=0, param2=0},
		{name="air", prob=0, param2=0},
		{name="everness:crystal_stone_brick", prob=254, param2=0},
		{name="air", prob=254, param2=0},
		{name="air", prob=254, param2=0},
		{name="air", prob=254, param2=0},
		{name="air", prob=254, param2=0},
		{name="air", prob=254, param2=0},
		{name="air", prob=254, param2=0},
		{name="air", prob=254, param2=0},
		{name="everness:crystal_sandstone_brick", prob=254, param2=0},
		{name="air", prob=0, param2=0},
		{name="air", prob=0, param2=0},
		{name="air", prob=0, param2=0},
		{name="air", prob=0, param2=0},
		{name="everness:crystal_mossy_cobble", prob=254, param2=0},
		{name="air", prob=254, param2=0},
		{name="air", prob=254, param2=0},
		{name="air", prob=254, param2=0},
		{name="air", prob=254, param2=0},
		{name="air", prob=254, param2=0},
		{name="air", prob=254, param2=0},
		{name="air", prob=254, param2=0},
		{name="everness:crystal_cobble", prob=254, param2=0},
		{name="air", prob=0, param2=0},
		{name="air", prob=0, param2=0},
		{name="air", prob=0, param2=0},
		{name="everness:crystal_cobble", prob=254, param2=0},
		{name="everness:crystal_stone_brick", prob=254, param2=0},
		{name="air", prob=254, param2=0},
		{name="air", prob=254, param2=0},
		{name="air", prob=254, param2=0},
		{name="air", prob=254, param2=0},
		{name="air", prob=254, param2=0},
		{name="air", prob=254, param2=0},
		{name="air", prob=254, param2=0},
		{name="everness:crystal_sandstone_chiseled", prob=254, param2=0},
		{name="everness:crystal_cobble", prob=254, param2=0},
		{name="air", prob=0, param2=0},
		{name="air", prob=0, param2=0},
		{name="everness:crystal_forest_deep_ocean_sand", prob=254, param2=0},
		{name="everness:crystal_stone_brick", prob=254, param2=0},
		{name="air", prob=254, param2=0},
		{name="air", prob=254, param2=0},
		{name="air", prob=254, param2=0},
		{name="air", prob=254, param2=0},
		{name="air", prob=254, param2=0},
		{name="air", prob=254, param2=0},
		{name="air", prob=254, param2=0},
		{name="everness:crystal_mossy_cobble", prob=254, param2=0},
		{name="everness:crystal_forest_deep_ocean_sand", prob=254, param2=0},
		{name="air", prob=0, param2=0},
		{name="air", prob=0, param2=0},
		{name="air", prob=0, param2=0},
		{name="everness:crystal_sand", prob=254, param2=0},
		{name="everness:crystal_forest_deep_ocean_sandstone_block", prob=254, param2=0},
		{name="everness:crystal_forest_deep_ocean_sandstone_block", prob=254, param2=0},
		{name="stairs:slab_crystal_forest_deep_ocean_sandstone_block", prob=254, param2=0},
		{name="stairs:slab_crystal_forest_deep_ocean_sandstone_block", prob=254, param2=0},
		{name="stairs:slab_crystal_forest_deep_ocean_sandstone_block", prob=254, param2=0},
		{name="everness:crystal_forest_deep_ocean_sandstone_block", prob=254, param2=0},
		{name="everness:crystal_forest_deep_ocean_sandstone_block", prob=254, param2=0},
		{name="everness:crystal_forest_deep_ocean_sand", prob=254, param2=0},
		{name="air", prob=0, param2=0},
		{name="air", prob=0, param2=0},
		{name="air", prob=0, param2=0},
		{name="air", prob=0, param2=0},
		{name="air", prob=0, param2=0},
		{name="air", prob=254, param2=0},
		{name="air", prob=254, param2=0},
		{name="air", prob=254, param2=0},
		{name="air", prob=254, param2=0},
		{name="air", prob=254, param2=0},
		{name="air", prob=254, param2=0},
		{name="air", prob=254, param2=0},
		{name="air", prob=0, param2=0},
		{name="air", prob=0, param2=0},
		{name="air", prob=0, param2=0},
		{name="air", prob=0, param2=0},
		{name="air", prob=0, param2=0},
		{name="air", prob=0, param2=0},
		{name="air", prob=254, param2=0},
		{name="air", prob=254, param2=0},
		{name="air", prob=254, param2=0},
		{name="air", prob=254, param2=0},
		{name="air", prob=254, param2=0},
		{name="air", prob=254, param2=0},
		{name="air", prob=254, param2=0},
		{name="air", prob=0, param2=0},
		{name="air", prob=0, param2=0},
		{name="air", prob=0, param2=0},
		{name="air", prob=0, param2=0},
		{name="air", prob=0, param2=0},
		{name="air", prob=0, param2=0},
		{name="air", prob=254, param2=0},
		{name="air", prob=254, param2=0},
		{name="air", prob=254, param2=0},
		{name="air", prob=254, param2=0},
		{name="air", prob=254, param2=0},
		{name="air", prob=254, param2=0},
		{name="air", prob=254, param2=0},
		{name="air", prob=0, param2=0},
		{name="air", prob=0, param2=0},
		{name="air", prob=0, param2=0},
		{name="air", prob=0, param2=0},
		{name="air", prob=0, param2=0},
		{name="stairs:stair_crystal_forest_deep_ocean_sandstone_block", prob=126, param2=22},
		{name="air", prob=254, param2=0},
		{name="air", prob=254, param2=0},
		{name="air", prob=254, param2=0},
		{name="air", prob=254, param2=0},
		{name="air", prob=254, param2=0},
		{name="air", prob=254, param2=0},
		{name="air", prob=254, param2=0},
		{name="stairs:stair_crystal_forest_deep_ocean_sandstone_block", prob=126, param2=22},
		{name="air", prob=0, param2=0},
		{name="air", prob=0, param2=0},
		{name="air", prob=0, param2=0},
		{name="air", prob=0, param2=0},
		{name="air", prob=0, param2=0},
		{name="air", prob=0, param2=0},
		{name="air", prob=0, param2=0},
		{name="air", prob=0, param2=0},
		{name="air", prob=0, param2=0},
		{name="air", prob=0, param2=0},
		{name="air", prob=0, param2=0},
		{name="air", prob=0, param2=0},
		{name="air", prob=0, param2=0},
		{name="air", prob=0, param2=0},
		{name="air", prob=0, param2=0},
		{name="air", prob=0, param2=0},
		{name="air", prob=0, param2=0},
		{name="air", prob=0, param2=0},
		{name="air", prob=0, param2=0},
		{name="air", prob=0, param2=0},
		{name="air", prob=0, param2=0},
		{name="air", prob=0, param2=0},
		{name="air", prob=0, param2=0},
		{name="air", prob=0, param2=0},
		{name="air", prob=0, param2=0},
		{name="air", prob=0, param2=0},
		{name="air", prob=0, param2=0},
		{name="air", prob=0, param2=0},
		{name="air", prob=0, param2=0},
		{name="air", prob=0, param2=0},
		{name="air", prob=0, param2=0},
		{name="everness:crystal_stone_brick", prob=254, param2=0},
		{name="everness:crystal_stone_brick", prob=254, param2=0},
		{name="everness:crystal_stone_brick", prob=254, param2=0},
		{name="everness:crystal_stone_brick", prob=254, param2=0},
		{name="everness:crystal_mossy_cobble", prob=254, param2=0},
		{name="everness:crystal_stone_brick", prob=254, param2=0},
		{name="everness:crystal_stone_brick", prob=254, param2=0},
		{name="air", prob=0, param2=0},
		{name="air", prob=0, param2=0},
		{name="air", prob=0, param2=0},
		{name="air", prob=0, param2=0},
		{name="air", prob=0, param2=0},
		{name="air", prob=0, param2=0},
		{name="everness:crystal_mossy_cobble", prob=254, param2=0},
		{name="everness:crystal_mossy_cobble", prob=254, param2=0},
		{name="everness:crystal_sand", prob=254, param2=0},
		{name="everness:crystal_forest_deep_ocean_sand", prob=254, param2=0},
		{name="everness:crystal_forest_deep_ocean_sand", prob=254, param2=0},
		{name="everness:crystal_mossy_cobble", prob=254, param2=0},
		{name="everness:crystal_cobble", prob=254, param2=0},
		{name="air", prob=0, param2=0},
		{name="air", prob=0, param2=0},
		{name="air", prob=0, param2=0},
		{name="air", prob=0, param2=0},
		{name="air", prob=0, param2=0},
		{name="air", prob=0, param2=0},
		{name="everness:crystal_sandstone_chiseled", prob=254, param2=0},
		{name="everness:crystal_stone_brick", prob=254, param2=0},
		{name="air", prob=254, param2=0},
		{name="air", prob=254, param2=0},
		{name="air", prob=254, param2=0},
		{name="everness:crystal_cobble", prob=254, param2=0},
		{name="everness:crystal_mossy_cobble", prob=254, param2=0},
		{name="air", prob=0, param2=0},
		{name="air", prob=0, param2=0},
		{name="air", prob=0, param2=0},
		{name="air", prob=0, param2=0},
		{name="air", prob=0, param2=0},
		{name="air", prob=0, param2=0},
		{name="everness:crystal_cobble", prob=254, param2=0},
		{name="everness:crystal_mossy_cobble", prob=254, param2=0},
		{name="air", prob=254, param2=0},
		{name="air", prob=254, param2=0},
		{name="air", prob=254, param2=0},
		{name="everness:crystal_sandstone_brick", prob=254, param2=0},
		{name="everness:crystal_cobble", prob=254, param2=0},
		{name="air", prob=0, param2=0},
		{name="air", prob=0, param2=0},
		{name="air", prob=0, param2=0},
		{name="air", prob=0, param2=0},
		{name="air", prob=0, param2=0},
		{name="air", prob=0, param2=0},
		{name="everness:crystal_cobble", prob=254, param2=0},
		{name="everness:crystal_cobble", prob=254, param2=0},
		{name="air", prob=254, param2=0},
		{name="air", prob=254, param2=0},
		{name="air", prob=254, param2=0},
		{name="everness:crystal_sandstone_brick", prob=254, param2=0},
		{name="everness:crystal_sandstone_chiseled", prob=254, param2=0},
		{name="air", prob=0, param2=0},
		{name="air", prob=0, param2=0},
		{name="air", prob=0, param2=0},
		{name="air", prob=0, param2=0},
		{name="air", prob=0, param2=0},
		{name="air", prob=0, param2=0},
		{name="everness:crystal_stone_brick", prob=254, param2=0},
		{name="everness:crystal_sandstone_brick", prob=254, param2=0},
		{name="air", prob=254, param2=0},
		{name="air", prob=254, param2=0},
		{name="air", prob=254, param2=0},
		{name="everness:crystal_stone_brick", prob=254, param2=0},
		{name="everness:crystal_mossy_cobble", prob=254, param2=0},
		{name="air", prob=0, param2=0},
		{name="air", prob=0, param2=0},
		{name="air", prob=0, param2=0},
		{name="air", prob=0, param2=0},
		{name="air", prob=0, param2=0},
		{name="air", prob=0, param2=0},
		{name="everness:crystal_sandstone_brick", prob=254, param2=0},
		{name="everness:pyrite_lantern", prob=254, param2=0},
		{name="air", prob=254, param2=0},
		{name="air", prob=254, param2=0},
		{name="air", prob=254, param2=0},
		{name="everness:pyrite_lantern", prob=254, param2=0},
		{name="everness:crystal_sandstone_chiseled", prob=254, param2=0},
		{name="air", prob=0, param2=0},
		{name="air", prob=0, param2=0},
		{name="air", prob=0, param2=0},
		{name="air", prob=0, param2=0},
		{name="air", prob=0, param2=0},
		{name="everness:crystal_cobble", prob=254, param2=0},
		{name="everness:crystal_sandstone_chiseled", prob=254, param2=0},
		{name="everness:crystal_stone_brick", prob=254, param2=0},
		{name="air", prob=254, param2=0},
		{name="air", prob=254, param2=0},
		{name="air", prob=254, param2=0},
		{name="everness:crystal_stone_brick", prob=254, param2=0},
		{name="everness:crystal_sandstone_chiseled", prob=254, param2=0},
		{name="everness:crystal_cobble", prob=254, param2=0},
		{name="air", prob=0, param2=0},
		{name="air", prob=0, param2=0},
		{name="air", prob=0, param2=0},
		{name="air", prob=0, param2=0},
		{name="everness:crystal_forest_deep_ocean_sand", prob=254, param2=0},
		{name="everness:crystal_stone_brick", prob=254, param2=0},
		{name="everness:crystal_cobble", prob=254, param2=0},
		{name="air", prob=254, param2=0},
		{name="air", prob=254, param2=0},
		{name="air", prob=254, param2=0},
		{name="everness:crystal_stone_brick", prob=254, param2=0},
		{name="everness:crystal_stone_brick", prob=254, param2=0},
		{name="everness:crystal_forest_deep_ocean_sand", prob=254, param2=0},
		{name="air", prob=0, param2=0},
		{name="air", prob=0, param2=0},
		{name="air", prob=0, param2=0},
		{name="air", prob=0, param2=0},
		{name="air", prob=0, param2=0},
		{name="everness:crystal_forest_deep_ocean_sand", prob=254, param2=0},
		{name="everness:crystal_stone_brick", prob=254, param2=0},
		{name="everness:crystal_forest_deep_ocean_sandstone_block", prob=254, param2=0},
		{name="everness:crystal_forest_deep_ocean_sandstone_block", prob=254, param2=0},
		{name="everness:crystal_forest_deep_ocean_sandstone_block", prob=254, param2=0},
		{name="everness:crystal_sandstone_chiseled", prob=254, param2=0},
		{name="everness:crystal_sand", prob=254, param2=0},
		{name="air", prob=0, param2=0},
		{name="air", prob=0, param2=0},
		{name="air", prob=0, param2=0},
		{name="air", prob=0, param2=0},
		{name="air", prob=0, param2=0},
		{name="air", prob=0, param2=0},
		{name="air", prob=0, param2=0},
		{name="everness:crystal_forest_deep_ocean_sandstone_block", prob=254, param2=0},
		{name="air", prob=254, param2=0},
		{name="air", prob=254, param2=0},
		{name="air", prob=254, param2=0},
		{name="everness:crystal_forest_deep_ocean_sandstone_block", prob=254, param2=0},
		{name="air", prob=0, param2=0},
		{name="air", prob=0, param2=0},
		{name="air", prob=0, param2=0},
		{name="air", prob=0, param2=0},
		{name="air", prob=0, param2=0},
		{name="air", prob=0, param2=0},
		{name="air", prob=0, param2=0},
		{name="air", prob=0, param2=0},
		{name="everness:crystal_forest_deep_ocean_sandstone_brick", prob=254, param2=0},
		{name="air", prob=254, param2=0},
		{name="air", prob=254, param2=0},
		{name="air", prob=254, param2=0},
		{name="everness:crystal_forest_deep_ocean_sandstone_brick", prob=254, param2=0},
		{name="air", prob=0, param2=0},
		{name="air", prob=0, param2=0},
		{name="air", prob=0, param2=0},
		{name="air", prob=0, param2=0},
		{name="air", prob=0, param2=0},
		{name="air", prob=0, param2=0},
		{name="air", prob=0, param2=0},
		{name="air", prob=0, param2=0},
		{name="everness:crystal_forest_deep_ocean_sandstone_brick", prob=254, param2=0},
		{name="air", prob=254, param2=0},
		{name="air", prob=254, param2=0},
		{name="air", prob=254, param2=0},
		{name="everness:crystal_forest_deep_ocean_sandstone_brick", prob=254, param2=0},
		{name="air", prob=0, param2=0},
		{name="air", prob=0, param2=0},
		{name="air", prob=0, param2=0},
		{name="air", prob=0, param2=0},
		{name="air", prob=0, param2=0},
		{name="air", prob=0, param2=0},
		{name="air", prob=0, param2=0},
		{name="air", prob=0, param2=0},
		{name="everness:crystal_forest_deep_ocean_sandstone_brick", prob=254, param2=0},
		{name="air", prob=254, param2=0},
		{name="air", prob=254, param2=0},
		{name="air", prob=254, param2=0},
		{name="everness:crystal_forest_deep_ocean_sandstone_brick", prob=254, param2=0},
		{name="air", prob=0, param2=0},
		{name="air", prob=0, param2=0},
		{name="air", prob=0, param2=0},
		{name="air", prob=0, param2=0},
		{name="air", prob=0, param2=0},
		{name="air", prob=0, param2=0},
		{name="air", prob=0, param2=0},
		{name="stairs:stair_crystal_forest_deep_ocean_sandstone_block", prob=126, param2=23},
		{name="everness:crystal_forest_deep_ocean_sandstone_block", prob=254, param2=0},
		{name="everness:crystal_forest_deep_ocean_sandstone_block", prob=254, param2=0},
		{name="everness:crystal_forest_deep_ocean_sandstone_block", prob=254, param2=0},
		{name="everness:crystal_forest_deep_ocean_sandstone_block", prob=254, param2=0},
		{name="everness:crystal_forest_deep_ocean_sandstone_block", prob=254, param2=0},
		{name="stairs:stair_crystal_forest_deep_ocean_sandstone_block", prob=126, param2=21},
		{name="air", prob=0, param2=0},
		{name="air", prob=0, param2=0},
		{name="air", prob=0, param2=0},
		{name="air", prob=0, param2=0},
		{name="air", prob=0, param2=0},
		{name="air", prob=0, param2=0},
		{name="air", prob=0, param2=0},
		{name="air", prob=0, param2=0},
		{name="stairs:slab_crystal_forest_deep_ocean_sandstone_brick", prob=126, param2=2},
		{name="stairs:stair_crystal_forest_deep_ocean_sandstone_brick", prob=126, param2=2},
		{name="stairs:slab_crystal_forest_deep_ocean_sandstone_brick", prob=126, param2=2},
		{name="air", prob=0, param2=0},
		{name="air", prob=0, param2=0},
