schematic = {
	size = {x=20, y=19, z=19},
	yslice_prob = {
		{ypos=0, prob=254},
		{ypos=1, prob=254},
		{ypos=2, prob=254},
		{ypos=3, prob=254},
		{ypos=4, prob=254},
		{ypos=5, prob=254},
		{ypos=6, prob=254},
		{ypos=7, prob=254},
		{ypos=8, prob=254},
		{ypos=9, prob=254},
		{ypos=10, prob=254},
		{ypos=11, prob=254},
		{ypos=12, prob=254},
		{ypos=13, prob=254},
		{ypos=14, prob=254},
		{ypos=15, prob=254},
		{ypos=16, prob=254},
		{ypos=17, prob=254},
		{ypos=18, prob=254},
	},
	data = {
		{name="air", prob=0, param2=0},
		{name="air", prob=0, param2=0},
		{name="air", prob=0, param2=0},
		{name="air", prob=0, param2=0},
		{name="air", prob=0, param2=0},
		{name="air", prob=0, param2=0},
		{name="air", prob=0, param2=0},
		{name="air", prob=0, param2=0},
		{name="air", prob=0, param2=0},
		{name="air", prob=0, param2=0},
		{name="air", prob=0, param2=0},
		{name="air", prob=0, param2=0},
		{name="air", prob=0, param2=0},
		{name="air", prob=0, param2=0},
		{name="air", prob=0, param2=0},
		{name="air", prob=0, param2=0},
		{name="air", prob=0, param2=0},
		{name="air", prob=0, param2=0},
		{name="air", prob=0, param2=0},
		{name="air", prob=0, param2=0},
		{name="air", prob=0, param2=0},
		{name="air", prob=0, param2=0},
		{name="air", prob=0, param2=0},
		{name="air", prob=0, param2=0},
		{name="air", prob=0, param2=0},
		{name="air", prob=0, param2=0},
		{name="air", prob=0, param2=0},
		{name="air", prob=0, param2=0},
		{name="air", prob=0, param2=0},
		{name="air", prob=0, param2=0},
		{name="air", prob=0, param2=0},
		{name="air", prob=0, param2=0},
		{name="air", prob=0, param2=0},
		{name="air", prob=0, param2=0},
		{name="air", prob=0, param2=0},
		{name="air", prob=0, param2=0},
		{name="air", prob=0, param2=0},
		{name="air", prob=0, param2=0},
		{name="air", prob=0, param2=0},
		{name="air", prob=0, param2=0},
		{name="air", prob=0, param2=0},
		{name="air", prob=0, param2=0},
		{name="air", prob=0, param2=0},
		{name="air", prob=0, param2=0},
		{name="air", prob=0, param2=0},
		{name="air", prob=0, param2=0},
		{name="air", prob=0, param2=0},
		{name="air", prob=0, param2=0},
		{name="air", prob=0, param2=0},
		{name="air", prob=0, param2=0},
		{name="air", prob=0, param2=0},
		{name="air", prob=0, param2=0},
		{name="air", prob=0, param2=0},
		{name="air", prob=0, param2=0},
		{name="air", prob=0, param2=0},
		{name="air", prob=0, param2=0},
		{name="air", prob=0, param2=0},
		{name="air", prob=0, param2=0},
		{name="air", prob=0, param2=0},
		{name="air", prob=0, param2=0},
		{name="air", prob=0, param2=0},
		{name="air", prob=0, param2=0},
		{name="air", prob=0, param2=0},
		{name="air", prob=0, param2=0},
		{name="air", prob=0, param2=0},
		{name="air", prob=0, param2=0},
		{name="air", prob=0, param2=0},
		{name="air", prob=0, param2=0},
		{name="air", prob=0, param2=0},
		{name="air", prob=0, param2=0},
		{name="air", prob=0, param2=0},
		{name="air", prob=0, param2=0},
		{name="air", prob=0, param2=0},
		{name="air", prob=0, param2=0},
		{name="air", prob=0, param2=0},
		{name="air", prob=0, param2=0},
		{name="air", prob=0, param2=0},
		{name="air", prob=0, param2=0},
		{name="air", prob=0, param2=0},
		{name="air", prob=0, param2=0},
		{name="air", prob=0, param2=0},
		{name="air", prob=0, param2=0},
		{name="air", prob=0, param2=0},
		{name="air", prob=0, param2=0},
		{name="air", prob=0, param2=0},
		{name="air", prob=0, param2=0},
		{name="air", prob=0, param2=0},
		{name="air", prob=0, param2=0},
		{name="air", prob=0, param2=0},
		{name="air", prob=0, param2=0},
		{name="air", prob=0, param2=0},
		{name="air", prob=0, param2=0},
		{name="air", prob=0, param2=0},
		{name="air", prob=0, param2=0},
		{name="air", prob=0, param2=0},
		{name="air", prob=0, param2=0},
		{name="air", prob=0, param2=0},
		{name="air", prob=0, param2=0},
		{name="air", prob=0, param2=0},
		{name="air", prob=0, param2=0},
		{name="air", prob=0, param2=0},
		{name="air", prob=0, param2=0},
		{name="air", prob=0, param2=0},
		{name="air", prob=0, param2=0},
		{name="air", prob=0, param2=0},
		{name="air", prob=0, param2=0},
		{name="air", prob=0, param2=0},
		{name="air", prob=0, param2=0},
		{name="air", prob=0, param2=0},
		{name="air", prob=0, param2=0},
		{name="air", prob=0, param2=0},
		{name="air", prob=0, param2=0},
		{name="air", prob=0, param2=0},
		{name="air", prob=0, param2=0},
		{name="air", prob=0, param2=0},
		{name="air", prob=0, param2=0},
		{name="air", prob=0, param2=0},
		{name="air", prob=0, param2=0},
		{name="air", prob=0, param2=0},
		{name="air", prob=0, param2=0},
		{name="air", prob=0, param2=0},
		{name="air", prob=0, param2=0},
		{name="air", prob=0, param2=0},
		{name="air", prob=0, param2=0},
		{name="air", prob=0, param2=0},
		{name="air", prob=0, param2=0},
		{name="air", prob=0, param2=0},
		{name="air", prob=0, param2=0},
		{name="air", prob=0, param2=0},
		{name="air", prob=0, param2=0},
		{name="everness:volcanic_rock", prob=254, param2=0},
		{name="air", prob=0, param2=0},
		{name="air", prob=0, param2=0},
		{name="air", prob=0, param2=0},
		{name="air", prob=0, param2=0},
		{name="air", prob=0, param2=0},
		{name="air", prob=0, param2=0},
		{name="air", prob=0, param2=0},
		{name="air", prob=0, param2=0},
		{name="air", prob=0, param2=0},
		{name="air", prob=0, param2=0},
		{name="air", prob=0, param2=0},
		{name="air", prob=0, param2=0},
		{name="air", prob=0, param2=0},
		{name="air", prob=0, param2=0},
		{name="air", prob=0, param2=0},
		{name="air", prob=0, param2=0},
		{name="air", prob=0, param2=0},
		{name="everness:volcanic_rock", prob=254, param2=0},
		{name="everness:volcanic_rock", prob=254, param2=0},
		{name="everness:volcanic_rock", prob=254, param2=0},
		{name="everness:volcanic_rock", prob=254, param2=0},
		{name="everness:volcanic_rock", prob=254, param2=0},
		{name="air", prob=0, param2=0},
		{name="air", prob=0, param2=0},
		{name="air", prob=0, param2=0},
		{name="air", prob=0, param2=0},
		{name="air", prob=0, param2=0},
		{name="air", prob=0, param2=0},
		{name="air", prob=0, param2=0},
		{name="air", prob=0, param2=0},
		{name="air", prob=0, param2=0},
		{name="air", prob=0, param2=0},
		{name="air", prob=0, param2=0},
		{name="air", prob=0, param2=0},
		{name="air", prob=0, param2=0},
		{name="air", prob=0, param2=0},
		{name="air", prob=0, param2=0},
		{name="everness:volcanic_rock", prob=254, param2=0},
		{name="everness:volcanic_rock", prob=254, param2=0},
		{name="everness:volcanic_rock", prob=254, param2=0},
		{name="everness:volcanic_rock", prob=254, param2=0},
		{name="everness:volcanic_rock", prob=254, param2=0},
		{name="air", prob=0, param2=0},
		{name="air", prob=0, param2=0},
		{name="air", prob=0, param2=0},
		{name="air", prob=0, param2=0},
		{name="air", prob=0, param2=0},
		{name="air", prob=0, param2=0},
		{name="air", prob=0, param2=0},
		{name="air", prob=0, param2=0},
		{name="air", prob=0, param2=0},
		{name="air", prob=0, param2=0},
		{name="air", prob=0, param2=0},
		{name="air", prob=0, param2=0},
		{name="air", prob=0, param2=0},
		{name="air", prob=0, param2=0},
		{name="everness:volcanic_rock", prob=254, param2=0},
		{name="everness:volcanic_rock", prob=254, param2=0},
		{name="everness:volcanic_rock", prob=254, param2=0},
		{name="everness:volcanic_rock", prob=254, param2=0},
		{name="everness:volcanic_rock", prob=254, param2=0},
		{name="everness:volcanic_rock", prob=254, param2=0},
		{name="everness:volcanic_rock", prob=254, param2=0},
		{name="air", prob=0, param2=0},
		{name="air", prob=0, param2=0},
		{name="air", prob=0, param2=0},
		{name="air", prob=0, param2=0},
		{name="air", prob=0, param2=0},
		{name="air", prob=0, param2=0},
		{name="air", prob=0, param2=0},
		{name="air", prob=0, param2=0},
		{name="air", prob=0, param2=0},
		{name="air", prob=0, param2=0},
		{name="air", prob=0, param2=0},
		{name="air", prob=0, param2=0},
		{name="air", prob=0, param2=0},
		{name="air", prob=0, param2=0},
		{name="everness:volcanic_rock", prob=254, param2=0},
		{name="everness:volcanic_rock", prob=254, param2=0},
		{name="everness:volcanic_rock", prob=254, param2=0},
		{name="everness:volcanic_rock", prob=254, param2=0},
		{name="everness:volcanic_rock", prob=254, param2=0},
		{name="air", prob=0, param2=0},
		{name="air", prob=0, param2=0},
		{name="air", prob=0, param2=0},
		{name="air", prob=0, param2=0},
		{name="air", prob=0, param2=0},
		{name="air", prob=0, param2=0},
		{name="air", prob=0, param2=0},
		{name="air", prob=0, param2=0},
		{name="air", prob=0, param2=0},
		{name="air", prob=0, param2=0},
		{name="air", prob=0, param2=0},
		{name="air", prob=0, param2=0},
		{name="air", prob=0, param2=0},
		{name="air", prob=0, param2=0},
		{name="air", prob=0, param2=0},
		{name="everness:volcanic_rock", prob=254, param2=0},
		{name="everness:volcanic_rock", prob=254, param2=0},
		{name="everness:volcanic_rock", prob=254, param2=0},
		{name="everness:volcanic_rock", prob=254, param2=0},
		{name="everness:volcanic_rock", prob=254, param2=0},
		{name="air", prob=0, param2=0},
		{name="air", prob=0, param2=0},
		{name="air", prob=0, param2=0},
		{name="air", prob=0, param2=0},
		{name="air", prob=0, param2=0},
		{name="air", prob=0, param2=0},
		{name="air", prob=0, param2=0},
		{name="air", prob=0, param2=0},
		{name="air", prob=0, param2=0},
		{name="air", prob=0, param2=0},
		{name="air", prob=0, param2=0},
		{name="air", prob=0, param2=0},
		{name="air", prob=0, param2=0},
		{name="air", prob=0, param2=0},
		{name="air", prob=0, param2=0},
		{name="air", prob=0, param2=0},
		{name="air", prob=0, param2=0},
		{name="everness:volcanic_rock", prob=254, param2=0},
		{name="air", prob=0, param2=0},
		{name="air", prob=0, param2=0},
		{name="air", prob=0, param2=0},
		{name="air", prob=0, param2=0},
		{name="air", prob=0, param2=0},
		{name="air", prob=0, param2=0},
		{name="air", prob=0, param2=0},
		{name="air", prob=0, param2=0},
		{name="air", prob=0, param2=0},
		{name="air", prob=0, param2=0},
		{name="air", prob=0, param2=0},
		{name="air", prob=0, param2=0},
		{name="air", prob=0, param2=0},
		{name="air", prob=0, param2=0},
		{name="air", prob=0, param2=0},
		{name="air", prob=0, param2=0},
		{name="air", prob=0, param2=0},
		{name="air", prob=0, param2=0},
		{name="air", prob=0, param2=0},
		{name="air", prob=0, param2=0},
		{name="air", prob=0, param2=0},
		{name="air", prob=0, param2=0},
		{name="air", prob=0, param2=0},
		{name="air", prob=0, param2=0},
		{name="air", prob=0, param2=0},
		{name="air", prob=0, param2=0},
		{name="air", prob=0, param2=0},
		{name="air", prob=0, param2=0},
		{name="air", prob=0, param2=0},
		{name="air", prob=0, param2=0},
		{name="air", prob=0, param2=0},
		{name="air", prob=0, param2=0},
		{name="air", prob=0, param2=0},
		{name="air", prob=0, param2=0},
		{name="air", prob=0, param2=0},
		{name="air", prob=0, param2=0},
		{name="air", prob=0, param2=0},
		{name="air", prob=0, param2=0},
		{name="air", prob=0, param2=0},
		{name="air", prob=0, param2=0},
		{name="air", prob=0, param2=0},
		{name="air", prob=0, param2=0},
		{name="air", prob=0, param2=0},
		{name="air", prob=0, param2=0},
		{name="air", prob=0, param2=0},
		{name="air", prob=0, param2=0},
		{name="air", prob=0, param2=0},
		{name="air", prob=0, param2=0},
		{name="air", prob=0, param2=0},
		{name="air", prob=0, param2=0},
		{name="air", prob=0, param2=0},
		{name="air", prob=0, param2=0},
		{name="air", prob=0, param2=0},
		{name="air", prob=0, param2=0},
		{name="air", prob=0, param2=0},
		{name="air", prob=0, param2=0},
		{name="air", prob=0, param2=0},
		{name="air", prob=0, param2=0},
		{name="air", prob=0, param2=0},
		{name="air", prob=0, param2=0},
		{name="air", prob=0, param2=0},
		{name="air", prob=0, param2=0},
		{name="air", prob=0, param2=0},
		{name="air", prob=0, param2=0},
		{name="air", prob=0, param2=0},
		{name="air", prob=0, param2=0},
		{name="air", prob=0, param2=0},
		{name="air", prob=0, param2=0},
		{name="air", prob=0, param2=0},
		{name="air", prob=0, param2=0},
		{name="air", prob=0, param2=0},
		{name="air", prob=0, param2=0},
		{name="air", prob=0, param2=0},
		{name="air", prob=0, param2=0},
		{name="air", prob=0, param2=0},
		{name="air", prob=0, param2=0},
		{name="air", prob=0, param2=0},
		{name="air", prob=0, param2=0},
		{name="air", prob=0, param2=0},
		{name="air", prob=0, param2=0},
		{name="air", prob=0, param2=0},
		{name="air", prob=0, param2=0},
		{name="air", prob=0, param2=0},
		{name="air", prob=0, param2=0},
		{name="air", prob=0, param2=0},
		{name="air", prob=0, param2=0},
		{name="air", prob=0, param2=0},
		{name="air", prob=0, param2=0},
		{name="air", prob=0, param2=0},
		{name="air", prob=0, param2=0},
		{name="air", prob=0, param2=0},
		{name="air", prob=0, param2=0},
		{name="air", prob=0, param2=0},
		{name="air", prob=0, param2=0},
		{name="air", prob=0, param2=0},
		{name="air", prob=0, param2=0},
		{name="air", prob=0, param2=0},
		{name="air", prob=0, param2=0},
		{name="air", prob=0, param2=0},
		{name="air", prob=0, param2=0},
		{name="air", prob=0, param2=0},
		{name="air", prob=0, param2=0},
		{name="air", prob=0, param2=0},
		{name="air", prob=0, param2=0},
		{name="air", prob=0, param2=0},
		{name="air", prob=0, param2=0},
		{name="air", prob=0, param2=0},
		{name="air", prob=0, param2=0},
		{name="air", prob=0, param2=0},
		{name="air", prob=0, param2=0},
		{name="air", prob=0, param2=0},
		{name="air", prob=0, param2=0},
		{name="air", prob=0, param2=0},
		{name="air", prob=0, param2=0},
		{name="air", prob=0, param2=0},
		{name="air", prob=0, param2=0},
		{name="air", prob=0, param2=0},
		{name="air", prob=0, param2=0},
		{name="air", prob=0, param2=0},
		{name="air", prob=0, param2=0},
		{name="air", prob=0, param2=0},
		{name="air", prob=0, param2=0},
		{name="air", prob=0, param2=0},
		{name="air", prob=0, param2=0},
		{name="air", prob=0, param2=0},
		{name="air", prob=0, param2=0},
		{name="air", prob=0, param2=0},
		{name="air", prob=0, param2=0},
		{name="air", prob=0, param2=0},
		{name="air", prob=0, param2=0},
		{name="air", prob=0, param2=0},
		{name="air", prob=0, param2=0},
		{name="air", prob=0, param2=0},
		{name="air", prob=0, param2=0},
		{name="air", prob=0, param2=0},
		{name="air", prob=0, param2=0},
		{name="air", prob=0, param2=0},
		{name="air", prob=0, param2=0},
		{name="air", prob=0, param2=0},
		{name="air", prob=0, param2=0},
		{name="air", prob=0, param2=0},
		{name="air", prob=0, param2=0},
		{name="air", prob=0, param2=0},
		{name="air", prob=0, param2=0},
		{name="air", prob=0, param2=0},
		{name="air", prob=0, param2=0},
		{name="air", prob=0, param2=0},
		{name="air", prob=0, param2=0},
		{name="air", prob=0, param2=0},
		{name="air", prob=0, param2=0},
		{name="air", prob=0, param2=0},
		{name="air", prob=0, param2=0},
		{name="air", prob=0, param2=0},
		{name="air", prob=0, param2=0},
		{name="air", prob=0, param2=0},
		{name="air", prob=0, param2=0},
		{name="air", prob=0, param2=0},
		{name="air", prob=0, param2=0},
		{name="air", prob=0, param2=0},
		{name="air", prob=0, param2=0},
		{name="air", prob=0, param2=0},
		{name="air", prob=0, param2=0},
		{name="air", prob=0, param2=0},
		{name="air", prob=0, param2=0},
		{name="air", prob=0, param2=0},
		{name="air", prob=0, param2=0},
		{name="air", prob=0, param2=0},
		{name="air", prob=0, param2=0},
		{name="air", prob=0, param2=0},
		{name="air", prob=0, param2=0},
		{name="air", prob=0, param2=0},
		{name="air", prob=0, param2=0},
		{name="air", prob=0, param2=0},
		{name="air", prob=0, param2=0},
		{name="air", prob=0, param2=0},
		{name="air", prob=0, param2=0},
		{name="air", prob=0, param2=0},
		{name="air", prob=0, param2=0},
		{name="air", prob=0, param2=0},
		{name="air", prob=0, param2=0},
		{name="air", prob=0, param2=0},
		{name="air", prob=0, param2=0},
		{name="air", prob=0, param2=0},
		{name="air", prob=0, param2=0},
		{name="air", prob=0, param2=0},
		{name="air", prob=0, param2=0},
		{name="air", prob=0, param2=0},
		{name="air", prob=0, param2=0},
		{name="air", prob=0, param2=0},
		{name="air", prob=0, param2=0},
		{name="air", prob=0, param2=0},
		{name="air", prob=0, param2=0},
		{name="air", prob=0, param2=0},
		{name="air", prob=0, param2=0},
		{name="air", prob=0, param2=0},
		{name="air", prob=0, param2=0},
		{name="air", prob=0, param2=0},
		{name="air", prob=0, param2=0},
		{name="air", prob=0, param2=0},
		{name="air", prob=0, param2=0},
		{name="air", prob=0, param2=0},
		{name="air", prob=0, param2=0},
		{name="air", prob=0, param2=0},
		{name="air", prob=0, param2=0},
		{name="air", prob=0, param2=0},
		{name="air", prob=0, param2=0},
		{name="air", prob=0, param2=0},
		{name="air", prob=0, param2=0},
		{name="air", prob=0, param2=0},
		{name="air", prob=0, param2=0},
		{name="air", prob=0, param2=0},
		{name="air", prob=0, param2=0},
		{name="air", prob=0, param2=0},
		{name="air", prob=0, param2=0},
		{name="air", prob=0, param2=0},
		{name="air", prob=0, param2=0},
		{name="air", prob=0, param2=0},
		{name="air", prob=0, param2=0},
		{name="everness:volcanic_rock", prob=254, param2=0},
		{name="everness:volcanic_rock", prob=254, param2=0},
		{name="everness:volcanic_rock", prob=254, param2=0},
		{name="air", prob=0, param2=0},
		{name="air", prob=0, param2=0},
		{name="air", prob=0, param2=0},
		{name="air", prob=0, param2=0},
		{name="air", prob=0, param2=0},
		{name="air", prob=0, param2=0},
		{name="air", prob=0, param2=0},
		{name="air", prob=0, param2=0},
		{name="air", prob=0, param2=0},
		{name="air", prob=0, param2=0},
		{name="air", prob=0, param2=0},
		{name="air", prob=0, param2=0},
		{name="air", prob=0, param2=0},
		{name="air", prob=0, param2=0},
		{name="air", prob=0, param2=0},
		{name="everness:volcanic_rock", prob=254, param2=0},
		{name="everness:volcanic_rock", prob=254, param2=0},
		{name="everness:volcanic_rock", prob=254, param2=0},
		{name="everness:volcanic_rock", prob=254, param2=0},
		{name="everness:volcanic_rock", prob=254, param2=0},
		{name="everness:volcanic_rock", prob=254, param2=0},
		{name="everness:volcanic_rock", prob=254, param2=0},
		{name="air", prob=0, param2=0},
		{name="air", prob=0, param2=0},
		{name="air", prob=0, param2=0},
		{name="air", prob=0, param2=0},
		{name="air", prob=0, param2=0},
		{name="air", prob=0, param2=0},
		{name="air", prob=0, param2=0},
		{name="air", prob=0, param2=0},
		{name="air", prob=0, param2=0},
		{name="air", prob=0, param2=0},
		{name="air", prob=0, param2=0},
		{name="air", prob=0, param2=0},
		{name="everness:volcanic_rock", prob=254, param2=0},
		{name="everness:volcanic_rock", prob=254, param2=0},
		{name="everness:volcanic_rock", prob=254, param2=0},
		{name="everness:volcanic_rock", prob=254, param2=0},
		{name="everness:volcanic_rock", prob=254, param2=0},
		{name="everness:volcanic_rock", prob=254, param2=0},
		{name="everness:volcanic_rock", prob=254, param2=0},
		{name="everness:volcanic_rock", prob=254, param2=0},
		{name="everness:volcanic_rock", prob=254, param2=0},
		{name="air", prob=0, param2=0},
		{name="air", prob=0, param2=0},
		{name="air", prob=0, param2=0},
		{name="air", prob=0, param2=0},
		{name="air", prob=0, param2=0},
		{name="air", prob=0, param2=0},
		{name="air", prob=0, param2=0},
		{name="air", prob=0, param2=0},
		{name="air", prob=0, param2=0},
		{name="air", prob=0, param2=0},
		{name="air", prob=0, param2=0},
		{name="everness:volcanic_rock", prob=254, param2=0},
		{name="everness:volcanic_rock", prob=254, param2=0},
		{name="everness:gravel", prob=254, param2=0},
		{name="everness:gravel", prob=254, param2=0},
		{name="everness:gravel", prob=254, param2=0},
		{name="everness:gravel", prob=254, param2=0},
		{name="everness:gravel", prob=254, param2=0},
		{name="everness:volcanic_rock", prob=254, param2=0},
		{name="everness:volcanic_rock", prob=254, param2=0},
		{name="air", prob=0, param2=0},
		{name="air", prob=0, param2=0},
		{name="air", prob=0, param2=0},
		{name="air", prob=0, param2=0},
		{name="air", prob=0, param2=0},
		{name="air", prob=0, param2=0},
		{name="air", prob=0, param2=0},
		{name="air", prob=0, param2=0},
		{name="air", prob=0, param2=0},
		{name="air", prob=0, param2=0},
		{name="everness:volcanic_rock", prob=254, param2=0},
		{name="everness:volcanic_rock", prob=254, param2=0},
		{name="everness:volcanic_rock", prob=254, param2=0},
		{name="everness:gravel", prob=254, param2=0},
		{name="everness:gravel", prob=254, param2=0},
		{name="everness:gravel", prob=254, param2=0},
		{name="everness:gravel", prob=254, param2=0},
		{name="everness:gravel", prob=254, param2=0},
		{name="everness:volcanic_rock", prob=254, param2=0},
		{name="everness:volcanic_rock", prob=254, param2=0},
		{name="everness:volcanic_rock", prob=254, param2=0},
		{name="air", prob=0, param2=0},
		{name="air", prob=0, param2=0},
		{name="air", prob=0, param2=0},
		{name="air", prob=0, param2=0},
		{name="air", prob=0, param2=0},
		{name="air", prob=0, param2=0},
		{name="air", prob=0, param2=0},
		{name="air", prob=0, param2=0},
		{name="air", prob=0, param2=0},
		{name="everness:volcanic_rock", prob=254, param2=0},
		{name="everness:volcanic_rock", prob=254, param2=0},
		{name="everness:volcanic_rock", prob=254, param2=0},
		{name="everness:gravel", prob=254, param2=0},
		{name="everness:gravel", prob=254, param2=0},
		{name="everness:gravel", prob=254, param2=0},
		{name="everness:gravel", prob=254, param2=0},
		{name="everness:gravel", prob=254, param2=0},
		{name="everness:volcanic_rock", prob=254, param2=0},
		{name="everness:volcanic_rock", prob=254, param2=0},
		{name="everness:volcanic_rock", prob=254, param2=0},
		{name="air", prob=0, param2=0},
		{name="air", prob=0, param2=0},
		{name="air", prob=0, param2=0},
		{name="air", prob=0, param2=0},
		{name="air", prob=0, param2=0},
		{name="air", prob=0, param2=0},
		{name="air", prob=0, param2=0},
		{name="air", prob=0, param2=0},
		{name="air", prob=0, param2=0},
		{name="everness:volcanic_rock", prob=254, param2=0},
		{name="everness:volcanic_rock", prob=254, param2=0},
		{name="everness:volcanic_rock", prob=254, param2=0},
		{name="everness:gravel", prob=254, param2=0},
		{name="everness:gravel", prob=254, param2=0},
		{name="everness:gravel", prob=254, param2=0},
		{name="everness:gravel", prob=254, param2=0},
		{name="everness:gravel", prob=254, param2=0},
		{name="everness:volcanic_rock", prob=254, param2=0},
		{name="everness:volcanic_rock", prob=254, param2=0},
		{name="everness:volcanic_rock", prob=254, param2=0},
		{name="air", prob=0, param2=0},
		{name="air", prob=0, param2=0},
		{name="air", prob=0, param2=0},
		{name="air", prob=0, param2=0},
		{name="air", prob=0, param2=0},
		{name="air", prob=0, param2=0},
		{name="air", prob=0, param2=0},
		{name="air", prob=0, param2=0},
		{name="air", prob=0, param2=0},
		{name="air", prob=0, param2=0},
		{name="everness:volcanic_rock", prob=254, param2=0},
		{name="everness:volcanic_rock", prob=254, param2=0},
		{name="everness:gravel", prob=254, param2=0},
		{name="everness:gravel", prob=254, param2=0},
		{name="everness:gravel", prob=254, param2=0},
		{name="everness:gravel", prob=254, param2=0},
		{name="everness:gravel", prob=254, param2=0},
		{name="everness:volcanic_rock", prob=254, param2=0},
		{name="everness:volcanic_rock", prob=254, param2=0},
		{name="air", prob=0, param2=0},
		{name="air", prob=0, param2=0},
		{name="air", prob=0, param2=0},
		{name="air", prob=0, param2=0},
		{name="air", prob=0, param2=0},
		{name="air", prob=0, param2=0},
		{name="air", prob=0, param2=0},
		{name="air", prob=0, param2=0},
		{name="air", prob=0, param2=0},
		{name="air", prob=0, param2=0},
		{name="air", prob=0, param2=0},
		{name="everness:volcanic_rock", prob=254, param2=0},
		{name="everness:volcanic_rock", prob=254, param2=0},
		{name="everness:volcanic_rock", prob=254, param2=0},
		{name="everness:volcanic_rock", prob=254, param2=0},
		{name="everness:volcanic_rock", prob=254, param2=0},
		{name="everness:volcanic_rock", prob=254, param2=0},
		{name="everness:volcanic_rock", prob=254, param2=0},
		{name="everness:volcanic_rock", prob=254, param2=0},
		{name="everness:volcanic_rock", prob=254, param2=0},
		{name="air", prob=0, param2=0},
		{name="air", prob=0, param2=0},
		{name="air", prob=0, param2=0},
		{name="air", prob=0, param2=0},
		{name="air", prob=0, param2=0},
		{name="air", prob=0, param2=0},
		{name="air", prob=0, param2=0},
		{name="air", prob=0, param2=0},
		{name="air", prob=0, param2=0},
		{name="air", prob=0, param2=0},
		{name="air", prob=0, param2=0},
		{name="air", prob=0, param2=0},
		{name="everness:volcanic_rock", prob=254, param2=0},
		{name="everness:volcanic_rock", prob=254, param2=0},
		{name="everness:volcanic_rock", prob=254, param2=0},
		{name="everness:volcanic_rock", prob=254, param2=0},
		{name="everness:volcanic_rock", prob=254, param2=0},
		{name="everness:volcanic_rock", prob=254, param2=0},
		{name="everness:volcanic_rock", prob=254, param2=0},
		{name="air", prob=0, param2=0},
		{name="air", prob=0, param2=0},
		{name="air", prob=0, param2=0},
		{name="air", prob=0, param2=0},
		{name="air", prob=0, param2=0},
		{name="air", prob=0, param2=0},
		{name="air", prob=0, param2=0},
		{name="air", prob=0, param2=0},
		{name="air", prob=0, param2=0},
		{name="air", prob=0, param2=0},
		{name="air", prob=0, param2=0},
		{name="air", prob=0, param2=0},
		{name="air", prob=0, param2=0},
		{name="air", prob=0, param2=0},
		{name="air", prob=0, param2=0},
		{name="everness:volcanic_rock", prob=254, param2=0},
		{name="everness:volcanic_rock", prob=254, param2=0},
		{name="everness:volcanic_rock", prob=254, param2=0},
		{name="air", prob=0, param2=0},
		{name="air", prob=0, param2=0},
		{name="air", prob=0, param2=0},
		{name="air", prob=0, param2=0},
		{name="air", prob=0, param2=0},
		{name="air", prob=0, param2=0},
		{name="air", prob=0, param2=0},
		{name="air", prob=0, param2=0},
		{name="air", prob=0, param2=0},
		{name="air", prob=0, param2=0},
		{name="air", prob=0, param2=0},
		{name="air", prob=0, param2=0},
		{name="air", prob=0, param2=0},
		{name="air", prob=0, param2=0},
		{name="air", prob=0, param2=0},
		{name="air", prob=0, param2=0},
		{name="air", prob=0, param2=0},
		{name="air", prob=0, param2=0},
		{name="air", prob=0, param2=0},
		{name="air", prob=0, param2=0},
		{name="air", prob=0, param2=0},
		{name="air", prob=0, param2=0},
		{name="air", prob=0, param2=0},
		{name="air", prob=0, param2=0},
		{name="air", prob=0, param2=0},
		{name="air", prob=0, param2=0},
		{name="air", prob=0, param2=0},
		{name="air", prob=0, param2=0},
		{name="air", prob=0, param2=0},
		{name="air", prob=0, param2=0},
		{name="air", prob=0, param2=0},
		{name="air", prob=0, param2=0},
		{name="air", prob=0, param2=0},
		{name="air", prob=0, param2=0},
		{name="air", prob=0, param2=0},
		{name="air", prob=0, param2=0},
		{name="air", prob=0, param2=0},
		{name="air", prob=0, param2=0},
		{name="air", prob=0, param2=0},
		{name="air", prob=0, param2=0},
		{name="air", prob=0, param2=0},
		{name="air", prob=0, param2=0},
		{name="air", prob=0, param2=0},
		{name="air", prob=0, param2=0},
		{name="air", prob=0, param2=0},
		{name="air", prob=0, param2=0},
		{name="air", prob=0, param2=0},
		{name="air", prob=0, param2=0},
		{name="air", prob=0, param2=0},
		{name="air", prob=0, param2=0},
		{name="air", prob=0, param2=0},
		{name="air", prob=0, param2=0},
		{name="air", prob=0, param2=0},
		{name="air", prob=0, param2=0},
		{name="air", prob=0, param2=0},
		{name="air", prob=0, param2=0},
		{name="air", prob=0, param2=0},
		{name="air", prob=0, param2=0},
		{name="air", prob=0, param2=0},
		{name="air", prob=0, param2=0},
		{name="air", prob=0, param2=0},
		{name="air", prob=0, param2=0},
		{name="air", prob=0, param2=0},
		{name="air", prob=0, param2=0},
		{name="air", prob=0, param2=0},
		{name="air", prob=0, param2=0},
		{name="air", prob=0, param2=0},
		{name="air", prob=0, param2=0},
		{name="air", prob=0, param2=0},
		{name="air", prob=0, param2=0},
		{name="air", prob=0, param2=0},
		{name="air", prob=0, param2=0},
		{name="air", prob=0, param2=0},
		{name="air", prob=0, param2=0},
		{name="air", prob=0, param2=0},
		{name="air", prob=0, param2=0},
		{name="air", prob=0, param2=0},
		{name="air", prob=0, param2=0},
		{name="air", prob=0, param2=0},
		{name="air", prob=0, param2=0},
		{name="air", prob=0, param2=0},
		{name="air", prob=0, param2=0},
		{name="air", prob=0, param2=0},
		{name="air", prob=0, param2=0},
		{name="air", prob=0, param2=0},
		{name="air", prob=0, param2=0},
		{name="air", prob=0, param2=0},
		{name="air", prob=0, param2=0},
		{name="air", prob=0, param2=0},
		{name="air", prob=0, param2=0},
		{name="air", prob=0, param2=0},
		{name="air", prob=0, param2=0},
		{name="air", prob=0, param2=0},
		{name="air", prob=0, param2=0},
		{name="air", prob=0, param2=0},
		{name="air", prob=0, param2=0},
		{name="air", prob=0, param2=0},
		{name="air", prob=0, param2=0},
		{name="air", prob=0, param2=0},
		{name="air", prob=0, param2=0},
		{name="air", prob=0, param2=0},
		{name="air", prob=0, param2=0},
		{name="air", prob=0, param2=0},
		{name="air", prob=0, param2=0},
		{name="air", prob=0, param2=0},
		{name="air", prob=0, param2=0},
		{name="air", prob=0, param2=0},
		{name="air", prob=0, param2=0},
		{name="air", prob=0, param2=0},
		{name="air", prob=0, param2=0},
		{name="air", prob=0, param2=0},
		{name="air", prob=0, param2=0},
		{name="air", prob=0, param2=0},
		{name="air", prob=0, param2=0},
		{name="air", prob=0, param2=0},
		{name="air", prob=0, param2=0},
		{name="air", prob=0, param2=0},
		{name="air", prob=0, param2=0},
		{name="air", prob=0, param2=0},
		{name="air", prob=0, param2=0},
		{name="air", prob=0, param2=0},
		{name="air", prob=0, param2=0},
		{name="air", prob=0, param2=0},
		{name="air", prob=0, param2=0},
		{name="air", prob=0, param2=0},
		{name="air", prob=0, param2=0},
		{name="air", prob=0, param2=0},
		{name="air", prob=0, param2=0},
		{name="air", prob=0, param2=0},
		{name="air", prob=0, param2=0},
		{name="air", prob=0, param2=0},
		{name="air", prob=0, param2=0},
		{name="air", prob=0, param2=0},
		{name="air", prob=0, param2=0},
		{name="air", prob=0, param2=0},
		{name="air", prob=0, param2=0},
		{name="air", prob=0, param2=0},
		{name="air", prob=0, param2=0},
		{name="air", prob=0, param2=0},
		{name="air", prob=0, param2=0},
		{name="air", prob=0, param2=0},
		{name="air", prob=0, param2=0},
		{name="air", prob=0, param2=0},
		{name="air", prob=0, param2=0},
		{name="air", prob=0, param2=0},
		{name="air", prob=0, param2=0},
		{name="air", prob=0, param2=0},
		{name="air", prob=0, param2=0},
		{name="air", prob=0, param2=0},
		{name="air", prob=0, param2=0},
		{name="air", prob=0, param2=0},
		{name="air", prob=0, param2=0},
		{name="air", prob=0, param2=0},
		{name="air", prob=0, param2=0},
		{name="air", prob=0, param2=0},
		{name="air", prob=0, param2=0},
		{name="everness:volcanic_rock", prob=254, param2=0},
		{name="everness:volcanic_rock", prob=254, param2=0},
		{name="everness:volcanic_rock", prob=254, param2=0},
		{name="everness:volcanic_rock", prob=254, param2=0},
		{name="everness:volcanic_rock", prob=254, param2=0},
		{name="air", prob=0, param2=0},
		{name="air", prob=0, param2=0},
		{name="air", prob=0, param2=0},
		{name="air", prob=0, param2=0},
		{name="air", prob=0, param2=0},
		{name="air", prob=0, param2=0},
		{name="air", prob=0, param2=0},
		{name="air", prob=0, param2=0},
		{name="air", prob=0, param2=0},
		{name="air", prob=0, param2=0},
		{name="air", prob=0, param2=0},
		{name="air", prob=0, param2=0},
		{name="air", prob=0, param2=0},
		{name="everness:volcanic_rock", prob=254, param2=0},
		{name="everness:volcanic_rock", prob=254, param2=0},
		{name="everness:volcanic_rock", prob=254, param2=0},
		{name="everness:volcanic_rock", prob=254, param2=0},
		{name="everness:volcanic_rock", prob=254, param2=0},
		{name="everness:volcanic_rock", prob=254, param2=0},
		{name="everness:volcanic_rock", prob=254, param2=0},
		{name="everness:volcanic_rock", prob=254, param2=0},
		{name="everness:volcanic_rock", prob=254, param2=0},
		{name="air", prob=0, param2=0},
		{name="air", prob=0, param2=0},
		{name="air", prob=0, param2=0},
		{name="air", prob=0, param2=0},
		{name="air", prob=0, param2=0},
		{name="air", prob=0, param2=0},
		{name="air", prob=0, param2=0},
		{name="air", prob=0, param2=0},
		{name="air", prob=0, param2=0},
		{name="air", prob=0, param2=0},
		{name="everness:volcanic_rock", prob=254, param2=0},
		{name="everness:volcanic_rock", prob=254, param2=0},
		{name="everness:volcanic_rock", prob=254, param2=0},
		{name="everness:gravel", prob=254, param2=0},
		{name="everness:gravel", prob=254, param2=0},
		{name="everness:gravel", prob=254, param2=0},
		{name="everness:gravel", prob=254, param2=0},
		{name="everness:gravel", prob=254, param2=0},
		{name="everness:volcanic_rock", prob=254, param2=0},
		{name="everness:volcanic_rock", prob=254, param2=0},
		{name="everness:volcanic_rock", prob=254, param2=0},
		{name="air", prob=0, param2=0},
		{name="air", prob=0, param2=0},
		{name="air", prob=0, param2=0},
		{name="air", prob=0, param2=0},
		{name="air", prob=0, param2=0},
		{name="air", prob=0, param2=0},
		{name="air", prob=0, param2=0},
		{name="air", prob=0, param2=0},
		{name="air", prob=0, param2=0},
		{name="everness:volcanic_rock", prob=254, param2=0},
		{name="everness:volcanic_rock", prob=254, param2=0},
		{name="everness:gravel", prob=254, param2=0},
		{name="everness:gravel", prob=254, param2=0},
		{name="everness:gravel", prob=254, param2=0},
		{name="everness:gravel", prob=254, param2=0},
		{name="everness:gravel", prob=254, param2=0},
		{name="everness:gravel", prob=254, param2=0},
		{name="everness:gravel", prob=254, param2=0},
		{name="everness:volcanic_rock", prob=254, param2=0},
		{name="everness:volcanic_rock", prob=254, param2=0},
		{name="air", prob=0, param2=0},
		{name="air", prob=0, param2=0},
		{name="air", prob=0, param2=0},
		{name="air", prob=0, param2=0},
		{name="air", prob=0, param2=0},
		{name="air", prob=0, param2=0},
		{name="air", prob=0, param2=0},
		{name="air", prob=0, param2=0},
		{name="everness:volcanic_rock", prob=254, param2=0},
		{name="everness:volcanic_rock", prob=254, param2=0},
		{name="everness:gravel", prob=254, param2=0},
		{name="everness:gravel", prob=254, param2=0},
		{name="everness:gravel", prob=254, param2=0},
		{name="everness:crystal_block_purple", prob=254, param2=0},
		{name="everness:crystal_block_purple", prob=254, param2=0},
		{name="everness:crystal_block_purple", prob=254, param2=0},
		{name="everness:gravel", prob=254, param2=0},
		{name="everness:gravel", prob=254, param2=0},
		{name="everness:gravel", prob=254, param2=0},
		{name="everness:volcanic_rock", prob=254, param2=0},
		{name="everness:volcanic_rock", prob=254, param2=0},
		{name="air", prob=0, param2=0},
		{name="air", prob=0, param2=0},
		{name="air", prob=0, param2=0},
		{name="air", prob=0, param2=0},
		{name="air", prob=0, param2=0},
		{name="air", prob=0, param2=0},
		{name="air", prob=0, param2=0},
		{name="everness:volcanic_rock", prob=254, param2=0},
		{name="everness:volcanic_rock", prob=254, param2=0},
		{name="everness:gravel", prob=254, param2=0},
		{name="everness:gravel", prob=254, param2=0},
		{name="everness:crystal_block_purple", prob=254, param2=0},
		{name="everness:crystal_block_purple", prob=254, param2=0},
		{name="everness:crystal_block_purple", prob=254, param2=0},
		{name="everness:crystal_block_purple", prob=254, param2=0},
		{name="everness:crystal_block_purple", prob=254, param2=0},
		{name="everness:gravel", prob=254, param2=0},
		{name="everness:gravel", prob=254, param2=0},
		{name="everness:volcanic_rock", prob=254, param2=0},
		{name="everness:volcanic_rock", prob=254, param2=0},
		{name="air", prob=0, param2=0},
		{name="air", prob=0, param2=0},
		{name="air", prob=0, param2=0},
		{name="air", prob=0, param2=0},
		{name="air", prob=0, param2=0},
		{name="air", prob=0, param2=0},
		{name="air", prob=0, param2=0},
		{name="everness:volcanic_rock", prob=254, param2=0},
		{name="everness:volcanic_rock", prob=254, param2=0},
		{name="everness:gravel", prob=254, param2=0},
		{name="everness:gravel", prob=254, param2=0},
		{name="everness:crystal_block_purple", prob=254, param2=0},
		{name="everness:crystal_block_purple", prob=254, param2=0},
		{name="everness:crystal_block_purple", prob=254, param2=0},
		{name="everness:crystal_block_purple", prob=254, param2=0},
		{name="everness:crystal_block_purple", prob=254, param2=0},
		{name="everness:gravel", prob=254, param2=0},
		{name="everness:gravel", prob=254, param2=0},
		{name="everness:volcanic_rock", prob=254, param2=0},
		{name="everness:volcanic_rock", prob=254, param2=0},
		{name="air", prob=0, param2=0},
		{name="air", prob=0, param2=0},
		{name="air", prob=0, param2=0},
		{name="air", prob=0, param2=0},
		{name="air", prob=0, param2=0},
		{name="air", prob=0, param2=0},
		{name="air", prob=0, param2=0},
		{name="everness:volcanic_rock", prob=254, param2=0},
		{name="everness:volcanic_rock", prob=254, param2=0},
		{name="everness:gravel", prob=254, param2=0},
		{name="everness:gravel", prob=254, param2=0},
		{name="everness:crystal_block_purple", prob=254, param2=0},
		{name="everness:crystal_block_purple", prob=254, param2=0},
		{name="everness:crystal_block_purple", prob=254, param2=0},
		{name="everness:crystal_block_purple", prob=254, param2=0},
		{name="everness:crystal_block_purple", prob=254, param2=0},
		{name="everness:gravel", prob=254, param2=0},
		{name="everness:gravel", prob=254, param2=0},
		{name="everness:volcanic_rock", prob=254, param2=0},
		{name="everness:volcanic_rock", prob=254, param2=0},
		{name="air", prob=0, param2=0},
		{name="air", prob=0, param2=0},
		{name="air", prob=0, param2=0},
		{name="air", prob=0, param2=0},
		{name="air", prob=0, param2=0},
		{name="air", prob=0, param2=0},
		{name="air", prob=0, param2=0},
		{name="everness:volcanic_rock", prob=254, param2=0},
		{name="everness:volcanic_rock", prob=254, param2=0},
		{name="everness:gravel", prob=254, param2=0},
		{name="everness:gravel", prob=254, param2=0},
		{name="everness:gravel", prob=254, param2=0},
		{name="everness:crystal_block_purple", prob=254, param2=0},
		{name="everness:crystal_block_purple", prob=254, param2=0},
		{name="everness:crystal_block_purple", prob=254, param2=0},
		{name="everness:gravel", prob=254, param2=0},
		{name="everness:gravel", prob=254, param2=0},
		{name="everness:gravel", prob=254, param2=0},
		{name="everness:volcanic_rock", prob=254, param2=0},
		{name="everness:volcanic_rock", prob=254, param2=0},
		{name="air", prob=0, param2=0},
		{name="air", prob=0, param2=0},
		{name="air", prob=0, param2=0},
		{name="air", prob=0, param2=0},
		{name="air", prob=0, param2=0},
		{name="air", prob=0, param2=0},
		{name="air", prob=0, param2=0},
		{name="air", prob=0, param2=0},
		{name="everness:volcanic_rock", prob=254, param2=0},
		{name="everness:volcanic_rock", prob=254, param2=0},
		{name="everness:gravel", prob=254, param2=0},
		{name="everness:gravel", prob=254, param2=0},
		{name="everness:gravel", prob=254, param2=0},
		{name="everness:gravel", prob=254, param2=0},
		{name="everness:gravel", prob=254, param2=0},
		{name="everness:gravel", prob=254, param2=0},
		{name="everness:gravel", prob=254, param2=0},
		{name="everness:volcanic_rock", prob=254, param2=0},
		{name="everness:volcanic_rock", prob=254, param2=0},
		{name="air", prob=0, param2=0},
		{name="air", prob=0, param2=0},
		{name="air", prob=0, param2=0},
		{name="air", prob=0, param2=0},
		{name="air", prob=0, param2=0},
		{name="air", prob=0, param2=0},
		{name="air", prob=0, param2=0},
		{name="air", prob=0, param2=0},
		{name="air", prob=0, param2=0},
		{name="everness:volcanic_rock", prob=254, param2=0},
		{name="everness:volcanic_rock", prob=254, param2=0},
		{name="everness:volcanic_rock", prob=254, param2=0},
		{name="everness:gravel", prob=254, param2=0},
		{name="everness:gravel", prob=254, param2=0},
		{name="everness:gravel", prob=254, param2=0},
		{name="everness:gravel", prob=254, param2=0},
		{name="everness:gravel", prob=254, param2=0},
		{name="everness:volcanic_rock", prob=254, param2=0},
		{name="everness:volcanic_rock", prob=254, param2=0},
		{name="everness:volcanic_rock", prob=254, param2=0},
		{name="air", prob=0, param2=0},
		{name="air", prob=0, param2=0},
		{name="air", prob=0, param2=0},
		{name="air", prob=0, param2=0},
		{name="air", prob=0, param2=0},
		{name="air", prob=0, param2=0},
		{name="air", prob=0, param2=0},
		{name="air", prob=0, param2=0},
		{name="air", prob=0, param2=0},
		{name="air", prob=0, param2=0},
		{name="everness:volcanic_rock", prob=254, param2=0},
		{name="everness:volcanic_rock", prob=254, param2=0},
		{name="everness:volcanic_rock", prob=254, param2=0},
		{name="everness:volcanic_rock", prob=254, param2=0},
		{name="everness:volcanic_rock", prob=254, param2=0},
		{name="everness:volcanic_rock", prob=254, param2=0},
		{name="everness:volcanic_rock", prob=254, param2=0},
		{name="everness:volcanic_rock", prob=254, param2=0},
		{name="everness:volcanic_rock", prob=254, param2=0},
		{name="air", prob=0, param2=0},
		{name="air", prob=0, param2=0},
		{name="air", prob=0, param2=0},
		{name="air", prob=0, param2=0},
		{name="air", prob=0, param2=0},
		{name="air", prob=0, param2=0},
		{name="air", prob=0, param2=0},
		{name="air", prob=0, param2=0},
		{name="air", prob=0, param2=0},
		{name="air", prob=0, param2=0},
		{name="air", prob=0, param2=0},
		{name="air", prob=0, param2=0},
		{name="air", prob=0, param2=0},
		{name="everness:volcanic_rock", prob=254, param2=0},
		{name="everness:volcanic_rock", prob=254, param2=0},
		{name="everness:volcanic_rock", prob=254, param2=0},
		{name="everness:volcanic_rock", prob=254, param2=0},
		{name="everness:volcanic_rock", prob=254, param2=0},
		{name="air", prob=0, param2=0},
		{name="air", prob=0, param2=0},
		{name="air", prob=0, param2=0},
		{name="air", prob=0, param2=0},
		{name="air", prob=0, param2=0},
		{name="air", prob=0, param2=0},
		{name="air", prob=0, param2=0},
		{name="air", prob=0, param2=0},
		{name="air", prob=0, param2=0},
		{name="air", prob=0, param2=0},
		{name="air", prob=0, param2=0},
		{name="air", prob=0, param2=0},
		{name="air", prob=0, param2=0},
		{name="air", prob=0, param2=0},
		{name="air", prob=0, param2=0},
		{name="air", prob=0, param2=0},
		{name="air", prob=0, param2=0},
		{name="air", prob=0, param2=0},
		{name="air", prob=0, param2=0},
		{name="air", prob=0, param2=0},
		{name="air", prob=0, param2=0},
		{name="air", prob=0, param2=0},
		{name="air", prob=0, param2=0},
		{name="air", prob=0, param2=0},
		{name="air", prob=0, param2=0},
		{name="air", prob=0, param2=0},
		{name="air", prob=0, param2=0},
		{name="air", prob=0, param2=0},
		{name="air", prob=0, param2=0},
		{name="air", prob=0, param2=0},
		{name="air", prob=0, param2=0},
		{name="air", prob=0, param2=0},
		{name="air", prob=0, param2=0},
		{name="air", prob=0, param2=0},
		{name="air", prob=0, param2=0},
		{name="air", prob=0, param2=0},
		{name="air", prob=0, param2=0},
		{name="air", prob=0, param2=0},
		{name="air", prob=0, param2=0},
		{name="air", prob=0, param2=0},
		{name="air", prob=0, param2=0},
		{name="air", prob=0, param2=0},
		{name="air", prob=0, param2=0},
		{name="air", prob=0, param2=0},
		{name="air", prob=0, param2=0},
		{name="air", prob=0, param2=0},
		{name="air", prob=0, param2=0},
		{name="air", prob=0, param2=0},
		{name="air", prob=0, param2=0},
		{name="air", prob=0, param2=0},
		{name="air", prob=0, param2=0},
		{name="air", prob=0, param2=0},
		{name="air", prob=0, param2=0},
		{name="air", prob=0, param2=0},
		{name="air", prob=0, param2=0},
		{name="air", prob=0, param2=0},
		{name="air", prob=0, param2=0},
		{name="air", prob=0, param2=0},
		{name="air", prob=0, param2=0},
		{name="air", prob=0, param2=0},
		{name="air", prob=0, param2=0},
		{name="air", prob=0, param2=0},
		{name="air", prob=0, param2=0},
		{name="air", prob=0, param2=0},
		{name="air", prob=0, param2=0},
		{name="air", prob=0, param2=0},
		{name="air", prob=0, param2=0},
		{name="air", prob=0, param2=0},
		{name="air", prob=0, param2=0},
		{name="air", prob=0, param2=0},
		{name="air", prob=0, param2=0},
		{name="air", prob=0, param2=0},
		{name="air", prob=0, param2=0},
		{name="air", prob=0, param2=0},
		{name="air", prob=0, param2=0},
		{name="air", prob=0, param2=0},
		{name="air", prob=0, param2=0},
		{name="air", prob=0, param2=0},
		{name="air", prob=0, param2=0},
		{name="air", prob=0, param2=0},
		{name="air", prob=0, param2=0},
		{name="air", prob=0, param2=0},
		{name="air", prob=0, param2=0},
		{name="air", prob=0, param2=0},
		{name="air", prob=0, param2=0},
		{name="air", prob=0, param2=0},
		{name="air", prob=0, param2=0},
		{name="air", prob=0, param2=0},
		{name="air", prob=0, param2=0},
		{name="air", prob=0, param2=0},
		{name="air", prob=0, param2=0},
		{name="air", prob=0, param2=0},
		{name="air", prob=0, param2=0},
		{name="air", prob=0, param2=0},
		{name="air", prob=0, param2=0},
		{name="air", prob=0, param2=0},
		{name="air", prob=0, param2=0},
		{name="air", prob=0, param2=0},
		{name="air", prob=0, param2=0},
		{name="air", prob=0, param2=0},
		{name="air", prob=0, param2=0},
		{name="air", prob=0, param2=0},
		{name="air", prob=0, param2=0},
		{name="air", prob=0, param2=0},
		{name="air", prob=0, param2=0},
		{name="air", prob=0, param2=0},
		{name="air", prob=0, param2=0},
		{name="air", prob=0, param2=0},
		{name="air", prob=0, param2=0},
		{name="air", prob=0, param2=0},
		{name="air", prob=0, param2=0},
		{name="air", prob=0, param2=0},
		{name="air", prob=0, param2=0},
		{name="air", prob=0, param2=0},
		{name="air", prob=0, param2=0},
		{name="everness:volcanic_rock", prob=254, param2=0},
		{name="everness:volcanic_rock", prob=254, param2=0},
		{name="everness:volcanic_rock", prob=254, param2=0},
		{name="everness:volcanic_rock", prob=254, param2=0},
		{name="everness:volcanic_rock", prob=254, param2=0},
		{name="air", prob=0, param2=0},
		{name="air", prob=0, param2=0},
		{name="air", prob=0, param2=0},
		{name="air", prob=0, param2=0},
		{name="air", prob=0, param2=0},
		{name="air", prob=0, param2=0},
		{name="air", prob=0, param2=0},
		{name="air", prob=0, param2=0},
		{name="air", prob=0, param2=0},
		{name="air", prob=0, param2=0},
		{name="air", prob=0, param2=0},
		{name="air", prob=0, param2=0},
		{name="air", prob=0, param2=0},
		{name="everness:volcanic_rock", prob=254, param2=0},
		{name="everness:volcanic_rock", prob=254, param2=0},
		{name="everness:volcanic_rock", prob=254, param2=0},
		{name="everness:volcanic_rock", prob=254, param2=0},
		{name="everness:gravel", prob=254, param2=0},
		{name="everness:volcanic_rock", prob=254, param2=0},
		{name="everness:volcanic_rock", prob=254, param2=0},
		{name="everness:volcanic_rock", prob=254, param2=0},
		{name="everness:volcanic_rock", prob=254, param2=0},
		{name="air", prob=0, param2=0},
		{name="air", prob=0, param2=0},
		{name="air", prob=0, param2=0},
		{name="air", prob=0, param2=0},
		{name="air", prob=0, param2=0},
		{name="air", prob=0, param2=0},
		{name="air", prob=0, param2=0},
		{name="air", prob=0, param2=0},
		{name="air", prob=0, param2=0},
		{name="air", prob=0, param2=0},
		{name="everness:volcanic_rock", prob=254, param2=0},
		{name="everness:volcanic_rock", prob=254, param2=0},
		{name="everness:gravel", prob=254, param2=0},
		{name="everness:gravel", prob=254, param2=0},
		{name="everness:gravel", prob=254, param2=0},
		{name="everness:gravel", prob=254, param2=0},
		{name="everness:gravel", prob=254, param2=0},
		{name="everness:gravel", prob=254, param2=0},
		{name="everness:gravel", prob=254, param2=0},
		{name="everness:volcanic_rock", prob=254, param2=0},
		{name="everness:volcanic_rock", prob=254, param2=0},
		{name="air", prob=0, param2=0},
		{name="air", prob=0, param2=0},
		{name="air", prob=0, param2=0},
		{name="air", prob=0, param2=0},
		{name="air", prob=0, param2=0},
		{name="air", prob=0, param2=0},
		{name="air", prob=0, param2=0},
		{name="air", prob=0, param2=0},
		{name="everness:volcanic_rock", prob=254, param2=0},
		{name="everness:volcanic_rock", prob=254, param2=0},
		{name="everness:gravel", prob=254, param2=0},
		{name="everness:gravel", prob=254, param2=0},
		{name="everness:gravel", prob=254, param2=0},
		{name="everness:crystal_block_purple", prob=254, param2=0},
		{name="everness:crystal_block_purple", prob=254, param2=0},
		{name="everness:crystal_block_purple", prob=254, param2=0},
		{name="everness:gravel", prob=254, param2=0},
		{name="everness:gravel", prob=254, param2=0},
		{name="everness:gravel", prob=254, param2=0},
		{name="everness:volcanic_rock", prob=254, param2=0},
		{name="everness:volcanic_rock", prob=254, param2=0},
		{name="air", prob=0, param2=0},
		{name="air", prob=0, param2=0},
		{name="air", prob=0, param2=0},
		{name="air", prob=0, param2=0},
		{name="air", prob=0, param2=0},
		{name="air", prob=0, param2=0},
		{name="air", prob=0, param2=0},
		{name="everness:volcanic_rock", prob=254, param2=0},
		{name="everness:gravel", prob=254, param2=0},
		{name="everness:gravel", prob=254, param2=0},
		{name="everness:crystal_block_purple", prob=254, param2=0},
		{name="everness:crystal_block_purple", prob=254, param2=0},
		{name="everness:crystal_block_purple", prob=254, param2=0},
		{name="everness:crystal_block_purple", prob=254, param2=0},
		{name="everness:crystal_block_purple", prob=254, param2=0},
		{name="everness:crystal_block_purple", prob=254, param2=0},
		{name="everness:crystal_block_purple", prob=254, param2=0},
		{name="everness:gravel", prob=254, param2=0},
		{name="everness:gravel", prob=254, param2=0},
		{name="everness:volcanic_rock", prob=254, param2=0},
		{name="air", prob=0, param2=0},
		{name="air", prob=0, param2=0},
		{name="air", prob=0, param2=0},
		{name="air", prob=0, param2=0},
		{name="air", prob=0, param2=0},
		{name="air", prob=0, param2=0},
		{name="everness:volcanic_rock", prob=254, param2=0},
		{name="everness:volcanic_rock", prob=254, param2=0},
		{name="everness:gravel", prob=254, param2=0},
		{name="everness:gravel", prob=254, param2=0},
		{name="everness:crystal_block_purple", prob=254, param2=0},
		{name="everness:crystal_block_purple", prob=254, param2=0},
		{name="air", prob=254, param2=0},
		{name="everness:crystal_purple", prob=126, param2=1},
		{name="air", prob=254, param2=0},
		{name="everness:crystal_block_purple", prob=254, param2=0},
		{name="everness:crystal_block_purple", prob=254, param2=0},
		{name="everness:gravel", prob=254, param2=0},
		{name="everness:gravel", prob=254, param2=0},
		{name="everness:volcanic_rock", prob=254, param2=0},
		{name="everness:volcanic_rock", prob=254, param2=0},
		{name="air", prob=0, param2=0},
		{name="air", prob=0, param2=0},
		{name="air", prob=0, param2=0},
		{name="air", prob=0, param2=0},
		{name="air", prob=0, param2=0},
		{name="everness:volcanic_rock", prob=254, param2=0},
		{name="everness:volcanic_rock", prob=254, param2=0},
		{name="everness:gravel", prob=254, param2=0},
		{name="everness:crystal_block_purple", prob=254, param2=0},
		{name="everness:crystal_block_purple", prob=254, param2=0},
		{name="air", prob=254, param2=0},
		{name="air", prob=254, param2=0},
		{name="everness:crystal_purple", prob=126, param2=5},
		{name="air", prob=254, param2=0},
		{name="air", prob=254, param2=0},
		{name="everness:crystal_block_purple", prob=254, param2=0},
		{name="everness:crystal_block_purple", prob=254, param2=0},
		{name="everness:gravel", prob=254, param2=0},
		{name="everness:volcanic_rock", prob=254, param2=0},
		{name="everness:volcanic_rock", prob=254, param2=0},
		{name="air", prob=0, param2=0},
		{name="air", prob=0, param2=0},
		{name="air", prob=0, param2=0},
		{name="air", prob=0, param2=0},
		{name="air", prob=0, param2=0},
		{name="everness:volcanic_rock", prob=254, param2=0},
		{name="everness:gravel", prob=254, param2=0},
		{name="everness:gravel", prob=254, param2=0},
		{name="everness:crystal_block_purple", prob=254, param2=0},
		{name="everness:crystal_block_purple", prob=254, param2=0},
		{name="air", prob=254, param2=0},
		{name="air", prob=254, param2=0},
		{name="air", prob=254, param2=0},
		{name="air", prob=254, param2=0},
		{name="air", prob=254, param2=0},
		{name="everness:crystal_block_purple", prob=254, param2=0},
		{name="everness:crystal_block_purple", prob=254, param2=0},
		{name="everness:gravel", prob=254, param2=0},
		{name="everness:gravel", prob=254, param2=0},
		{name="everness:volcanic_rock", prob=254, param2=0},
		{name="air", prob=0, param2=0},
		{name="air", prob=0, param2=0},
		{name="air", prob=0, param2=0},
		{name="air", prob=0, param2=0},
		{name="air", prob=0, param2=0},
		{name="everness:volcanic_rock", prob=254, param2=0},
		{name="everness:volcanic_rock", prob=254, param2=0},
		{name="everness:gravel", prob=254, param2=0},
		{name="everness:crystal_block_purple", prob=254, param2=0},
		{name="everness:crystal_block_purple", prob=254, param2=0},
		{name="air", prob=254, param2=0},
		{name="air", prob=254, param2=0},
		{name="air", prob=254, param2=0},
		{name="everness:crystal_purple", prob=126, param2=5},
		{name="air", prob=254, param2=0},
		{name="everness:crystal_block_purple", prob=254, param2=0},
		{name="everness:crystal_block_purple", prob=254, param2=0},
		{name="everness:gravel", prob=254, param2=0},
		{name="everness:volcanic_rock", prob=254, param2=0},
		{name="everness:volcanic_rock", prob=254, param2=0},
		{name="air", prob=0, param2=0},
		{name="air", prob=0, param2=0},
		{name="air", prob=0, param2=0},
		{name="air", prob=0, param2=0},
		{name="air", prob=0, param2=0},
		{name="everness:volcanic_rock", prob=254, param2=0},
		{name="everness:volcanic_rock", prob=254, param2=0},
		{name="everness:gravel", prob=254, param2=0},
		{name="everness:gravel", prob=254, param2=0},
		{name="everness:crystal_block_purple", prob=254, param2=0},
		{name="everness:crystal_block_purple", prob=254, param2=0},
		{name="air", prob=254, param2=0},
		{name="air", prob=254, param2=0},
		{name="air", prob=254, param2=0},
		{name="everness:crystal_block_purple", prob=254, param2=0},
		{name="everness:crystal_block_purple", prob=254, param2=0},
		{name="everness:gravel", prob=254, param2=0},
		{name="everness:gravel", prob=254, param2=0},
		{name="everness:volcanic_rock", prob=254, param2=0},
		{name="everness:volcanic_rock", prob=254, param2=0},
		{name="air", prob=0, param2=0},
		{name="air", prob=0, param2=0},
		{name="air", prob=0, param2=0},
		{name="air", prob=0, param2=0},
		{name="air", prob=0, param2=0},
		{name="air", prob=0, param2=0},
		{name="everness:volcanic_rock", prob=254, param2=0},
		{name="everness:gravel", prob=254, param2=0},
		{name="everness:gravel", prob=254, param2=0},
		{name="everness:crystal_block_purple", prob=254, param2=0},
		{name="everness:crystal_block_purple", prob=254, param2=0},
		{name="everness:crystal_block_purple", prob=254, param2=0},
		{name="everness:crystal_block_purple", prob=254, param2=0},
		{name="everness:crystal_block_purple", prob=254, param2=0},
		{name="everness:crystal_block_purple", prob=254, param2=0},
		{name="everness:crystal_block_purple", prob=254, param2=0},
		{name="everness:gravel", prob=254, param2=0},
		{name="everness:gravel", prob=254, param2=0},
		{name="everness:volcanic_rock", prob=254, param2=0},
		{name="air", prob=0, param2=0},
		{name="air", prob=0, param2=0},
		{name="air", prob=0, param2=0},
		{name="air", prob=0, param2=0},
		{name="air", prob=0, param2=0},
		{name="air", prob=0, param2=0},
		{name="air", prob=0, param2=0},
		{name="everness:volcanic_rock", prob=254, param2=0},
		{name="everness:volcanic_rock", prob=254, param2=0},
		{name="everness:gravel", prob=254, param2=0},
		{name="everness:gravel", prob=254, param2=0},
		{name="everness:gravel", prob=254, param2=0},
		{name="everness:crystal_block_purple", prob=254, param2=0},
		{name="everness:crystal_block_purple", prob=254, param2=0},
		{name="everness:crystal_block_purple", prob=254, param2=0},
		{name="everness:gravel", prob=254, param2=0},
		{name="everness:gravel", prob=254, param2=0},
		{name="everness:gravel", prob=254, param2=0},
		{name="everness:volcanic_rock", prob=254, param2=0},
		{name="everness:volcanic_rock", prob=254, param2=0},
		{name="air", prob=0, param2=0},
		{name="air", prob=0, param2=0},
		{name="air", prob=0, param2=0},
		{name="air", prob=0, param2=0},
		{name="air", prob=0, param2=0},
		{name="air", prob=0, param2=0},
		{name="air", prob=0, param2=0},
		{name="air", prob=0, param2=0},
		{name="everness:volcanic_rock", prob=254, param2=0},
		{name="everness:volcanic_rock", prob=254, param2=0},
		{name="everness:gravel", prob=254, param2=0},
		{name="everness:gravel", prob=254, param2=0},
		{name="everness:gravel", prob=254, param2=0},
		{name="everness:gravel", prob=254, param2=0},
		{name="everness:gravel", prob=254, param2=0},
		{name="everness:gravel", prob=254, param2=0},
		{name="everness:gravel", prob=254, param2=0},
		{name="everness:volcanic_rock", prob=254, param2=0},
		{name="everness:volcanic_rock", prob=254, param2=0},
		{name="air", prob=0, param2=0},
		{name="air", prob=0, param2=0},
		{name="air", prob=0, param2=0},
		{name="air", prob=0, param2=0},
		{name="air", prob=0, param2=0},
		{name="air", prob=0, param2=0},
		{name="air", prob=0, param2=0},
		{name="air", prob=0, param2=0},
		{name="air", prob=0, param2=0},
		{name="air", prob=0, param2=0},
		{name="everness:volcanic_rock", prob=254, param2=0},
		{name="everness:volcanic_rock", prob=254, param2=0},
		{name="everness:volcanic_rock", prob=254, param2=0},
		{name="everness:volcanic_rock", prob=254, param2=0},
		{name="everness:gravel", prob=254, param2=0},
		{name="everness:volcanic_rock", prob=254, param2=0},
		{name="everness:volcanic_rock", prob=254, param2=0},
		{name="everness:volcanic_rock", prob=254, param2=0},
		{name="everness:volcanic_rock", prob=254, param2=0},
		{name="air", prob=0, param2=0},
		{name="air", prob=0, param2=0},
		{name="air", prob=0, param2=0},
		{name="air", prob=0, param2=0},
		{name="air", prob=0, param2=0},
		{name="air", prob=0, param2=0},
		{name="air", prob=0, param2=0},
		{name="air", prob=0, param2=0},
		{name="air", prob=0, param2=0},
		{name="air", prob=0, param2=0},
		{name="air", prob=0, param2=0},
		{name="air", prob=0, param2=0},
		{name="air", prob=0, param2=0},
		{name="everness:volcanic_rock", prob=254, param2=0},
		{name="everness:volcanic_rock", prob=254, param2=0},
		{name="everness:volcanic_rock", prob=254, param2=0},
		{name="everness:volcanic_rock", prob=254, param2=0},
		{name="everness:volcanic_rock", prob=254, param2=0},
		{name="air", prob=0, param2=0},
		{name="air", prob=0, param2=0},
		{name="air", prob=0, param2=0},
		{name="air", prob=0, param2=0},
		{name="air", prob=0, param2=0},
		{name="air", prob=0, param2=0},
		{name="air", prob=0, param2=0},
		{name="air", prob=0, param2=0},
		{name="air", prob=0, param2=0},
		{name="air", prob=0, param2=0},
		{name="air", prob=0, param2=0},
		{name="air", prob=0, param2=0},
		{name="air", prob=0, param2=0},
		{name="air", prob=0, param2=0},
		{name="air", prob=0, param2=0},
		{name="air", prob=0, param2=0},
		{name="air", prob=0, param2=0},
		{name="air", prob=0, param2=0},
		{name="air", prob=0, param2=0},
		{name="air", prob=0, param2=0},
		{name="air", prob=0, param2=0},
		{name="air", prob=0, param2=0},
		{name="air", prob=0, param2=0},
		{name="air", prob=0, param2=0},
		{name="air", prob=0, param2=0},
		{name="air", prob=0, param2=0},
		{name="air", prob=0, param2=0},
		{name="air", prob=0, param2=0},
		{name="air", prob=0, param2=0},
		{name="air", prob=0, param2=0},
		{name="air", prob=0, param2=0},
		{name="air", prob=0, param2=0},
		{name="air", prob=0, param2=0},
		{name="air", prob=0, param2=0},
		{name="air", prob=0, param2=0},
		{name="air", prob=0, param2=0},
		{name="air", prob=0, param2=0},
		{name="air", prob=0, param2=0},
		{name="air", prob=0, param2=0},
		{name="air", prob=0, param2=0},
		{name="air", prob=0, param2=0},
		{name="air", prob=0, param2=0},
		{name="air", prob=0, param2=0},
		{name="air", prob=0, param2=0},
		{name="air", prob=0, param2=0},
		{name="air", prob=0, param2=0},
		{name="air", prob=0, param2=0},
		{name="air", prob=0, param2=0},
		{name="air", prob=0, param2=0},
		{name="air", prob=0, param2=0},
		{name="air", prob=0, param2=0},
		{name="air", prob=0, param2=0},
		{name="air", prob=0, param2=0},
		{name="air", prob=0, param2=0},
		{name="air", prob=0, param2=0},
		{name="air", prob=0, param2=0},
		{name="air", prob=0, param2=0},
		{name="air", prob=0, param2=0},
		{name="air", prob=0, param2=0},
		{name="air", prob=0, param2=0},
		{name="air", prob=0, param2=0},
		{name="air", prob=0, param2=0},
		{name="air", prob=0, param2=0},
		{name="air", prob=0, param2=0},
		{name="air", prob=0, param2=0},
		{name="air", prob=0, param2=0},
		{name="air", prob=0, param2=0},
		{name="air", prob=0, param2=0},
		{name="air", prob=0, param2=0},
		{name="air", prob=0, param2=0},
		{name="air", prob=0, param2=0},
		{name="air", prob=0, param2=0},
		{name="air", prob=0, param2=0},
		{name="air", prob=0, param2=0},
		{name="air", prob=0, param2=0},
		{name="air", prob=0, param2=0},
		{name="everness:volcanic_rock", prob=254, param2=0},
		{name="everness:volcanic_rock", prob=254, param2=0},
		{name="everness:volcanic_rock", prob=254, param2=0},
		{name="air", prob=0, param2=0},
		{name="air", prob=0, param2=0},
		{name="air", prob=0, param2=0},
		{name="air", prob=0, param2=0},
		{name="air", prob=0, param2=0},
		{name="air", prob=0, param2=0},
		{name="air", prob=0, param2=0},
		{name="air", prob=0, param2=0},
		{name="air", prob=0, param2=0},
		{name="air", prob=0, param2=0},
		{name="air", prob=0, param2=0},
		{name="air", prob=0, param2=0},
		{name="air", prob=0, param2=0},
		{name="air", prob=0, param2=0},
		{name="everness:volcanic_rock", prob=254, param2=0},
		{name="everness:volcanic_rock", prob=254, param2=0},
		{name="everness:volcanic_rock", prob=254, param2=0},
		{name="everness:volcanic_rock", prob=254, param2=0},
		{name="everness:volcanic_rock", prob=254, param2=0},
		{name="everness:volcanic_rock", prob=254, param2=0},
		{name="everness:volcanic_rock", prob=254, param2=0},
		{name="everness:volcanic_rock", prob=254, param2=0},
		{name="everness:volcanic_rock", prob=254, param2=0},
		{name="air", prob=0, param2=0},
		{name="air", prob=0, param2=0},
		{name="air", prob=0, param2=0},
		{name="air", prob=0, param2=0},
		{name="air", prob=0, param2=0},
		{name="air", prob=0, param2=0},
		{name="air", prob=0, param2=0},
		{name="air", prob=0, param2=0},
		{name="air", prob=0, param2=0},
		{name="air", prob=0, param2=0},
		{name="everness:volcanic_rock", prob=254, param2=0},
		{name="everness:volcanic_rock", prob=254, param2=0},
		{name="everness:gravel", prob=254, param2=0},
		{name="everness:gravel", prob=254, param2=0},
		{name="everness:gravel", prob=254, param2=0},
		{name="everness:gravel", prob=254, param2=0},
		{name="everness:gravel", prob=254, param2=0},
		{name="everness:gravel", prob=254, param2=0},
		{name="everness:gravel", prob=254, param2=0},
		{name="everness:volcanic_rock", prob=254, param2=0},
		{name="everness:volcanic_rock", prob=254, param2=0},
		{name="air", prob=0, param2=0},
		{name="air", prob=0, param2=0},
		{name="air", prob=0, param2=0},
		{name="air", prob=0, param2=0},
		{name="air", prob=0, param2=0},
		{name="air", prob=0, param2=0},
		{name="air", prob=0, param2=0},
		{name="air", prob=0, param2=0},
		{name="everness:volcanic_rock", prob=254, param2=0},
		{name="everness:volcanic_rock", prob=254, param2=0},
		{name="everness:gravel", prob=254, param2=0},
		{name="everness:gravel", prob=254, param2=0},
		{name="everness:crystal_block_purple", prob=254, param2=0},
		{name="everness:crystal_block_purple", prob=254, param2=0},
		{name="everness:crystal_block_purple", prob=254, param2=0},
		{name="everness:crystal_block_purple", prob=254, param2=0},
		{name="everness:crystal_block_purple", prob=254, param2=0},
		{name="everness:gravel", prob=254, param2=0},
		{name="everness:gravel", prob=254, param2=0},
		{name="everness:volcanic_rock", prob=254, param2=0},
		{name="everness:volcanic_rock", prob=254, param2=0},
		{name="air", prob=0, param2=0},
		{name="air", prob=0, param2=0},
		{name="air", prob=0, param2=0},
		{name="air", prob=0, param2=0},
		{name="air", prob=0, param2=0},
		{name="air", prob=0, param2=0},
		{name="everness:volcanic_rock", prob=254, param2=0},
		{name="everness:volcanic_rock", prob=254, param2=0},
		{name="everness:gravel", prob=254, param2=0},
		{name="everness:gravel", prob=254, param2=0},
		{name="everness:crystal_block_purple", prob=254, param2=0},
		{name="everness:crystal_block_purple", prob=254, param2=0},
		{name="everness:crystal_block_purple", prob=254, param2=0},
		{name="air", prob=254, param2=0},
		{name="everness:crystal_block_purple", prob=254, param2=0},
		{name="everness:crystal_block_purple", prob=254, param2=0},
		{name="everness:crystal_block_purple", prob=254, param2=0},
		{name="everness:gravel", prob=254, param2=0},
		{name="everness:gravel", prob=254, param2=0},
		{name="everness:volcanic_rock", prob=254, param2=0},
		{name="everness:volcanic_rock", prob=254, param2=0},
		{name="air", prob=0, param2=0},
		{name="air", prob=0, param2=0},
		{name="air", prob=0, param2=0},
		{name="air", prob=0, param2=0},
		{name="air", prob=0, param2=0},
		{name="everness:volcanic_rock", prob=254, param2=0},
		{name="everness:gravel", prob=254, param2=0},
		{name="everness:gravel", prob=254, param2=0},
		{name="everness:crystal_block_purple", prob=254, param2=0},
		{name="everness:crystal_block_purple", prob=254, param2=0},
		{name="air", prob=254, param2=0},
		{name="everness:crystal_purple", prob=126, param2=1},
		{name="air", prob=254, param2=0},
		{name="air", prob=254, param2=0},
		{name="air", prob=254, param2=0},
		{name="everness:crystal_block_purple", prob=254, param2=0},
		{name="everness:crystal_block_purple", prob=254, param2=0},
		{name="everness:gravel", prob=254, param2=0},
		{name="everness:gravel", prob=254, param2=0},
		{name="everness:volcanic_rock", prob=254, param2=0},
		{name="air", prob=0, param2=0},
		{name="air", prob=0, param2=0},
		{name="air", prob=0, param2=0},
		{name="air", prob=0, param2=0},
		{name="air", prob=0, param2=0},
		{name="everness:volcanic_rock", prob=254, param2=0},
		{name="everness:gravel", prob=254, param2=0},
		{name="everness:crystal_block_purple", prob=254, param2=0},
		{name="everness:crystal_block_purple", prob=254, param2=0},
		{name="air", prob=254, param2=0},
		{name="everness:crystal_purple", prob=126, param2=5},
		{name="air", prob=254, param2=0},
		{name="air", prob=254, param2=0},
		{name="air", prob=254, param2=0},
		{name="air", prob=254, param2=0},
		{name="air", prob=254, param2=0},
		{name="everness:crystal_block_purple", prob=254, param2=0},
		{name="everness:crystal_block_purple", prob=254, param2=0},
		{name="everness:gravel", prob=254, param2=0},
		{name="everness:volcanic_rock", prob=254, param2=0},
		{name="air", prob=0, param2=0},
		{name="air", prob=0, param2=0},
		{name="air", prob=0, param2=0},
		{name="air", prob=0, param2=0},
		{name="everness:volcanic_rock", prob=254, param2=0},
		{name="everness:volcanic_rock", prob=254, param2=0},
		{name="everness:gravel", prob=254, param2=0},
		{name="everness:crystal_block_purple", prob=254, param2=0},
		{name="everness:crystal_block_purple", prob=254, param2=0},
		{name="air", prob=254, param2=0},
		{name="air", prob=254, param2=0},
		{name="air", prob=254, param2=0},
		{name="air", prob=254, param2=0},
		{name="air", prob=254, param2=0},
		{name="air", prob=254, param2=0},
		{name="air", prob=254, param2=0},
		{name="everness:crystal_block_purple", prob=254, param2=0},
		{name="everness:crystal_block_purple", prob=254, param2=0},
		{name="everness:gravel", prob=254, param2=0},
		{name="everness:volcanic_rock", prob=254, param2=0},
		{name="everness:volcanic_rock", prob=254, param2=0},
		{name="air", prob=0, param2=0},
		{name="air", prob=0, param2=0},
		{name="air", prob=0, param2=0},
		{name="everness:volcanic_rock", prob=254, param2=0},
		{name="everness:volcanic_rock", prob=254, param2=0},
		{name="everness:gravel", prob=254, param2=0},
		{name="everness:crystal_block_purple", prob=254, param2=0},
		{name="everness:crystal_purple", prob=126, param2=3},
		{name="air", prob=254, param2=0},
		{name="air", prob=254, param2=0},
		{name="air", prob=254, param2=0},
		{name="air", prob=254, param2=0},
		{name="air", prob=254, param2=0},
		{name="air", prob=254, param2=0},
		{name="air", prob=254, param2=0},
		{name="everness:crystal_purple", prob=126, param2=2},
		{name="everness:crystal_block_purple", prob=254, param2=0},
		{name="everness:gravel", prob=254, param2=0},
		{name="everness:volcanic_rock", prob=254, param2=0},
		{name="everness:volcanic_rock", prob=254, param2=0},
		{name="air", prob=0, param2=0},
		{name="air", prob=0, param2=0},
		{name="air", prob=0, param2=0},
		{name="everness:volcanic_rock", prob=254, param2=0},
		{name="everness:volcanic_rock", prob=254, param2=0},
		{name="everness:gravel", prob=254, param2=0},
		{name="everness:crystal_block_purple", prob=254, param2=0},
		{name="everness:crystal_block_purple", prob=254, param2=0},
		{name="everness:crystal_purple", prob=126, param2=3},
		{name="air", prob=254, param2=0},
		{name="air", prob=254, param2=0},
		{name="air", prob=254, param2=0},
		{name="air", prob=254, param2=0},
		{name="air", prob=254, param2=0},
		{name="air", prob=254, param2=0},
		{name="everness:crystal_block_purple", prob=254, param2=0},
		{name="everness:crystal_block_purple", prob=254, param2=0},
		{name="everness:gravel", prob=254, param2=0},
		{name="everness:volcanic_rock", prob=254, param2=0},
		{name="everness:volcanic_rock", prob=254, param2=0},
		{name="air", prob=0, param2=0},
		{name="air", prob=0, param2=0},
		{name="air", prob=0, param2=0},
		{name="air", prob=0, param2=0},
		{name="everness:volcanic_rock", prob=254, param2=0},
		{name="everness:gravel", prob=254, param2=0},
		{name="everness:crystal_block_purple", prob=254, param2=0},
		{name="everness:crystal_block_purple", prob=254, param2=0},
		{name="air", prob=254, param2=0},
		{name="air", prob=254, param2=0},
		{name="air", prob=254, param2=0},
		{name="air", prob=254, param2=0},
		{name="air", prob=254, param2=0},
		{name="air", prob=254, param2=0},
		{name="air", prob=254, param2=0},
		{name="everness:crystal_block_purple", prob=254, param2=0},
		{name="everness:crystal_block_purple", prob=254, param2=0},
		{name="everness:gravel", prob=254, param2=0},
		{name="everness:volcanic_rock", prob=254, param2=0},
		{name="air", prob=0, param2=0},
		{name="air", prob=0, param2=0},
		{name="air", prob=0, param2=0},
		{name="air", prob=0, param2=0},
		{name="air", prob=0, param2=0},
		{name="everness:volcanic_rock", prob=254, param2=0},
		{name="everness:gravel", prob=254, param2=0},
		{name="everness:gravel", prob=254, param2=0},
		{name="everness:crystal_block_purple", prob=254, param2=0},
		{name="everness:crystal_block_purple", prob=254, param2=0},
		{name="air", prob=254, param2=0},
		{name="air", prob=254, param2=0},
		{name="air", prob=254, param2=0},
		{name="air", prob=254, param2=0},
		{name="air", prob=254, param2=0},
		{name="everness:crystal_block_purple", prob=254, param2=0},
		{name="everness:crystal_block_purple", prob=254, param2=0},
		{name="everness:gravel", prob=254, param2=0},
		{name="everness:gravel", prob=254, param2=0},
		{name="everness:volcanic_rock", prob=254, param2=0},
		{name="air", prob=0, param2=0},
		{name="air", prob=0, param2=0},
		{name="air", prob=0, param2=0},
		{name="air", prob=0, param2=0},
		{name="air", prob=0, param2=0},
		{name="everness:volcanic_rock", prob=254, param2=0},
		{name="everness:volcanic_rock", prob=254, param2=0},
		{name="everness:gravel", prob=254, param2=0},
		{name="everness:gravel", prob=254, param2=0},
		{name="everness:crystal_block_purple", prob=254, param2=0},
		{name="everness:crystal_block_purple", prob=254, param2=0},
		{name="everness:crystal_block_purple", prob=254, param2=0},
		{name="air", prob=254, param2=0},
		{name="everness:crystal_block_purple", prob=254, param2=0},
		{name="everness:crystal_block_purple", prob=254, param2=0},
		{name="everness:crystal_block_purple", prob=254, param2=0},
		{name="everness:gravel", prob=254, param2=0},
		{name="everness:gravel", prob=254, param2=0},
		{name="everness:volcanic_rock", prob=254, param2=0},
		{name="everness:volcanic_rock", prob=254, param2=0},
		{name="air", prob=0, param2=0},
		{name="air", prob=0, param2=0},
		{name="air", prob=0, param2=0},
		{name="air", prob=0, param2=0},
		{name="air", prob=0, param2=0},
		{name="air", prob=0, param2=0},
		{name="everness:volcanic_rock", prob=254, param2=0},
		{name="everness:volcanic_rock", prob=254, param2=0},
		{name="everness:gravel", prob=254, param2=0},
		{name="everness:gravel", prob=254, param2=0},
		{name="everness:crystal_block_purple", prob=254, param2=0},
		{name="everness:crystal_block_purple", prob=254, param2=0},
		{name="everness:crystal_block_purple", prob=254, param2=0},
		{name="everness:crystal_block_purple", prob=254, param2=0},
		{name="everness:crystal_block_purple", prob=254, param2=0},
		{name="everness:gravel", prob=254, param2=0},
		{name="everness:gravel", prob=254, param2=0},
		{name="everness:volcanic_rock", prob=254, param2=0},
		{name="everness:volcanic_rock", prob=254, param2=0},
		{name="air", prob=0, param2=0},
		{name="air", prob=0, param2=0},
		{name="air", prob=0, param2=0},
		{name="air", prob=0, param2=0},
		{name="air", prob=0, param2=0},
		{name="air", prob=0, param2=0},
		{name="air", prob=0, param2=0},
		{name="air", prob=0, param2=0},
		{name="everness:volcanic_rock", prob=254, param2=0},
		{name="everness:volcanic_rock", prob=254, param2=0},
		{name="everness:gravel", prob=254, param2=0},
		{name="everness:gravel", prob=254, param2=0},
		{name="everness:gravel", prob=254, param2=0},
		{name="everness:gravel", prob=254, param2=0},
		{name="everness:gravel", prob=254, param2=0},
		{name="everness:gravel", prob=254, param2=0},
		{name="everness:gravel", prob=254, param2=0},
		{name="everness:volcanic_rock", prob=254, param2=0},
		{name="everness:volcanic_rock", prob=254, param2=0},
		{name="air", prob=0, param2=0},
		{name="air", prob=0, param2=0},
		{name="air", prob=0, param2=0},
		{name="air", prob=0, param2=0},
		{name="air", prob=0, param2=0},
		{name="air", prob=0, param2=0},
		{name="air", prob=0, param2=0},
		{name="air", prob=0, param2=0},
		{name="air", prob=0, param2=0},
		{name="air", prob=0, param2=0},
		{name="everness:volcanic_rock", prob=254, param2=0},
		{name="everness:volcanic_rock", prob=254, param2=0},
		{name="everness:volcanic_rock", prob=254, param2=0},
		{name="everness:volcanic_rock", prob=254, param2=0},
		{name="everness:volcanic_rock", prob=254, param2=0},
		{name="everness:volcanic_rock", prob=254, param2=0},
		{name="everness:volcanic_rock", prob=254, param2=0},
		{name="everness:volcanic_rock", prob=254, param2=0},
		{name="everness:volcanic_rock", prob=254, param2=0},
		{name="air", prob=0, param2=0},
		{name="air", prob=0, param2=0},
		{name="air", prob=0, param2=0},
		{name="air", prob=0, param2=0},
		{name="air", prob=0, param2=0},
		{name="air", prob=0, param2=0},
		{name="air", prob=0, param2=0},
		{name="air", prob=0, param2=0},
		{name="air", prob=0, param2=0},
		{name="air", prob=0, param2=0},
		{name="air", prob=0, param2=0},
		{name="air", prob=0, param2=0},
		{name="air", prob=0, param2=0},
		{name="air", prob=0, param2=0},
		{name="everness:volcanic_rock", prob=254, param2=0},
		{name="everness:volcanic_rock", prob=254, param2=0},
		{name="everness:volcanic_rock", prob=254, param2=0},
		{name="air", prob=0, param2=0},
		{name="air", prob=0, param2=0},
		{name="air", prob=0, param2=0},
		{name="air", prob=0, param2=0},
		{name="air", prob=0, param2=0},
		{name="air", prob=0, param2=0},
		{name="air", prob=0, param2=0},
		{name="air", prob=0, param2=0},
		{name="air", prob=0, param2=0},
		{name="air", prob=0, param2=0},
		{name="air", prob=0, param2=0},
		{name="air", prob=0, param2=0},
		{name="air", prob=0, param2=0},
		{name="air", prob=0, param2=0},
		{name="air", prob=0, param2=0},
		{name="air", prob=0, param2=0},
		{name="air", prob=0, param2=0},
		{name="air", prob=0, param2=0},
		{name="air", prob=0, param2=0},
		{name="air", prob=0, param2=0},
		{name="air", prob=0, param2=0},
		{name="air", prob=0, param2=0},
		{name="air", prob=0, param2=0},
		{name="air", prob=0, param2=0},
		{name="air", prob=0, param2=0},
		{name="air", prob=0, param2=0},
		{name="air", prob=0, param2=0},
		{name="air", prob=0, param2=0},
		{name="air", prob=0, param2=0},
		{name="air", prob=0, param2=0},
		{name="air", prob=0, param2=0},
		{name="air", prob=0, param2=0},
		{name="air", prob=0, param2=0},
		{name="air", prob=0, param2=0},
		{name="air", prob=0, param2=0},
		{name="air", prob=0, param2=0},
		{name="air", prob=0, param2=0},
		{name="air", prob=0, param2=0},
		{name="air", prob=0, param2=0},
		{name="air", prob=0, param2=0},
		{name="air", prob=0, param2=0},
		{name="air", prob=0, param2=0},
		{name="air", prob=0, param2=0},
		{name="air", prob=0, param2=0},
		{name="air", prob=0, param2=0},
		{name="air", prob=0, param2=0},
		{name="air", prob=0, param2=0},
		{name="air", prob=0, param2=0},
		{name="air", prob=0, param2=0},
		{name="air", prob=0, param2=0},
		{name="air", prob=0, param2=0},
		{name="air", prob=0, param2=0},
		{name="air", prob=0, param2=0},
		{name="air", prob=0, param2=0},
		{name="air", prob=0, param2=0},
		{name="everness:volcanic_rock", prob=254, param2=0},
		{name="everness:volcanic_rock", prob=254, param2=0},
		{name="everness:volcanic_rock", prob=254, param2=0},
		{name="everness:volcanic_rock", prob=254, param2=0},
		{name="everness:volcanic_rock", prob=254, param2=0},
		{name="everness:volcanic_rock", prob=254, param2=0},
		{name="everness:volcanic_rock", prob=254, param2=0},
		{name="air", prob=0, param2=0},
		{name="air", prob=0, param2=0},
		{name="air", prob=0, param2=0},
		{name="air", prob=0, param2=0},
		{name="air", prob=0, param2=0},
		{name="air", prob=0, param2=0},
		{name="air", prob=0, param2=0},
		{name="air", prob=0, param2=0},
		{name="air", prob=0, param2=0},
		{name="air", prob=0, param2=0},
		{name="air", prob=0, param2=0},
		{name="everness:volcanic_rock", prob=254, param2=0},
		{name="everness:volcanic_rock", prob=254, param2=0},
		{name="everness:volcanic_rock", prob=254, param2=0},
		{name="everness:gravel", prob=254, param2=0},
		{name="everness:gravel", prob=254, param2=0},
		{name="everness:gravel", prob=254, param2=0},
		{name="everness:gravel", prob=254, param2=0},
		{name="everness:gravel", prob=254, param2=0},
		{name="everness:volcanic_rock", prob=254, param2=0},
		{name="everness:volcanic_rock", prob=254, param2=0},
		{name="everness:volcanic_rock", prob=254, param2=0},
		{name="air", prob=0, param2=0},
		{name="air", prob=0, param2=0},
		{name="air", prob=0, param2=0},
		{name="air", prob=0, param2=0},
		{name="air", prob=0, param2=0},
		{name="air", prob=0, param2=0},
		{name="air", prob=0, param2=0},
		{name="air", prob=0, param2=0},
		{name="everness:volcanic_rock", prob=254, param2=0},
		{name="everness:volcanic_rock", prob=254, param2=0},
		{name="everness:gravel", prob=254, param2=0},
		{name="everness:gravel", prob=254, param2=0},
		{name="everness:gravel", prob=254, param2=0},
		{name="everness:crystal_block_purple", prob=254, param2=0},
		{name="everness:crystal_block_purple", prob=254, param2=0},
		{name="everness:crystal_block_purple", prob=254, param2=0},
		{name="everness:gravel", prob=254, param2=0},
		{name="everness:gravel", prob=254, param2=0},
		{name="everness:gravel", prob=254, param2=0},
		{name="everness:volcanic_rock", prob=254, param2=0},
		{name="everness:volcanic_rock", prob=254, param2=0},
		{name="air", prob=0, param2=0},
		{name="air", prob=0, param2=0},
		{name="air", prob=0, param2=0},
		{name="air", prob=0, param2=0},
		{name="air", prob=0, param2=0},
		{name="air", prob=0, param2=0},
		{name="everness:volcanic_rock", prob=254, param2=0},
		{name="everness:volcanic_rock", prob=254, param2=0},
		{name="everness:gravel", prob=254, param2=0},
		{name="everness:gravel", prob=254, param2=0},
		{name="everness:crystal_block_purple", prob=254, param2=0},
		{name="everness:crystal_block_purple", prob=254, param2=0},
		{name="everness:crystal_block_purple", prob=254, param2=0},
		{name="air", prob=254, param2=0},
		{name="everness:crystal_block_purple", prob=254, param2=0},
		{name="everness:crystal_block_purple", prob=254, param2=0},
		{name="everness:crystal_block_purple", prob=254, param2=0},
		{name="everness:gravel", prob=254, param2=0},
		{name="everness:gravel", prob=254, param2=0},
		{name="everness:volcanic_rock", prob=254, param2=0},
		{name="everness:volcanic_rock", prob=254, param2=0},
		{name="air", prob=0, param2=0},
		{name="air", prob=0, param2=0},
		{name="air", prob=0, param2=0},
		{name="air", prob=0, param2=0},
		{name="air", prob=0, param2=0},
		{name="everness:volcanic_rock", prob=254, param2=0},
		{name="everness:gravel", prob=254, param2=0},
		{name="everness:gravel", prob=254, param2=0},
		{name="everness:crystal_block_purple", prob=254, param2=0},
		{name="air", prob=254, param2=0},
		{name="air", prob=254, param2=0},
		{name="air", prob=254, param2=0},
		{name="air", prob=254, param2=0},
		{name="air", prob=254, param2=0},
		{name="air", prob=254, param2=0},
		{name="air", prob=254, param2=0},
		{name="everness:crystal_block_purple", prob=254, param2=0},
		{name="everness:gravel", prob=254, param2=0},
		{name="everness:gravel", prob=254, param2=0},
		{name="everness:volcanic_rock", prob=254, param2=0},
		{name="air", prob=0, param2=0},
		{name="air", prob=0, param2=0},
		{name="air", prob=0, param2=0},
		{name="air", prob=0, param2=0},
		{name="everness:volcanic_rock", prob=254, param2=0},
		{name="everness:volcanic_rock", prob=254, param2=0},
		{name="everness:gravel", prob=254, param2=0},
		{name="everness:crystal_block_purple", prob=254, param2=0},
		{name="air", prob=254, param2=0},
		{name="air", prob=254, param2=0},
		{name="air", prob=254, param2=0},
		{name="air", prob=254, param2=0},
		{name="air", prob=254, param2=0},
		{name="air", prob=254, param2=0},
		{name="air", prob=254, param2=0},
		{name="air", prob=254, param2=0},
		{name="air", prob=254, param2=0},
		{name="everness:crystal_block_purple", prob=254, param2=0},
		{name="everness:gravel", prob=254, param2=0},
		{name="everness:volcanic_rock", prob=254, param2=0},
		{name="everness:volcanic_rock", prob=254, param2=0},
		{name="air", prob=0, param2=0},
		{name="air", prob=0, param2=0},
		{name="air", prob=0, param2=0},
		{name="everness:volcanic_rock", prob=254, param2=0},
		{name="everness:gravel", prob=254, param2=0},
		{name="everness:gravel", prob=254, param2=0},
		{name="everness:crystal_block_purple", prob=254, param2=0},
		{name="air", prob=254, param2=0},
		{name="air", prob=254, param2=0},
		{name="air", prob=254, param2=0},
		{name="air", prob=254, param2=0},
		{name="air", prob=254, param2=0},
		{name="air", prob=254, param2=0},
		{name="air", prob=254, param2=0},
		{name="air", prob=254, param2=0},
		{name="air", prob=254, param2=0},
		{name="everness:crystal_block_purple", prob=254, param2=0},
		{name="everness:gravel", prob=254, param2=0},
		{name="everness:gravel", prob=254, param2=0},
		{name="everness:volcanic_rock", prob=254, param2=0},
		{name="air", prob=0, param2=0},
		{name="air", prob=0, param2=0},
		{name="air", prob=0, param2=0},
		{name="everness:volcanic_rock", prob=254, param2=0},
		{name="everness:gravel", prob=254, param2=0},
		{name="everness:crystal_block_purple", prob=254, param2=0},
		{name="everness:crystal_block_purple", prob=254, param2=0},
		{name="everness:crystal_purple", prob=126, param2=3},
		{name="air", prob=254, param2=0},
		{name="air", prob=254, param2=0},
		{name="air", prob=254, param2=0},
		{name="air", prob=254, param2=0},
		{name="air", prob=254, param2=0},
		{name="air", prob=254, param2=0},
		{name="air", prob=254, param2=0},
		{name="air", prob=254, param2=0},
		{name="everness:crystal_block_purple", prob=254, param2=0},
		{name="everness:crystal_block_purple", prob=254, param2=0},
		{name="everness:gravel", prob=254, param2=0},
		{name="everness:volcanic_rock", prob=254, param2=0},
		{name="air", prob=0, param2=0},
		{name="air", prob=0, param2=0},
		{name="air", prob=0, param2=0},
		{name="everness:volcanic_rock", prob=254, param2=0},
		{name="everness:gravel", prob=254, param2=0},
		{name="everness:crystal_block_purple", prob=254, param2=0},
		{name="air", prob=254, param2=0},
		{name="air", prob=254, param2=0},
		{name="air", prob=254, param2=0},
		{name="air", prob=254, param2=0},
		{name="air", prob=254, param2=0},
		{name="air", prob=254, param2=0},
		{name="air", prob=254, param2=0},
		{name="air", prob=254, param2=0},
		{name="air", prob=254, param2=0},
		{name="air", prob=254, param2=0},
		{name="air", prob=254, param2=0},
		{name="everness:crystal_block_purple", prob=254, param2=0},
		{name="everness:gravel", prob=254, param2=0},
		{name="everness:volcanic_rock", prob=254, param2=0},
		{name="air", prob=254, param2=0},
		{name="air", prob=0, param2=0},
		{name="air", prob=0, param2=0},
		{name="everness:volcanic_rock", prob=254, param2=0},
		{name="everness:gravel", prob=254, param2=0},
		{name="everness:crystal_block_purple", prob=254, param2=0},
		{name="everness:crystal_block_purple", prob=254, param2=0},
		{name="air", prob=254, param2=0},
		{name="air", prob=254, param2=0},
		{name="air", prob=254, param2=0},
		{name="air", prob=254, param2=0},
		{name="air", prob=254, param2=0},
		{name="air", prob=254, param2=0},
		{name="air", prob=254, param2=0},
		{name="air", prob=254, param2=0},
		{name="air", prob=254, param2=0},
		{name="everness:crystal_block_purple", prob=254, param2=0},
		{name="everness:crystal_block_purple", prob=254, param2=0},
		{name="everness:gravel", prob=254, param2=0},
		{name="everness:volcanic_rock", prob=254, param2=0},
		{name="air", prob=0, param2=0},
		{name="air", prob=0, param2=0},
		{name="air", prob=0, param2=0},
		{name="everness:volcanic_rock", prob=254, param2=0},
		{name="everness:gravel", prob=254, param2=0},
		{name="everness:gravel", prob=254, param2=0},
		{name="everness:crystal_block_purple", prob=254, param2=0},
		{name="air", prob=254, param2=0},
		{name="air", prob=254, param2=0},
		{name="air", prob=254, param2=0},
		{name="air", prob=254, param2=0},
		{name="air", prob=254, param2=0},
		{name="air", prob=254, param2=0},
		{name="air", prob=254, param2=0},
		{name="air", prob=254, param2=0},
		{name="air", prob=254, param2=0},
		{name="everness:crystal_block_purple", prob=254, param2=0},
		{name="everness:gravel", prob=254, param2=0},
		{name="everness:gravel", prob=254, param2=0},
		{name="everness:volcanic_rock", prob=254, param2=0},
		{name="air", prob=0, param2=0},
		{name="air", prob=0, param2=0},
		{name="air", prob=0, param2=0},
		{name="everness:volcanic_rock", prob=254, param2=0},
		{name="everness:volcanic_rock", prob=254, param2=0},
		{name="everness:gravel", prob=254, param2=0},
		{name="everness:crystal_block_purple", prob=254, param2=0},
		{name="air", prob=254, param2=0},
		{name="air", prob=254, param2=0},
		{name="air", prob=254, param2=0},
		{name="air", prob=254, param2=0},
		{name="air", prob=254, param2=0},
		{name="air", prob=254, param2=0},
		{name="air", prob=254, param2=0},
		{name="air", prob=254, param2=0},
		{name="air", prob=254, param2=0},
		{name="everness:crystal_block_purple", prob=254, param2=0},
		{name="everness:gravel", prob=254, param2=0},
		{name="everness:volcanic_rock", prob=254, param2=0},
		{name="everness:volcanic_rock", prob=254, param2=0},
		{name="air", prob=0, param2=0},
		{name="air", prob=0, param2=0},
		{name="air", prob=0, param2=0},
		{name="air", prob=0, param2=0},
		{name="everness:volcanic_rock", prob=254, param2=0},
		{name="everness:gravel", prob=254, param2=0},
		{name="everness:gravel", prob=254, param2=0},
		{name="everness:crystal_block_purple", prob=254, param2=0},
		{name="air", prob=254, param2=0},
		{name="everness:crystal_purple", prob=126, param2=0},
		{name="air", prob=254, param2=0},
		{name="air", prob=254, param2=0},
		{name="everness:crystal_purple", prob=126, param2=5},
		{name="air", prob=254, param2=0},
		{name="air", prob=254, param2=0},
		{name="everness:crystal_block_purple", prob=254, param2=0},
		{name="everness:gravel", prob=254, param2=0},
		{name="everness:gravel", prob=254, param2=0},
		{name="everness:volcanic_rock", prob=254, param2=0},
		{name="air", prob=0, param2=0},
		{name="air", prob=0, param2=0},
		{name="air", prob=0, param2=0},
		{name="air", prob=0, param2=0},
		{name="air", prob=0, param2=0},
		{name="everness:volcanic_rock", prob=254, param2=0},
		{name="everness:volcanic_rock", prob=254, param2=0},
		{name="everness:gravel", prob=254, param2=0},
		{name="everness:gravel", prob=254, param2=0},
		{name="everness:crystal_block_purple", prob=254, param2=0},
		{name="everness:crystal_block_purple", prob=254, param2=0},
		{name="everness:crystal_block_purple", prob=254, param2=0},
		{name="air", prob=254, param2=0},
		{name="everness:crystal_block_purple", prob=254, param2=0},
		{name="everness:crystal_block_purple", prob=254, param2=0},
		{name="everness:crystal_block_purple", prob=254, param2=0},
		{name="everness:gravel", prob=254, param2=0},
		{name="everness:gravel", prob=254, param2=0},
		{name="everness:volcanic_rock", prob=254, param2=0},
		{name="everness:volcanic_rock", prob=254, param2=0},
		{name="air", prob=0, param2=0},
		{name="air", prob=0, param2=0},
		{name="air", prob=0, param2=0},
		{name="air", prob=0, param2=0},
		{name="air", prob=0, param2=0},
		{name="air", prob=0, param2=0},
		{name="everness:volcanic_rock", prob=254, param2=0},
		{name="everness:volcanic_rock", prob=254, param2=0},
		{name="everness:gravel", prob=254, param2=0},
		{name="everness:gravel", prob=254, param2=0},
		{name="everness:gravel", prob=254, param2=0},
		{name="everness:crystal_block_purple", prob=254, param2=0},
		{name="everness:crystal_block_purple", prob=254, param2=0},
		{name="everness:crystal_block_purple", prob=254, param2=0},
		{name="everness:gravel", prob=254, param2=0},
		{name="everness:gravel", prob=254, param2=0},
		{name="everness:gravel", prob=254, param2=0},
		{name="everness:volcanic_rock", prob=254, param2=0},
		{name="everness:volcanic_rock", prob=254, param2=0},
		{name="air", prob=0, param2=0},
		{name="air", prob=0, param2=0},
		{name="air", prob=0, param2=0},
		{name="air", prob=0, param2=0},
		{name="air", prob=0, param2=0},
		{name="air", prob=0, param2=0},
		{name="air", prob=0, param2=0},
		{name="air", prob=0, param2=0},
		{name="everness:volcanic_rock", prob=254, param2=0},
		{name="everness:volcanic_rock", prob=254, param2=0},
		{name="everness:volcanic_rock", prob=254, param2=0},
		{name="everness:gravel", prob=254, param2=0},
		{name="everness:gravel", prob=254, param2=0},
		{name="everness:gravel", prob=254, param2=0},
		{name="everness:gravel", prob=254, param2=0},
		{name="everness:gravel", prob=254, param2=0},
		{name="everness:volcanic_rock", prob=254, param2=0},
		{name="everness:volcanic_rock", prob=254, param2=0},
		{name="everness:volcanic_rock", prob=254, param2=0},
		{name="air", prob=0, param2=0},
		{name="air", prob=0, param2=0},
		{name="air", prob=0, param2=0},
		{name="air", prob=0, param2=0},
		{name="air", prob=0, param2=0},
		{name="air", prob=0, param2=0},
		{name="air", prob=0, param2=0},
		{name="air", prob=0, param2=0},
		{name="air", prob=0, param2=0},
		{name="air", prob=0, param2=0},
		{name="air", prob=0, param2=0},
		{name="everness:volcanic_rock", prob=254, param2=0},
		{name="everness:volcanic_rock", prob=254, param2=0},
		{name="everness:volcanic_rock", prob=254, param2=0},
		{name="everness:volcanic_rock", prob=254, param2=0},
		{name="everness:volcanic_rock", prob=254, param2=0},
		{name="everness:volcanic_rock", prob=254, param2=0},
		{name="everness:volcanic_rock", prob=254, param2=0},
		{name="air", prob=0, param2=0},
		{name="air", prob=0, param2=0},
		{name="air", prob=0, param2=0},
		{name="air", prob=0, param2=0},
		{name="air", prob=0, param2=0},
		{name="air", prob=0, param2=0},
		{name="air", prob=0, param2=0},
		{name="air", prob=0, param2=0},
		{name="air", prob=0, param2=0},
		{name="air", prob=0, param2=0},
		{name="air", prob=0, param2=0},
		{name="air", prob=0, param2=0},
		{name="air", prob=0, param2=0},
		{name="air", prob=0, param2=0},
		{name="air", prob=0, param2=0},
		{name="air", prob=0, param2=0},
		{name="air", prob=0, param2=0},
		{name="air", prob=0, param2=0},
		{name="air", prob=0, param2=0},
		{name="air", prob=0, param2=0},
		{name="air", prob=0, param2=0},
		{name="air", prob=0, param2=0},
		{name="air", prob=0, param2=0},
		{name="air", prob=0, param2=0},
		{name="air", prob=0, param2=0},
		{name="air", prob=0, param2=0},
		{name="air", prob=0, param2=0},
		{name="air", prob=0, param2=0},
		{name="air", prob=0, param2=0},
		{name="air", prob=0, param2=0},
		{name="air", prob=0, param2=0},
		{name="air", prob=0, param2=0},
		{name="air", prob=0, param2=0},
		{name="air", prob=0, param2=0},
		{name="air", prob=0, param2=0},
		{name="air", prob=0, param2=0},
		{name="everness:volcanic_rock", prob=254, param2=0},
		{name="air", prob=0, param2=0},
		{name="air", prob=0, param2=0},
		{name="air", prob=0, param2=0},
		{name="air", prob=0, param2=0},
		{name="air", prob=0, param2=0},
		{name="air", prob=0, param2=0},
		{name="air", prob=0, param2=0},
		{name="air", prob=0, param2=0},
		{name="air", prob=0, param2=0},
		{name="air", prob=0, param2=0},
		{name="air", prob=0, param2=0},
		{name="air", prob=0, param2=0},
		{name="air", prob=0, param2=0},
		{name="air", prob=0, param2=0},
		{name="air", prob=0, param2=0},
		{name="everness:volcanic_rock", prob=254, param2=0},
		{name="everness:volcanic_rock", prob=254, param2=0},
		{name="everness:volcanic_rock", prob=254, param2=0},
		{name="everness:volcanic_rock", prob=254, param2=0},
		{name="everness:volcanic_rock", prob=254, param2=0},
		{name="everness:volcanic_rock", prob=254, param2=0},
		{name="everness:volcanic_rock", prob=254, param2=0},
		{name="everness:volcanic_rock", prob=254, param2=0},
		{name="everness:volcanic_rock", prob=254, param2=0},
		{name="air", prob=0, param2=0},
		{name="air", prob=0, param2=0},
		{name="air", prob=0, param2=0},
		{name="air", prob=0, param2=0},
		{name="air", prob=0, param2=0},
		{name="air", prob=0, param2=0},
		{name="air", prob=0, param2=0},
		{name="air", prob=0, param2=0},
		{name="air", prob=0, param2=0},
		{name="air", prob=0, param2=0},
		{name="everness:volcanic_rock", prob=254, param2=0},
		{name="everness:volcanic_rock", prob=254, param2=0},
		{name="everness:gravel", prob=254, param2=0},
		{name="everness:gravel", prob=254, param2=0},
		{name="everness:gravel", prob=254, param2=0},
		{name="everness:gravel", prob=254, param2=0},
		{name="everness:gravel", prob=254, param2=0},
		{name="everness:gravel", prob=254, param2=0},
		{name="everness:gravel", prob=254, param2=0},
		{name="everness:volcanic_rock", prob=254, param2=0},
		{name="everness:volcanic_rock", prob=254, param2=0},
		{name="air", prob=0, param2=0},
		{name="air", prob=0, param2=0},
		{name="air", prob=0, param2=0},
		{name="air", prob=0, param2=0},
		{name="air", prob=0, param2=0},
		{name="air", prob=0, param2=0},
		{name="air", prob=0, param2=0},
		{name="air", prob=0, param2=0},
		{name="everness:volcanic_rock", prob=254, param2=0},
		{name="everness:gravel", prob=254, param2=0},
		{name="everness:gravel", prob=254, param2=0},
		{name="everness:crystal_block_purple", prob=254, param2=0},
		{name="everness:crystal_block_purple", prob=254, param2=0},
		{name="everness:crystal_block_purple", prob=254, param2=0},
		{name="everness:crystal_block_purple", prob=254, param2=0},
		{name="everness:crystal_block_purple", prob=254, param2=0},
		{name="everness:crystal_block_purple", prob=254, param2=0},
		{name="everness:crystal_block_purple", prob=254, param2=0},
		{name="everness:gravel", prob=254, param2=0},
		{name="everness:gravel", prob=254, param2=0},
		{name="everness:volcanic_rock", prob=254, param2=0},
		{name="air", prob=0, param2=0},
		{name="air", prob=0, param2=0},
		{name="air", prob=0, param2=0},
		{name="air", prob=0, param2=0},
		{name="air", prob=0, param2=0},
		{name="air", prob=0, param2=0},
		{name="everness:volcanic_rock", prob=254, param2=0},
		{name="everness:gravel", prob=254, param2=0},
		{name="everness:gravel", prob=254, param2=0},
		{name="everness:crystal_block_purple", prob=254, param2=0},
		{name="everness:crystal_block_purple", prob=254, param2=0},
		{name="air", prob=254, param2=0},
		{name="air", prob=254, param2=0},
		{name="air", prob=254, param2=0},
		{name="everness:crystal_purple", prob=126, param2=5},
		{name="air", prob=254, param2=0},
		{name="everness:crystal_block_purple", prob=254, param2=0},
		{name="everness:crystal_block_purple", prob=254, param2=0},
		{name="everness:gravel", prob=254, param2=0},
		{name="everness:gravel", prob=254, param2=0},
		{name="everness:volcanic_rock", prob=254, param2=0},
		{name="air", prob=0, param2=0},
		{name="air", prob=0, param2=0},
		{name="air", prob=0, param2=0},
		{name="air", prob=0, param2=0},
		{name="everness:volcanic_rock", prob=254, param2=0},
		{name="everness:volcanic_rock", prob=254, param2=0},
		{name="everness:gravel", prob=254, param2=0},
		{name="everness:crystal_block_purple", prob=254, param2=0},
		{name="air", prob=254, param2=0},
		{name="air", prob=254, param2=0},
		{name="air", prob=254, param2=0},
		{name="air", prob=254, param2=0},
		{name="air", prob=254, param2=0},
		{name="air", prob=254, param2=0},
		{name="air", prob=254, param2=0},
		{name="everness:crystal_purple", prob=126, param2=1},
		{name="air", prob=254, param2=0},
		{name="everness:crystal_block_purple", prob=254, param2=0},
		{name="everness:gravel", prob=254, param2=0},
		{name="everness:volcanic_rock", prob=254, param2=0},
		{name="everness:volcanic_rock", prob=254, param2=0},
		{name="air", prob=0, param2=0},
		{name="air", prob=0, param2=0},
		{name="air", prob=0, param2=0},
		{name="everness:volcanic_rock", prob=254, param2=0},
		{name="everness:gravel", prob=254, param2=0},
		{name="everness:crystal_block_purple", prob=254, param2=0},
		{name="everness:crystal_block_purple", prob=254, param2=0},
		{name="air", prob=254, param2=0},
		{name="air", prob=254, param2=0},
		{name="air", prob=254, param2=0},
		{name="air", prob=254, param2=0},
		{name="air", prob=254, param2=0},
		{name="air", prob=254, param2=0},
		{name="air", prob=254, param2=0},
		{name="air", prob=254, param2=0},
		{name="air", prob=254, param2=0},
		{name="everness:crystal_block_purple", prob=254, param2=0},
		{name="everness:crystal_block_purple", prob=254, param2=0},
		{name="everness:gravel", prob=254, param2=0},
		{name="everness:volcanic_rock", prob=254, param2=0},
		{name="air", prob=0, param2=0},
		{name="air", prob=0, param2=0},
		{name="air", prob=0, param2=0},
		{name="everness:volcanic_rock", prob=254, param2=0},
		{name="everness:gravel", prob=254, param2=0},
		{name="everness:crystal_block_purple", prob=254, param2=0},
		{name="everness:crystal_purple", prob=126, param2=1},
		{name="air", prob=254, param2=0},
		{name="air", prob=254, param2=0},
		{name="air", prob=254, param2=0},
		{name="air", prob=254, param2=0},
		{name="air", prob=254, param2=0},
