schematic = {
	size = {x=1, y=14, z=1},
	yslice_prob = {
		{ypos=0, prob=254},
		{ypos=1, prob=254},
		{ypos=2, prob=254},
		{ypos=3, prob=254},
		{ypos=4, prob=170},
		{ypos=5, prob=170},
		{ypos=6, prob=170},
		{ypos=7, prob=170},
		{ypos=8, prob=170},
		{ypos=9, prob=170},
		{ypos=10, prob=170},
		{ypos=11, prob=170},
		{ypos=12, prob=170},
		{ypos=13, prob=170},
	},
	data = {
		{name="everness:dirt_with_grass_extras_2", prob=254, param2=0, force_place=true},
		{name="everness:bamboo_3", prob=254, param2=0},
		{name="everness:bamboo_3", prob=254, param2=0},
		{name="everness:bamboo_3", prob=254, param2=0},
		{name="everness:bamboo_3", prob=254, param2=0},
		{name="everness:bamboo_3", prob=254, param2=0},
		{name="everness:bamboo_3", prob=254, param2=0},
		{name="everness:bamboo_3", prob=254, param2=0},
		{name="everness:bamboo_3", prob=254, param2=0},
		{name="everness:bamboo_3", prob=254, param2=0},
		{name="everness:bamboo_3", prob=254, param2=0},
		{name="everness:bamboo_3", prob=254, param2=0},
		{name="everness:bamboo_3", prob=254, param2=0},
		{name="everness:bamboo_3", prob=254, param2=0},
	},
}
