schematic = {
	size = {x=7, y=16, z=9},
	yslice_prob = {
		{ypos=0, prob=254},
		{ypos=1, prob=254},
		{ypos=2, prob=254},
		{ypos=3, prob=254},
		{ypos=4, prob=254},
		{ypos=5, prob=254},
		{ypos=6, prob=254},
		{ypos=7, prob=254},
		{ypos=8, prob=254},
		{ypos=9, prob=254},
		{ypos=10, prob=254},
		{ypos=11, prob=254},
		{ypos=12, prob=254},
		{ypos=13, prob=254},
		{ypos=14, prob=254},
		{ypos=15, prob=254},
	},
	data = {
		{name="air", prob=0, param2=0},
		{name="air", prob=0, param2=0},
		{name="air", prob=0, param2=0},
		{name="air", prob=0, param2=0},
		{name="air", prob=0, param2=0},
		{name="air", prob=0, param2=0},
		{name="air", prob=0, param2=0},
		{name="air", prob=0, param2=0},
		{name="air", prob=0, param2=0},
		{name="air", prob=0, param2=0},
		{name="air", prob=0, param2=0},
		{name="air", prob=0, param2=0},
		{name="air", prob=0, param2=0},
		{name="air", prob=0, param2=0},
		{name="air", prob=0, param2=0},
		{name="air", prob=0, param2=0},
		{name="air", prob=0, param2=0},
		{name="air", prob=0, param2=0},
		{name="air", prob=0, param2=0},
		{name="air", prob=0, param2=0},
		{name="air", prob=0, param2=0},
		{name="air", prob=0, param2=0},
		{name="air", prob=0, param2=0},
		{name="air", prob=0, param2=0},
		{name="air", prob=0, param2=0},
		{name="air", prob=0, param2=0},
		{name="air", prob=0, param2=0},
		{name="air", prob=0, param2=0},
		{name="air", prob=0, param2=0},
		{name="air", prob=0, param2=0},
		{name="air", prob=0, param2=0},
		{name="stairs:slab_palm_tree_wood", prob=254, param2=0},
		{name="air", prob=0, param2=0},
		{name="air", prob=0, param2=0},
		{name="air", prob=0, param2=0},
		{name="air", prob=0, param2=0},
		{name="air", prob=0, param2=0},
		{name="air", prob=0, param2=0},
		{name="air", prob=0, param2=0},
		{name="air", prob=0, param2=0},
		{name="air", prob=0, param2=0},
		{name="air", prob=0, param2=0},
		{name="air", prob=0, param2=0},
		{name="air", prob=0, param2=0},
		{name="air", prob=0, param2=0},
		{name="air", prob=0, param2=0},
		{name="air", prob=0, param2=0},
		{name="air", prob=0, param2=0},
		{name="air", prob=0, param2=0},
		{name="air", prob=0, param2=0},
		{name="air", prob=0, param2=0},
		{name="air", prob=0, param2=0},
		{name="air", prob=0, param2=0},
		{name="air", prob=0, param2=0},
		{name="air", prob=0, param2=0},
		{name="air", prob=0, param2=0},
		{name="air", prob=0, param2=0},
		{name="air", prob=0, param2=0},
		{name="air", prob=0, param2=0},
		{name="stairs:slab_palm_tree_wood", prob=254, param2=0},
		{name="air", prob=0, param2=0},
		{name="air", prob=0, param2=0},
		{name="air", prob=0, param2=0},
		{name="air", prob=0, param2=0},
		{name="air", prob=0, param2=0},
		{name="air", prob=0, param2=0},
		{name="air", prob=0, param2=0},
		{name="air", prob=0, param2=0},
		{name="air", prob=0, param2=0},
		{name="air", prob=0, param2=0},
		{name="air", prob=0, param2=0},
		{name="air", prob=0, param2=0},
		{name="air", prob=0, param2=0},
		{name="air", prob=0, param2=0},
		{name="air", prob=0, param2=0},
		{name="air", prob=0, param2=0},
		{name="air", prob=0, param2=0},
		{name="air", prob=0, param2=0},
		{name="air", prob=0, param2=0},
		{name="air", prob=0, param2=0},
		{name="air", prob=0, param2=0},
		{name="air", prob=0, param2=0},
		{name="air", prob=0, param2=0},
		{name="air", prob=0, param2=0},
		{name="air", prob=0, param2=0},
		{name="air", prob=0, param2=0},
		{name="air", prob=0, param2=0},
		{name="stairs:slab_palm_tree_wood", prob=254, param2=3},
		{name="air", prob=0, param2=0},
		{name="air", prob=0, param2=0},
		{name="air", prob=0, param2=0},
		{name="air", prob=0, param2=0},
		{name="air", prob=0, param2=0},
		{name="air", prob=0, param2=0},
		{name="air", prob=0, param2=0},
		{name="air", prob=0, param2=0},
		{name="air", prob=0, param2=0},
		{name="air", prob=0, param2=0},
		{name="air", prob=0, param2=0},
		{name="air", prob=0, param2=0},
		{name="air", prob=0, param2=0},
		{name="air", prob=0, param2=0},
		{name="air", prob=0, param2=0},
		{name="air", prob=0, param2=0},
		{name="air", prob=0, param2=0},
		{name="air", prob=0, param2=0},
		{name="air", prob=0, param2=0},
		{name="air", prob=0, param2=0},
		{name="air", prob=0, param2=0},
		{name="air", prob=0, param2=0},
		{name="air", prob=0, param2=0},
		{name="air", prob=0, param2=0},
		{name="air", prob=0, param2=0},
		{name="everness:mineral_sandstone", prob=254, param2=0},
		{name="everness:mineral_sandstone", prob=254, param2=0},
		{name="everness:mineral_sandstone", prob=254, param2=0},
		{name="everness:mineral_sandstone", prob=254, param2=0},
		{name="everness:mineral_sandstone", prob=254, param2=0},
		{name="air", prob=0, param2=0},
		{name="air", prob=0, param2=0},
		{name="air", prob=0, param2=0},
		{name="everness:mineral_sandstone_brick_block", prob=254, param2=0},
		{name="everness:mineral_sandstone_brick_block", prob=254, param2=0},
		{name="everness:mineral_sandstone_brick_block", prob=254, param2=0},
		{name="air", prob=0, param2=0},
		{name="air", prob=0, param2=0},
		{name="air", prob=0, param2=0},
		{name="air", prob=0, param2=0},
		{name="everness:mineral_sandstone_brick", prob=254, param2=0},
		{name="everness:fence_palm_wood", prob=254, param2=0},
		{name="everness:mineral_sandstone_brick", prob=254, param2=0},
		{name="air", prob=0, param2=0},
		{name="air", prob=0, param2=0},
		{name="air", prob=0, param2=0},
		{name="air", prob=0, param2=0},
		{name="everness:mineral_sandstone_brick", prob=254, param2=0},
		{name="everness:fence_palm_wood", prob=254, param2=0},
		{name="everness:mineral_sandstone_brick", prob=254, param2=0},
		{name="air", prob=0, param2=0},
		{name="air", prob=0, param2=0},
		{name="air", prob=0, param2=0},
		{name="air", prob=0, param2=0},
		{name="everness:mineral_sandstone_brick_block", prob=254, param2=0},
		{name="stairs:stair_palm_tree_wood", prob=254, param2=0},
		{name="everness:mineral_sandstone_brick_block", prob=254, param2=0},
		{name="air", prob=0, param2=0},
		{name="air", prob=0, param2=0},
		{name="air", prob=0, param2=0},
		{name="air", prob=0, param2=0},
		{name="everness:mineral_sandstone_brick", prob=254, param2=0},
		{name="everness:mineral_sandstone_brick", prob=254, param2=0},
		{name="everness:mineral_sandstone_brick", prob=254, param2=0},
		{name="air", prob=0, param2=0},
		{name="air", prob=0, param2=0},
		{name="air", prob=0, param2=0},
		{name="air", prob=0, param2=0},
		{name="everness:mineral_sandstone_brick", prob=254, param2=0},
		{name="everness:fence_palm_wood", prob=254, param2=0},
		{name="everness:mineral_sandstone_brick", prob=254, param2=0},
		{name="air", prob=0, param2=0},
		{name="air", prob=0, param2=0},
		{name="air", prob=0, param2=0},
		{name="air", prob=0, param2=0},
		{name="everness:mineral_sandstone_brick", prob=254, param2=0},
		{name="everness:fence_palm_wood", prob=254, param2=0},
		{name="everness:mineral_sandstone_brick", prob=254, param2=0},
		{name="air", prob=0, param2=0},
		{name="air", prob=0, param2=0},
		{name="air", prob=0, param2=0},
		{name="air", prob=0, param2=0},
		{name="everness:mineral_sandstone_brick_block", prob=254, param2=0},
		{name="stairs:stair_palm_tree_wood", prob=254, param2=0},
		{name="everness:mineral_sandstone_brick_block", prob=254, param2=0},
		{name="air", prob=0, param2=0},
		{name="air", prob=0, param2=0},
		{name="air", prob=0, param2=0},
		{name="air", prob=0, param2=0},
		{name="everness:mineral_sandstone_brick", prob=254, param2=0},
		{name="everness:mineral_sandstone_brick", prob=254, param2=0},
		{name="everness:mineral_sandstone_brick", prob=254, param2=0},
		{name="air", prob=0, param2=0},
		{name="air", prob=0, param2=0},
		{name="air", prob=0, param2=0},
		{name="air", prob=0, param2=0},
		{name="everness:mineral_sandstone_brick", prob=254, param2=0},
		{name="everness:fence_palm_wood", prob=254, param2=0},
		{name="everness:mineral_sandstone_brick", prob=254, param2=0},
		{name="air", prob=0, param2=0},
		{name="air", prob=0, param2=0},
		{name="air", prob=0, param2=0},
		{name="air", prob=0, param2=0},
		{name="everness:mineral_sandstone_brick", prob=254, param2=0},
		{name="everness:fence_palm_wood", prob=254, param2=0},
		{name="everness:mineral_sandstone_brick", prob=254, param2=0},
		{name="air", prob=0, param2=0},
		{name="air", prob=0, param2=0},
		{name="air", prob=0, param2=0},
		{name="air", prob=0, param2=0},
		{name="everness:mineral_sandstone_brick_block", prob=254, param2=0},
		{name="stairs:stair_palm_tree_wood", prob=254, param2=0},
		{name="everness:mineral_sandstone_brick_block", prob=254, param2=0},
		{name="air", prob=0, param2=0},
		{name="air", prob=0, param2=0},
		{name="air", prob=0, param2=0},
		{name="air", prob=0, param2=0},
		{name="everness:mineral_sandstone_brick", prob=254, param2=0},
		{name="stairs:slab_mineral_sandstone_brick", prob=254, param2=1},
		{name="everness:mineral_sandstone_brick", prob=254, param2=0},
		{name="air", prob=0, param2=0},
		{name="air", prob=0, param2=0},
		{name="air", prob=0, param2=0},
		{name="air", prob=0, param2=0},
		{name="everness:fence_palm_wood", prob=254, param2=0},
		{name="air", prob=254, param2=0},
		{name="everness:fence_palm_wood", prob=254, param2=0},
		{name="air", prob=0, param2=0},
		{name="air", prob=0, param2=0},
		{name="air", prob=0, param2=0},
		{name="everness:fence_rail_palm_wood", prob=254, param2=0},
		{name="everness:fence_palm_wood", prob=254, param2=0},
		{name="everness:fence_rail_palm_wood", prob=254, param2=0},
		{name="everness:fence_palm_wood", prob=254, param2=0},
		{name="everness:fence_rail_palm_wood", prob=254, param2=0},
		{name="air", prob=0, param2=0},
		{name="air", prob=0, param2=0},
		{name="everness:mineral_sandstone", prob=254, param2=0},
		{name="everness:palm_tree_wood", prob=254, param2=0},
		{name="everness:palm_tree_wood", prob=254, param2=0},
		{name="everness:palm_tree_wood", prob=254, param2=0},
		{name="everness:mineral_sandstone", prob=254, param2=0},
		{name="air", prob=0, param2=0},
		{name="air", prob=0, param2=0},
		{name="everness:mineral_sandstone_brick_block", prob=254, param2=0},
		{name="air", prob=254, param2=0},
		{name="air", prob=254, param2=0},
		{name="everness:vine_cave_end", prob=254, param2=8},
		{name="everness:mineral_sandstone_brick_block", prob=254, param2=0},
		{name="air", prob=0, param2=0},
		{name="air", prob=0, param2=0},
		{name="everness:mineral_sandstone_brick", prob=254, param2=0},
		{name="air", prob=254, param2=0},
		{name="air", prob=254, param2=0},
		{name="everness:vine_cave", prob=254, param2=8},
		{name="everness:mineral_sandstone_brick", prob=254, param2=0},
		{name="air", prob=0, param2=0},
		{name="air", prob=0, param2=0},
		{name="everness:mineral_sandstone_brick", prob=254, param2=0},
		{name="air", prob=254, param2=0},
		{name="air", prob=254, param2=0},
		{name="everness:vine_cave", prob=254, param2=8},
		{name="everness:mineral_sandstone_brick", prob=254, param2=0},
		{name="air", prob=0, param2=0},
		{name="air", prob=0, param2=0},
		{name="everness:mineral_sandstone_brick_block", prob=254, param2=0},
		{name="stairs:slab_palm_tree_wood", prob=254, param2=22},
		{name="stairs:slab_palm_tree_wood", prob=254, param2=22},
		{name="everness:vine_cave", prob=254, param2=8},
		{name="everness:mineral_sandstone_brick_block", prob=254, param2=0},
		{name="air", prob=0, param2=0},
		{name="air", prob=0, param2=0},
		{name="everness:mineral_sandstone_brick", prob=254, param2=0},
		{name="everness:vine_cave_end", prob=254, param2=8},
		{name="air", prob=254, param2=0},
		{name="everness:vine_cave_with_mese_leaves", prob=254, param2=8},
		{name="everness:mineral_sandstone_brick", prob=254, param2=0},
		{name="air", prob=0, param2=0},
		{name="air", prob=0, param2=0},
		{name="everness:mineral_sandstone_brick", prob=254, param2=0},
		{name="everness:vine_cave", prob=254, param2=8},
		{name="air", prob=254, param2=0},
		{name="everness:vine_cave_with_mese_leaves", prob=254, param2=8},
		{name="everness:mineral_sandstone_brick", prob=254, param2=0},
		{name="air", prob=0, param2=0},
		{name="air", prob=0, param2=0},
		{name="everness:mineral_sandstone_brick", prob=254, param2=0},
		{name="everness:vine_cave", prob=254, param2=8},
		{name="air", prob=254, param2=0},
		{name="everness:vine_cave_with_mese_leaves", prob=254, param2=8},
		{name="everness:mineral_sandstone_brick", prob=254, param2=0},
		{name="air", prob=0, param2=0},
		{name="air", prob=0, param2=0},
		{name="everness:mineral_sandstone_brick_block", prob=254, param2=0},
		{name="everness:vine_cave", prob=254, param2=8},
		{name="air", prob=254, param2=0},
		{name="everness:vine_cave_with_mese_leaves", prob=254, param2=8},
		{name="everness:mineral_sandstone_brick_block", prob=254, param2=0},
		{name="air", prob=0, param2=0},
		{name="air", prob=0, param2=0},
		{name="everness:mineral_sandstone_brick", prob=254, param2=0},
		{name="everness:vine_cave", prob=254, param2=8},
		{name="stairs:slab_palm_tree_wood", prob=254, param2=0},
		{name="stairs:slab_palm_tree_wood", prob=254, param2=0},
		{name="everness:mineral_sandstone_brick", prob=254, param2=0},
		{name="air", prob=0, param2=0},
		{name="air", prob=0, param2=0},
		{name="everness:mineral_sandstone_brick", prob=254, param2=0},
		{name="everness:vine_cave", prob=254, param2=8},
		{name="air", prob=254, param2=0},
		{name="air", prob=254, param2=0},
		{name="everness:mineral_sandstone_brick", prob=254, param2=0},
		{name="air", prob=0, param2=0},
		{name="air", prob=0, param2=0},
		{name="everness:mineral_sandstone_brick", prob=254, param2=0},
		{name="everness:vine_cave_with_mese_leaves", prob=254, param2=8},
		{name="air", prob=254, param2=0},
		{name="air", prob=254, param2=0},
		{name="everness:mineral_sandstone_brick", prob=254, param2=0},
		{name="air", prob=0, param2=0},
		{name="air", prob=0, param2=0},
		{name="everness:mineral_sandstone_brick_block", prob=254, param2=0},
		{name="stairs:slab_palm_tree_wood", prob=254, param2=22},
		{name="stairs:slab_palm_tree_wood", prob=254, param2=22},
		{name="stairs:slab_palm_tree_wood", prob=254, param2=23},
		{name="everness:mineral_sandstone_brick_block", prob=254, param2=0},
		{name="air", prob=0, param2=0},
		{name="air", prob=0, param2=0},
		{name="everness:mineral_sandstone_brick", prob=254, param2=0},
		{name="everness:chest", prob=254, param2=3},
		{name="air", prob=254, param2=0},
		{name="air", prob=254, param2=0},
		{name="everness:mineral_sandstone_brick", prob=254, param2=0},
		{name="air", prob=0, param2=0},
		{name="air", prob=0, param2=0},
		{name="everness:fence_palm_wood", prob=254, param2=0},
		{name="air", prob=254, param2=0},
		{name="air", prob=254, param2=0},
		{name="air", prob=254, param2=0},
		{name="everness:fence_palm_wood", prob=254, param2=0},
		{name="air", prob=0, param2=0},
		{name="air", prob=0, param2=0},
		{name="everness:fence_palm_wood", prob=254, param2=0},
		{name="everness:mineral_sandstone_block", prob=254, param2=0},
		{name="everness:mineral_sandstone_block", prob=254, param2=0},
		{name="everness:mineral_sandstone_block", prob=254, param2=0},
		{name="everness:fence_palm_wood", prob=254, param2=0},
		{name="air", prob=0, param2=0},
		{name="air", prob=0, param2=0},
		{name="everness:mineral_sandstone", prob=254, param2=0},
		{name="everness:palm_tree_wood", prob=254, param2=0},
		{name="everness:palm_tree_wood", prob=254, param2=0},
		{name="everness:palm_tree_wood", prob=254, param2=0},
		{name="everness:mineral_sandstone_brick_block", prob=254, param2=0},
		{name="air", prob=0, param2=0},
		{name="air", prob=0, param2=0},
		{name="everness:mineral_sandstone_brick_block", prob=254, param2=0},
		{name="air", prob=254, param2=0},
		{name="air", prob=254, param2=0},
		{name="air", prob=254, param2=0},
		{name="everness:door_palm_wood_a", prob=254, param2=3},
		{name="air", prob=254, param2=0},
		{name="air", prob=0, param2=0},
		{name="everness:fence_palm_wood", prob=254, param2=0},
		{name="air", prob=254, param2=0},
		{name="air", prob=254, param2=0},
		{name="air", prob=254, param2=0},
		{name="doors:hidden", prob=254, param2=3},
		{name="air", prob=254, param2=0},
		{name="air", prob=0, param2=0},
		{name="everness:fence_palm_wood", prob=254, param2=0},
		{name="air", prob=254, param2=0},
		{name="air", prob=254, param2=0},
		{name="air", prob=254, param2=0},
		{name="stairs:stair_mineral_sandstone_brick", prob=254, param2=3},
		{name="air", prob=0, param2=0},
		{name="stairs:slab_palm_tree_wood", prob=254, param2=1},
		{name="stairs:stair_palm_tree_wood", prob=254, param2=1},
		{name="stairs:slab_palm_tree_wood", prob=254, param2=21},
		{name="stairs:slab_palm_tree_wood", prob=254, param2=22},
		{name="stairs:slab_palm_tree_wood", prob=254, param2=22},
		{name="everness:mineral_sandstone_brick_block", prob=254, param2=0},
		{name="air", prob=0, param2=0},
		{name="air", prob=0, param2=0},
		{name="everness:mineral_sandstone_brick", prob=254, param2=0},
		{name="air", prob=254, param2=0},
		{name="air", prob=254, param2=0},
		{name="air", prob=254, param2=0},
		{name="everness:mineral_sandstone_brick", prob=254, param2=0},
		{name="air", prob=0, param2=0},
		{name="air", prob=0, param2=0},
		{name="everness:fence_palm_wood", prob=254, param2=0},
		{name="air", prob=254, param2=0},
		{name="air", prob=254, param2=0},
		{name="air", prob=254, param2=0},
		{name="everness:fence_palm_wood", prob=254, param2=0},
		{name="air", prob=0, param2=0},
		{name="air", prob=0, param2=0},
		{name="everness:fence_palm_wood", prob=254, param2=0},
		{name="air", prob=254, param2=0},
		{name="air", prob=254, param2=0},
		{name="air", prob=254, param2=0},
		{name="everness:fence_palm_wood", prob=254, param2=0},
		{name="air", prob=0, param2=0},
		{name="stairs:slab_palm_tree_wood", prob=254, param2=1},
		{name="stairs:stair_palm_tree_wood", prob=254, param2=1},
		{name="air", prob=254, param2=0},
		{name="air", prob=254, param2=0},
		{name="air", prob=254, param2=0},
		{name="stairs:stair_palm_tree_wood", prob=254, param2=3},
		{name="stairs:slab_palm_tree_wood", prob=254, param2=0},
		{name="air", prob=0, param2=0},
		{name="everness:mineral_sandstone_brick", prob=254, param2=0},
		{name="stairs:slab_palm_tree_wood", prob=254, param2=0},
		{name="stairs:slab_palm_tree_wood", prob=254, param2=0},
		{name="stairs:slab_palm_tree_wood", prob=254, param2=0},
		{name="everness:mineral_sandstone_brick", prob=254, param2=0},
		{name="air", prob=0, param2=0},
		{name="air", prob=0, param2=0},
		{name="everness:fence_palm_wood", prob=254, param2=0},
		{name="air", prob=254, param2=0},
		{name="air", prob=254, param2=0},
		{name="air", prob=254, param2=0},
		{name="everness:fence_palm_wood", prob=254, param2=0},
		{name="air", prob=0, param2=0},
		{name="air", prob=0, param2=0},
		{name="everness:fence_palm_wood", prob=254, param2=0},
		{name="air", prob=254, param2=0},
		{name="air", prob=254, param2=0},
		{name="air", prob=254, param2=0},
		{name="everness:fence_palm_wood", prob=254, param2=0},
		{name="air", prob=0, param2=0},
		{name="stairs:slab_palm_tree_wood", prob=254, param2=1},
		{name="stairs:stair_palm_tree_wood", prob=254, param2=1},
		{name="stairs:slab_palm_tree_wood", prob=254, param2=20},
		{name="stairs:slab_palm_tree_wood", prob=254, param2=20},
		{name="stairs:slab_palm_tree_wood", prob=254, param2=23},
		{name="stairs:stair_palm_tree_wood", prob=254, param2=3},
		{name="stairs:slab_palm_tree_wood", prob=254, param2=3},
		{name="air", prob=0, param2=0},
		{name="stairs:slab_mineral_sandstone_brick", prob=254, param2=1},
		{name="air", prob=254, param2=0},
		{name="air", prob=254, param2=0},
		{name="air", prob=254, param2=0},
		{name="stairs:slab_mineral_sandstone_brick", prob=254, param2=0},
		{name="air", prob=0, param2=0},
		{name="air", prob=0, param2=0},
		{name="air", prob=254, param2=0},
		{name="air", prob=254, param2=0},
		{name="air", prob=254, param2=0},
		{name="air", prob=254, param2=0},
		{name="air", prob=254, param2=0},
		{name="air", prob=0, param2=0},
		{name="air", prob=0, param2=0},
		{name="everness:fence_rail_palm_wood", prob=254, param2=0},
		{name="everness:mineral_sandstone_block", prob=254, param2=0},
		{name="everness:mineral_sandstone_block", prob=254, param2=0},
		{name="everness:mineral_sandstone_block", prob=254, param2=0},
		{name="everness:fence_rail_palm_wood", prob=254, param2=0},
		{name="air", prob=0, param2=0},
		{name="air", prob=0, param2=0},
		{name="everness:mineral_sandstone", prob=254, param2=0},
		{name="everness:palm_tree_wood", prob=254, param2=0},
		{name="everness:palm_tree_wood", prob=254, param2=0},
		{name="everness:palm_tree_wood", prob=254, param2=0},
		{name="everness:mineral_sandstone", prob=254, param2=0},
		{name="air", prob=0, param2=0},
		{name="air", prob=0, param2=0},
		{name="everness:mineral_sandstone_brick_block", prob=254, param2=0},
		{name="air", prob=254, param2=0},
		{name="air", prob=254, param2=0},
		{name="air", prob=254, param2=0},
		{name="everness:mineral_sandstone_brick_block", prob=254, param2=0},
		{name="air", prob=0, param2=0},
		{name="air", prob=0, param2=0},
		{name="everness:mineral_sandstone_brick", prob=254, param2=0},
		{name="air", prob=254, param2=0},
		{name="air", prob=254, param2=0},
		{name="air", prob=254, param2=0},
		{name="everness:mineral_sandstone_brick", prob=254, param2=0},
		{name="air", prob=0, param2=0},
		{name="air", prob=0, param2=0},
		{name="everness:mineral_sandstone_brick", prob=254, param2=0},
		{name="air", prob=254, param2=0},
		{name="air", prob=254, param2=0},
		{name="air", prob=254, param2=0},
		{name="everness:mineral_sandstone_brick", prob=254, param2=0},
		{name="air", prob=0, param2=0},
		{name="air", prob=0, param2=0},
		{name="everness:mineral_sandstone_brick_block", prob=254, param2=0},
		{name="stairs:slab_palm_tree_wood", prob=254, param2=20},
		{name="stairs:slab_palm_tree_wood", prob=254, param2=20},
		{name="stairs:slab_palm_tree_wood", prob=254, param2=20},
		{name="everness:mineral_sandstone_brick_block", prob=254, param2=0},
		{name="air", prob=0, param2=0},
		{name="air", prob=0, param2=0},
		{name="everness:mineral_sandstone_brick", prob=254, param2=0},
		{name="everness:chest", prob=254, param2=0},
		{name="air", prob=254, param2=0},
		{name="air", prob=254, param2=0},
		{name="everness:mineral_sandstone_brick", prob=254, param2=0},
		{name="air", prob=0, param2=0},
		{name="air", prob=0, param2=0},
		{name="everness:mineral_sandstone_brick", prob=254, param2=0},
		{name="air", prob=254, param2=0},
		{name="air", prob=254, param2=0},
		{name="air", prob=254, param2=0},
		{name="everness:mineral_sandstone_brick", prob=254, param2=0},
		{name="air", prob=0, param2=0},
		{name="air", prob=0, param2=0},
		{name="everness:mineral_sandstone_brick", prob=254, param2=0},
		{name="air", prob=254, param2=0},
		{name="air", prob=254, param2=0},
		{name="air", prob=254, param2=0},
		{name="everness:mineral_sandstone_brick", prob=254, param2=0},
		{name="air", prob=0, param2=0},
		{name="air", prob=0, param2=0},
		{name="everness:mineral_sandstone_brick_block", prob=254, param2=0},
		{name="air", prob=254, param2=0},
		{name="air", prob=254, param2=0},
		{name="air", prob=254, param2=0},
		{name="everness:mineral_sandstone_brick_block", prob=254, param2=0},
		{name="air", prob=0, param2=0},
		{name="air", prob=0, param2=0},
		{name="everness:mineral_sandstone_brick", prob=254, param2=0},
		{name="stairs:slab_palm_tree_wood", prob=254, param2=0},
		{name="stairs:slab_palm_tree_wood", prob=254, param2=0},
		{name="stairs:slab_palm_tree_wood", prob=254, param2=0},
		{name="everness:mineral_sandstone_brick", prob=254, param2=0},
		{name="air", prob=0, param2=0},
		{name="air", prob=0, param2=0},
		{name="everness:mineral_sandstone_brick", prob=254, param2=0},
		{name="air", prob=254, param2=0},
		{name="air", prob=254, param2=0},
		{name="everness:vine_cave_end", prob=254, param2=8},
		{name="everness:mineral_sandstone_brick", prob=254, param2=0},
		{name="air", prob=0, param2=0},
		{name="air", prob=0, param2=0},
		{name="everness:mineral_sandstone_brick", prob=254, param2=0},
		{name="air", prob=254, param2=0},
		{name="air", prob=254, param2=0},
		{name="everness:vine_cave", prob=254, param2=8},
		{name="everness:mineral_sandstone_brick", prob=254, param2=0},
		{name="air", prob=0, param2=0},
		{name="air", prob=0, param2=0},
		{name="everness:mineral_sandstone_brick_block", prob=254, param2=0},
		{name="stairs:slab_palm_tree_wood", prob=254, param2=20},
		{name="stairs:slab_palm_tree_wood", prob=254, param2=20},
		{name="everness:vine_cave", prob=254, param2=8},
		{name="everness:mineral_sandstone_brick_block", prob=254, param2=0},
		{name="air", prob=0, param2=0},
		{name="air", prob=0, param2=0},
		{name="everness:mineral_sandstone_brick", prob=254, param2=0},
		{name="air", prob=254, param2=0},
		{name="air", prob=254, param2=0},
		{name="everness:vine_cave_with_mese_leaves", prob=254, param2=8},
		{name="everness:mineral_sandstone_brick", prob=254, param2=0},
		{name="air", prob=0, param2=0},
		{name="air", prob=0, param2=0},
		{name="everness:fence_palm_wood", prob=254, param2=0},
		{name="air", prob=254, param2=0},
		{name="air", prob=254, param2=0},
		{name="everness:vine_cave_with_mese_leaves", prob=254, param2=8},
		{name="everness:fence_palm_wood", prob=254, param2=0},
		{name="air", prob=0, param2=0},
		{name="air", prob=0, param2=0},
		{name="everness:fence_palm_wood", prob=254, param2=0},
		{name="everness:mineral_sandstone_block", prob=254, param2=0},
		{name="everness:mineral_sandstone_block", prob=254, param2=0},
		{name="everness:mineral_sandstone_block", prob=254, param2=0},
		{name="everness:fence_palm_wood", prob=254, param2=0},
		{name="air", prob=0, param2=0},
		{name="air", prob=0, param2=0},
		{name="everness:mineral_sandstone", prob=254, param2=0},
		{name="everness:palm_tree_wood", prob=254, param2=0},
		{name="everness:palm_tree_wood", prob=254, param2=0},
		{name="everness:palm_tree_wood", prob=254, param2=0},
		{name="everness:mineral_sandstone", prob=254, param2=0},
		{name="air", prob=0, param2=0},
		{name="air", prob=0, param2=0},
		{name="everness:mineral_sandstone_brick_block", prob=254, param2=0},
		{name="air", prob=254, param2=0},
		{name="air", prob=254, param2=0},
		{name="air", prob=254, param2=0},
		{name="everness:mineral_sandstone_brick_block", prob=254, param2=0},
		{name="air", prob=0, param2=0},
		{name="air", prob=0, param2=0},
		{name="everness:fence_palm_wood", prob=254, param2=0},
		{name="air", prob=254, param2=0},
		{name="air", prob=254, param2=0},
		{name="air", prob=254, param2=0},
		{name="everness:fence_palm_wood", prob=254, param2=0},
		{name="air", prob=0, param2=0},
		{name="air", prob=0, param2=0},
		{name="everness:fence_palm_wood", prob=254, param2=0},
		{name="air", prob=254, param2=0},
		{name="air", prob=254, param2=0},
		{name="air", prob=254, param2=0},
		{name="everness:fence_palm_wood", prob=254, param2=0},
		{name="air", prob=0, param2=0},
		{name="stairs:slab_palm_tree_wood", prob=254, param2=1},
		{name="stairs:stair_palm_tree_wood", prob=254, param2=1},
		{name="stairs:slab_palm_tree_wood", prob=254, param2=20},
		{name="stairs:slab_palm_tree_wood", prob=254, param2=20},
		{name="stairs:slab_palm_tree_wood", prob=254, param2=20},
		{name="stairs:stair_palm_tree_wood", prob=254, param2=3},
		{name="stairs:slab_palm_tree_wood", prob=254, param2=3},
		{name="air", prob=0, param2=0},
		{name="everness:mineral_sandstone_brick", prob=254, param2=0},
		{name="everness:mineral_sandstone_brick", prob=254, param2=0},
		{name="air", prob=254, param2=0},
		{name="everness:mineral_sandstone_brick", prob=254, param2=0},
		{name="everness:mineral_sandstone_brick", prob=254, param2=0},
		{name="air", prob=0, param2=0},
		{name="air", prob=0, param2=0},
		{name="air", prob=0, param2=0},
		{name="everness:mineral_sandstone_brick", prob=254, param2=0},
		{name="air", prob=254, param2=0},
		{name="everness:mineral_sandstone_brick", prob=254, param2=0},
		{name="air", prob=0, param2=0},
		{name="air", prob=0, param2=0},
		{name="air", prob=0, param2=0},
		{name="air", prob=0, param2=0},
		{name="everness:mineral_sandstone_brick", prob=254, param2=0},
		{name="stairs:stair_mineral_sandstone_brick", prob=254, param2=2},
		{name="everness:mineral_sandstone_brick", prob=254, param2=0},
		{name="air", prob=0, param2=0},
		{name="air", prob=0, param2=0},
		{name="air", prob=0, param2=0},
		{name="air", prob=0, param2=0},
		{name="everness:mineral_sandstone_brick_block", prob=254, param2=0},
		{name="everness:mineral_sandstone_brick_block", prob=254, param2=0},
		{name="everness:mineral_sandstone_brick_block", prob=254, param2=0},
		{name="air", prob=0, param2=0},
		{name="air", prob=0, param2=0},
		{name="air", prob=0, param2=0},
		{name="air", prob=0, param2=0},
		{name="everness:mineral_sandstone_brick", prob=254, param2=0},
		{name="everness:mineral_sandstone_brick", prob=254, param2=0},
		{name="everness:mineral_sandstone_brick", prob=254, param2=0},
		{name="air", prob=0, param2=0},
		{name="air", prob=0, param2=0},
		{name="air", prob=0, param2=0},
		{name="air", prob=0, param2=0},
		{name="everness:mineral_sandstone_brick", prob=254, param2=0},
		{name="everness:fence_palm_wood", prob=254, param2=0},
		{name="everness:mineral_sandstone_brick", prob=254, param2=0},
		{name="air", prob=0, param2=0},
		{name="air", prob=0, param2=0},
		{name="air", prob=0, param2=0},
		{name="air", prob=0, param2=0},
		{name="everness:mineral_sandstone_brick", prob=254, param2=0},
		{name="everness:fence_palm_wood", prob=254, param2=0},
		{name="everness:mineral_sandstone_brick", prob=254, param2=0},
		{name="air", prob=0, param2=0},
		{name="air", prob=0, param2=0},
		{name="air", prob=0, param2=0},
		{name="air", prob=0, param2=0},
		{name="everness:mineral_sandstone_brick_block", prob=254, param2=0},
		{name="stairs:stair_palm_tree_wood", prob=254, param2=2},
		{name="everness:mineral_sandstone_brick_block", prob=254, param2=0},
		{name="air", prob=0, param2=0},
		{name="air", prob=0, param2=0},
		{name="air", prob=0, param2=0},
		{name="air", prob=0, param2=0},
		{name="everness:mineral_sandstone_brick", prob=254, param2=0},
		{name="stairs:slab_mineral_sandstone_brick", prob=254, param2=3},
		{name="everness:mineral_sandstone_brick", prob=254, param2=0},
		{name="air", prob=0, param2=0},
		{name="air", prob=0, param2=0},
		{name="air", prob=0, param2=0},
		{name="air", prob=0, param2=0},
		{name="everness:fence_palm_wood", prob=254, param2=0},
		{name="air", prob=254, param2=0},
		{name="everness:fence_palm_wood", prob=254, param2=0},
		{name="air", prob=0, param2=0},
		{name="air", prob=0, param2=0},
		{name="air", prob=0, param2=0},
		{name="everness:fence_rail_palm_wood", prob=254, param2=0},
		{name="everness:fence_palm_wood", prob=254, param2=0},
		{name="everness:fence_rail_palm_wood", prob=254, param2=0},
		{name="everness:fence_palm_wood", prob=254, param2=0},
		{name="everness:fence_rail_palm_wood", prob=254, param2=0},
		{name="air", prob=0, param2=0},
		{name="air", prob=0, param2=0},
		{name="everness:mineral_sandstone", prob=254, param2=0},
		{name="everness:palm_tree_wood", prob=254, param2=0},
		{name="everness:palm_tree_wood", prob=254, param2=0},
		{name="everness:palm_tree_wood", prob=254, param2=0},
		{name="everness:mineral_sandstone", prob=254, param2=0},
		{name="air", prob=0, param2=0},
		{name="air", prob=0, param2=0},
		{name="everness:mineral_sandstone_brick_block", prob=254, param2=0},
		{name="air", prob=254, param2=0},
		{name="air", prob=254, param2=0},
		{name="air", prob=254, param2=0},
		{name="everness:mineral_sandstone_brick_block", prob=254, param2=0},
		{name="air", prob=0, param2=0},
		{name="air", prob=0, param2=0},
		{name="everness:mineral_sandstone_brick", prob=254, param2=0},
		{name="air", prob=254, param2=0},
		{name="air", prob=254, param2=0},
		{name="air", prob=254, param2=0},
		{name="everness:mineral_sandstone_brick", prob=254, param2=0},
		{name="air", prob=0, param2=0},
		{name="air", prob=0, param2=0},
		{name="everness:mineral_sandstone_brick", prob=254, param2=0},
		{name="air", prob=254, param2=0},
		{name="air", prob=254, param2=0},
		{name="air", prob=254, param2=0},
		{name="everness:mineral_sandstone_brick", prob=254, param2=0},
		{name="air", prob=0, param2=0},
		{name="air", prob=0, param2=0},
		{name="everness:mineral_sandstone_brick_block", prob=254, param2=0},
		{name="stairs:slab_palm_tree_wood", prob=254, param2=20},
		{name="stairs:slab_palm_tree_wood", prob=254, param2=20},
		{name="stairs:slab_palm_tree_wood", prob=254, param2=20},
		{name="everness:mineral_sandstone_brick_block", prob=254, param2=0},
		{name="air", prob=0, param2=0},
		{name="air", prob=0, param2=0},
		{name="stairs:slab_mineral_sandstone_brick", prob=254, param2=2},
		{name="air", prob=254, param2=0},
		{name="air", prob=254, param2=0},
		{name="air", prob=254, param2=0},
		{name="stairs:slab_mineral_sandstone_brick", prob=254, param2=2},
		{name="air", prob=0, param2=0},
		{name="air", prob=0, param2=0},
		{name="air", prob=0, param2=0},
		{name="air", prob=254, param2=0},
		{name="air", prob=254, param2=0},
		{name="air", prob=254, param2=0},
		{name="air", prob=0, param2=0},
		{name="air", prob=0, param2=0},
		{name="air", prob=0, param2=0},
		{name="air", prob=0, param2=0},
		{name="air", prob=0, param2=0},
		{name="air", prob=0, param2=0},
		{name="air", prob=0, param2=0},
		{name="air", prob=0, param2=0},
		{name="air", prob=0, param2=0},
		{name="air", prob=0, param2=0},
		{name="air", prob=0, param2=0},
		{name="air", prob=0, param2=0},
		{name="air", prob=0, param2=0},
		{name="air", prob=0, param2=0},
		{name="air", prob=0, param2=0},
		{name="air", prob=0, param2=0},
		{name="air", prob=0, param2=0},
		{name="air", prob=0, param2=0},
		{name="air", prob=0, param2=0},
		{name="air", prob=0, param2=0},
		{name="air", prob=0, param2=0},
		{name="air", prob=0, param2=0},
		{name="air", prob=0, param2=0},
		{name="air", prob=0, param2=0},
		{name="air", prob=0, param2=0},
		{name="air", prob=0, param2=0},
		{name="air", prob=0, param2=0},
		{name="air", prob=0, param2=0},
		{name="air", prob=0, param2=0},
		{name="air", prob=0, param2=0},
		{name="air", prob=0, param2=0},
		{name="air", prob=0, param2=0},
		{name="air", prob=0, param2=0},
		{name="air", prob=0, param2=0},
		{name="air", prob=0, param2=0},
		{name="air", prob=0, param2=0},
		{name="air", prob=0, param2=0},
		{name="air", prob=0, param2=0},
		{name="air", prob=0, param2=0},
		{name="air", prob=0, param2=0},
		{name="stairs:slab_palm_tree_wood", prob=254, param2=2},
		{name="air", prob=0, param2=0},
		{name="air", prob=0, param2=0},
		{name="air", prob=0, param2=0},
		{name="air", prob=0, param2=0},
		{name="air", prob=0, param2=0},
		{name="air", prob=0, param2=0},
		{name="air", prob=0, param2=0},
		{name="air", prob=0, param2=0},
		{name="air", prob=0, param2=0},
		{name="air", prob=0, param2=0},
		{name="air", prob=0, param2=0},
		{name="air", prob=0, param2=0},
		{name="air", prob=0, param2=0},
		{name="air", prob=0, param2=0},
		{name="air", prob=0, param2=0},
		{name="air", prob=0, param2=0},
		{name="air", prob=0, param2=0},
		{name="air", prob=0, param2=0},
		{name="air", prob=0, param2=0},
		{name="air", prob=0, param2=0},
		{name="air", prob=0, param2=0},
		{name="air", prob=0, param2=0},
		{name="air", prob=0, param2=0},
		{name="air", prob=0, param2=0},
		{name="air", prob=0, param2=0},
		{name="everness:mineral_sandstone", prob=254, param2=0},
		{name="everness:mineral_sandstone", prob=254, param2=0},
		{name="everness:mineral_sandstone", prob=254, param2=0},
		{name="everness:mineral_sandstone", prob=254, param2=0},
		{name="everness:mineral_sandstone", prob=254, param2=0},
		{name="air", prob=0, param2=0},
		{name="air", prob=0, param2=0},
		{name="air", prob=0, param2=0},
		{name="everness:mineral_sandstone_brick_block", prob=254, param2=0},
		{name="everness:mineral_sandstone_brick_block", prob=254, param2=0},
		{name="everness:mineral_sandstone_brick_block", prob=254, param2=0},
		{name="air", prob=0, param2=0},
		{name="air", prob=0, param2=0},
		{name="air", prob=0, param2=0},
		{name="air", prob=0, param2=0},
		{name="everness:mineral_sandstone_brick", prob=254, param2=0},
		{name="everness:fence_palm_wood", prob=254, param2=0},
		{name="everness:mineral_sandstone_brick", prob=254, param2=0},
		{name="air", prob=0, param2=0},
		{name="air", prob=0, param2=0},
		{name="air", prob=0, param2=0},
		{name="air", prob=0, param2=0},
		{name="everness:mineral_sandstone_brick", prob=254, param2=0},
		{name="everness:fence_palm_wood", prob=254, param2=0},
		{name="everness:mineral_sandstone_brick", prob=254, param2=0},
		{name="air", prob=0, param2=0},
		{name="air", prob=0, param2=0},
		{name="air", prob=0, param2=0},
		{name="air", prob=0, param2=0},
		{name="everness:mineral_sandstone_brick_block", prob=254, param2=0},
		{name="stairs:stair_palm_tree_wood", prob=254, param2=2},
		{name="everness:mineral_sandstone_brick_block", prob=254, param2=0},
		{name="air", prob=0, param2=0},
		{name="air", prob=0, param2=0},
		{name="air", prob=0, param2=0},
		{name="air", prob=0, param2=0},
		{name="everness:mineral_sandstone_brick", prob=254, param2=0},
		{name="stairs:slab_mineral_sandstone_brick", prob=254, param2=2},
		{name="everness:mineral_sandstone_brick", prob=254, param2=0},
		{name="air", prob=0, param2=0},
		{name="air", prob=0, param2=0},
		{name="air", prob=0, param2=0},
		{name="air", prob=0, param2=0},
		{name="air", prob=0, param2=0},
		{name="air", prob=0, param2=0},
		{name="air", prob=0, param2=0},
		{name="air", prob=0, param2=0},
		{name="air", prob=0, param2=0},
		{name="air", prob=0, param2=0},
		{name="air", prob=0, param2=0},
		{name="air", prob=0, param2=0},
		{name="air", prob=0, param2=0},
		{name="air", prob=0, param2=0},
		{name="air", prob=0, param2=0},
		{name="air", prob=0, param2=0},
		{name="air", prob=0, param2=0},
		{name="air", prob=0, param2=0},
		{name="air", prob=0, param2=0},
		{name="air", prob=0, param2=0},
		{name="air", prob=0, param2=0},
		{name="air", prob=0, param2=0},
		{name="air", prob=0, param2=0},
		{name="air", prob=0, param2=0},
		{name="air", prob=0, param2=0},
		{name="air", prob=0, param2=0},
		{name="air", prob=0, param2=0},
		{name="air", prob=0, param2=0},
		{name="air", prob=0, param2=0},
		{name="air", prob=0, param2=0},
		{name="air", prob=0, param2=0},
		{name="air", prob=0, param2=0},
		{name="air", prob=0, param2=0},
		{name="air", prob=0, param2=0},
		{name="air", prob=0, param2=0},
		{name="air", prob=0, param2=0},
		{name="air", prob=0, param2=0},
		{name="air", prob=0, param2=0},
		{name="air", prob=0, param2=0},
		{name="air", prob=0, param2=0},
		{name="air", prob=0, param2=0},
		{name="air", prob=0, param2=0},
		{name="air", prob=0, param2=0},
		{name="air", prob=0, param2=0},
		{name="air", prob=0, param2=0},
		{name="air", prob=0, param2=0},
		{name="air", prob=0, param2=0},
		{name="air", prob=0, param2=0},
		{name="air", prob=0, param2=0},
		{name="air", prob=0, param2=0},
		{name="air", prob=0, param2=0},
		{name="air", prob=0, param2=0},
		{name="air", prob=0, param2=0},
		{name="air", prob=0, param2=0},
		{name="air", prob=0, param2=0},
		{name="air", prob=0, param2=0},
		{name="air", prob=0, param2=0},
		{name="air", prob=0, param2=0},
		{name="air", prob=0, param2=0},
		{name="air", prob=0, param2=0},
		{name="air", prob=0, param2=0},
		{name="air", prob=0, param2=0},
		{name="air", prob=0, param2=0},
		{name="air", prob=0, param2=0},
		{name="air", prob=0, param2=0},
		{name="air", prob=0, param2=0},
		{name="air", prob=0, param2=0},
		{name="air", prob=0, param2=0},
		{name="air", prob=0, param2=0},
		{name="air", prob=0, param2=0},
		{name="air", prob=0, param2=0},
		{name="air", prob=0, param2=0},
		{name="air", prob=0, param2=0},
		{name="air", prob=0, param2=0},
		{name="air", prob=0, param2=0},
		{name="air", prob=0, param2=0},
		{name="air", prob=0, param2=0},
		{name="air", prob=0, param2=0},
		{name="air", prob=0, param2=0},
		{name="air", prob=0, param2=0},
		{name="air", prob=0, param2=0},
		{name="air", prob=0, param2=0},
		{name="air", prob=0, param2=0},
		{name="air", prob=0, param2=0},
		{name="air", prob=0, param2=0},
		{name="air", prob=0, param2=0},
		{name="air", prob=0, param2=0},
		{name="air", prob=0, param2=0},
		{name="air", prob=0, param2=0},
		{name="air", prob=0, param2=0},
		{name="air", prob=0, param2=0},
		{name="air", prob=0, param2=0},
		{name="air", prob=0, param2=0},
		{name="air", prob=0, param2=0},
		{name="air", prob=0, param2=0},
		{name="air", prob=0, param2=0},
		{name="air", prob=0, param2=0},
		{name="air", prob=0, param2=0},
		{name="air", prob=0, param2=0},
		{name="air", prob=0, param2=0},
		{name="air", prob=0, param2=0},
		{name="air", prob=0, param2=0},
		{name="air", prob=0, param2=0},
		{name="stairs:slab_palm_tree_wood", prob=254, param2=2},
		{name="air", prob=0, param2=0},
		{name="air", prob=0, param2=0},
		{name="air", prob=0, param2=0},
		{name="air", prob=0, param2=0},
		{name="air", prob=0, param2=0},
		{name="air", prob=0, param2=0},
		{name="air", prob=0, param2=0},
		{name="air", prob=0, param2=0},
		{name="air", prob=0, param2=0},
		{name="air", prob=0, param2=0},
		{name="air", prob=0, param2=0},
		{name="air", prob=0, param2=0},
		{name="air", prob=0, param2=0},
		{name="air", prob=0, param2=0},
		{name="air", prob=0, param2=0},
		{name="air", prob=0, param2=0},
		{name="air", prob=0, param2=0},
		{name="air", prob=0, param2=0},
		{name="air", prob=0, param2=0},
		{name="air", prob=0, param2=0},
		{name="air", prob=0, param2=0},
		{name="air", prob=0, param2=0},
		{name="air", prob=0, param2=0},
		{name="air", prob=0, param2=0},
		{name="air", prob=0, param2=0},
		{name="air", prob=0, param2=0},
		{name="air", prob=0, param2=0},
		{name="air", prob=0, param2=0},
		{name="air", prob=0, param2=0},
		{name="air", prob=0, param2=0},
		{name="air", prob=0, param2=0},
		{name="air", prob=0, param2=0},
		{name="air", prob=0, param2=0},
		{name="air", prob=0, param2=0},
		{name="air", prob=0, param2=0},
		{name="air", prob=0, param2=0},
		{name="air", prob=0, param2=0},
		{name="air", prob=0, param2=0},
		{name="air", prob=0, param2=0},
		{name="air", prob=0, param2=0},
		{name="air", prob=0, param2=0},
		{name="air", prob=0, param2=0},
		{name="air", prob=0, param2=0},
		{name="air", prob=0, param2=0},
		{name="air", prob=0, param2=0},
		{name="air", prob=0, param2=0},
		{name="air", prob=0, param2=0},
		{name="air", prob=0, param2=0},
		{name="air", prob=0, param2=0},
		{name="air", prob=0, param2=0},
		{name="air", prob=0, param2=0},
		{name="air", prob=0, param2=0},
		{name="air", prob=0, param2=0},
		{name="air", prob=0, param2=0},
		{name="air", prob=0, param2=0},
		{name="air", prob=0, param2=0},
		{name="air", prob=0, param2=0},
		{name="air", prob=0, param2=0},
		{name="air", prob=0, param2=0},
		{name="air", prob=0, param2=0},
		{name="air", prob=0, param2=0},
		{name="air", prob=0, param2=0},
		{name="air", prob=0, param2=0},
		{name="air", prob=0, param2=0},
		{name="air", prob=0, param2=0},
		{name="air", prob=0, param2=0},
		{name="air", prob=0, param2=0},
		{name="air", prob=0, param2=0},
		{name="air", prob=0, param2=0},
		{name="air", prob=0, param2=0},
		{name="air", prob=0, param2=0},
		{name="air", prob=0, param2=0},
		{name="air", prob=0, param2=0},
		{name="air", prob=0, param2=0},
		{name="air", prob=0, param2=0},
		{name="air", prob=0, param2=0},
		{name="air", prob=0, param2=0},
		{name="air", prob=0, param2=0},
		{name="air", prob=0, param2=0},
		{name="air", prob=0, param2=0},
	},
}
