schematic = {
	size = {x=11, y=22, z=10},
	yslice_prob = {
		{ypos=0, prob=254},
		{ypos=1, prob=254},
		{ypos=2, prob=254},
		{ypos=3, prob=254},
		{ypos=4, prob=254},
		{ypos=5, prob=254},
		{ypos=6, prob=254},
		{ypos=7, prob=254},
		{ypos=8, prob=254},
		{ypos=9, prob=254},
		{ypos=10, prob=254},
		{ypos=11, prob=254},
		{ypos=12, prob=254},
		{ypos=13, prob=254},
		{ypos=14, prob=254},
		{ypos=15, prob=254},
		{ypos=16, prob=254},
		{ypos=17, prob=254},
		{ypos=18, prob=254},
		{ypos=19, prob=254},
		{ypos=20, prob=254},
		{ypos=21, prob=254},
	},
	data = {
		{name="air", prob=0, param2=0},
		{name="air", prob=0, param2=0},
		{name="air", prob=0, param2=0},
		{name="air", prob=0, param2=0},
		{name="air", prob=0, param2=0},
		{name="air", prob=0, param2=0},
		{name="air", prob=0, param2=0},
		{name="air", prob=0, param2=0},
		{name="air", prob=0, param2=0},
		{name="air", prob=0, param2=0},
		{name="air", prob=0, param2=0},
		{name="air", prob=0, param2=0},
		{name="air", prob=0, param2=0},
		{name="air", prob=0, param2=0},
		{name="air", prob=0, param2=0},
		{name="air", prob=0, param2=0},
		{name="air", prob=0, param2=0},
		{name="air", prob=0, param2=0},
		{name="air", prob=0, param2=0},
		{name="air", prob=0, param2=0},
		{name="air", prob=0, param2=0},
		{name="air", prob=0, param2=0},
		{name="air", prob=254, param2=0},
		{name="air", prob=254, param2=0},
		{name="air", prob=254, param2=0},
		{name="air", prob=254, param2=0},
		{name="air", prob=254, param2=0},
		{name="air", prob=254, param2=0},
		{name="air", prob=254, param2=0},
		{name="air", prob=254, param2=0},
		{name="air", prob=254, param2=0},
		{name="air", prob=254, param2=0},
		{name="air", prob=254, param2=0},
		{name="air", prob=254, param2=0},
		{name="air", prob=254, param2=0},
		{name="air", prob=254, param2=0},
		{name="air", prob=254, param2=0},
		{name="air", prob=254, param2=0},
		{name="air", prob=254, param2=0},
		{name="air", prob=254, param2=0},
		{name="air", prob=254, param2=0},
		{name="air", prob=254, param2=0},
		{name="air", prob=254, param2=0},
		{name="air", prob=254, param2=0},
		{name="air", prob=254, param2=0},
		{name="air", prob=254, param2=0},
		{name="air", prob=254, param2=0},
		{name="air", prob=254, param2=0},
		{name="air", prob=254, param2=0},
		{name="air", prob=254, param2=0},
		{name="air", prob=254, param2=0},
		{name="air", prob=254, param2=0},
		{name="air", prob=254, param2=0},
		{name="air", prob=254, param2=0},
		{name="air", prob=254, param2=0},
		{name="air", prob=254, param2=0},
		{name="air", prob=254, param2=0},
		{name="air", prob=254, param2=0},
		{name="air", prob=254, param2=0},
		{name="air", prob=254, param2=0},
		{name="air", prob=254, param2=0},
		{name="air", prob=254, param2=0},
		{name="air", prob=254, param2=0},
		{name="air", prob=254, param2=0},
		{name="air", prob=254, param2=0},
		{name="air", prob=254, param2=0},
		{name="air", prob=254, param2=0},
		{name="air", prob=254, param2=0},
		{name="air", prob=254, param2=0},
		{name="air", prob=254, param2=0},
		{name="air", prob=254, param2=0},
		{name="air", prob=254, param2=0},
		{name="air", prob=254, param2=0},
		{name="air", prob=254, param2=0},
		{name="air", prob=254, param2=0},
		{name="air", prob=254, param2=0},
		{name="air", prob=254, param2=0},
		{name="air", prob=254, param2=0},
		{name="air", prob=254, param2=0},
		{name="air", prob=254, param2=0},
		{name="stairs:slab_dry_wood", prob=254, param2=20},
		{name="air", prob=254, param2=0},
		{name="air", prob=254, param2=0},
		{name="air", prob=254, param2=0},
		{name="stairs:slab_dry_wood", prob=254, param2=20},
		{name="stairs:slab_dry_wood", prob=254, param2=20},
		{name="air", prob=254, param2=0},
		{name="air", prob=254, param2=0},
		{name="air", prob=254, param2=0},
		{name="stairs:stair_dry_wood", prob=254, param2=0},
		{name="stairs:stair_dry_wood", prob=254, param2=0},
		{name="stairs:slab_dry_wood", prob=254, param2=0},
		{name="stairs:stair_dry_wood", prob=254, param2=0},
		{name="stairs:stair_dry_wood", prob=254, param2=0},
		{name="stairs:stair_dry_wood", prob=254, param2=0},
		{name="stairs:slab_dry_wood", prob=254, param2=0},
		{name="stairs:slab_dry_wood", prob=254, param2=0},
		{name="stairs:stair_dry_wood", prob=254, param2=0},
		{name="air", prob=254, param2=0},
		{name="air", prob=254, param2=0},
		{name="air", prob=254, param2=0},
		{name="air", prob=254, param2=0},
		{name="air", prob=254, param2=0},
		{name="air", prob=254, param2=0},
		{name="air", prob=254, param2=0},
		{name="air", prob=254, param2=0},
		{name="air", prob=254, param2=0},
		{name="air", prob=254, param2=0},
		{name="air", prob=254, param2=0},
		{name="air", prob=254, param2=0},
		{name="air", prob=254, param2=0},
		{name="air", prob=254, param2=0},
		{name="air", prob=254, param2=0},
		{name="air", prob=254, param2=0},
		{name="air", prob=254, param2=0},
		{name="air", prob=254, param2=0},
		{name="air", prob=254, param2=0},
		{name="air", prob=254, param2=0},
		{name="air", prob=254, param2=0},
		{name="air", prob=254, param2=0},
		{name="air", prob=254, param2=0},
		{name="air", prob=254, param2=0},
		{name="air", prob=254, param2=0},
		{name="air", prob=254, param2=0},
		{name="air", prob=254, param2=0},
		{name="air", prob=254, param2=0},
		{name="air", prob=254, param2=0},
		{name="air", prob=254, param2=0},
		{name="air", prob=254, param2=0},
		{name="air", prob=254, param2=0},
		{name="air", prob=254, param2=0},
		{name="air", prob=254, param2=0},
		{name="air", prob=254, param2=0},
		{name="air", prob=254, param2=0},
		{name="air", prob=254, param2=0},
		{name="air", prob=254, param2=0},
		{name="air", prob=254, param2=0},
		{name="air", prob=254, param2=0},
		{name="air", prob=254, param2=0},
		{name="air", prob=254, param2=0},
		{name="air", prob=254, param2=0},
		{name="air", prob=254, param2=0},
		{name="air", prob=254, param2=0},
		{name="air", prob=254, param2=0},
		{name="air", prob=254, param2=0},
		{name="air", prob=254, param2=0},
		{name="air", prob=254, param2=0},
		{name="air", prob=254, param2=0},
		{name="air", prob=254, param2=0},
		{name="air", prob=254, param2=0},
		{name="air", prob=254, param2=0},
		{name="air", prob=254, param2=0},
		{name="air", prob=254, param2=0},
		{name="air", prob=254, param2=0},
		{name="air", prob=254, param2=0},
		{name="air", prob=254, param2=0},
		{name="air", prob=254, param2=0},
		{name="everness:trapdoor_cursed_wood_open", prob=254, param2=0},
		{name="air", prob=254, param2=0},
		{name="air", prob=254, param2=0},
		{name="air", prob=254, param2=0},
		{name="everness:trapdoor_cursed_wood_open", prob=254, param2=0},
		{name="air", prob=254, param2=0},
		{name="air", prob=254, param2=0},
		{name="air", prob=254, param2=0},
		{name="air", prob=254, param2=0},
		{name="air", prob=254, param2=0},
		{name="air", prob=254, param2=0},
		{name="stairs:stair_dry_wood", prob=254, param2=20},
		{name="stairs:slab_dry_wood", prob=254, param2=20},
		{name="stairs:stair_dry_wood", prob=254, param2=20},
		{name="stairs:slab_dry_wood", prob=254, param2=20},
		{name="stairs:stair_dry_wood", prob=254, param2=20},
		{name="air", prob=254, param2=0},
		{name="air", prob=254, param2=0},
		{name="air", prob=254, param2=0},
		{name="air", prob=254, param2=0},
		{name="air", prob=254, param2=0},
		{name="air", prob=254, param2=0},
		{name="stairs:slab_dry_wood", prob=254, param2=1},
		{name="everness:trapdoor_cursed_wood", prob=254, param2=0},
		{name="stairs:stair_dry_wood", prob=254, param2=0},
		{name="everness:trapdoor_cursed_wood", prob=254, param2=0},
		{name="stairs:slab_dry_wood", prob=254, param2=1},
		{name="air", prob=254, param2=0},
		{name="air", prob=254, param2=0},
		{name="air", prob=254, param2=0},
		{name="air", prob=254, param2=0},
		{name="air", prob=254, param2=0},
		{name="air", prob=254, param2=0},
		{name="air", prob=254, param2=0},
		{name="air", prob=254, param2=0},
		{name="air", prob=254, param2=0},
		{name="air", prob=254, param2=0},
		{name="air", prob=254, param2=0},
		{name="air", prob=254, param2=0},
		{name="air", prob=254, param2=0},
		{name="air", prob=254, param2=0},
		{name="air", prob=254, param2=0},
		{name="air", prob=254, param2=0},
		{name="air", prob=254, param2=0},
		{name="air", prob=254, param2=0},
		{name="air", prob=254, param2=0},
		{name="air", prob=254, param2=0},
		{name="air", prob=254, param2=0},
		{name="air", prob=254, param2=0},
		{name="air", prob=254, param2=0},
		{name="air", prob=254, param2=0},
		{name="air", prob=254, param2=0},
		{name="air", prob=254, param2=0},
		{name="air", prob=254, param2=0},
		{name="air", prob=254, param2=0},
		{name="air", prob=254, param2=0},
		{name="air", prob=254, param2=0},
		{name="air", prob=254, param2=0},
		{name="air", prob=254, param2=0},
		{name="air", prob=254, param2=0},
		{name="air", prob=254, param2=0},
		{name="air", prob=254, param2=0},
		{name="air", prob=254, param2=0},
		{name="air", prob=254, param2=0},
		{name="air", prob=254, param2=0},
		{name="air", prob=254, param2=0},
		{name="air", prob=254, param2=0},
		{name="air", prob=254, param2=0},
		{name="air", prob=254, param2=0},
		{name="air", prob=254, param2=0},
		{name="air", prob=254, param2=0},
		{name="air", prob=254, param2=0},
		{name="air", prob=254, param2=0},
		{name="air", prob=254, param2=0},
		{name="air", prob=254, param2=0},
		{name="air", prob=254, param2=0},
		{name="air", prob=254, param2=0},
		{name="air", prob=254, param2=0},
		{name="air", prob=254, param2=0},
		{name="air", prob=254, param2=0},
		{name="air", prob=254, param2=0},
		{name="air", prob=254, param2=0},
		{name="air", prob=254, param2=0},
		{name="air", prob=254, param2=0},
		{name="air", prob=254, param2=0},
		{name="air", prob=0, param2=0},
		{name="air", prob=0, param2=0},
		{name="everness:cursed_dirt", prob=254, param2=0},
		{name="everness:cursed_dirt", prob=254, param2=0},
		{name="everness:cursed_dirt", prob=254, param2=0},
		{name="everness:cursed_dirt", prob=254, param2=0},
		{name="everness:cursed_dirt", prob=254, param2=0},
		{name="everness:cursed_dirt", prob=254, param2=0},
		{name="everness:cursed_dirt", prob=254, param2=0},
		{name="air", prob=0, param2=0},
		{name="air", prob=0, param2=0},
		{name="air", prob=0, param2=0},
		{name="air", prob=0, param2=0},
		{name="everness:dry_tree", prob=254, param2=22},
		{name="everness:dirt_with_cursed_grass", prob=254, param2=0},
		{name="everness:dry_tree", prob=254, param2=22},
		{name="everness:dirt_with_cursed_grass", prob=254, param2=0},
		{name="everness:dry_tree", prob=254, param2=22},
		{name="everness:dirt_with_cursed_grass", prob=254, param2=0},
		{name="everness:dry_tree", prob=254, param2=23},
		{name="air", prob=0, param2=0},
		{name="air", prob=0, param2=0},
		{name="air", prob=254, param2=0},
		{name="air", prob=254, param2=0},
		{name="everness:dry_tree", prob=254, param2=1},
		{name="everness:fence_dry_wood", prob=254, param2=0},
		{name="everness:dry_tree", prob=254, param2=2},
		{name="everness:fence_dry_wood", prob=254, param2=0},
		{name="everness:dry_tree", prob=254, param2=2},
		{name="everness:fence_dry_wood", prob=254, param2=0},
		{name="everness:dry_tree", prob=254, param2=0},
		{name="air", prob=254, param2=0},
		{name="air", prob=254, param2=0},
		{name="air", prob=254, param2=0},
		{name="air", prob=254, param2=0},
		{name="everness:dry_tree", prob=254, param2=3},
		{name="everness:dry_tree", prob=254, param2=12},
		{name="everness:dry_tree", prob=254, param2=12},
		{name="everness:dry_tree", prob=254, param2=12},
		{name="everness:dry_tree", prob=254, param2=12},
		{name="everness:dry_tree", prob=254, param2=12},
		{name="everness:dry_tree", prob=254, param2=0},
		{name="air", prob=254, param2=0},
		{name="air", prob=254, param2=0},
		{name="air", prob=254, param2=0},
		{name="air", prob=254, param2=0},
		{name="everness:dry_tree", prob=254, param2=3},
		{name="everness:cursed_brick_mixed", prob=254, param2=0},
		{name="everness:dry_tree", prob=254, param2=0},
		{name="everness:cursed_brick_mixed", prob=254, param2=0},
		{name="everness:dry_tree", prob=254, param2=0},
		{name="everness:cursed_brick_mixed", prob=254, param2=0},
		{name="everness:dry_tree", prob=254, param2=0},
		{name="air", prob=254, param2=0},
		{name="air", prob=254, param2=0},
		{name="air", prob=254, param2=0},
		{name="air", prob=254, param2=0},
		{name="everness:dry_tree", prob=254, param2=3},
		{name="everness:cursed_brick_mixed", prob=254, param2=0},
		{name="everness:dry_tree", prob=254, param2=0},
		{name="everness:trapdoor_cursed_wood_open", prob=254, param2=2},
		{name="everness:dry_tree", prob=254, param2=0},
		{name="everness:cursed_brick_mixed", prob=254, param2=0},
		{name="everness:dry_tree", prob=254, param2=0},
		{name="air", prob=254, param2=0},
		{name="air", prob=254, param2=0},
		{name="air", prob=254, param2=0},
		{name="air", prob=254, param2=0},
		{name="everness:dry_tree", prob=254, param2=3},
		{name="everness:cursed_brick_mixed", prob=254, param2=0},
		{name="everness:dry_tree", prob=254, param2=0},
		{name="everness:cursed_brick_mixed", prob=254, param2=0},
		{name="everness:dry_tree", prob=254, param2=0},
		{name="everness:cursed_brick_mixed", prob=254, param2=0},
		{name="everness:dry_tree", prob=254, param2=0},
		{name="air", prob=254, param2=0},
		{name="air", prob=254, param2=0},
		{name="air", prob=254, param2=0},
		{name="air", prob=254, param2=0},
		{name="everness:dry_tree", prob=254, param2=3},
		{name="everness:cursed_brick_mixed", prob=254, param2=0},
		{name="everness:dry_tree", prob=254, param2=0},
		{name="everness:cursed_brick_mixed", prob=254, param2=0},
		{name="everness:dry_tree", prob=254, param2=0},
		{name="everness:cursed_brick_mixed", prob=254, param2=0},
		{name="everness:dry_tree", prob=254, param2=0},
		{name="air", prob=254, param2=0},
		{name="air", prob=254, param2=0},
		{name="air", prob=254, param2=0},
		{name="stairs:stair_dry_wood", prob=254, param2=22},
		{name="everness:cursed_brick_with_growth", prob=254, param2=0},
		{name="everness:cursed_brick_mixed", prob=254, param2=0},
		{name="air", prob=254, param2=0},
		{name="air", prob=254, param2=0},
		{name="air", prob=254, param2=0},
		{name="everness:cursed_brick_mixed", prob=254, param2=0},
		{name="everness:cursed_brick_with_growth", prob=254, param2=0},
		{name="stairs:stair_dry_wood", prob=254, param2=22},
		{name="air", prob=254, param2=0},
		{name="air", prob=254, param2=0},
		{name="everness:dry_wood", prob=254, param2=0},
		{name="everness:cursed_brick_with_growth", prob=254, param2=0},
		{name="everness:cursed_brick_mixed", prob=254, param2=0},
		{name="everness:cursed_brick_mixed", prob=254, param2=0},
		{name="everness:cursed_brick_mixed", prob=254, param2=0},
		{name="everness:cursed_brick_mixed", prob=254, param2=0},
		{name="everness:cursed_brick_mixed", prob=254, param2=0},
		{name="everness:cursed_brick_with_growth", prob=254, param2=0},
		{name="everness:dry_wood", prob=254, param2=0},
		{name="air", prob=254, param2=0},
		{name="air", prob=254, param2=0},
		{name="stairs:stair_dry_wood", prob=254, param2=0},
		{name="stairs:stair_cursed_brick_with_growth", prob=254, param2=0},
		{name="everness:cursed_brick_mixed", prob=254, param2=0},
		{name="stairs:stair_cursed_brick_with_growth", prob=254, param2=0},
		{name="stairs:stair_cursed_brick_with_growth", prob=254, param2=0},
		{name="stairs:stair_cursed_brick_with_growth", prob=254, param2=0},
		{name="everness:cursed_brick_mixed", prob=254, param2=0},
		{name="stairs:stair_cursed_brick_with_growth", prob=254, param2=0},
		{name="stairs:stair_dry_wood", prob=254, param2=0},
		{name="air", prob=254, param2=0},
		{name="air", prob=254, param2=0},
		{name="air", prob=254, param2=0},
		{name="air", prob=254, param2=0},
		{name="everness:cursed_brick_mixed", prob=254, param2=0},
		{name="everness:cursed_brick_mixed", prob=254, param2=0},
		{name="everness:cursed_brick_mixed", prob=254, param2=0},
		{name="everness:cursed_brick_mixed", prob=254, param2=0},
		{name="everness:cursed_brick_mixed", prob=254, param2=0},
		{name="air", prob=254, param2=0},
		{name="air", prob=254, param2=0},
		{name="air", prob=254, param2=0},
		{name="air", prob=254, param2=0},
		{name="air", prob=254, param2=0},
		{name="air", prob=254, param2=0},
		{name="everness:cursed_brick_mixed", prob=254, param2=0},
		{name="everness:dry_wood", prob=254, param2=0},
		{name="stairs:stair_dry_wood", prob=254, param2=0},
		{name="stairs:stair_dry_wood", prob=254, param2=20},
		{name="everness:cursed_brick_mixed", prob=254, param2=0},
		{name="air", prob=254, param2=0},
		{name="air", prob=254, param2=0},
		{name="air", prob=254, param2=0},
		{name="air", prob=254, param2=0},
		{name="air", prob=254, param2=0},
		{name="air", prob=254, param2=0},
		{name="everness:cursed_brick_mixed", prob=254, param2=0},
		{name="everness:dry_wood", prob=254, param2=0},
		{name="xpanes:cursed_bar", prob=254, param2=0},
		{name="everness:dry_wood", prob=254, param2=0},
		{name="everness:cursed_brick_mixed", prob=254, param2=0},
		{name="air", prob=254, param2=0},
		{name="air", prob=254, param2=0},
		{name="air", prob=254, param2=0},
		{name="air", prob=254, param2=0},
		{name="air", prob=254, param2=0},
		{name="everness:trapdoor_cursed_wood_open", prob=254, param2=1},
		{name="everness:cursed_brick_mixed", prob=254, param2=0},
		{name="stairs:stair_dry_wood", prob=254, param2=0},
		{name="stairs:stair_dry_wood", prob=254, param2=20},
		{name="everness:dry_wood", prob=254, param2=0},
		{name="everness:cursed_brick_mixed", prob=254, param2=0},
		{name="everness:trapdoor_cursed_wood_open", prob=254, param2=3},
		{name="air", prob=254, param2=0},
		{name="air", prob=254, param2=0},
		{name="air", prob=254, param2=0},
		{name="air", prob=254, param2=0},
		{name="stairs:stair_dry_wood", prob=254, param2=23},
		{name="everness:cursed_brick_mixed", prob=254, param2=0},
		{name="everness:cursed_brick_mixed", prob=254, param2=0},
		{name="everness:cursed_brick_mixed", prob=254, param2=0},
		{name="everness:cursed_brick_mixed", prob=254, param2=0},
		{name="everness:cursed_brick_mixed", prob=254, param2=0},
		{name="stairs:stair_dry_wood", prob=254, param2=21},
		{name="air", prob=254, param2=0},
		{name="air", prob=254, param2=0},
		{name="air", prob=254, param2=0},
		{name="air", prob=254, param2=0},
		{name="stairs:slab_dry_wood", prob=254, param2=1},
		{name="everness:dry_wood", prob=254, param2=0},
		{name="everness:dry_wood", prob=254, param2=0},
		{name="everness:dry_wood", prob=254, param2=0},
		{name="everness:dry_wood", prob=254, param2=0},
		{name="everness:dry_wood", prob=254, param2=0},
		{name="stairs:slab_dry_wood", prob=254, param2=0},
		{name="air", prob=254, param2=0},
		{name="air", prob=254, param2=0},
		{name="air", prob=254, param2=0},
		{name="air", prob=254, param2=0},
		{name="air", prob=254, param2=0},
		{name="everness:trapdoor_cursed_wood", prob=254, param2=0},
		{name="stairs:slab_dry_wood", prob=254, param2=1},
		{name="everness:dry_wood", prob=254, param2=0},
		{name="stairs:slab_dry_wood", prob=254, param2=0},
		{name="everness:trapdoor_cursed_wood", prob=254, param2=0},
		{name="air", prob=254, param2=0},
		{name="air", prob=254, param2=0},
		{name="air", prob=254, param2=0},
		{name="air", prob=254, param2=0},
		{name="air", prob=254, param2=0},
		{name="air", prob=254, param2=0},
		{name="air", prob=254, param2=0},
		{name="air", prob=254, param2=0},
		{name="air", prob=254, param2=0},
		{name="air", prob=254, param2=0},
		{name="air", prob=254, param2=0},
		{name="air", prob=254, param2=0},
		{name="air", prob=254, param2=0},
		{name="air", prob=254, param2=0},
		{name="air", prob=254, param2=0},
		{name="air", prob=254, param2=0},
		{name="air", prob=254, param2=0},
		{name="air", prob=254, param2=0},
		{name="air", prob=254, param2=0},
		{name="air", prob=254, param2=0},
		{name="air", prob=254, param2=0},
		{name="air", prob=254, param2=0},
		{name="air", prob=254, param2=0},
		{name="air", prob=254, param2=0},
		{name="air", prob=254, param2=0},
		{name="air", prob=254, param2=0},
		{name="air", prob=254, param2=0},
		{name="air", prob=254, param2=0},
		{name="air", prob=254, param2=0},
		{name="air", prob=254, param2=0},
		{name="air", prob=254, param2=0},
		{name="air", prob=254, param2=0},
		{name="air", prob=254, param2=0},
		{name="air", prob=254, param2=0},
		{name="air", prob=254, param2=0},
		{name="air", prob=254, param2=0},
		{name="air", prob=254, param2=0},
		{name="air", prob=254, param2=0},
		{name="air", prob=254, param2=0},
		{name="air", prob=254, param2=0},
		{name="air", prob=254, param2=0},
		{name="air", prob=254, param2=0},
		{name="air", prob=254, param2=0},
		{name="air", prob=254, param2=0},
		{name="air", prob=254, param2=0},
		{name="air", prob=254, param2=0},
		{name="air", prob=254, param2=0},
		{name="air", prob=0, param2=0},
		{name="air", prob=0, param2=0},
		{name="everness:cursed_dirt", prob=254, param2=0},
		{name="everness:cursed_dirt", prob=254, param2=0},
		{name="everness:cursed_dirt", prob=254, param2=0},
		{name="everness:cursed_dirt", prob=254, param2=0},
		{name="everness:cursed_dirt", prob=254, param2=0},
		{name="everness:cursed_dirt", prob=254, param2=0},
		{name="everness:cursed_dirt", prob=254, param2=0},
		{name="air", prob=0, param2=0},
		{name="air", prob=0, param2=0},
		{name="air", prob=0, param2=0},
		{name="air", prob=0, param2=0},
		{name="everness:dirt_with_cursed_grass", prob=254, param2=0},
		{name="everness:ivis_vine_end", prob=254, param2=8},
		{name="air", prob=254, param2=0},
		{name="air", prob=254, param2=0},
		{name="everness:ngrass_1", prob=254, param2=0},
		{name="air", prob=254, param2=0},
		{name="everness:dirt_with_cursed_grass", prob=254, param2=0},
		{name="air", prob=0, param2=0},
		{name="air", prob=0, param2=0},
		{name="air", prob=254, param2=0},
		{name="air", prob=254, param2=0},
		{name="everness:fence_dry_wood", prob=254, param2=0},
		{name="everness:ivis_vine_1", prob=254, param2=8},
		{name="air", prob=254, param2=0},
		{name="air", prob=254, param2=0},
		{name="air", prob=254, param2=0},
		{name="everness:dry_branches", prob=254, param2=1},
		{name="everness:fence_dry_wood", prob=254, param2=0},
		{name="air", prob=254, param2=0},
		{name="air", prob=254, param2=0},
		{name="air", prob=254, param2=0},
		{name="air", prob=254, param2=0},
		{name="everness:dry_tree", prob=254, param2=7},
		{name="everness:ivis_vine_2", prob=254, param2=8},
		{name="everness:cursed_brick", prob=254, param2=0},
		{name="everness:cursed_brick", prob=254, param2=0},
		{name="everness:cursed_brick", prob=254, param2=0},
		{name="everness:cursed_brick", prob=254, param2=0},
		{name="everness:dry_tree", prob=254, param2=9},
		{name="air", prob=254, param2=0},
		{name="air", prob=254, param2=0},
		{name="air", prob=254, param2=0},
		{name="air", prob=254, param2=0},
		{name="everness:cursed_brick_mixed", prob=254, param2=0},
		{name="everness:ivis_vine_2", prob=254, param2=8},
		{name="air", prob=254, param2=0},
		{name="stairs:stair_dry_wood", prob=254, param2=21},
		{name="stairs:slab_dry_wood", prob=254, param2=22},
		{name="stairs:stair_dry_wood", prob=254, param2=23},
		{name="everness:cursed_brick_mixed", prob=254, param2=0},
		{name="air", prob=254, param2=0},
		{name="air", prob=254, param2=0},
		{name="air", prob=254, param2=0},
		{name="air", prob=254, param2=0},
		{name="everness:trapdoor_cursed_wood_open", prob=254, param2=3},
		{name="everness:ivis_vine_2", prob=254, param2=8},
		{name="air", prob=254, param2=0},
		{name="air", prob=254, param2=0},
		{name="air", prob=254, param2=0},
		{name="air", prob=254, param2=0},
		{name="everness:trapdoor_cursed_wood_open", prob=254, param2=1},
		{name="air", prob=254, param2=0},
		{name="air", prob=254, param2=0},
		{name="air", prob=254, param2=0},
		{name="air", prob=254, param2=0},
		{name="everness:cursed_brick_mixed", prob=254, param2=0},
		{name="everness:ivis_vine_1", prob=254, param2=8},
		{name="air", prob=254, param2=0},
		{name="air", prob=254, param2=0},
		{name="air", prob=254, param2=0},
		{name="air", prob=254, param2=0},
		{name="everness:cursed_brick_mixed", prob=254, param2=0},
		{name="air", prob=254, param2=0},
		{name="air", prob=254, param2=0},
		{name="air", prob=254, param2=0},
		{name="air", prob=254, param2=0},
		{name="everness:cursed_brick_mixed", prob=254, param2=0},
		{name="stairs:slab_cursed_brick", prob=254, param2=22},
		{name="everness:dry_tree", prob=254, param2=7},
		{name="stairs:slab_cursed_brick", prob=254, param2=22},
		{name="everness:dry_tree", prob=254, param2=7},
		{name="stairs:slab_cursed_brick", prob=254, param2=21},
		{name="everness:cursed_brick_mixed", prob=254, param2=0},
		{name="air", prob=254, param2=0},
		{name="air", prob=254, param2=0},
		{name="air", prob=254, param2=0},
		{name="air", prob=254, param2=0},
		{name="everness:cursed_brick_with_growth", prob=254, param2=0},
		{name="stairs:slab_dry_wood", prob=254, param2=21},
		{name="everness:ivis_vine_end", prob=254, param2=8},
		{name="air", prob=254, param2=0},
		{name="everness:dry_branches", prob=254, param2=1},
		{name="everness:dry_branches", prob=254, param2=1},
		{name="everness:cursed_brick_with_growth", prob=254, param2=0},
		{name="air", prob=254, param2=0},
		{name="air", prob=254, param2=0},
		{name="air", prob=254, param2=0},
		{name="air", prob=254, param2=0},
		{name="everness:cursed_brick_with_growth", prob=254, param2=0},
		{name="everness:dry_branches", prob=254, param2=1},
		{name="everness:ivis_vine_1", prob=254, param2=8},
		{name="air", prob=254, param2=0},
		{name="air", prob=254, param2=0},
		{name="everness:dry_branches", prob=254, param2=1},
		{name="everness:cursed_brick_with_growth", prob=254, param2=0},
		{name="air", prob=254, param2=0},
		{name="air", prob=254, param2=0},
		{name="air", prob=254, param2=0},
		{name="stairs:stair_dry_wood", prob=254, param2=22},
		{name="everness:cursed_brick_with_growth", prob=254, param2=0},
		{name="everness:cobweb", prob=254, param2=8},
		{name="everness:ivis_vine_2", prob=254, param2=8},
		{name="air", prob=254, param2=0},
		{name="everness:dry_branches", prob=254, param2=1},
		{name="everness:dry_branches", prob=254, param2=1},
		{name="everness:cursed_brick_with_growth", prob=254, param2=0},
		{name="stairs:stair_dry_wood", prob=254, param2=22},
		{name="air", prob=254, param2=0},
		{name="air", prob=254, param2=0},
		{name="everness:dry_wood", prob=254, param2=0},
		{name="everness:cursed_brick_with_growth", prob=254, param2=0},
		{name="everness:cursed_brick", prob=254, param2=0},
		{name="everness:ivis_vine_2", prob=254, param2=8},
		{name="stairs:slab_cursed_brick", prob=254, param2=21},
		{name="stairs:slab_cursed_brick", prob=254, param2=21},
		{name="everness:cursed_brick_mixed", prob=254, param2=0},
		{name="everness:cursed_brick_with_growth", prob=254, param2=0},
		{name="everness:dry_wood", prob=254, param2=0},
		{name="air", prob=254, param2=0},
		{name="air", prob=254, param2=0},
		{name="stairs:stair_dry_wood", prob=254, param2=0},
		{name="stairs:stair_cursed_brick_with_growth", prob=254, param2=0},
		{name="everness:dry_wood", prob=254, param2=0},
		{name="everness:ivis_vine_1", prob=254, param2=8},
		{name="everness:dry_branches", prob=254, param2=1},
		{name="air", prob=254, param2=0},
		{name="everness:dry_wood", prob=254, param2=0},
		{name="stairs:stair_cursed_brick_with_growth", prob=254, param2=0},
		{name="stairs:stair_dry_wood", prob=254, param2=0},
		{name="air", prob=254, param2=0},
		{name="air", prob=254, param2=0},
		{name="air", prob=254, param2=0},
		{name="air", prob=254, param2=0},
		{name="everness:dry_wood", prob=254, param2=0},
		{name="everness:ivis_vine_1", prob=254, param2=8},
		{name="everness:cursed_dream_stone", prob=254, param2=0},
		{name="air", prob=254, param2=0},
		{name="everness:dry_wood", prob=254, param2=0},
		{name="air", prob=254, param2=0},
		{name="air", prob=254, param2=0},
		{name="air", prob=254, param2=0},
		{name="air", prob=254, param2=0},
		{name="air", prob=254, param2=0},
		{name="air", prob=254, param2=0},
		{name="everness:dry_wood", prob=254, param2=0},
		{name="everness:ivis_vine_1", prob=254, param2=8},
		{name="everness:cobweb", prob=254, param2=8},
		{name="air", prob=254, param2=0},
		{name="everness:dry_wood", prob=254, param2=0},
		{name="everness:cobweb", prob=254, param2=8},
		{name="air", prob=254, param2=0},
		{name="air", prob=254, param2=0},
		{name="air", prob=254, param2=0},
		{name="air", prob=254, param2=0},
		{name="stairs:slab_dry_wood", prob=254, param2=23},
		{name="everness:cursed_brick_mixed", prob=254, param2=0},
		{name="stairs:stair_dry_wood", prob=254, param2=21},
		{name="everness:dry_branches", prob=254, param2=1},
		{name="stairs:stair_dry_wood", prob=254, param2=23},
		{name="everness:cursed_brick_mixed", prob=254, param2=0},
		{name="stairs:slab_dry_wood", prob=254, param2=21},
		{name="air", prob=254, param2=0},
		{name="air", prob=254, param2=0},
		{name="air", prob=254, param2=0},
		{name="air", prob=254, param2=0},
		{name="everness:trapdoor_cursed_wood", prob=254, param2=1},
		{name="everness:dry_wood", prob=254, param2=0},
		{name="everness:dry_tree", prob=254, param2=22},
		{name="stairs:stair_dry_wood", prob=254, param2=22},
		{name="everness:dry_tree", prob=254, param2=22},
		{name="everness:dry_wood", prob=254, param2=0},
		{name="everness:trapdoor_cursed_wood", prob=254, param2=3},
		{name="air", prob=254, param2=0},
		{name="air", prob=254, param2=0},
		{name="air", prob=254, param2=0},
		{name="air", prob=254, param2=0},
		{name="air", prob=254, param2=0},
		{name="stairs:slab_dry_wood", prob=254, param2=1},
		{name="everness:dry_wood", prob=254, param2=0},
		{name="everness:dry_wood", prob=254, param2=0},
		{name="everness:dry_wood", prob=254, param2=0},
		{name="stairs:slab_dry_wood", prob=254, param2=0},
		{name="air", prob=254, param2=0},
		{name="air", prob=254, param2=0},
		{name="air", prob=254, param2=0},
		{name="air", prob=254, param2=0},
		{name="air", prob=254, param2=0},
		{name="air", prob=254, param2=0},
		{name="air", prob=254, param2=0},
		{name="everness:trapdoor_cursed_wood", prob=254, param2=0},
		{name="everness:dry_wood", prob=254, param2=0},
		{name="everness:trapdoor_cursed_wood", prob=254, param2=0},
		{name="air", prob=254, param2=0},
		{name="air", prob=254, param2=0},
		{name="air", prob=254, param2=0},
		{name="air", prob=254, param2=0},
		{name="air", prob=254, param2=0},
		{name="air", prob=254, param2=0},
		{name="air", prob=254, param2=0},
		{name="air", prob=254, param2=0},
		{name="air", prob=254, param2=0},
		{name="air", prob=254, param2=0},
		{name="air", prob=254, param2=0},
		{name="air", prob=254, param2=0},
		{name="air", prob=254, param2=0},
		{name="air", prob=254, param2=0},
		{name="air", prob=254, param2=0},
		{name="air", prob=254, param2=0},
		{name="air", prob=254, param2=0},
		{name="air", prob=254, param2=0},
		{name="air", prob=254, param2=0},
		{name="air", prob=254, param2=0},
		{name="air", prob=254, param2=0},
		{name="air", prob=254, param2=0},
		{name="air", prob=254, param2=0},
		{name="air", prob=254, param2=0},
		{name="air", prob=254, param2=0},
		{name="air", prob=254, param2=0},
		{name="air", prob=254, param2=0},
		{name="air", prob=254, param2=0},
		{name="air", prob=254, param2=0},
		{name="air", prob=254, param2=0},
		{name="air", prob=254, param2=0},
		{name="air", prob=254, param2=0},
		{name="air", prob=254, param2=0},
		{name="air", prob=254, param2=0},
		{name="air", prob=254, param2=0},
		{name="air", prob=254, param2=0},
		{name="air", prob=254, param2=0},
		{name="air", prob=0, param2=0},
		{name="air", prob=0, param2=0},
		{name="everness:cursed_dirt", prob=254, param2=0},
		{name="everness:cursed_dirt", prob=254, param2=0},
		{name="everness:cursed_dirt", prob=254, param2=0},
		{name="everness:cursed_dirt", prob=254, param2=0},
		{name="everness:cursed_dirt", prob=254, param2=0},
		{name="everness:cursed_dirt", prob=254, param2=0},
		{name="everness:cursed_dirt", prob=254, param2=0},
		{name="air", prob=0, param2=0},
		{name="air", prob=0, param2=0},
		{name="air", prob=0, param2=0},
		{name="air", prob=0, param2=0},
		{name="everness:dirt_with_cursed_grass", prob=254, param2=0},
		{name="air", prob=254, param2=0},
		{name="air", prob=254, param2=0},
		{name="everness:egg_plant", prob=254, param2=0},
		{name="air", prob=254, param2=0},
		{name="everness:dry_branches", prob=254, param2=1},
		{name="everness:dirt_with_cursed_grass", prob=254, param2=0},
		{name="air", prob=0, param2=0},
		{name="air", prob=0, param2=0},
		{name="air", prob=254, param2=0},
		{name="air", prob=254, param2=0},
		{name="everness:fence_dry_wood", prob=254, param2=0},
		{name="air", prob=254, param2=0},
		{name="air", prob=254, param2=0},
		{name="air", prob=254, param2=0},
		{name="air", prob=254, param2=0},
		{name="air", prob=254, param2=0},
		{name="everness:fence_dry_wood", prob=254, param2=0},
		{name="air", prob=254, param2=0},
		{name="air", prob=254, param2=0},
		{name="air", prob=254, param2=0},
		{name="air", prob=254, param2=0},
		{name="everness:dry_tree", prob=254, param2=7},
		{name="everness:cursed_brick", prob=254, param2=0},
		{name="everness:cursed_brick", prob=254, param2=0},
		{name="everness:cursed_brick", prob=254, param2=0},
		{name="everness:cursed_brick", prob=254, param2=0},
		{name="everness:cursed_brick", prob=254, param2=0},
		{name="everness:dry_tree", prob=254, param2=9},
		{name="air", prob=254, param2=0},
		{name="air", prob=254, param2=0},
		{name="air", prob=254, param2=0},
		{name="air", prob=254, param2=0},
		{name="everness:dry_tree", prob=254, param2=1},
		{name="air", prob=254, param2=0},
		{name="air", prob=254, param2=0},
		{name="air", prob=254, param2=0},
		{name="everness:cobweb", prob=254, param2=8},
		{name="everness:ivis_vine_end", prob=254, param2=8},
		{name="everness:dry_tree", prob=254, param2=3},
		{name="air", prob=254, param2=0},
		{name="air", prob=254, param2=0},
		{name="air", prob=254, param2=0},
		{name="air", prob=254, param2=0},
		{name="everness:dry_tree", prob=254, param2=1},
		{name="air", prob=254, param2=0},
		{name="air", prob=254, param2=0},
		{name="air", prob=254, param2=0},
		{name="air", prob=254, param2=0},
		{name="everness:ivis_vine_1", prob=254, param2=8},
		{name="everness:dry_tree", prob=254, param2=3},
		{name="air", prob=254, param2=0},
		{name="air", prob=254, param2=0},
		{name="air", prob=254, param2=0},
		{name="air", prob=254, param2=0},
		{name="everness:dry_tree", prob=254, param2=1},
		{name="air", prob=254, param2=0},
		{name="air", prob=254, param2=0},
		{name="air", prob=254, param2=0},
		{name="air", prob=254, param2=0},
		{name="everness:ivis_vine_1", prob=254, param2=8},
		{name="everness:dry_tree", prob=254, param2=3},
		{name="air", prob=254, param2=0},
		{name="air", prob=254, param2=0},
		{name="air", prob=254, param2=0},
		{name="air", prob=254, param2=0},
		{name="everness:dry_tree", prob=254, param2=1},
		{name="everness:cursed_brick", prob=254, param2=0},
		{name="everness:dry_tree", prob=254, param2=9},
		{name="everness:cursed_brick", prob=254, param2=0},
		{name="everness:dry_tree", prob=254, param2=9},
		{name="everness:ivis_vine_1", prob=254, param2=8},
		{name="everness:dry_tree", prob=254, param2=3},
		{name="air", prob=254, param2=0},
		{name="air", prob=254, param2=0},
		{name="air", prob=254, param2=0},
		{name="air", prob=254, param2=0},
		{name="everness:cursed_brick_with_growth", prob=254, param2=0},
		{name="stairs:slab_dry_wood", prob=254, param2=21},
		{name="air", prob=254, param2=0},
		{name="air", prob=254, param2=0},
		{name="everness:cobweb", prob=254, param2=8},
		{name="everness:ivis_vine_1", prob=254, param2=8},
		{name="everness:cursed_brick_with_growth", prob=254, param2=0},
		{name="air", prob=254, param2=0},
		{name="air", prob=254, param2=0},
		{name="air", prob=254, param2=0},
		{name="air", prob=254, param2=0},
		{name="everness:cursed_brick_with_growth", prob=254, param2=0},
		{name="everness:cobweb", prob=254, param2=8},
		{name="air", prob=254, param2=0},
		{name="air", prob=254, param2=0},
		{name="air", prob=254, param2=0},
		{name="everness:ivis_vine_1", prob=254, param2=8},
		{name="everness:cursed_brick_with_growth", prob=254, param2=0},
		{name="air", prob=254, param2=0},
		{name="air", prob=254, param2=0},
		{name="air", prob=254, param2=0},
		{name="air", prob=254, param2=0},
		{name="everness:cursed_brick_with_growth", prob=254, param2=0},
		{name="air", prob=254, param2=0},
		{name="air", prob=254, param2=0},
		{name="air", prob=254, param2=0},
		{name="air", prob=254, param2=0},
		{name="everness:dry_branches", prob=254, param2=1},
		{name="everness:cursed_brick_with_growth", prob=254, param2=0},
		{name="air", prob=254, param2=0},
		{name="air", prob=254, param2=0},
		{name="air", prob=254, param2=0},
		{name="air", prob=254, param2=0},
		{name="everness:cursed_brick_with_growth", prob=254, param2=0},
		{name="everness:cursed_brick_mixed", prob=254, param2=0},
		{name="everness:dry_tree", prob=254, param2=12},
		{name="everness:dry_tree", prob=254, param2=18},
		{name="everness:dry_tree", prob=254, param2=18},
		{name="everness:cursed_brick_mixed", prob=254, param2=0},
		{name="everness:cursed_brick_with_growth", prob=254, param2=0},
		{name="air", prob=254, param2=0},
		{name="air", prob=254, param2=0},
		{name="air", prob=254, param2=0},
		{name="stairs:stair_dry_wood", prob=254, param2=23},
		{name="everness:cursed_brick_with_growth", prob=254, param2=0},
		{name="everness:dry_wood", prob=254, param2=0},
		{name="everness:cobweb", prob=254, param2=8},
		{name="everness:cobweb", prob=254, param2=8},
		{name="air", prob=254, param2=0},
		{name="everness:dry_wood", prob=254, param2=0},
		{name="everness:cursed_brick_with_growth", prob=254, param2=0},
		{name="stairs:stair_dry_wood", prob=254, param2=21},
		{name="air", prob=254, param2=0},
		{name="stairs:stair_dry_wood", prob=254, param2=23},
		{name="everness:dry_wood", prob=254, param2=0},
		{name="everness:cursed_brick_with_growth", prob=254, param2=0},
		{name="everness:dry_wood", prob=254, param2=0},
		{name="air", prob=254, param2=0},
		{name="air", prob=254, param2=0},
		{name="air", prob=254, param2=0},
		{name="everness:dry_wood", prob=254, param2=0},
		{name="everness:cursed_brick_with_growth", prob=254, param2=0},
		{name="everness:dry_wood", prob=254, param2=0},
		{name="stairs:stair_dry_wood", prob=254, param2=21},
		{name="air", prob=254, param2=0},
		{name="air", prob=254, param2=0},
		{name="air", prob=254, param2=0},
		{name="everness:dry_wood", prob=254, param2=0},
		{name="everness:cobweb", prob=254, param2=8},
		{name="air", prob=254, param2=0},
		{name="air", prob=254, param2=0},
		{name="everness:dry_wood", prob=254, param2=0},
		{name="air", prob=254, param2=0},
		{name="air", prob=254, param2=0},
		{name="air", prob=254, param2=0},
		{name="air", prob=254, param2=0},
		{name="air", prob=254, param2=0},
		{name="stairs:stair_dry_wood", prob=254, param2=23},
		{name="everness:cursed_brick_mixed", prob=254, param2=0},
		{name="everness:dry_branches", prob=254, param2=1},
		{name="air", prob=254, param2=0},
		{name="air", prob=254, param2=0},
		{name="everness:cursed_brick_mixed", prob=254, param2=0},
		{name="stairs:stair_dry_wood", prob=254, param2=21},
		{name="air", prob=254, param2=0},
		{name="air", prob=254, param2=0},
		{name="air", prob=254, param2=0},
		{name="air", prob=254, param2=0},
		{name="stairs:stair_dry_wood", prob=254, param2=1},
		{name="everness:dry_wood", prob=254, param2=0},
		{name="stairs:stair_dry_wood", prob=254, param2=21},
		{name="everness:dry_branches", prob=254, param2=1},
		{name="stairs:stair_dry_wood", prob=254, param2=23},
		{name="everness:dry_wood", prob=254, param2=0},
		{name="stairs:stair_dry_wood", prob=254, param2=3},
		{name="air", prob=254, param2=0},
		{name="air", prob=254, param2=0},
		{name="air", prob=254, param2=0},
		{name="air", prob=254, param2=0},
		{name="air", prob=254, param2=0},
		{name="everness:dry_wood", prob=254, param2=0},
		{name="everness:dry_wood", prob=254, param2=0},
		{name="everness:dry_branches", prob=254, param2=1},
		{name="everness:dry_wood", prob=254, param2=0},
		{name="everness:dry_wood", prob=254, param2=0},
		{name="air", prob=254, param2=0},
		{name="air", prob=254, param2=0},
		{name="air", prob=254, param2=0},
		{name="air", prob=254, param2=0},
		{name="air", prob=254, param2=0},
		{name="air", prob=254, param2=0},
		{name="air", prob=254, param2=0},
		{name="everness:dry_wood", prob=254, param2=0},
		{name="everness:dry_wood", prob=254, param2=0},
		{name="everness:dry_wood", prob=254, param2=0},
		{name="air", prob=254, param2=0},
		{name="air", prob=254, param2=0},
		{name="air", prob=254, param2=0},
		{name="air", prob=254, param2=0},
		{name="air", prob=254, param2=0},
		{name="air", prob=254, param2=0},
		{name="air", prob=254, param2=0},
		{name="air", prob=254, param2=0},
		{name="air", prob=254, param2=0},
		{name="everness:dry_wood", prob=254, param2=0},
		{name="air", prob=254, param2=0},
		{name="air", prob=254, param2=0},
		{name="air", prob=254, param2=0},
		{name="air", prob=254, param2=0},
		{name="air", prob=254, param2=0},
		{name="air", prob=254, param2=0},
		{name="air", prob=254, param2=0},
		{name="air", prob=254, param2=0},
		{name="air", prob=254, param2=0},
		{name="air", prob=254, param2=0},
		{name="everness:cursed_brick_wall", prob=254, param2=0},
		{name="air", prob=254, param2=0},
		{name="air", prob=254, param2=0},
		{name="air", prob=254, param2=0},
		{name="air", prob=254, param2=0},
		{name="air", prob=254, param2=0},
		{name="air", prob=254, param2=0},
		{name="air", prob=254, param2=0},
		{name="air", prob=254, param2=0},
		{name="air", prob=254, param2=0},
		{name="air", prob=254, param2=0},
		{name="everness:fence_dry_wood", prob=254, param2=0},
		{name="air", prob=254, param2=0},
		{name="air", prob=254, param2=0},
		{name="air", prob=254, param2=0},
		{name="air", prob=254, param2=0},
		{name="air", prob=254, param2=0},
		{name="air", prob=0, param2=0},
		{name="air", prob=0, param2=0},
		{name="everness:cursed_dirt", prob=254, param2=0},
		{name="everness:cursed_dirt", prob=254, param2=0},
		{name="everness:cursed_dirt", prob=254, param2=0},
		{name="everness:cursed_dirt", prob=254, param2=0},
		{name="everness:cursed_dirt", prob=254, param2=0},
		{name="everness:cursed_dirt", prob=254, param2=0},
		{name="everness:cursed_dirt", prob=254, param2=0},
		{name="air", prob=0, param2=0},
		{name="air", prob=0, param2=0},
		{name="air", prob=0, param2=0},
		{name="air", prob=0, param2=0},
		{name="everness:dirt_with_cursed_grass", prob=254, param2=0},
		{name="everness:ngrass_1", prob=254, param2=0},
		{name="everness:ngrass_2", prob=254, param2=0},
		{name="air", prob=254, param2=0},
		{name="air", prob=254, param2=0},
		{name="everness:ngrass_2", prob=254, param2=0},
		{name="everness:dirt_with_cursed_grass", prob=254, param2=0},
		{name="air", prob=0, param2=0},
		{name="air", prob=0, param2=0},
		{name="air", prob=254, param2=0},
		{name="air", prob=254, param2=0},
		{name="everness:fence_dry_wood", prob=254, param2=0},
		{name="air", prob=254, param2=0},
		{name="air", prob=254, param2=0},
		{name="air", prob=254, param2=0},
		{name="air", prob=254, param2=0},
		{name="everness:dry_branches", prob=254, param2=1},
		{name="everness:fence_dry_wood", prob=254, param2=0},
		{name="air", prob=254, param2=0},
		{name="air", prob=254, param2=0},
		{name="air", prob=254, param2=0},
		{name="air", prob=254, param2=0},
		{name="everness:dry_tree", prob=254, param2=7},
		{name="everness:cursed_brick", prob=254, param2=0},
		{name="everness:cursed_brick", prob=254, param2=0},
		{name="everness:cursed_brick", prob=254, param2=0},
		{name="everness:cursed_brick", prob=254, param2=0},
		{name="everness:cursed_brick", prob=254, param2=0},
		{name="everness:dry_tree", prob=254, param2=9},
		{name="air", prob=254, param2=0},
		{name="air", prob=254, param2=0},
		{name="air", prob=254, param2=0},
		{name="air", prob=254, param2=0},
		{name="everness:cursed_brick_mixed", prob=254, param2=0},
		{name="everness:skull_with_candle", prob=254, param2=3},
		{name="air", prob=254, param2=0},
		{name="air", prob=254, param2=0},
		{name="air", prob=254, param2=0},
		{name="everness:cobweb", prob=254, param2=8},
		{name="everness:cursed_brick_mixed", prob=254, param2=0},
		{name="air", prob=254, param2=0},
		{name="air", prob=254, param2=0},
		{name="air", prob=254, param2=0},
		{name="air", prob=254, param2=0},
		{name="everness:trapdoor_cursed_wood_open", prob=254, param2=3},
		{name="air", prob=254, param2=0},
		{name="air", prob=254, param2=0},
		{name="air", prob=254, param2=0},
		{name="air", prob=254, param2=0},
		{name="air", prob=254, param2=0},
		{name="everness:trapdoor_cursed_wood_open", prob=254, param2=1},
		{name="air", prob=254, param2=0},
		{name="air", prob=254, param2=0},
		{name="air", prob=254, param2=0},
		{name="air", prob=254, param2=0},
		{name="everness:cursed_brick_mixed", prob=254, param2=0},
		{name="air", prob=254, param2=0},
		{name="air", prob=254, param2=0},
		{name="air", prob=254, param2=0},
		{name="air", prob=254, param2=0},
		{name="air", prob=254, param2=0},
		{name="everness:cursed_brick_mixed", prob=254, param2=0},
		{name="air", prob=254, param2=0},
		{name="air", prob=254, param2=0},
		{name="air", prob=254, param2=0},
		{name="air", prob=254, param2=0},
		{name="everness:cursed_brick_mixed", prob=254, param2=0},
		{name="stairs:slab_cursed_brick", prob=254, param2=20},
		{name="everness:dry_tree", prob=254, param2=9},
		{name="stairs:slab_cursed_brick", prob=254, param2=20},
		{name="everness:dry_tree", prob=254, param2=9},
		{name="stairs:slab_cursed_brick", prob=254, param2=21},
		{name="everness:cursed_brick_mixed", prob=254, param2=0},
		{name="air", prob=254, param2=0},
		{name="air", prob=254, param2=0},
		{name="air", prob=254, param2=0},
		{name="air", prob=254, param2=0},
		{name="everness:cursed_brick_with_growth", prob=254, param2=0},
		{name="everness:cursed_stone_carved", prob=254, param2=0},
		{name="air", prob=254, param2=0},
		{name="air", prob=254, param2=0},
		{name="air", prob=254, param2=0},
		{name="everness:cobweb", prob=254, param2=8},
		{name="everness:cursed_brick_with_growth", prob=254, param2=0},
		{name="air", prob=254, param2=0},
		{name="air", prob=254, param2=0},
		{name="air", prob=254, param2=0},
		{name="air", prob=254, param2=0},
		{name="everness:cursed_brick_with_growth", prob=254, param2=0},
		{name="everness:cursed_stone_carved", prob=254, param2=0},
		{name="air", prob=254, param2=0},
		{name="air", prob=254, param2=0},
		{name="air", prob=254, param2=0},
		{name="everness:dry_branches", prob=254, param2=1},
		{name="everness:cursed_brick_with_growth", prob=254, param2=0},
		{name="air", prob=254, param2=0},
		{name="air", prob=254, param2=0},
		{name="air", prob=254, param2=0},
		{name="stairs:stair_dry_wood", prob=254, param2=20},
		{name="everness:cursed_brick_with_growth", prob=254, param2=0},
		{name="everness:cursed_bush_leaves", prob=254, param2=1},
		{name="air", prob=254, param2=0},
		{name="air", prob=254, param2=0},
		{name="air", prob=254, param2=0},
		{name="air", prob=254, param2=0},
		{name="everness:cursed_brick_with_growth", prob=254, param2=0},
		{name="stairs:stair_dry_wood", prob=254, param2=20},
		{name="air", prob=254, param2=0},
		{name="air", prob=254, param2=0},
		{name="everness:dry_wood", prob=254, param2=0},
		{name="stairs:stair_dry_wood", prob=254, param2=2},
		{name="everness:cursed_brick_mixed", prob=254, param2=0},
		{name="stairs:slab_cursed_brick", prob=254, param2=21},
		{name="stairs:slab_cursed_brick", prob=254, param2=21},
		{name="stairs:slab_cursed_brick", prob=254, param2=20},
		{name="everness:cursed_brick_mixed", prob=254, param2=0},
		{name="stairs:stair_dry_wood", prob=254, param2=2},
		{name="everness:dry_wood", prob=254, param2=0},
		{name="air", prob=254, param2=0},
		{name="air", prob=254, param2=0},
		{name="stairs:stair_dry_wood", prob=254, param2=2},
		{name="stairs:stair_cursed_brick_with_growth", prob=254, param2=2},
		{name="everness:dry_wood", prob=254, param2=0},
		{name="everness:haunted_house_lootchest_marker", prob=254, param2=0},
		{name="everness:dry_branches", prob=254, param2=1},
		{name="air", prob=254, param2=0},
		{name="everness:dry_wood", prob=254, param2=0},
		{name="stairs:stair_cursed_brick_with_growth", prob=254, param2=2},
		{name="stairs:stair_dry_wood", prob=254, param2=2},
		{name="air", prob=254, param2=0},
		{name="air", prob=254, param2=0},
		{name="air", prob=254, param2=0},
		{name="air", prob=254, param2=0},
		{name="everness:dry_wood", prob=254, param2=0},
		{name="air", prob=254, param2=0},
		{name="everness:cursed_dream_stone", prob=254, param2=0},
		{name="air", prob=254, param2=0},
		{name="everness:dry_wood", prob=254, param2=0},
		{name="air", prob=254, param2=0},
		{name="air", prob=254, param2=0},
		{name="air", prob=254, param2=0},
		{name="air", prob=254, param2=0},
		{name="air", prob=254, param2=0},
		{name="everness:cobweb", prob=254, param2=8},
		{name="everness:dry_wood", prob=254, param2=0},
		{name="air", prob=254, param2=0},
		{name="air", prob=254, param2=0},
		{name="air", prob=254, param2=0},
		{name="everness:dry_wood", prob=254, param2=0},
		{name="air", prob=254, param2=0},
		{name="air", prob=254, param2=0},
		{name="air", prob=254, param2=0},
		{name="air", prob=254, param2=0},
		{name="air", prob=254, param2=0},
		{name="stairs:slab_dry_wood", prob=254, param2=23},
		{name="everness:cursed_brick_mixed", prob=254, param2=0},
		{name="stairs:stair_dry_wood", prob=254, param2=21},
		{name="everness:dry_branches", prob=254, param2=1},
		{name="stairs:stair_dry_wood", prob=254, param2=23},
		{name="everness:cursed_brick_mixed", prob=254, param2=0},
		{name="stairs:slab_dry_wood", prob=254, param2=21},
		{name="air", prob=254, param2=0},
		{name="air", prob=254, param2=0},
		{name="air", prob=254, param2=0},
		{name="air", prob=254, param2=0},
		{name="everness:trapdoor_cursed_wood", prob=254, param2=1},
		{name="everness:dry_wood", prob=254, param2=0},
		{name="everness:dry_tree", prob=254, param2=22},
		{name="stairs:stair_dry_wood", prob=254, param2=20},
		{name="everness:dry_tree", prob=254, param2=22},
		{name="everness:dry_wood", prob=254, param2=0},
		{name="everness:trapdoor_cursed_wood", prob=254, param2=3},
		{name="air", prob=254, param2=0},
		{name="air", prob=254, param2=0},
		{name="air", prob=254, param2=0},
		{name="air", prob=254, param2=0},
		{name="air", prob=254, param2=0},
		{name="stairs:slab_dry_wood", prob=254, param2=1},
		{name="everness:dry_wood", prob=254, param2=0},
		{name="everness:dry_wood", prob=254, param2=0},
		{name="everness:dry_wood", prob=254, param2=0},
		{name="stairs:slab_dry_wood", prob=254, param2=3},
		{name="air", prob=254, param2=0},
		{name="air", prob=254, param2=0},
		{name="air", prob=254, param2=0},
		{name="air", prob=254, param2=0},
		{name="air", prob=254, param2=0},
		{name="air", prob=254, param2=0},
		{name="air", prob=254, param2=0},
		{name="everness:trapdoor_cursed_wood", prob=254, param2=2},
		{name="everness:dry_wood", prob=254, param2=0},
		{name="everness:trapdoor_cursed_wood", prob=254, param2=2},
		{name="air", prob=254, param2=0},
		{name="air", prob=254, param2=0},
		{name="air", prob=254, param2=0},
		{name="air", prob=254, param2=0},
		{name="air", prob=254, param2=0},
		{name="air", prob=254, param2=0},
		{name="air", prob=254, param2=0},
		{name="air", prob=254, param2=0},
		{name="air", prob=254, param2=0},
		{name="air", prob=254, param2=0},
		{name="air", prob=254, param2=0},
		{name="air", prob=254, param2=0},
		{name="air", prob=254, param2=0},
		{name="air", prob=254, param2=0},
		{name="air", prob=254, param2=0},
		{name="air", prob=254, param2=0},
		{name="air", prob=254, param2=0},
		{name="air", prob=254, param2=0},
		{name="air", prob=254, param2=0},
		{name="air", prob=254, param2=0},
		{name="air", prob=254, param2=0},
		{name="air", prob=254, param2=0},
		{name="air", prob=254, param2=0},
		{name="air", prob=254, param2=0},
		{name="air", prob=254, param2=0},
		{name="air", prob=254, param2=0},
		{name="air", prob=254, param2=0},
		{name="air", prob=254, param2=0},
		{name="air", prob=254, param2=0},
		{name="air", prob=254, param2=0},
		{name="air", prob=254, param2=0},
		{name="air", prob=254, param2=0},
		{name="air", prob=254, param2=0},
		{name="air", prob=254, param2=0},
		{name="air", prob=254, param2=0},
		{name="air", prob=254, param2=0},
		{name="air", prob=254, param2=0},
		{name="air", prob=0, param2=0},
		{name="air", prob=0, param2=0},
		{name="everness:cursed_dirt", prob=254, param2=0},
		{name="everness:cursed_dirt", prob=254, param2=0},
		{name="everness:cursed_dirt", prob=254, param2=0},
		{name="everness:cursed_dirt", prob=254, param2=0},
		{name="everness:cursed_dirt", prob=254, param2=0},
		{name="everness:cursed_dirt", prob=254, param2=0},
		{name="everness:cursed_dirt", prob=254, param2=0},
		{name="air", prob=0, param2=0},
		{name="air", prob=0, param2=0},
		{name="air", prob=0, param2=0},
		{name="air", prob=0, param2=0},
		{name="everness:dry_tree", prob=254, param2=20},
		{name="everness:dirt_with_cursed_grass", prob=254, param2=0},
		{name="everness:dry_tree", prob=254, param2=20},
		{name="everness:dirt_with_cursed_grass", prob=254, param2=0},
		{name="everness:dry_tree", prob=254, param2=20},
		{name="everness:dirt_with_cursed_grass", prob=254, param2=0},
		{name="everness:dry_tree", prob=254, param2=23},
		{name="air", prob=0, param2=0},
		{name="air", prob=0, param2=0},
		{name="air", prob=254, param2=0},
		{name="air", prob=254, param2=0},
		{name="everness:dry_tree", prob=254, param2=2},
		{name="everness:fence_dry_wood", prob=254, param2=0},
		{name="everness:dry_tree", prob=254, param2=0},
		{name="everness:fence_dry_wood", prob=254, param2=0},
		{name="everness:dry_tree", prob=254, param2=0},
		{name="everness:fence_dry_wood", prob=254, param2=0},
		{name="everness:dry_tree", prob=254, param2=3},
		{name="air", prob=254, param2=0},
		{name="air", prob=254, param2=0},
		{name="air", prob=254, param2=0},
		{name="air", prob=254, param2=0},
		{name="everness:dry_tree", prob=254, param2=0},
		{name="everness:dry_tree", prob=254, param2=12},
		{name="everness:dry_tree", prob=254, param2=12},
		{name="everness:dry_tree", prob=254, param2=12},
		{name="everness:dry_tree", prob=254, param2=18},
		{name="everness:dry_tree", prob=254, param2=18},
		{name="everness:dry_tree", prob=254, param2=3},
		{name="air", prob=254, param2=0},
		{name="air", prob=254, param2=0},
		{name="air", prob=254, param2=0},
		{name="air", prob=254, param2=0},
		{name="everness:dry_tree", prob=254, param2=0},
		{name="everness:cursed_brick_carved", prob=254, param2=0},
		{name="everness:dry_tree", prob=254, param2=2},
		{name="everness:door_cursed_wood_a", prob=254, param2=0},
		{name="everness:dry_tree", prob=254, param2=2},
		{name="everness:cursed_brick_carved", prob=254, param2=0},
		{name="everness:dry_tree", prob=254, param2=3},
		{name="air", prob=254, param2=0},
		{name="air", prob=254, param2=0},
		{name="air", prob=254, param2=0},
		{name="air", prob=254, param2=0},
		{name="everness:dry_tree", prob=254, param2=0},
		{name="xpanes:cursed_bar_flat", prob=254, param2=0},
		{name="everness:dry_tree", prob=254, param2=2},
		{name="doors:hidden", prob=254, param2=0},
		{name="everness:dry_tree", prob=254, param2=2},
		{name="xpanes:cursed_bar_flat", prob=254, param2=0},
		{name="everness:dry_tree", prob=254, param2=3},
		{name="air", prob=254, param2=0},
		{name="air", prob=254, param2=0},
		{name="air", prob=254, param2=0},
		{name="air", prob=254, param2=0},
		{name="everness:dry_tree", prob=254, param2=0},
		{name="xpanes:cursed_bar_flat", prob=254, param2=0},
		{name="everness:dry_tree", prob=254, param2=2},
		{name="stairs:stair_dry_wood", prob=254, param2=22},
		{name="everness:dry_tree", prob=254, param2=2},
		{name="xpanes:cursed_bar_flat", prob=254, param2=0},
		{name="everness:dry_tree", prob=254, param2=3},
		{name="air", prob=254, param2=0},
		{name="air", prob=254, param2=0},
		{name="air", prob=254, param2=0},
		{name="air", prob=254, param2=0},
		{name="everness:dry_tree", prob=254, param2=0},
		{name="everness:cursed_brick_mixed", prob=254, param2=0},
		{name="everness:dry_tree", prob=254, param2=2},
		{name="everness:cursed_brick_mixed", prob=254, param2=0},
		{name="everness:dry_tree", prob=254, param2=2},
		{name="everness:cursed_brick_mixed", prob=254, param2=0},
		{name="everness:dry_tree", prob=254, param2=3},
		{name="air", prob=254, param2=0},
		{name="air", prob=254, param2=0},
		{name="air", prob=254, param2=0},
		{name="stairs:stair_dry_wood", prob=254, param2=20},
		{name="everness:cursed_brick_with_growth", prob=254, param2=0},
		{name="everness:cursed_brick_mixed", prob=254, param2=0},
		{name="everness:cursed_brick_with_growth", prob=254, param2=0},
		{name="everness:cursed_brick_with_growth", prob=254, param2=0},
		{name="everness:cursed_brick_with_growth", prob=254, param2=0},
		{name="everness:cursed_brick_mixed", prob=254, param2=0},
		{name="everness:cursed_brick_with_growth", prob=254, param2=0},
		{name="stairs:stair_dry_wood", prob=254, param2=20},
		{name="air", prob=254, param2=0},
		{name="air", prob=254, param2=0},
		{name="everness:dry_wood", prob=254, param2=0},
		{name="everness:cursed_brick_with_growth", prob=254, param2=0},
		{name="everness:cursed_brick_mixed", prob=254, param2=0},
		{name="stairs:stair_dry_wood", prob=254, param2=22},
		{name="stairs:stair_dry_wood", prob=254, param2=2},
		{name="everness:cursed_brick_with_growth", prob=254, param2=0},
		{name="everness:cursed_brick_mixed", prob=254, param2=0},
		{name="everness:cursed_brick_with_growth", prob=254, param2=0},
		{name="everness:dry_wood", prob=254, param2=0},
		{name="air", prob=254, param2=0},
		{name="air", prob=254, param2=0},
		{name="stairs:stair_dry_wood", prob=254, param2=2},
		{name="stairs:stair_cursed_brick_with_growth", prob=254, param2=2},
		{name="everness:cursed_brick_mixed", prob=254, param2=0},
		{name="stairs:stair_cursed_brick_with_growth", prob=254, param2=2},
		{name="stairs:stair_cursed_brick_with_growth", prob=254, param2=2},
		{name="stairs:stair_cursed_brick_with_growth", prob=254, param2=2},
		{name="everness:cursed_brick_mixed", prob=254, param2=0},
		{name="stairs:stair_cursed_brick_with_growth", prob=254, param2=2},
		{name="stairs:stair_dry_wood", prob=254, param2=2},
		{name="air", prob=254, param2=0},
		{name="air", prob=254, param2=0},
		{name="air", prob=254, param2=0},
		{name="air", prob=254, param2=0},
		{name="everness:cursed_brick_mixed", prob=254, param2=0},
		{name="everness:cursed_brick_mixed", prob=254, param2=0},
		{name="everness:cursed_brick_mixed", prob=254, param2=0},
		{name="everness:cursed_brick_mixed", prob=254, param2=0},
		{name="everness:cursed_brick_mixed", prob=254, param2=0},
		{name="everness:cobweb", prob=254, param2=8},
		{name="air", prob=254, param2=0},
		{name="air", prob=254, param2=0},
		{name="air", prob=254, param2=0},
		{name="air", prob=254, param2=0},
		{name="air", prob=254, param2=0},
		{name="everness:cursed_brick_mixed", prob=254, param2=0},
		{name="stairs:stair_dry_wood", prob=254, param2=22},
		{name="stairs:stair_dry_wood", prob=254, param2=2},
		{name="everness:dry_wood", prob=254, param2=0},
		{name="everness:cursed_brick_mixed", prob=254, param2=0},
		{name="air", prob=254, param2=0},
		{name="air", prob=254, param2=0},
		{name="air", prob=254, param2=0},
		{name="air", prob=254, param2=0},
		{name="air", prob=254, param2=0},
		{name="air", prob=254, param2=0},
		{name="everness:cursed_brick_mixed", prob=254, param2=0},
		{name="everness:dry_wood", prob=254, param2=0},
		{name="xpanes:cursed_bar", prob=254, param2=0},
		{name="everness:dry_wood", prob=254, param2=0},
		{name="everness:cursed_brick_mixed", prob=254, param2=0},
		{name="air", prob=254, param2=0},
		{name="air", prob=254, param2=0},
		{name="air", prob=254, param2=0},
		{name="air", prob=254, param2=0},
		{name="air", prob=254, param2=0},
		{name="everness:trapdoor_cursed_wood_open", prob=254, param2=1},
		{name="everness:cursed_brick_mixed", prob=254, param2=0},
		{name="everness:dry_wood", prob=254, param2=0},
		{name="stairs:stair_dry_wood", prob=254, param2=22},
		{name="stairs:stair_dry_wood", prob=254, param2=2},
		{name="everness:cursed_brick_mixed", prob=254, param2=0},
		{name="everness:trapdoor_cursed_wood_open", prob=254, param2=3},
		{name="air", prob=254, param2=0},
		{name="air", prob=254, param2=0},
		{name="air", prob=254, param2=0},
		{name="air", prob=254, param2=0},
		{name="stairs:stair_dry_wood", prob=254, param2=23},
		{name="everness:cursed_brick_mixed", prob=254, param2=0},
		{name="everness:cursed_brick_mixed", prob=254, param2=0},
		{name="everness:cursed_brick_mixed", prob=254, param2=0},
		{name="everness:cursed_brick_mixed", prob=254, param2=0},
		{name="everness:cursed_brick_mixed", prob=254, param2=0},
		{name="stairs:stair_dry_wood", prob=254, param2=21},
		{name="air", prob=254, param2=0},
		{name="air", prob=254, param2=0},
		{name="air", prob=254, param2=0},
		{name="air", prob=254, param2=0},
		{name="stairs:slab_dry_wood", prob=254, param2=2},
		{name="everness:dry_wood", prob=254, param2=0},
		{name="everness:dry_wood", prob=254, param2=0},
		{name="everness:dry_wood", prob=254, param2=0},
		{name="everness:dry_wood", prob=254, param2=0},
		{name="everness:dry_wood", prob=254, param2=0},
		{name="stairs:slab_dry_wood", prob=254, param2=3},
		{name="air", prob=254, param2=0},
		{name="air", prob=254, param2=0},
		{name="air", prob=254, param2=0},
		{name="air", prob=254, param2=0},
		{name="air", prob=254, param2=0},
		{name="everness:trapdoor_cursed_wood", prob=254, param2=2},
		{name="stairs:slab_dry_wood", prob=254, param2=1},
		{name="everness:dry_wood", prob=254, param2=0},
		{name="stairs:slab_dry_wood", prob=254, param2=3},
		{name="everness:trapdoor_cursed_wood", prob=254, param2=2},
		{name="air", prob=254, param2=0},
		{name="air", prob=254, param2=0},
		{name="air", prob=254, param2=0},
		{name="air", prob=254, param2=0},
		{name="air", prob=254, param2=0},
		{name="air", prob=254, param2=0},
		{name="air", prob=254, param2=0},
		{name="air", prob=254, param2=0},
		{name="air", prob=254, param2=0},
		{name="air", prob=254, param2=0},
		{name="air", prob=254, param2=0},
		{name="air", prob=254, param2=0},
		{name="air", prob=254, param2=0},
		{name="air", prob=254, param2=0},
		{name="air", prob=254, param2=0},
		{name="air", prob=254, param2=0},
		{name="air", prob=254, param2=0},
		{name="air", prob=254, param2=0},
		{name="air", prob=254, param2=0},
		{name="air", prob=254, param2=0},
		{name="air", prob=254, param2=0},
		{name="air", prob=254, param2=0},
		{name="air", prob=254, param2=0},
		{name="air", prob=254, param2=0},
		{name="air", prob=254, param2=0},
		{name="air", prob=254, param2=0},
		{name="air", prob=254, param2=0},
		{name="air", prob=254, param2=0},
		{name="air", prob=254, param2=0},
		{name="air", prob=254, param2=0},
		{name="air", prob=254, param2=0},
		{name="air", prob=254, param2=0},
		{name="air", prob=254, param2=0},
		{name="air", prob=254, param2=0},
		{name="air", prob=254, param2=0},
		{name="air", prob=254, param2=0},
		{name="air", prob=254, param2=0},
		{name="air", prob=254, param2=0},
		{name="air", prob=254, param2=0},
		{name="air", prob=254, param2=0},
		{name="air", prob=254, param2=0},
		{name="air", prob=254, param2=0},
		{name="air", prob=254, param2=0},
		{name="air", prob=254, param2=0},
		{name="air", prob=254, param2=0},
		{name="air", prob=254, param2=0},
		{name="air", prob=254, param2=0},
		{name="air", prob=0, param2=0},
		{name="air", prob=0, param2=0},
		{name="air", prob=0, param2=0},
		{name="air", prob=0, param2=0},
		{name="air", prob=0, param2=0},
		{name="air", prob=0, param2=0},
		{name="air", prob=0, param2=0},
		{name="air", prob=0, param2=0},
		{name="air", prob=0, param2=0},
		{name="air", prob=0, param2=0},
		{name="air", prob=0, param2=0},
		{name="air", prob=0, param2=0},
		{name="air", prob=0, param2=0},
		{name="air", prob=0, param2=0},
		{name="air", prob=0, param2=0},
		{name="air", prob=0, param2=0},
		{name="air", prob=0, param2=0},
		{name="air", prob=0, param2=0},
		{name="air", prob=0, param2=0},
		{name="air", prob=0, param2=0},
		{name="air", prob=0, param2=0},
		{name="air", prob=0, param2=0},
		{name="air", prob=254, param2=0},
		{name="air", prob=254, param2=0},
		{name="air", prob=254, param2=0},
		{name="air", prob=254, param2=0},
		{name="air", prob=254, param2=0},
		{name="air", prob=254, param2=0},
		{name="air", prob=254, param2=0},
		{name="air", prob=254, param2=0},
		{name="everness:fence_dry_wood", prob=254, param2=0},
		{name="air", prob=254, param2=0},
		{name="air", prob=254, param2=0},
		{name="air", prob=254, param2=0},
		{name="air", prob=254, param2=0},
		{name="everness:dry_tree", prob=254, param2=7},
		{name="everness:dry_wood", prob=254, param2=0},
		{name="everness:dry_wood", prob=254, param2=0},
		{name="everness:cursed_brick_carved", prob=254, param2=0},
		{name="everness:cursed_brick_carved", prob=254, param2=0},
		{name="everness:dry_wood", prob=254, param2=0},
		{name="everness:dry_tree", prob=254, param2=9},
		{name="air", prob=254, param2=0},
		{name="air", prob=254, param2=0},
		{name="air", prob=254, param2=0},
		{name="air", prob=254, param2=0},
		{name="everness:fence_dry_wood", prob=254, param2=0},
		{name="air", prob=254, param2=0},
		{name="air", prob=254, param2=0},
		{name="air", prob=254, param2=0},
		{name="air", prob=254, param2=0},
		{name="air", prob=254, param2=0},
		{name="everness:fence_dry_wood", prob=254, param2=0},
		{name="air", prob=254, param2=0},
		{name="air", prob=254, param2=0},
		{name="air", prob=254, param2=0},
		{name="air", prob=254, param2=0},
		{name="air", prob=254, param2=0},
		{name="air", prob=254, param2=0},
		{name="air", prob=254, param2=0},
		{name="air", prob=254, param2=0},
		{name="air", prob=254, param2=0},
		{name="air", prob=254, param2=0},
		{name="air", prob=254, param2=0},
		{name="air", prob=254, param2=0},
		{name="air", prob=254, param2=0},
		{name="air", prob=254, param2=0},
		{name="air", prob=254, param2=0},
		{name="air", prob=254, param2=0},
		{name="everness:cobweb", prob=254, param2=8},
		{name="air", prob=254, param2=0},
		{name="air", prob=254, param2=0},
		{name="air", prob=254, param2=0},
		{name="air", prob=254, param2=0},
		{name="air", prob=254, param2=0},
		{name="air", prob=254, param2=0},
		{name="air", prob=254, param2=0},
		{name="air", prob=254, param2=0},
		{name="air", prob=254, param2=0},
		{name="everness:fence_dry_wood", prob=254, param2=0},
		{name="air", prob=254, param2=0},
		{name="air", prob=254, param2=0},
		{name="air", prob=254, param2=0},
		{name="air", prob=254, param2=0},
		{name="everness:cobweb", prob=254, param2=8},
		{name="everness:fence_dry_wood", prob=254, param2=0},
		{name="air", prob=254, param2=0},
		{name="air", prob=254, param2=0},
		{name="air", prob=254, param2=0},
		{name="stairs:stair_dry_wood", prob=254, param2=2},
		{name="stairs:stair_dry_wood", prob=254, param2=2},
		{name="stairs:stair_dry_wood", prob=254, param2=2},
		{name="stairs:stair_dry_wood", prob=254, param2=2},
		{name="stairs:stair_dry_wood", prob=254, param2=2},
		{name="stairs:stair_dry_wood", prob=254, param2=2},
		{name="stairs:stair_dry_wood", prob=254, param2=2},
		{name="stairs:stair_dry_wood", prob=254, param2=2},
		{name="stairs:stair_dry_wood", prob=254, param2=2},
		{name="air", prob=254, param2=0},
		{name="air", prob=254, param2=0},
		{name="air", prob=254, param2=0},
		{name="everness:cobweb", prob=254, param2=8},
		{name="air", prob=254, param2=0},
		{name="air", prob=254, param2=0},
		{name="air", prob=254, param2=0},
		{name="air", prob=254, param2=0},
		{name="air", prob=254, param2=0},
		{name="air", prob=254, param2=0},
		{name="air", prob=254, param2=0},
		{name="air", prob=254, param2=0},
		{name="air", prob=254, param2=0},
		{name="air", prob=254, param2=0},
		{name="air", prob=254, param2=0},
		{name="air", prob=254, param2=0},
		{name="air", prob=254, param2=0},
		{name="air", prob=254, param2=0},
		{name="air", prob=254, param2=0},
		{name="air", prob=254, param2=0},
		{name="air", prob=254, param2=0},
		{name="air", prob=254, param2=0},
		{name="air", prob=254, param2=0},
		{name="air", prob=254, param2=0},
		{name="air", prob=254, param2=0},
		{name="air", prob=254, param2=0},
		{name="air", prob=254, param2=0},
		{name="air", prob=254, param2=0},
		{name="air", prob=254, param2=0},
		{name="air", prob=254, param2=0},
		{name="air", prob=254, param2=0},
		{name="air", prob=254, param2=0},
		{name="air", prob=254, param2=0},
		{name="air", prob=254, param2=0},
		{name="air", prob=254, param2=0},
		{name="air", prob=254, param2=0},
		{name="air", prob=254, param2=0},
		{name="air", prob=254, param2=0},
		{name="air", prob=254, param2=0},
		{name="air", prob=254, param2=0},
		{name="air", prob=254, param2=0},
		{name="air", prob=254, param2=0},
		{name="air", prob=254, param2=0},
		{name="air", prob=254, param2=0},
		{name="air", prob=254, param2=0},
		{name="air", prob=254, param2=0},
		{name="air", prob=254, param2=0},
		{name="air", prob=254, param2=0},
		{name="air", prob=254, param2=0},
		{name="air", prob=254, param2=0},
		{name="air", prob=254, param2=0},
		{name="air", prob=254, param2=0},
		{name="air", prob=254, param2=0},
		{name="air", prob=254, param2=0},
		{name="air", prob=254, param2=0},
		{name="air", prob=254, param2=0},
		{name="air", prob=254, param2=0},
		{name="air", prob=254, param2=0},
		{name="air", prob=254, param2=0},
		{name="everness:trapdoor_cursed_wood_open", prob=254, param2=2},
		{name="everness:cobweb", prob=254, param2=8},
		{name="air", prob=254, param2=0},
		{name="air", prob=254, param2=0},
		{name="everness:trapdoor_cursed_wood_open", prob=254, param2=2},
		{name="air", prob=254, param2=0},
		{name="air", prob=254, param2=0},
		{name="air", prob=254, param2=0},
		{name="air", prob=254, param2=0},
		{name="air", prob=254, param2=0},
		{name="air", prob=254, param2=0},
		{name="stairs:stair_dry_wood", prob=254, param2=22},
		{name="stairs:slab_dry_wood", prob=254, param2=22},
		{name="stairs:stair_dry_wood", prob=254, param2=22},
		{name="stairs:slab_dry_wood", prob=254, param2=22},
		{name="stairs:stair_dry_wood", prob=254, param2=22},
		{name="air", prob=254, param2=0},
		{name="air", prob=254, param2=0},
		{name="air", prob=254, param2=0},
		{name="air", prob=254, param2=0},
		{name="air", prob=254, param2=0},
		{name="air", prob=254, param2=0},
		{name="stairs:slab_dry_wood", prob=254, param2=2},
		{name="everness:trapdoor_cursed_wood", prob=254, param2=2},
		{name="stairs:stair_dry_wood", prob=254, param2=2},
		{name="everness:trapdoor_cursed_wood", prob=254, param2=2},
		{name="stairs:slab_dry_wood", prob=254, param2=2},
		{name="air", prob=254, param2=0},
		{name="air", prob=254, param2=0},
		{name="air", prob=254, param2=0},
		{name="air", prob=254, param2=0},
		{name="air", prob=254, param2=0},
		{name="air", prob=254, param2=0},
		{name="air", prob=254, param2=0},
		{name="air", prob=254, param2=0},
		{name="air", prob=254, param2=0},
		{name="air", prob=254, param2=0},
		{name="air", prob=254, param2=0},
		{name="air", prob=254, param2=0},
		{name="air", prob=254, param2=0},
		{name="air", prob=254, param2=0},
		{name="air", prob=254, param2=0},
		{name="air", prob=254, param2=0},
		{name="air", prob=254, param2=0},
		{name="air", prob=254, param2=0},
		{name="air", prob=254, param2=0},
		{name="air", prob=254, param2=0},
		{name="air", prob=254, param2=0},
		{name="air", prob=254, param2=0},
		{name="air", prob=254, param2=0},
		{name="air", prob=254, param2=0},
		{name="air", prob=254, param2=0},
		{name="air", prob=254, param2=0},
		{name="air", prob=254, param2=0},
		{name="air", prob=254, param2=0},
		{name="air", prob=254, param2=0},
		{name="air", prob=254, param2=0},
		{name="air", prob=254, param2=0},
		{name="air", prob=254, param2=0},
		{name="air", prob=254, param2=0},
		{name="air", prob=254, param2=0},
		{name="air", prob=254, param2=0},
		{name="air", prob=254, param2=0},
		{name="air", prob=254, param2=0},
		{name="air", prob=254, param2=0},
		{name="air", prob=254, param2=0},
		{name="air", prob=254, param2=0},
		{name="air", prob=254, param2=0},
		{name="air", prob=254, param2=0},
		{name="air", prob=254, param2=0},
		{name="air", prob=254, param2=0},
		{name="air", prob=254, param2=0},
		{name="air", prob=254, param2=0},
		{name="air", prob=254, param2=0},
		{name="air", prob=254, param2=0},
		{name="air", prob=254, param2=0},
		{name="air", prob=254, param2=0},
		{name="air", prob=254, param2=0},
		{name="air", prob=254, param2=0},
		{name="air", prob=254, param2=0},
		{name="air", prob=254, param2=0},
		{name="air", prob=254, param2=0},
		{name="air", prob=254, param2=0},
		{name="air", prob=254, param2=0},
		{name="air", prob=254, param2=0},
		{name="air", prob=0, param2=0},
		{name="air", prob=0, param2=0},
		{name="air", prob=0, param2=0},
		{name="air", prob=0, param2=0},
		{name="air", prob=0, param2=0},
		{name="air", prob=0, param2=0},
		{name="air", prob=0, param2=0},
		{name="air", prob=0, param2=0},
		{name="air", prob=0, param2=0},
		{name="air", prob=0, param2=0},
		{name="air", prob=0, param2=0},
		{name="air", prob=0, param2=0},
		{name="air", prob=0, param2=0},
		{name="air", prob=0, param2=0},
		{name="air", prob=0, param2=0},
		{name="air", prob=0, param2=0},
		{name="air", prob=0, param2=0},
		{name="air", prob=0, param2=0},
		{name="air", prob=0, param2=0},
		{name="air", prob=0, param2=0},
		{name="air", prob=0, param2=0},
		{name="air", prob=0, param2=0},
		{name="air", prob=254, param2=0},
		{name="air", prob=254, param2=0},
		{name="air", prob=254, param2=0},
		{name="air", prob=254, param2=0},
		{name="air", prob=254, param2=0},
		{name="air", prob=254, param2=0},
		{name="air", prob=254, param2=0},
		{name="air", prob=254, param2=0},
		{name="everness:fence_dry_wood", prob=254, param2=0},
		{name="air", prob=254, param2=0},
		{name="air", prob=254, param2=0},
		{name="air", prob=254, param2=0},
		{name="air", prob=254, param2=0},
		{name="everness:dry_tree", prob=254, param2=7},
		{name="everness:cursed_brick_carved", prob=254, param2=0},
		{name="everness:dry_wood", prob=254, param2=0},
		{name="everness:cursed_brick_carved", prob=254, param2=0},
		{name="everness:dry_wood", prob=254, param2=0},
		{name="everness:cursed_brick_carved", prob=254, param2=0},
		{name="everness:dry_tree", prob=254, param2=9},
		{name="air", prob=254, param2=0},
		{name="air", prob=254, param2=0},
		{name="air", prob=254, param2=0},
		{name="air", prob=254, param2=0},
		{name="everness:fence_dry_wood", prob=254, param2=0},
		{name="air", prob=254, param2=0},
		{name="air", prob=254, param2=0},
		{name="air", prob=254, param2=0},
		{name="air", prob=254, param2=0},
		{name="air", prob=254, param2=0},
		{name="everness:fence_dry_wood", prob=254, param2=0},
		{name="air", prob=254, param2=0},
		{name="air", prob=254, param2=0},
		{name="air", prob=254, param2=0},
		{name="air", prob=254, param2=0},
		{name="air", prob=254, param2=0},
		{name="air", prob=254, param2=0},
		{name="air", prob=254, param2=0},
		{name="air", prob=254, param2=0},
		{name="air", prob=254, param2=0},
		{name="air", prob=254, param2=0},
		{name="air", prob=254, param2=0},
		{name="air", prob=254, param2=0},
		{name="air", prob=254, param2=0},
		{name="air", prob=254, param2=0},
		{name="air", prob=254, param2=0},
		{name="air", prob=254, param2=0},
		{name="air", prob=254, param2=0},
		{name="air", prob=254, param2=0},
		{name="air", prob=254, param2=0},
		{name="air", prob=254, param2=0},
		{name="air", prob=254, param2=0},
		{name="air", prob=254, param2=0},
		{name="air", prob=254, param2=0},
		{name="air", prob=254, param2=0},
		{name="air", prob=254, param2=0},
		{name="air", prob=254, param2=0},
		{name="everness:fence_dry_wood", prob=254, param2=0},
		{name="air", prob=254, param2=0},
		{name="air", prob=254, param2=0},
		{name="air", prob=254, param2=0},
		{name="air", prob=254, param2=0},
		{name="air", prob=254, param2=0},
		{name="everness:fence_dry_wood", prob=254, param2=0},
		{name="air", prob=254, param2=0},
		{name="air", prob=254, param2=0},
		{name="air", prob=254, param2=0},
		{name="stairs:slab_dry_wood", prob=254, param2=2},
		{name="stairs:slab_dry_wood", prob=254, param2=2},
		{name="stairs:slab_dry_wood", prob=254, param2=2},
		{name="everness:trapdoor_cursed_wood", prob=254, param2=2},
		{name="stairs:slab_dry_wood", prob=254, param2=2},
		{name="stairs:slab_dry_wood", prob=254, param2=2},
		{name="stairs:slab_dry_wood", prob=254, param2=2},
		{name="stairs:slab_dry_wood", prob=254, param2=2},
		{name="stairs:slab_dry_wood", prob=254, param2=2},
		{name="air", prob=254, param2=0},
		{name="air", prob=254, param2=0},
		{name="air", prob=254, param2=0},
		{name="air", prob=254, param2=0},
		{name="air", prob=254, param2=0},
		{name="air", prob=254, param2=0},
		{name="air", prob=254, param2=0},
		{name="air", prob=254, param2=0},
		{name="air", prob=254, param2=0},
		{name="air", prob=254, param2=0},
		{name="air", prob=254, param2=0},
		{name="air", prob=254, param2=0},
		{name="air", prob=254, param2=0},
		{name="air", prob=254, param2=0},
		{name="air", prob=254, param2=0},
		{name="air", prob=254, param2=0},
		{name="air", prob=254, param2=0},
		{name="air", prob=254, param2=0},
		{name="air", prob=254, param2=0},
		{name="air", prob=254, param2=0},
		{name="air", prob=254, param2=0},
		{name="air", prob=254, param2=0},
		{name="air", prob=254, param2=0},
		{name="air", prob=254, param2=0},
		{name="air", prob=254, param2=0},
		{name="air", prob=254, param2=0},
		{name="air", prob=254, param2=0},
		{name="air", prob=254, param2=0},
		{name="air", prob=254, param2=0},
		{name="air", prob=254, param2=0},
		{name="air", prob=254, param2=0},
		{name="air", prob=254, param2=0},
		{name="air", prob=254, param2=0},
		{name="air", prob=254, param2=0},
		{name="air", prob=254, param2=0},
		{name="air", prob=254, param2=0},
		{name="air", prob=254, param2=0},
		{name="air", prob=254, param2=0},
		{name="air", prob=254, param2=0},
		{name="air", prob=254, param2=0},
		{name="air", prob=254, param2=0},
		{name="air", prob=254, param2=0},
		{name="air", prob=254, param2=0},
		{name="air", prob=254, param2=0},
		{name="air", prob=254, param2=0},
		{name="air", prob=254, param2=0},
		{name="air", prob=254, param2=0},
		{name="air", prob=254, param2=0},
		{name="air", prob=254, param2=0},
		{name="air", prob=254, param2=0},
		{name="air", prob=254, param2=0},
		{name="air", prob=254, param2=0},
		{name="air", prob=254, param2=0},
		{name="air", prob=254, param2=0},
		{name="air", prob=254, param2=0},
		{name="air", prob=254, param2=0},
		{name="air", prob=254, param2=0},
		{name="air", prob=254, param2=0},
		{name="air", prob=254, param2=0},
		{name="air", prob=254, param2=0},
		{name="air", prob=254, param2=0},
		{name="air", prob=254, param2=0},
		{name="air", prob=254, param2=0},
		{name="air", prob=254, param2=0},
		{name="air", prob=254, param2=0},
		{name="air", prob=254, param2=0},
		{name="air", prob=254, param2=0},
		{name="air", prob=254, param2=0},
		{name="air", prob=254, param2=0},
		{name="air", prob=254, param2=0},
		{name="air", prob=254, param2=0},
		{name="air", prob=254, param2=0},
		{name="air", prob=254, param2=0},
		{name="air", prob=254, param2=0},
		{name="air", prob=254, param2=0},
		{name="air", prob=254, param2=0},
		{name="air", prob=254, param2=0},
		{name="air", prob=254, param2=0},
		{name="air", prob=254, param2=0},
		{name="air", prob=254, param2=0},
		{name="air", prob=254, param2=0},
		{name="air", prob=254, param2=0},
		{name="air", prob=254, param2=0},
		{name="air", prob=254, param2=0},
		{name="air", prob=254, param2=0},
		{name="air", prob=254, param2=0},
		{name="air", prob=254, param2=0},
		{name="air", prob=254, param2=0},
		{name="air", prob=254, param2=0},
		{name="air", prob=254, param2=0},
		{name="air", prob=254, param2=0},
		{name="air", prob=254, param2=0},
		{name="air", prob=254, param2=0},
		{name="air", prob=254, param2=0},
		{name="air", prob=254, param2=0},
		{name="air", prob=254, param2=0},
		{name="air", prob=254, param2=0},
		{name="air", prob=254, param2=0},
		{name="air", prob=254, param2=0},
		{name="air", prob=254, param2=0},
		{name="air", prob=254, param2=0},
		{name="air", prob=254, param2=0},
		{name="air", prob=254, param2=0},
		{name="air", prob=254, param2=0},
		{name="air", prob=254, param2=0},
		{name="air", prob=254, param2=0},
		{name="air", prob=254, param2=0},
		{name="air", prob=254, param2=0},
		{name="air", prob=254, param2=0},
		{name="air", prob=254, param2=0},
		{name="air", prob=254, param2=0},
		{name="air", prob=254, param2=0},
		{name="air", prob=254, param2=0},
		{name="air", prob=254, param2=0},
		{name="air", prob=254, param2=0},
		{name="air", prob=254, param2=0},
		{name="air", prob=254, param2=0},
		{name="air", prob=254, param2=0},
		{name="air", prob=254, param2=0},
		{name="air", prob=254, param2=0},
		{name="air", prob=254, param2=0},
		{name="air", prob=254, param2=0},
		{name="air", prob=254, param2=0},
		{name="air", prob=254, param2=0},
		{name="air", prob=254, param2=0},
		{name="air", prob=254, param2=0},
		{name="air", prob=254, param2=0},
		{name="air", prob=254, param2=0},
		{name="air", prob=254, param2=0},
		{name="air", prob=254, param2=0},
		{name="air", prob=254, param2=0},
		{name="air", prob=254, param2=0},
		{name="air", prob=254, param2=0},
		{name="air", prob=254, param2=0},
		{name="air", prob=254, param2=0},
		{name="air", prob=254, param2=0},
		{name="air", prob=254, param2=0},
		{name="air", prob=254, param2=0},
		{name="air", prob=254, param2=0},
		{name="air", prob=254, param2=0},
		{name="air", prob=254, param2=0},
		{name="air", prob=254, param2=0},
		{name="air", prob=254, param2=0},
		{name="air", prob=254, param2=0},
		{name="air", prob=0, param2=0},
		{name="air", prob=0, param2=0},
		{name="air", prob=0, param2=0},
		{name="air", prob=0, param2=0},
		{name="air", prob=0, param2=0},
		{name="air", prob=0, param2=0},
		{name="air", prob=0, param2=0},
		{name="air", prob=0, param2=0},
		{name="air", prob=0, param2=0},
		{name="air", prob=0, param2=0},
		{name="air", prob=0, param2=0},
		{name="air", prob=0, param2=0},
		{name="air", prob=0, param2=0},
		{name="air", prob=0, param2=0},
		{name="air", prob=0, param2=0},
		{name="air", prob=0, param2=0},
		{name="air", prob=0, param2=0},
		{name="air", prob=0, param2=0},
		{name="air", prob=0, param2=0},
		{name="air", prob=0, param2=0},
		{name="air", prob=0, param2=0},
		{name="air", prob=0, param2=0},
		{name="air", prob=254, param2=0},
		{name="air", prob=254, param2=0},
		{name="everness:dry_tree", prob=254, param2=3},
		{name="air", prob=254, param2=0},
		{name="everness:dry_tree", prob=254, param2=2},
		{name="air", prob=254, param2=0},
		{name="everness:dry_tree", prob=254, param2=2},
		{name="air", prob=254, param2=0},
		{name="everness:dry_tree", prob=254, param2=3},
		{name="air", prob=254, param2=0},
		{name="air", prob=254, param2=0},
		{name="air", prob=254, param2=0},
		{name="air", prob=254, param2=0},
		{name="everness:dry_tree", prob=254, param2=3},
		{name="everness:dry_tree", prob=254, param2=12},
		{name="everness:dry_tree", prob=254, param2=2},
		{name="stairs:stair_cursed_brick_with_growth", prob=254, param2=2},
		{name="everness:dry_tree", prob=254, param2=2},
		{name="everness:dry_tree", prob=254, param2=12},
		{name="everness:dry_tree", prob=254, param2=3},
		{name="everness:cobweb", prob=254, param2=8},
		{name="air", prob=254, param2=0},
		{name="air", prob=254, param2=0},
		{name="air", prob=254, param2=0},
		{name="everness:dry_tree", prob=254, param2=3},
		{name="everness:fence_dry_wood", prob=254, param2=0},
		{name="everness:dry_tree", prob=254, param2=2},
		{name="everness:cobweb", prob=254, param2=8},
		{name="everness:dry_tree", prob=254, param2=2},
		{name="everness:fence_dry_wood", prob=254, param2=0},
		{name="everness:dry_tree", prob=254, param2=3},
		{name="air", prob=254, param2=0},
		{name="air", prob=254, param2=0},
		{name="air", prob=254, param2=0},
		{name="air", prob=254, param2=0},
		{name="everness:fence_dry_wood", prob=254, param2=0},
		{name="air", prob=254, param2=0},
		{name="everness:fence_dry_wood", prob=254, param2=0},
		{name="air", prob=254, param2=0},
		{name="everness:fence_dry_wood", prob=254, param2=0},
		{name="air", prob=254, param2=0},
		{name="everness:fence_dry_wood", prob=254, param2=0},
		{name="air", prob=254, param2=0},
		{name="air", prob=254, param2=0},
		{name="air", prob=254, param2=0},
		{name="air", prob=254, param2=0},
		{name="everness:fence_dry_wood", prob=254, param2=0},
		{name="air", prob=254, param2=0},
		{name="everness:fence_dry_wood", prob=254, param2=0},
		{name="air", prob=254, param2=0},
		{name="everness:fence_dry_wood", prob=254, param2=0},
		{name="air", prob=254, param2=0},
		{name="everness:fence_dry_wood", prob=254, param2=0},
		{name="air", prob=254, param2=0},
		{name="air", prob=254, param2=0},
		{name="air", prob=254, param2=0},
		{name="air", prob=254, param2=0},
		{name="everness:fence_dry_wood", prob=254, param2=0},
		{name="everness:fence_dry_wood", prob=254, param2=0},
		{name="everness:fence_dry_wood", prob=254, param2=0},
		{name="everness:fence_dry_wood", prob=254, param2=0},
		{name="everness:fence_dry_wood", prob=254, param2=0},
		{name="everness:fence_dry_wood", prob=254, param2=0},
		{name="everness:fence_dry_wood", prob=254, param2=0},
		{name="air", prob=254, param2=0},
		{name="air", prob=254, param2=0},
		{name="air", prob=254, param2=0},
		{name="stairs:slab_dry_wood", prob=254, param2=2},
		{name="everness:trapdoor_cursed_wood", prob=254, param2=2},
		{name="stairs:slab_dry_wood", prob=254, param2=2},
		{name="stairs:slab_dry_wood", prob=254, param2=2},
		{name="stairs:slab_dry_wood", prob=254, param2=2},
		{name="everness:trapdoor_cursed_wood", prob=254, param2=2},
		{name="everness:trapdoor_cursed_wood", prob=254, param2=2},
		{name="stairs:slab_dry_wood", prob=254, param2=2},
		{name="stairs:slab_dry_wood", prob=254, param2=2},
		{name="air", prob=254, param2=0},
		{name="air", prob=254, param2=0},
		{name="air", prob=254, param2=0},
		{name="air", prob=254, param2=0},
		{name="air", prob=254, param2=0},
		{name="air", prob=254, param2=0},
		{name="air", prob=254, param2=0},
		{name="air", prob=254, param2=0},
		{name="air", prob=254, param2=0},
		{name="air", prob=254, param2=0},
		{name="air", prob=254, param2=0},
		{name="air", prob=254, param2=0},
		{name="air", prob=254, param2=0},
		{name="air", prob=254, param2=0},
		{name="air", prob=254, param2=0},
		{name="air", prob=254, param2=0},
		{name="air", prob=254, param2=0},
		{name="air", prob=254, param2=0},
		{name="air", prob=254, param2=0},
		{name="air", prob=254, param2=0},
		{name="air", prob=254, param2=0},
		{name="air", prob=254, param2=0},
		{name="air", prob=254, param2=0},
		{name="air", prob=254, param2=0},
		{name="air", prob=254, param2=0},
		{name="air", prob=254, param2=0},
		{name="air", prob=254, param2=0},
		{name="air", prob=254, param2=0},
		{name="air", prob=254, param2=0},
		{name="air", prob=254, param2=0},
		{name="air", prob=254, param2=0},
		{name="air", prob=254, param2=0},
		{name="air", prob=254, param2=0},
		{name="air", prob=254, param2=0},
		{name="air", prob=254, param2=0},
		{name="air", prob=254, param2=0},
		{name="air", prob=254, param2=0},
		{name="air", prob=254, param2=0},
		{name="air", prob=254, param2=0},
		{name="air", prob=254, param2=0},
		{name="air", prob=254, param2=0},
		{name="air", prob=254, param2=0},
		{name="air", prob=254, param2=0},
		{name="air", prob=254, param2=0},
		{name="air", prob=254, param2=0},
		{name="air", prob=254, param2=0},
		{name="air", prob=254, param2=0},
		{name="air", prob=254, param2=0},
		{name="air", prob=254, param2=0},
		{name="air", prob=254, param2=0},
		{name="air", prob=254, param2=0},
		{name="air", prob=254, param2=0},
		{name="air", prob=254, param2=0},
		{name="air", prob=254, param2=0},
		{name="air", prob=254, param2=0},
		{name="air", prob=254, param2=0},
		{name="air", prob=254, param2=0},
		{name="air", prob=254, param2=0},
		{name="air", prob=254, param2=0},
		{name="air", prob=254, param2=0},
		{name="air", prob=254, param2=0},
		{name="air", prob=254, param2=0},
		{name="air", prob=254, param2=0},
		{name="air", prob=254, param2=0},
		{name="air", prob=254, param2=0},
		{name="air", prob=254, param2=0},
		{name="air", prob=254, param2=0},
		{name="air", prob=254, param2=0},
		{name="air", prob=254, param2=0},
		{name="air", prob=254, param2=0},
		{name="air", prob=254, param2=0},
		{name="air", prob=254, param2=0},
		{name="air", prob=254, param2=0},
		{name="air", prob=254, param2=0},
		{name="air", prob=254, param2=0},
		{name="air", prob=254, param2=0},
		{name="air", prob=254, param2=0},
		{name="air", prob=254, param2=0},
		{name="air", prob=254, param2=0},
		{name="air", prob=254, param2=0},
		{name="air", prob=254, param2=0},
		{name="air", prob=254, param2=0},
		{name="air", prob=254, param2=0},
		{name="air", prob=254, param2=0},
		{name="air", prob=254, param2=0},
		{name="air", prob=254, param2=0},
		{name="air", prob=254, param2=0},
		{name="air", prob=254, param2=0},
		{name="air", prob=254, param2=0},
		{name="air", prob=254, param2=0},
		{name="air", prob=254, param2=0},
		{name="air", prob=254, param2=0},
		{name="air", prob=254, param2=0},
		{name="air", prob=254, param2=0},
		{name="air", prob=254, param2=0},
		{name="air", prob=254, param2=0},
		{name="air", prob=254, param2=0},
		{name="air", prob=254, param2=0},
		{name="air", prob=254, param2=0},
		{name="air", prob=254, param2=0},
		{name="air", prob=254, param2=0},
		{name="air", prob=254, param2=0},
		{name="air", prob=254, param2=0},
		{name="air", prob=254, param2=0},
		{name="air", prob=254, param2=0},
		{name="air", prob=254, param2=0},
		{name="air", prob=254, param2=0},
		{name="air", prob=254, param2=0},
		{name="air", prob=254, param2=0},
		{name="air", prob=254, param2=0},
		{name="air", prob=254, param2=0},
		{name="air", prob=254, param2=0},
		{name="air", prob=254, param2=0},
		{name="air", prob=254, param2=0},
		{name="air", prob=254, param2=0},
		{name="air", prob=254, param2=0},
		{name="air", prob=254, param2=0},
		{name="air", prob=254, param2=0},
		{name="air", prob=254, param2=0},
		{name="air", prob=254, param2=0},
		{name="air", prob=254, param2=0},
		{name="air", prob=254, param2=0},
		{name="air", prob=254, param2=0},
		{name="air", prob=254, param2=0},
		{name="air", prob=254, param2=0},
		{name="air", prob=254, param2=0},
		{name="air", prob=254, param2=0},
		{name="air", prob=254, param2=0},
		{name="air", prob=254, param2=0},
		{name="air", prob=254, param2=0},
		{name="air", prob=254, param2=0},
		{name="air", prob=254, param2=0},
		{name="air", prob=254, param2=0},
		{name="air", prob=254, param2=0},
		{name="air", prob=254, param2=0},
		{name="air", prob=254, param2=0},
		{name="air", prob=254, param2=0},
		{name="air", prob=254, param2=0},
		{name="air", prob=254, param2=0},
		{name="air", prob=254, param2=0},
		{name="air", prob=254, param2=0},
		{name="air", prob=254, param2=0},
		{name="air", prob=254, param2=0},
		{name="air", prob=254, param2=0},
		{name="air", prob=0, param2=0},
		{name="air", prob=0, param2=0},
		{name="air", prob=0, param2=0},
		{name="air", prob=0, param2=0},
		{name="air", prob=0, param2=0},
		{name="air", prob=0, param2=0},
		{name="air", prob=0, param2=0},
		{name="air", prob=0, param2=0},
		{name="air", prob=0, param2=0},
		{name="air", prob=0, param2=0},
		{name="air", prob=0, param2=0},
		{name="air", prob=0, param2=0},
		{name="air", prob=0, param2=0},
		{name="air", prob=0, param2=0},
		{name="air", prob=0, param2=0},
		{name="air", prob=0, param2=0},
		{name="air", prob=0, param2=0},
		{name="air", prob=0, param2=0},
		{name="air", prob=0, param2=0},
		{name="air", prob=0, param2=0},
		{name="air", prob=0, param2=0},
		{name="air", prob=0, param2=0},
		{name="air", prob=254, param2=0},
		{name="air", prob=254, param2=0},
		{name="air", prob=254, param2=0},
		{name="everness:dry_branches", prob=254, param2=1},
		{name="everness:dry_tree", prob=254, param2=2},
		{name="stairs:stair_cursed_brick_with_growth", prob=254, param2=2},
		{name="everness:dry_tree", prob=254, param2=2},
		{name="everness:dry_branches", prob=254, param2=1},
		{name="air", prob=254, param2=0},
		{name="air", prob=254, param2=0},
		{name="air", prob=254, param2=0},
		{name="air", prob=254, param2=0},
		{name="air", prob=254, param2=0},
		{name="air", prob=254, param2=0},
		{name="air", prob=254, param2=0},
		{name="everness:dry_branches", prob=254, param2=1},
		{name="air", prob=254, param2=0},
		{name="everness:dry_branches", prob=254, param2=1},
		{name="everness:cobweb", prob=254, param2=8},
		{name="air", prob=254, param2=0},
		{name="air", prob=254, param2=0},
		{name="air", prob=254, param2=0},
		{name="air", prob=254, param2=0},
		{name="air", prob=254, param2=0},
		{name="air", prob=254, param2=0},
		{name="air", prob=254, param2=0},
		{name="air", prob=254, param2=0},
		{name="air", prob=254, param2=0},
		{name="air", prob=254, param2=0},
		{name="air", prob=254, param2=0},
		{name="air", prob=254, param2=0},
		{name="air", prob=254, param2=0},
		{name="air", prob=254, param2=0},
		{name="air", prob=254, param2=0},
		{name="air", prob=254, param2=0},
		{name="air", prob=254, param2=0},
		{name="air", prob=254, param2=0},
		{name="air", prob=254, param2=0},
		{name="air", prob=254, param2=0},
		{name="air", prob=254, param2=0},
		{name="air", prob=254, param2=0},
		{name="air", prob=254, param2=0},
		{name="air", prob=254, param2=0},
		{name="air", prob=254, param2=0},
		{name="air", prob=254, param2=0},
		{name="air", prob=254, param2=0},
		{name="air", prob=254, param2=0},
		{name="air", prob=254, param2=0},
		{name="air", prob=254, param2=0},
		{name="air", prob=254, param2=0},
		{name="air", prob=254, param2=0},
		{name="air", prob=254, param2=0},
		{name="air", prob=254, param2=0},
		{name="air", prob=254, param2=0},
		{name="air", prob=254, param2=0},
		{name="air", prob=254, param2=0},
		{name="air", prob=254, param2=0},
		{name="air", prob=254, param2=0},
		{name="air", prob=254, param2=0},
		{name="air", prob=254, param2=0},
		{name="air", prob=254, param2=0},
		{name="air", prob=254, param2=0},
		{name="air", prob=254, param2=0},
		{name="air", prob=254, param2=0},
		{name="air", prob=254, param2=0},
		{name="air", prob=254, param2=0},
		{name="air", prob=254, param2=0},
		{name="air", prob=254, param2=0},
		{name="air", prob=254, param2=0},
		{name="air", prob=254, param2=0},
		{name="air", prob=254, param2=0},
		{name="air", prob=254, param2=0},
		{name="air", prob=254, param2=0},
		{name="air", prob=254, param2=0},
		{name="air", prob=254, param2=0},
		{name="air", prob=254, param2=0},
		{name="air", prob=254, param2=0},
		{name="air", prob=254, param2=0},
		{name="air", prob=254, param2=0},
		{name="air", prob=254, param2=0},
		{name="air", prob=254, param2=0},
		{name="air", prob=254, param2=0},
		{name="air", prob=254, param2=0},
		{name="air", prob=254, param2=0},
		{name="air", prob=254, param2=0},
		{name="air", prob=254, param2=0},
		{name="air", prob=254, param2=0},
		{name="air", prob=254, param2=0},
		{name="air", prob=254, param2=0},
		{name="air", prob=254, param2=0},
		{name="air", prob=254, param2=0},
		{name="air", prob=254, param2=0},
		{name="air", prob=254, param2=0},
		{name="air", prob=254, param2=0},
		{name="air", prob=254, param2=0},
		{name="air", prob=254, param2=0},
		{name="air", prob=254, param2=0},
		{name="air", prob=254, param2=0},
		{name="air", prob=254, param2=0},
		{name="air", prob=254, param2=0},
		{name="air", prob=254, param2=0},
		{name="air", prob=254, param2=0},
		{name="air", prob=254, param2=0},
		{name="air", prob=254, param2=0},
		{name="air", prob=254, param2=0},
		{name="air", prob=254, param2=0},
		{name="air", prob=254, param2=0},
		{name="air", prob=254, param2=0},
		{name="air", prob=254, param2=0},
		{name="air", prob=254, param2=0},
		{name="air", prob=254, param2=0},
		{name="air", prob=254, param2=0},
		{name="air", prob=254, param2=0},
		{name="air", prob=254, param2=0},
		{name="air", prob=254, param2=0},
		{name="air", prob=254, param2=0},
		{name="air", prob=254, param2=0},
		{name="air", prob=254, param2=0},
		{name="air", prob=254, param2=0},
		{name="air", prob=254, param2=0},
		{name="air", prob=254, param2=0},
		{name="air", prob=254, param2=0},
		{name="air", prob=254, param2=0},
		{name="air", prob=254, param2=0},
		{name="air", prob=254, param2=0},
		{name="air", prob=254, param2=0},
		{name="air", prob=254, param2=0},
		{name="air", prob=254, param2=0},
		{name="air", prob=254, param2=0},
		{name="air", prob=254, param2=0},
		{name="air", prob=254, param2=0},
		{name="air", prob=254, param2=0},
		{name="air", prob=254, param2=0},
		{name="air", prob=254, param2=0},
		{name="air", prob=254, param2=0},
		{name="air", prob=254, param2=0},
		{name="air", prob=254, param2=0},
		{name="air", prob=254, param2=0},
		{name="air", prob=254, param2=0},
		{name="air", prob=254, param2=0},
		{name="air", prob=254, param2=0},
		{name="air", prob=254, param2=0},
		{name="air", prob=254, param2=0},
		{name="air", prob=254, param2=0},
		{name="air", prob=254, param2=0},
		{name="air", prob=254, param2=0},
		{name="air", prob=254, param2=0},
		{name="air", prob=254, param2=0},
		{name="air", prob=254, param2=0},
		{name="air", prob=254, param2=0},
		{name="air", prob=254, param2=0},
		{name="air", prob=254, param2=0},
		{name="air", prob=254, param2=0},
		{name="air", prob=254, param2=0},
		{name="air", prob=254, param2=0},
		{name="air", prob=254, param2=0},
		{name="air", prob=254, param2=0},
		{name="air", prob=254, param2=0},
		{name="air", prob=254, param2=0},
		{name="air", prob=254, param2=0},
		{name="air", prob=254, param2=0},
		{name="air", prob=254, param2=0},
		{name="air", prob=254, param2=0},
		{name="air", prob=254, param2=0},
		{name="air", prob=254, param2=0},
		{name="air", prob=254, param2=0},
		{name="air", prob=254, param2=0},
		{name="air", prob=254, param2=0},
		{name="air", prob=254, param2=0},
		{name="air", prob=254, param2=0},
		{name="air", prob=254, param2=0},
		{name="air", prob=254, param2=0},
		{name="air", prob=254, param2=0},
		{name="air", prob=254, param2=0},
		{name="air", prob=254, param2=0},
		{name="air", prob=254, param2=0},
		{name="air", prob=254, param2=0},
		{name="air", prob=254, param2=0},
		{name="air", prob=254, param2=0},
		{name="air", prob=254, param2=0},
		{name="air", prob=254, param2=0},
		{name="air", prob=254, param2=0},
		{name="air", prob=254, param2=0},
		{name="air", prob=254, param2=0},
		{name="air", prob=254, param2=0},
		{name="air", prob=254, param2=0},
		{name="air", prob=254, param2=0},
		{name="air", prob=254, param2=0},
		{name="air", prob=254, param2=0},
		{name="air", prob=254, param2=0},
		{name="air", prob=254, param2=0},
		{name="air", prob=254, param2=0},
		{name="air", prob=254, param2=0},
		{name="air", prob=254, param2=0},
		{name="air", prob=254, param2=0},
		{name="air", prob=254, param2=0},
		{name="air", prob=254, param2=0},
		{name="air", prob=254, param2=0},
		{name="air", prob=254, param2=0},
		{name="air", prob=254, param2=0},
		{name="air", prob=254, param2=0},
		{name="air", prob=254, param2=0},
