schematic = {
	size = {x=7, y=7, z=12},
	yslice_prob = {
		{ypos=0, prob=254},
		{ypos=1, prob=254},
		{ypos=2, prob=254},
		{ypos=3, prob=254},
		{ypos=4, prob=254},
		{ypos=5, prob=254},
		{ypos=6, prob=254},
	},
	data = {
		{name="air", prob=0, param2=0},
		{name="air", prob=0, param2=0},
		{name="air", prob=0, param2=0},
		{name="air", prob=0, param2=0},
		{name="air", prob=0, param2=0},
		{name="air", prob=0, param2=0},
		{name="air", prob=0, param2=0},
		{name="air", prob=0, param2=0},
		{name="air", prob=0, param2=0},
		{name="air", prob=254, param2=0},
		{name="air", prob=254, param2=0},
		{name="air", prob=254, param2=0},
		{name="air", prob=0, param2=0},
		{name="air", prob=0, param2=0},
		{name="air", prob=0, param2=0},
		{name="air", prob=0, param2=0},
		{name="air", prob=254, param2=0},
		{name="air", prob=254, param2=0},
		{name="air", prob=254, param2=0},
		{name="air", prob=0, param2=0},
		{name="air", prob=0, param2=0},
		{name="air", prob=0, param2=0},
		{name="air", prob=0, param2=0},
		{name="air", prob=0, param2=0},
		{name="air", prob=0, param2=0},
		{name="air", prob=0, param2=0},
		{name="air", prob=0, param2=0},
		{name="air", prob=0, param2=0},
		{name="air", prob=0, param2=0},
		{name="air", prob=0, param2=0},
		{name="air", prob=0, param2=0},
		{name="air", prob=0, param2=0},
		{name="air", prob=0, param2=0},
		{name="air", prob=0, param2=0},
		{name="air", prob=0, param2=0},
		{name="air", prob=0, param2=0},
		{name="air", prob=0, param2=0},
		{name="air", prob=0, param2=0},
		{name="air", prob=0, param2=0},
		{name="air", prob=0, param2=0},
		{name="air", prob=0, param2=0},
		{name="air", prob=0, param2=0},
		{name="air", prob=0, param2=0},
		{name="air", prob=0, param2=0},
		{name="air", prob=0, param2=0},
		{name="stairs:stair_cursed_brick_with_growth", prob=254, param2=20},
		{name="air", prob=0, param2=0},
		{name="air", prob=0, param2=0},
		{name="air", prob=0, param2=0},
		{name="everness:cursed_sandstone_block", prob=254, param2=0},
		{name="everness:cursed_sandstone_block", prob=254, param2=0},
		{name="everness:cursed_sandstone_block", prob=254, param2=0},
		{name="everness:cursed_sandstone_block", prob=254, param2=0},
		{name="everness:cursed_sandstone_block", prob=254, param2=0},
		{name="everness:cursed_sandstone_block", prob=254, param2=0},
		{name="everness:cursed_sandstone_block", prob=254, param2=0},
		{name="air", prob=0, param2=0},
		{name="stairs:stair_cursed_sandstone_block", prob=254, param2=0},
		{name="everness:cursed_sandstone_block_wall", prob=254, param2=0},
		{name="air", prob=254, param2=0},
		{name="everness:cursed_sandstone_block_wall", prob=254, param2=0},
		{name="stairs:stair_cursed_sandstone_block", prob=254, param2=0},
		{name="air", prob=0, param2=0},
		{name="air", prob=0, param2=0},
		{name="everness:fence_dry_wood", prob=254, param2=0},
		{name="everness:skull_with_candle", prob=126, param2=0},
		{name="air", prob=254, param2=0},
		{name="everness:skull_with_candle", prob=126, param2=0},
		{name="everness:fence_dry_wood", prob=254, param2=0},
		{name="air", prob=0, param2=0},
		{name="stairs:stair_cursed_brick_with_growth", prob=254, param2=1},
		{name="stairs:stair_cursed_brick_with_growth", prob=254, param2=21},
		{name="air", prob=0, param2=0},
		{name="everness:trapdoor_cursed_wood_open", prob=126, param2=0},
		{name="air", prob=0, param2=0},
		{name="stairs:stair_cursed_brick_with_growth", prob=254, param2=23},
		{name="stairs:stair_cursed_brick_with_growth", prob=254, param2=3},
		{name="air", prob=0, param2=0},
		{name="stairs:stair_cursed_brick_with_growth", prob=254, param2=1},
		{name="stairs:stair_cursed_brick_with_growth", prob=254, param2=21},
		{name="air", prob=0, param2=0},
		{name="stairs:stair_cursed_brick_with_growth", prob=254, param2=23},
		{name="stairs:stair_cursed_brick_with_growth", prob=254, param2=3},
		{name="air", prob=0, param2=0},
		{name="air", prob=0, param2=0},
		{name="air", prob=0, param2=0},
		{name="stairs:stair_cursed_brick_with_growth", prob=254, param2=1},
		{name="stairs:stair_cursed_brick_with_growth", prob=254, param2=20},
		{name="stairs:stair_cursed_brick_with_growth", prob=254, param2=3},
		{name="air", prob=0, param2=0},
		{name="air", prob=0, param2=0},
		{name="air", prob=0, param2=0},
		{name="air", prob=0, param2=0},
		{name="air", prob=0, param2=0},
		{name="stairs:stair_cursed_brick_with_growth", prob=254, param2=2},
		{name="air", prob=0, param2=0},
		{name="air", prob=0, param2=0},
		{name="air", prob=0, param2=0},
		{name="everness:cursed_sandstone_block", prob=254, param2=0},
		{name="everness:dry_tree", prob=254, param2=0},
		{name="everness:cursed_sandstone_block", prob=254, param2=0},
		{name="everness:cursed_sandstone_block", prob=254, param2=0},
		{name="everness:cursed_sandstone_block", prob=254, param2=0},
		{name="everness:dry_tree", prob=254, param2=0},
		{name="everness:cursed_sandstone_block", prob=254, param2=0},
		{name="stairs:stair_cursed_sandstone_block", prob=254, param2=1},
		{name="everness:dry_tree", prob=254, param2=0},
		{name="everness:cursed_sandstone_block", prob=254, param2=0},
		{name="everness:door_cursed_wood_a", prob=254, param2=2},
		{name="everness:cursed_sandstone_block", prob=254, param2=0},
		{name="everness:dry_tree", prob=254, param2=0},
		{name="stairs:stair_cursed_sandstone_block", prob=254, param2=3},
		{name="everness:fence_dry_wood", prob=254, param2=0},
		{name="everness:dry_tree", prob=254, param2=0},
		{name="everness:dry_wood", prob=254, param2=0},
		{name="doors:hidden", prob=254, param2=2},
		{name="everness:dry_wood", prob=254, param2=0},
		{name="everness:dry_tree", prob=254, param2=0},
		{name="everness:fence_dry_wood", prob=254, param2=0},
		{name="stairs:stair_cursed_brick_with_growth", prob=254, param2=1},
		{name="everness:dry_tree", prob=254, param2=0},
		{name="everness:dry_wood", prob=254, param2=0},
		{name="everness:dry_wood", prob=254, param2=0},
		{name="everness:dry_wood", prob=254, param2=0},
		{name="everness:dry_tree", prob=254, param2=0},
		{name="stairs:stair_cursed_brick_with_growth", prob=254, param2=3},
		{name="air", prob=0, param2=0},
		{name="stairs:stair_dry_tree", prob=254, param2=1},
		{name="everness:dry_wood", prob=254, param2=0},
		{name="xpanes:cursed_bar_flat", prob=254, param2=0},
		{name="everness:dry_wood", prob=254, param2=0},
		{name="stairs:stair_dry_tree", prob=254, param2=3},
		{name="air", prob=0, param2=0},
		{name="air", prob=0, param2=0},
		{name="air", prob=0, param2=0},
		{name="stairs:stair_dry_tree", prob=254, param2=1},
		{name="everness:dry_wood", prob=254, param2=0},
		{name="stairs:stair_dry_tree", prob=254, param2=3},
		{name="air", prob=0, param2=0},
		{name="air", prob=0, param2=0},
		{name="air", prob=0, param2=0},
		{name="air", prob=0, param2=0},
		{name="air", prob=0, param2=0},
		{name="stairs:slab_dry_tree", prob=254, param2=2},
		{name="air", prob=0, param2=0},
		{name="air", prob=0, param2=0},
		{name="air", prob=0, param2=0},
		{name="everness:cursed_sandstone_block", prob=254, param2=0},
		{name="everness:cursed_sandstone_block", prob=254, param2=0},
		{name="everness:cursed_sandstone_brick", prob=254, param2=0},
		{name="everness:cursed_sandstone_brick", prob=254, param2=0},
		{name="everness:cursed_sandstone_brick", prob=254, param2=0},
		{name="everness:cursed_sandstone_block", prob=254, param2=0},
		{name="everness:cursed_sandstone_block", prob=254, param2=0},
		{name="air", prob=0, param2=0},
		{name="everness:dry_wood", prob=254, param2=0},
		{name="air", prob=254, param2=0},
		{name="air", prob=254, param2=0},
		{name="air", prob=254, param2=0},
		{name="everness:dry_wood", prob=254, param2=0},
		{name="air", prob=0, param2=0},
		{name="air", prob=0, param2=0},
		{name="everness:dry_wood", prob=254, param2=0},
		{name="air", prob=254, param2=0},
		{name="air", prob=254, param2=0},
		{name="air", prob=254, param2=0},
		{name="everness:dry_wood", prob=254, param2=0},
		{name="air", prob=0, param2=0},
		{name="stairs:stair_cursed_brick_with_growth", prob=254, param2=1},
		{name="everness:dry_wood", prob=254, param2=0},
		{name="air", prob=254, param2=0},
		{name="air", prob=254, param2=0},
		{name="air", prob=254, param2=0},
		{name="everness:dry_wood", prob=254, param2=0},
		{name="stairs:stair_cursed_brick_with_growth", prob=254, param2=3},
		{name="air", prob=0, param2=0},
		{name="stairs:stair_dry_tree", prob=254, param2=1},
		{name="stairs:stair_dry_tree", prob=254, param2=21},
		{name="air", prob=254, param2=0},
		{name="stairs:stair_dry_tree", prob=254, param2=23},
		{name="stairs:stair_dry_tree", prob=254, param2=3},
		{name="air", prob=0, param2=0},
		{name="air", prob=0, param2=0},
		{name="air", prob=0, param2=0},
		{name="stairs:stair_dry_tree", prob=254, param2=1},
		{name="everness:dry_tree", prob=254, param2=7},
		{name="stairs:stair_dry_tree", prob=254, param2=3},
		{name="air", prob=0, param2=0},
		{name="air", prob=0, param2=0},
		{name="air", prob=0, param2=0},
		{name="air", prob=0, param2=0},
		{name="air", prob=0, param2=0},
		{name="stairs:slab_dry_tree", prob=254, param2=2},
		{name="air", prob=0, param2=0},
		{name="air", prob=0, param2=0},
		{name="air", prob=0, param2=0},
		{name="everness:cursed_sandstone_block", prob=254, param2=0},
		{name="everness:cursed_sandstone_block", prob=254, param2=0},
		{name="everness:cursed_sandstone_brick", prob=254, param2=0},
		{name="everness:cursed_sandstone_brick", prob=254, param2=0},
		{name="everness:cursed_sandstone_brick", prob=254, param2=0},
		{name="everness:cursed_sandstone_block", prob=254, param2=0},
		{name="everness:cursed_sandstone_block", prob=254, param2=0},
		{name="everness:dry_branches", prob=126, param2=1},
		{name="everness:dry_wood", prob=254, param2=0},
		{name="air", prob=254, param2=0},
		{name="air", prob=254, param2=0},
		{name="air", prob=254, param2=0},
		{name="everness:dry_wood", prob=254, param2=0},
		{name="everness:dry_branches", prob=126, param2=1},
		{name="everness:trapdoor_cursed_wood_open", prob=126, param2=1},
		{name="everness:dry_wood", prob=254, param2=0},
		{name="air", prob=254, param2=0},
		{name="air", prob=254, param2=0},
		{name="air", prob=254, param2=0},
		{name="everness:dry_wood", prob=254, param2=0},
		{name="everness:trapdoor_cursed_wood_open", prob=126, param2=3},
		{name="stairs:stair_cursed_brick_with_growth", prob=254, param2=1},
		{name="everness:dry_wood", prob=254, param2=0},
		{name="air", prob=254, param2=0},
		{name="air", prob=254, param2=0},
		{name="air", prob=254, param2=0},
		{name="everness:dry_wood", prob=254, param2=0},
		{name="stairs:stair_cursed_brick_with_growth", prob=254, param2=3},
		{name="air", prob=0, param2=0},
		{name="stairs:stair_dry_tree", prob=254, param2=1},
		{name="stairs:stair_dry_tree", prob=254, param2=21},
		{name="air", prob=254, param2=0},
		{name="stairs:stair_dry_tree", prob=254, param2=23},
		{name="stairs:stair_dry_tree", prob=254, param2=3},
		{name="air", prob=0, param2=0},
		{name="air", prob=0, param2=0},
		{name="air", prob=0, param2=0},
		{name="stairs:stair_dry_tree", prob=254, param2=1},
		{name="everness:dry_tree", prob=254, param2=7},
		{name="stairs:stair_dry_tree", prob=254, param2=3},
		{name="air", prob=0, param2=0},
		{name="air", prob=0, param2=0},
		{name="air", prob=0, param2=0},
		{name="air", prob=0, param2=0},
		{name="air", prob=0, param2=0},
		{name="stairs:slab_dry_tree", prob=254, param2=2},
		{name="air", prob=0, param2=0},
		{name="air", prob=0, param2=0},
		{name="air", prob=0, param2=0},
		{name="everness:cursed_sandstone_block", prob=254, param2=0},
		{name="everness:cursed_sandstone_block", prob=254, param2=0},
		{name="everness:cursed_sandstone_brick", prob=254, param2=0},
		{name="everness:cursed_sandstone_brick", prob=254, param2=0},
		{name="everness:cursed_sandstone_brick", prob=254, param2=0},
		{name="everness:cursed_sandstone_block", prob=254, param2=0},
		{name="everness:cursed_sandstone_block", prob=254, param2=0},
		{name="everness:dry_branches", prob=126, param2=1},
		{name="everness:dry_wood", prob=254, param2=0},
		{name="air", prob=254, param2=0},
		{name="air", prob=254, param2=0},
		{name="air", prob=254, param2=0},
		{name="everness:dry_wood", prob=254, param2=0},
		{name="everness:dry_branches", prob=126, param2=1},
		{name="air", prob=0, param2=0},
		{name="xpanes:cursed_bar_flat", prob=254, param2=3},
		{name="air", prob=254, param2=0},
		{name="air", prob=254, param2=0},
		{name="air", prob=254, param2=0},
		{name="xpanes:cursed_bar_flat", prob=254, param2=3},
		{name="air", prob=0, param2=0},
		{name="stairs:stair_cursed_brick_with_growth", prob=254, param2=1},
		{name="everness:dry_wood", prob=254, param2=0},
		{name="air", prob=254, param2=0},
		{name="air", prob=254, param2=0},
		{name="air", prob=254, param2=0},
		{name="everness:dry_wood", prob=254, param2=0},
		{name="stairs:stair_cursed_brick_with_growth", prob=254, param2=3},
		{name="air", prob=0, param2=0},
		{name="stairs:stair_dry_tree", prob=254, param2=1},
		{name="stairs:stair_dry_tree", prob=254, param2=21},
		{name="air", prob=254, param2=0},
		{name="stairs:stair_dry_tree", prob=254, param2=23},
		{name="stairs:stair_dry_tree", prob=254, param2=3},
		{name="air", prob=0, param2=0},
		{name="air", prob=0, param2=0},
		{name="air", prob=0, param2=0},
		{name="stairs:stair_dry_tree", prob=254, param2=1},
		{name="everness:dry_tree", prob=254, param2=7},
		{name="stairs:stair_dry_tree", prob=254, param2=3},
		{name="air", prob=0, param2=0},
		{name="air", prob=0, param2=0},
		{name="air", prob=0, param2=0},
		{name="air", prob=0, param2=0},
		{name="air", prob=0, param2=0},
		{name="stairs:slab_dry_tree", prob=254, param2=2},
		{name="air", prob=0, param2=0},
		{name="air", prob=0, param2=0},
		{name="air", prob=0, param2=0},
		{name="everness:cursed_sandstone_block", prob=254, param2=0},
		{name="everness:cursed_sandstone_block", prob=254, param2=0},
		{name="everness:cursed_sandstone_brick", prob=254, param2=0},
		{name="everness:cursed_sandstone_brick", prob=254, param2=0},
		{name="everness:cursed_sandstone_brick", prob=254, param2=0},
		{name="everness:cursed_sandstone_block", prob=254, param2=0},
		{name="everness:cursed_sandstone_block", prob=254, param2=0},
		{name="everness:dry_branches", prob=126, param2=1},
		{name="everness:dry_wood", prob=254, param2=0},
		{name="air", prob=254, param2=0},
		{name="air", prob=254, param2=0},
		{name="air", prob=254, param2=0},
		{name="everness:dry_wood", prob=254, param2=0},
		{name="everness:dry_branches", prob=126, param2=1},
		{name="air", prob=0, param2=0},
		{name="xpanes:cursed_bar_flat", prob=254, param2=3},
		{name="air", prob=254, param2=0},
		{name="air", prob=254, param2=0},
		{name="air", prob=254, param2=0},
		{name="xpanes:cursed_bar_flat", prob=254, param2=3},
		{name="air", prob=0, param2=0},
		{name="stairs:stair_cursed_brick_with_growth", prob=254, param2=1},
		{name="everness:dry_wood", prob=254, param2=0},
		{name="air", prob=254, param2=0},
		{name="air", prob=254, param2=0},
		{name="air", prob=254, param2=0},
		{name="everness:dry_wood", prob=254, param2=0},
		{name="stairs:stair_cursed_brick_with_growth", prob=254, param2=3},
		{name="air", prob=0, param2=0},
		{name="stairs:stair_dry_tree", prob=254, param2=1},
		{name="stairs:stair_dry_tree", prob=254, param2=21},
		{name="air", prob=254, param2=0},
		{name="stairs:stair_dry_tree", prob=254, param2=23},
		{name="stairs:stair_dry_tree", prob=254, param2=3},
		{name="air", prob=0, param2=0},
		{name="air", prob=0, param2=0},
		{name="air", prob=0, param2=0},
		{name="stairs:stair_dry_tree", prob=254, param2=1},
		{name="everness:dry_tree", prob=254, param2=7},
		{name="stairs:stair_dry_tree", prob=254, param2=3},
		{name="air", prob=0, param2=0},
		{name="air", prob=0, param2=0},
		{name="air", prob=0, param2=0},
		{name="air", prob=0, param2=0},
		{name="air", prob=0, param2=0},
		{name="stairs:slab_dry_tree", prob=254, param2=2},
		{name="air", prob=0, param2=0},
		{name="air", prob=0, param2=0},
		{name="air", prob=0, param2=0},
		{name="everness:cursed_sandstone_block", prob=254, param2=0},
		{name="everness:cursed_sandstone_block", prob=254, param2=0},
		{name="everness:cursed_sandstone_brick", prob=254, param2=0},
		{name="everness:cursed_sandstone_brick", prob=254, param2=0},
		{name="everness:cursed_sandstone_brick", prob=254, param2=0},
		{name="everness:cursed_sandstone_block", prob=254, param2=0},
		{name="everness:cursed_sandstone_block", prob=254, param2=0},
		{name="everness:dry_branches", prob=126, param2=1},
		{name="everness:dry_wood", prob=254, param2=0},
		{name="air", prob=254, param2=0},
		{name="air", prob=254, param2=0},
		{name="air", prob=254, param2=0},
		{name="everness:dry_wood", prob=254, param2=0},
		{name="everness:dry_branches", prob=126, param2=1},
		{name="everness:trapdoor_cursed_wood_open", prob=254, param2=1},
		{name="everness:dry_wood", prob=254, param2=0},
		{name="air", prob=254, param2=0},
		{name="air", prob=254, param2=0},
		{name="air", prob=254, param2=0},
		{name="everness:dry_wood", prob=254, param2=0},
		{name="everness:trapdoor_cursed_wood_open", prob=126, param2=3},
		{name="stairs:stair_cursed_brick_with_growth", prob=254, param2=1},
		{name="everness:dry_wood", prob=254, param2=0},
		{name="air", prob=254, param2=0},
		{name="air", prob=254, param2=0},
		{name="air", prob=254, param2=0},
		{name="everness:dry_wood", prob=254, param2=0},
		{name="stairs:stair_cursed_brick_with_growth", prob=254, param2=3},
		{name="air", prob=0, param2=0},
		{name="stairs:stair_dry_tree", prob=254, param2=1},
		{name="stairs:stair_dry_tree", prob=254, param2=21},
		{name="air", prob=254, param2=0},
		{name="stairs:stair_dry_tree", prob=254, param2=23},
		{name="stairs:stair_dry_tree", prob=254, param2=3},
		{name="air", prob=0, param2=0},
		{name="air", prob=0, param2=0},
		{name="air", prob=0, param2=0},
		{name="stairs:stair_dry_tree", prob=254, param2=1},
		{name="everness:dry_tree", prob=254, param2=7},
		{name="stairs:stair_dry_tree", prob=254, param2=3},
		{name="air", prob=0, param2=0},
		{name="air", prob=0, param2=0},
		{name="air", prob=0, param2=0},
		{name="air", prob=0, param2=0},
		{name="air", prob=0, param2=0},
		{name="stairs:slab_dry_tree", prob=254, param2=2},
		{name="air", prob=0, param2=0},
		{name="air", prob=0, param2=0},
		{name="air", prob=0, param2=0},
		{name="everness:cursed_sandstone_block", prob=254, param2=0},
		{name="everness:cursed_sandstone_block", prob=254, param2=0},
		{name="everness:cursed_sandstone_brick", prob=254, param2=0},
		{name="everness:cursed_sandstone_brick", prob=254, param2=0},
		{name="everness:cursed_sandstone_brick", prob=254, param2=0},
		{name="everness:cursed_sandstone_block", prob=254, param2=0},
		{name="everness:cursed_sandstone_block", prob=254, param2=0},
		{name="air", prob=0, param2=0},
		{name="everness:dry_wood", prob=254, param2=0},
		{name="default:bookshelf", prob=254, param2=0},
		{name="everness:chest", prob=126, param2=0},
		{name="default:bookshelf", prob=254, param2=0},
		{name="everness:dry_wood", prob=254, param2=0},
		{name="air", prob=0, param2=0},
		{name="air", prob=0, param2=0},
		{name="everness:dry_wood", prob=254, param2=0},
		{name="everness:skull_with_candle", prob=126, param2=0},
		{name="air", prob=254, param2=0},
		{name="everness:skull_with_candle", prob=126, param2=0},
		{name="everness:dry_wood", prob=254, param2=0},
		{name="air", prob=0, param2=0},
		{name="stairs:stair_cursed_brick_with_growth", prob=254, param2=1},
		{name="everness:dry_wood", prob=254, param2=0},
		{name="air", prob=254, param2=0},
		{name="air", prob=254, param2=0},
		{name="air", prob=254, param2=0},
		{name="everness:dry_wood", prob=254, param2=0},
		{name="stairs:stair_cursed_brick_with_growth", prob=254, param2=3},
		{name="air", prob=0, param2=0},
		{name="stairs:stair_dry_tree", prob=254, param2=1},
		{name="stairs:stair_dry_tree", prob=254, param2=21},
		{name="air", prob=254, param2=0},
		{name="stairs:stair_dry_tree", prob=254, param2=23},
		{name="stairs:stair_dry_tree", prob=254, param2=3},
		{name="air", prob=0, param2=0},
		{name="air", prob=0, param2=0},
		{name="air", prob=0, param2=0},
		{name="stairs:stair_dry_tree", prob=254, param2=1},
		{name="everness:dry_tree", prob=254, param2=7},
		{name="stairs:stair_dry_tree", prob=254, param2=3},
		{name="air", prob=0, param2=0},
		{name="air", prob=0, param2=0},
		{name="air", prob=0, param2=0},
		{name="air", prob=0, param2=0},
		{name="air", prob=0, param2=0},
		{name="stairs:slab_dry_tree", prob=254, param2=3},
		{name="air", prob=0, param2=0},
		{name="air", prob=0, param2=0},
		{name="air", prob=0, param2=0},
		{name="everness:cursed_sandstone_block", prob=254, param2=0},
		{name="everness:dry_tree", prob=254, param2=0},
		{name="everness:cursed_sandstone_block", prob=254, param2=0},
		{name="everness:cursed_sandstone_block", prob=254, param2=0},
		{name="everness:cursed_sandstone_block", prob=254, param2=0},
		{name="everness:dry_tree", prob=254, param2=0},
		{name="everness:cursed_sandstone_block", prob=254, param2=0},
		{name="stairs:stair_cursed_sandstone_block", prob=254, param2=1},
		{name="everness:dry_tree", prob=254, param2=0},
		{name="everness:dry_wood", prob=254, param2=0},
		{name="everness:dry_wood", prob=254, param2=0},
		{name="everness:dry_wood", prob=254, param2=0},
		{name="everness:dry_tree", prob=254, param2=0},
		{name="stairs:stair_cursed_sandstone_block", prob=254, param2=3},
		{name="everness:fence_dry_wood", prob=254, param2=0},
		{name="everness:dry_tree", prob=254, param2=0},
		{name="everness:dry_wood", prob=254, param2=0},
		{name="xpanes:cursed_bar_flat", prob=254, param2=0},
		{name="everness:dry_wood", prob=254, param2=0},
		{name="everness:dry_tree", prob=254, param2=0},
		{name="everness:fence_dry_wood", prob=254, param2=0},
		{name="stairs:stair_cursed_brick_with_growth", prob=254, param2=1},
		{name="everness:dry_tree", prob=254, param2=0},
		{name="everness:dry_wood", prob=254, param2=0},
		{name="everness:dry_wood", prob=254, param2=0},
		{name="everness:dry_wood", prob=254, param2=0},
		{name="everness:dry_tree", prob=254, param2=0},
		{name="stairs:stair_cursed_brick_with_growth", prob=254, param2=3},
		{name="air", prob=0, param2=0},
		{name="stairs:stair_dry_tree", prob=254, param2=1},
		{name="everness:dry_wood", prob=254, param2=0},
		{name="xpanes:cursed_bar_flat", prob=254, param2=0},
		{name="everness:dry_wood", prob=254, param2=0},
		{name="stairs:stair_dry_tree", prob=254, param2=3},
		{name="air", prob=0, param2=0},
		{name="air", prob=0, param2=0},
		{name="air", prob=0, param2=0},
		{name="stairs:stair_dry_tree", prob=254, param2=1},
		{name="everness:dry_wood", prob=254, param2=0},
		{name="stairs:stair_dry_tree", prob=254, param2=3},
		{name="air", prob=0, param2=0},
		{name="air", prob=0, param2=0},
		{name="air", prob=0, param2=0},
		{name="air", prob=0, param2=0},
		{name="air", prob=0, param2=0},
		{name="stairs:slab_dry_tree", prob=254, param2=3},
		{name="air", prob=0, param2=0},
		{name="air", prob=0, param2=0},
		{name="air", prob=0, param2=0},
		{name="everness:cursed_sandstone_block", prob=254, param2=0},
		{name="everness:cursed_sandstone_block", prob=254, param2=0},
		{name="everness:cursed_sandstone_block", prob=254, param2=0},
		{name="everness:cursed_sandstone_block", prob=254, param2=0},
		{name="everness:cursed_sandstone_block", prob=254, param2=0},
		{name="everness:cursed_sandstone_block", prob=254, param2=0},
		{name="everness:cursed_sandstone_block", prob=254, param2=0},
		{name="air", prob=0, param2=0},
		{name="stairs:stair_cursed_sandstone_block", prob=254, param2=2},
		{name="everness:dry_branches", prob=126, param2=1},
		{name="everness:dry_branches", prob=126, param2=1},
		{name="everness:dry_branches", prob=126, param2=1},
		{name="stairs:stair_cursed_sandstone_block", prob=254, param2=2},
		{name="air", prob=0, param2=0},
		{name="air", prob=0, param2=0},
		{name="everness:fence_dry_wood", prob=254, param2=0},
		{name="air", prob=0, param2=0},
		{name="air", prob=0, param2=0},
		{name="air", prob=0, param2=0},
		{name="everness:fence_dry_wood", prob=254, param2=0},
		{name="air", prob=0, param2=0},
		{name="stairs:stair_cursed_brick_with_growth", prob=254, param2=1},
		{name="stairs:stair_cursed_brick_with_growth", prob=254, param2=21},
		{name="air", prob=0, param2=0},
		{name="everness:trapdoor_cursed_wood_open", prob=126, param2=2},
		{name="air", prob=0, param2=0},
		{name="stairs:stair_cursed_brick_with_growth", prob=254, param2=23},
		{name="stairs:stair_cursed_brick_with_growth", prob=254, param2=3},
		{name="air", prob=0, param2=0},
		{name="stairs:stair_cursed_brick_with_growth", prob=254, param2=1},
		{name="stairs:stair_cursed_brick_with_growth", prob=254, param2=21},
		{name="air", prob=0, param2=0},
		{name="stairs:stair_cursed_brick_with_growth", prob=254, param2=23},
		{name="stairs:stair_cursed_brick_with_growth", prob=254, param2=3},
		{name="air", prob=0, param2=0},
		{name="air", prob=0, param2=0},
		{name="air", prob=0, param2=0},
		{name="stairs:stair_cursed_brick_with_growth", prob=254, param2=1},
		{name="stairs:stair_cursed_brick_with_growth", prob=254, param2=22},
		{name="stairs:stair_cursed_brick_with_growth", prob=254, param2=3},
		{name="air", prob=0, param2=0},
		{name="air", prob=0, param2=0},
		{name="air", prob=0, param2=0},
		{name="air", prob=0, param2=0},
		{name="air", prob=0, param2=0},
		{name="stairs:stair_cursed_brick_with_growth", prob=254, param2=0},
		{name="air", prob=0, param2=0},
		{name="air", prob=0, param2=0},
		{name="air", prob=0, param2=0},
		{name="air", prob=0, param2=0},
		{name="air", prob=0, param2=0},
		{name="air", prob=0, param2=0},
		{name="air", prob=0, param2=0},
		{name="air", prob=0, param2=0},
		{name="air", prob=0, param2=0},
		{name="air", prob=0, param2=0},
		{name="air", prob=0, param2=0},
		{name="air", prob=0, param2=0},
		{name="air", prob=0, param2=0},
		{name="air", prob=0, param2=0},
		{name="air", prob=0, param2=0},
		{name="air", prob=0, param2=0},
		{name="air", prob=0, param2=0},
		{name="air", prob=0, param2=0},
		{name="air", prob=0, param2=0},
		{name="air", prob=0, param2=0},
		{name="air", prob=0, param2=0},
		{name="air", prob=0, param2=0},
		{name="air", prob=0, param2=0},
		{name="air", prob=0, param2=0},
		{name="air", prob=0, param2=0},
		{name="air", prob=0, param2=0},
		{name="air", prob=0, param2=0},
		{name="air", prob=0, param2=0},
		{name="air", prob=0, param2=0},
		{name="air", prob=0, param2=0},
		{name="air", prob=0, param2=0},
		{name="air", prob=0, param2=0},
		{name="air", prob=0, param2=0},
		{name="air", prob=0, param2=0},
		{name="air", prob=0, param2=0},
		{name="air", prob=0, param2=0},
		{name="air", prob=0, param2=0},
		{name="air", prob=0, param2=0},
		{name="air", prob=0, param2=0},
		{name="air", prob=0, param2=0},
		{name="air", prob=0, param2=0},
		{name="air", prob=0, param2=0},
		{name="air", prob=0, param2=0},
		{name="air", prob=0, param2=0},
		{name="air", prob=0, param2=0},
		{name="air", prob=0, param2=0},
		{name="air", prob=0, param2=0},
		{name="air", prob=0, param2=0},
		{name="stairs:stair_cursed_brick_with_growth", prob=254, param2=22},
		{name="air", prob=0, param2=0},
		{name="air", prob=0, param2=0},
		{name="air", prob=0, param2=0},
	},
}
