schematic = {
	size = {x=11, y=19, z=15},
	yslice_prob = {
		{ypos=0, prob=254},
		{ypos=1, prob=254},
		{ypos=2, prob=254},
		{ypos=3, prob=254},
		{ypos=4, prob=254},
		{ypos=5, prob=254},
		{ypos=6, prob=254},
		{ypos=7, prob=254},
		{ypos=8, prob=254},
		{ypos=9, prob=254},
		{ypos=10, prob=254},
		{ypos=11, prob=254},
		{ypos=12, prob=254},
		{ypos=13, prob=254},
		{ypos=14, prob=254},
		{ypos=15, prob=254},
		{ypos=16, prob=254},
		{ypos=17, prob=254},
		{ypos=18, prob=254},
	},
	data = {
		{name="air", prob=0, param2=0},
		{name="everness:forsaken_tundra_brick", prob=254, param2=0},
		{name="everness:forsaken_tundra_brick", prob=254, param2=0},
		{name="everness:forsaken_tundra_brick", prob=254, param2=0},
		{name="everness:forsaken_tundra_brick", prob=254, param2=0},
		{name="everness:forsaken_tundra_brick", prob=254, param2=0},
		{name="everness:forsaken_tundra_brick", prob=254, param2=0},
		{name="everness:forsaken_tundra_brick", prob=254, param2=0},
		{name="everness:forsaken_tundra_brick", prob=254, param2=0},
		{name="everness:forsaken_tundra_brick", prob=254, param2=0},
		{name="air", prob=0, param2=0},
		{name="air", prob=0, param2=0},
		{name="air", prob=254, param2=0},
		{name="air", prob=254, param2=0},
		{name="air", prob=254, param2=0},
		{name="air", prob=254, param2=0},
		{name="air", prob=254, param2=0},
		{name="air", prob=254, param2=0},
		{name="air", prob=254, param2=0},
		{name="air", prob=254, param2=0},
		{name="air", prob=254, param2=0},
		{name="air", prob=0, param2=0},
		{name="air", prob=254, param2=0},
		{name="air", prob=254, param2=0},
		{name="air", prob=254, param2=0},
		{name="air", prob=254, param2=0},
		{name="air", prob=254, param2=0},
		{name="air", prob=254, param2=0},
		{name="air", prob=254, param2=0},
		{name="air", prob=254, param2=0},
		{name="air", prob=254, param2=0},
		{name="air", prob=254, param2=0},
		{name="air", prob=254, param2=0},
		{name="air", prob=254, param2=0},
		{name="air", prob=254, param2=0},
		{name="everness:trapdoor_bamboo_open", prob=254, param2=0},
		{name="air", prob=254, param2=0},
		{name="air", prob=254, param2=0},
		{name="air", prob=254, param2=0},
		{name="air", prob=254, param2=0},
		{name="air", prob=254, param2=0},
		{name="everness:trapdoor_bamboo_open", prob=254, param2=0},
		{name="air", prob=254, param2=0},
		{name="air", prob=254, param2=0},
		{name="air", prob=254, param2=0},
		{name="air", prob=254, param2=0},
		{name="air", prob=254, param2=0},
		{name="air", prob=254, param2=0},
		{name="air", prob=254, param2=0},
		{name="air", prob=254, param2=0},
		{name="air", prob=254, param2=0},
		{name="air", prob=254, param2=0},
		{name="air", prob=254, param2=0},
		{name="air", prob=254, param2=0},
		{name="air", prob=254, param2=0},
		{name="air", prob=254, param2=0},
		{name="air", prob=254, param2=0},
		{name="air", prob=254, param2=0},
		{name="air", prob=254, param2=0},
		{name="air", prob=254, param2=0},
		{name="air", prob=254, param2=0},
		{name="air", prob=254, param2=0},
		{name="air", prob=254, param2=0},
		{name="air", prob=254, param2=0},
		{name="air", prob=254, param2=0},
		{name="air", prob=254, param2=0},
		{name="air", prob=254, param2=0},
		{name="air", prob=254, param2=0},
		{name="air", prob=254, param2=0},
		{name="air", prob=254, param2=0},
		{name="air", prob=254, param2=0},
		{name="air", prob=254, param2=0},
		{name="air", prob=254, param2=0},
		{name="air", prob=254, param2=0},
		{name="air", prob=254, param2=0},
		{name="air", prob=254, param2=0},
		{name="air", prob=254, param2=0},
		{name="air", prob=254, param2=0},
		{name="air", prob=254, param2=0},
		{name="air", prob=254, param2=0},
		{name="air", prob=254, param2=0},
		{name="air", prob=254, param2=0},
		{name="air", prob=254, param2=0},
		{name="air", prob=254, param2=0},
		{name="air", prob=254, param2=0},
		{name="air", prob=254, param2=0},
		{name="air", prob=254, param2=0},
		{name="air", prob=254, param2=0},
		{name="air", prob=254, param2=0},
		{name="air", prob=254, param2=0},
		{name="air", prob=254, param2=0},
		{name="air", prob=254, param2=0},
		{name="air", prob=254, param2=0},
		{name="air", prob=254, param2=0},
		{name="air", prob=254, param2=0},
		{name="air", prob=254, param2=0},
		{name="air", prob=254, param2=0},
		{name="air", prob=254, param2=0},
		{name="air", prob=254, param2=0},
		{name="air", prob=254, param2=0},
		{name="air", prob=254, param2=0},
		{name="air", prob=254, param2=0},
		{name="air", prob=254, param2=0},
		{name="air", prob=254, param2=0},
		{name="air", prob=254, param2=0},
		{name="air", prob=254, param2=0},
		{name="air", prob=254, param2=0},
		{name="air", prob=254, param2=0},
		{name="air", prob=254, param2=0},
		{name="air", prob=254, param2=0},
		{name="air", prob=254, param2=0},
		{name="air", prob=254, param2=0},
		{name="air", prob=254, param2=0},
		{name="air", prob=254, param2=0},
		{name="air", prob=254, param2=0},
		{name="air", prob=254, param2=0},
		{name="air", prob=254, param2=0},
		{name="air", prob=254, param2=0},
		{name="air", prob=254, param2=0},
		{name="air", prob=254, param2=0},
		{name="air", prob=254, param2=0},
		{name="air", prob=254, param2=0},
		{name="air", prob=254, param2=0},
		{name="air", prob=254, param2=0},
		{name="air", prob=254, param2=0},
		{name="air", prob=254, param2=0},
		{name="air", prob=254, param2=0},
		{name="air", prob=254, param2=0},
		{name="air", prob=254, param2=0},
		{name="air", prob=254, param2=0},
		{name="air", prob=254, param2=0},
		{name="air", prob=254, param2=0},
		{name="air", prob=254, param2=0},
		{name="air", prob=254, param2=0},
		{name="air", prob=254, param2=0},
		{name="air", prob=254, param2=0},
		{name="air", prob=254, param2=0},
		{name="air", prob=254, param2=0},
		{name="air", prob=254, param2=0},
		{name="air", prob=254, param2=0},
		{name="air", prob=254, param2=0},
		{name="air", prob=254, param2=0},
		{name="air", prob=254, param2=0},
		{name="air", prob=254, param2=0},
		{name="air", prob=254, param2=0},
		{name="air", prob=254, param2=0},
		{name="air", prob=254, param2=0},
		{name="air", prob=254, param2=0},
		{name="air", prob=254, param2=0},
		{name="air", prob=254, param2=0},
		{name="air", prob=254, param2=0},
		{name="air", prob=254, param2=0},
		{name="air", prob=254, param2=0},
		{name="air", prob=254, param2=0},
		{name="air", prob=254, param2=0},
		{name="air", prob=254, param2=0},
		{name="air", prob=254, param2=0},
		{name="air", prob=254, param2=0},
		{name="air", prob=254, param2=0},
		{name="air", prob=254, param2=0},
		{name="air", prob=254, param2=0},
		{name="air", prob=254, param2=0},
		{name="air", prob=254, param2=0},
		{name="air", prob=254, param2=0},
		{name="air", prob=254, param2=0},
		{name="air", prob=254, param2=0},
		{name="air", prob=254, param2=0},
		{name="air", prob=254, param2=0},
		{name="air", prob=254, param2=0},
		{name="air", prob=254, param2=0},
		{name="air", prob=254, param2=0},
		{name="air", prob=254, param2=0},
		{name="air", prob=254, param2=0},
		{name="air", prob=254, param2=0},
		{name="air", prob=254, param2=0},
		{name="air", prob=254, param2=0},
		{name="air", prob=254, param2=0},
		{name="air", prob=254, param2=0},
		{name="air", prob=254, param2=0},
		{name="air", prob=254, param2=0},
		{name="air", prob=254, param2=0},
		{name="air", prob=254, param2=0},
		{name="air", prob=254, param2=0},
		{name="air", prob=254, param2=0},
		{name="air", prob=254, param2=0},
		{name="air", prob=254, param2=0},
		{name="air", prob=254, param2=0},
		{name="air", prob=254, param2=0},
		{name="air", prob=254, param2=0},
		{name="air", prob=254, param2=0},
		{name="air", prob=254, param2=0},
		{name="air", prob=254, param2=0},
		{name="air", prob=254, param2=0},
		{name="air", prob=254, param2=0},
		{name="air", prob=254, param2=0},
		{name="air", prob=254, param2=0},
		{name="air", prob=254, param2=0},
		{name="air", prob=254, param2=0},
		{name="air", prob=254, param2=0},
		{name="air", prob=254, param2=0},
		{name="air", prob=254, param2=0},
		{name="air", prob=254, param2=0},
		{name="air", prob=254, param2=0},
		{name="air", prob=254, param2=0},
		{name="air", prob=254, param2=0},
		{name="air", prob=254, param2=0},
		{name="air", prob=254, param2=0},
		{name="air", prob=254, param2=0},
		{name="air", prob=254, param2=0},
		{name="air", prob=0, param2=0},
		{name="everness:forsaken_tundra_brick", prob=254, param2=0},
		{name="everness:forsaken_tundra_brick", prob=254, param2=0},
		{name="everness:forsaken_tundra_brick", prob=254, param2=0},
		{name="everness:forsaken_tundra_brick", prob=254, param2=0},
		{name="everness:forsaken_tundra_brick", prob=254, param2=0},
		{name="everness:forsaken_tundra_brick", prob=254, param2=0},
		{name="everness:forsaken_tundra_brick", prob=254, param2=0},
		{name="everness:forsaken_tundra_brick", prob=254, param2=0},
		{name="everness:forsaken_tundra_brick", prob=254, param2=0},
		{name="air", prob=0, param2=0},
		{name="air", prob=0, param2=0},
		{name="air", prob=254, param2=0},
		{name="everness:forsaken_tundra_brick", prob=254, param2=0},
		{name="air", prob=254, param2=0},
		{name="air", prob=254, param2=0},
		{name="air", prob=254, param2=0},
		{name="air", prob=254, param2=0},
		{name="air", prob=254, param2=0},
		{name="everness:forsaken_tundra_brick", prob=254, param2=0},
		{name="air", prob=254, param2=0},
		{name="air", prob=0, param2=0},
		{name="air", prob=254, param2=0},
		{name="air", prob=254, param2=0},
		{name="everness:fence_bamboo_wood", prob=254, param2=0},
		{name="air", prob=254, param2=0},
		{name="air", prob=254, param2=0},
		{name="air", prob=254, param2=0},
		{name="air", prob=254, param2=0},
		{name="air", prob=254, param2=0},
		{name="everness:fence_bamboo_wood", prob=254, param2=0},
		{name="air", prob=254, param2=0},
		{name="air", prob=254, param2=0},
		{name="air", prob=254, param2=0},
		{name="everness:trapdoor_bamboo_open", prob=254, param2=1},
		{name="everness:pyrite_lantern", prob=254, param2=0},
		{name="everness:trapdoor_bamboo_open", prob=254, param2=3},
		{name="air", prob=254, param2=0},
		{name="air", prob=254, param2=0},
		{name="air", prob=254, param2=0},
		{name="everness:trapdoor_bamboo_open", prob=254, param2=1},
		{name="everness:pyrite_lantern", prob=254, param2=0},
		{name="everness:trapdoor_bamboo_open", prob=254, param2=3},
		{name="air", prob=254, param2=0},
		{name="air", prob=254, param2=0},
		{name="air", prob=254, param2=0},
		{name="stairs:slab_forsaken_tundra_brick", prob=254, param2=1},
		{name="air", prob=254, param2=0},
		{name="air", prob=254, param2=0},
		{name="air", prob=254, param2=0},
		{name="air", prob=254, param2=0},
		{name="air", prob=254, param2=0},
		{name="stairs:slab_forsaken_tundra_brick", prob=254, param2=1},
		{name="air", prob=254, param2=0},
		{name="air", prob=254, param2=0},
		{name="air", prob=254, param2=0},
		{name="air", prob=254, param2=0},
		{name="air", prob=254, param2=0},
		{name="air", prob=254, param2=0},
		{name="air", prob=254, param2=0},
		{name="air", prob=254, param2=0},
		{name="air", prob=254, param2=0},
		{name="air", prob=254, param2=0},
		{name="air", prob=254, param2=0},
		{name="air", prob=254, param2=0},
		{name="air", prob=254, param2=0},
		{name="air", prob=254, param2=0},
		{name="air", prob=254, param2=0},
		{name="air", prob=254, param2=0},
		{name="air", prob=254, param2=0},
		{name="air", prob=254, param2=0},
		{name="air", prob=254, param2=0},
		{name="air", prob=254, param2=0},
		{name="air", prob=254, param2=0},
		{name="air", prob=254, param2=0},
		{name="air", prob=254, param2=0},
		{name="air", prob=254, param2=0},
		{name="air", prob=254, param2=0},
		{name="air", prob=254, param2=0},
		{name="air", prob=254, param2=0},
		{name="air", prob=254, param2=0},
		{name="air", prob=254, param2=0},
		{name="air", prob=254, param2=0},
		{name="air", prob=254, param2=0},
		{name="air", prob=254, param2=0},
		{name="air", prob=254, param2=0},
		{name="air", prob=254, param2=0},
		{name="air", prob=254, param2=0},
		{name="air", prob=254, param2=0},
		{name="air", prob=254, param2=0},
		{name="air", prob=254, param2=0},
		{name="air", prob=254, param2=0},
		{name="air", prob=254, param2=0},
		{name="air", prob=254, param2=0},
		{name="air", prob=254, param2=0},
		{name="air", prob=254, param2=0},
		{name="air", prob=254, param2=0},
		{name="air", prob=254, param2=0},
		{name="air", prob=254, param2=0},
		{name="air", prob=254, param2=0},
		{name="air", prob=254, param2=0},
		{name="air", prob=254, param2=0},
		{name="air", prob=254, param2=0},
		{name="air", prob=254, param2=0},
		{name="air", prob=254, param2=0},
		{name="air", prob=254, param2=0},
		{name="air", prob=254, param2=0},
		{name="air", prob=254, param2=0},
		{name="air", prob=254, param2=0},
		{name="air", prob=254, param2=0},
		{name="air", prob=254, param2=0},
		{name="air", prob=254, param2=0},
		{name="air", prob=254, param2=0},
		{name="air", prob=254, param2=0},
		{name="air", prob=254, param2=0},
		{name="air", prob=254, param2=0},
		{name="air", prob=254, param2=0},
		{name="air", prob=254, param2=0},
		{name="air", prob=254, param2=0},
		{name="air", prob=254, param2=0},
		{name="air", prob=254, param2=0},
		{name="air", prob=254, param2=0},
		{name="air", prob=254, param2=0},
		{name="air", prob=254, param2=0},
		{name="air", prob=254, param2=0},
		{name="air", prob=254, param2=0},
		{name="air", prob=254, param2=0},
		{name="air", prob=254, param2=0},
		{name="air", prob=254, param2=0},
		{name="air", prob=254, param2=0},
		{name="air", prob=254, param2=0},
		{name="air", prob=254, param2=0},
		{name="air", prob=254, param2=0},
		{name="air", prob=254, param2=0},
		{name="air", prob=254, param2=0},
		{name="air", prob=254, param2=0},
		{name="air", prob=254, param2=0},
		{name="air", prob=254, param2=0},
		{name="air", prob=254, param2=0},
		{name="air", prob=254, param2=0},
		{name="air", prob=254, param2=0},
		{name="air", prob=254, param2=0},
		{name="air", prob=254, param2=0},
		{name="air", prob=254, param2=0},
		{name="air", prob=254, param2=0},
		{name="air", prob=254, param2=0},
		{name="air", prob=254, param2=0},
		{name="air", prob=254, param2=0},
		{name="air", prob=254, param2=0},
		{name="air", prob=254, param2=0},
		{name="air", prob=254, param2=0},
		{name="air", prob=254, param2=0},
		{name="air", prob=254, param2=0},
		{name="air", prob=254, param2=0},
		{name="air", prob=254, param2=0},
		{name="air", prob=254, param2=0},
		{name="air", prob=254, param2=0},
		{name="air", prob=254, param2=0},
		{name="air", prob=254, param2=0},
		{name="air", prob=254, param2=0},
		{name="air", prob=254, param2=0},
		{name="air", prob=254, param2=0},
		{name="air", prob=254, param2=0},
		{name="air", prob=254, param2=0},
		{name="air", prob=254, param2=0},
		{name="air", prob=254, param2=0},
		{name="air", prob=254, param2=0},
		{name="air", prob=254, param2=0},
		{name="air", prob=254, param2=0},
		{name="air", prob=254, param2=0},
		{name="air", prob=254, param2=0},
		{name="air", prob=254, param2=0},
		{name="air", prob=254, param2=0},
		{name="air", prob=254, param2=0},
		{name="air", prob=254, param2=0},
		{name="air", prob=254, param2=0},
		{name="air", prob=254, param2=0},
		{name="air", prob=254, param2=0},
		{name="air", prob=254, param2=0},
		{name="air", prob=254, param2=0},
		{name="air", prob=254, param2=0},
		{name="air", prob=254, param2=0},
		{name="air", prob=254, param2=0},
		{name="air", prob=254, param2=0},
		{name="air", prob=254, param2=0},
		{name="air", prob=254, param2=0},
		{name="air", prob=254, param2=0},
		{name="air", prob=254, param2=0},
		{name="air", prob=254, param2=0},
		{name="air", prob=254, param2=0},
		{name="air", prob=254, param2=0},
		{name="air", prob=254, param2=0},
		{name="air", prob=254, param2=0},
		{name="air", prob=254, param2=0},
		{name="air", prob=254, param2=0},
		{name="air", prob=254, param2=0},
		{name="air", prob=254, param2=0},
		{name="air", prob=254, param2=0},
		{name="air", prob=254, param2=0},
		{name="air", prob=254, param2=0},
		{name="air", prob=254, param2=0},
		{name="air", prob=254, param2=0},
		{name="air", prob=254, param2=0},
		{name="air", prob=254, param2=0},
		{name="air", prob=254, param2=0},
		{name="air", prob=254, param2=0},
		{name="air", prob=254, param2=0},
		{name="air", prob=254, param2=0},
		{name="air", prob=254, param2=0},
		{name="air", prob=0, param2=0},
		{name="everness:forsaken_tundra_brick", prob=254, param2=0},
		{name="everness:forsaken_tundra_brick", prob=254, param2=0},
		{name="everness:forsaken_tundra_brick", prob=254, param2=0},
		{name="everness:forsaken_tundra_brick", prob=254, param2=0},
		{name="everness:forsaken_tundra_brick", prob=254, param2=0},
		{name="everness:forsaken_tundra_brick", prob=254, param2=0},
		{name="everness:forsaken_tundra_brick", prob=254, param2=0},
		{name="everness:forsaken_tundra_brick", prob=254, param2=0},
		{name="everness:forsaken_tundra_brick", prob=254, param2=0},
		{name="air", prob=0, param2=0},
		{name="air", prob=0, param2=0},
		{name="air", prob=254, param2=0},
		{name="air", prob=254, param2=0},
		{name="air", prob=254, param2=0},
		{name="air", prob=254, param2=0},
		{name="air", prob=254, param2=0},
		{name="air", prob=254, param2=0},
		{name="air", prob=254, param2=0},
		{name="air", prob=254, param2=0},
		{name="air", prob=254, param2=0},
		{name="air", prob=0, param2=0},
		{name="air", prob=254, param2=0},
		{name="air", prob=254, param2=0},
		{name="air", prob=254, param2=0},
		{name="air", prob=254, param2=0},
		{name="air", prob=254, param2=0},
		{name="air", prob=254, param2=0},
		{name="air", prob=254, param2=0},
		{name="air", prob=254, param2=0},
		{name="air", prob=254, param2=0},
		{name="air", prob=254, param2=0},
		{name="air", prob=254, param2=0},
		{name="air", prob=254, param2=0},
		{name="air", prob=254, param2=0},
		{name="everness:trapdoor_bamboo_open", prob=254, param2=2},
		{name="air", prob=254, param2=0},
		{name="air", prob=254, param2=0},
		{name="air", prob=254, param2=0},
		{name="air", prob=254, param2=0},
		{name="air", prob=254, param2=0},
		{name="everness:trapdoor_bamboo_open", prob=254, param2=2},
		{name="air", prob=254, param2=0},
		{name="air", prob=254, param2=0},
		{name="air", prob=254, param2=0},
		{name="air", prob=254, param2=0},
		{name="air", prob=254, param2=0},
		{name="air", prob=254, param2=0},
		{name="air", prob=254, param2=0},
		{name="air", prob=254, param2=0},
		{name="air", prob=254, param2=0},
		{name="air", prob=254, param2=0},
		{name="air", prob=254, param2=0},
		{name="air", prob=254, param2=0},
		{name="air", prob=254, param2=0},
		{name="air", prob=254, param2=0},
		{name="air", prob=254, param2=0},
		{name="air", prob=254, param2=0},
		{name="air", prob=254, param2=0},
		{name="air", prob=254, param2=0},
		{name="air", prob=254, param2=0},
		{name="air", prob=254, param2=0},
		{name="air", prob=254, param2=0},
		{name="air", prob=254, param2=0},
		{name="air", prob=254, param2=0},
		{name="air", prob=254, param2=0},
		{name="air", prob=254, param2=0},
		{name="air", prob=254, param2=0},
		{name="air", prob=254, param2=0},
		{name="air", prob=254, param2=0},
		{name="air", prob=254, param2=0},
		{name="air", prob=254, param2=0},
		{name="air", prob=254, param2=0},
		{name="air", prob=254, param2=0},
		{name="air", prob=254, param2=0},
		{name="air", prob=254, param2=0},
		{name="air", prob=254, param2=0},
		{name="air", prob=254, param2=0},
		{name="air", prob=254, param2=0},
		{name="air", prob=254, param2=0},
		{name="air", prob=254, param2=0},
		{name="air", prob=254, param2=0},
		{name="air", prob=254, param2=0},
		{name="air", prob=254, param2=0},
		{name="air", prob=254, param2=0},
		{name="air", prob=254, param2=0},
		{name="air", prob=254, param2=0},
		{name="air", prob=254, param2=0},
		{name="air", prob=254, param2=0},
		{name="air", prob=254, param2=0},
		{name="air", prob=254, param2=0},
		{name="air", prob=254, param2=0},
		{name="air", prob=254, param2=0},
		{name="air", prob=254, param2=0},
		{name="air", prob=254, param2=0},
		{name="air", prob=254, param2=0},
		{name="air", prob=254, param2=0},
		{name="air", prob=254, param2=0},
		{name="air", prob=254, param2=0},
		{name="air", prob=254, param2=0},
		{name="air", prob=254, param2=0},
		{name="air", prob=254, param2=0},
		{name="air", prob=254, param2=0},
		{name="air", prob=254, param2=0},
		{name="air", prob=254, param2=0},
		{name="air", prob=254, param2=0},
		{name="air", prob=254, param2=0},
		{name="air", prob=254, param2=0},
		{name="air", prob=254, param2=0},
		{name="air", prob=254, param2=0},
		{name="air", prob=254, param2=0},
		{name="air", prob=254, param2=0},
		{name="air", prob=254, param2=0},
		{name="air", prob=254, param2=0},
		{name="air", prob=254, param2=0},
		{name="air", prob=254, param2=0},
		{name="air", prob=254, param2=0},
		{name="air", prob=254, param2=0},
		{name="air", prob=254, param2=0},
		{name="air", prob=254, param2=0},
		{name="air", prob=254, param2=0},
		{name="air", prob=254, param2=0},
		{name="air", prob=254, param2=0},
		{name="air", prob=254, param2=0},
		{name="air", prob=254, param2=0},
		{name="air", prob=254, param2=0},
		{name="air", prob=254, param2=0},
		{name="air", prob=254, param2=0},
		{name="air", prob=254, param2=0},
		{name="air", prob=254, param2=0},
		{name="air", prob=254, param2=0},
		{name="air", prob=254, param2=0},
		{name="air", prob=254, param2=0},
		{name="air", prob=254, param2=0},
		{name="air", prob=254, param2=0},
		{name="air", prob=254, param2=0},
		{name="air", prob=254, param2=0},
		{name="air", prob=254, param2=0},
		{name="air", prob=254, param2=0},
		{name="air", prob=254, param2=0},
		{name="air", prob=254, param2=0},
		{name="air", prob=254, param2=0},
		{name="air", prob=254, param2=0},
		{name="air", prob=254, param2=0},
		{name="air", prob=254, param2=0},
		{name="air", prob=254, param2=0},
		{name="air", prob=254, param2=0},
		{name="air", prob=254, param2=0},
		{name="air", prob=254, param2=0},
		{name="air", prob=254, param2=0},
		{name="air", prob=254, param2=0},
		{name="air", prob=254, param2=0},
		{name="air", prob=254, param2=0},
		{name="air", prob=254, param2=0},
		{name="air", prob=254, param2=0},
		{name="air", prob=254, param2=0},
		{name="air", prob=254, param2=0},
		{name="air", prob=254, param2=0},
		{name="air", prob=254, param2=0},
		{name="air", prob=254, param2=0},
		{name="air", prob=254, param2=0},
		{name="air", prob=254, param2=0},
		{name="air", prob=254, param2=0},
		{name="air", prob=254, param2=0},
		{name="air", prob=254, param2=0},
		{name="air", prob=254, param2=0},
		{name="air", prob=254, param2=0},
		{name="air", prob=254, param2=0},
		{name="air", prob=254, param2=0},
		{name="air", prob=254, param2=0},
		{name="air", prob=254, param2=0},
		{name="air", prob=254, param2=0},
		{name="air", prob=254, param2=0},
		{name="air", prob=254, param2=0},
		{name="air", prob=254, param2=0},
		{name="air", prob=254, param2=0},
		{name="air", prob=254, param2=0},
		{name="air", prob=254, param2=0},
		{name="air", prob=254, param2=0},
		{name="air", prob=254, param2=0},
		{name="air", prob=254, param2=0},
		{name="air", prob=254, param2=0},
		{name="air", prob=254, param2=0},
		{name="air", prob=254, param2=0},
		{name="air", prob=254, param2=0},
		{name="air", prob=254, param2=0},
		{name="air", prob=254, param2=0},
		{name="air", prob=254, param2=0},
		{name="air", prob=254, param2=0},
		{name="air", prob=254, param2=0},
		{name="air", prob=254, param2=0},
		{name="air", prob=254, param2=0},
		{name="air", prob=254, param2=0},
		{name="air", prob=254, param2=0},
		{name="air", prob=254, param2=0},
		{name="air", prob=254, param2=0},
		{name="air", prob=254, param2=0},
		{name="air", prob=254, param2=0},
		{name="air", prob=254, param2=0},
		{name="air", prob=254, param2=0},
		{name="air", prob=254, param2=0},
		{name="air", prob=254, param2=0},
		{name="air", prob=254, param2=0},
		{name="air", prob=254, param2=0},
		{name="air", prob=254, param2=0},
		{name="air", prob=254, param2=0},
		{name="air", prob=254, param2=0},
		{name="air", prob=254, param2=0},
		{name="air", prob=254, param2=0},
		{name="air", prob=0, param2=0},
		{name="everness:forsaken_tundra_brick", prob=254, param2=0},
		{name="everness:forsaken_tundra_brick", prob=254, param2=0},
		{name="everness:forsaken_tundra_brick", prob=254, param2=0},
		{name="everness:forsaken_tundra_brick", prob=254, param2=0},
		{name="everness:forsaken_tundra_brick", prob=254, param2=0},
		{name="everness:forsaken_tundra_brick", prob=254, param2=0},
		{name="everness:forsaken_tundra_brick", prob=254, param2=0},
		{name="everness:forsaken_tundra_brick", prob=254, param2=0},
		{name="everness:forsaken_tundra_brick", prob=254, param2=0},
		{name="air", prob=0, param2=0},
		{name="air", prob=0, param2=0},
		{name="air", prob=254, param2=0},
		{name="air", prob=254, param2=0},
		{name="air", prob=254, param2=0},
		{name="air", prob=254, param2=0},
		{name="air", prob=254, param2=0},
		{name="air", prob=254, param2=0},
		{name="air", prob=254, param2=0},
		{name="air", prob=254, param2=0},
		{name="air", prob=254, param2=0},
		{name="air", prob=0, param2=0},
		{name="air", prob=254, param2=0},
		{name="air", prob=254, param2=0},
		{name="air", prob=254, param2=0},
		{name="air", prob=254, param2=0},
		{name="air", prob=254, param2=0},
		{name="air", prob=254, param2=0},
		{name="air", prob=254, param2=0},
		{name="air", prob=254, param2=0},
		{name="air", prob=254, param2=0},
		{name="air", prob=254, param2=0},
		{name="air", prob=254, param2=0},
		{name="air", prob=254, param2=0},
		{name="air", prob=254, param2=0},
		{name="air", prob=254, param2=0},
		{name="air", prob=254, param2=0},
		{name="air", prob=254, param2=0},
		{name="air", prob=254, param2=0},
		{name="air", prob=254, param2=0},
		{name="air", prob=254, param2=0},
		{name="air", prob=254, param2=0},
		{name="air", prob=254, param2=0},
		{name="air", prob=254, param2=0},
		{name="air", prob=254, param2=0},
		{name="air", prob=254, param2=0},
		{name="air", prob=254, param2=0},
		{name="air", prob=254, param2=0},
		{name="air", prob=254, param2=0},
		{name="air", prob=254, param2=0},
		{name="air", prob=254, param2=0},
		{name="air", prob=254, param2=0},
		{name="air", prob=254, param2=0},
		{name="air", prob=254, param2=0},
		{name="air", prob=254, param2=0},
		{name="air", prob=254, param2=0},
		{name="air", prob=254, param2=0},
		{name="air", prob=254, param2=0},
		{name="air", prob=254, param2=0},
		{name="air", prob=254, param2=0},
		{name="air", prob=254, param2=0},
		{name="air", prob=254, param2=0},
		{name="air", prob=254, param2=0},
		{name="air", prob=254, param2=0},
		{name="air", prob=254, param2=0},
		{name="air", prob=254, param2=0},
		{name="air", prob=254, param2=0},
		{name="air", prob=254, param2=0},
		{name="air", prob=254, param2=0},
		{name="air", prob=254, param2=0},
		{name="air", prob=254, param2=0},
		{name="air", prob=254, param2=0},
		{name="air", prob=254, param2=0},
		{name="air", prob=254, param2=0},
		{name="air", prob=254, param2=0},
		{name="air", prob=254, param2=0},
		{name="air", prob=254, param2=0},
		{name="air", prob=254, param2=0},
		{name="air", prob=254, param2=0},
		{name="air", prob=254, param2=0},
		{name="air", prob=254, param2=0},
		{name="air", prob=254, param2=0},
		{name="air", prob=254, param2=0},
		{name="air", prob=254, param2=0},
		{name="air", prob=254, param2=0},
		{name="air", prob=254, param2=0},
		{name="air", prob=254, param2=0},
		{name="air", prob=254, param2=0},
		{name="air", prob=254, param2=0},
		{name="air", prob=254, param2=0},
		{name="air", prob=254, param2=0},
		{name="air", prob=254, param2=0},
		{name="air", prob=254, param2=0},
		{name="air", prob=254, param2=0},
		{name="air", prob=254, param2=0},
		{name="air", prob=254, param2=0},
		{name="air", prob=254, param2=0},
		{name="air", prob=254, param2=0},
		{name="air", prob=254, param2=0},
		{name="air", prob=254, param2=0},
		{name="air", prob=254, param2=0},
		{name="air", prob=254, param2=0},
		{name="air", prob=254, param2=0},
		{name="air", prob=254, param2=0},
		{name="air", prob=254, param2=0},
		{name="air", prob=254, param2=0},
		{name="air", prob=254, param2=0},
		{name="air", prob=254, param2=0},
		{name="air", prob=254, param2=0},
		{name="air", prob=254, param2=0},
		{name="air", prob=254, param2=0},
		{name="air", prob=254, param2=0},
		{name="air", prob=254, param2=0},
		{name="air", prob=254, param2=0},
		{name="air", prob=254, param2=0},
		{name="air", prob=254, param2=0},
		{name="air", prob=254, param2=0},
		{name="air", prob=254, param2=0},
		{name="air", prob=254, param2=0},
		{name="air", prob=254, param2=0},
		{name="air", prob=254, param2=0},
		{name="air", prob=254, param2=0},
		{name="air", prob=254, param2=0},
		{name="air", prob=254, param2=0},
		{name="air", prob=254, param2=0},
		{name="air", prob=254, param2=0},
		{name="air", prob=254, param2=0},
		{name="air", prob=254, param2=0},
		{name="air", prob=254, param2=0},
		{name="air", prob=254, param2=0},
		{name="air", prob=254, param2=0},
		{name="air", prob=254, param2=0},
		{name="air", prob=254, param2=0},
		{name="air", prob=254, param2=0},
		{name="air", prob=254, param2=0},
		{name="air", prob=254, param2=0},
		{name="air", prob=254, param2=0},
		{name="air", prob=254, param2=0},
		{name="air", prob=254, param2=0},
		{name="air", prob=254, param2=0},
		{name="air", prob=254, param2=0},
		{name="air", prob=254, param2=0},
		{name="air", prob=254, param2=0},
		{name="air", prob=254, param2=0},
		{name="air", prob=254, param2=0},
		{name="air", prob=254, param2=0},
		{name="air", prob=254, param2=0},
		{name="air", prob=254, param2=0},
		{name="air", prob=254, param2=0},
		{name="air", prob=254, param2=0},
		{name="air", prob=254, param2=0},
		{name="air", prob=254, param2=0},
		{name="air", prob=254, param2=0},
		{name="air", prob=254, param2=0},
		{name="air", prob=254, param2=0},
		{name="air", prob=254, param2=0},
		{name="air", prob=254, param2=0},
		{name="air", prob=254, param2=0},
		{name="air", prob=254, param2=0},
		{name="air", prob=254, param2=0},
		{name="air", prob=254, param2=0},
		{name="air", prob=254, param2=0},
		{name="air", prob=254, param2=0},
		{name="air", prob=254, param2=0},
		{name="air", prob=254, param2=0},
		{name="air", prob=254, param2=0},
		{name="air", prob=254, param2=0},
		{name="air", prob=254, param2=0},
		{name="air", prob=254, param2=0},
		{name="air", prob=254, param2=0},
		{name="air", prob=254, param2=0},
		{name="air", prob=254, param2=0},
		{name="air", prob=254, param2=0},
		{name="air", prob=254, param2=0},
		{name="air", prob=254, param2=0},
		{name="air", prob=254, param2=0},
		{name="air", prob=254, param2=0},
		{name="air", prob=254, param2=0},
		{name="air", prob=254, param2=0},
		{name="air", prob=254, param2=0},
		{name="air", prob=254, param2=0},
		{name="air", prob=254, param2=0},
		{name="air", prob=254, param2=0},
		{name="air", prob=254, param2=0},
		{name="air", prob=254, param2=0},
		{name="air", prob=254, param2=0},
		{name="air", prob=254, param2=0},
		{name="air", prob=254, param2=0},
		{name="air", prob=254, param2=0},
		{name="air", prob=254, param2=0},
		{name="air", prob=254, param2=0},
		{name="air", prob=254, param2=0},
		{name="air", prob=254, param2=0},
		{name="air", prob=254, param2=0},
		{name="air", prob=254, param2=0},
		{name="air", prob=254, param2=0},
		{name="air", prob=254, param2=0},
		{name="air", prob=254, param2=0},
		{name="air", prob=254, param2=0},
		{name="air", prob=254, param2=0},
		{name="air", prob=254, param2=0},
		{name="air", prob=254, param2=0},
		{name="air", prob=254, param2=0},
		{name="air", prob=254, param2=0},
		{name="air", prob=254, param2=0},
		{name="air", prob=254, param2=0},
		{name="air", prob=254, param2=0},
		{name="air", prob=254, param2=0},
		{name="air", prob=254, param2=0},
		{name="air", prob=0, param2=0},
		{name="everness:forsaken_tundra_brick", prob=254, param2=0},
		{name="everness:forsaken_tundra_brick", prob=254, param2=0},
		{name="everness:forsaken_tundra_brick", prob=254, param2=0},
		{name="everness:forsaken_tundra_brick", prob=254, param2=0},
		{name="everness:forsaken_tundra_brick", prob=254, param2=0},
		{name="everness:forsaken_tundra_brick", prob=254, param2=0},
		{name="everness:forsaken_tundra_brick", prob=254, param2=0},
		{name="everness:forsaken_tundra_brick", prob=254, param2=0},
		{name="everness:forsaken_tundra_brick", prob=254, param2=0},
		{name="air", prob=0, param2=0},
		{name="air", prob=0, param2=0},
		{name="air", prob=254, param2=0},
		{name="air", prob=254, param2=0},
		{name="air", prob=254, param2=0},
		{name="stairs:stair_bamboo_wood", prob=254, param2=0},
		{name="stairs:stair_bamboo_wood", prob=254, param2=0},
		{name="stairs:stair_bamboo_wood", prob=254, param2=0},
		{name="air", prob=254, param2=0},
		{name="air", prob=254, param2=0},
		{name="air", prob=254, param2=0},
		{name="air", prob=0, param2=0},
		{name="air", prob=254, param2=0},
		{name="air", prob=254, param2=0},
		{name="air", prob=254, param2=0},
		{name="air", prob=254, param2=0},
		{name="air", prob=254, param2=0},
		{name="air", prob=254, param2=0},
		{name="air", prob=254, param2=0},
		{name="air", prob=254, param2=0},
		{name="air", prob=254, param2=0},
		{name="air", prob=254, param2=0},
		{name="air", prob=254, param2=0},
		{name="air", prob=254, param2=0},
		{name="air", prob=254, param2=0},
		{name="air", prob=254, param2=0},
		{name="air", prob=254, param2=0},
		{name="air", prob=254, param2=0},
		{name="air", prob=254, param2=0},
		{name="air", prob=254, param2=0},
		{name="air", prob=254, param2=0},
		{name="air", prob=254, param2=0},
		{name="air", prob=254, param2=0},
		{name="air", prob=254, param2=0},
		{name="air", prob=254, param2=0},
		{name="air", prob=254, param2=0},
		{name="air", prob=254, param2=0},
		{name="air", prob=254, param2=0},
		{name="air", prob=254, param2=0},
		{name="air", prob=254, param2=0},
		{name="air", prob=254, param2=0},
		{name="air", prob=254, param2=0},
		{name="air", prob=254, param2=0},
		{name="air", prob=254, param2=0},
		{name="air", prob=254, param2=0},
		{name="air", prob=254, param2=0},
		{name="air", prob=254, param2=0},
		{name="air", prob=254, param2=0},
		{name="air", prob=254, param2=0},
		{name="air", prob=254, param2=0},
		{name="air", prob=254, param2=0},
		{name="air", prob=254, param2=0},
		{name="air", prob=254, param2=0},
		{name="air", prob=254, param2=0},
		{name="air", prob=254, param2=0},
		{name="air", prob=254, param2=0},
		{name="air", prob=254, param2=0},
		{name="air", prob=254, param2=0},
		{name="air", prob=254, param2=0},
		{name="air", prob=254, param2=0},
		{name="air", prob=254, param2=0},
		{name="air", prob=254, param2=0},
		{name="air", prob=254, param2=0},
		{name="air", prob=254, param2=0},
		{name="air", prob=254, param2=0},
		{name="air", prob=254, param2=0},
		{name="air", prob=254, param2=0},
		{name="air", prob=254, param2=0},
		{name="stairs:slab_forsaken_tundra_brick", prob=254, param2=20},
		{name="stairs:slab_forsaken_tundra_brick", prob=254, param2=20},
		{name="stairs:slab_forsaken_tundra_brick", prob=254, param2=20},
		{name="stairs:slab_forsaken_tundra_brick", prob=254, param2=20},
		{name="stairs:slab_forsaken_tundra_brick", prob=254, param2=20},
		{name="stairs:slab_forsaken_tundra_brick", prob=254, param2=20},
		{name="stairs:slab_forsaken_tundra_brick", prob=254, param2=20},
		{name="stairs:slab_forsaken_tundra_brick", prob=254, param2=20},
		{name="stairs:slab_forsaken_tundra_brick", prob=254, param2=20},
		{name="air", prob=254, param2=0},
		{name="stairs:slab_forsaken_tundra_brick", prob=254, param2=2},
		{name="air", prob=254, param2=0},
		{name="air", prob=254, param2=0},
		{name="air", prob=254, param2=0},
		{name="air", prob=254, param2=0},
		{name="air", prob=254, param2=0},
		{name="air", prob=254, param2=0},
		{name="air", prob=254, param2=0},
		{name="air", prob=254, param2=0},
		{name="air", prob=254, param2=0},
		{name="stairs:slab_forsaken_tundra_brick", prob=254, param2=2},
		{name="air", prob=254, param2=0},
		{name="air", prob=254, param2=0},
		{name="air", prob=254, param2=0},
		{name="air", prob=254, param2=0},
		{name="air", prob=254, param2=0},
		{name="air", prob=254, param2=0},
		{name="air", prob=254, param2=0},
		{name="air", prob=254, param2=0},
		{name="air", prob=254, param2=0},
		{name="air", prob=254, param2=0},
		{name="air", prob=254, param2=0},
		{name="air", prob=254, param2=0},
		{name="air", prob=254, param2=0},
		{name="air", prob=254, param2=0},
		{name="air", prob=254, param2=0},
		{name="air", prob=254, param2=0},
		{name="air", prob=254, param2=0},
		{name="air", prob=254, param2=0},
		{name="air", prob=254, param2=0},
		{name="air", prob=254, param2=0},
		{name="air", prob=254, param2=0},
		{name="air", prob=254, param2=0},
		{name="air", prob=254, param2=0},
		{name="air", prob=254, param2=0},
		{name="air", prob=254, param2=0},
		{name="air", prob=254, param2=0},
		{name="air", prob=254, param2=0},
		{name="air", prob=254, param2=0},
		{name="air", prob=254, param2=0},
		{name="air", prob=254, param2=0},
		{name="air", prob=254, param2=0},
		{name="air", prob=254, param2=0},
		{name="air", prob=254, param2=0},
		{name="air", prob=254, param2=0},
		{name="air", prob=254, param2=0},
		{name="air", prob=254, param2=0},
		{name="air", prob=254, param2=0},
		{name="air", prob=254, param2=0},
		{name="air", prob=254, param2=0},
		{name="air", prob=254, param2=0},
		{name="air", prob=254, param2=0},
		{name="air", prob=254, param2=0},
		{name="air", prob=254, param2=0},
		{name="air", prob=254, param2=0},
		{name="air", prob=254, param2=0},
		{name="air", prob=254, param2=0},
		{name="air", prob=254, param2=0},
		{name="air", prob=254, param2=0},
		{name="air", prob=254, param2=0},
		{name="air", prob=254, param2=0},
		{name="air", prob=254, param2=0},
		{name="air", prob=254, param2=0},
		{name="air", prob=254, param2=0},
		{name="air", prob=254, param2=0},
		{name="air", prob=254, param2=0},
		{name="air", prob=254, param2=0},
		{name="air", prob=254, param2=0},
		{name="air", prob=254, param2=0},
		{name="air", prob=254, param2=0},
		{name="air", prob=254, param2=0},
		{name="air", prob=254, param2=0},
		{name="air", prob=254, param2=0},
		{name="air", prob=254, param2=0},
		{name="air", prob=254, param2=0},
		{name="air", prob=254, param2=0},
		{name="air", prob=254, param2=0},
		{name="air", prob=254, param2=0},
		{name="air", prob=254, param2=0},
		{name="air", prob=254, param2=0},
		{name="air", prob=254, param2=0},
		{name="air", prob=254, param2=0},
		{name="air", prob=254, param2=0},
		{name="air", prob=254, param2=0},
		{name="air", prob=254, param2=0},
		{name="air", prob=254, param2=0},
		{name="air", prob=254, param2=0},
		{name="air", prob=254, param2=0},
		{name="air", prob=254, param2=0},
		{name="air", prob=254, param2=0},
		{name="air", prob=254, param2=0},
		{name="air", prob=254, param2=0},
		{name="air", prob=254, param2=0},
		{name="air", prob=254, param2=0},
		{name="air", prob=254, param2=0},
		{name="air", prob=254, param2=0},
		{name="air", prob=254, param2=0},
		{name="air", prob=254, param2=0},
		{name="air", prob=254, param2=0},
		{name="air", prob=254, param2=0},
		{name="air", prob=254, param2=0},
		{name="air", prob=254, param2=0},
		{name="air", prob=254, param2=0},
		{name="air", prob=254, param2=0},
		{name="air", prob=254, param2=0},
		{name="air", prob=254, param2=0},
		{name="air", prob=254, param2=0},
		{name="air", prob=254, param2=0},
		{name="air", prob=254, param2=0},
		{name="air", prob=254, param2=0},
		{name="air", prob=254, param2=0},
		{name="air", prob=254, param2=0},
		{name="air", prob=254, param2=0},
		{name="air", prob=254, param2=0},
		{name="air", prob=254, param2=0},
		{name="air", prob=254, param2=0},
		{name="air", prob=254, param2=0},
		{name="air", prob=254, param2=0},
		{name="air", prob=254, param2=0},
		{name="air", prob=254, param2=0},
		{name="air", prob=254, param2=0},
		{name="air", prob=0, param2=0},
		{name="everness:forsaken_tundra_brick", prob=254, param2=0},
		{name="everness:forsaken_tundra_brick", prob=254, param2=0},
		{name="everness:forsaken_tundra_brick", prob=254, param2=0},
		{name="everness:forsaken_tundra_brick", prob=254, param2=0},
		{name="everness:forsaken_tundra_brick", prob=254, param2=0},
		{name="everness:forsaken_tundra_brick", prob=254, param2=0},
		{name="everness:forsaken_tundra_brick", prob=254, param2=0},
		{name="everness:forsaken_tundra_brick", prob=254, param2=0},
		{name="everness:forsaken_tundra_brick", prob=254, param2=0},
		{name="air", prob=0, param2=0},
		{name="air", prob=0, param2=0},
		{name="everness:dirt_with_grass_1", prob=254, param2=0},
		{name="everness:dirt_with_grass_1", prob=254, param2=0},
		{name="everness:forsaken_tundra_brick", prob=254, param2=0},
		{name="everness:forsaken_tundra_brick", prob=254, param2=0},
		{name="everness:forsaken_tundra_brick", prob=254, param2=0},
		{name="everness:forsaken_tundra_brick", prob=254, param2=0},
		{name="everness:forsaken_tundra_brick", prob=254, param2=0},
		{name="everness:dirt_with_grass_1", prob=254, param2=0},
		{name="everness:dirt_with_grass_1", prob=254, param2=0},
		{name="air", prob=0, param2=0},
		{name="air", prob=254, param2=0},
		{name="everness:flowers_4", prob=254, param2=0},
		{name="everness:flowers_3", prob=254, param2=0},
		{name="air", prob=254, param2=0},
		{name="air", prob=254, param2=0},
		{name="air", prob=254, param2=0},
		{name="air", prob=254, param2=0},
		{name="air", prob=254, param2=0},
		{name="everness:flowers_4", prob=254, param2=0},
		{name="everness:flowers_3", prob=254, param2=3},
		{name="air", prob=254, param2=0},
		{name="air", prob=254, param2=0},
		{name="air", prob=254, param2=0},
		{name="everness:fence_bamboo_wood", prob=254, param2=0},
		{name="air", prob=254, param2=0},
		{name="air", prob=254, param2=0},
		{name="air", prob=254, param2=0},
		{name="air", prob=254, param2=0},
		{name="air", prob=254, param2=0},
		{name="everness:fence_bamboo_wood", prob=254, param2=0},
		{name="air", prob=254, param2=0},
		{name="air", prob=254, param2=0},
		{name="air", prob=254, param2=0},
		{name="air", prob=254, param2=0},
		{name="air", prob=254, param2=0},
		{name="air", prob=254, param2=0},
		{name="air", prob=254, param2=0},
		{name="air", prob=254, param2=0},
		{name="air", prob=254, param2=0},
		{name="air", prob=254, param2=0},
		{name="air", prob=254, param2=0},
		{name="air", prob=254, param2=0},
		{name="air", prob=254, param2=0},
		{name="air", prob=254, param2=0},
		{name="air", prob=254, param2=0},
		{name="air", prob=254, param2=0},
		{name="air", prob=254, param2=0},
		{name="air", prob=254, param2=0},
		{name="air", prob=254, param2=0},
		{name="air", prob=254, param2=0},
		{name="air", prob=254, param2=0},
		{name="air", prob=254, param2=0},
		{name="air", prob=254, param2=0},
		{name="air", prob=254, param2=0},
		{name="air", prob=254, param2=0},
		{name="air", prob=254, param2=0},
		{name="air", prob=254, param2=0},
		{name="air", prob=254, param2=0},
		{name="air", prob=254, param2=0},
		{name="air", prob=254, param2=0},
		{name="air", prob=254, param2=0},
		{name="air", prob=254, param2=0},
		{name="air", prob=254, param2=0},
		{name="air", prob=254, param2=0},
		{name="air", prob=254, param2=0},
		{name="stairs:slab_forsaken_tundra_brick", prob=254, param2=23},
		{name="everness:pyrite_lantern", prob=254, param2=0},
		{name="stairs:stair_bamboo_mosaic_wood", prob=254, param2=20},
		{name="everness:fence_bamboo_wood", prob=254, param2=0},
		{name="air", prob=254, param2=0},
		{name="everness:fence_bamboo_wood", prob=254, param2=0},
		{name="air", prob=254, param2=0},
		{name="everness:fence_bamboo_wood", prob=254, param2=0},
		{name="stairs:stair_bamboo_mosaic_wood", prob=254, param2=20},
		{name="everness:pyrite_lantern", prob=254, param2=0},
		{name="stairs:slab_forsaken_tundra_brick", prob=254, param2=21},
		{name="air", prob=254, param2=0},
		{name="stairs:slab_forsaken_tundra_brick", prob=254, param2=0},
		{name="stairs:slab_forsaken_tundra_brick", prob=254, param2=0},
		{name="stairs:slab_forsaken_tundra_brick", prob=254, param2=0},
		{name="stairs:slab_forsaken_tundra_brick", prob=254, param2=0},
		{name="stairs:slab_forsaken_tundra_brick", prob=254, param2=0},
		{name="stairs:slab_forsaken_tundra_brick", prob=254, param2=0},
		{name="stairs:slab_forsaken_tundra_brick", prob=254, param2=0},
		{name="stairs:slab_forsaken_tundra_brick", prob=254, param2=0},
		{name="stairs:slab_forsaken_tundra_brick", prob=254, param2=0},
		{name="air", prob=254, param2=0},
		{name="air", prob=254, param2=0},
		{name="air", prob=254, param2=0},
		{name="air", prob=254, param2=0},
		{name="air", prob=254, param2=0},
		{name="air", prob=254, param2=0},
		{name="air", prob=254, param2=0},
		{name="air", prob=254, param2=0},
		{name="air", prob=254, param2=0},
		{name="air", prob=254, param2=0},
		{name="air", prob=254, param2=0},
		{name="air", prob=254, param2=0},
		{name="air", prob=254, param2=0},
		{name="air", prob=254, param2=0},
		{name="air", prob=254, param2=0},
		{name="air", prob=254, param2=0},
		{name="air", prob=254, param2=0},
		{name="air", prob=254, param2=0},
		{name="air", prob=254, param2=0},
		{name="air", prob=254, param2=0},
		{name="air", prob=254, param2=0},
		{name="air", prob=254, param2=0},
		{name="air", prob=254, param2=0},
		{name="air", prob=254, param2=0},
		{name="air", prob=254, param2=0},
		{name="air", prob=254, param2=0},
		{name="air", prob=254, param2=0},
		{name="air", prob=254, param2=0},
		{name="air", prob=254, param2=0},
		{name="air", prob=254, param2=0},
		{name="air", prob=254, param2=0},
		{name="air", prob=254, param2=0},
		{name="air", prob=254, param2=0},
		{name="air", prob=254, param2=0},
		{name="air", prob=254, param2=0},
		{name="air", prob=254, param2=0},
		{name="air", prob=254, param2=0},
		{name="air", prob=254, param2=0},
		{name="air", prob=254, param2=0},
		{name="air", prob=254, param2=0},
		{name="air", prob=254, param2=0},
		{name="air", prob=254, param2=0},
		{name="air", prob=254, param2=0},
		{name="air", prob=254, param2=0},
		{name="air", prob=254, param2=0},
		{name="air", prob=254, param2=0},
		{name="air", prob=254, param2=0},
		{name="stairs:slab_forsaken_tundra_brick", prob=254, param2=20},
		{name="stairs:slab_forsaken_tundra_brick", prob=254, param2=20},
		{name="stairs:slab_forsaken_tundra_brick", prob=254, param2=20},
		{name="stairs:slab_forsaken_tundra_brick", prob=254, param2=20},
		{name="stairs:slab_forsaken_tundra_brick", prob=254, param2=20},
		{name="stairs:slab_forsaken_tundra_brick", prob=254, param2=20},
		{name="stairs:slab_forsaken_tundra_brick", prob=254, param2=20},
		{name="air", prob=254, param2=0},
		{name="air", prob=254, param2=0},
		{name="air", prob=254, param2=0},
		{name="stairs:slab_forsaken_tundra_brick", prob=254, param2=0},
		{name="air", prob=254, param2=0},
		{name="air", prob=254, param2=0},
		{name="air", prob=254, param2=0},
		{name="air", prob=254, param2=0},
		{name="air", prob=254, param2=0},
		{name="air", prob=254, param2=0},
		{name="air", prob=254, param2=0},
		{name="stairs:slab_forsaken_tundra_brick", prob=254, param2=0},
		{name="air", prob=254, param2=0},
		{name="air", prob=254, param2=0},
		{name="air", prob=254, param2=0},
		{name="air", prob=254, param2=0},
		{name="air", prob=254, param2=0},
		{name="air", prob=254, param2=0},
		{name="air", prob=254, param2=0},
		{name="air", prob=254, param2=0},
		{name="air", prob=254, param2=0},
		{name="air", prob=254, param2=0},
		{name="air", prob=254, param2=0},
		{name="air", prob=254, param2=0},
		{name="air", prob=254, param2=0},
		{name="air", prob=254, param2=0},
		{name="air", prob=254, param2=0},
		{name="air", prob=254, param2=0},
		{name="air", prob=254, param2=0},
		{name="air", prob=254, param2=0},
		{name="air", prob=254, param2=0},
		{name="air", prob=254, param2=0},
		{name="air", prob=254, param2=0},
		{name="air", prob=254, param2=0},
		{name="air", prob=254, param2=0},
		{name="air", prob=254, param2=0},
		{name="air", prob=254, param2=0},
		{name="air", prob=254, param2=0},
		{name="air", prob=254, param2=0},
		{name="air", prob=254, param2=0},
		{name="air", prob=254, param2=0},
		{name="air", prob=254, param2=0},
		{name="air", prob=254, param2=0},
		{name="air", prob=254, param2=0},
		{name="air", prob=254, param2=0},
		{name="air", prob=254, param2=0},
		{name="air", prob=254, param2=0},
		{name="air", prob=254, param2=0},
		{name="air", prob=254, param2=0},
		{name="air", prob=254, param2=0},
		{name="air", prob=254, param2=0},
		{name="air", prob=254, param2=0},
		{name="air", prob=254, param2=0},
		{name="air", prob=254, param2=0},
		{name="air", prob=254, param2=0},
		{name="air", prob=254, param2=0},
		{name="air", prob=254, param2=0},
		{name="air", prob=0, param2=0},
		{name="everness:forsaken_tundra_brick", prob=254, param2=0},
		{name="everness:forsaken_tundra_brick", prob=254, param2=0},
		{name="everness:forsaken_tundra_brick", prob=254, param2=0},
		{name="everness:forsaken_tundra_brick", prob=254, param2=0},
		{name="everness:forsaken_tundra_brick", prob=254, param2=0},
		{name="everness:forsaken_tundra_brick", prob=254, param2=0},
		{name="everness:forsaken_tundra_brick", prob=254, param2=0},
		{name="everness:forsaken_tundra_brick", prob=254, param2=0},
		{name="everness:forsaken_tundra_brick", prob=254, param2=0},
		{name="air", prob=0, param2=0},
		{name="air", prob=0, param2=0},
		{name="everness:dirt_with_grass_1", prob=254, param2=0},
		{name="everness:forsaken_tundra_brick", prob=254, param2=0},
		{name="everness:forsaken_tundra_brick", prob=254, param2=0},
		{name="everness:forsaken_tundra_brick", prob=254, param2=0},
		{name="everness:forsaken_tundra_brick", prob=254, param2=0},
		{name="everness:forsaken_tundra_brick", prob=254, param2=0},
		{name="everness:forsaken_tundra_brick", prob=254, param2=0},
		{name="everness:forsaken_tundra_brick", prob=254, param2=0},
		{name="everness:dirt_with_grass_1", prob=254, param2=0},
		{name="air", prob=0, param2=0},
		{name="air", prob=254, param2=0},
		{name="everness:flowers_2", prob=254, param2=1},
		{name="everness:sequoia_tree", prob=254, param2=0},
		{name="everness:forsaken_tundra_brick", prob=254, param2=0},
		{name="air", prob=254, param2=0},
		{name="air", prob=254, param2=0},
		{name="air", prob=254, param2=0},
		{name="everness:forsaken_tundra_brick", prob=254, param2=0},
		{name="everness:sequoia_tree", prob=254, param2=0},
		{name="everness:flowers_4", prob=254, param2=3},
		{name="air", prob=254, param2=0},
		{name="air", prob=254, param2=0},
		{name="everness:fence_bamboo_wood", prob=254, param2=0},
		{name="everness:sequoia_tree", prob=254, param2=0},
		{name="stairs:stair_bamboo_mosaic_wood", prob=254, param2=0},
		{name="air", prob=254, param2=0},
		{name="air", prob=254, param2=0},
		{name="air", prob=254, param2=0},
		{name="stairs:stair_bamboo_mosaic_wood", prob=254, param2=0},
		{name="everness:sequoia_tree", prob=254, param2=0},
		{name="everness:fence_bamboo_wood", prob=254, param2=0},
		{name="air", prob=254, param2=0},
		{name="air", prob=254, param2=0},
		{name="air", prob=254, param2=0},
		{name="everness:sequoia_tree", prob=254, param2=0},
		{name="everness:fence_bamboo_wood", prob=254, param2=0},
		{name="air", prob=254, param2=0},
		{name="air", prob=254, param2=0},
		{name="air", prob=254, param2=0},
		{name="everness:fence_bamboo_wood", prob=254, param2=0},
		{name="everness:sequoia_tree", prob=254, param2=0},
		{name="air", prob=254, param2=0},
		{name="air", prob=254, param2=0},
		{name="air", prob=254, param2=0},
		{name="air", prob=254, param2=0},
		{name="everness:sequoia_tree", prob=254, param2=0},
		{name="everness:fence_bamboo_wood", prob=254, param2=0},
		{name="everness:fence_bamboo_wood", prob=254, param2=0},
		{name="everness:fence_bamboo_wood", prob=254, param2=0},
		{name="everness:fence_bamboo_wood", prob=254, param2=0},
		{name="everness:fence_bamboo_wood", prob=254, param2=0},
		{name="everness:sequoia_tree", prob=254, param2=0},
		{name="air", prob=254, param2=0},
		{name="air", prob=254, param2=0},
		{name="air", prob=254, param2=0},
		{name="air", prob=254, param2=0},
		{name="everness:sequoia_tree", prob=254, param2=0},
		{name="stairs:stair_bamboo_mosaic_wood", prob=254, param2=20},
		{name="stairs:stair_bamboo_mosaic_wood", prob=254, param2=20},
		{name="stairs:stair_bamboo_mosaic_wood", prob=254, param2=20},
		{name="stairs:stair_bamboo_mosaic_wood", prob=254, param2=20},
		{name="stairs:stair_bamboo_mosaic_wood", prob=254, param2=20},
		{name="everness:sequoia_tree", prob=254, param2=0},
		{name="air", prob=254, param2=0},
		{name="air", prob=254, param2=0},
		{name="stairs:slab_forsaken_tundra_brick", prob=254, param2=23},
		{name="stairs:stair_bamboo_mosaic_wood", prob=254, param2=23},
		{name="everness:sequoia_tree", prob=254, param2=0},
		{name="everness:bamboo_wood", prob=254, param2=0},
		{name="everness:bamboo_wood", prob=254, param2=0},
		{name="everness:bamboo_wood", prob=254, param2=0},
		{name="everness:bamboo_wood", prob=254, param2=0},
		{name="everness:bamboo_wood", prob=254, param2=0},
		{name="everness:sequoia_tree", prob=254, param2=0},
		{name="stairs:stair_bamboo_mosaic_wood", prob=254, param2=21},
		{name="stairs:slab_forsaken_tundra_brick", prob=254, param2=21},
		{name="air", prob=254, param2=0},
		{name="stairs:slab_forsaken_tundra_brick", prob=254, param2=1},
		{name="everness:pyriteblock_polished", prob=254, param2=0},
		{name="stairs:slab_forsaken_tundra_brick", prob=254, param2=20},
		{name="stairs:slab_forsaken_tundra_brick", prob=254, param2=20},
		{name="stairs:slab_forsaken_tundra_brick", prob=254, param2=20},
		{name="stairs:slab_forsaken_tundra_brick", prob=254, param2=20},
		{name="stairs:slab_forsaken_tundra_brick", prob=254, param2=20},
		{name="everness:pyriteblock_polished", prob=254, param2=0},
		{name="stairs:slab_forsaken_tundra_brick", prob=254, param2=3},
		{name="air", prob=254, param2=0},
		{name="air", prob=254, param2=0},
		{name="air", prob=254, param2=0},
		{name="air", prob=254, param2=0},
		{name="air", prob=254, param2=0},
		{name="air", prob=254, param2=0},
		{name="air", prob=254, param2=0},
		{name="air", prob=254, param2=0},
		{name="air", prob=254, param2=0},
		{name="air", prob=254, param2=0},
		{name="air", prob=254, param2=0},
		{name="air", prob=254, param2=0},
		{name="air", prob=254, param2=0},
		{name="air", prob=254, param2=0},
		{name="air", prob=254, param2=0},
		{name="air", prob=254, param2=0},
		{name="air", prob=254, param2=0},
		{name="air", prob=254, param2=0},
		{name="air", prob=254, param2=0},
		{name="air", prob=254, param2=0},
		{name="air", prob=254, param2=0},
		{name="air", prob=254, param2=0},
		{name="air", prob=254, param2=0},
		{name="air", prob=254, param2=0},
		{name="air", prob=254, param2=0},
		{name="air", prob=254, param2=0},
		{name="air", prob=254, param2=0},
		{name="air", prob=254, param2=0},
		{name="air", prob=254, param2=0},
		{name="air", prob=254, param2=0},
		{name="air", prob=254, param2=0},
		{name="air", prob=254, param2=0},
		{name="air", prob=254, param2=0},
		{name="air", prob=254, param2=0},
		{name="air", prob=254, param2=0},
		{name="air", prob=254, param2=0},
		{name="air", prob=254, param2=0},
		{name="air", prob=254, param2=0},
		{name="air", prob=254, param2=0},
		{name="air", prob=254, param2=0},
		{name="air", prob=254, param2=0},
		{name="air", prob=254, param2=0},
		{name="air", prob=254, param2=0},
		{name="air", prob=254, param2=0},
		{name="air", prob=254, param2=0},
		{name="air", prob=254, param2=0},
		{name="stairs:slab_forsaken_tundra_brick", prob=254, param2=23},
		{name="everness:pyrite_lantern", prob=254, param2=0},
		{name="stairs:stair_bamboo_mosaic_wood", prob=254, param2=20},
		{name="air", prob=254, param2=0},
		{name="everness:fence_bamboo_wood", prob=254, param2=0},
		{name="air", prob=254, param2=0},
		{name="stairs:stair_bamboo_mosaic_wood", prob=254, param2=20},
		{name="everness:pyrite_lantern", prob=254, param2=0},
		{name="stairs:slab_forsaken_tundra_brick", prob=254, param2=21},
		{name="air", prob=254, param2=0},
		{name="air", prob=254, param2=0},
		{name="air", prob=254, param2=0},
		{name="stairs:slab_forsaken_tundra_brick", prob=254, param2=2},
		{name="stairs:slab_forsaken_tundra_brick", prob=254, param2=2},
		{name="stairs:slab_forsaken_tundra_brick", prob=254, param2=2},
		{name="stairs:slab_forsaken_tundra_brick", prob=254, param2=2},
		{name="stairs:slab_forsaken_tundra_brick", prob=254, param2=2},
		{name="stairs:slab_forsaken_tundra_brick", prob=254, param2=2},
		{name="stairs:slab_forsaken_tundra_brick", prob=254, param2=2},
		{name="air", prob=254, param2=0},
		{name="air", prob=254, param2=0},
		{name="air", prob=254, param2=0},
		{name="air", prob=254, param2=0},
		{name="air", prob=254, param2=0},
		{name="air", prob=254, param2=0},
		{name="air", prob=254, param2=0},
		{name="air", prob=254, param2=0},
		{name="air", prob=254, param2=0},
		{name="air", prob=254, param2=0},
		{name="air", prob=254, param2=0},
		{name="air", prob=254, param2=0},
		{name="air", prob=254, param2=0},
		{name="air", prob=254, param2=0},
		{name="air", prob=254, param2=0},
		{name="air", prob=254, param2=0},
		{name="air", prob=254, param2=0},
		{name="air", prob=254, param2=0},
		{name="air", prob=254, param2=0},
		{name="air", prob=254, param2=0},
		{name="air", prob=254, param2=0},
		{name="air", prob=254, param2=0},
		{name="air", prob=254, param2=0},
		{name="air", prob=254, param2=0},
		{name="air", prob=254, param2=0},
		{name="air", prob=254, param2=0},
		{name="air", prob=254, param2=0},
		{name="air", prob=254, param2=0},
		{name="air", prob=254, param2=0},
		{name="air", prob=254, param2=0},
		{name="air", prob=254, param2=0},
		{name="air", prob=254, param2=0},
		{name="air", prob=254, param2=0},
		{name="air", prob=254, param2=0},
		{name="air", prob=254, param2=0},
		{name="air", prob=254, param2=0},
		{name="air", prob=254, param2=0},
		{name="air", prob=254, param2=0},
		{name="air", prob=254, param2=0},
		{name="air", prob=254, param2=0},
		{name="air", prob=254, param2=0},
		{name="air", prob=254, param2=0},
		{name="air", prob=254, param2=0},
		{name="air", prob=254, param2=0},
		{name="air", prob=254, param2=0},
		{name="air", prob=254, param2=0},
		{name="air", prob=0, param2=0},
		{name="everness:forsaken_tundra_brick", prob=254, param2=0},
		{name="everness:forsaken_tundra_brick", prob=254, param2=0},
		{name="everness:forsaken_tundra_brick", prob=254, param2=0},
		{name="everness:forsaken_tundra_brick", prob=254, param2=0},
		{name="everness:forsaken_tundra_brick", prob=254, param2=0},
		{name="everness:forsaken_tundra_brick", prob=254, param2=0},
		{name="everness:forsaken_tundra_brick", prob=254, param2=0},
		{name="everness:forsaken_tundra_brick", prob=254, param2=0},
		{name="everness:forsaken_tundra_brick", prob=254, param2=0},
		{name="air", prob=0, param2=0},
		{name="air", prob=0, param2=0},
		{name="everness:forsaken_tundra_brick", prob=254, param2=0},
		{name="everness:forsaken_tundra_brick", prob=254, param2=0},
		{name="everness:forsaken_tundra_brick", prob=254, param2=0},
		{name="everness:forsaken_tundra_brick", prob=254, param2=0},
		{name="everness:forsaken_tundra_brick", prob=254, param2=0},
		{name="everness:forsaken_tundra_brick", prob=254, param2=0},
		{name="everness:forsaken_tundra_brick", prob=254, param2=0},
		{name="everness:forsaken_tundra_brick", prob=254, param2=0},
		{name="everness:forsaken_tundra_brick", prob=254, param2=0},
		{name="air", prob=0, param2=0},
		{name="air", prob=254, param2=0},
		{name="air", prob=254, param2=0},
		{name="everness:forsaken_tundra_brick", prob=254, param2=0},
		{name="everness:sequoia_tree", prob=254, param2=0},
		{name="air", prob=254, param2=0},
		{name="air", prob=254, param2=0},
		{name="air", prob=254, param2=0},
		{name="everness:sequoia_tree", prob=254, param2=0},
		{name="everness:forsaken_tundra_brick", prob=254, param2=0},
		{name="air", prob=254, param2=0},
		{name="air", prob=254, param2=0},
		{name="air", prob=254, param2=0},
		{name="air", prob=254, param2=0},
		{name="stairs:stair_bamboo_mosaic_wood", prob=254, param2=1},
		{name="everness:sequoia_tree", prob=254, param2=0},
		{name="air", prob=254, param2=0},
		{name="air", prob=254, param2=0},
		{name="air", prob=254, param2=0},
		{name="everness:sequoia_tree", prob=254, param2=0},
		{name="stairs:stair_bamboo_mosaic_wood", prob=254, param2=3},
		{name="air", prob=254, param2=0},
		{name="air", prob=254, param2=0},
		{name="air", prob=254, param2=0},
		{name="air", prob=254, param2=0},
		{name="everness:fence_bamboo_wood", prob=254, param2=0},
		{name="everness:sequoia_tree", prob=254, param2=0},
		{name="air", prob=254, param2=0},
		{name="air", prob=254, param2=0},
		{name="air", prob=254, param2=0},
		{name="everness:sequoia_tree", prob=254, param2=0},
		{name="everness:fence_bamboo_wood", prob=254, param2=0},
		{name="air", prob=254, param2=0},
		{name="air", prob=254, param2=0},
		{name="air", prob=254, param2=0},
		{name="air", prob=254, param2=0},
		{name="everness:fence_bamboo_wood", prob=254, param2=0},
		{name="everness:sequoia_tree", prob=254, param2=0},
		{name="air", prob=254, param2=0},
		{name="air", prob=254, param2=0},
		{name="air", prob=254, param2=0},
		{name="everness:sequoia_tree", prob=254, param2=0},
		{name="everness:fence_bamboo_wood", prob=254, param2=0},
		{name="air", prob=254, param2=0},
		{name="air", prob=254, param2=0},
		{name="air", prob=254, param2=0},
		{name="air", prob=254, param2=0},
		{name="stairs:stair_bamboo_mosaic_wood", prob=254, param2=23},
		{name="everness:sequoia_tree", prob=254, param2=0},
		{name="stairs:stair_bamboo_mosaic_wood", prob=254, param2=22},
		{name="stairs:stair_bamboo_mosaic_wood", prob=254, param2=22},
		{name="stairs:stair_bamboo_mosaic_wood", prob=254, param2=22},
		{name="everness:sequoia_tree", prob=254, param2=0},
		{name="stairs:stair_bamboo_mosaic_wood", prob=254, param2=21},
		{name="air", prob=254, param2=0},
		{name="air", prob=254, param2=0},
		{name="stairs:slab_forsaken_tundra_brick", prob=254, param2=23},
		{name="everness:fence_bamboo_wood", prob=254, param2=0},
		{name="everness:bamboo_wood", prob=254, param2=0},
		{name="everness:sequoia_tree", prob=254, param2=0},
		{name="everness:pyrite_pillar_small", prob=254, param2=0},
		{name="everness:pyrite_pillar_small", prob=254, param2=0},
		{name="everness:pyrite_pillar_small", prob=254, param2=0},
		{name="everness:sequoia_tree", prob=254, param2=0},
		{name="everness:bamboo_wood", prob=254, param2=0},
		{name="everness:fence_bamboo_wood", prob=254, param2=0},
		{name="stairs:slab_forsaken_tundra_brick", prob=254, param2=21},
		{name="air", prob=254, param2=0},
		{name="stairs:slab_forsaken_tundra_brick", prob=254, param2=1},
		{name="stairs:slab_forsaken_tundra_brick", prob=254, param2=23},
		{name="everness:sequoia_tree", prob=254, param2=0},
		{name="everness:pyrite_pillar_small", prob=254, param2=0},
		{name="everness:pyrite_pillar_small", prob=254, param2=0},
		{name="everness:pyrite_pillar_small", prob=254, param2=0},
		{name="everness:sequoia_tree", prob=254, param2=0},
		{name="stairs:slab_forsaken_tundra_brick", prob=254, param2=21},
		{name="stairs:slab_forsaken_tundra_brick", prob=254, param2=3},
		{name="air", prob=254, param2=0},
		{name="air", prob=254, param2=0},
		{name="air", prob=254, param2=0},
		{name="air", prob=254, param2=0},
		{name="everness:sequoia_tree", prob=254, param2=0},
		{name="stairs:stair_bamboo_mosaic_wood", prob=254, param2=0},
		{name="stairs:stair_bamboo_mosaic_wood", prob=254, param2=0},
		{name="stairs:stair_bamboo_mosaic_wood", prob=254, param2=0},
		{name="everness:sequoia_tree", prob=254, param2=0},
		{name="air", prob=254, param2=0},
		{name="air", prob=254, param2=0},
		{name="air", prob=254, param2=0},
		{name="air", prob=254, param2=0},
		{name="air", prob=254, param2=0},
		{name="air", prob=254, param2=0},
		{name="everness:sequoia_tree", prob=254, param2=0},
		{name="everness:trapdoor_bamboo_open", prob=254, param2=0},
		{name="everness:trapdoor_bamboo_open", prob=254, param2=0},
		{name="everness:trapdoor_bamboo_open", prob=254, param2=0},
		{name="everness:sequoia_tree", prob=254, param2=0},
		{name="air", prob=254, param2=0},
		{name="air", prob=254, param2=0},
		{name="air", prob=254, param2=0},
		{name="air", prob=254, param2=0},
		{name="air", prob=254, param2=0},
		{name="air", prob=254, param2=0},
		{name="everness:sequoia_tree", prob=254, param2=0},
		{name="everness:trapdoor_bamboo_open", prob=254, param2=0},
		{name="everness:trapdoor_bamboo_open", prob=254, param2=0},
		{name="everness:trapdoor_bamboo_open", prob=254, param2=0},
		{name="everness:sequoia_tree", prob=254, param2=0},
		{name="air", prob=254, param2=0},
		{name="air", prob=254, param2=0},
		{name="air", prob=254, param2=0},
		{name="air", prob=254, param2=0},
		{name="air", prob=254, param2=0},
		{name="air", prob=254, param2=0},
		{name="everness:sequoia_tree", prob=254, param2=0},
		{name="stairs:stair_bamboo_mosaic_wood", prob=254, param2=20},
		{name="stairs:stair_bamboo_mosaic_wood", prob=254, param2=20},
		{name="stairs:stair_bamboo_mosaic_wood", prob=254, param2=20},
		{name="everness:sequoia_tree", prob=254, param2=0},
		{name="air", prob=254, param2=0},
		{name="air", prob=254, param2=0},
		{name="air", prob=254, param2=0},
		{name="air", prob=254, param2=0},
		{name="stairs:slab_forsaken_tundra_brick", prob=254, param2=23},
		{name="stairs:stair_bamboo_mosaic_wood", prob=254, param2=23},
		{name="everness:sequoia_tree", prob=254, param2=0},
		{name="everness:bamboo_wood", prob=254, param2=0},
		{name="everness:bamboo_wood", prob=254, param2=0},
		{name="everness:bamboo_wood", prob=254, param2=0},
		{name="everness:sequoia_tree", prob=254, param2=0},
		{name="stairs:stair_bamboo_mosaic_wood", prob=254, param2=21},
		{name="stairs:slab_forsaken_tundra_brick", prob=254, param2=21},
		{name="air", prob=254, param2=0},
		{name="air", prob=254, param2=0},
		{name="air", prob=254, param2=0},
		{name="stairs:slab_forsaken_tundra_brick", prob=254, param2=2},
		{name="everness:forsaken_tundra_brick", prob=254, param2=0},
		{name="everness:forsaken_tundra_brick", prob=254, param2=0},
		{name="everness:forsaken_tundra_brick", prob=254, param2=0},
		{name="everness:forsaken_tundra_brick", prob=254, param2=0},
		{name="everness:forsaken_tundra_brick", prob=254, param2=0},
		{name="stairs:slab_forsaken_tundra_brick", prob=254, param2=2},
		{name="air", prob=254, param2=0},
		{name="air", prob=254, param2=0},
		{name="air", prob=254, param2=0},
		{name="air", prob=254, param2=0},
		{name="air", prob=254, param2=0},
		{name="air", prob=254, param2=0},
		{name="air", prob=254, param2=0},
		{name="air", prob=254, param2=0},
		{name="air", prob=254, param2=0},
		{name="air", prob=254, param2=0},
		{name="air", prob=254, param2=0},
		{name="air", prob=254, param2=0},
		{name="air", prob=254, param2=0},
		{name="air", prob=254, param2=0},
		{name="air", prob=254, param2=0},
		{name="air", prob=254, param2=0},
		{name="air", prob=254, param2=0},
		{name="air", prob=254, param2=0},
		{name="air", prob=254, param2=0},
		{name="air", prob=254, param2=0},
		{name="air", prob=254, param2=0},
		{name="air", prob=254, param2=0},
		{name="air", prob=254, param2=0},
		{name="air", prob=254, param2=0},
		{name="air", prob=254, param2=0},
		{name="air", prob=254, param2=0},
		{name="air", prob=254, param2=0},
		{name="air", prob=254, param2=0},
		{name="air", prob=254, param2=0},
		{name="air", prob=254, param2=0},
		{name="air", prob=254, param2=0},
		{name="air", prob=254, param2=0},
		{name="air", prob=254, param2=0},
		{name="air", prob=254, param2=0},
		{name="air", prob=254, param2=0},
		{name="air", prob=254, param2=0},
		{name="air", prob=254, param2=0},
		{name="air", prob=254, param2=0},
		{name="air", prob=254, param2=0},
		{name="air", prob=254, param2=0},
		{name="air", prob=254, param2=0},
		{name="air", prob=254, param2=0},
		{name="air", prob=254, param2=0},
		{name="air", prob=254, param2=0},
		{name="air", prob=254, param2=0},
		{name="air", prob=254, param2=0},
		{name="air", prob=0, param2=0},
		{name="everness:forsaken_tundra_brick", prob=254, param2=0},
		{name="everness:forsaken_tundra_brick", prob=254, param2=0},
		{name="everness:forsaken_tundra_brick", prob=254, param2=0},
		{name="everness:forsaken_tundra_brick", prob=254, param2=0},
		{name="everness:forsaken_tundra_brick", prob=254, param2=0},
		{name="everness:forsaken_tundra_brick", prob=254, param2=0},
		{name="everness:forsaken_tundra_brick", prob=254, param2=0},
		{name="everness:forsaken_tundra_brick", prob=254, param2=0},
		{name="everness:forsaken_tundra_brick", prob=254, param2=0},
		{name="air", prob=0, param2=0},
		{name="air", prob=0, param2=0},
		{name="everness:dirt_with_grass_1", prob=254, param2=0},
		{name="everness:forsaken_tundra_brick", prob=254, param2=0},
		{name="everness:forsaken_tundra_brick", prob=254, param2=0},
		{name="everness:forsaken_tundra_brick", prob=254, param2=0},
		{name="everness:forsaken_tundra_brick", prob=254, param2=0},
		{name="everness:forsaken_tundra_brick", prob=254, param2=0},
		{name="everness:forsaken_tundra_brick", prob=254, param2=0},
		{name="everness:forsaken_tundra_brick", prob=254, param2=0},
		{name="everness:dirt_with_grass_1", prob=254, param2=0},
		{name="air", prob=0, param2=0},
		{name="air", prob=254, param2=0},
		{name="everness:flowers_2", prob=254, param2=1},
		{name="everness:bamboo_wood", prob=254, param2=0},
		{name="stairs:slab_baobab_wood", prob=254, param2=21},
		{name="air", prob=254, param2=0},
		{name="air", prob=254, param2=0},
		{name="air", prob=254, param2=0},
		{name="stairs:slab_baobab_wood", prob=254, param2=23},
		{name="everness:bamboo_wood", prob=254, param2=0},
		{name="everness:flowers_4", prob=254, param2=3},
		{name="air", prob=254, param2=0},
		{name="air", prob=254, param2=0},
		{name="air", prob=254, param2=0},
		{name="stairs:stair_bamboo_mosaic_wood", prob=254, param2=1},
		{name="air", prob=254, param2=0},
		{name="air", prob=254, param2=0},
		{name="air", prob=254, param2=0},
		{name="air", prob=254, param2=0},
		{name="air", prob=254, param2=0},
		{name="stairs:stair_bamboo_mosaic_wood", prob=254, param2=3},
		{name="air", prob=254, param2=0},
		{name="air", prob=254, param2=0},
		{name="air", prob=254, param2=0},
		{name="air", prob=254, param2=0},
		{name="air", prob=254, param2=0},
		{name="air", prob=254, param2=0},
		{name="air", prob=254, param2=0},
		{name="air", prob=254, param2=0},
		{name="air", prob=254, param2=0},
		{name="air", prob=254, param2=0},
		{name="air", prob=254, param2=0},
		{name="air", prob=254, param2=0},
		{name="air", prob=254, param2=0},
		{name="air", prob=254, param2=0},
		{name="air", prob=254, param2=0},
		{name="everness:fence_bamboo_wood", prob=254, param2=0},
		{name="air", prob=254, param2=0},
		{name="air", prob=254, param2=0},
		{name="air", prob=254, param2=0},
		{name="air", prob=254, param2=0},
		{name="air", prob=254, param2=0},
		{name="everness:fence_bamboo_wood", prob=254, param2=0},
		{name="air", prob=254, param2=0},
		{name="air", prob=254, param2=0},
		{name="air", prob=254, param2=0},
		{name="air", prob=254, param2=0},
		{name="stairs:stair_bamboo_mosaic_wood", prob=254, param2=23},
		{name="stairs:stair_bamboo_mosaic_wood", prob=254, param2=21},
		{name="air", prob=254, param2=0},
		{name="air", prob=254, param2=0},
		{name="air", prob=254, param2=0},
		{name="stairs:stair_bamboo_mosaic_wood", prob=254, param2=23},
		{name="stairs:stair_bamboo_mosaic_wood", prob=254, param2=21},
		{name="air", prob=254, param2=0},
		{name="air", prob=254, param2=0},
		{name="stairs:slab_forsaken_tundra_brick", prob=254, param2=23},
		{name="air", prob=254, param2=0},
		{name="everness:bamboo_wood", prob=254, param2=0},
		{name="everness:pyrite_pillar_small", prob=254, param2=0},
		{name="air", prob=254, param2=0},
		{name="air", prob=254, param2=0},
		{name="air", prob=254, param2=0},
		{name="everness:pyrite_pillar_small", prob=254, param2=0},
		{name="everness:bamboo_wood", prob=254, param2=0},
		{name="air", prob=254, param2=0},
		{name="stairs:slab_forsaken_tundra_brick", prob=254, param2=21},
		{name="air", prob=254, param2=0},
		{name="stairs:slab_forsaken_tundra_brick", prob=254, param2=1},
		{name="stairs:slab_forsaken_tundra_brick", prob=254, param2=23},
		{name="everness:pyrite_pillar_small", prob=254, param2=0},
		{name="air", prob=254, param2=0},
		{name="air", prob=254, param2=0},
		{name="air", prob=254, param2=0},
		{name="everness:pyrite_pillar_small", prob=254, param2=0},
		{name="stairs:slab_forsaken_tundra_brick", prob=254, param2=21},
		{name="stairs:slab_forsaken_tundra_brick", prob=254, param2=3},
		{name="air", prob=254, param2=0},
		{name="air", prob=254, param2=0},
		{name="air", prob=254, param2=0},
		{name="air", prob=254, param2=0},
		{name="stairs:stair_bamboo_mosaic_wood", prob=254, param2=1},
		{name="air", prob=254, param2=0},
		{name="air", prob=254, param2=0},
		{name="air", prob=254, param2=0},
		{name="stairs:stair_bamboo_mosaic_wood", prob=254, param2=3},
		{name="air", prob=254, param2=0},
		{name="air", prob=254, param2=0},
		{name="air", prob=254, param2=0},
		{name="air", prob=254, param2=0},
		{name="air", prob=254, param2=0},
		{name="air", prob=254, param2=0},
		{name="everness:trapdoor_bamboo_open", prob=254, param2=1},
		{name="air", prob=254, param2=0},
		{name="air", prob=254, param2=0},
		{name="air", prob=254, param2=0},
		{name="everness:trapdoor_bamboo_open", prob=254, param2=3},
		{name="air", prob=254, param2=0},
		{name="air", prob=254, param2=0},
		{name="air", prob=254, param2=0},
		{name="air", prob=254, param2=0},
		{name="air", prob=254, param2=0},
		{name="air", prob=254, param2=0},
		{name="everness:trapdoor_bamboo_open", prob=254, param2=1},
		{name="air", prob=254, param2=0},
		{name="air", prob=254, param2=0},
		{name="air", prob=254, param2=0},
		{name="everness:trapdoor_bamboo_open", prob=254, param2=3},
		{name="air", prob=254, param2=0},
		{name="air", prob=254, param2=0},
		{name="air", prob=254, param2=0},
		{name="air", prob=254, param2=0},
		{name="air", prob=254, param2=0},
		{name="air", prob=254, param2=0},
		{name="stairs:stair_bamboo_mosaic_wood", prob=254, param2=23},
		{name="air", prob=254, param2=0},
		{name="air", prob=254, param2=0},
		{name="air", prob=254, param2=0},
		{name="stairs:stair_bamboo_mosaic_wood", prob=254, param2=21},
		{name="air", prob=254, param2=0},
		{name="air", prob=254, param2=0},
		{name="air", prob=254, param2=0},
		{name="air", prob=254, param2=0},
		{name="stairs:slab_forsaken_tundra_brick", prob=254, param2=23},
		{name="air", prob=254, param2=0},
		{name="everness:bamboo_wood", prob=254, param2=0},
		{name="stairs:stair_inner_bamboo_mosaic_wood", prob=254, param2=22},
		{name="stairs:stair_bamboo_mosaic_wood", prob=254, param2=22},
		{name="stairs:stair_inner_bamboo_mosaic_wood", prob=254, param2=23},
		{name="everness:bamboo_wood", prob=254, param2=0},
		{name="air", prob=254, param2=0},
		{name="stairs:slab_forsaken_tundra_brick", prob=254, param2=21},
		{name="air", prob=254, param2=0},
		{name="air", prob=254, param2=0},
		{name="air", prob=254, param2=0},
		{name="stairs:slab_forsaken_tundra_brick", prob=254, param2=2},
		{name="everness:forsaken_tundra_brick", prob=254, param2=0},
		{name="everness:bamboo_mosaic_wood", prob=254, param2=0},
		{name="everness:bamboo_mosaic_wood", prob=254, param2=0},
		{name="everness:bamboo_mosaic_wood", prob=254, param2=0},
		{name="everness:forsaken_tundra_brick", prob=254, param2=0},
		{name="stairs:slab_forsaken_tundra_brick", prob=254, param2=2},
		{name="air", prob=254, param2=0},
		{name="air", prob=254, param2=0},
		{name="air", prob=254, param2=0},
		{name="air", prob=254, param2=0},
		{name="air", prob=254, param2=0},
		{name="air", prob=254, param2=0},
		{name="stairs:stair_outer_forsaken_tundra_brick", prob=254, param2=1},
		{name="stairs:stair_forsaken_tundra_brick", prob=254, param2=0},
		{name="stairs:stair_outer_forsaken_tundra_brick", prob=254, param2=0},
		{name="air", prob=254, param2=0},
		{name="air", prob=254, param2=0},
		{name="air", prob=254, param2=0},
		{name="air", prob=254, param2=0},
		{name="air", prob=254, param2=0},
		{name="air", prob=254, param2=0},
		{name="air", prob=254, param2=0},
		{name="air", prob=254, param2=0},
		{name="air", prob=254, param2=0},
		{name="air", prob=254, param2=0},
		{name="air", prob=254, param2=0},
		{name="air", prob=254, param2=0},
		{name="air", prob=254, param2=0},
		{name="air", prob=254, param2=0},
		{name="air", prob=254, param2=0},
		{name="air", prob=254, param2=0},
		{name="air", prob=254, param2=0},
		{name="air", prob=254, param2=0},
		{name="air", prob=254, param2=0},
		{name="air", prob=254, param2=0},
		{name="air", prob=254, param2=0},
		{name="air", prob=254, param2=0},
		{name="air", prob=254, param2=0},
		{name="air", prob=254, param2=0},
		{name="air", prob=254, param2=0},
		{name="air", prob=254, param2=0},
		{name="air", prob=254, param2=0},
		{name="air", prob=254, param2=0},
		{name="air", prob=254, param2=0},
		{name="air", prob=254, param2=0},
		{name="air", prob=254, param2=0},
		{name="air", prob=254, param2=0},
		{name="air", prob=254, param2=0},
		{name="air", prob=254, param2=0},
		{name="air", prob=254, param2=0},
		{name="air", prob=254, param2=0},
		{name="air", prob=254, param2=0},
		{name="air", prob=0, param2=0},
		{name="everness:forsaken_tundra_brick", prob=254, param2=0},
		{name="everness:forsaken_tundra_brick", prob=254, param2=0},
		{name="everness:forsaken_tundra_brick", prob=254, param2=0},
		{name="everness:forsaken_tundra_brick", prob=254, param2=0},
		{name="everness:forsaken_tundra_brick", prob=254, param2=0},
		{name="everness:forsaken_tundra_brick", prob=254, param2=0},
		{name="everness:forsaken_tundra_brick", prob=254, param2=0},
		{name="everness:forsaken_tundra_brick", prob=254, param2=0},
		{name="everness:forsaken_tundra_brick", prob=254, param2=0},
		{name="air", prob=0, param2=0},
		{name="air", prob=0, param2=0},
		{name="everness:dirt_with_grass_1", prob=254, param2=0},
		{name="everness:forsaken_tundra_brick", prob=254, param2=0},
		{name="everness:forsaken_tundra_brick", prob=254, param2=0},
		{name="everness:forsaken_tundra_brick", prob=254, param2=0},
		{name="everness:forsaken_tundra_brick", prob=254, param2=0},
		{name="everness:forsaken_tundra_brick", prob=254, param2=0},
		{name="everness:forsaken_tundra_brick", prob=254, param2=0},
		{name="everness:forsaken_tundra_brick", prob=254, param2=0},
		{name="everness:dirt_with_grass_1", prob=254, param2=0},
		{name="air", prob=0, param2=0},
		{name="air", prob=254, param2=0},
		{name="everness:flowers_4", prob=254, param2=1},
		{name="everness:bamboo_wood", prob=254, param2=0},
		{name="air", prob=254, param2=0},
		{name="air", prob=254, param2=0},
		{name="air", prob=254, param2=0},
		{name="air", prob=254, param2=0},
		{name="air", prob=254, param2=0},
		{name="everness:bamboo_wood", prob=254, param2=0},
		{name="everness:flowers_4", prob=254, param2=3},
		{name="air", prob=254, param2=0},
		{name="air", prob=254, param2=0},
		{name="air", prob=254, param2=0},
		{name="stairs:stair_bamboo_mosaic_wood", prob=254, param2=1},
		{name="air", prob=254, param2=0},
		{name="air", prob=254, param2=0},
		{name="air", prob=254, param2=0},
		{name="air", prob=254, param2=0},
		{name="air", prob=254, param2=0},
		{name="stairs:stair_bamboo_mosaic_wood", prob=254, param2=3},
		{name="air", prob=254, param2=0},
		{name="air", prob=254, param2=0},
		{name="air", prob=254, param2=0},
		{name="air", prob=254, param2=0},
		{name="air", prob=254, param2=0},
		{name="air", prob=254, param2=0},
		{name="air", prob=254, param2=0},
		{name="air", prob=254, param2=0},
		{name="air", prob=254, param2=0},
		{name="air", prob=254, param2=0},
		{name="air", prob=254, param2=0},
		{name="air", prob=254, param2=0},
		{name="air", prob=254, param2=0},
		{name="air", prob=254, param2=0},
		{name="air", prob=254, param2=0},
		{name="everness:fence_bamboo_wood", prob=254, param2=0},
		{name="air", prob=254, param2=0},
		{name="air", prob=254, param2=0},
		{name="air", prob=254, param2=0},
		{name="air", prob=254, param2=0},
		{name="air", prob=254, param2=0},
		{name="everness:fence_bamboo_wood", prob=254, param2=0},
		{name="air", prob=254, param2=0},
		{name="air", prob=254, param2=0},
		{name="air", prob=254, param2=0},
		{name="air", prob=254, param2=0},
		{name="stairs:stair_bamboo_mosaic_wood", prob=254, param2=23},
		{name="stairs:stair_bamboo_mosaic_wood", prob=254, param2=21},
		{name="air", prob=254, param2=0},
		{name="air", prob=254, param2=0},
		{name="air", prob=254, param2=0},
		{name="stairs:stair_bamboo_mosaic_wood", prob=254, param2=23},
		{name="stairs:stair_bamboo_mosaic_wood", prob=254, param2=21},
		{name="air", prob=254, param2=0},
		{name="air", prob=254, param2=0},
		{name="stairs:slab_forsaken_tundra_brick", prob=254, param2=23},
		{name="everness:fence_bamboo_wood", prob=254, param2=0},
		{name="everness:bamboo_wood", prob=254, param2=0},
		{name="everness:pyrite_pillar_small", prob=254, param2=0},
		{name="air", prob=254, param2=0},
		{name="air", prob=254, param2=0},
		{name="air", prob=254, param2=0},
		{name="everness:pyrite_pillar_small", prob=254, param2=0},
		{name="everness:bamboo_wood", prob=254, param2=0},
		{name="everness:fence_bamboo_wood", prob=254, param2=0},
		{name="stairs:slab_forsaken_tundra_brick", prob=254, param2=21},
		{name="air", prob=254, param2=0},
		{name="stairs:slab_forsaken_tundra_brick", prob=254, param2=1},
		{name="stairs:slab_forsaken_tundra_brick", prob=254, param2=23},
		{name="everness:pyrite_pillar_small", prob=254, param2=0},
		{name="air", prob=254, param2=0},
		{name="air", prob=254, param2=0},
		{name="air", prob=254, param2=0},
		{name="everness:pyrite_pillar_small", prob=254, param2=0},
		{name="stairs:slab_forsaken_tundra_brick", prob=254, param2=21},
		{name="stairs:slab_forsaken_tundra_brick", prob=254, param2=3},
		{name="air", prob=254, param2=0},
		{name="air", prob=254, param2=0},
		{name="air", prob=254, param2=0},
		{name="air", prob=254, param2=0},
		{name="stairs:stair_bamboo_mosaic_wood", prob=254, param2=1},
		{name="air", prob=254, param2=0},
		{name="air", prob=254, param2=0},
		{name="air", prob=254, param2=0},
		{name="stairs:stair_bamboo_mosaic_wood", prob=254, param2=3},
		{name="air", prob=254, param2=0},
		{name="air", prob=254, param2=0},
		{name="air", prob=254, param2=0},
		{name="air", prob=254, param2=0},
		{name="air", prob=254, param2=0},
		{name="air", prob=254, param2=0},
		{name="everness:trapdoor_bamboo_open", prob=254, param2=1},
		{name="air", prob=254, param2=0},
		{name="everness:pyrite_lantern", prob=254, param2=0},
		{name="air", prob=254, param2=0},
		{name="everness:trapdoor_bamboo_open", prob=254, param2=3},
		{name="air", prob=254, param2=0},
		{name="air", prob=254, param2=0},
		{name="air", prob=254, param2=0},
		{name="air", prob=254, param2=0},
		{name="air", prob=254, param2=0},
		{name="air", prob=254, param2=0},
		{name="everness:trapdoor_bamboo_open", prob=254, param2=1},
		{name="air", prob=254, param2=0},
		{name="everness:pyrite_lantern", prob=254, param2=0},
		{name="air", prob=254, param2=0},
		{name="everness:trapdoor_bamboo_open", prob=254, param2=3},
		{name="air", prob=254, param2=0},
		{name="air", prob=254, param2=0},
		{name="air", prob=254, param2=0},
		{name="air", prob=254, param2=0},
		{name="air", prob=254, param2=0},
		{name="air", prob=254, param2=0},
		{name="stairs:stair_bamboo_mosaic_wood", prob=254, param2=23},
		{name="air", prob=254, param2=0},
		{name="everness:fence_bamboo_wood", prob=254, param2=0},
		{name="air", prob=254, param2=0},
		{name="stairs:stair_bamboo_mosaic_wood", prob=254, param2=21},
		{name="air", prob=254, param2=0},
		{name="air", prob=254, param2=0},
		{name="air", prob=254, param2=0},
		{name="air", prob=254, param2=0},
		{name="stairs:slab_forsaken_tundra_brick", prob=254, param2=23},
		{name="everness:fence_bamboo_wood", prob=254, param2=0},
		{name="everness:bamboo_wood", prob=254, param2=0},
		{name="stairs:stair_bamboo_mosaic_wood", prob=254, param2=21},
		{name="everness:fence_bamboo_wood", prob=254, param2=0},
		{name="stairs:stair_bamboo_mosaic_wood", prob=254, param2=23},
		{name="everness:bamboo_wood", prob=254, param2=0},
		{name="everness:fence_bamboo_wood", prob=254, param2=0},
		{name="stairs:slab_forsaken_tundra_brick", prob=254, param2=21},
		{name="air", prob=254, param2=0},
		{name="air", prob=254, param2=0},
		{name="air", prob=254, param2=0},
		{name="stairs:slab_forsaken_tundra_brick", prob=254, param2=2},
		{name="everness:forsaken_tundra_brick", prob=254, param2=0},
		{name="everness:bamboo_mosaic_wood", prob=254, param2=0},
		{name="everness:bamboo_mosaic_wood", prob=254, param2=0},
		{name="everness:bamboo_mosaic_wood", prob=254, param2=0},
		{name="everness:forsaken_tundra_brick", prob=254, param2=0},
		{name="stairs:slab_forsaken_tundra_brick", prob=254, param2=2},
		{name="air", prob=254, param2=0},
		{name="air", prob=254, param2=0},
		{name="air", prob=254, param2=0},
		{name="air", prob=254, param2=0},
		{name="air", prob=254, param2=0},
		{name="air", prob=254, param2=0},
		{name="stairs:stair_forsaken_tundra_brick", prob=254, param2=1},
		{name="everness:forsaken_tundra_brick", prob=254, param2=0},
		{name="stairs:stair_forsaken_tundra_brick", prob=254, param2=3},
		{name="air", prob=254, param2=0},
		{name="air", prob=254, param2=0},
		{name="air", prob=254, param2=0},
		{name="air", prob=254, param2=0},
		{name="air", prob=254, param2=0},
		{name="air", prob=254, param2=0},
		{name="air", prob=254, param2=0},
		{name="air", prob=254, param2=0},
		{name="air", prob=254, param2=0},
		{name="everness:pyriteblock_polished", prob=254, param2=0},
		{name="air", prob=254, param2=0},
		{name="air", prob=254, param2=0},
		{name="air", prob=254, param2=0},
		{name="air", prob=254, param2=0},
		{name="air", prob=254, param2=0},
		{name="air", prob=254, param2=0},
		{name="air", prob=254, param2=0},
		{name="air", prob=254, param2=0},
		{name="air", prob=254, param2=0},
		{name="air", prob=254, param2=0},
		{name="everness:fence_bamboo_wood", prob=254, param2=0},
		{name="air", prob=254, param2=0},
		{name="air", prob=254, param2=0},
		{name="air", prob=254, param2=0},
		{name="air", prob=254, param2=0},
		{name="air", prob=254, param2=0},
		{name="air", prob=254, param2=0},
		{name="air", prob=254, param2=0},
		{name="air", prob=254, param2=0},
		{name="air", prob=254, param2=0},
		{name="air", prob=254, param2=0},
		{name="everness:fence_bamboo_wood", prob=254, param2=0},
		{name="air", prob=254, param2=0},
		{name="air", prob=254, param2=0},
		{name="air", prob=254, param2=0},
		{name="air", prob=254, param2=0},
		{name="air", prob=254, param2=0},
		{name="air", prob=0, param2=0},
		{name="everness:forsaken_tundra_brick", prob=254, param2=0},
		{name="everness:forsaken_tundra_brick", prob=254, param2=0},
		{name="everness:forsaken_tundra_brick", prob=254, param2=0},
		{name="everness:forsaken_tundra_brick", prob=254, param2=0},
		{name="everness:forsaken_tundra_brick", prob=254, param2=0},
		{name="everness:forsaken_tundra_brick", prob=254, param2=0},
		{name="everness:forsaken_tundra_brick", prob=254, param2=0},
		{name="everness:forsaken_tundra_brick", prob=254, param2=0},
		{name="everness:forsaken_tundra_brick", prob=254, param2=0},
		{name="air", prob=0, param2=0},
		{name="air", prob=0, param2=0},
		{name="everness:dirt_with_grass_1", prob=254, param2=0},
		{name="everness:forsaken_tundra_brick", prob=254, param2=0},
		{name="everness:forsaken_tundra_brick", prob=254, param2=0},
		{name="everness:forsaken_tundra_brick", prob=254, param2=0},
		{name="everness:forsaken_tundra_brick", prob=254, param2=0},
		{name="everness:forsaken_tundra_brick", prob=254, param2=0},
		{name="everness:forsaken_tundra_brick", prob=254, param2=0},
		{name="everness:forsaken_tundra_brick", prob=254, param2=0},
		{name="everness:dirt_with_grass_1", prob=254, param2=0},
		{name="air", prob=0, param2=0},
		{name="air", prob=254, param2=0},
		{name="everness:flowers_4", prob=254, param2=1},
		{name="everness:bamboo_wood", prob=254, param2=0},
		{name="stairs:slab_baobab_wood", prob=254, param2=21},
		{name="air", prob=254, param2=0},
		{name="air", prob=254, param2=0},
		{name="air", prob=254, param2=0},
		{name="stairs:slab_baobab_wood", prob=254, param2=23},
		{name="everness:bamboo_wood", prob=254, param2=0},
		{name="everness:flowers_3", prob=254, param2=3},
		{name="air", prob=254, param2=0},
		{name="air", prob=254, param2=0},
		{name="air", prob=254, param2=0},
		{name="stairs:stair_bamboo_mosaic_wood", prob=254, param2=1},
		{name="air", prob=254, param2=0},
		{name="air", prob=254, param2=0},
		{name="air", prob=254, param2=0},
		{name="air", prob=254, param2=0},
		{name="air", prob=254, param2=0},
		{name="stairs:stair_bamboo_mosaic_wood", prob=254, param2=3},
		{name="air", prob=254, param2=0},
		{name="air", prob=254, param2=0},
		{name="air", prob=254, param2=0},
		{name="air", prob=254, param2=0},
		{name="air", prob=254, param2=0},
		{name="air", prob=254, param2=0},
		{name="air", prob=254, param2=0},
		{name="air", prob=254, param2=0},
		{name="air", prob=254, param2=0},
		{name="air", prob=254, param2=0},
		{name="air", prob=254, param2=0},
		{name="air", prob=254, param2=0},
		{name="air", prob=254, param2=0},
		{name="air", prob=254, param2=0},
		{name="air", prob=254, param2=0},
		{name="everness:fence_bamboo_wood", prob=254, param2=0},
		{name="air", prob=254, param2=0},
		{name="air", prob=254, param2=0},
		{name="air", prob=254, param2=0},
		{name="air", prob=254, param2=0},
		{name="air", prob=254, param2=0},
		{name="everness:fence_bamboo_wood", prob=254, param2=0},
		{name="air", prob=254, param2=0},
		{name="air", prob=254, param2=0},
		{name="air", prob=254, param2=0},
		{name="air", prob=254, param2=0},
		{name="stairs:stair_bamboo_mosaic_wood", prob=254, param2=23},
		{name="stairs:stair_bamboo_mosaic_wood", prob=254, param2=21},
		{name="air", prob=254, param2=0},
		{name="air", prob=254, param2=0},
		{name="air", prob=254, param2=0},
		{name="stairs:stair_bamboo_mosaic_wood", prob=254, param2=23},
		{name="stairs:stair_bamboo_mosaic_wood", prob=254, param2=21},
		{name="air", prob=254, param2=0},
		{name="air", prob=254, param2=0},
		{name="stairs:slab_forsaken_tundra_brick", prob=254, param2=23},
		{name="air", prob=254, param2=0},
		{name="everness:bamboo_wood", prob=254, param2=0},
		{name="everness:pyrite_pillar_small", prob=254, param2=0},
		{name="air", prob=254, param2=0},
		{name="air", prob=254, param2=0},
		{name="air", prob=254, param2=0},
		{name="everness:pyrite_pillar_small", prob=254, param2=0},
		{name="everness:bamboo_wood", prob=254, param2=0},
		{name="air", prob=254, param2=0},
		{name="stairs:slab_forsaken_tundra_brick", prob=254, param2=21},
		{name="air", prob=254, param2=0},
		{name="stairs:slab_forsaken_tundra_brick", prob=254, param2=1},
		{name="stairs:slab_forsaken_tundra_brick", prob=254, param2=23},
		{name="everness:pyrite_pillar_small", prob=254, param2=0},
		{name="air", prob=254, param2=0},
		{name="air", prob=254, param2=0},
		{name="air", prob=254, param2=0},
		{name="everness:pyrite_pillar_small", prob=254, param2=0},
		{name="stairs:slab_forsaken_tundra_brick", prob=254, param2=21},
		{name="stairs:slab_forsaken_tundra_brick", prob=254, param2=3},
		{name="air", prob=254, param2=0},
		{name="air", prob=254, param2=0},
		{name="air", prob=254, param2=0},
		{name="air", prob=254, param2=0},
		{name="stairs:stair_bamboo_mosaic_wood", prob=254, param2=1},
		{name="air", prob=254, param2=0},
		{name="air", prob=254, param2=0},
		{name="air", prob=254, param2=0},
		{name="stairs:stair_bamboo_mosaic_wood", prob=254, param2=3},
		{name="air", prob=254, param2=0},
		{name="air", prob=254, param2=0},
		{name="air", prob=254, param2=0},
		{name="air", prob=254, param2=0},
		{name="air", prob=254, param2=0},
		{name="air", prob=254, param2=0},
		{name="everness:trapdoor_bamboo_open", prob=254, param2=1},
		{name="air", prob=254, param2=0},
		{name="air", prob=254, param2=0},
		{name="air", prob=254, param2=0},
		{name="everness:trapdoor_bamboo_open", prob=254, param2=3},
		{name="air", prob=254, param2=0},
		{name="air", prob=254, param2=0},
		{name="air", prob=254, param2=0},
		{name="air", prob=254, param2=0},
		{name="air", prob=254, param2=0},
		{name="air", prob=254, param2=0},
		{name="everness:trapdoor_bamboo_open", prob=254, param2=1},
		{name="air", prob=254, param2=0},
		{name="air", prob=254, param2=0},
		{name="air", prob=254, param2=0},
		{name="everness:trapdoor_bamboo_open", prob=254, param2=3},
		{name="air", prob=254, param2=0},
		{name="air", prob=254, param2=0},
		{name="air", prob=254, param2=0},
		{name="air", prob=254, param2=0},
		{name="air", prob=254, param2=0},
		{name="air", prob=254, param2=0},
		{name="stairs:stair_bamboo_mosaic_wood", prob=254, param2=23},
		{name="air", prob=254, param2=0},
		{name="air", prob=254, param2=0},
		{name="air", prob=254, param2=0},
		{name="stairs:stair_bamboo_mosaic_wood", prob=254, param2=21},
		{name="air", prob=254, param2=0},
		{name="air", prob=254, param2=0},
		{name="air", prob=254, param2=0},
		{name="air", prob=254, param2=0},
		{name="stairs:slab_forsaken_tundra_brick", prob=254, param2=23},
		{name="air", prob=254, param2=0},
		{name="everness:bamboo_wood", prob=254, param2=0},
		{name="stairs:stair_inner_bamboo_mosaic_wood", prob=254, param2=21},
		{name="stairs:stair_bamboo_mosaic_wood", prob=254, param2=20},
		{name="stairs:stair_inner_bamboo_mosaic_wood", prob=254, param2=20},
		{name="everness:bamboo_wood", prob=254, param2=0},
		{name="air", prob=254, param2=0},
		{name="stairs:slab_forsaken_tundra_brick", prob=254, param2=21},
		{name="air", prob=254, param2=0},
		{name="air", prob=254, param2=0},
		{name="air", prob=254, param2=0},
		{name="stairs:slab_forsaken_tundra_brick", prob=254, param2=2},
		{name="everness:forsaken_tundra_brick", prob=254, param2=0},
		{name="everness:bamboo_mosaic_wood", prob=254, param2=0},
		{name="everness:bamboo_mosaic_wood", prob=254, param2=0},
		{name="everness:bamboo_mosaic_wood", prob=254, param2=0},
		{name="everness:forsaken_tundra_brick", prob=254, param2=0},
		{name="stairs:slab_forsaken_tundra_brick", prob=254, param2=2},
		{name="air", prob=254, param2=0},
		{name="air", prob=254, param2=0},
		{name="air", prob=254, param2=0},
		{name="air", prob=254, param2=0},
		{name="air", prob=254, param2=0},
		{name="air", prob=254, param2=0},
		{name="stairs:stair_outer_forsaken_tundra_brick", prob=254, param2=2},
		{name="stairs:stair_forsaken_tundra_brick", prob=254, param2=2},
		{name="stairs:stair_outer_forsaken_tundra_brick", prob=254, param2=3},
		{name="air", prob=254, param2=0},
		{name="air", prob=254, param2=0},
		{name="air", prob=254, param2=0},
		{name="air", prob=254, param2=0},
		{name="air", prob=254, param2=0},
		{name="air", prob=254, param2=0},
		{name="air", prob=254, param2=0},
		{name="air", prob=254, param2=0},
		{name="air", prob=254, param2=0},
		{name="air", prob=254, param2=0},
		{name="air", prob=254, param2=0},
		{name="air", prob=254, param2=0},
		{name="air", prob=254, param2=0},
		{name="air", prob=254, param2=0},
		{name="air", prob=254, param2=0},
		{name="air", prob=254, param2=0},
		{name="air", prob=254, param2=0},
		{name="air", prob=254, param2=0},
		{name="air", prob=254, param2=0},
		{name="air", prob=254, param2=0},
		{name="air", prob=254, param2=0},
		{name="air", prob=254, param2=0},
		{name="air", prob=254, param2=0},
		{name="air", prob=254, param2=0},
		{name="air", prob=254, param2=0},
		{name="air", prob=254, param2=0},
		{name="air", prob=254, param2=0},
		{name="air", prob=254, param2=0},
		{name="air", prob=254, param2=0},
		{name="air", prob=254, param2=0},
		{name="air", prob=254, param2=0},
		{name="air", prob=254, param2=0},
		{name="air", prob=254, param2=0},
		{name="air", prob=254, param2=0},
		{name="air", prob=254, param2=0},
		{name="air", prob=254, param2=0},
		{name="air", prob=254, param2=0},
		{name="air", prob=0, param2=0},
		{name="everness:forsaken_tundra_brick", prob=254, param2=0},
		{name="everness:forsaken_tundra_brick", prob=254, param2=0},
		{name="everness:forsaken_tundra_brick", prob=254, param2=0},
		{name="everness:forsaken_tundra_brick", prob=254, param2=0},
		{name="everness:forsaken_tundra_brick", prob=254, param2=0},
		{name="everness:forsaken_tundra_brick", prob=254, param2=0},
		{name="everness:forsaken_tundra_brick", prob=254, param2=0},
		{name="everness:forsaken_tundra_brick", prob=254, param2=0},
		{name="everness:forsaken_tundra_brick", prob=254, param2=0},
		{name="air", prob=0, param2=0},
		{name="air", prob=0, param2=0},
		{name="everness:forsaken_tundra_brick", prob=254, param2=0},
		{name="everness:forsaken_tundra_brick", prob=254, param2=0},
		{name="everness:forsaken_tundra_brick", prob=254, param2=0},
		{name="everness:forsaken_tundra_brick", prob=254, param2=0},
		{name="everness:forsaken_tundra_brick", prob=254, param2=0},
		{name="everness:forsaken_tundra_brick", prob=254, param2=0},
		{name="everness:forsaken_tundra_brick", prob=254, param2=0},
		{name="everness:forsaken_tundra_brick", prob=254, param2=0},
		{name="everness:forsaken_tundra_brick", prob=254, param2=0},
		{name="air", prob=0, param2=0},
		{name="air", prob=254, param2=0},
		{name="air", prob=254, param2=0},
		{name="everness:forsaken_tundra_brick", prob=254, param2=0},
		{name="everness:sequoia_tree", prob=254, param2=2},
		{name="air", prob=254, param2=0},
		{name="everness:chest", prob=254, param2=0},
		{name="air", prob=254, param2=0},
		{name="everness:sequoia_tree", prob=254, param2=3},
		{name="everness:forsaken_tundra_brick", prob=254, param2=0},
		{name="air", prob=254, param2=0},
		{name="air", prob=254, param2=0},
		{name="air", prob=254, param2=0},
		{name="air", prob=254, param2=0},
		{name="stairs:stair_bamboo_mosaic_wood", prob=254, param2=1},
		{name="everness:sequoia_tree", prob=254, param2=2},
		{name="stairs:slab_baobab_wood", prob=254, param2=20},
		{name="air", prob=254, param2=0},
		{name="stairs:slab_baobab_wood", prob=254, param2=20},
		{name="everness:sequoia_tree", prob=254, param2=3},
		{name="stairs:stair_bamboo_mosaic_wood", prob=254, param2=3},
		{name="air", prob=254, param2=0},
		{name="air", prob=254, param2=0},
		{name="air", prob=254, param2=0},
		{name="air", prob=254, param2=0},
		{name="everness:fence_bamboo_wood", prob=254, param2=0},
		{name="everness:sequoia_tree", prob=254, param2=2},
		{name="air", prob=254, param2=0},
		{name="air", prob=254, param2=0},
		{name="air", prob=254, param2=0},
		{name="everness:sequoia_tree", prob=254, param2=3},
		{name="everness:fence_bamboo_wood", prob=254, param2=0},
		{name="air", prob=254, param2=0},
		{name="air", prob=254, param2=0},
		{name="air", prob=254, param2=0},
		{name="air", prob=254, param2=0},
		{name="everness:fence_bamboo_wood", prob=254, param2=0},
		{name="everness:sequoia_tree", prob=254, param2=2},
		{name="air", prob=254, param2=0},
		{name="air", prob=254, param2=0},
		{name="air", prob=254, param2=0},
		{name="everness:sequoia_tree", prob=254, param2=3},
		{name="everness:fence_bamboo_wood", prob=254, param2=0},
		{name="air", prob=254, param2=0},
		{name="air", prob=254, param2=0},
		{name="air", prob=254, param2=0},
		{name="air", prob=254, param2=0},
		{name="stairs:stair_bamboo_mosaic_wood", prob=254, param2=23},
