schematic = {
	size = {x=7, y=5, z=7},
	yslice_prob = {
		{ypos=0, prob=254},
		{ypos=1, prob=254},
		{ypos=2, prob=254},
		{ypos=3, prob=254},
		{ypos=4, prob=254},
	},
	data = {
		{name="everness:coral_forest_deep_ocean_coral_2", prob=126, param2=0},
		{name="everness:coral_forest_deep_ocean_coral_2", prob=126, param2=0},
		{name="everness:coral_forest_deep_ocean_coral_2", prob=126, param2=0},
		{name="everness:coral_forest_deep_ocean_coral_2", prob=126, param2=0},
		{name="everness:coral_forest_deep_ocean_coral_2", prob=126, param2=0},
		{name="everness:coral_forest_deep_ocean_coral_2", prob=126, param2=0},
		{name="everness:coral_forest_deep_ocean_coral_2", prob=126, param2=0},
		{name="air", prob=0, param2=0},
		{name="air", prob=0, param2=0},
		{name="air", prob=0, param2=0},
		{name="air", prob=0, param2=0},
		{name="air", prob=0, param2=0},
		{name="air", prob=0, param2=0},
		{name="air", prob=0, param2=0},
		{name="air", prob=0, param2=0},
		{name="air", prob=0, param2=0},
		{name="air", prob=0, param2=0},
		{name="air", prob=0, param2=0},
		{name="air", prob=0, param2=0},
		{name="air", prob=0, param2=0},
		{name="air", prob=0, param2=0},
		{name="air", prob=0, param2=0},
		{name="air", prob=0, param2=0},
		{name="air", prob=0, param2=0},
		{name="air", prob=0, param2=0},
		{name="air", prob=0, param2=0},
		{name="air", prob=0, param2=0},
		{name="air", prob=0, param2=0},
		{name="air", prob=0, param2=0},
		{name="air", prob=0, param2=0},
		{name="air", prob=0, param2=0},
		{name="air", prob=0, param2=0},
		{name="air", prob=0, param2=0},
		{name="air", prob=0, param2=0},
		{name="air", prob=0, param2=0},
		{name="everness:coral_forest_deep_ocean_coral_2", prob=126, param2=0},
		{name="everness:coral_desert_stone", prob=254, param2=0},
		{name="everness:coral_desert_stone", prob=254, param2=0},
		{name="everness:coral_desert_stone", prob=254, param2=0},
		{name="everness:coral_desert_stone", prob=254, param2=0},
		{name="everness:coral_desert_stone", prob=254, param2=0},
		{name="everness:coral_forest_deep_ocean_coral_2", prob=126, param2=0},
		{name="air", prob=0, param2=0},
		{name="everness:coral_forest_deep_ocean_coral_2", prob=254, param2=0},
		{name="everness:coral_forest_deep_ocean_coral_2", prob=254, param2=0},
		{name="everness:coral_forest_deep_ocean_coral_2", prob=254, param2=0},
		{name="everness:coral_forest_deep_ocean_coral_2", prob=254, param2=0},
		{name="everness:coral_forest_deep_ocean_coral_2", prob=254, param2=0},
		{name="air", prob=0, param2=0},
		{name="air", prob=0, param2=0},
		{name="everness:coral_forest_deep_ocean_coral_2", prob=126, param2=0},
		{name="everness:coral_forest_deep_ocean_coral_2", prob=126, param2=0},
		{name="everness:coral_forest_deep_ocean_coral_2", prob=126, param2=0},
		{name="everness:coral_forest_deep_ocean_coral_2", prob=126, param2=0},
		{name="everness:coral_forest_deep_ocean_coral_2", prob=126, param2=0},
		{name="air", prob=0, param2=0},
		{name="air", prob=0, param2=0},
		{name="air", prob=0, param2=0},
		{name="air", prob=0, param2=0},
		{name="air", prob=0, param2=0},
		{name="air", prob=0, param2=0},
		{name="air", prob=0, param2=0},
		{name="air", prob=0, param2=0},
		{name="air", prob=0, param2=0},
		{name="air", prob=0, param2=0},
		{name="air", prob=0, param2=0},
		{name="air", prob=0, param2=0},
		{name="air", prob=0, param2=0},
		{name="air", prob=0, param2=0},
		{name="air", prob=0, param2=0},
		{name="everness:coral_forest_deep_ocean_coral_2", prob=126, param2=0},
		{name="everness:coral_desert_stone", prob=254, param2=0},
		{name="everness:coral_desert_stone", prob=254, param2=0},
		{name="everness:coral_desert_stone", prob=254, param2=0},
		{name="everness:coral_desert_stone", prob=254, param2=0},
		{name="everness:coral_desert_stone", prob=254, param2=0},
		{name="everness:coral_forest_deep_ocean_coral_2", prob=126, param2=0},
		{name="air", prob=0, param2=0},
		{name="everness:coral_forest_deep_ocean_coral_2", prob=254, param2=0},
		{name="everness:coral_skeleton", prob=254, param2=0},
		{name="everness:coral_skeleton", prob=254, param2=0},
		{name="everness:coral_skeleton", prob=254, param2=0},
		{name="everness:coral_forest_deep_ocean_coral_2", prob=254, param2=0},
		{name="air", prob=0, param2=0},
		{name="air", prob=0, param2=0},
		{name="everness:coral_forest_deep_ocean_coral_2", prob=126, param2=0},
		{name="everness:coral_forest_deep_ocean_coral_2", prob=254, param2=0},
		{name="everness:coral_forest_deep_ocean_coral_2", prob=254, param2=0},
		{name="everness:coral_forest_deep_ocean_coral_2", prob=254, param2=0},
		{name="everness:coral_forest_deep_ocean_coral_2", prob=126, param2=0},
		{name="air", prob=0, param2=0},
		{name="air", prob=0, param2=0},
		{name="air", prob=0, param2=0},
		{name="everness:coral_forest_deep_ocean_coral_2", prob=254, param2=0},
		{name="everness:coral_forest_deep_ocean_coral_2", prob=254, param2=0},
		{name="everness:coral_forest_deep_ocean_coral_2", prob=254, param2=0},
		{name="air", prob=0, param2=0},
		{name="air", prob=0, param2=0},
		{name="air", prob=0, param2=0},
		{name="air", prob=0, param2=0},
		{name="everness:coral_forest_deep_ocean_coral_2", prob=126, param2=0},
		{name="everness:coral_forest_deep_ocean_coral_2", prob=126, param2=0},
		{name="everness:coral_forest_deep_ocean_coral_2", prob=126, param2=0},
		{name="air", prob=0, param2=0},
		{name="air", prob=0, param2=0},
		{name="everness:coral_forest_deep_ocean_coral_2", prob=126, param2=0},
		{name="everness:coral_desert_stone", prob=254, param2=0},
		{name="everness:coral_desert_stone", prob=254, param2=0},
		{name="everness:coral_desert_stone", prob=254, param2=0},
		{name="everness:coral_desert_stone", prob=254, param2=0},
		{name="everness:coral_desert_stone", prob=254, param2=0},
		{name="everness:coral_forest_deep_ocean_coral_2", prob=126, param2=0},
		{name="air", prob=0, param2=0},
		{name="everness:coral_forest_deep_ocean_coral_2", prob=254, param2=0},
		{name="everness:coral_skeleton", prob=254, param2=0},
		{name="everness:coral_skeleton", prob=254, param2=0},
		{name="everness:coral_skeleton", prob=254, param2=0},
		{name="everness:coral_forest_deep_ocean_coral_2", prob=254, param2=0},
		{name="air", prob=0, param2=0},
		{name="air", prob=0, param2=0},
		{name="everness:coral_forest_deep_ocean_coral_2", prob=126, param2=0},
		{name="everness:coral_forest_deep_ocean_coral_2", prob=254, param2=0},
		{name="everness:coral_skeleton", prob=254, param2=0},
		{name="everness:coral_forest_deep_ocean_coral_2", prob=254, param2=0},
		{name="everness:coral_forest_deep_ocean_coral_2", prob=126, param2=0},
		{name="air", prob=0, param2=0},
		{name="air", prob=0, param2=0},
		{name="air", prob=0, param2=0},
		{name="everness:coral_forest_deep_ocean_coral_2", prob=254, param2=0},
		{name="everness:coral_forest_deep_ocean_coral_2", prob=254, param2=0},
		{name="everness:coral_forest_deep_ocean_coral_2", prob=254, param2=0},
		{name="air", prob=0, param2=0},
		{name="air", prob=0, param2=0},
		{name="air", prob=0, param2=0},
		{name="air", prob=0, param2=0},
		{name="everness:coral_forest_deep_ocean_coral_2", prob=126, param2=0},
		{name="everness:coral_forest_deep_ocean_coral_2", prob=126, param2=0},
		{name="everness:coral_forest_deep_ocean_coral_2", prob=126, param2=0},
		{name="air", prob=0, param2=0},
		{name="air", prob=0, param2=0},
		{name="everness:coral_forest_deep_ocean_coral_2", prob=126, param2=0},
		{name="everness:coral_desert_stone", prob=254, param2=0},
		{name="everness:coral_desert_stone", prob=254, param2=0},
		{name="everness:coral_desert_stone", prob=254, param2=0},
		{name="everness:coral_desert_stone", prob=254, param2=0},
		{name="everness:coral_desert_stone", prob=254, param2=0},
		{name="everness:coral_forest_deep_ocean_coral_2", prob=126, param2=0},
		{name="air", prob=0, param2=0},
		{name="everness:coral_forest_deep_ocean_coral_2", prob=254, param2=0},
		{name="everness:coral_skeleton", prob=254, param2=0},
		{name="everness:coral_skeleton", prob=254, param2=0},
		{name="everness:coral_skeleton", prob=254, param2=0},
		{name="everness:coral_forest_deep_ocean_coral_2", prob=254, param2=0},
		{name="air", prob=0, param2=0},
		{name="air", prob=0, param2=0},
		{name="everness:coral_forest_deep_ocean_coral_2", prob=126, param2=0},
		{name="everness:coral_forest_deep_ocean_coral_2", prob=254, param2=0},
		{name="everness:coral_forest_deep_ocean_coral_2", prob=254, param2=0},
		{name="everness:coral_forest_deep_ocean_coral_2", prob=254, param2=0},
		{name="everness:coral_forest_deep_ocean_coral_2", prob=126, param2=0},
		{name="air", prob=0, param2=0},
		{name="air", prob=0, param2=0},
		{name="air", prob=0, param2=0},
		{name="everness:coral_forest_deep_ocean_coral_2", prob=254, param2=0},
		{name="everness:coral_forest_deep_ocean_coral_2", prob=254, param2=0},
		{name="everness:coral_forest_deep_ocean_coral_2", prob=254, param2=0},
		{name="air", prob=0, param2=0},
		{name="air", prob=0, param2=0},
		{name="air", prob=0, param2=0},
		{name="air", prob=0, param2=0},
		{name="everness:coral_forest_deep_ocean_coral_2", prob=126, param2=0},
		{name="everness:coral_forest_deep_ocean_coral_2", prob=126, param2=0},
		{name="everness:coral_forest_deep_ocean_coral_2", prob=126, param2=0},
		{name="air", prob=0, param2=0},
		{name="air", prob=0, param2=0},
		{name="everness:coral_forest_deep_ocean_coral_2", prob=126, param2=0},
		{name="everness:coral_desert_stone", prob=254, param2=0},
		{name="everness:coral_desert_stone", prob=254, param2=0},
		{name="everness:coral_desert_stone", prob=254, param2=0},
		{name="everness:coral_desert_stone", prob=254, param2=0},
		{name="everness:coral_desert_stone", prob=254, param2=0},
		{name="everness:coral_forest_deep_ocean_coral_2", prob=126, param2=0},
		{name="air", prob=0, param2=0},
		{name="everness:coral_forest_deep_ocean_coral_2", prob=254, param2=0},
		{name="everness:coral_forest_deep_ocean_coral_2", prob=254, param2=0},
		{name="everness:coral_forest_deep_ocean_coral_2", prob=254, param2=0},
		{name="everness:coral_forest_deep_ocean_coral_2", prob=254, param2=0},
		{name="everness:coral_forest_deep_ocean_coral_2", prob=254, param2=0},
		{name="air", prob=0, param2=0},
		{name="air", prob=0, param2=0},
		{name="everness:coral_forest_deep_ocean_coral_2", prob=254, param2=0},
		{name="everness:coral_forest_deep_ocean_coral_2", prob=126, param2=0},
		{name="everness:coral_forest_deep_ocean_coral_2", prob=126, param2=0},
		{name="everness:coral_forest_deep_ocean_coral_2", prob=126, param2=0},
		{name="everness:coral_forest_deep_ocean_coral_2", prob=126, param2=0},
		{name="air", prob=0, param2=0},
		{name="air", prob=0, param2=0},
		{name="air", prob=0, param2=0},
		{name="air", prob=0, param2=0},
		{name="air", prob=0, param2=0},
		{name="air", prob=0, param2=0},
		{name="air", prob=0, param2=0},
		{name="air", prob=0, param2=0},
		{name="air", prob=0, param2=0},
		{name="air", prob=0, param2=0},
		{name="air", prob=0, param2=0},
		{name="air", prob=0, param2=0},
		{name="air", prob=0, param2=0},
		{name="air", prob=0, param2=0},
		{name="air", prob=0, param2=0},
		{name="everness:coral_forest_deep_ocean_coral_2", prob=126, param2=0},
		{name="everness:coral_forest_deep_ocean_coral_2", prob=126, param2=0},
		{name="everness:coral_forest_deep_ocean_coral_2", prob=126, param2=0},
		{name="everness:coral_forest_deep_ocean_coral_2", prob=126, param2=0},
		{name="everness:coral_forest_deep_ocean_coral_2", prob=126, param2=0},
		{name="everness:coral_forest_deep_ocean_coral_2", prob=126, param2=0},
		{name="everness:coral_forest_deep_ocean_coral_2", prob=126, param2=0},
		{name="air", prob=0, param2=0},
		{name="air", prob=0, param2=0},
		{name="air", prob=0, param2=0},
		{name="air", prob=0, param2=0},
		{name="air", prob=0, param2=0},
		{name="air", prob=0, param2=0},
		{name="air", prob=0, param2=0},
		{name="air", prob=0, param2=0},
		{name="air", prob=0, param2=0},
		{name="air", prob=0, param2=0},
		{name="air", prob=0, param2=0},
		{name="air", prob=0, param2=0},
		{name="air", prob=0, param2=0},
		{name="air", prob=0, param2=0},
		{name="air", prob=0, param2=0},
		{name="air", prob=0, param2=0},
		{name="air", prob=0, param2=0},
		{name="air", prob=0, param2=0},
		{name="air", prob=0, param2=0},
		{name="air", prob=0, param2=0},
		{name="air", prob=0, param2=0},
		{name="air", prob=0, param2=0},
		{name="air", prob=0, param2=0},
		{name="air", prob=0, param2=0},
		{name="air", prob=0, param2=0},
		{name="air", prob=0, param2=0},
		{name="air", prob=0, param2=0},
		{name="air", prob=0, param2=0},
	},
}
