schematic = {
	size = {x=8, y=4, z=8},
	yslice_prob = {
		{ypos=0, prob=254},
		{ypos=1, prob=254},
		{ypos=2, prob=254},
		{ypos=3, prob=254},
	},
	data = {
		{name="everness:dirt_with_cursed_grass", prob=254, param2=0},
		{name="everness:dirt_with_cursed_grass", prob=254, param2=0},
		{name="everness:dirt_with_cursed_grass", prob=254, param2=0},
		{name="everness:dirt_with_cursed_grass", prob=254, param2=0},
		{name="everness:dirt_with_cursed_grass", prob=254, param2=0},
		{name="everness:dirt_with_cursed_grass", prob=254, param2=0},
		{name="everness:dirt_with_cursed_grass", prob=254, param2=0},
		{name="everness:dirt_with_cursed_grass", prob=254, param2=0},
		{name="air", prob=254, param2=0},
		{name="air", prob=254, param2=0},
		{name="air", prob=254, param2=0},
		{name="air", prob=254, param2=0},
		{name="air", prob=254, param2=0},
		{name="air", prob=254, param2=0},
		{name="air", prob=254, param2=0},
		{name="air", prob=254, param2=0},
		{name="air", prob=254, param2=0},
		{name="air", prob=254, param2=0},
		{name="air", prob=254, param2=0},
		{name="air", prob=254, param2=0},
		{name="air", prob=254, param2=0},
		{name="air", prob=254, param2=0},
		{name="air", prob=254, param2=0},
		{name="air", prob=254, param2=0},
		{name="air", prob=254, param2=0},
		{name="air", prob=254, param2=0},
		{name="air", prob=254, param2=0},
		{name="air", prob=254, param2=0},
		{name="air", prob=254, param2=0},
		{name="air", prob=254, param2=0},
		{name="air", prob=254, param2=0},
		{name="air", prob=254, param2=0},
		{name="everness:dirt_with_cursed_grass", prob=254, param2=0},
		{name="everness:dirt_with_cursed_grass", prob=254, param2=0},
		{name="everness:dirt_with_cursed_grass", prob=254, param2=0},
		{name="everness:dirt_with_cursed_grass", prob=254, param2=0},
		{name="everness:dirt_with_cursed_grass", prob=254, param2=0},
		{name="everness:dirt_with_cursed_grass", prob=254, param2=0},
		{name="everness:dirt_with_cursed_grass", prob=254, param2=0},
		{name="everness:dirt_with_cursed_grass", prob=254, param2=0},
		{name="air", prob=254, param2=0},
		{name="air", prob=254, param2=0},
		{name="air", prob=254, param2=0},
		{name="air", prob=254, param2=0},
		{name="everness:fence_dry_wood", prob=254, param2=0},
		{name="everness:fence_dry_wood", prob=254, param2=0},
		{name="everness:fence_dry_wood", prob=254, param2=0},
		{name="everness:fence_dry_wood", prob=254, param2=0},
		{name="air", prob=254, param2=0},
		{name="air", prob=254, param2=0},
		{name="air", prob=254, param2=0},
		{name="air", prob=254, param2=0},
		{name="air", prob=254, param2=0},
		{name="air", prob=254, param2=0},
		{name="air", prob=254, param2=0},
		{name="air", prob=254, param2=0},
		{name="air", prob=254, param2=0},
		{name="air", prob=254, param2=0},
		{name="air", prob=254, param2=0},
		{name="air", prob=254, param2=0},
		{name="air", prob=254, param2=0},
		{name="air", prob=254, param2=0},
		{name="air", prob=254, param2=0},
		{name="air", prob=254, param2=0},
		{name="everness:dirt_with_cursed_grass", prob=254, param2=0},
		{name="everness:dirt_with_cursed_grass", prob=254, param2=0},
		{name="everness:dirt_with_cursed_grass", prob=254, param2=0},
		{name="everness:dirt_with_cursed_grass", prob=254, param2=0},
		{name="everness:dirt_with_cursed_grass", prob=254, param2=0},
		{name="everness:dirt_with_cursed_grass", prob=254, param2=0},
		{name="everness:dirt_with_cursed_grass", prob=254, param2=0},
		{name="everness:dirt_with_cursed_grass", prob=254, param2=0},
		{name="air", prob=254, param2=0},
		{name="air", prob=254, param2=0},
		{name="air", prob=254, param2=0},
		{name="air", prob=254, param2=0},
		{name="air", prob=254, param2=0},
		{name="air", prob=254, param2=0},
		{name="air", prob=254, param2=0},
		{name="everness:fence_dry_wood", prob=254, param2=0},
		{name="air", prob=254, param2=0},
		{name="air", prob=254, param2=0},
		{name="air", prob=254, param2=0},
		{name="air", prob=254, param2=0},
		{name="air", prob=254, param2=0},
		{name="air", prob=254, param2=0},
		{name="air", prob=254, param2=0},
		{name="air", prob=254, param2=0},
		{name="air", prob=254, param2=0},
		{name="air", prob=254, param2=0},
		{name="air", prob=254, param2=0},
		{name="air", prob=254, param2=0},
		{name="air", prob=254, param2=0},
		{name="air", prob=254, param2=0},
		{name="air", prob=254, param2=0},
		{name="air", prob=254, param2=0},
		{name="everness:dirt_with_cursed_grass", prob=254, param2=0},
		{name="everness:dirt_with_cursed_grass", prob=254, param2=0},
		{name="everness:dirt_with_cursed_grass", prob=254, param2=0},
		{name="everness:dirt_with_cursed_grass", prob=254, param2=0},
		{name="everness:dirt_with_cursed_grass", prob=254, param2=0},
		{name="everness:dirt_with_cursed_grass", prob=254, param2=0},
		{name="everness:dirt_with_cursed_grass", prob=254, param2=0},
		{name="everness:dirt_with_cursed_grass", prob=254, param2=0},
		{name="xpanes:cursed_bar", prob=254, param2=0},
		{name="xpanes:cursed_bar_flat", prob=254, param2=0},
		{name="xpanes:cursed_bar", prob=254, param2=0},
		{name="air", prob=254, param2=0},
		{name="everness:fence_dry_wood", prob=254, param2=0},
		{name="stairs:slab_cursed_lands_deep_ocean_sandstone_block", prob=254, param2=0},
		{name="stairs:slab_cursed_lands_deep_ocean_sandstone_block", prob=254, param2=2},
		{name="everness:fence_dry_wood", prob=254, param2=0},
		{name="air", prob=254, param2=0},
		{name="air", prob=254, param2=0},
		{name="air", prob=254, param2=0},
		{name="air", prob=254, param2=0},
		{name="air", prob=254, param2=0},
		{name="air", prob=254, param2=0},
		{name="air", prob=254, param2=0},
		{name="air", prob=254, param2=0},
		{name="air", prob=254, param2=0},
		{name="air", prob=254, param2=0},
		{name="air", prob=254, param2=0},
		{name="air", prob=254, param2=0},
		{name="air", prob=254, param2=0},
		{name="air", prob=254, param2=0},
		{name="air", prob=254, param2=0},
		{name="air", prob=254, param2=0},
		{name="everness:dirt_with_cursed_grass", prob=254, param2=0},
		{name="everness:dirt_with_cursed_grass", prob=254, param2=0},
		{name="everness:dirt_with_cursed_grass", prob=254, param2=0},
		{name="everness:dirt_with_cursed_grass", prob=254, param2=0},
		{name="everness:dirt_with_cursed_grass", prob=254, param2=0},
		{name="everness:dirt_with_cursed_grass", prob=254, param2=0},
		{name="everness:dirt_with_cursed_grass", prob=254, param2=0},
		{name="everness:dirt_with_cursed_grass", prob=254, param2=0},
		{name="xpanes:cursed_bar_flat", prob=254, param2=3},
		{name="everness:skull_with_candle", prob=254, param2=3},
		{name="xpanes:cursed_bar_flat", prob=254, param2=3},
		{name="air", prob=254, param2=0},
		{name="everness:fence_dry_wood", prob=254, param2=0},
		{name="everness:fence_dry_wood", prob=254, param2=0},
		{name="everness:fence_dry_wood", prob=254, param2=0},
		{name="everness:fence_dry_wood", prob=254, param2=0},
		{name="air", prob=254, param2=0},
		{name="air", prob=254, param2=0},
		{name="air", prob=254, param2=0},
		{name="air", prob=254, param2=0},
		{name="air", prob=254, param2=0},
		{name="air", prob=254, param2=0},
		{name="air", prob=254, param2=0},
		{name="air", prob=254, param2=0},
		{name="air", prob=254, param2=0},
		{name="air", prob=254, param2=0},
		{name="air", prob=254, param2=0},
		{name="air", prob=254, param2=0},
		{name="air", prob=254, param2=0},
		{name="air", prob=254, param2=0},
		{name="air", prob=254, param2=0},
		{name="air", prob=254, param2=0},
		{name="everness:dirt_with_cursed_grass", prob=254, param2=0},
		{name="everness:dirt_with_cursed_grass", prob=254, param2=0},
		{name="everness:dirt_with_cursed_grass", prob=254, param2=0},
		{name="everness:dirt_with_cursed_grass", prob=254, param2=0},
		{name="everness:dirt_with_cursed_grass", prob=254, param2=0},
		{name="everness:dirt_with_cursed_grass", prob=254, param2=0},
		{name="everness:dirt_with_cursed_grass", prob=254, param2=0},
		{name="everness:dirt_with_cursed_grass", prob=254, param2=0},
		{name="xpanes:cursed_bar", prob=254, param2=0},
		{name="xpanes:cursed_bar_flat", prob=254, param2=0},
		{name="xpanes:cursed_bar", prob=254, param2=0},
		{name="air", prob=254, param2=0},
		{name="air", prob=254, param2=0},
		{name="air", prob=254, param2=0},
		{name="air", prob=254, param2=0},
		{name="air", prob=254, param2=0},
		{name="air", prob=254, param2=0},
		{name="air", prob=254, param2=0},
		{name="air", prob=254, param2=0},
		{name="air", prob=254, param2=0},
		{name="air", prob=254, param2=0},
		{name="air", prob=254, param2=0},
		{name="air", prob=254, param2=0},
		{name="air", prob=254, param2=0},
		{name="air", prob=254, param2=0},
		{name="air", prob=254, param2=0},
		{name="air", prob=254, param2=0},
		{name="air", prob=254, param2=0},
		{name="air", prob=254, param2=0},
		{name="air", prob=254, param2=0},
		{name="air", prob=254, param2=0},
		{name="air", prob=254, param2=0},
		{name="everness:dirt_with_cursed_grass", prob=254, param2=0},
		{name="everness:dirt_with_cursed_grass", prob=254, param2=0},
		{name="everness:dirt_with_cursed_grass", prob=254, param2=0},
		{name="everness:dirt_with_cursed_grass", prob=254, param2=0},
		{name="everness:dirt_with_cursed_grass", prob=254, param2=0},
		{name="everness:dirt_with_cursed_grass", prob=254, param2=0},
		{name="everness:dirt_with_cursed_grass", prob=254, param2=0},
		{name="everness:dirt_with_cursed_grass", prob=254, param2=0},
		{name="air", prob=254, param2=0},
		{name="air", prob=254, param2=0},
		{name="air", prob=254, param2=0},
		{name="air", prob=254, param2=0},
		{name="air", prob=254, param2=0},
		{name="air", prob=254, param2=0},
		{name="air", prob=254, param2=0},
		{name="air", prob=254, param2=0},
		{name="air", prob=254, param2=0},
		{name="air", prob=254, param2=0},
		{name="air", prob=254, param2=0},
		{name="air", prob=254, param2=0},
		{name="air", prob=254, param2=0},
		{name="air", prob=254, param2=0},
		{name="air", prob=254, param2=0},
		{name="air", prob=254, param2=0},
		{name="air", prob=254, param2=0},
		{name="air", prob=254, param2=0},
		{name="air", prob=254, param2=0},
		{name="air", prob=254, param2=0},
		{name="air", prob=254, param2=0},
		{name="air", prob=254, param2=0},
		{name="air", prob=254, param2=0},
		{name="air", prob=254, param2=0},
		{name="everness:dirt_with_cursed_grass", prob=254, param2=0},
		{name="everness:dirt_with_cursed_grass", prob=254, param2=0},
		{name="everness:dirt_with_cursed_grass", prob=254, param2=0},
		{name="everness:dirt_with_cursed_grass", prob=254, param2=0},
		{name="everness:dirt_with_cursed_grass", prob=254, param2=0},
		{name="everness:dirt_with_cursed_grass", prob=254, param2=0},
		{name="everness:dirt_with_cursed_grass", prob=254, param2=0},
		{name="everness:dirt_with_cursed_grass", prob=254, param2=0},
		{name="air", prob=254, param2=0},
		{name="air", prob=254, param2=0},
		{name="air", prob=254, param2=0},
		{name="air", prob=254, param2=0},
		{name="air", prob=254, param2=0},
		{name="air", prob=254, param2=0},
		{name="air", prob=254, param2=0},
		{name="air", prob=254, param2=0},
		{name="air", prob=254, param2=0},
		{name="air", prob=254, param2=0},
		{name="air", prob=254, param2=0},
		{name="air", prob=254, param2=0},
		{name="air", prob=254, param2=0},
		{name="air", prob=254, param2=0},
		{name="air", prob=254, param2=0},
		{name="air", prob=254, param2=0},
		{name="air", prob=254, param2=0},
		{name="air", prob=254, param2=0},
		{name="air", prob=254, param2=0},
		{name="air", prob=254, param2=0},
		{name="air", prob=254, param2=0},
		{name="air", prob=254, param2=0},
		{name="air", prob=254, param2=0},
		{name="air", prob=254, param2=0},
	},
}
