schematic = {
	size = {x=17, y=17, z=17},
	yslice_prob = {
		{ypos=0, prob=254},
		{ypos=1, prob=254},
		{ypos=2, prob=254},
		{ypos=3, prob=254},
		{ypos=4, prob=254},
		{ypos=5, prob=254},
		{ypos=6, prob=254},
		{ypos=7, prob=254},
		{ypos=8, prob=254},
		{ypos=9, prob=254},
		{ypos=10, prob=254},
		{ypos=11, prob=254},
		{ypos=12, prob=254},
		{ypos=13, prob=254},
		{ypos=14, prob=254},
		{ypos=15, prob=254},
		{ypos=16, prob=254},
	},
	data = {
		{name="air", prob=0, param2=0},
		{name="air", prob=0, param2=0},
		{name="air", prob=0, param2=0},
		{name="air", prob=0, param2=0},
		{name="air", prob=0, param2=0},
		{name="air", prob=0, param2=0},
		{name="air", prob=0, param2=0},
		{name="air", prob=0, param2=0},
		{name="air", prob=0, param2=0},
		{name="air", prob=0, param2=0},
		{name="air", prob=0, param2=0},
		{name="air", prob=0, param2=0},
		{name="air", prob=0, param2=0},
		{name="air", prob=0, param2=0},
		{name="air", prob=0, param2=0},
		{name="air", prob=0, param2=0},
		{name="air", prob=0, param2=0},
		{name="air", prob=0, param2=0},
		{name="air", prob=0, param2=0},
		{name="air", prob=0, param2=0},
		{name="air", prob=0, param2=0},
		{name="air", prob=0, param2=0},
		{name="air", prob=0, param2=0},
		{name="air", prob=0, param2=0},
		{name="air", prob=0, param2=0},
		{name="air", prob=0, param2=0},
		{name="air", prob=0, param2=0},
		{name="air", prob=0, param2=0},
		{name="air", prob=0, param2=0},
		{name="air", prob=0, param2=0},
		{name="air", prob=0, param2=0},
		{name="air", prob=0, param2=0},
		{name="air", prob=0, param2=0},
		{name="air", prob=0, param2=0},
		{name="air", prob=0, param2=0},
		{name="air", prob=0, param2=0},
		{name="air", prob=0, param2=0},
		{name="air", prob=0, param2=0},
		{name="air", prob=0, param2=0},
		{name="air", prob=0, param2=0},
		{name="air", prob=0, param2=0},
		{name="air", prob=0, param2=0},
		{name="air", prob=0, param2=0},
		{name="air", prob=0, param2=0},
		{name="air", prob=0, param2=0},
		{name="air", prob=0, param2=0},
		{name="air", prob=0, param2=0},
		{name="air", prob=0, param2=0},
		{name="air", prob=0, param2=0},
		{name="air", prob=0, param2=0},
		{name="air", prob=0, param2=0},
		{name="air", prob=0, param2=0},
		{name="air", prob=0, param2=0},
		{name="air", prob=0, param2=0},
		{name="air", prob=0, param2=0},
		{name="air", prob=0, param2=0},
		{name="air", prob=0, param2=0},
		{name="air", prob=0, param2=0},
		{name="air", prob=0, param2=0},
		{name="air", prob=0, param2=0},
		{name="air", prob=0, param2=0},
		{name="air", prob=0, param2=0},
		{name="air", prob=0, param2=0},
		{name="air", prob=0, param2=0},
		{name="air", prob=0, param2=0},
		{name="air", prob=0, param2=0},
		{name="air", prob=0, param2=0},
		{name="air", prob=0, param2=0},
		{name="air", prob=0, param2=0},
		{name="air", prob=0, param2=0},
		{name="air", prob=0, param2=0},
		{name="air", prob=0, param2=0},
		{name="air", prob=0, param2=0},
		{name="air", prob=0, param2=0},
		{name="air", prob=0, param2=0},
		{name="air", prob=0, param2=0},
		{name="air", prob=0, param2=0},
		{name="air", prob=0, param2=0},
		{name="air", prob=0, param2=0},
		{name="air", prob=0, param2=0},
		{name="air", prob=0, param2=0},
		{name="air", prob=0, param2=0},
		{name="air", prob=0, param2=0},
		{name="air", prob=0, param2=0},
		{name="air", prob=0, param2=0},
		{name="air", prob=0, param2=0},
		{name="air", prob=0, param2=0},
		{name="air", prob=0, param2=0},
		{name="air", prob=0, param2=0},
		{name="air", prob=0, param2=0},
		{name="air", prob=0, param2=0},
		{name="air", prob=0, param2=0},
		{name="air", prob=0, param2=0},
		{name="air", prob=0, param2=0},
		{name="air", prob=0, param2=0},
		{name="air", prob=0, param2=0},
		{name="air", prob=0, param2=0},
		{name="air", prob=0, param2=0},
		{name="air", prob=0, param2=0},
		{name="air", prob=0, param2=0},
		{name="air", prob=0, param2=0},
		{name="air", prob=0, param2=0},
		{name="air", prob=0, param2=0},
		{name="air", prob=0, param2=0},
		{name="air", prob=0, param2=0},
		{name="air", prob=0, param2=0},
		{name="air", prob=0, param2=0},
		{name="air", prob=0, param2=0},
		{name="air", prob=0, param2=0},
		{name="air", prob=0, param2=0},
		{name="air", prob=0, param2=0},
		{name="air", prob=0, param2=0},
		{name="air", prob=0, param2=0},
		{name="air", prob=0, param2=0},
		{name="air", prob=0, param2=0},
		{name="air", prob=0, param2=0},
		{name="air", prob=0, param2=0},
		{name="air", prob=0, param2=0},
		{name="air", prob=0, param2=0},
		{name="air", prob=0, param2=0},
		{name="air", prob=0, param2=0},
		{name="air", prob=0, param2=0},
		{name="air", prob=0, param2=0},
		{name="everness:frosted_snowblock", prob=254, param2=0},
		{name="everness:frosted_snowblock", prob=254, param2=0},
		{name="everness:frosted_snowblock", prob=254, param2=0},
		{name="everness:frosted_snowblock", prob=254, param2=0},
		{name="everness:frosted_snowblock", prob=254, param2=0},
		{name="everness:frosted_snowblock", prob=254, param2=0},
		{name="everness:frosted_snowblock", prob=254, param2=0},
		{name="everness:frosted_snowblock", prob=254, param2=0},
		{name="everness:frosted_snowblock", prob=254, param2=0},
		{name="air", prob=0, param2=0},
		{name="air", prob=0, param2=0},
		{name="air", prob=0, param2=0},
		{name="air", prob=0, param2=0},
		{name="air", prob=0, param2=0},
		{name="air", prob=0, param2=0},
		{name="air", prob=0, param2=0},
		{name="air", prob=0, param2=0},
		{name="everness:frosted_snowblock", prob=254, param2=0},
		{name="everness:frosted_snowblock", prob=254, param2=0},
		{name="everness:frosted_snowblock", prob=254, param2=0},
		{name="everness:frosted_snowblock", prob=254, param2=0},
		{name="everness:frosted_snowblock", prob=254, param2=0},
		{name="everness:frosted_snowblock", prob=254, param2=0},
		{name="everness:frosted_snowblock", prob=254, param2=0},
		{name="everness:frosted_snowblock", prob=254, param2=0},
		{name="everness:frosted_snowblock", prob=254, param2=0},
		{name="air", prob=0, param2=0},
		{name="air", prob=0, param2=0},
		{name="air", prob=0, param2=0},
		{name="air", prob=0, param2=0},
		{name="air", prob=0, param2=0},
		{name="air", prob=0, param2=0},
		{name="air", prob=0, param2=0},
		{name="air", prob=0, param2=0},
		{name="air", prob=0, param2=0},
		{name="air", prob=0, param2=0},
		{name="air", prob=0, param2=0},
		{name="air", prob=0, param2=0},
		{name="air", prob=254, param2=0},
		{name="air", prob=0, param2=0},
		{name="air", prob=0, param2=0},
		{name="air", prob=0, param2=0},
		{name="air", prob=0, param2=0},
		{name="air", prob=0, param2=0},
		{name="air", prob=0, param2=0},
		{name="air", prob=0, param2=0},
		{name="air", prob=0, param2=0},
		{name="air", prob=0, param2=0},
		{name="air", prob=0, param2=0},
		{name="air", prob=0, param2=0},
		{name="air", prob=0, param2=0},
		{name="air", prob=0, param2=0},
		{name="air", prob=0, param2=0},
		{name="air", prob=0, param2=0},
		{name="air", prob=0, param2=0},
		{name="air", prob=254, param2=0},
		{name="air", prob=0, param2=0},
		{name="air", prob=0, param2=0},
		{name="air", prob=0, param2=0},
		{name="air", prob=0, param2=0},
		{name="air", prob=0, param2=0},
		{name="air", prob=0, param2=0},
		{name="air", prob=0, param2=0},
		{name="air", prob=0, param2=0},
		{name="air", prob=0, param2=0},
		{name="air", prob=0, param2=0},
		{name="air", prob=0, param2=0},
		{name="air", prob=0, param2=0},
		{name="air", prob=0, param2=0},
		{name="air", prob=0, param2=0},
		{name="air", prob=0, param2=0},
		{name="air", prob=0, param2=0},
		{name="air", prob=0, param2=0},
		{name="air", prob=0, param2=0},
		{name="air", prob=0, param2=0},
		{name="air", prob=0, param2=0},
		{name="air", prob=0, param2=0},
		{name="air", prob=0, param2=0},
		{name="air", prob=0, param2=0},
		{name="air", prob=0, param2=0},
		{name="air", prob=0, param2=0},
		{name="air", prob=0, param2=0},
		{name="air", prob=0, param2=0},
		{name="air", prob=0, param2=0},
		{name="air", prob=0, param2=0},
		{name="air", prob=0, param2=0},
		{name="air", prob=0, param2=0},
		{name="air", prob=0, param2=0},
		{name="air", prob=0, param2=0},
		{name="air", prob=0, param2=0},
		{name="air", prob=0, param2=0},
		{name="air", prob=0, param2=0},
		{name="air", prob=0, param2=0},
		{name="air", prob=0, param2=0},
		{name="air", prob=0, param2=0},
		{name="air", prob=0, param2=0},
		{name="air", prob=0, param2=0},
		{name="air", prob=0, param2=0},
		{name="air", prob=0, param2=0},
		{name="air", prob=0, param2=0},
		{name="air", prob=0, param2=0},
		{name="air", prob=0, param2=0},
		{name="air", prob=0, param2=0},
		{name="air", prob=0, param2=0},
		{name="air", prob=0, param2=0},
		{name="air", prob=0, param2=0},
		{name="air", prob=0, param2=0},
		{name="air", prob=0, param2=0},
		{name="air", prob=0, param2=0},
		{name="air", prob=0, param2=0},
		{name="air", prob=0, param2=0},
		{name="air", prob=0, param2=0},
		{name="air", prob=0, param2=0},
		{name="air", prob=0, param2=0},
		{name="air", prob=0, param2=0},
		{name="air", prob=0, param2=0},
		{name="air", prob=0, param2=0},
		{name="air", prob=0, param2=0},
		{name="air", prob=0, param2=0},
		{name="air", prob=0, param2=0},
		{name="air", prob=0, param2=0},
		{name="air", prob=0, param2=0},
		{name="air", prob=0, param2=0},
		{name="air", prob=0, param2=0},
		{name="air", prob=0, param2=0},
		{name="air", prob=0, param2=0},
		{name="air", prob=0, param2=0},
		{name="air", prob=0, param2=0},
		{name="air", prob=0, param2=0},
		{name="air", prob=0, param2=0},
		{name="air", prob=0, param2=0},
		{name="air", prob=0, param2=0},
		{name="air", prob=0, param2=0},
		{name="air", prob=0, param2=0},
		{name="air", prob=0, param2=0},
		{name="air", prob=0, param2=0},
		{name="air", prob=0, param2=0},
		{name="air", prob=0, param2=0},
		{name="air", prob=0, param2=0},
		{name="air", prob=0, param2=0},
		{name="air", prob=0, param2=0},
		{name="air", prob=0, param2=0},
		{name="air", prob=0, param2=0},
		{name="air", prob=0, param2=0},
		{name="air", prob=0, param2=0},
		{name="air", prob=0, param2=0},
		{name="air", prob=0, param2=0},
		{name="air", prob=0, param2=0},
		{name="air", prob=0, param2=0},
		{name="air", prob=0, param2=0},
		{name="air", prob=0, param2=0},
		{name="air", prob=0, param2=0},
		{name="air", prob=0, param2=0},
		{name="air", prob=0, param2=0},
		{name="air", prob=0, param2=0},
		{name="air", prob=0, param2=0},
		{name="air", prob=0, param2=0},
		{name="air", prob=0, param2=0},
		{name="air", prob=0, param2=0},
		{name="air", prob=0, param2=0},
		{name="air", prob=0, param2=0},
		{name="air", prob=0, param2=0},
		{name="air", prob=0, param2=0},
		{name="air", prob=0, param2=0},
		{name="air", prob=0, param2=0},
		{name="air", prob=0, param2=0},
		{name="air", prob=0, param2=0},
		{name="air", prob=0, param2=0},
		{name="air", prob=0, param2=0},
		{name="air", prob=0, param2=0},
		{name="air", prob=0, param2=0},
		{name="air", prob=0, param2=0},
		{name="air", prob=0, param2=0},
		{name="air", prob=0, param2=0},
		{name="air", prob=0, param2=0},
		{name="air", prob=0, param2=0},
		{name="air", prob=0, param2=0},
		{name="air", prob=0, param2=0},
		{name="air", prob=0, param2=0},
		{name="air", prob=0, param2=0},
		{name="air", prob=0, param2=0},
		{name="air", prob=0, param2=0},
		{name="air", prob=0, param2=0},
		{name="air", prob=0, param2=0},
		{name="air", prob=0, param2=0},
		{name="air", prob=0, param2=0},
		{name="air", prob=0, param2=0},
		{name="air", prob=0, param2=0},
		{name="air", prob=0, param2=0},
		{name="air", prob=0, param2=0},
		{name="air", prob=0, param2=0},
		{name="air", prob=0, param2=0},
		{name="air", prob=0, param2=0},
		{name="air", prob=0, param2=0},
		{name="air", prob=0, param2=0},
		{name="air", prob=0, param2=0},
		{name="air", prob=0, param2=0},
		{name="air", prob=0, param2=0},
		{name="air", prob=0, param2=0},
		{name="air", prob=0, param2=0},
		{name="air", prob=0, param2=0},
		{name="air", prob=0, param2=0},
		{name="air", prob=0, param2=0},
		{name="air", prob=0, param2=0},
		{name="air", prob=0, param2=0},
		{name="air", prob=0, param2=0},
		{name="air", prob=0, param2=0},
		{name="air", prob=0, param2=0},
		{name="air", prob=0, param2=0},
		{name="air", prob=0, param2=0},
		{name="air", prob=0, param2=0},
		{name="air", prob=0, param2=0},
		{name="air", prob=0, param2=0},
		{name="air", prob=0, param2=0},
		{name="air", prob=0, param2=0},
		{name="air", prob=0, param2=0},
		{name="air", prob=0, param2=0},
		{name="air", prob=0, param2=0},
		{name="air", prob=0, param2=0},
		{name="air", prob=0, param2=0},
		{name="air", prob=0, param2=0},
		{name="air", prob=0, param2=0},
		{name="air", prob=0, param2=0},
		{name="air", prob=0, param2=0},
		{name="air", prob=0, param2=0},
		{name="air", prob=0, param2=0},
		{name="air", prob=0, param2=0},
		{name="air", prob=0, param2=0},
		{name="air", prob=0, param2=0},
		{name="air", prob=0, param2=0},
		{name="air", prob=0, param2=0},
		{name="air", prob=0, param2=0},
		{name="air", prob=0, param2=0},
		{name="air", prob=0, param2=0},
		{name="air", prob=0, param2=0},
		{name="air", prob=0, param2=0},
		{name="air", prob=0, param2=0},
		{name="air", prob=0, param2=0},
		{name="air", prob=0, param2=0},
		{name="air", prob=0, param2=0},
		{name="air", prob=0, param2=0},
		{name="air", prob=0, param2=0},
		{name="air", prob=0, param2=0},
		{name="air", prob=0, param2=0},
		{name="air", prob=0, param2=0},
		{name="air", prob=0, param2=0},
		{name="air", prob=0, param2=0},
		{name="air", prob=0, param2=0},
		{name="air", prob=0, param2=0},
		{name="air", prob=0, param2=0},
		{name="air", prob=0, param2=0},
		{name="air", prob=0, param2=0},
		{name="air", prob=0, param2=0},
		{name="air", prob=0, param2=0},
		{name="air", prob=0, param2=0},
		{name="air", prob=0, param2=0},
		{name="air", prob=0, param2=0},
		{name="air", prob=0, param2=0},
		{name="air", prob=0, param2=0},
		{name="air", prob=0, param2=0},
		{name="air", prob=0, param2=0},
		{name="air", prob=0, param2=0},
		{name="air", prob=0, param2=0},
		{name="air", prob=0, param2=0},
		{name="air", prob=0, param2=0},
		{name="air", prob=0, param2=0},
		{name="air", prob=0, param2=0},
		{name="air", prob=0, param2=0},
		{name="air", prob=0, param2=0},
		{name="air", prob=0, param2=0},
		{name="air", prob=0, param2=0},
		{name="air", prob=0, param2=0},
		{name="air", prob=0, param2=0},
		{name="everness:frosted_snowblock", prob=254, param2=0},
		{name="everness:frosted_snowblock", prob=254, param2=0},
		{name="everness:frosted_snowblock", prob=254, param2=0},
		{name="everness:frosted_snowblock", prob=254, param2=0},
		{name="everness:frosted_snowblock", prob=254, param2=0},
		{name="everness:frosted_snowblock", prob=254, param2=0},
		{name="everness:frosted_snowblock", prob=254, param2=0},
		{name="air", prob=0, param2=0},
		{name="air", prob=0, param2=0},
		{name="air", prob=0, param2=0},
		{name="air", prob=0, param2=0},
		{name="air", prob=0, param2=0},
		{name="air", prob=0, param2=0},
		{name="air", prob=0, param2=0},
		{name="air", prob=0, param2=0},
		{name="everness:frosted_snowblock", prob=254, param2=0},
		{name="everness:frosted_snowblock", prob=254, param2=0},
		{name="everness:frosted_snowblock", prob=254, param2=0},
		{name="everness:frosted_snowblock", prob=254, param2=0},
		{name="everness:frosted_snowblock", prob=254, param2=0},
		{name="everness:frosted_snowblock", prob=254, param2=0},
		{name="everness:frosted_snowblock", prob=254, param2=0},
		{name="everness:frosted_snowblock", prob=254, param2=0},
		{name="everness:frosted_snowblock", prob=254, param2=0},
		{name="everness:frosted_snowblock", prob=254, param2=0},
		{name="everness:frosted_snowblock", prob=254, param2=0},
		{name="air", prob=0, param2=0},
		{name="air", prob=0, param2=0},
		{name="air", prob=0, param2=0},
		{name="air", prob=0, param2=0},
		{name="air", prob=0, param2=0},
		{name="air", prob=0, param2=0},
		{name="everness:frosted_snowblock", prob=254, param2=0},
		{name="everness:frosted_snowblock", prob=254, param2=0},
		{name="everness:frosted_snowblock", prob=254, param2=0},
		{name="everness:snowcobble", prob=254, param2=0},
		{name="everness:snowcobble", prob=254, param2=0},
		{name="everness:snowcobble", prob=254, param2=0},
		{name="everness:snowcobble", prob=254, param2=0},
		{name="everness:snowcobble", prob=254, param2=0},
		{name="everness:frosted_snowblock", prob=254, param2=0},
		{name="everness:frosted_snowblock", prob=254, param2=0},
		{name="everness:frosted_snowblock", prob=254, param2=0},
		{name="air", prob=0, param2=0},
		{name="air", prob=0, param2=0},
		{name="air", prob=0, param2=0},
		{name="air", prob=0, param2=0},
		{name="air", prob=0, param2=0},
		{name="air", prob=0, param2=0},
		{name="air", prob=0, param2=0},
		{name="everness:frosted_snowblock", prob=254, param2=0},
		{name="everness:frosted_snowblock", prob=254, param2=0},
		{name="default:pine_tree", prob=254, param2=0},
		{name="air", prob=0, param2=0},
		{name="air", prob=254, param2=0},
		{name="air", prob=0, param2=0},
		{name="default:pine_tree", prob=254, param2=0},
		{name="everness:frosted_snowblock", prob=254, param2=0},
		{name="everness:frosted_snowblock", prob=254, param2=0},
		{name="air", prob=0, param2=0},
		{name="air", prob=0, param2=0},
		{name="air", prob=0, param2=0},
		{name="air", prob=0, param2=0},
		{name="air", prob=0, param2=0},
		{name="air", prob=0, param2=0},
		{name="air", prob=0, param2=0},
		{name="air", prob=0, param2=0},
		{name="air", prob=0, param2=0},
		{name="air", prob=0, param2=0},
		{name="default:pine_tree", prob=254, param2=0},
		{name="air", prob=0, param2=0},
		{name="air", prob=254, param2=0},
		{name="air", prob=0, param2=0},
		{name="default:pine_tree", prob=254, param2=0},
		{name="air", prob=0, param2=0},
		{name="air", prob=0, param2=0},
		{name="air", prob=0, param2=0},
		{name="air", prob=0, param2=0},
		{name="air", prob=0, param2=0},
		{name="air", prob=0, param2=0},
		{name="air", prob=0, param2=0},
		{name="air", prob=0, param2=0},
		{name="air", prob=0, param2=0},
		{name="air", prob=0, param2=0},
		{name="air", prob=0, param2=0},
		{name="air", prob=0, param2=0},
		{name="default:pine_tree", prob=254, param2=0},
		{name="air", prob=0, param2=0},
		{name="air", prob=0, param2=0},
		{name="air", prob=0, param2=0},
		{name="default:pine_tree", prob=254, param2=0},
		{name="air", prob=0, param2=0},
		{name="air", prob=0, param2=0},
		{name="air", prob=0, param2=0},
		{name="air", prob=0, param2=0},
		{name="air", prob=0, param2=0},
		{name="air", prob=0, param2=0},
		{name="air", prob=0, param2=0},
		{name="air", prob=0, param2=0},
		{name="air", prob=0, param2=0},
		{name="air", prob=0, param2=0},
		{name="air", prob=0, param2=0},
		{name="air", prob=0, param2=0},
		{name="stairs:stair_junglewood", prob=254, param2=1},
		{name="stairs:stair_junglewood", prob=254, param2=21},
		{name="air", prob=0, param2=0},
		{name="stairs:stair_junglewood", prob=254, param2=23},
		{name="stairs:stair_junglewood", prob=254, param2=3},
		{name="air", prob=0, param2=0},
		{name="air", prob=0, param2=0},
		{name="air", prob=0, param2=0},
		{name="air", prob=0, param2=0},
		{name="air", prob=0, param2=0},
		{name="air", prob=0, param2=0},
		{name="air", prob=0, param2=0},
		{name="air", prob=0, param2=0},
		{name="air", prob=0, param2=0},
		{name="air", prob=0, param2=0},
		{name="air", prob=0, param2=0},
		{name="air", prob=0, param2=0},
		{name="air", prob=0, param2=0},
		{name="stairs:slab_junglewood", prob=254, param2=3},
		{name="stairs:slab_junglewood", prob=254, param2=3},
		{name="stairs:slab_junglewood", prob=254, param2=3},
		{name="air", prob=0, param2=0},
		{name="air", prob=0, param2=0},
		{name="air", prob=0, param2=0},
		{name="air", prob=0, param2=0},
		{name="air", prob=0, param2=0},
		{name="air", prob=0, param2=0},
		{name="air", prob=0, param2=0},
		{name="air", prob=0, param2=0},
		{name="air", prob=0, param2=0},
		{name="air", prob=0, param2=0},
		{name="air", prob=0, param2=0},
		{name="air", prob=0, param2=0},
		{name="air", prob=0, param2=0},
		{name="air", prob=0, param2=0},
		{name="air", prob=0, param2=0},
		{name="air", prob=0, param2=0},
		{name="air", prob=0, param2=0},
		{name="air", prob=0, param2=0},
		{name="air", prob=0, param2=0},
		{name="air", prob=0, param2=0},
		{name="air", prob=0, param2=0},
		{name="air", prob=0, param2=0},
		{name="air", prob=0, param2=0},
		{name="air", prob=0, param2=0},
		{name="air", prob=0, param2=0},
		{name="air", prob=0, param2=0},
		{name="air", prob=0, param2=0},
		{name="air", prob=0, param2=0},
		{name="air", prob=0, param2=0},
		{name="air", prob=0, param2=0},
		{name="air", prob=0, param2=0},
		{name="air", prob=0, param2=0},
		{name="air", prob=0, param2=0},
		{name="air", prob=0, param2=0},
		{name="air", prob=0, param2=0},
		{name="air", prob=0, param2=0},
		{name="air", prob=0, param2=0},
		{name="air", prob=0, param2=0},
		{name="air", prob=0, param2=0},
		{name="air", prob=0, param2=0},
		{name="air", prob=0, param2=0},
		{name="air", prob=0, param2=0},
		{name="air", prob=0, param2=0},
		{name="air", prob=0, param2=0},
		{name="air", prob=0, param2=0},
		{name="air", prob=0, param2=0},
		{name="air", prob=0, param2=0},
		{name="air", prob=0, param2=0},
		{name="air", prob=0, param2=0},
		{name="air", prob=0, param2=0},
		{name="air", prob=0, param2=0},
		{name="air", prob=0, param2=0},
		{name="air", prob=0, param2=0},
		{name="air", prob=0, param2=0},
		{name="air", prob=0, param2=0},
		{name="air", prob=0, param2=0},
		{name="air", prob=0, param2=0},
		{name="air", prob=0, param2=0},
		{name="air", prob=0, param2=0},
		{name="air", prob=0, param2=0},
		{name="air", prob=0, param2=0},
		{name="air", prob=0, param2=0},
		{name="air", prob=0, param2=0},
		{name="air", prob=0, param2=0},
		{name="air", prob=0, param2=0},
		{name="air", prob=0, param2=0},
		{name="air", prob=0, param2=0},
		{name="air", prob=0, param2=0},
		{name="air", prob=0, param2=0},
		{name="air", prob=0, param2=0},
		{name="air", prob=0, param2=0},
		{name="air", prob=0, param2=0},
		{name="air", prob=0, param2=0},
		{name="air", prob=0, param2=0},
		{name="air", prob=0, param2=0},
		{name="air", prob=0, param2=0},
		{name="air", prob=0, param2=0},
		{name="air", prob=0, param2=0},
		{name="air", prob=0, param2=0},
		{name="air", prob=0, param2=0},
		{name="air", prob=0, param2=0},
		{name="air", prob=0, param2=0},
		{name="air", prob=0, param2=0},
		{name="air", prob=0, param2=0},
		{name="air", prob=0, param2=0},
		{name="air", prob=0, param2=0},
		{name="air", prob=0, param2=0},
		{name="air", prob=0, param2=0},
		{name="air", prob=0, param2=0},
		{name="air", prob=0, param2=0},
		{name="air", prob=0, param2=0},
		{name="air", prob=0, param2=0},
		{name="air", prob=0, param2=0},
		{name="air", prob=0, param2=0},
		{name="air", prob=0, param2=0},
		{name="air", prob=0, param2=0},
		{name="air", prob=0, param2=0},
		{name="air", prob=0, param2=0},
		{name="air", prob=0, param2=0},
		{name="air", prob=0, param2=0},
		{name="air", prob=0, param2=0},
		{name="air", prob=0, param2=0},
		{name="air", prob=0, param2=0},
		{name="air", prob=0, param2=0},
		{name="air", prob=0, param2=0},
		{name="air", prob=0, param2=0},
		{name="air", prob=0, param2=0},
		{name="air", prob=0, param2=0},
		{name="air", prob=0, param2=0},
		{name="air", prob=0, param2=0},
		{name="air", prob=0, param2=0},
		{name="air", prob=0, param2=0},
		{name="air", prob=0, param2=0},
		{name="air", prob=0, param2=0},
		{name="air", prob=0, param2=0},
		{name="air", prob=0, param2=0},
		{name="air", prob=0, param2=0},
		{name="air", prob=0, param2=0},
		{name="air", prob=0, param2=0},
		{name="air", prob=0, param2=0},
		{name="air", prob=0, param2=0},
		{name="air", prob=0, param2=0},
		{name="air", prob=0, param2=0},
		{name="air", prob=0, param2=0},
		{name="air", prob=0, param2=0},
		{name="air", prob=0, param2=0},
		{name="air", prob=0, param2=0},
		{name="air", prob=0, param2=0},
		{name="air", prob=0, param2=0},
		{name="air", prob=0, param2=0},
		{name="air", prob=0, param2=0},
		{name="air", prob=0, param2=0},
		{name="air", prob=0, param2=0},
		{name="air", prob=0, param2=0},
		{name="air", prob=0, param2=0},
		{name="air", prob=0, param2=0},
		{name="air", prob=0, param2=0},
		{name="air", prob=0, param2=0},
		{name="air", prob=0, param2=0},
		{name="air", prob=0, param2=0},
		{name="air", prob=0, param2=0},
		{name="air", prob=0, param2=0},
		{name="air", prob=0, param2=0},
		{name="air", prob=0, param2=0},
		{name="air", prob=0, param2=0},
		{name="air", prob=0, param2=0},
		{name="air", prob=0, param2=0},
		{name="air", prob=0, param2=0},
		{name="air", prob=0, param2=0},
		{name="everness:frosted_snowblock", prob=254, param2=0},
		{name="everness:frosted_snowblock", prob=254, param2=0},
		{name="everness:frosted_snowblock", prob=254, param2=0},
		{name="everness:frosted_snowblock", prob=254, param2=0},
		{name="everness:frosted_snowblock", prob=254, param2=0},
		{name="air", prob=0, param2=0},
		{name="air", prob=0, param2=0},
		{name="air", prob=0, param2=0},
		{name="air", prob=0, param2=0},
		{name="air", prob=0, param2=0},
		{name="air", prob=0, param2=0},
		{name="air", prob=0, param2=0},
		{name="air", prob=0, param2=0},
		{name="air", prob=0, param2=0},
		{name="air", prob=0, param2=0},
		{name="everness:frosted_snowblock", prob=254, param2=0},
		{name="everness:frosted_snowblock", prob=254, param2=0},
		{name="everness:frosted_snowblock", prob=254, param2=0},
		{name="everness:frosted_snowblock", prob=254, param2=0},
		{name="everness:frosted_snowblock", prob=254, param2=0},
		{name="everness:frosted_snowblock", prob=254, param2=0},
		{name="everness:frosted_snowblock", prob=254, param2=0},
		{name="everness:frosted_snowblock", prob=254, param2=0},
		{name="everness:frosted_snowblock", prob=254, param2=0},
		{name="air", prob=0, param2=0},
		{name="air", prob=0, param2=0},
		{name="air", prob=0, param2=0},
		{name="air", prob=0, param2=0},
		{name="air", prob=0, param2=0},
		{name="air", prob=0, param2=0},
		{name="everness:frosted_snowblock", prob=254, param2=0},
		{name="everness:frosted_snowblock", prob=254, param2=0},
		{name="everness:frosted_snowblock", prob=254, param2=0},
		{name="everness:frosted_snowblock", prob=254, param2=0},
		{name="everness:frosted_snowblock", prob=254, param2=0},
		{name="everness:frosted_snowblock", prob=254, param2=0},
		{name="everness:frosted_snowblock", prob=254, param2=0},
		{name="everness:frosted_snowblock", prob=254, param2=0},
		{name="everness:frosted_snowblock", prob=254, param2=0},
		{name="everness:frosted_snowblock", prob=254, param2=0},
		{name="everness:frosted_snowblock", prob=254, param2=0},
		{name="everness:frosted_snowblock", prob=254, param2=0},
		{name="everness:frosted_snowblock", prob=254, param2=0},
		{name="air", prob=0, param2=0},
		{name="air", prob=0, param2=0},
		{name="air", prob=0, param2=0},
		{name="air", prob=0, param2=0},
		{name="everness:frosted_snowblock", prob=254, param2=0},
		{name="everness:frosted_snowblock", prob=254, param2=0},
		{name="everness:frosted_snowblock", prob=254, param2=0},
		{name="everness:frosted_snowblock", prob=254, param2=0},
		{name="default:junglewood", prob=254, param2=0},
		{name="default:junglewood", prob=254, param2=0},
		{name="default:junglewood", prob=254, param2=0},
		{name="default:junglewood", prob=254, param2=0},
		{name="default:junglewood", prob=254, param2=0},
		{name="everness:frosted_snowblock", prob=254, param2=0},
		{name="everness:frosted_snowblock", prob=254, param2=0},
		{name="everness:frosted_snowblock", prob=254, param2=0},
		{name="everness:frosted_snowblock", prob=254, param2=0},
		{name="air", prob=0, param2=0},
		{name="air", prob=0, param2=0},
		{name="air", prob=0, param2=0},
		{name="air", prob=0, param2=0},
		{name="air", prob=0, param2=0},
		{name="everness:frosted_snowblock", prob=254, param2=0},
		{name="everness:frosted_snowblock", prob=254, param2=0},
		{name="everness:frosted_snowblock", prob=254, param2=0},
		{name="default:pine_tree", prob=254, param2=2},
		{name="default:pine_tree", prob=254, param2=2},
		{name="air", prob=254, param2=0},
		{name="default:pine_tree", prob=254, param2=2},
		{name="default:pine_tree", prob=254, param2=2},
		{name="everness:frosted_snowblock", prob=254, param2=0},
		{name="everness:frosted_snowblock", prob=254, param2=0},
		{name="everness:frosted_snowblock", prob=254, param2=0},
		{name="air", prob=0, param2=0},
		{name="air", prob=0, param2=0},
		{name="air", prob=0, param2=0},
		{name="air", prob=0, param2=0},
		{name="air", prob=0, param2=0},
		{name="air", prob=0, param2=0},
		{name="air", prob=0, param2=0},
		{name="everness:frosted_snowblock", prob=254, param2=0},
		{name="everness:frosted_snowblock", prob=254, param2=0},
		{name="default:pine_tree", prob=254, param2=2},
		{name="default:pine_tree", prob=254, param2=2},
		{name="air", prob=254, param2=0},
		{name="default:pine_tree", prob=254, param2=2},
		{name="default:pine_tree", prob=254, param2=2},
		{name="everness:frosted_snowblock", prob=254, param2=0},
		{name="everness:frosted_snowblock", prob=254, param2=0},
		{name="air", prob=0, param2=0},
		{name="air", prob=0, param2=0},
		{name="air", prob=0, param2=0},
		{name="air", prob=0, param2=0},
		{name="air", prob=0, param2=0},
		{name="air", prob=0, param2=0},
		{name="air", prob=0, param2=0},
		{name="air", prob=0, param2=0},
		{name="everness:frosted_snowblock", prob=254, param2=0},
		{name="everness:frosted_snowblock", prob=254, param2=0},
		{name="default:pine_tree", prob=254, param2=22},
		{name="default:pine_tree", prob=254, param2=2},
		{name="stairs:stair_junglewood", prob=254, param2=20},
		{name="default:pine_tree", prob=254, param2=2},
		{name="default:pine_tree", prob=254, param2=2},
		{name="everness:frosted_snowblock", prob=254, param2=0},
		{name="everness:frosted_snowblock", prob=254, param2=0},
		{name="air", prob=0, param2=0},
		{name="air", prob=0, param2=0},
		{name="air", prob=0, param2=0},
		{name="air", prob=0, param2=0},
		{name="air", prob=0, param2=0},
		{name="air", prob=0, param2=0},
		{name="air", prob=0, param2=0},
		{name="air", prob=0, param2=0},
		{name="air", prob=0, param2=0},
		{name="air", prob=0, param2=0},
		{name="everness:frosted_snowblock", prob=254, param2=0},
		{name="default:pine_tree", prob=254, param2=1},
		{name="default:junglewood", prob=254, param2=0},
		{name="default:pine_tree", prob=254, param2=1},
		{name="everness:frosted_snowblock", prob=254, param2=0},
		{name="air", prob=0, param2=0},
		{name="air", prob=0, param2=0},
		{name="air", prob=0, param2=0},
		{name="air", prob=0, param2=0},
		{name="air", prob=0, param2=0},
		{name="air", prob=0, param2=0},
		{name="air", prob=0, param2=0},
		{name="air", prob=0, param2=0},
		{name="air", prob=0, param2=0},
		{name="air", prob=0, param2=0},
		{name="air", prob=0, param2=0},
		{name="air", prob=0, param2=0},
		{name="air", prob=0, param2=0},
		{name="everness:frosted_snowblock", prob=254, param2=0},
		{name="everness:frosted_snowblock", prob=254, param2=0},
		{name="everness:frosted_snowblock", prob=254, param2=0},
		{name="air", prob=0, param2=0},
		{name="air", prob=0, param2=0},
		{name="air", prob=0, param2=0},
		{name="air", prob=0, param2=0},
		{name="air", prob=0, param2=0},
		{name="air", prob=0, param2=0},
		{name="air", prob=0, param2=0},
		{name="air", prob=0, param2=0},
		{name="air", prob=0, param2=0},
		{name="air", prob=0, param2=0},
		{name="air", prob=0, param2=0},
		{name="air", prob=0, param2=0},
		{name="air", prob=0, param2=0},
		{name="air", prob=0, param2=0},
		{name="air", prob=0, param2=0},
		{name="air", prob=0, param2=0},
		{name="air", prob=0, param2=0},
		{name="air", prob=0, param2=0},
		{name="air", prob=0, param2=0},
		{name="air", prob=0, param2=0},
		{name="air", prob=0, param2=0},
		{name="air", prob=0, param2=0},
		{name="air", prob=0, param2=0},
		{name="air", prob=0, param2=0},
		{name="air", prob=0, param2=0},
		{name="air", prob=0, param2=0},
		{name="air", prob=0, param2=0},
		{name="air", prob=0, param2=0},
		{name="air", prob=0, param2=0},
		{name="air", prob=0, param2=0},
		{name="air", prob=0, param2=0},
		{name="air", prob=0, param2=0},
		{name="air", prob=0, param2=0},
		{name="air", prob=0, param2=0},
		{name="air", prob=0, param2=0},
		{name="air", prob=0, param2=0},
		{name="air", prob=0, param2=0},
		{name="air", prob=0, param2=0},
		{name="air", prob=0, param2=0},
		{name="air", prob=0, param2=0},
		{name="air", prob=0, param2=0},
		{name="air", prob=0, param2=0},
		{name="air", prob=0, param2=0},
		{name="air", prob=0, param2=0},
		{name="air", prob=0, param2=0},
		{name="air", prob=0, param2=0},
		{name="air", prob=0, param2=0},
		{name="air", prob=0, param2=0},
		{name="air", prob=0, param2=0},
		{name="air", prob=0, param2=0},
		{name="air", prob=0, param2=0},
		{name="air", prob=0, param2=0},
		{name="air", prob=0, param2=0},
		{name="air", prob=0, param2=0},
		{name="air", prob=0, param2=0},
		{name="air", prob=0, param2=0},
		{name="air", prob=0, param2=0},
		{name="air", prob=0, param2=0},
		{name="air", prob=0, param2=0},
		{name="air", prob=0, param2=0},
		{name="air", prob=0, param2=0},
		{name="air", prob=0, param2=0},
		{name="air", prob=0, param2=0},
		{name="air", prob=0, param2=0},
		{name="air", prob=0, param2=0},
		{name="air", prob=0, param2=0},
		{name="air", prob=0, param2=0},
		{name="air", prob=0, param2=0},
		{name="air", prob=0, param2=0},
		{name="air", prob=0, param2=0},
		{name="air", prob=0, param2=0},
		{name="air", prob=0, param2=0},
		{name="air", prob=0, param2=0},
		{name="air", prob=0, param2=0},
		{name="air", prob=0, param2=0},
		{name="air", prob=0, param2=0},
		{name="air", prob=0, param2=0},
		{name="air", prob=0, param2=0},
		{name="air", prob=0, param2=0},
		{name="air", prob=0, param2=0},
		{name="air", prob=0, param2=0},
		{name="air", prob=0, param2=0},
		{name="air", prob=0, param2=0},
		{name="air", prob=0, param2=0},
		{name="air", prob=0, param2=0},
		{name="air", prob=0, param2=0},
		{name="air", prob=0, param2=0},
		{name="air", prob=0, param2=0},
		{name="air", prob=0, param2=0},
		{name="air", prob=0, param2=0},
		{name="air", prob=0, param2=0},
		{name="air", prob=0, param2=0},
		{name="air", prob=0, param2=0},
		{name="air", prob=0, param2=0},
		{name="air", prob=0, param2=0},
		{name="air", prob=0, param2=0},
		{name="air", prob=0, param2=0},
		{name="air", prob=0, param2=0},
		{name="air", prob=0, param2=0},
		{name="air", prob=0, param2=0},
		{name="air", prob=0, param2=0},
		{name="air", prob=0, param2=0},
		{name="air", prob=0, param2=0},
		{name="air", prob=0, param2=0},
		{name="air", prob=0, param2=0},
		{name="air", prob=0, param2=0},
		{name="air", prob=0, param2=0},
		{name="air", prob=0, param2=0},
		{name="air", prob=0, param2=0},
		{name="air", prob=0, param2=0},
		{name="air", prob=0, param2=0},
		{name="air", prob=0, param2=0},
		{name="air", prob=0, param2=0},
		{name="air", prob=0, param2=0},
		{name="air", prob=0, param2=0},
		{name="air", prob=0, param2=0},
		{name="air", prob=0, param2=0},
		{name="air", prob=0, param2=0},
		{name="air", prob=0, param2=0},
		{name="air", prob=0, param2=0},
		{name="air", prob=0, param2=0},
		{name="air", prob=0, param2=0},
		{name="air", prob=0, param2=0},
		{name="air", prob=0, param2=0},
		{name="air", prob=0, param2=0},
		{name="air", prob=0, param2=0},
		{name="air", prob=0, param2=0},
		{name="air", prob=0, param2=0},
		{name="air", prob=0, param2=0},
		{name="air", prob=0, param2=0},
		{name="air", prob=0, param2=0},
		{name="air", prob=0, param2=0},
		{name="air", prob=0, param2=0},
		{name="everness:frosted_snowblock", prob=254, param2=0},
		{name="everness:frosted_snowblock", prob=254, param2=0},
		{name="everness:frosted_snowblock", prob=254, param2=0},
		{name="air", prob=0, param2=0},
		{name="air", prob=0, param2=0},
		{name="air", prob=0, param2=0},
		{name="air", prob=0, param2=0},
		{name="air", prob=0, param2=0},
		{name="air", prob=0, param2=0},
		{name="air", prob=0, param2=0},
		{name="air", prob=0, param2=0},
		{name="air", prob=0, param2=0},
		{name="air", prob=0, param2=0},
		{name="air", prob=0, param2=0},
		{name="air", prob=0, param2=0},
		{name="everness:frosted_snowblock", prob=254, param2=0},
		{name="everness:frosted_snowblock", prob=254, param2=0},
		{name="everness:frosted_snowblock", prob=254, param2=0},
		{name="everness:frosted_snowblock", prob=254, param2=0},
		{name="everness:frosted_snowblock", prob=254, param2=0},
		{name="everness:frosted_snowblock", prob=254, param2=0},
		{name="everness:frosted_snowblock", prob=254, param2=0},
		{name="air", prob=0, param2=0},
		{name="air", prob=0, param2=0},
		{name="air", prob=0, param2=0},
		{name="air", prob=0, param2=0},
		{name="air", prob=0, param2=0},
		{name="air", prob=0, param2=0},
		{name="air", prob=0, param2=0},
		{name="air", prob=0, param2=0},
		{name="everness:frosted_snowblock", prob=254, param2=0},
		{name="everness:frosted_snowblock", prob=254, param2=0},
		{name="everness:frosted_snowblock", prob=254, param2=0},
		{name="everness:frosted_snowblock", prob=254, param2=0},
		{name="everness:frosted_snowblock", prob=254, param2=0},
		{name="everness:frosted_snowblock", prob=254, param2=0},
		{name="everness:frosted_snowblock", prob=254, param2=0},
		{name="everness:frosted_snowblock", prob=254, param2=0},
		{name="everness:frosted_snowblock", prob=254, param2=0},
		{name="everness:frosted_snowblock", prob=254, param2=0},
		{name="everness:frosted_snowblock", prob=254, param2=0},
		{name="air", prob=0, param2=0},
		{name="air", prob=0, param2=0},
		{name="air", prob=0, param2=0},
		{name="air", prob=0, param2=0},
		{name="everness:frosted_snowblock", prob=254, param2=0},
		{name="everness:frosted_snowblock", prob=254, param2=0},
		{name="everness:frosted_snowblock", prob=254, param2=0},
		{name="everness:frosted_snowblock", prob=254, param2=0},
		{name="everness:frosted_snowblock", prob=254, param2=0},
		{name="everness:frosted_snowblock", prob=254, param2=0},
		{name="everness:frosted_snowblock", prob=254, param2=0},
		{name="everness:frosted_snowblock", prob=254, param2=0},
		{name="everness:frosted_snowblock", prob=254, param2=0},
		{name="everness:frosted_snowblock", prob=254, param2=0},
		{name="everness:frosted_snowblock", prob=254, param2=0},
		{name="everness:frosted_snowblock", prob=254, param2=0},
		{name="everness:frosted_snowblock", prob=254, param2=0},
		{name="everness:frosted_snowblock", prob=254, param2=0},
		{name="everness:frosted_snowblock", prob=254, param2=0},
		{name="air", prob=0, param2=0},
		{name="air", prob=0, param2=0},
		{name="everness:frosted_snowblock", prob=254, param2=0},
		{name="everness:frosted_snowblock", prob=254, param2=0},
		{name="everness:frosted_snowblock", prob=254, param2=0},
		{name="default:junglewood", prob=254, param2=0},
		{name="default:junglewood", prob=254, param2=0},
		{name="default:pine_wood", prob=254, param2=0},
		{name="default:pine_wood", prob=254, param2=0},
		{name="default:pine_wood", prob=254, param2=0},
		{name="default:pine_wood", prob=254, param2=0},
		{name="default:pine_wood", prob=254, param2=0},
		{name="default:junglewood", prob=254, param2=0},
		{name="default:junglewood", prob=254, param2=0},
		{name="everness:frosted_snowblock", prob=254, param2=0},
		{name="everness:frosted_snowblock", prob=254, param2=0},
		{name="everness:frosted_snowblock", prob=254, param2=0},
		{name="air", prob=0, param2=0},
		{name="air", prob=0, param2=0},
		{name="air", prob=0, param2=0},
		{name="everness:frosted_snowblock", prob=254, param2=0},
		{name="everness:frosted_snowblock", prob=254, param2=0},
		{name="default:pine_tree", prob=254, param2=3},
		{name="default:pine_tree", prob=254, param2=2},
		{name="air", prob=254, param2=0},
		{name="air", prob=254, param2=0},
		{name="air", prob=254, param2=0},
		{name="air", prob=254, param2=0},
		{name="air", prob=254, param2=0},
		{name="default:pine_tree", prob=254, param2=2},
		{name="default:pine_tree", prob=254, param2=1},
		{name="everness:frosted_snowblock", prob=254, param2=0},
		{name="everness:frosted_snowblock", prob=254, param2=0},
		{name="air", prob=0, param2=0},
		{name="air", prob=0, param2=0},
		{name="air", prob=0, param2=0},
		{name="air", prob=0, param2=0},
		{name="air", prob=0, param2=0},
		{name="everness:frosted_snowblock", prob=254, param2=0},
		{name="default:pine_tree", prob=254, param2=3},
		{name="default:pine_tree", prob=254, param2=2},
		{name="air", prob=254, param2=0},
		{name="air", prob=254, param2=0},
		{name="air", prob=254, param2=0},
		{name="air", prob=254, param2=0},
		{name="air", prob=254, param2=0},
		{name="default:pine_tree", prob=254, param2=2},
		{name="default:pine_tree", prob=254, param2=1},
		{name="everness:frosted_snowblock", prob=254, param2=0},
		{name="air", prob=0, param2=0},
		{name="air", prob=0, param2=0},
		{name="air", prob=0, param2=0},
		{name="air", prob=0, param2=0},
		{name="air", prob=0, param2=0},
		{name="air", prob=0, param2=0},
		{name="everness:frosted_snowblock", prob=254, param2=0},
		{name="default:pine_tree", prob=254, param2=3},
		{name="default:pine_tree", prob=254, param2=2},
		{name="air", prob=254, param2=0},
		{name="air", prob=254, param2=0},
		{name="air", prob=254, param2=0},
		{name="air", prob=254, param2=0},
		{name="air", prob=254, param2=0},
		{name="default:pine_tree", prob=254, param2=2},
		{name="default:pine_tree", prob=254, param2=1},
		{name="everness:frosted_snowblock", prob=254, param2=0},
		{name="air", prob=0, param2=0},
		{name="air", prob=0, param2=0},
		{name="air", prob=0, param2=0},
		{name="air", prob=0, param2=0},
		{name="air", prob=0, param2=0},
		{name="air", prob=0, param2=0},
		{name="air", prob=0, param2=0},
		{name="everness:frosted_snowblock", prob=254, param2=0},
		{name="everness:frosted_snowblock", prob=254, param2=0},
		{name="everness:frosted_snowblock", prob=254, param2=0},
		{name="air", prob=254, param2=0},
		{name="air", prob=254, param2=0},
		{name="air", prob=254, param2=0},
		{name="everness:frosted_snowblock", prob=254, param2=0},
		{name="everness:frosted_snowblock", prob=254, param2=0},
		{name="everness:frosted_snowblock", prob=254, param2=0},
		{name="air", prob=0, param2=0},
		{name="air", prob=0, param2=0},
		{name="air", prob=0, param2=0},
		{name="air", prob=0, param2=0},
		{name="air", prob=0, param2=0},
		{name="air", prob=0, param2=0},
		{name="air", prob=0, param2=0},
		{name="air", prob=0, param2=0},
		{name="air", prob=0, param2=0},
		{name="air", prob=0, param2=0},
		{name="air", prob=0, param2=0},
		{name="everness:frosted_snowblock", prob=254, param2=0},
		{name="everness:frosted_snowblock", prob=254, param2=0},
		{name="everness:frosted_snowblock", prob=254, param2=0},
		{name="air", prob=0, param2=0},
		{name="air", prob=0, param2=0},
		{name="air", prob=0, param2=0},
		{name="air", prob=0, param2=0},
		{name="air", prob=0, param2=0},
		{name="air", prob=0, param2=0},
		{name="air", prob=0, param2=0},
		{name="air", prob=0, param2=0},
		{name="air", prob=0, param2=0},
		{name="air", prob=0, param2=0},
		{name="air", prob=0, param2=0},
		{name="air", prob=0, param2=0},
		{name="air", prob=0, param2=0},
		{name="air", prob=0, param2=0},
		{name="air", prob=0, param2=0},
		{name="air", prob=0, param2=0},
		{name="air", prob=0, param2=0},
		{name="air", prob=0, param2=0},
		{name="air", prob=0, param2=0},
		{name="air", prob=0, param2=0},
		{name="air", prob=0, param2=0},
		{name="air", prob=0, param2=0},
		{name="air", prob=0, param2=0},
		{name="air", prob=0, param2=0},
		{name="air", prob=0, param2=0},
		{name="air", prob=0, param2=0},
		{name="air", prob=0, param2=0},
		{name="air", prob=0, param2=0},
		{name="air", prob=0, param2=0},
		{name="air", prob=0, param2=0},
		{name="air", prob=0, param2=0},
		{name="air", prob=0, param2=0},
		{name="air", prob=0, param2=0},
		{name="air", prob=0, param2=0},
		{name="air", prob=0, param2=0},
		{name="air", prob=0, param2=0},
		{name="air", prob=0, param2=0},
		{name="air", prob=0, param2=0},
		{name="air", prob=0, param2=0},
		{name="air", prob=0, param2=0},
		{name="air", prob=0, param2=0},
		{name="air", prob=0, param2=0},
		{name="air", prob=0, param2=0},
		{name="air", prob=0, param2=0},
		{name="air", prob=0, param2=0},
		{name="air", prob=0, param2=0},
		{name="air", prob=0, param2=0},
		{name="air", prob=0, param2=0},
		{name="air", prob=0, param2=0},
		{name="air", prob=0, param2=0},
		{name="air", prob=0, param2=0},
		{name="air", prob=0, param2=0},
		{name="air", prob=0, param2=0},
		{name="air", prob=0, param2=0},
		{name="air", prob=0, param2=0},
		{name="air", prob=0, param2=0},
		{name="air", prob=0, param2=0},
		{name="air", prob=0, param2=0},
		{name="air", prob=0, param2=0},
		{name="air", prob=0, param2=0},
		{name="air", prob=0, param2=0},
		{name="air", prob=0, param2=0},
		{name="air", prob=0, param2=0},
		{name="air", prob=0, param2=0},
		{name="air", prob=0, param2=0},
		{name="air", prob=0, param2=0},
		{name="air", prob=0, param2=0},
		{name="air", prob=0, param2=0},
		{name="air", prob=0, param2=0},
		{name="air", prob=0, param2=0},
		{name="air", prob=0, param2=0},
		{name="air", prob=0, param2=0},
		{name="air", prob=0, param2=0},
		{name="air", prob=0, param2=0},
		{name="air", prob=0, param2=0},
		{name="air", prob=0, param2=0},
		{name="air", prob=0, param2=0},
		{name="air", prob=0, param2=0},
		{name="air", prob=0, param2=0},
		{name="air", prob=0, param2=0},
		{name="air", prob=0, param2=0},
		{name="air", prob=0, param2=0},
		{name="air", prob=0, param2=0},
		{name="air", prob=0, param2=0},
		{name="air", prob=0, param2=0},
		{name="air", prob=0, param2=0},
		{name="air", prob=0, param2=0},
		{name="air", prob=0, param2=0},
		{name="air", prob=0, param2=0},
		{name="air", prob=0, param2=0},
		{name="air", prob=0, param2=0},
		{name="air", prob=0, param2=0},
		{name="air", prob=0, param2=0},
		{name="air", prob=0, param2=0},
		{name="air", prob=0, param2=0},
		{name="air", prob=0, param2=0},
		{name="air", prob=0, param2=0},
		{name="air", prob=0, param2=0},
		{name="air", prob=0, param2=0},
		{name="air", prob=0, param2=0},
		{name="air", prob=0, param2=0},
		{name="air", prob=0, param2=0},
		{name="air", prob=0, param2=0},
		{name="air", prob=0, param2=0},
		{name="air", prob=0, param2=0},
		{name="air", prob=0, param2=0},
		{name="air", prob=0, param2=0},
		{name="air", prob=0, param2=0},
		{name="air", prob=0, param2=0},
		{name="air", prob=0, param2=0},
		{name="air", prob=0, param2=0},
		{name="air", prob=0, param2=0},
		{name="air", prob=0, param2=0},
		{name="air", prob=0, param2=0},
		{name="air", prob=0, param2=0},
		{name="air", prob=0, param2=0},
		{name="air", prob=0, param2=0},
		{name="everness:frosted_snowblock", prob=254, param2=0},
		{name="air", prob=0, param2=0},
		{name="air", prob=0, param2=0},
		{name="air", prob=0, param2=0},
		{name="air", prob=0, param2=0},
		{name="air", prob=0, param2=0},
		{name="air", prob=0, param2=0},
		{name="air", prob=0, param2=0},
		{name="air", prob=0, param2=0},
		{name="air", prob=0, param2=0},
		{name="air", prob=0, param2=0},
		{name="air", prob=0, param2=0},
		{name="air", prob=0, param2=0},
		{name="air", prob=0, param2=0},
		{name="air", prob=0, param2=0},
		{name="everness:frosted_snowblock", prob=254, param2=0},
		{name="everness:frosted_snowblock", prob=254, param2=0},
		{name="everness:frosted_snowblock", prob=254, param2=0},
		{name="everness:frosted_snowblock", prob=254, param2=0},
		{name="everness:frosted_snowblock", prob=254, param2=0},
		{name="air", prob=0, param2=0},
		{name="air", prob=0, param2=0},
		{name="air", prob=0, param2=0},
		{name="air", prob=0, param2=0},
		{name="air", prob=0, param2=0},
		{name="air", prob=0, param2=0},
		{name="air", prob=0, param2=0},
		{name="air", prob=0, param2=0},
		{name="air", prob=0, param2=0},
		{name="air", prob=0, param2=0},
		{name="everness:frosted_snowblock", prob=254, param2=0},
		{name="everness:frosted_snowblock", prob=254, param2=0},
		{name="everness:frosted_snowblock", prob=254, param2=0},
		{name="everness:frosted_snowblock", prob=254, param2=0},
		{name="everness:frosted_snowblock", prob=254, param2=0},
		{name="everness:frosted_snowblock", prob=254, param2=0},
		{name="everness:frosted_snowblock", prob=254, param2=0},
		{name="everness:frosted_snowblock", prob=254, param2=0},
		{name="everness:frosted_snowblock", prob=254, param2=0},
		{name="air", prob=0, param2=0},
		{name="air", prob=0, param2=0},
		{name="air", prob=0, param2=0},
		{name="air", prob=0, param2=0},
		{name="air", prob=0, param2=0},
		{name="air", prob=0, param2=0},
		{name="everness:frosted_snowblock", prob=254, param2=0},
		{name="everness:frosted_snowblock", prob=254, param2=0},
		{name="everness:frosted_snowblock", prob=254, param2=0},
		{name="everness:frosted_snowblock", prob=254, param2=0},
		{name="everness:frosted_snowblock", prob=254, param2=0},
		{name="everness:frosted_snowblock", prob=254, param2=0},
		{name="everness:frosted_snowblock", prob=254, param2=0},
		{name="everness:frosted_snowblock", prob=254, param2=0},
		{name="everness:frosted_snowblock", prob=254, param2=0},
		{name="everness:frosted_snowblock", prob=254, param2=0},
		{name="everness:frosted_snowblock", prob=254, param2=0},
		{name="everness:frosted_snowblock", prob=254, param2=0},
		{name="everness:frosted_snowblock", prob=254, param2=0},
		{name="air", prob=0, param2=0},
		{name="air", prob=0, param2=0},
		{name="everness:frosted_snowblock", prob=254, param2=0},
		{name="everness:frosted_snowblock", prob=254, param2=0},
		{name="everness:frosted_snowblock", prob=254, param2=0},
		{name="everness:frosted_snowblock", prob=254, param2=0},
		{name="everness:frosted_snowblock", prob=254, param2=0},
		{name="everness:frosted_snowblock", prob=254, param2=0},
		{name="everness:frosted_snowblock", prob=254, param2=0},
		{name="everness:frosted_snowblock", prob=254, param2=0},
		{name="everness:frosted_snowblock", prob=254, param2=0},
		{name="everness:frosted_snowblock", prob=254, param2=0},
		{name="everness:frosted_snowblock", prob=254, param2=0},
		{name="everness:frosted_snowblock", prob=254, param2=0},
		{name="everness:frosted_snowblock", prob=254, param2=0},
		{name="everness:frosted_snowblock", prob=254, param2=0},
		{name="everness:frosted_snowblock", prob=254, param2=0},
		{name="everness:frosted_snowblock", prob=254, param2=0},
		{name="everness:frosted_snowblock", prob=254, param2=0},
		{name="everness:frosted_snowblock", prob=254, param2=0},
		{name="everness:frosted_snowblock", prob=254, param2=0},
		{name="everness:frosted_snowblock", prob=254, param2=0},
		{name="default:junglewood", prob=254, param2=0},
		{name="default:pine_wood", prob=254, param2=0},
		{name="default:pine_wood", prob=254, param2=0},
		{name="default:junglewood", prob=254, param2=0},
		{name="default:wood", prob=254, param2=0},
		{name="default:wood", prob=254, param2=0},
		{name="default:junglewood", prob=254, param2=0},
		{name="default:junglewood", prob=254, param2=0},
		{name="default:pine_wood", prob=254, param2=0},
		{name="default:pine_wood", prob=254, param2=0},
		{name="default:junglewood", prob=254, param2=0},
		{name="everness:frosted_snowblock", prob=254, param2=0},
		{name="everness:frosted_snowblock", prob=254, param2=0},
		{name="everness:frosted_snowblock", prob=254, param2=0},
		{name="air", prob=0, param2=0},
		{name="everness:frosted_snowblock", prob=254, param2=0},
		{name="everness:frosted_snowblock", prob=254, param2=0},
		{name="default:pine_tree", prob=254, param2=3},
		{name="air", prob=254, param2=0},
		{name="air", prob=254, param2=0},
		{name="air", prob=254, param2=0},
		{name="air", prob=254, param2=0},
		{name="air", prob=254, param2=0},
		{name="air", prob=254, param2=0},
		{name="air", prob=254, param2=0},
		{name="air", prob=254, param2=0},
		{name="air", prob=254, param2=0},
		{name="default:pine_tree", prob=254, param2=1},
		{name="everness:frosted_snowblock", prob=254, param2=0},
		{name="everness:frosted_snowblock", prob=254, param2=0},
		{name="air", prob=0, param2=0},
		{name="air", prob=0, param2=0},
		{name="air", prob=0, param2=0},
		{name="everness:frosted_snowblock", prob=254, param2=0},
		{name="default:pine_tree", prob=254, param2=3},
		{name="air", prob=254, param2=0},
		{name="air", prob=254, param2=0},
		{name="air", prob=254, param2=0},
		{name="air", prob=254, param2=0},
		{name="air", prob=254, param2=0},
		{name="air", prob=254, param2=0},
		{name="air", prob=254, param2=0},
		{name="air", prob=254, param2=0},
		{name="air", prob=254, param2=0},
		{name="default:pine_tree", prob=254, param2=1},
		{name="everness:frosted_snowblock", prob=254, param2=0},
		{name="air", prob=0, param2=0},
		{name="air", prob=0, param2=0},
		{name="air", prob=0, param2=0},
		{name="air", prob=0, param2=0},
		{name="everness:frosted_snowblock", prob=254, param2=0},
		{name="default:pine_tree", prob=254, param2=21},
		{name="air", prob=254, param2=0},
		{name="air", prob=254, param2=0},
		{name="air", prob=254, param2=0},
		{name="air", prob=254, param2=0},
		{name="air", prob=254, param2=0},
		{name="air", prob=254, param2=0},
		{name="air", prob=254, param2=0},
		{name="air", prob=254, param2=0},
		{name="air", prob=254, param2=0},
		{name="default:pine_tree", prob=254, param2=1},
		{name="everness:frosted_snowblock", prob=254, param2=0},
		{name="air", prob=0, param2=0},
		{name="air", prob=0, param2=0},
		{name="air", prob=0, param2=0},
		{name="air", prob=0, param2=0},
		{name="air", prob=0, param2=0},
		{name="everness:frosted_snowblock", prob=254, param2=0},
		{name="everness:frosted_snowblock", prob=254, param2=0},
		{name="air", prob=254, param2=0},
		{name="air", prob=254, param2=0},
		{name="air", prob=254, param2=0},
		{name="air", prob=254, param2=0},
		{name="air", prob=254, param2=0},
		{name="air", prob=254, param2=0},
		{name="air", prob=254, param2=0},
		{name="everness:frosted_snowblock", prob=254, param2=0},
		{name="everness:frosted_snowblock", prob=254, param2=0},
		{name="air", prob=0, param2=0},
		{name="air", prob=0, param2=0},
		{name="air", prob=0, param2=0},
		{name="air", prob=0, param2=0},
		{name="air", prob=0, param2=0},
		{name="air", prob=0, param2=0},
		{name="air", prob=0, param2=0},
		{name="air", prob=0, param2=0},
		{name="everness:frosted_snowblock", prob=254, param2=0},
		{name="everness:frosted_snowblock", prob=254, param2=0},
		{name="everness:frosted_snowblock", prob=254, param2=0},
		{name="air", prob=254, param2=0},
		{name="everness:frosted_snowblock", prob=254, param2=0},
		{name="everness:frosted_snowblock", prob=254, param2=0},
		{name="everness:frosted_snowblock", prob=254, param2=0},
		{name="air", prob=0, param2=0},
		{name="air", prob=0, param2=0},
		{name="air", prob=0, param2=0},
		{name="air", prob=0, param2=0},
		{name="air", prob=0, param2=0},
		{name="air", prob=0, param2=0},
		{name="air", prob=0, param2=0},
		{name="air", prob=0, param2=0},
		{name="air", prob=0, param2=0},
		{name="air", prob=0, param2=0},
		{name="air", prob=0, param2=0},
		{name="air", prob=0, param2=0},
		{name="air", prob=0, param2=0},
		{name="everness:frosted_snowblock", prob=254, param2=0},
		{name="air", prob=0, param2=0},
		{name="air", prob=0, param2=0},
		{name="air", prob=0, param2=0},
		{name="air", prob=0, param2=0},
		{name="air", prob=0, param2=0},
		{name="air", prob=0, param2=0},
		{name="air", prob=0, param2=0},
		{name="air", prob=0, param2=0},
		{name="air", prob=0, param2=0},
		{name="air", prob=0, param2=0},
		{name="air", prob=0, param2=0},
		{name="air", prob=0, param2=0},
		{name="air", prob=0, param2=0},
		{name="air", prob=0, param2=0},
		{name="air", prob=0, param2=0},
		{name="air", prob=0, param2=0},
		{name="air", prob=0, param2=0},
		{name="air", prob=0, param2=0},
		{name="air", prob=0, param2=0},
		{name="air", prob=0, param2=0},
		{name="air", prob=0, param2=0},
		{name="air", prob=0, param2=0},
		{name="air", prob=0, param2=0},
		{name="air", prob=0, param2=0},
		{name="air", prob=0, param2=0},
		{name="air", prob=0, param2=0},
		{name="air", prob=0, param2=0},
		{name="air", prob=0, param2=0},
		{name="air", prob=0, param2=0},
		{name="air", prob=0, param2=0},
		{name="air", prob=0, param2=0},
		{name="air", prob=0, param2=0},
		{name="air", prob=0, param2=0},
		{name="air", prob=0, param2=0},
		{name="air", prob=0, param2=0},
		{name="air", prob=0, param2=0},
		{name="air", prob=0, param2=0},
		{name="air", prob=0, param2=0},
		{name="air", prob=0, param2=0},
		{name="air", prob=0, param2=0},
		{name="air", prob=0, param2=0},
		{name="air", prob=0, param2=0},
		{name="air", prob=0, param2=0},
		{name="air", prob=0, param2=0},
		{name="air", prob=0, param2=0},
		{name="air", prob=0, param2=0},
		{name="air", prob=0, param2=0},
		{name="air", prob=0, param2=0},
		{name="air", prob=0, param2=0},
		{name="air", prob=0, param2=0},
		{name="air", prob=0, param2=0},
		{name="air", prob=0, param2=0},
		{name="air", prob=0, param2=0},
		{name="air", prob=0, param2=0},
		{name="air", prob=0, param2=0},
		{name="air", prob=0, param2=0},
		{name="air", prob=0, param2=0},
		{name="air", prob=0, param2=0},
		{name="air", prob=0, param2=0},
		{name="air", prob=0, param2=0},
		{name="air", prob=0, param2=0},
		{name="air", prob=0, param2=0},
		{name="air", prob=0, param2=0},
		{name="air", prob=0, param2=0},
		{name="air", prob=0, param2=0},
		{name="air", prob=0, param2=0},
		{name="air", prob=0, param2=0},
		{name="air", prob=0, param2=0},
		{name="air", prob=0, param2=0},
		{name="air", prob=0, param2=0},
		{name="air", prob=0, param2=0},
		{name="air", prob=0, param2=0},
		{name="air", prob=0, param2=0},
		{name="air", prob=0, param2=0},
		{name="air", prob=0, param2=0},
		{name="air", prob=0, param2=0},
		{name="air", prob=0, param2=0},
		{name="air", prob=0, param2=0},
		{name="air", prob=0, param2=0},
		{name="air", prob=0, param2=0},
		{name="air", prob=0, param2=0},
		{name="air", prob=0, param2=0},
		{name="air", prob=0, param2=0},
		{name="air", prob=0, param2=0},
		{name="air", prob=0, param2=0},
		{name="air", prob=0, param2=0},
		{name="air", prob=0, param2=0},
		{name="air", prob=0, param2=0},
		{name="air", prob=0, param2=0},
		{name="air", prob=0, param2=0},
		{name="air", prob=0, param2=0},
		{name="air", prob=0, param2=0},
		{name="air", prob=0, param2=0},
		{name="air", prob=0, param2=0},
		{name="air", prob=0, param2=0},
		{name="air", prob=0, param2=0},
		{name="air", prob=0, param2=0},
		{name="air", prob=0, param2=0},
		{name="air", prob=0, param2=0},
		{name="air", prob=0, param2=0},
		{name="everness:frosted_snowblock", prob=254, param2=0},
		{name="everness:frosted_snowblock", prob=254, param2=0},
		{name="everness:frosted_snowblock", prob=254, param2=0},
		{name="air", prob=0, param2=0},
		{name="air", prob=0, param2=0},
		{name="air", prob=0, param2=0},
		{name="air", prob=0, param2=0},
		{name="air", prob=0, param2=0},
		{name="air", prob=0, param2=0},
		{name="air", prob=0, param2=0},
		{name="air", prob=0, param2=0},
		{name="air", prob=0, param2=0},
		{name="air", prob=0, param2=0},
		{name="air", prob=0, param2=0},
		{name="air", prob=0, param2=0},
		{name="everness:frosted_snowblock", prob=254, param2=0},
		{name="everness:frosted_snowblock", prob=254, param2=0},
		{name="everness:frosted_snowblock", prob=254, param2=0},
		{name="everness:frosted_snowblock", prob=254, param2=0},
		{name="everness:frosted_snowblock", prob=254, param2=0},
		{name="everness:frosted_snowblock", prob=254, param2=0},
		{name="everness:frosted_snowblock", prob=254, param2=0},
		{name="air", prob=0, param2=0},
		{name="air", prob=0, param2=0},
		{name="air", prob=0, param2=0},
		{name="air", prob=0, param2=0},
		{name="air", prob=0, param2=0},
		{name="air", prob=0, param2=0},
		{name="air", prob=0, param2=0},
		{name="air", prob=0, param2=0},
		{name="everness:frosted_snowblock", prob=254, param2=0},
		{name="everness:frosted_snowblock", prob=254, param2=0},
		{name="everness:frosted_snowblock", prob=254, param2=0},
		{name="everness:frosted_snowblock", prob=254, param2=0},
		{name="everness:frosted_snowblock", prob=254, param2=0},
		{name="everness:frosted_snowblock", prob=254, param2=0},
		{name="everness:frosted_snowblock", prob=254, param2=0},
		{name="everness:frosted_snowblock", prob=254, param2=0},
		{name="everness:frosted_snowblock", prob=254, param2=0},
		{name="everness:frosted_snowblock", prob=254, param2=0},
		{name="everness:frosted_snowblock", prob=254, param2=0},
		{name="air", prob=0, param2=0},
		{name="air", prob=0, param2=0},
		{name="air", prob=0, param2=0},
		{name="air", prob=0, param2=0},
		{name="everness:frosted_snowblock", prob=254, param2=0},
		{name="everness:frosted_snowblock", prob=254, param2=0},
		{name="everness:frosted_snowblock", prob=254, param2=0},
		{name="everness:frosted_snowblock", prob=254, param2=0},
		{name="everness:frosted_snowblock", prob=254, param2=0},
		{name="everness:frosted_snowblock", prob=254, param2=0},
		{name="everness:frosted_snowblock", prob=254, param2=0},
		{name="everness:frosted_snowblock", prob=254, param2=0},
		{name="everness:frosted_snowblock", prob=254, param2=0},
		{name="everness:frosted_snowblock", prob=254, param2=0},
		{name="everness:frosted_snowblock", prob=254, param2=0},
		{name="everness:frosted_snowblock", prob=254, param2=0},
		{name="everness:frosted_snowblock", prob=254, param2=0},
		{name="everness:frosted_snowblock", prob=254, param2=0},
		{name="everness:frosted_snowblock", prob=254, param2=0},
		{name="air", prob=0, param2=0},
		{name="everness:frosted_snowblock", prob=254, param2=0},
		{name="everness:frosted_snowblock", prob=254, param2=0},
		{name="everness:frosted_snowblock", prob=254, param2=0},
		{name="everness:frosted_snowblock", prob=254, param2=0},
		{name="everness:frosted_snowblock", prob=254, param2=0},
		{name="everness:frosted_snowblock", prob=254, param2=0},
		{name="everness:frosted_snowblock", prob=254, param2=0},
		{name="everness:frosted_snowblock", prob=254, param2=0},
		{name="everness:frosted_snowblock", prob=254, param2=0},
		{name="everness:frosted_snowblock", prob=254, param2=0},
		{name="everness:frosted_snowblock", prob=254, param2=0},
		{name="everness:frosted_snowblock", prob=254, param2=0},
		{name="everness:frosted_snowblock", prob=254, param2=0},
		{name="everness:frosted_snowblock", prob=254, param2=0},
		{name="everness:frosted_snowblock", prob=254, param2=0},
		{name="everness:frosted_snowblock", prob=254, param2=0},
		{name="everness:frosted_snowblock", prob=254, param2=0},
		{name="everness:frosted_snowblock", prob=254, param2=0},
		{name="everness:frosted_snowblock", prob=254, param2=0},
		{name="everness:frosted_snowblock", prob=254, param2=0},
		{name="default:junglewood", prob=254, param2=0},
		{name="default:pine_wood", prob=254, param2=0},
		{name="default:junglewood", prob=254, param2=0},
		{name="default:wood", prob=254, param2=0},
		{name="default:junglewood", prob=254, param2=0},
		{name="default:junglewood", prob=254, param2=0},
		{name="default:junglewood", prob=254, param2=0},
		{name="default:wood", prob=254, param2=0},
		{name="default:junglewood", prob=254, param2=0},
		{name="default:pine_wood", prob=254, param2=0},
		{name="default:junglewood", prob=254, param2=0},
		{name="everness:frosted_snowblock", prob=254, param2=0},
		{name="everness:frosted_snowblock", prob=254, param2=0},
		{name="everness:frosted_snowblock", prob=254, param2=0},
		{name="air", prob=0, param2=0},
		{name="everness:frosted_snowblock", prob=254, param2=0},
		{name="everness:frosted_snowblock", prob=254, param2=0},
		{name="default:pine_tree", prob=254, param2=3},
		{name="air", prob=254, param2=0},
		{name="air", prob=254, param2=0},
		{name="air", prob=254, param2=0},
		{name="air", prob=254, param2=0},
		{name="air", prob=254, param2=0},
		{name="air", prob=254, param2=0},
		{name="air", prob=254, param2=0},
		{name="air", prob=254, param2=0},
		{name="air", prob=254, param2=0},
		{name="default:pine_tree", prob=254, param2=1},
		{name="everness:frosted_snowblock", prob=254, param2=0},
		{name="everness:frosted_snowblock", prob=254, param2=0},
		{name="air", prob=0, param2=0},
		{name="air", prob=0, param2=0},
		{name="air", prob=0, param2=0},
		{name="everness:frosted_snowblock", prob=254, param2=0},
		{name="default:pine_tree", prob=254, param2=3},
		{name="air", prob=254, param2=0},
		{name="air", prob=254, param2=0},
		{name="air", prob=254, param2=0},
		{name="air", prob=254, param2=0},
		{name="air", prob=254, param2=0},
		{name="air", prob=254, param2=0},
		{name="air", prob=254, param2=0},
		{name="air", prob=254, param2=0},
		{name="air", prob=254, param2=0},
		{name="default:pine_tree", prob=254, param2=1},
		{name="everness:frosted_snowblock", prob=254, param2=0},
		{name="air", prob=0, param2=0},
		{name="air", prob=0, param2=0},
		{name="air", prob=0, param2=0},
		{name="air", prob=0, param2=0},
		{name="everness:frosted_snowblock", prob=254, param2=0},
		{name="default:pine_tree", prob=254, param2=3},
		{name="air", prob=254, param2=0},
		{name="air", prob=254, param2=0},
		{name="air", prob=254, param2=0},
		{name="air", prob=254, param2=0},
		{name="air", prob=254, param2=0},
		{name="air", prob=254, param2=0},
		{name="air", prob=254, param2=0},
		{name="air", prob=254, param2=0},
		{name="air", prob=254, param2=0},
		{name="default:pine_tree", prob=254, param2=1},
		{name="everness:frosted_snowblock", prob=254, param2=0},
		{name="air", prob=0, param2=0},
		{name="air", prob=0, param2=0},
		{name="air", prob=0, param2=0},
		{name="air", prob=0, param2=0},
		{name="air", prob=0, param2=0},
		{name="everness:frosted_snowblock", prob=254, param2=0},
		{name="air", prob=254, param2=0},
		{name="air", prob=254, param2=0},
		{name="air", prob=254, param2=0},
		{name="air", prob=254, param2=0},
		{name="air", prob=254, param2=0},
		{name="air", prob=254, param2=0},
		{name="air", prob=254, param2=0},
		{name="air", prob=254, param2=0},
		{name="air", prob=254, param2=0},
		{name="everness:frosted_snowblock", prob=254, param2=0},
		{name="air", prob=0, param2=0},
		{name="air", prob=0, param2=0},
		{name="air", prob=0, param2=0},
		{name="air", prob=0, param2=0},
		{name="air", prob=0, param2=0},
		{name="air", prob=0, param2=0},
		{name="air", prob=0, param2=0},
		{name="everness:frosted_snowblock", prob=254, param2=0},
		{name="everness:frosted_snowblock", prob=254, param2=0},
		{name="air", prob=254, param2=0},
		{name="air", prob=254, param2=0},
		{name="air", prob=254, param2=0},
		{name="air", prob=254, param2=0},
		{name="air", prob=254, param2=0},
		{name="everness:frosted_snowblock", prob=254, param2=0},
		{name="everness:frosted_snowblock", prob=254, param2=0},
		{name="air", prob=0, param2=0},
		{name="air", prob=0, param2=0},
		{name="air", prob=0, param2=0},
		{name="air", prob=0, param2=0},
		{name="air", prob=0, param2=0},
		{name="air", prob=0, param2=0},
		{name="air", prob=0, param2=0},
		{name="air", prob=0, param2=0},
		{name="air", prob=0, param2=0},
		{name="air", prob=0, param2=0},
		{name="everness:frosted_snowblock", prob=254, param2=0},
		{name="everness:frosted_snowblock", prob=254, param2=0},
		{name="everness:frosted_snowblock", prob=254, param2=0},
		{name="everness:frosted_snowblock", prob=254, param2=0},
		{name="everness:frosted_snowblock", prob=254, param2=0},
		{name="air", prob=0, param2=0},
		{name="air", prob=0, param2=0},
		{name="air", prob=0, param2=0},
		{name="air", prob=0, param2=0},
		{name="air", prob=0, param2=0},
		{name="air", prob=0, param2=0},
		{name="air", prob=0, param2=0},
		{name="air", prob=0, param2=0},
		{name="air", prob=0, param2=0},
		{name="air", prob=0, param2=0},
		{name="air", prob=0, param2=0},
		{name="air", prob=0, param2=0},
		{name="air", prob=0, param2=0},
		{name="air", prob=0, param2=0},
		{name="air", prob=0, param2=0},
		{name="air", prob=0, param2=0},
		{name="air", prob=0, param2=0},
		{name="air", prob=0, param2=0},
		{name="air", prob=0, param2=0},
		{name="air", prob=0, param2=0},
		{name="air", prob=0, param2=0},
		{name="air", prob=0, param2=0},
		{name="air", prob=0, param2=0},
		{name="air", prob=0, param2=0},
		{name="air", prob=0, param2=0},
		{name="air", prob=0, param2=0},
		{name="air", prob=0, param2=0},
		{name="air", prob=0, param2=0},
		{name="air", prob=0, param2=0},
		{name="air", prob=0, param2=0},
		{name="air", prob=0, param2=0},
		{name="air", prob=0, param2=0},
		{name="air", prob=0, param2=0},
		{name="air", prob=0, param2=0},
		{name="air", prob=0, param2=0},
		{name="air", prob=0, param2=0},
		{name="air", prob=0, param2=0},
		{name="air", prob=0, param2=0},
		{name="air", prob=0, param2=0},
		{name="air", prob=0, param2=0},
		{name="air", prob=0, param2=0},
		{name="air", prob=0, param2=0},
		{name="air", prob=0, param2=0},
		{name="air", prob=0, param2=0},
		{name="air", prob=0, param2=0},
		{name="air", prob=0, param2=0},
		{name="air", prob=0, param2=0},
		{name="air", prob=0, param2=0},
		{name="air", prob=0, param2=0},
		{name="air", prob=0, param2=0},
		{name="air", prob=0, param2=0},
		{name="air", prob=0, param2=0},
		{name="air", prob=0, param2=0},
		{name="air", prob=0, param2=0},
		{name="air", prob=0, param2=0},
		{name="air", prob=0, param2=0},
		{name="air", prob=0, param2=0},
		{name="air", prob=0, param2=0},
		{name="air", prob=0, param2=0},
		{name="air", prob=0, param2=0},
		{name="air", prob=0, param2=0},
		{name="air", prob=0, param2=0},
		{name="air", prob=0, param2=0},
		{name="air", prob=0, param2=0},
		{name="air", prob=0, param2=0},
		{name="air", prob=0, param2=0},
		{name="air", prob=0, param2=0},
		{name="air", prob=0, param2=0},
		{name="air", prob=0, param2=0},
		{name="air", prob=0, param2=0},
		{name="air", prob=0, param2=0},
		{name="air", prob=0, param2=0},
		{name="air", prob=0, param2=0},
		{name="air", prob=0, param2=0},
		{name="air", prob=0, param2=0},
		{name="air", prob=0, param2=0},
		{name="air", prob=0, param2=0},
		{name="air", prob=0, param2=0},
		{name="air", prob=0, param2=0},
		{name="air", prob=0, param2=0},
		{name="air", prob=0, param2=0},
		{name="air", prob=0, param2=0},
		{name="everness:frosted_snowblock", prob=254, param2=0},
		{name="air", prob=0, param2=0},
		{name="air", prob=0, param2=0},
		{name="air", prob=0, param2=0},
		{name="air", prob=0, param2=0},
		{name="air", prob=0, param2=0},
		{name="air", prob=0, param2=0},
		{name="air", prob=0, param2=0},
		{name="air", prob=0, param2=0},
		{name="air", prob=0, param2=0},
		{name="air", prob=0, param2=0},
		{name="air", prob=0, param2=0},
		{name="air", prob=0, param2=0},
		{name="air", prob=0, param2=0},
		{name="air", prob=0, param2=0},
		{name="everness:frosted_snowblock", prob=254, param2=0},
		{name="everness:frosted_snowblock", prob=254, param2=0},
		{name="everness:frosted_snowblock", prob=254, param2=0},
		{name="everness:frosted_snowblock", prob=254, param2=0},
		{name="everness:frosted_snowblock", prob=254, param2=0},
		{name="air", prob=0, param2=0},
		{name="air", prob=0, param2=0},
		{name="air", prob=0, param2=0},
		{name="air", prob=0, param2=0},
		{name="air", prob=0, param2=0},
		{name="air", prob=0, param2=0},
		{name="air", prob=0, param2=0},
		{name="air", prob=0, param2=0},
		{name="air", prob=0, param2=0},
		{name="air", prob=0, param2=0},
		{name="everness:frosted_snowblock", prob=254, param2=0},
		{name="everness:frosted_snowblock", prob=254, param2=0},
		{name="everness:frosted_snowblock", prob=254, param2=0},
		{name="everness:frosted_snowblock", prob=254, param2=0},
		{name="everness:frosted_snowblock", prob=254, param2=0},
		{name="everness:frosted_snowblock", prob=254, param2=0},
		{name="everness:frosted_snowblock", prob=254, param2=0},
		{name="everness:frosted_snowblock", prob=254, param2=0},
		{name="everness:frosted_snowblock", prob=254, param2=0},
		{name="air", prob=0, param2=0},
		{name="air", prob=0, param2=0},
		{name="air", prob=0, param2=0},
		{name="air", prob=0, param2=0},
		{name="air", prob=0, param2=0},
		{name="air", prob=0, param2=0},
		{name="everness:frosted_snowblock", prob=254, param2=0},
		{name="everness:frosted_snowblock", prob=254, param2=0},
		{name="everness:frosted_snowblock", prob=254, param2=0},
		{name="everness:frosted_snowblock", prob=254, param2=0},
		{name="everness:frosted_snowblock", prob=254, param2=0},
		{name="everness:frosted_snowblock", prob=254, param2=0},
		{name="everness:frosted_snowblock", prob=254, param2=0},
		{name="everness:frosted_snowblock", prob=254, param2=0},
		{name="everness:frosted_snowblock", prob=254, param2=0},
		{name="everness:frosted_snowblock", prob=254, param2=0},
		{name="everness:frosted_snowblock", prob=254, param2=0},
		{name="everness:frosted_snowblock", prob=254, param2=0},
		{name="everness:frosted_snowblock", prob=254, param2=0},
		{name="air", prob=0, param2=0},
		{name="air", prob=0, param2=0},
		{name="air", prob=0, param2=0},
		{name="everness:frosted_snowblock", prob=254, param2=0},
		{name="everness:frosted_snowblock", prob=254, param2=0},
		{name="everness:frosted_snowblock", prob=254, param2=0},
		{name="everness:frosted_snowblock", prob=254, param2=0},
		{name="everness:frosted_snowblock", prob=254, param2=0},
		{name="everness:frosted_snowblock", prob=254, param2=0},
		{name="everness:frosted_snowblock", prob=254, param2=0},
		{name="everness:frosted_snowblock", prob=254, param2=0},
		{name="everness:frosted_snowblock", prob=254, param2=0},
		{name="everness:frosted_snowblock", prob=254, param2=0},
		{name="everness:frosted_snowblock", prob=254, param2=0},
		{name="everness:frosted_snowblock", prob=254, param2=0},
		{name="everness:frosted_snowblock", prob=254, param2=0},
		{name="everness:frosted_snowblock", prob=254, param2=0},
		{name="everness:frosted_snowblock", prob=254, param2=0},
		{name="air", prob=0, param2=0},
		{name="everness:frosted_snowblock", prob=254, param2=0},
		{name="everness:frosted_snowblock", prob=254, param2=0},
		{name="everness:frosted_snowblock", prob=254, param2=0},
		{name="everness:frosted_snowblock", prob=254, param2=0},
		{name="everness:frosted_snowblock", prob=254, param2=0},
		{name="everness:frosted_snowblock", prob=254, param2=0},
		{name="everness:frosted_snowblock", prob=254, param2=0},
		{name="everness:frosted_snowblock", prob=254, param2=0},
		{name="everness:frosted_snowblock", prob=254, param2=0},
		{name="everness:frosted_snowblock", prob=254, param2=0},
		{name="everness:frosted_snowblock", prob=254, param2=0},
		{name="everness:frosted_snowblock", prob=254, param2=0},
		{name="everness:frosted_snowblock", prob=254, param2=0},
		{name="everness:frosted_snowblock", prob=254, param2=0},
		{name="everness:frosted_snowblock", prob=254, param2=0},
		{name="everness:frosted_snowblock", prob=254, param2=0},
		{name="everness:frosted_snowblock", prob=254, param2=0},
		{name="everness:frosted_snowblock", prob=254, param2=0},
		{name="everness:snowcobble", prob=254, param2=0},
		{name="default:junglewood", prob=254, param2=0},
		{name="default:pine_wood", prob=254, param2=0},
		{name="default:junglewood", prob=254, param2=0},
		{name="default:junglewood", prob=254, param2=0},
		{name="default:wood", prob=254, param2=0},
		{name="default:junglewood", prob=254, param2=0},
		{name="default:wood", prob=254, param2=0},
		{name="default:junglewood", prob=254, param2=0},
		{name="default:wood", prob=254, param2=0},
		{name="default:wood", prob=254, param2=0},
		{name="default:junglewood", prob=254, param2=0},
		{name="default:pine_wood", prob=254, param2=0},
		{name="default:junglewood", prob=254, param2=0},
		{name="everness:snowcobble", prob=254, param2=0},
		{name="everness:frosted_snowblock", prob=254, param2=0},
		{name="air", prob=0, param2=0},
		{name="default:pine_tree", prob=254, param2=1},
		{name="default:pine_tree", prob=254, param2=3},
		{name="air", prob=254, param2=0},
		{name="air", prob=254, param2=0},
		{name="air", prob=254, param2=0},
		{name="air", prob=254, param2=0},
		{name="air", prob=254, param2=0},
		{name="air", prob=254, param2=0},
		{name="air", prob=254, param2=0},
		{name="air", prob=254, param2=0},
		{name="air", prob=254, param2=0},
		{name="air", prob=254, param2=0},
		{name="air", prob=254, param2=0},
		{name="default:pine_tree", prob=254, param2=1},
		{name="default:pine_tree", prob=254, param2=3},
		{name="air", prob=0, param2=0},
		{name="air", prob=0, param2=0},
		{name="default:pine_tree", prob=254, param2=1},
		{name="default:pine_tree", prob=254, param2=3},
		{name="air", prob=254, param2=0},
		{name="air", prob=254, param2=0},
		{name="air", prob=254, param2=0},
		{name="air", prob=254, param2=0},
		{name="air", prob=254, param2=0},
		{name="air", prob=254, param2=0},
		{name="air", prob=254, param2=0},
		{name="air", prob=254, param2=0},
		{name="air", prob=254, param2=0},
		{name="air", prob=254, param2=0},
		{name="air", prob=254, param2=0},
		{name="default:pine_tree", prob=254, param2=1},
		{name="default:pine_tree", prob=254, param2=3},
		{name="air", prob=0, param2=0},
		{name="air", prob=0, param2=0},
		{name="default:pine_tree", prob=254, param2=1},
		{name="default:pine_tree", prob=254, param2=3},
		{name="air", prob=254, param2=0},
		{name="air", prob=254, param2=0},
		{name="air", prob=254, param2=0},
		{name="air", prob=254, param2=0},
		{name="air", prob=254, param2=0},
		{name="air", prob=254, param2=0},
		{name="air", prob=254, param2=0},
		{name="air", prob=254, param2=0},
		{name="air", prob=254, param2=0},
		{name="air", prob=254, param2=0},
		{name="air", prob=254, param2=0},
		{name="default:pine_tree", prob=254, param2=1},
		{name="default:pine_tree", prob=254, param2=3},
		{name="air", prob=0, param2=0},
		{name="air", prob=0, param2=0},
		{name="stairs:stair_junglewood", prob=254, param2=0},
		{name="everness:frosted_snowblock", prob=254, param2=0},
		{name="everness:frosted_snowblock", prob=254, param2=0},
		{name="air", prob=254, param2=0},
		{name="air", prob=254, param2=0},
		{name="air", prob=254, param2=0},
		{name="air", prob=254, param2=0},
		{name="air", prob=254, param2=0},
		{name="air", prob=254, param2=0},
		{name="air", prob=254, param2=0},
		{name="air", prob=254, param2=0},
		{name="air", prob=254, param2=0},
		{name="everness:frosted_snowblock", prob=254, param2=0},
		{name="everness:frosted_snowblock", prob=254, param2=0},
		{name="stairs:stair_junglewood", prob=254, param2=0},
		{name="air", prob=0, param2=0},
		{name="air", prob=0, param2=0},
		{name="air", prob=0, param2=0},
		{name="air", prob=0, param2=0},
		{name="air", prob=0, param2=0},
		{name="everness:frosted_snowblock", prob=254, param2=0},
		{name="air", prob=254, param2=0},
		{name="air", prob=254, param2=0},
		{name="air", prob=254, param2=0},
		{name="air", prob=254, param2=0},
		{name="air", prob=254, param2=0},
		{name="air", prob=254, param2=0},
		{name="air", prob=254, param2=0},
		{name="everness:frosted_snowblock", prob=254, param2=0},
		{name="air", prob=0, param2=0},
		{name="air", prob=0, param2=0},
		{name="air", prob=0, param2=0},
		{name="air", prob=0, param2=0},
		{name="air", prob=0, param2=0},
		{name="air", prob=0, param2=0},
		{name="air", prob=0, param2=0},
		{name="air", prob=0, param2=0},
		{name="air", prob=0, param2=0},
		{name="everness:frosted_snowblock", prob=254, param2=0},
		{name="everness:frosted_snowblock", prob=254, param2=0},
		{name="everness:frosted_snowblock", prob=254, param2=0},
		{name="air", prob=254, param2=0},
		{name="everness:frosted_snowblock", prob=254, param2=0},
		{name="everness:frosted_snowblock", prob=254, param2=0},
		{name="everness:frosted_snowblock", prob=254, param2=0},
		{name="air", prob=0, param2=0},
		{name="air", prob=0, param2=0},
		{name="air", prob=0, param2=0},
		{name="air", prob=0, param2=0},
		{name="air", prob=0, param2=0},
		{name="air", prob=0, param2=0},
		{name="air", prob=0, param2=0},
		{name="air", prob=0, param2=0},
		{name="air", prob=0, param2=0},
		{name="air", prob=0, param2=0},
		{name="air", prob=0, param2=0},
		{name="air", prob=0, param2=0},
		{name="air", prob=0, param2=0},
		{name="everness:frosted_snowblock", prob=254, param2=0},
		{name="air", prob=0, param2=0},
		{name="air", prob=0, param2=0},
		{name="air", prob=0, param2=0},
		{name="air", prob=0, param2=0},
		{name="air", prob=0, param2=0},
		{name="air", prob=0, param2=0},
		{name="air", prob=0, param2=0},
		{name="air", prob=0, param2=0},
		{name="air", prob=0, param2=0},
		{name="air", prob=0, param2=0},
		{name="air", prob=0, param2=0},
		{name="air", prob=0, param2=0},
		{name="air", prob=0, param2=0},
		{name="air", prob=0, param2=0},
		{name="air", prob=0, param2=0},
		{name="air", prob=0, param2=0},
		{name="air", prob=0, param2=0},
		{name="air", prob=0, param2=0},
		{name="air", prob=0, param2=0},
		{name="air", prob=0, param2=0},
		{name="air", prob=0, param2=0},
		{name="air", prob=0, param2=0},
		{name="air", prob=0, param2=0},
		{name="air", prob=0, param2=0},
		{name="air", prob=0, param2=0},
		{name="air", prob=0, param2=0},
		{name="air", prob=0, param2=0},
		{name="air", prob=0, param2=0},
		{name="air", prob=0, param2=0},
		{name="air", prob=0, param2=0},
		{name="air", prob=0, param2=0},
		{name="air", prob=0, param2=0},
		{name="air", prob=0, param2=0},
		{name="air", prob=0, param2=0},
		{name="air", prob=0, param2=0},
		{name="air", prob=0, param2=0},
		{name="air", prob=0, param2=0},
		{name="air", prob=0, param2=0},
		{name="air", prob=0, param2=0},
		{name="air", prob=0, param2=0},
		{name="air", prob=0, param2=0},
		{name="air", prob=0, param2=0},
		{name="air", prob=0, param2=0},
		{name="air", prob=0, param2=0},
		{name="air", prob=0, param2=0},
		{name="air", prob=0, param2=0},
		{name="air", prob=0, param2=0},
		{name="air", prob=0, param2=0},
		{name="air", prob=0, param2=0},
		{name="air", prob=0, param2=0},
		{name="everness:frosted_snowblock", prob=254, param2=0},
		{name="air", prob=0, param2=0},
		{name="air", prob=0, param2=0},
		{name="air", prob=0, param2=0},
		{name="air", prob=0, param2=0},
		{name="air", prob=0, param2=0},
		{name="air", prob=0, param2=0},
		{name="air", prob=0, param2=0},
		{name="air", prob=0, param2=0},
		{name="air", prob=0, param2=0},
		{name="air", prob=0, param2=0},
		{name="air", prob=0, param2=0},
		{name="air", prob=0, param2=0},
		{name="air", prob=0, param2=0},
		{name="air", prob=0, param2=0},
		{name="air", prob=0, param2=0},
		{name="everness:frosted_snowblock", prob=254, param2=0},
		{name="everness:frosted_snowblock", prob=254, param2=0},
		{name="everness:frosted_snowblock", prob=254, param2=0},
		{name="air", prob=0, param2=0},
		{name="air", prob=0, param2=0},
		{name="air", prob=0, param2=0},
		{name="air", prob=0, param2=0},
		{name="air", prob=0, param2=0},
		{name="air", prob=0, param2=0},
		{name="air", prob=0, param2=0},
		{name="air", prob=0, param2=0},
		{name="air", prob=0, param2=0},
		{name="air", prob=0, param2=0},
		{name="air", prob=0, param2=0},
		{name="air", prob=0, param2=0},
		{name="everness:frosted_snowblock", prob=254, param2=0},
		{name="everness:frosted_snowblock", prob=254, param2=0},
		{name="everness:frosted_snowblock", prob=254, param2=0},
		{name="everness:frosted_snowblock", prob=254, param2=0},
		{name="everness:frosted_snowblock", prob=254, param2=0},
		{name="everness:frosted_snowblock", prob=254, param2=0},
		{name="everness:frosted_snowblock", prob=254, param2=0},
		{name="air", prob=0, param2=0},
		{name="air", prob=0, param2=0},
		{name="air", prob=0, param2=0},
		{name="air", prob=0, param2=0},
		{name="air", prob=0, param2=0},
		{name="air", prob=0, param2=0},
		{name="air", prob=0, param2=0},
		{name="air", prob=0, param2=0},
		{name="everness:frosted_snowblock", prob=254, param2=0},
		{name="everness:frosted_snowblock", prob=254, param2=0},
		{name="everness:frosted_snowblock", prob=254, param2=0},
		{name="everness:frosted_snowblock", prob=254, param2=0},
		{name="everness:frosted_snowblock", prob=254, param2=0},
		{name="everness:frosted_snowblock", prob=254, param2=0},
		{name="everness:frosted_snowblock", prob=254, param2=0},
		{name="everness:frosted_snowblock", prob=254, param2=0},
		{name="everness:frosted_snowblock", prob=254, param2=0},
		{name="everness:frosted_snowblock", prob=254, param2=0},
		{name="everness:frosted_snowblock", prob=254, param2=0},
		{name="air", prob=0, param2=0},
		{name="air", prob=0, param2=0},
		{name="air", prob=0, param2=0},
		{name="air", prob=0, param2=0},
		{name="air", prob=0, param2=0},
		{name="everness:frosted_snowblock", prob=254, param2=0},
		{name="everness:frosted_snowblock", prob=254, param2=0},
		{name="everness:frosted_snowblock", prob=254, param2=0},
		{name="everness:frosted_snowblock", prob=254, param2=0},
		{name="everness:frosted_snowblock", prob=254, param2=0},
		{name="everness:frosted_snowblock", prob=254, param2=0},
		{name="everness:frosted_snowblock", prob=254, param2=0},
		{name="everness:frosted_snowblock", prob=254, param2=0},
		{name="everness:frosted_snowblock", prob=254, param2=0},
		{name="everness:frosted_snowblock", prob=254, param2=0},
		{name="everness:frosted_snowblock", prob=254, param2=0},
		{name="everness:frosted_snowblock", prob=254, param2=0},
		{name="everness:frosted_snowblock", prob=254, param2=0},
		{name="air", prob=0, param2=0},
		{name="air", prob=0, param2=0},
		{name="air", prob=0, param2=0},
		{name="everness:frosted_snowblock", prob=254, param2=0},
		{name="everness:frosted_snowblock", prob=254, param2=0},
		{name="everness:frosted_snowblock", prob=254, param2=0},
		{name="everness:frosted_snowblock", prob=254, param2=0},
		{name="everness:frosted_snowblock", prob=254, param2=0},
		{name="everness:frosted_snowblock", prob=254, param2=0},
		{name="everness:frosted_snowblock", prob=254, param2=0},
		{name="everness:frosted_snowblock", prob=254, param2=0},
		{name="everness:frosted_snowblock", prob=254, param2=0},
		{name="everness:frosted_snowblock", prob=254, param2=0},
		{name="everness:frosted_snowblock", prob=254, param2=0},
		{name="everness:frosted_snowblock", prob=254, param2=0},
		{name="everness:frosted_snowblock", prob=254, param2=0},
		{name="everness:frosted_snowblock", prob=254, param2=0},
		{name="everness:frosted_snowblock", prob=254, param2=0},
		{name="air", prob=0, param2=0},
		{name="everness:frosted_snowblock", prob=254, param2=0},
		{name="everness:frosted_snowblock", prob=254, param2=0},
		{name="everness:frosted_snowblock", prob=254, param2=0},
		{name="everness:frosted_snowblock", prob=254, param2=0},
		{name="everness:frosted_snowblock", prob=254, param2=0},
		{name="everness:frosted_snowblock", prob=254, param2=0},
		{name="everness:frosted_snowblock", prob=254, param2=0},
		{name="everness:frosted_snowblock", prob=254, param2=0},
		{name="everness:frosted_snowblock", prob=254, param2=0},
		{name="everness:frosted_snowblock", prob=254, param2=0},
		{name="everness:frosted_snowblock", prob=254, param2=0},
		{name="everness:frosted_snowblock", prob=254, param2=0},
		{name="everness:frosted_snowblock", prob=254, param2=0},
		{name="everness:frosted_snowblock", prob=254, param2=0},
		{name="everness:frosted_snowblock", prob=254, param2=0},
		{name="everness:frosted_snowblock", prob=254, param2=0},
		{name="everness:frosted_snowblock", prob=254, param2=0},
		{name="everness:frosted_snowblock", prob=254, param2=0},
		{name="everness:snowcobble", prob=254, param2=0},
		{name="default:junglewood", prob=254, param2=0},
		{name="default:pine_wood", prob=254, param2=0},
		{name="default:wood", prob=254, param2=0},
		{name="default:junglewood", prob=254, param2=0},
		{name="default:junglewood", prob=254, param2=0},
		{name="default:junglewood", prob=254, param2=0},
		{name="default:junglewood", prob=254, param2=0},
		{name="default:wood", prob=254, param2=0},
		{name="default:junglewood", prob=254, param2=0},
		{name="default:junglewood", prob=254, param2=0},
		{name="default:wood", prob=254, param2=0},
		{name="default:pine_wood", prob=254, param2=0},
		{name="default:junglewood", prob=254, param2=0},
		{name="everness:snowcobble", prob=254, param2=0},
		{name="everness:frosted_snowblock", prob=254, param2=0},
		{name="air", prob=0, param2=0},
		{name="air", prob=0, param2=0},
		{name="default:pine_tree", prob=254, param2=1},
		{name="air", prob=254, param2=0},
		{name="air", prob=254, param2=0},
		{name="air", prob=254, param2=0},
		{name="air", prob=254, param2=0},
		{name="air", prob=254, param2=0},
		{name="air", prob=254, param2=0},
		{name="air", prob=254, param2=0},
		{name="air", prob=254, param2=0},
		{name="air", prob=254, param2=0},
		{name="air", prob=254, param2=0},
		{name="air", prob=254, param2=0},
		{name="default:pine_tree", prob=254, param2=1},
		{name="air", prob=0, param2=0},
		{name="air", prob=0, param2=0},
		{name="air", prob=0, param2=0},
		{name="air", prob=0, param2=0},
		{name="default:pine_tree", prob=254, param2=0},
		{name="air", prob=254, param2=0},
		{name="air", prob=254, param2=0},
		{name="air", prob=254, param2=0},
		{name="air", prob=254, param2=0},
		{name="air", prob=254, param2=0},
		{name="air", prob=254, param2=0},
		{name="air", prob=254, param2=0},
		{name="air", prob=254, param2=0},
		{name="air", prob=254, param2=0},
		{name="air", prob=254, param2=0},
		{name="air", prob=254, param2=0},
		{name="default:pine_tree", prob=254, param2=1},
		{name="air", prob=0, param2=0},
		{name="air", prob=0, param2=0},
		{name="air", prob=0, param2=0},
		{name="air", prob=0, param2=0},
		{name="default:pine_tree", prob=254, param2=0},
		{name="air", prob=254, param2=0},
		{name="air", prob=254, param2=0},
		{name="air", prob=254, param2=0},
		{name="air", prob=254, param2=0},
		{name="air", prob=254, param2=0},
		{name="air", prob=254, param2=0},
		{name="air", prob=254, param2=0},
		{name="air", prob=254, param2=0},
		{name="air", prob=254, param2=0},
		{name="air", prob=254, param2=0},
		{name="air", prob=254, param2=0},
		{name="default:pine_tree", prob=254, param2=1},
		{name="air", prob=0, param2=0},
		{name="air", prob=0, param2=0},
		{name="air", prob=0, param2=0},
		{name="stairs:stair_junglewood", prob=254, param2=22},
		{name="default:pine_tree", prob=254, param2=0},
		{name="air", prob=254, param2=0},
		{name="air", prob=254, param2=0},
		{name="air", prob=254, param2=0},
		{name="air", prob=254, param2=0},
		{name="air", prob=254, param2=0},
		{name="air", prob=254, param2=0},
		{name="air", prob=254, param2=0},
		{name="air", prob=254, param2=0},
		{name="air", prob=254, param2=0},
		{name="air", prob=254, param2=0},
		{name="air", prob=254, param2=0},
		{name="default:pine_tree", prob=254, param2=2},
		{name="stairs:stair_junglewood", prob=254, param2=22},
		{name="air", prob=0, param2=0},
		{name="air", prob=0, param2=0},
		{name="stairs:slab_junglewood", prob=254, param2=2},
		{name="everness:frosted_snowblock", prob=254, param2=0},
		{name="everness:frosted_snowblock", prob=254, param2=0},
		{name="everness:frosted_snowblock", prob=254, param2=0},
		{name="air", prob=254, param2=0},
		{name="air", prob=254, param2=0},
		{name="air", prob=254, param2=0},
		{name="air", prob=254, param2=0},
		{name="air", prob=254, param2=0},
		{name="air", prob=254, param2=0},
		{name="air", prob=254, param2=0},
		{name="everness:frosted_snowblock", prob=254, param2=0},
		{name="everness:frosted_snowblock", prob=254, param2=0},
		{name="everness:frosted_snowblock", prob=254, param2=0},
		{name="stairs:slab_junglewood", prob=254, param2=3},
		{name="air", prob=0, param2=0},
		{name="air", prob=0, param2=0},
		{name="air", prob=0, param2=0},
		{name="air", prob=0, param2=0},
		{name="air", prob=0, param2=0},
		{name="air", prob=0, param2=0},
		{name="everness:frosted_snowblock", prob=254, param2=0},
		{name="everness:frosted_snowblock", prob=254, param2=0},
		{name="air", prob=254, param2=0},
		{name="air", prob=254, param2=0},
		{name="air", prob=254, param2=0},
		{name="everness:frosted_snowblock", prob=254, param2=0},
		{name="everness:frosted_snowblock", prob=254, param2=0},
		{name="air", prob=0, param2=0},
		{name="air", prob=0, param2=0},
		{name="air", prob=0, param2=0},
		{name="air", prob=0, param2=0},
		{name="air", prob=0, param2=0},
		{name="air", prob=0, param2=0},
		{name="air", prob=0, param2=0},
		{name="air", prob=0, param2=0},
		{name="air", prob=0, param2=0},
		{name="air", prob=0, param2=0},
		{name="air", prob=0, param2=0},
		{name="air", prob=0, param2=0},
		{name="everness:frosted_snowblock", prob=254, param2=0},
		{name="everness:frosted_snowblock", prob=254, param2=0},
		{name="everness:frosted_snowblock", prob=254, param2=0},
		{name="air", prob=0, param2=0},
		{name="air", prob=0, param2=0},
		{name="air", prob=0, param2=0},
		{name="air", prob=0, param2=0},
		{name="air", prob=0, param2=0},
		{name="air", prob=0, param2=0},
		{name="air", prob=0, param2=0},
		{name="air", prob=0, param2=0},
		{name="air", prob=0, param2=0},
		{name="air", prob=0, param2=0},
		{name="air", prob=0, param2=0},
		{name="air", prob=0, param2=0},
		{name="air", prob=0, param2=0},
		{name="air", prob=0, param2=0},
		{name="air", prob=0, param2=0},
		{name="air", prob=0, param2=0},
		{name="air", prob=0, param2=0},
		{name="air", prob=0, param2=0},
		{name="air", prob=0, param2=0},
		{name="air", prob=0, param2=0},
		{name="air", prob=0, param2=0},
		{name="air", prob=0, param2=0},
		{name="air", prob=0, param2=0},
		{name="air", prob=0, param2=0},
		{name="air", prob=0, param2=0},
		{name="air", prob=0, param2=0},
		{name="air", prob=0, param2=0},
		{name="air", prob=0, param2=0},
		{name="air", prob=0, param2=0},
		{name="air", prob=0, param2=0},
		{name="air", prob=0, param2=0},
		{name="air", prob=0, param2=0},
		{name="everness:frosted_snowblock", prob=254, param2=0},
		{name="air", prob=0, param2=0},
		{name="air", prob=0, param2=0},
		{name="air", prob=0, param2=0},
		{name="air", prob=0, param2=0},
		{name="air", prob=0, param2=0},
		{name="air", prob=0, param2=0},
		{name="air", prob=0, param2=0},
		{name="air", prob=0, param2=0},
		{name="air", prob=0, param2=0},
		{name="air", prob=0, param2=0},
		{name="air", prob=0, param2=0},
		{name="air", prob=0, param2=0},
		{name="air", prob=0, param2=0},
		{name="air", prob=0, param2=0},
		{name="air", prob=0, param2=0},
		{name="everness:frosted_snowblock", prob=254, param2=0},
		{name="everness:frosted_snowblock", prob=254, param2=0},
		{name="everness:frosted_snowblock", prob=254, param2=0},
		{name="air", prob=0, param2=0},
		{name="air", prob=0, param2=0},
		{name="air", prob=0, param2=0},
		{name="air", prob=0, param2=0},
		{name="air", prob=0, param2=0},
		{name="air", prob=0, param2=0},
		{name="air", prob=0, param2=0},
		{name="air", prob=0, param2=0},
		{name="air", prob=0, param2=0},
		{name="air", prob=0, param2=0},
		{name="air", prob=0, param2=0},
		{name="air", prob=0, param2=0},
		{name="air", prob=0, param2=0},
		{name="everness:frosted_snowblock", prob=254, param2=0},
		{name="everness:frosted_snowblock", prob=254, param2=0},
		{name="everness:frosted_snowblock", prob=254, param2=0},
		{name="everness:frosted_snowblock", prob=254, param2=0},
		{name="everness:frosted_snowblock", prob=254, param2=0},
		{name="air", prob=0, param2=0},
		{name="air", prob=0, param2=0},
		{name="air", prob=0, param2=0},
		{name="air", prob=0, param2=0},
		{name="air", prob=0, param2=0},
		{name="air", prob=0, param2=0},
		{name="air", prob=0, param2=0},
		{name="air", prob=0, param2=0},
		{name="air", prob=0, param2=0},
		{name="air", prob=0, param2=0},
		{name="everness:frosted_snowblock", prob=254, param2=0},
		{name="everness:frosted_snowblock", prob=254, param2=0},
		{name="everness:frosted_snowblock", prob=254, param2=0},
		{name="everness:frosted_snowblock", prob=254, param2=0},
		{name="everness:frosted_snowblock", prob=254, param2=0},
		{name="everness:frosted_snowblock", prob=254, param2=0},
		{name="everness:frosted_snowblock", prob=254, param2=0},
		{name="everness:frosted_snowblock", prob=254, param2=0},
		{name="everness:frosted_snowblock", prob=254, param2=0},
		{name="air", prob=0, param2=0},
		{name="air", prob=0, param2=0},
		{name="air", prob=0, param2=0},
		{name="air", prob=0, param2=0},
		{name="air", prob=0, param2=0},
		{name="air", prob=0, param2=0},
		{name="air", prob=0, param2=0},
		{name="everness:frosted_snowblock", prob=254, param2=0},
		{name="everness:frosted_snowblock", prob=254, param2=0},
		{name="everness:frosted_snowblock", prob=254, param2=0},
		{name="everness:frosted_snowblock", prob=254, param2=0},
		{name="everness:frosted_snowblock", prob=254, param2=0},
		{name="everness:frosted_snowblock", prob=254, param2=0},
		{name="everness:frosted_snowblock", prob=254, param2=0},
		{name="everness:frosted_snowblock", prob=254, param2=0},
		{name="everness:frosted_snowblock", prob=254, param2=0},
		{name="everness:frosted_snowblock", prob=254, param2=0},
		{name="everness:frosted_snowblock", prob=254, param2=0},
		{name="air", prob=0, param2=0},
		{name="air", prob=0, param2=0},
		{name="air", prob=0, param2=0},
		{name="air", prob=0, param2=0},
		{name="air", prob=0, param2=0},
		{name="everness:frosted_snowblock", prob=254, param2=0},
		{name="everness:frosted_snowblock", prob=254, param2=0},
		{name="everness:frosted_snowblock", prob=254, param2=0},
		{name="everness:frosted_snowblock", prob=254, param2=0},
		{name="everness:frosted_snowblock", prob=254, param2=0},
		{name="everness:frosted_snowblock", prob=254, param2=0},
		{name="everness:frosted_snowblock", prob=254, param2=0},
		{name="everness:frosted_snowblock", prob=254, param2=0},
		{name="everness:frosted_snowblock", prob=254, param2=0},
		{name="everness:frosted_snowblock", prob=254, param2=0},
		{name="everness:frosted_snowblock", prob=254, param2=0},
		{name="everness:frosted_snowblock", prob=254, param2=0},
		{name="everness:frosted_snowblock", prob=254, param2=0},
		{name="air", prob=0, param2=0},
		{name="air", prob=0, param2=0},
		{name="air", prob=0, param2=0},
		{name="everness:frosted_snowblock", prob=254, param2=0},
		{name="everness:frosted_snowblock", prob=254, param2=0},
		{name="everness:frosted_snowblock", prob=254, param2=0},
		{name="everness:frosted_snowblock", prob=254, param2=0},
		{name="everness:frosted_snowblock", prob=254, param2=0},
		{name="everness:frosted_snowblock", prob=254, param2=0},
		{name="everness:frosted_snowblock", prob=254, param2=0},
		{name="everness:frosted_snowblock", prob=254, param2=0},
		{name="everness:frosted_snowblock", prob=254, param2=0},
		{name="everness:frosted_snowblock", prob=254, param2=0},
		{name="everness:frosted_snowblock", prob=254, param2=0},
		{name="everness:frosted_snowblock", prob=254, param2=0},
		{name="everness:frosted_snowblock", prob=254, param2=0},
		{name="everness:frosted_snowblock", prob=254, param2=0},
		{name="everness:frosted_snowblock", prob=254, param2=0},
		{name="air", prob=0, param2=0},
		{name="everness:frosted_snowblock", prob=254, param2=0},
		{name="everness:frosted_snowblock", prob=254, param2=0},
		{name="everness:frosted_snowblock", prob=254, param2=0},
		{name="everness:frosted_snowblock", prob=254, param2=0},
		{name="everness:frosted_snowblock", prob=254, param2=0},
		{name="everness:frosted_snowblock", prob=254, param2=0},
		{name="everness:frosted_snowblock", prob=254, param2=0},
		{name="everness:frosted_snowblock", prob=254, param2=0},
		{name="everness:frosted_snowblock", prob=254, param2=0},
		{name="everness:frosted_snowblock", prob=254, param2=0},
		{name="everness:frosted_snowblock", prob=254, param2=0},
		{name="everness:frosted_snowblock", prob=254, param2=0},
		{name="everness:frosted_snowblock", prob=254, param2=0},
		{name="everness:frosted_snowblock", prob=254, param2=0},
		{name="everness:frosted_snowblock", prob=254, param2=0},
		{name="everness:frosted_snowblock", prob=254, param2=0},
