schematic = {
	size = {x=4, y=6, z=4},
	yslice_prob = {
		{ypos=0, prob=254},
		{ypos=1, prob=254},
		{ypos=2, prob=254},
		{ypos=3, prob=254},
		{ypos=4, prob=254},
		{ypos=5, prob=254},
	},
	data = {
		{name="everness:forsaken_tundra_rocks", prob=126, param2=0, force_place=true},
		{name="everness:forsaken_tundra_rocks", prob=126, param2=0, force_place=true},
		{name="everness:forsaken_tundra_rocks", prob=126, param2=0, force_place=true},
		{name="everness:forsaken_tundra_rocks", prob=126, param2=0, force_place=true},
		{name="air", prob=254, param2=0},
		{name="air", prob=254, param2=0},
		{name="air", prob=254, param2=0},
		{name="air", prob=254, param2=0},
		{name="air", prob=254, param2=0},
		{name="air", prob=254, param2=0},
		{name="air", prob=254, param2=0},
		{name="air", prob=254, param2=0},
		{name="air", prob=254, param2=0},
		{name="air", prob=254, param2=0},
		{name="air", prob=254, param2=0},
		{name="air", prob=254, param2=0},
		{name="air", prob=254, param2=0},
		{name="air", prob=254, param2=0},
		{name="air", prob=254, param2=0},
		{name="air", prob=254, param2=0},
		{name="air", prob=254, param2=0},
		{name="air", prob=254, param2=0},
		{name="air", prob=254, param2=0},
		{name="air", prob=254, param2=0},
		{name="everness:forsaken_tundra_rocks", prob=126, param2=0, force_place=true},
		{name="everness:forsaken_tundra_rocks", prob=254, param2=0, force_place=true},
		{name="everness:forsaken_tundra_rocks", prob=254, param2=0, force_place=true},
		{name="everness:forsaken_tundra_rocks", prob=126, param2=0, force_place=true},
		{name="air", prob=254, param2=0},
		{name="everness:forsaken_tundra_rocks", prob=254, param2=0, force_place=true},
		{name="everness:forsaken_tundra_rocks", prob=254, param2=0, force_place=true},
		{name="air", prob=254, param2=0},
		{name="air", prob=254, param2=0},
		{name="everness:forsaken_tundra_rocks", prob=126, param2=0},
		{name="everness:forsaken_tundra_rocks", prob=126, param2=0},
		{name="air", prob=254, param2=0},
		{name="air", prob=254, param2=0},
		{name="air", prob=254, param2=0},
		{name="air", prob=254, param2=0},
		{name="air", prob=254, param2=0},
		{name="air", prob=254, param2=0},
		{name="air", prob=254, param2=0},
		{name="air", prob=254, param2=0},
		{name="air", prob=254, param2=0},
		{name="air", prob=254, param2=0},
		{name="air", prob=254, param2=0},
		{name="air", prob=254, param2=0},
		{name="air", prob=254, param2=0},
		{name="everness:forsaken_tundra_rocks", prob=126, param2=0, force_place=true},
		{name="everness:forsaken_tundra_rocks", prob=254, param2=0, force_place=true},
		{name="everness:forsaken_tundra_rocks", prob=254, param2=0, force_place=true},
		{name="everness:forsaken_tundra_rocks", prob=126, param2=0, force_place=true},
		{name="air", prob=254, param2=0},
		{name="everness:forsaken_tundra_rocks", prob=254, param2=0, force_place=true},
		{name="everness:forsaken_tundra_rocks", prob=254, param2=0, force_place=true},
		{name="air", prob=254, param2=0},
		{name="air", prob=254, param2=0},
		{name="everness:forsaken_tundra_rocks", prob=254, param2=0},
		{name="everness:forsaken_tundra_rocks", prob=126, param2=0},
		{name="air", prob=254, param2=0},
		{name="air", prob=254, param2=0},
		{name="everness:forsaken_tundra_rocks", prob=254, param2=0},
		{name="air", prob=254, param2=0},
		{name="air", prob=254, param2=0},
		{name="air", prob=254, param2=0},
		{name="everness:forsaken_tundra_rocks", prob=254, param2=0},
		{name="air", prob=254, param2=0},
		{name="air", prob=254, param2=0},
		{name="air", prob=254, param2=0},
		{name="everness:forsaken_tundra_rocks", prob=126, param2=0},
		{name="air", prob=254, param2=0},
		{name="air", prob=254, param2=0},
		{name="everness:forsaken_tundra_rocks", prob=126, param2=0, force_place=true},
		{name="everness:forsaken_tundra_rocks", prob=126, param2=0, force_place=true},
		{name="everness:forsaken_tundra_rocks", prob=126, param2=0, force_place=true},
		{name="everness:forsaken_tundra_rocks", prob=126, param2=0, force_place=true},
		{name="air", prob=254, param2=0},
		{name="air", prob=254, param2=0},
		{name="air", prob=254, param2=0},
		{name="air", prob=254, param2=0},
		{name="air", prob=254, param2=0},
		{name="air", prob=254, param2=0},
		{name="air", prob=254, param2=0},
		{name="air", prob=254, param2=0},
		{name="air", prob=254, param2=0},
		{name="air", prob=254, param2=0},
		{name="air", prob=254, param2=0},
		{name="air", prob=254, param2=0},
		{name="air", prob=254, param2=0},
		{name="air", prob=254, param2=0},
		{name="air", prob=254, param2=0},
		{name="air", prob=254, param2=0},
		{name="air", prob=254, param2=0},
		{name="air", prob=254, param2=0},
		{name="air", prob=254, param2=0},
		{name="air", prob=254, param2=0},
	},
}
