schematic = {
	size = {x=5, y=6, z=2},
	yslice_prob = {
		{ypos=0, prob=254},
		{ypos=1, prob=254},
		{ypos=2, prob=254},
		{ypos=3, prob=254},
		{ypos=4, prob=254},
		{ypos=5, prob=254},
	},
	data = {
		{name="everness:termite_block", prob=254, param2=0, force_place=true},
		{name="everness:termite_block", prob=254, param2=0, force_place=true},
		{name="everness:termite_block", prob=254, param2=0, force_place=true},
		{name="everness:termite_block", prob=254, param2=0, force_place=true},
		{name="everness:termite_block", prob=254, param2=0, force_place=true},
		{name="everness:termite_block", prob=126, param2=0},
		{name="everness:termite_block", prob=254, param2=0},
		{name="everness:termite_block", prob=254, param2=0},
		{name="everness:termite_block", prob=254, param2=0},
		{name="everness:termite_block", prob=126, param2=0},
		{name="air", prob=254, param2=0},
		{name="everness:termite_block", prob=254, param2=0},
		{name="everness:termite_block", prob=254, param2=0},
		{name="everness:termite_block", prob=126, param2=0},
		{name="air", prob=254, param2=0},
		{name="air", prob=254, param2=0},
		{name="everness:termite_block", prob=126, param2=0},
		{name="everness:termite_block", prob=254, param2=0},
		{name="air", prob=254, param2=0},
		{name="air", prob=254, param2=0},
		{name="air", prob=254, param2=0},
		{name="air", prob=254, param2=0},
		{name="everness:termite_block", prob=254, param2=0},
		{name="air", prob=254, param2=0},
		{name="air", prob=254, param2=0},
		{name="air", prob=254, param2=0},
		{name="air", prob=254, param2=0},
		{name="everness:termite_block", prob=126, param2=0},
		{name="air", prob=254, param2=0},
		{name="air", prob=254, param2=0},
		{name="air", prob=254, param2=0},
		{name="everness:termite_block", prob=254, param2=0, force_place=true},
		{name="everness:termite_block", prob=254, param2=0, force_place=true},
		{name="everness:termite_block", prob=254, param2=0, force_place=true},
		{name="air", prob=254, param2=0},
		{name="air", prob=254, param2=0},
		{name="everness:termite_block", prob=126, param2=0},
		{name="everness:termite_block", prob=254, param2=0},
		{name="everness:termite_block", prob=126, param2=0},
		{name="air", prob=254, param2=0},
		{name="air", prob=254, param2=0},
		{name="air", prob=254, param2=0},
		{name="everness:termite_block", prob=126, param2=0},
		{name="air", prob=254, param2=0},
		{name="air", prob=254, param2=0},
		{name="air", prob=254, param2=0},
		{name="air", prob=254, param2=0},
		{name="air", prob=254, param2=0},
		{name="air", prob=254, param2=0},
		{name="air", prob=254, param2=0},
		{name="air", prob=254, param2=0},
		{name="air", prob=254, param2=0},
		{name="air", prob=254, param2=0},
		{name="air", prob=254, param2=0},
		{name="air", prob=254, param2=0},
		{name="air", prob=254, param2=0},
		{name="air", prob=254, param2=0},
		{name="air", prob=254, param2=0},
		{name="air", prob=254, param2=0},
		{name="air", prob=254, param2=0},
	},
}
