schematic = {
	size = {x=16, y=13, z=16},
	yslice_prob = {
		{ypos=0, prob=254},
		{ypos=1, prob=254},
		{ypos=2, prob=254},
		{ypos=3, prob=254},
		{ypos=4, prob=254},
		{ypos=5, prob=254},
		{ypos=6, prob=254},
		{ypos=7, prob=254},
		{ypos=8, prob=254},
		{ypos=9, prob=254},
		{ypos=10, prob=254},
		{ypos=11, prob=254},
		{ypos=12, prob=254},
	},
	data = {
		{name="air", prob=0, param2=0},
		{name="air", prob=0, param2=0},
		{name="air", prob=0, param2=0},
		{name="air", prob=0, param2=0},
		{name="air", prob=0, param2=0},
		{name="everness:quartz_chiseled", prob=254, param2=0},
		{name="everness:quartz_chiseled", prob=254, param2=0},
		{name="everness:quartz_chiseled", prob=254, param2=0},
		{name="everness:quartz_chiseled", prob=254, param2=0},
		{name="everness:quartz_chiseled", prob=254, param2=0},
		{name="everness:quartz_chiseled", prob=254, param2=0},
		{name="air", prob=0, param2=0},
		{name="air", prob=0, param2=0},
		{name="air", prob=0, param2=0},
		{name="air", prob=0, param2=0},
		{name="air", prob=0, param2=0},
		{name="air", prob=0, param2=0},
		{name="air", prob=0, param2=0},
		{name="air", prob=0, param2=0},
		{name="air", prob=0, param2=0},
		{name="air", prob=0, param2=0},
		{name="stairs:stair_outer_quartz_chiseled", prob=254, param2=1},
		{name="stairs:stair_quartz_chiseled", prob=254, param2=0},
		{name="stairs:stair_quartz_chiseled", prob=254, param2=0},
		{name="stairs:stair_quartz_chiseled", prob=254, param2=0},
		{name="stairs:stair_quartz_chiseled", prob=254, param2=0},
		{name="stairs:stair_outer_quartz_chiseled", prob=254, param2=0},
		{name="air", prob=0, param2=0},
		{name="air", prob=0, param2=0},
		{name="air", prob=0, param2=0},
		{name="air", prob=0, param2=0},
		{name="air", prob=0, param2=0},
		{name="air", prob=0, param2=0},
		{name="air", prob=0, param2=0},
		{name="air", prob=0, param2=0},
		{name="air", prob=0, param2=0},
		{name="air", prob=0, param2=0},
		{name="air", prob=0, param2=0},
		{name="air", prob=0, param2=0},
		{name="air", prob=254, param2=0},
		{name="air", prob=254, param2=0},
		{name="air", prob=0, param2=0},
		{name="air", prob=0, param2=0},
		{name="air", prob=0, param2=0},
		{name="air", prob=0, param2=0},
		{name="air", prob=0, param2=0},
		{name="air", prob=0, param2=0},
		{name="air", prob=0, param2=0},
		{name="air", prob=0, param2=0},
		{name="air", prob=0, param2=0},
		{name="air", prob=0, param2=0},
		{name="air", prob=0, param2=0},
		{name="air", prob=0, param2=0},
		{name="air", prob=0, param2=0},
		{name="air", prob=0, param2=0},
		{name="air", prob=254, param2=0},
		{name="air", prob=254, param2=0},
		{name="air", prob=0, param2=0},
		{name="air", prob=0, param2=0},
		{name="air", prob=0, param2=0},
		{name="air", prob=0, param2=0},
		{name="air", prob=0, param2=0},
		{name="air", prob=0, param2=0},
		{name="air", prob=0, param2=0},
		{name="air", prob=0, param2=0},
		{name="air", prob=0, param2=0},
		{name="air", prob=0, param2=0},
		{name="air", prob=0, param2=0},
		{name="air", prob=0, param2=0},
		{name="air", prob=0, param2=0},
		{name="air", prob=0, param2=0},
		{name="air", prob=254, param2=0},
		{name="air", prob=254, param2=0},
		{name="air", prob=0, param2=0},
		{name="air", prob=0, param2=0},
		{name="air", prob=0, param2=0},
		{name="air", prob=0, param2=0},
		{name="air", prob=0, param2=0},
		{name="air", prob=0, param2=0},
		{name="air", prob=0, param2=0},
		{name="air", prob=0, param2=0},
		{name="air", prob=0, param2=0},
		{name="air", prob=0, param2=0},
		{name="air", prob=0, param2=0},
		{name="air", prob=0, param2=0},
		{name="air", prob=0, param2=0},
		{name="air", prob=0, param2=0},
		{name="air", prob=254, param2=0},
		{name="air", prob=254, param2=0},
		{name="air", prob=0, param2=0},
		{name="air", prob=0, param2=0},
		{name="air", prob=0, param2=0},
		{name="air", prob=0, param2=0},
		{name="air", prob=0, param2=0},
		{name="air", prob=0, param2=0},
		{name="air", prob=0, param2=0},
		{name="air", prob=0, param2=0},
		{name="air", prob=0, param2=0},
		{name="air", prob=0, param2=0},
		{name="air", prob=0, param2=0},
		{name="air", prob=0, param2=0},
		{name="air", prob=0, param2=0},
		{name="air", prob=0, param2=0},
		{name="air", prob=254, param2=0},
		{name="air", prob=254, param2=0},
		{name="air", prob=0, param2=0},
		{name="air", prob=0, param2=0},
		{name="air", prob=0, param2=0},
		{name="air", prob=0, param2=0},
		{name="air", prob=0, param2=0},
		{name="air", prob=0, param2=0},
		{name="air", prob=0, param2=0},
		{name="air", prob=0, param2=0},
		{name="air", prob=0, param2=0},
		{name="air", prob=0, param2=0},
		{name="air", prob=0, param2=0},
		{name="air", prob=0, param2=0},
		{name="stairs:stair_outer_quartz_chiseled", prob=254, param2=20},
		{name="stairs:stair_quartz_chiseled", prob=254, param2=20},
		{name="stairs:stair_quartz_chiseled", prob=254, param2=20},
		{name="stairs:stair_quartz_chiseled", prob=254, param2=20},
		{name="stairs:stair_quartz_chiseled", prob=254, param2=20},
		{name="stairs:stair_outer_quartz_chiseled", prob=254, param2=21},
		{name="air", prob=0, param2=0},
		{name="air", prob=0, param2=0},
		{name="air", prob=0, param2=0},
		{name="air", prob=0, param2=0},
		{name="air", prob=0, param2=0},
		{name="air", prob=0, param2=0},
		{name="air", prob=0, param2=0},
		{name="air", prob=0, param2=0},
		{name="air", prob=0, param2=0},
		{name="air", prob=0, param2=0},
		{name="air", prob=0, param2=0},
		{name="air", prob=0, param2=0},
		{name="air", prob=0, param2=0},
		{name="air", prob=0, param2=0},
		{name="air", prob=0, param2=0},
		{name="air", prob=0, param2=0},
		{name="air", prob=0, param2=0},
		{name="air", prob=0, param2=0},
		{name="air", prob=0, param2=0},
		{name="air", prob=0, param2=0},
		{name="air", prob=0, param2=0},
		{name="air", prob=0, param2=0},
		{name="air", prob=0, param2=0},
		{name="air", prob=0, param2=0},
		{name="air", prob=0, param2=0},
		{name="air", prob=0, param2=0},
		{name="air", prob=0, param2=0},
		{name="air", prob=0, param2=0},
		{name="air", prob=0, param2=0},
		{name="air", prob=0, param2=0},
		{name="air", prob=0, param2=0},
		{name="air", prob=0, param2=0},
		{name="air", prob=0, param2=0},
		{name="air", prob=0, param2=0},
		{name="air", prob=0, param2=0},
		{name="air", prob=0, param2=0},
		{name="air", prob=0, param2=0},
		{name="air", prob=0, param2=0},
		{name="air", prob=0, param2=0},
		{name="air", prob=0, param2=0},
		{name="air", prob=0, param2=0},
		{name="air", prob=0, param2=0},
		{name="air", prob=0, param2=0},
		{name="air", prob=0, param2=0},
		{name="air", prob=0, param2=0},
		{name="air", prob=0, param2=0},
		{name="air", prob=0, param2=0},
		{name="air", prob=0, param2=0},
		{name="air", prob=0, param2=0},
		{name="air", prob=0, param2=0},
		{name="air", prob=0, param2=0},
		{name="air", prob=0, param2=0},
		{name="air", prob=0, param2=0},
		{name="air", prob=0, param2=0},
		{name="air", prob=0, param2=0},
		{name="air", prob=0, param2=0},
		{name="air", prob=0, param2=0},
		{name="air", prob=0, param2=0},
		{name="air", prob=0, param2=0},
		{name="air", prob=0, param2=0},
		{name="air", prob=0, param2=0},
		{name="air", prob=0, param2=0},
		{name="air", prob=0, param2=0},
		{name="air", prob=0, param2=0},
		{name="air", prob=0, param2=0},
		{name="air", prob=0, param2=0},
		{name="air", prob=0, param2=0},
		{name="air", prob=0, param2=0},
		{name="air", prob=0, param2=0},
		{name="air", prob=0, param2=0},
		{name="air", prob=0, param2=0},
		{name="air", prob=0, param2=0},
		{name="air", prob=0, param2=0},
		{name="air", prob=0, param2=0},
		{name="air", prob=0, param2=0},
		{name="air", prob=0, param2=0},
		{name="air", prob=0, param2=0},
		{name="air", prob=0, param2=0},
		{name="air", prob=0, param2=0},
		{name="air", prob=0, param2=0},
		{name="air", prob=0, param2=0},
		{name="air", prob=0, param2=0},
		{name="air", prob=0, param2=0},
		{name="air", prob=0, param2=0},
		{name="air", prob=0, param2=0},
		{name="air", prob=0, param2=0},
		{name="air", prob=0, param2=0},
		{name="air", prob=0, param2=0},
		{name="everness:quartz_chiseled", prob=254, param2=0},
		{name="everness:quartz_chiseled", prob=254, param2=0},
		{name="everness:quartz_chiseled", prob=254, param2=0},
		{name="everness:quartz_chiseled", prob=254, param2=0},
		{name="everness:quartz_chiseled", prob=254, param2=0},
		{name="everness:quartz_chiseled", prob=254, param2=0},
		{name="everness:quartz_chiseled", prob=254, param2=0},
		{name="everness:quartz_chiseled", prob=254, param2=0},
		{name="everness:quartz_chiseled", prob=254, param2=0},
		{name="everness:quartz_chiseled", prob=254, param2=0},
		{name="air", prob=0, param2=0},
		{name="air", prob=0, param2=0},
		{name="air", prob=0, param2=0},
		{name="air", prob=0, param2=0},
		{name="air", prob=0, param2=0},
		{name="air", prob=0, param2=0},
		{name="stairs:stair_outer_quartz_chiseled", prob=254, param2=1},
		{name="stairs:stair_quartz_chiseled", prob=254, param2=0},
		{name="stairs:stair_inner_quartz_chiseled", prob=254, param2=1},
		{name="everness:quartz_chiseled", prob=254, param2=0},
		{name="everness:quartz_chiseled", prob=254, param2=0},
		{name="everness:quartz_chiseled", prob=254, param2=0},
		{name="everness:quartz_chiseled", prob=254, param2=0},
		{name="stairs:stair_inner_quartz_chiseled", prob=254, param2=0},
		{name="stairs:stair_quartz_chiseled", prob=254, param2=0},
		{name="stairs:stair_outer_quartz_chiseled", prob=254, param2=0},
		{name="air", prob=0, param2=0},
		{name="air", prob=0, param2=0},
		{name="air", prob=0, param2=0},
		{name="air", prob=0, param2=0},
		{name="air", prob=0, param2=0},
		{name="air", prob=0, param2=0},
		{name="air", prob=0, param2=0},
		{name="air", prob=0, param2=0},
		{name="air", prob=0, param2=0},
		{name="everness:quartz_pillar", prob=254, param2=0},
		{name="air", prob=254, param2=0},
		{name="air", prob=254, param2=0},
		{name="everness:quartz_pillar", prob=254, param2=0},
		{name="air", prob=0, param2=0},
		{name="air", prob=0, param2=0},
		{name="air", prob=0, param2=0},
		{name="air", prob=0, param2=0},
		{name="air", prob=0, param2=0},
		{name="air", prob=0, param2=0},
		{name="air", prob=0, param2=0},
		{name="air", prob=0, param2=0},
		{name="air", prob=0, param2=0},
		{name="air", prob=0, param2=0},
		{name="air", prob=0, param2=0},
		{name="air", prob=0, param2=0},
		{name="everness:quartz_pillar", prob=254, param2=0},
		{name="air", prob=254, param2=0},
		{name="air", prob=254, param2=0},
		{name="everness:quartz_pillar", prob=254, param2=0},
		{name="air", prob=0, param2=0},
		{name="air", prob=0, param2=0},
		{name="air", prob=0, param2=0},
		{name="air", prob=0, param2=0},
		{name="air", prob=0, param2=0},
		{name="air", prob=0, param2=0},
		{name="air", prob=0, param2=0},
		{name="air", prob=0, param2=0},
		{name="air", prob=0, param2=0},
		{name="air", prob=0, param2=0},
		{name="air", prob=0, param2=0},
		{name="air", prob=0, param2=0},
		{name="everness:quartz_pillar", prob=254, param2=0},
		{name="air", prob=254, param2=0},
		{name="air", prob=254, param2=0},
		{name="everness:quartz_pillar", prob=254, param2=0},
		{name="air", prob=0, param2=0},
		{name="air", prob=0, param2=0},
		{name="air", prob=0, param2=0},
		{name="air", prob=0, param2=0},
		{name="air", prob=0, param2=0},
		{name="air", prob=0, param2=0},
		{name="air", prob=0, param2=0},
		{name="air", prob=0, param2=0},
		{name="air", prob=0, param2=0},
		{name="air", prob=0, param2=0},
		{name="air", prob=0, param2=0},
		{name="air", prob=0, param2=0},
		{name="everness:quartz_pillar", prob=254, param2=0},
		{name="air", prob=254, param2=0},
		{name="air", prob=254, param2=0},
		{name="everness:quartz_pillar", prob=254, param2=0},
		{name="air", prob=0, param2=0},
		{name="air", prob=0, param2=0},
		{name="air", prob=0, param2=0},
		{name="air", prob=0, param2=0},
		{name="air", prob=0, param2=0},
		{name="air", prob=0, param2=0},
		{name="air", prob=0, param2=0},
		{name="air", prob=0, param2=0},
		{name="air", prob=0, param2=0},
		{name="air", prob=0, param2=0},
		{name="air", prob=0, param2=0},
		{name="air", prob=0, param2=0},
		{name="everness:quartz_pillar", prob=254, param2=0},
		{name="air", prob=254, param2=0},
		{name="air", prob=254, param2=0},
		{name="everness:quartz_pillar", prob=254, param2=0},
		{name="air", prob=0, param2=0},
		{name="air", prob=0, param2=0},
		{name="air", prob=0, param2=0},
		{name="air", prob=0, param2=0},
		{name="air", prob=0, param2=0},
		{name="air", prob=0, param2=0},
		{name="air", prob=0, param2=0},
		{name="air", prob=0, param2=0},
		{name="air", prob=0, param2=0},
		{name="stairs:stair_outer_quartz_chiseled", prob=254, param2=20},
		{name="stairs:stair_quartz_chiseled", prob=254, param2=20},
		{name="stairs:stair_inner_quartz_chiseled", prob=254, param2=20},
		{name="everness:quartz_chiseled", prob=254, param2=0},
		{name="everness:quartz_chiseled", prob=254, param2=0},
		{name="everness:quartz_chiseled", prob=254, param2=0},
		{name="everness:quartz_chiseled", prob=254, param2=0},
		{name="stairs:stair_inner_quartz_chiseled", prob=254, param2=21},
		{name="stairs:stair_quartz_chiseled", prob=254, param2=20},
		{name="stairs:stair_outer_quartz_chiseled", prob=254, param2=21},
		{name="air", prob=0, param2=0},
		{name="air", prob=0, param2=0},
		{name="air", prob=0, param2=0},
		{name="air", prob=0, param2=0},
		{name="air", prob=0, param2=0},
		{name="air", prob=0, param2=0},
		{name="air", prob=0, param2=0},
		{name="air", prob=0, param2=0},
		{name="air", prob=0, param2=0},
		{name="stairs:stair_outer_quartz_chiseled", prob=254, param2=1},
		{name="stairs:stair_quartz_chiseled", prob=254, param2=0},
		{name="stairs:stair_quartz_chiseled", prob=254, param2=0},
		{name="stairs:stair_outer_quartz_chiseled", prob=254, param2=0},
		{name="air", prob=0, param2=0},
		{name="air", prob=0, param2=0},
		{name="air", prob=0, param2=0},
		{name="air", prob=0, param2=0},
		{name="air", prob=0, param2=0},
		{name="air", prob=0, param2=0},
		{name="air", prob=0, param2=0},
		{name="air", prob=0, param2=0},
		{name="air", prob=0, param2=0},
		{name="air", prob=0, param2=0},
		{name="air", prob=0, param2=0},
		{name="air", prob=0, param2=0},
		{name="air", prob=0, param2=0},
		{name="air", prob=0, param2=0},
		{name="air", prob=0, param2=0},
		{name="air", prob=0, param2=0},
		{name="air", prob=0, param2=0},
		{name="air", prob=0, param2=0},
		{name="air", prob=0, param2=0},
		{name="air", prob=0, param2=0},
		{name="air", prob=0, param2=0},
		{name="air", prob=0, param2=0},
		{name="air", prob=0, param2=0},
		{name="air", prob=0, param2=0},
		{name="air", prob=0, param2=0},
		{name="air", prob=0, param2=0},
		{name="air", prob=0, param2=0},
		{name="air", prob=0, param2=0},
		{name="air", prob=0, param2=0},
		{name="air", prob=0, param2=0},
		{name="air", prob=0, param2=0},
		{name="air", prob=0, param2=0},
		{name="air", prob=0, param2=0},
		{name="air", prob=0, param2=0},
		{name="air", prob=0, param2=0},
		{name="air", prob=0, param2=0},
		{name="air", prob=0, param2=0},
		{name="air", prob=0, param2=0},
		{name="air", prob=0, param2=0},
		{name="air", prob=0, param2=0},
		{name="air", prob=0, param2=0},
		{name="air", prob=0, param2=0},
		{name="air", prob=0, param2=0},
		{name="air", prob=0, param2=0},
		{name="air", prob=0, param2=0},
		{name="air", prob=0, param2=0},
		{name="air", prob=0, param2=0},
		{name="air", prob=0, param2=0},
		{name="air", prob=0, param2=0},
		{name="air", prob=0, param2=0},
		{name="air", prob=0, param2=0},
		{name="air", prob=0, param2=0},
		{name="air", prob=0, param2=0},
		{name="air", prob=0, param2=0},
		{name="air", prob=0, param2=0},
		{name="air", prob=0, param2=0},
		{name="air", prob=0, param2=0},
		{name="air", prob=0, param2=0},
		{name="air", prob=0, param2=0},
		{name="air", prob=0, param2=0},
		{name="air", prob=0, param2=0},
		{name="air", prob=0, param2=0},
		{name="air", prob=0, param2=0},
		{name="air", prob=0, param2=0},
		{name="air", prob=0, param2=0},
		{name="air", prob=0, param2=0},
		{name="air", prob=0, param2=0},
		{name="air", prob=0, param2=0},
		{name="air", prob=0, param2=0},
		{name="air", prob=0, param2=0},
		{name="air", prob=0, param2=0},
		{name="air", prob=0, param2=0},
		{name="everness:quartz_chiseled", prob=254, param2=0},
		{name="everness:quartz_chiseled", prob=254, param2=0},
		{name="everness:quartz_chiseled", prob=254, param2=0},
		{name="everness:quartz_chiseled", prob=254, param2=0},
		{name="everness:quartz_chiseled", prob=254, param2=0},
		{name="everness:quartz_chiseled", prob=254, param2=0},
		{name="everness:quartz_chiseled", prob=254, param2=0},
		{name="everness:quartz_chiseled", prob=254, param2=0},
		{name="everness:quartz_chiseled", prob=254, param2=0},
		{name="everness:quartz_chiseled", prob=254, param2=0},
		{name="everness:quartz_chiseled", prob=254, param2=0},
		{name="everness:quartz_chiseled", prob=254, param2=0},
		{name="air", prob=0, param2=0},
		{name="air", prob=0, param2=0},
		{name="air", prob=0, param2=0},
		{name="air", prob=0, param2=0},
		{name="stairs:stair_outer_quartz_chiseled", prob=254, param2=1},
		{name="stairs:stair_inner_quartz_chiseled", prob=254, param2=1},
		{name="everness:quartz_chiseled", prob=254, param2=0},
		{name="everness:quartz_chiseled", prob=254, param2=0},
		{name="everness:quartz_chiseled", prob=254, param2=0},
		{name="everness:quartz_chiseled", prob=254, param2=0},
		{name="everness:quartz_chiseled", prob=254, param2=0},
		{name="everness:quartz_chiseled", prob=254, param2=0},
		{name="everness:quartz_chiseled", prob=254, param2=0},
		{name="everness:quartz_chiseled", prob=254, param2=0},
		{name="stairs:stair_inner_quartz_chiseled", prob=254, param2=0},
		{name="stairs:stair_outer_quartz_chiseled", prob=254, param2=0},
		{name="air", prob=0, param2=0},
		{name="air", prob=0, param2=0},
		{name="air", prob=0, param2=0},
		{name="air", prob=0, param2=0},
		{name="air", prob=0, param2=0},
		{name="air", prob=0, param2=0},
		{name="air", prob=254, param2=0},
		{name="air", prob=254, param2=0},
		{name="air", prob=254, param2=0},
		{name="air", prob=254, param2=0},
		{name="air", prob=254, param2=0},
		{name="air", prob=254, param2=0},
		{name="air", prob=254, param2=0},
		{name="air", prob=254, param2=0},
		{name="air", prob=0, param2=0},
		{name="air", prob=0, param2=0},
		{name="air", prob=0, param2=0},
		{name="air", prob=0, param2=0},
		{name="air", prob=0, param2=0},
		{name="air", prob=0, param2=0},
		{name="air", prob=0, param2=0},
		{name="air", prob=0, param2=0},
		{name="air", prob=254, param2=0},
		{name="air", prob=254, param2=0},
		{name="air", prob=254, param2=0},
		{name="air", prob=254, param2=0},
		{name="air", prob=254, param2=0},
		{name="air", prob=254, param2=0},
		{name="air", prob=254, param2=0},
		{name="air", prob=254, param2=0},
		{name="air", prob=0, param2=0},
		{name="air", prob=0, param2=0},
		{name="air", prob=0, param2=0},
		{name="air", prob=0, param2=0},
		{name="air", prob=0, param2=0},
		{name="air", prob=0, param2=0},
		{name="air", prob=0, param2=0},
		{name="air", prob=0, param2=0},
		{name="air", prob=254, param2=0},
		{name="air", prob=254, param2=0},
		{name="air", prob=254, param2=0},
		{name="air", prob=254, param2=0},
		{name="air", prob=254, param2=0},
		{name="air", prob=254, param2=0},
		{name="air", prob=254, param2=0},
		{name="air", prob=254, param2=0},
		{name="air", prob=0, param2=0},
		{name="air", prob=0, param2=0},
		{name="air", prob=0, param2=0},
		{name="air", prob=0, param2=0},
		{name="air", prob=0, param2=0},
		{name="air", prob=0, param2=0},
		{name="air", prob=0, param2=0},
		{name="air", prob=0, param2=0},
		{name="air", prob=254, param2=0},
		{name="air", prob=254, param2=0},
		{name="air", prob=254, param2=0},
		{name="air", prob=254, param2=0},
		{name="air", prob=254, param2=0},
		{name="air", prob=254, param2=0},
		{name="air", prob=254, param2=0},
		{name="air", prob=254, param2=0},
		{name="air", prob=0, param2=0},
		{name="air", prob=0, param2=0},
		{name="air", prob=0, param2=0},
		{name="air", prob=0, param2=0},
		{name="air", prob=0, param2=0},
		{name="air", prob=0, param2=0},
		{name="air", prob=0, param2=0},
		{name="air", prob=0, param2=0},
		{name="air", prob=254, param2=0},
		{name="air", prob=254, param2=0},
		{name="air", prob=254, param2=0},
		{name="air", prob=254, param2=0},
		{name="air", prob=254, param2=0},
		{name="air", prob=254, param2=0},
		{name="air", prob=254, param2=0},
		{name="air", prob=254, param2=0},
		{name="air", prob=0, param2=0},
		{name="air", prob=0, param2=0},
		{name="air", prob=0, param2=0},
		{name="air", prob=0, param2=0},
		{name="air", prob=0, param2=0},
		{name="air", prob=0, param2=0},
		{name="stairs:stair_outer_quartz_chiseled", prob=254, param2=20},
		{name="stairs:stair_inner_quartz_chiseled", prob=254, param2=20},
		{name="everness:quartz_chiseled", prob=254, param2=0},
		{name="everness:quartz_chiseled", prob=254, param2=0},
		{name="everness:quartz_chiseled", prob=254, param2=0},
		{name="stairs:stair_inner_quartz_chiseled", prob=254, param2=22},
		{name="stairs:stair_inner_quartz_chiseled", prob=254, param2=23},
		{name="everness:quartz_chiseled", prob=254, param2=0},
		{name="everness:quartz_chiseled", prob=254, param2=0},
		{name="everness:quartz_chiseled", prob=254, param2=0},
		{name="stairs:stair_inner_quartz_chiseled", prob=254, param2=21},
		{name="stairs:stair_outer_quartz_chiseled", prob=254, param2=21},
		{name="air", prob=0, param2=0},
		{name="air", prob=0, param2=0},
		{name="air", prob=0, param2=0},
		{name="air", prob=0, param2=0},
		{name="air", prob=0, param2=0},
		{name="air", prob=0, param2=0},
		{name="stairs:stair_outer_quartz_chiseled", prob=254, param2=1},
		{name="stairs:stair_quartz_chiseled", prob=254, param2=0},
		{name="stairs:stair_inner_quartz_chiseled", prob=254, param2=1},
		{name="everness:quartz_chiseled", prob=254, param2=0},
		{name="everness:quartz_chiseled", prob=254, param2=0},
		{name="stairs:stair_inner_quartz_chiseled", prob=254, param2=0},
		{name="stairs:stair_quartz_chiseled", prob=254, param2=0},
		{name="stairs:stair_outer_quartz_chiseled", prob=254, param2=0},
		{name="air", prob=0, param2=0},
		{name="air", prob=0, param2=0},
		{name="air", prob=0, param2=0},
		{name="air", prob=0, param2=0},
		{name="air", prob=0, param2=0},
		{name="air", prob=0, param2=0},
		{name="air", prob=0, param2=0},
		{name="air", prob=0, param2=0},
		{name="air", prob=0, param2=0},
		{name="air", prob=0, param2=0},
		{name="air", prob=0, param2=0},
		{name="stairs:stair_outer_quartz_chiseled", prob=254, param2=1},
		{name="stairs:stair_outer_quartz_chiseled", prob=254, param2=0},
		{name="air", prob=0, param2=0},
		{name="air", prob=0, param2=0},
		{name="air", prob=0, param2=0},
		{name="air", prob=0, param2=0},
		{name="air", prob=0, param2=0},
		{name="air", prob=0, param2=0},
		{name="air", prob=0, param2=0},
		{name="air", prob=0, param2=0},
		{name="air", prob=0, param2=0},
		{name="air", prob=0, param2=0},
		{name="air", prob=0, param2=0},
		{name="air", prob=0, param2=0},
		{name="air", prob=0, param2=0},
		{name="air", prob=0, param2=0},
		{name="air", prob=0, param2=0},
		{name="air", prob=0, param2=0},
		{name="air", prob=0, param2=0},
		{name="air", prob=0, param2=0},
		{name="air", prob=0, param2=0},
		{name="air", prob=0, param2=0},
		{name="air", prob=0, param2=0},
		{name="air", prob=0, param2=0},
		{name="air", prob=0, param2=0},
		{name="air", prob=0, param2=0},
		{name="air", prob=0, param2=0},
		{name="air", prob=0, param2=0},
		{name="air", prob=0, param2=0},
		{name="air", prob=0, param2=0},
		{name="air", prob=0, param2=0},
		{name="air", prob=0, param2=0},
		{name="air", prob=0, param2=0},
		{name="air", prob=0, param2=0},
		{name="air", prob=0, param2=0},
		{name="air", prob=0, param2=0},
		{name="air", prob=0, param2=0},
		{name="air", prob=0, param2=0},
		{name="air", prob=0, param2=0},
		{name="air", prob=0, param2=0},
		{name="air", prob=0, param2=0},
		{name="air", prob=0, param2=0},
		{name="air", prob=0, param2=0},
		{name="air", prob=0, param2=0},
		{name="air", prob=0, param2=0},
		{name="air", prob=0, param2=0},
		{name="air", prob=0, param2=0},
		{name="air", prob=0, param2=0},
		{name="air", prob=0, param2=0},
		{name="air", prob=0, param2=0},
		{name="air", prob=0, param2=0},
		{name="air", prob=0, param2=0},
		{name="air", prob=0, param2=0},
		{name="air", prob=0, param2=0},
		{name="air", prob=0, param2=0},
		{name="air", prob=0, param2=0},
		{name="air", prob=0, param2=0},
		{name="air", prob=0, param2=0},
		{name="everness:quartz_chiseled", prob=254, param2=0},
		{name="everness:quartz_chiseled", prob=254, param2=0},
		{name="everness:quartz_chiseled", prob=254, param2=0},
		{name="everness:quartz_chiseled", prob=254, param2=0},
		{name="everness:quartz_chiseled", prob=254, param2=0},
		{name="everness:quartz_chiseled", prob=254, param2=0},
		{name="everness:quartz_chiseled", prob=254, param2=0},
		{name="everness:quartz_chiseled", prob=254, param2=0},
		{name="everness:quartz_chiseled", prob=254, param2=0},
		{name="everness:quartz_chiseled", prob=254, param2=0},
		{name="everness:quartz_chiseled", prob=254, param2=0},
		{name="everness:quartz_chiseled", prob=254, param2=0},
		{name="everness:quartz_chiseled", prob=254, param2=0},
		{name="everness:quartz_chiseled", prob=254, param2=0},
		{name="air", prob=0, param2=0},
		{name="air", prob=0, param2=0},
		{name="stairs:stair_outer_quartz_chiseled", prob=254, param2=1},
		{name="stairs:stair_inner_quartz_chiseled", prob=254, param2=1},
		{name="everness:quartz_chiseled", prob=254, param2=0},
		{name="everness:quartz_chiseled", prob=254, param2=0},
		{name="everness:quartz_chiseled", prob=254, param2=0},
		{name="everness:quartz_chiseled", prob=254, param2=0},
		{name="everness:quartz_chiseled", prob=254, param2=0},
		{name="everness:quartz_chiseled", prob=254, param2=0},
		{name="everness:quartz_chiseled", prob=254, param2=0},
		{name="everness:quartz_chiseled", prob=254, param2=0},
		{name="everness:quartz_chiseled", prob=254, param2=0},
		{name="everness:quartz_chiseled", prob=254, param2=0},
		{name="stairs:stair_inner_quartz_chiseled", prob=254, param2=0},
		{name="stairs:stair_outer_quartz_chiseled", prob=254, param2=0},
		{name="air", prob=0, param2=0},
		{name="air", prob=0, param2=0},
		{name="air", prob=0, param2=0},
		{name="air", prob=0, param2=0},
		{name="everness:quartz_pillar", prob=254, param2=3},
		{name="air", prob=254, param2=0},
		{name="air", prob=254, param2=0},
		{name="air", prob=254, param2=0},
		{name="air", prob=254, param2=0},
		{name="air", prob=254, param2=0},
		{name="air", prob=254, param2=0},
		{name="air", prob=254, param2=0},
		{name="air", prob=254, param2=0},
		{name="everness:quartz_pillar", prob=254, param2=3},
		{name="air", prob=0, param2=0},
		{name="air", prob=0, param2=0},
		{name="air", prob=0, param2=0},
		{name="air", prob=0, param2=0},
		{name="air", prob=0, param2=0},
		{name="air", prob=0, param2=0},
		{name="everness:quartz_pillar", prob=254, param2=3},
		{name="air", prob=254, param2=0},
		{name="air", prob=254, param2=0},
		{name="air", prob=254, param2=0},
		{name="air", prob=254, param2=0},
		{name="air", prob=254, param2=0},
		{name="air", prob=254, param2=0},
		{name="air", prob=254, param2=0},
		{name="air", prob=254, param2=0},
		{name="everness:quartz_pillar", prob=254, param2=3},
		{name="air", prob=0, param2=0},
		{name="air", prob=0, param2=0},
		{name="air", prob=0, param2=0},
		{name="air", prob=0, param2=0},
		{name="air", prob=0, param2=0},
		{name="air", prob=0, param2=0},
		{name="everness:quartz_pillar", prob=254, param2=3},
		{name="air", prob=254, param2=0},
		{name="air", prob=254, param2=0},
		{name="air", prob=254, param2=0},
		{name="air", prob=254, param2=0},
		{name="air", prob=254, param2=0},
		{name="air", prob=254, param2=0},
		{name="air", prob=254, param2=0},
		{name="air", prob=254, param2=0},
		{name="everness:quartz_pillar", prob=254, param2=3},
		{name="air", prob=0, param2=0},
		{name="air", prob=0, param2=0},
		{name="air", prob=0, param2=0},
		{name="air", prob=0, param2=0},
		{name="air", prob=0, param2=0},
		{name="air", prob=0, param2=0},
		{name="everness:quartz_pillar", prob=254, param2=3},
		{name="air", prob=254, param2=0},
		{name="air", prob=254, param2=0},
		{name="air", prob=254, param2=0},
		{name="air", prob=254, param2=0},
		{name="air", prob=254, param2=0},
		{name="air", prob=254, param2=0},
		{name="air", prob=254, param2=0},
		{name="air", prob=254, param2=0},
		{name="everness:quartz_pillar", prob=254, param2=3},
		{name="air", prob=0, param2=0},
		{name="air", prob=0, param2=0},
		{name="air", prob=0, param2=0},
		{name="air", prob=0, param2=0},
		{name="air", prob=0, param2=0},
		{name="air", prob=0, param2=0},
		{name="everness:quartz_pillar", prob=254, param2=3},
		{name="air", prob=254, param2=0},
		{name="air", prob=254, param2=0},
		{name="air", prob=254, param2=0},
		{name="air", prob=254, param2=0},
		{name="air", prob=254, param2=0},
		{name="air", prob=254, param2=0},
		{name="air", prob=254, param2=0},
		{name="air", prob=254, param2=0},
		{name="everness:quartz_pillar", prob=254, param2=3},
		{name="air", prob=0, param2=0},
		{name="air", prob=0, param2=0},
		{name="air", prob=0, param2=0},
		{name="air", prob=0, param2=0},
		{name="stairs:stair_outer_quartz_chiseled", prob=254, param2=20},
		{name="stairs:stair_inner_quartz_chiseled", prob=254, param2=20},
		{name="everness:quartz_chiseled", prob=254, param2=0},
		{name="stairs:stair_inner_quartz_chiseled", prob=254, param2=22},
		{name="stairs:stair_quartz_chiseled", prob=254, param2=22},
		{name="stairs:stair_quartz_chiseled", prob=254, param2=22},
		{name="stairs:stair_outer_quartz_chiseled", prob=254, param2=22},
		{name="stairs:stair_outer_quartz_chiseled", prob=254, param2=23},
		{name="stairs:stair_quartz_chiseled", prob=254, param2=22},
		{name="stairs:stair_quartz_chiseled", prob=254, param2=22},
		{name="stairs:stair_inner_quartz_chiseled", prob=254, param2=23},
		{name="everness:quartz_chiseled", prob=254, param2=0},
		{name="stairs:stair_inner_quartz_chiseled", prob=254, param2=21},
		{name="stairs:stair_outer_quartz_chiseled", prob=254, param2=21},
		{name="air", prob=0, param2=0},
		{name="air", prob=0, param2=0},
		{name="air", prob=0, param2=0},
		{name="air", prob=0, param2=0},
		{name="stairs:stair_outer_quartz_chiseled", prob=254, param2=1},
		{name="stairs:stair_inner_quartz_chiseled", prob=254, param2=1},
		{name="everness:quartz_chiseled", prob=254, param2=0},
		{name="everness:quartz_chiseled", prob=254, param2=0},
		{name="everness:quartz_chiseled", prob=254, param2=0},
		{name="everness:quartz_chiseled", prob=254, param2=0},
		{name="everness:quartz_chiseled", prob=254, param2=0},
		{name="everness:quartz_chiseled", prob=254, param2=0},
		{name="stairs:stair_inner_quartz_chiseled", prob=254, param2=0},
		{name="stairs:stair_outer_quartz_chiseled", prob=254, param2=0},
		{name="air", prob=0, param2=0},
		{name="air", prob=0, param2=0},
		{name="air", prob=0, param2=0},
		{name="air", prob=0, param2=0},
		{name="air", prob=0, param2=0},
		{name="air", prob=0, param2=0},
		{name="air", prob=0, param2=0},
		{name="air", prob=0, param2=0},
		{name="stairs:stair_outer_quartz_chiseled", prob=254, param2=1},
		{name="stairs:stair_quartz_chiseled", prob=254, param2=0},
		{name="stairs:stair_inner_quartz_chiseled", prob=254, param2=1},
		{name="stairs:stair_inner_quartz_chiseled", prob=254, param2=0},
		{name="stairs:stair_quartz_chiseled", prob=254, param2=0},
		{name="stairs:stair_outer_quartz_chiseled", prob=254, param2=0},
		{name="air", prob=0, param2=0},
		{name="air", prob=0, param2=0},
		{name="air", prob=0, param2=0},
		{name="air", prob=0, param2=0},
		{name="air", prob=0, param2=0},
		{name="air", prob=0, param2=0},
		{name="air", prob=0, param2=0},
		{name="air", prob=0, param2=0},
		{name="air", prob=0, param2=0},
		{name="air", prob=0, param2=0},
		{name="air", prob=0, param2=0},
		{name="air", prob=0, param2=0},
		{name="air", prob=0, param2=0},
		{name="air", prob=0, param2=0},
		{name="air", prob=0, param2=0},
		{name="air", prob=0, param2=0},
		{name="air", prob=0, param2=0},
		{name="air", prob=0, param2=0},
		{name="air", prob=0, param2=0},
		{name="air", prob=0, param2=0},
		{name="air", prob=0, param2=0},
		{name="air", prob=0, param2=0},
		{name="air", prob=0, param2=0},
		{name="air", prob=0, param2=0},
		{name="air", prob=0, param2=0},
		{name="air", prob=0, param2=0},
		{name="air", prob=0, param2=0},
		{name="air", prob=0, param2=0},
		{name="air", prob=0, param2=0},
		{name="air", prob=0, param2=0},
		{name="air", prob=0, param2=0},
		{name="air", prob=0, param2=0},
		{name="air", prob=0, param2=0},
		{name="air", prob=0, param2=0},
		{name="air", prob=0, param2=0},
		{name="air", prob=0, param2=0},
		{name="air", prob=0, param2=0},
		{name="air", prob=0, param2=0},
		{name="air", prob=0, param2=0},
		{name="air", prob=0, param2=0},
		{name="air", prob=0, param2=0},
		{name="air", prob=0, param2=0},
		{name="air", prob=0, param2=0},
		{name="air", prob=0, param2=0},
		{name="air", prob=0, param2=0},
		{name="air", prob=0, param2=0},
		{name="air", prob=0, param2=0},
		{name="air", prob=0, param2=0},
		{name="air", prob=0, param2=0},
		{name="air", prob=0, param2=0},
		{name="air", prob=0, param2=0},
		{name="air", prob=0, param2=0},
		{name="air", prob=0, param2=0},
		{name="air", prob=0, param2=0},
		{name="everness:quartz_chiseled", prob=254, param2=0},
		{name="everness:quartz_chiseled", prob=254, param2=0},
		{name="everness:quartz_chiseled", prob=254, param2=0},
		{name="everness:quartz_chiseled", prob=254, param2=0},
		{name="everness:quartz_chiseled", prob=254, param2=0},
		{name="everness:quartz_chiseled", prob=254, param2=0},
		{name="everness:quartz_chiseled", prob=254, param2=0},
		{name="everness:quartz_chiseled", prob=254, param2=0},
		{name="everness:quartz_chiseled", prob=254, param2=0},
		{name="everness:quartz_chiseled", prob=254, param2=0},
		{name="everness:quartz_chiseled", prob=254, param2=0},
		{name="everness:quartz_chiseled", prob=254, param2=0},
		{name="everness:quartz_chiseled", prob=254, param2=0},
		{name="everness:quartz_chiseled", prob=254, param2=0},
		{name="air", prob=0, param2=0},
		{name="air", prob=0, param2=0},
		{name="stairs:stair_quartz_chiseled", prob=254, param2=1},
		{name="everness:quartz_chiseled", prob=254, param2=0},
		{name="everness:quartz_chiseled", prob=254, param2=0},
		{name="everness:quartz_chiseled", prob=254, param2=0},
		{name="everness:quartz_chiseled", prob=254, param2=0},
		{name="everness:quartz_chiseled", prob=254, param2=0},
		{name="everness:quartz_chiseled", prob=254, param2=0},
		{name="everness:quartz_chiseled", prob=254, param2=0},
		{name="everness:quartz_chiseled", prob=254, param2=0},
		{name="everness:quartz_chiseled", prob=254, param2=0},
		{name="everness:quartz_chiseled", prob=254, param2=0},
		{name="everness:quartz_chiseled", prob=254, param2=0},
		{name="everness:quartz_chiseled", prob=254, param2=0},
		{name="stairs:stair_quartz_chiseled", prob=254, param2=3},
		{name="air", prob=0, param2=0},
		{name="air", prob=0, param2=0},
		{name="air", prob=0, param2=0},
		{name="air", prob=254, param2=0},
		{name="air", prob=254, param2=0},
		{name="air", prob=254, param2=0},
		{name="air", prob=254, param2=0},
		{name="air", prob=254, param2=0},
		{name="air", prob=254, param2=0},
		{name="air", prob=254, param2=0},
		{name="air", prob=254, param2=0},
		{name="air", prob=254, param2=0},
		{name="air", prob=254, param2=0},
		{name="air", prob=254, param2=0},
		{name="air", prob=254, param2=0},
		{name="air", prob=0, param2=0},
		{name="air", prob=0, param2=0},
		{name="air", prob=0, param2=0},
		{name="air", prob=0, param2=0},
		{name="air", prob=254, param2=0},
		{name="air", prob=254, param2=0},
		{name="air", prob=254, param2=0},
		{name="air", prob=254, param2=0},
		{name="air", prob=254, param2=0},
		{name="air", prob=254, param2=0},
		{name="air", prob=254, param2=0},
		{name="air", prob=254, param2=0},
		{name="air", prob=254, param2=0},
		{name="air", prob=254, param2=0},
		{name="air", prob=254, param2=0},
		{name="air", prob=254, param2=0},
		{name="air", prob=0, param2=0},
		{name="air", prob=0, param2=0},
		{name="air", prob=0, param2=0},
		{name="air", prob=0, param2=0},
		{name="air", prob=254, param2=0},
		{name="air", prob=254, param2=0},
		{name="air", prob=254, param2=0},
		{name="air", prob=254, param2=0},
		{name="air", prob=254, param2=0},
		{name="air", prob=254, param2=0},
		{name="air", prob=254, param2=0},
		{name="air", prob=254, param2=0},
		{name="air", prob=254, param2=0},
		{name="air", prob=254, param2=0},
		{name="air", prob=254, param2=0},
		{name="air", prob=254, param2=0},
		{name="air", prob=0, param2=0},
		{name="air", prob=0, param2=0},
		{name="air", prob=0, param2=0},
		{name="air", prob=0, param2=0},
		{name="air", prob=254, param2=0},
		{name="air", prob=254, param2=0},
		{name="air", prob=254, param2=0},
		{name="air", prob=254, param2=0},
		{name="air", prob=254, param2=0},
		{name="air", prob=254, param2=0},
		{name="air", prob=254, param2=0},
		{name="air", prob=254, param2=0},
		{name="air", prob=254, param2=0},
		{name="air", prob=254, param2=0},
		{name="air", prob=254, param2=0},
		{name="air", prob=254, param2=0},
		{name="air", prob=0, param2=0},
		{name="air", prob=0, param2=0},
		{name="air", prob=0, param2=0},
		{name="air", prob=0, param2=0},
		{name="air", prob=254, param2=0},
		{name="air", prob=254, param2=0},
		{name="air", prob=254, param2=0},
		{name="air", prob=254, param2=0},
		{name="air", prob=254, param2=0},
		{name="air", prob=254, param2=0},
		{name="air", prob=254, param2=0},
		{name="air", prob=254, param2=0},
		{name="air", prob=254, param2=0},
		{name="air", prob=254, param2=0},
		{name="air", prob=254, param2=0},
		{name="air", prob=254, param2=0},
		{name="air", prob=0, param2=0},
		{name="air", prob=0, param2=0},
		{name="air", prob=0, param2=0},
		{name="stairs:stair_quartz_chiseled", prob=254, param2=23},
		{name="everness:quartz_chiseled", prob=254, param2=0},
		{name="stairs:stair_inner_quartz_chiseled", prob=254, param2=22},
		{name="stairs:stair_outer_quartz_chiseled", prob=254, param2=22},
		{name="air", prob=254, param2=0},
		{name="air", prob=254, param2=0},
		{name="air", prob=254, param2=0},
		{name="air", prob=254, param2=0},
		{name="air", prob=254, param2=0},
		{name="air", prob=254, param2=0},
		{name="stairs:stair_outer_quartz_chiseled", prob=254, param2=23},
		{name="stairs:stair_inner_quartz_chiseled", prob=254, param2=23},
		{name="everness:quartz_chiseled", prob=254, param2=0},
		{name="stairs:stair_quartz_chiseled", prob=254, param2=21},
		{name="air", prob=0, param2=0},
		{name="air", prob=0, param2=0},
		{name="air", prob=0, param2=0},
		{name="stairs:stair_outer_quartz_chiseled", prob=254, param2=1},
		{name="stairs:stair_inner_quartz_chiseled", prob=254, param2=1},
		{name="everness:quartz_chiseled", prob=254, param2=0},
		{name="stairs:stair_inner_quartz_chiseled", prob=254, param2=22},
		{name="stairs:stair_quartz_chiseled", prob=254, param2=22},
		{name="stairs:stair_quartz_chiseled", prob=254, param2=22},
		{name="stairs:stair_quartz_chiseled", prob=254, param2=22},
		{name="stairs:stair_quartz_chiseled", prob=254, param2=22},
		{name="stairs:stair_inner_quartz_chiseled", prob=254, param2=23},
		{name="everness:quartz_chiseled", prob=254, param2=0},
		{name="stairs:stair_inner_quartz_chiseled", prob=254, param2=0},
		{name="stairs:stair_outer_quartz_chiseled", prob=254, param2=0},
		{name="air", prob=0, param2=0},
		{name="air", prob=0, param2=0},
		{name="air", prob=0, param2=0},
		{name="air", prob=0, param2=0},
		{name="air", prob=0, param2=0},
		{name="air", prob=0, param2=0},
		{name="stairs:stair_outer_quartz_chiseled", prob=254, param2=1},
		{name="stairs:stair_inner_quartz_chiseled", prob=254, param2=1},
		{name="everness:quartz_chiseled", prob=254, param2=0},
		{name="everness:quartz_chiseled", prob=254, param2=0},
		{name="everness:quartz_chiseled", prob=254, param2=0},
		{name="everness:quartz_chiseled", prob=254, param2=0},
		{name="stairs:stair_inner_quartz_chiseled", prob=254, param2=0},
		{name="stairs:stair_outer_quartz_chiseled", prob=254, param2=0},
		{name="air", prob=0, param2=0},
		{name="air", prob=0, param2=0},
		{name="air", prob=0, param2=0},
		{name="air", prob=0, param2=0},
		{name="air", prob=0, param2=0},
		{name="air", prob=0, param2=0},
		{name="air", prob=0, param2=0},
		{name="air", prob=0, param2=0},
		{name="air", prob=0, param2=0},
		{name="air", prob=0, param2=0},
		{name="stairs:stair_outer_quartz_chiseled", prob=254, param2=1},
		{name="stairs:stair_quartz_chiseled", prob=254, param2=0},
		{name="stairs:stair_quartz_chiseled", prob=254, param2=0},
		{name="stairs:stair_outer_quartz_chiseled", prob=254, param2=0},
		{name="air", prob=0, param2=0},
		{name="air", prob=0, param2=0},
		{name="air", prob=0, param2=0},
		{name="air", prob=0, param2=0},
		{name="air", prob=0, param2=0},
		{name="air", prob=0, param2=0},
		{name="air", prob=0, param2=0},
		{name="air", prob=0, param2=0},
		{name="air", prob=0, param2=0},
		{name="air", prob=0, param2=0},
		{name="air", prob=0, param2=0},
		{name="air", prob=0, param2=0},
		{name="air", prob=0, param2=0},
		{name="air", prob=0, param2=0},
		{name="air", prob=0, param2=0},
		{name="air", prob=0, param2=0},
		{name="air", prob=0, param2=0},
		{name="air", prob=0, param2=0},
		{name="air", prob=0, param2=0},
		{name="air", prob=0, param2=0},
		{name="air", prob=0, param2=0},
		{name="air", prob=0, param2=0},
		{name="air", prob=0, param2=0},
		{name="air", prob=0, param2=0},
		{name="air", prob=0, param2=0},
		{name="air", prob=0, param2=0},
		{name="air", prob=0, param2=0},
		{name="air", prob=0, param2=0},
		{name="air", prob=0, param2=0},
		{name="air", prob=0, param2=0},
		{name="air", prob=0, param2=0},
		{name="air", prob=0, param2=0},
		{name="air", prob=0, param2=0},
		{name="air", prob=0, param2=0},
		{name="air", prob=0, param2=0},
		{name="air", prob=0, param2=0},
		{name="air", prob=0, param2=0},
		{name="air", prob=0, param2=0},
		{name="everness:quartz_chiseled", prob=254, param2=0},
		{name="everness:quartz_chiseled", prob=254, param2=0},
		{name="everness:quartz_chiseled", prob=254, param2=0},
		{name="everness:quartz_chiseled", prob=254, param2=0},
		{name="everness:quartz_chiseled", prob=254, param2=0},
		{name="everness:quartz_chiseled", prob=254, param2=0},
		{name="everness:quartz_chiseled", prob=254, param2=0},
		{name="everness:quartz_chiseled", prob=254, param2=0},
		{name="everness:quartz_chiseled", prob=254, param2=0},
		{name="everness:quartz_chiseled", prob=254, param2=0},
		{name="everness:quartz_chiseled", prob=254, param2=0},
		{name="everness:quartz_chiseled", prob=254, param2=0},
		{name="everness:quartz_chiseled", prob=254, param2=0},
		{name="everness:quartz_chiseled", prob=254, param2=0},
		{name="everness:quartz_chiseled", prob=254, param2=0},
		{name="everness:quartz_chiseled", prob=254, param2=0},
		{name="stairs:stair_outer_quartz_chiseled", prob=254, param2=1},
		{name="stairs:stair_inner_quartz_chiseled", prob=254, param2=1},
		{name="everness:quartz_chiseled", prob=254, param2=0},
		{name="everness:quartz_chiseled", prob=254, param2=0},
		{name="everness:quartz_chiseled", prob=254, param2=0},
		{name="everness:quartz_chiseled", prob=254, param2=0},
		{name="everness:quartz_chiseled", prob=254, param2=0},
		{name="everness:quartz_chiseled", prob=254, param2=0},
		{name="everness:quartz_chiseled", prob=254, param2=0},
		{name="everness:quartz_chiseled", prob=254, param2=0},
		{name="everness:quartz_chiseled", prob=254, param2=0},
		{name="everness:quartz_chiseled", prob=254, param2=0},
		{name="everness:quartz_chiseled", prob=254, param2=0},
		{name="everness:quartz_chiseled", prob=254, param2=0},
		{name="stairs:stair_inner_quartz_chiseled", prob=254, param2=0},
		{name="stairs:stair_outer_quartz_chiseled", prob=254, param2=0},
		{name="air", prob=0, param2=0},
		{name="air", prob=0, param2=0},
		{name="air", prob=254, param2=0},
		{name="air", prob=254, param2=0},
		{name="air", prob=254, param2=0},
		{name="air", prob=254, param2=0},
		{name="air", prob=254, param2=0},
		{name="air", prob=254, param2=0},
		{name="air", prob=254, param2=0},
		{name="air", prob=254, param2=0},
		{name="air", prob=254, param2=0},
		{name="air", prob=254, param2=0},
		{name="air", prob=254, param2=0},
		{name="air", prob=254, param2=0},
		{name="air", prob=0, param2=0},
		{name="air", prob=0, param2=0},
		{name="air", prob=0, param2=0},
		{name="air", prob=0, param2=0},
		{name="air", prob=254, param2=0},
		{name="air", prob=254, param2=0},
		{name="air", prob=254, param2=0},
		{name="air", prob=254, param2=0},
		{name="air", prob=254, param2=0},
		{name="air", prob=254, param2=0},
		{name="air", prob=254, param2=0},
		{name="air", prob=254, param2=0},
		{name="air", prob=254, param2=0},
		{name="air", prob=254, param2=0},
		{name="air", prob=254, param2=0},
		{name="air", prob=254, param2=0},
		{name="air", prob=0, param2=0},
		{name="air", prob=0, param2=0},
		{name="air", prob=0, param2=0},
		{name="air", prob=0, param2=0},
		{name="air", prob=254, param2=0},
		{name="air", prob=254, param2=0},
		{name="air", prob=254, param2=0},
		{name="air", prob=254, param2=0},
		{name="air", prob=254, param2=0},
		{name="air", prob=254, param2=0},
		{name="air", prob=254, param2=0},
		{name="air", prob=254, param2=0},
		{name="air", prob=254, param2=0},
		{name="air", prob=254, param2=0},
		{name="air", prob=254, param2=0},
		{name="air", prob=254, param2=0},
		{name="air", prob=0, param2=0},
		{name="air", prob=0, param2=0},
		{name="air", prob=0, param2=0},
		{name="air", prob=0, param2=0},
		{name="air", prob=254, param2=0},
		{name="air", prob=254, param2=0},
		{name="air", prob=254, param2=0},
		{name="air", prob=254, param2=0},
		{name="air", prob=254, param2=0},
		{name="air", prob=254, param2=0},
		{name="air", prob=254, param2=0},
		{name="air", prob=254, param2=0},
		{name="air", prob=254, param2=0},
		{name="air", prob=254, param2=0},
		{name="air", prob=254, param2=0},
		{name="air", prob=254, param2=0},
		{name="air", prob=0, param2=0},
		{name="air", prob=0, param2=0},
		{name="air", prob=0, param2=0},
		{name="air", prob=0, param2=0},
		{name="air", prob=254, param2=0},
		{name="air", prob=254, param2=0},
		{name="air", prob=254, param2=0},
		{name="air", prob=254, param2=0},
		{name="air", prob=254, param2=0},
		{name="air", prob=254, param2=0},
		{name="air", prob=254, param2=0},
		{name="air", prob=254, param2=0},
		{name="air", prob=254, param2=0},
		{name="air", prob=254, param2=0},
		{name="air", prob=254, param2=0},
		{name="air", prob=254, param2=0},
		{name="air", prob=0, param2=0},
		{name="air", prob=0, param2=0},
		{name="stairs:stair_outer_quartz_chiseled", prob=254, param2=20},
		{name="stairs:stair_inner_quartz_chiseled", prob=254, param2=20},
		{name="everness:quartz_chiseled", prob=254, param2=0},
		{name="stairs:stair_quartz_chiseled", prob=254, param2=21},
		{name="air", prob=254, param2=0},
		{name="air", prob=254, param2=0},
		{name="air", prob=254, param2=0},
		{name="air", prob=254, param2=0},
		{name="air", prob=254, param2=0},
		{name="air", prob=254, param2=0},
		{name="air", prob=254, param2=0},
		{name="air", prob=254, param2=0},
		{name="stairs:stair_quartz_chiseled", prob=254, param2=23},
		{name="everness:quartz_chiseled", prob=254, param2=0},
		{name="stairs:stair_inner_quartz_chiseled", prob=254, param2=21},
		{name="stairs:stair_outer_quartz_chiseled", prob=254, param2=21},
		{name="air", prob=0, param2=0},
		{name="air", prob=0, param2=0},
		{name="stairs:stair_quartz_chiseled", prob=254, param2=1},
		{name="everness:quartz_chiseled", prob=254, param2=0},
		{name="stairs:stair_inner_quartz_chiseled", prob=254, param2=22},
		{name="stairs:stair_outer_quartz_chiseled", prob=254, param2=22},
		{name="air", prob=254, param2=0},
		{name="air", prob=254, param2=0},
		{name="air", prob=254, param2=0},
		{name="air", prob=254, param2=0},
		{name="stairs:stair_outer_quartz_chiseled", prob=254, param2=23},
		{name="stairs:stair_inner_quartz_chiseled", prob=254, param2=23},
		{name="everness:quartz_chiseled", prob=254, param2=0},
		{name="stairs:stair_quartz_chiseled", prob=254, param2=3},
		{name="air", prob=0, param2=0},
		{name="air", prob=0, param2=0},
		{name="air", prob=0, param2=0},
		{name="air", prob=0, param2=0},
		{name="air", prob=0, param2=0},
		{name="stairs:stair_outer_quartz_chiseled", prob=254, param2=1},
		{name="stairs:stair_inner_quartz_chiseled", prob=254, param2=1},
		{name="everness:quartz_chiseled", prob=254, param2=0},
		{name="stairs:stair_inner_quartz_chiseled", prob=254, param2=22},
		{name="stairs:stair_quartz_chiseled", prob=254, param2=22},
		{name="stairs:stair_quartz_chiseled", prob=254, param2=22},
		{name="stairs:stair_inner_quartz_chiseled", prob=254, param2=23},
		{name="everness:quartz_chiseled", prob=254, param2=0},
		{name="stairs:stair_inner_quartz_chiseled", prob=254, param2=0},
		{name="stairs:stair_outer_quartz_chiseled", prob=254, param2=0},
		{name="air", prob=0, param2=0},
		{name="air", prob=0, param2=0},
		{name="air", prob=0, param2=0},
		{name="air", prob=0, param2=0},
		{name="air", prob=0, param2=0},
		{name="air", prob=0, param2=0},
		{name="air", prob=0, param2=0},
		{name="air", prob=0, param2=0},
		{name="stairs:stair_outer_quartz_chiseled", prob=254, param2=1},
		{name="stairs:stair_inner_quartz_chiseled", prob=254, param2=1},
		{name="everness:quartz_chiseled", prob=254, param2=0},
		{name="everness:quartz_chiseled", prob=254, param2=0},
		{name="stairs:stair_inner_quartz_chiseled", prob=254, param2=0},
		{name="stairs:stair_outer_quartz_chiseled", prob=254, param2=0},
		{name="air", prob=0, param2=0},
		{name="air", prob=0, param2=0},
		{name="air", prob=0, param2=0},
		{name="air", prob=0, param2=0},
		{name="air", prob=0, param2=0},
		{name="air", prob=0, param2=0},
		{name="air", prob=0, param2=0},
		{name="air", prob=0, param2=0},
		{name="air", prob=0, param2=0},
		{name="air", prob=0, param2=0},
		{name="air", prob=0, param2=0},
		{name="air", prob=0, param2=0},
		{name="stairs:slab_quartz_chiseled", prob=254, param2=0},
		{name="stairs:slab_quartz_chiseled", prob=254, param2=0},
		{name="air", prob=0, param2=0},
		{name="air", prob=0, param2=0},
		{name="air", prob=0, param2=0},
		{name="air", prob=0, param2=0},
		{name="air", prob=0, param2=0},
		{name="air", prob=0, param2=0},
		{name="air", prob=0, param2=0},
		{name="air", prob=0, param2=0},
		{name="air", prob=0, param2=0},
		{name="air", prob=0, param2=0},
		{name="air", prob=0, param2=0},
		{name="air", prob=0, param2=0},
		{name="air", prob=0, param2=0},
		{name="air", prob=0, param2=0},
		{name="air", prob=0, param2=0},
		{name="air", prob=0, param2=0},
		{name="air", prob=0, param2=0},
		{name="air", prob=0, param2=0},
		{name="air", prob=0, param2=0},
		{name="air", prob=0, param2=0},
		{name="air", prob=0, param2=0},
		{name="air", prob=0, param2=0},
		{name="air", prob=0, param2=0},
		{name="everness:quartz_chiseled", prob=254, param2=0},
		{name="everness:quartz_chiseled", prob=254, param2=0},
		{name="everness:quartz_chiseled", prob=254, param2=0},
		{name="everness:quartz_chiseled", prob=254, param2=0},
		{name="everness:quartz_chiseled", prob=254, param2=0},
		{name="everness:quartz_chiseled", prob=254, param2=0},
		{name="everness:quartz_chiseled", prob=254, param2=0},
		{name="everness:quartz_chiseled", prob=254, param2=0},
		{name="everness:quartz_chiseled", prob=254, param2=0},
		{name="everness:quartz_chiseled", prob=254, param2=0},
		{name="everness:quartz_chiseled", prob=254, param2=0},
		{name="everness:quartz_chiseled", prob=254, param2=0},
		{name="everness:quartz_chiseled", prob=254, param2=0},
		{name="everness:quartz_chiseled", prob=254, param2=0},
		{name="everness:quartz_chiseled", prob=254, param2=0},
		{name="everness:quartz_chiseled", prob=254, param2=0},
		{name="stairs:stair_quartz_chiseled", prob=254, param2=1},
		{name="everness:quartz_chiseled", prob=254, param2=0},
		{name="everness:quartz_chiseled", prob=254, param2=0},
		{name="everness:quartz_chiseled", prob=254, param2=0},
		{name="everness:quartz_chiseled", prob=254, param2=0},
		{name="everness:quartz_chiseled", prob=254, param2=0},
		{name="everness:quartz_chiseled", prob=254, param2=0},
		{name="everness:quartz_chiseled", prob=254, param2=0},
		{name="everness:quartz_chiseled", prob=254, param2=0},
		{name="everness:quartz_chiseled", prob=254, param2=0},
		{name="everness:quartz_chiseled", prob=254, param2=0},
		{name="everness:quartz_chiseled", prob=254, param2=0},
		{name="everness:quartz_chiseled", prob=254, param2=0},
		{name="everness:quartz_chiseled", prob=254, param2=0},
		{name="everness:quartz_chiseled", prob=254, param2=0},
		{name="stairs:stair_quartz_chiseled", prob=254, param2=3},
		{name="air", prob=0, param2=0},
		{name="everness:quartz_pillar", prob=254, param2=1},
		{name="air", prob=254, param2=0},
		{name="air", prob=254, param2=0},
		{name="air", prob=254, param2=0},
		{name="air", prob=254, param2=0},
		{name="everness:quartz_pillar", prob=254, param2=0},
		{name="air", prob=254, param2=0},
		{name="air", prob=254, param2=0},
		{name="everness:quartz_pillar", prob=254, param2=3},
		{name="air", prob=254, param2=0},
		{name="air", prob=254, param2=0},
		{name="air", prob=254, param2=0},
		{name="air", prob=254, param2=0},
		{name="everness:quartz_pillar", prob=254, param2=1},
		{name="air", prob=0, param2=0},
		{name="air", prob=0, param2=0},
		{name="everness:quartz_pillar", prob=254, param2=1},
		{name="air", prob=254, param2=0},
		{name="air", prob=254, param2=0},
		{name="air", prob=254, param2=0},
		{name="air", prob=254, param2=0},
		{name="everness:quartz_pillar", prob=254, param2=0},
		{name="air", prob=254, param2=0},
		{name="air", prob=254, param2=0},
		{name="everness:quartz_pillar", prob=254, param2=3},
		{name="air", prob=254, param2=0},
		{name="air", prob=254, param2=0},
		{name="air", prob=254, param2=0},
		{name="air", prob=254, param2=0},
		{name="everness:quartz_pillar", prob=254, param2=1},
		{name="air", prob=0, param2=0},
		{name="air", prob=0, param2=0},
		{name="everness:quartz_pillar", prob=254, param2=1},
		{name="air", prob=254, param2=0},
		{name="air", prob=254, param2=0},
		{name="air", prob=254, param2=0},
		{name="air", prob=254, param2=0},
		{name="everness:quartz_pillar", prob=254, param2=0},
		{name="air", prob=254, param2=0},
		{name="air", prob=254, param2=0},
		{name="everness:quartz_pillar", prob=254, param2=3},
		{name="air", prob=254, param2=0},
		{name="air", prob=254, param2=0},
		{name="air", prob=254, param2=0},
		{name="air", prob=254, param2=0},
		{name="everness:quartz_pillar", prob=254, param2=1},
		{name="air", prob=0, param2=0},
		{name="air", prob=0, param2=0},
		{name="everness:quartz_pillar", prob=254, param2=1},
		{name="air", prob=254, param2=0},
		{name="air", prob=254, param2=0},
		{name="air", prob=254, param2=0},
		{name="air", prob=254, param2=0},
		{name="everness:quartz_pillar", prob=254, param2=1},
		{name="everness:quartz_block", prob=254, param2=0},
		{name="everness:quartz_block", prob=254, param2=0},
		{name="everness:quartz_pillar", prob=254, param2=1},
		{name="air", prob=254, param2=0},
		{name="air", prob=254, param2=0},
		{name="air", prob=254, param2=0},
		{name="air", prob=254, param2=0},
		{name="everness:quartz_pillar", prob=254, param2=1},
		{name="air", prob=0, param2=0},
		{name="air", prob=0, param2=0},
		{name="everness:quartz_pillar", prob=254, param2=1},
		{name="air", prob=254, param2=0},
		{name="air", prob=254, param2=0},
		{name="air", prob=254, param2=0},
		{name="air", prob=254, param2=0},
		{name="air", prob=254, param2=0},
		{name="air", prob=254, param2=0},
		{name="air", prob=254, param2=0},
		{name="air", prob=254, param2=0},
		{name="air", prob=254, param2=0},
		{name="air", prob=254, param2=0},
		{name="air", prob=254, param2=0},
		{name="air", prob=254, param2=0},
		{name="everness:quartz_pillar", prob=254, param2=1},
		{name="air", prob=0, param2=0},
		{name="stairs:stair_quartz_chiseled", prob=254, param2=23},
		{name="everness:quartz_chiseled", prob=254, param2=0},
		{name="everness:quartz_chiseled", prob=254, param2=0},
		{name="stairs:stair_quartz_chiseled", prob=254, param2=21},
		{name="air", prob=254, param2=0},
		{name="air", prob=254, param2=0},
		{name="air", prob=254, param2=0},
		{name="air", prob=254, param2=0},
		{name="air", prob=254, param2=0},
		{name="air", prob=254, param2=0},
		{name="air", prob=254, param2=0},
		{name="air", prob=254, param2=0},
		{name="stairs:stair_quartz_chiseled", prob=254, param2=23},
		{name="everness:quartz_chiseled", prob=254, param2=0},
		{name="everness:quartz_chiseled", prob=254, param2=0},
		{name="stairs:stair_quartz_chiseled", prob=254, param2=21},
		{name="air", prob=0, param2=0},
		{name="stairs:stair_outer_quartz_chiseled", prob=254, param2=1},
		{name="stairs:stair_inner_quartz_chiseled", prob=254, param2=1},
		{name="everness:quartz_chiseled", prob=254, param2=0},
		{name="stairs:stair_quartz_chiseled", prob=254, param2=21},
		{name="air", prob=254, param2=0},
		{name="air", prob=254, param2=0},
		{name="air", prob=254, param2=0},
		{name="air", prob=254, param2=0},
		{name="air", prob=254, param2=0},
		{name="air", prob=254, param2=0},
		{name="stairs:stair_quartz_chiseled", prob=254, param2=23},
		{name="everness:quartz_chiseled", prob=254, param2=0},
		{name="stairs:stair_inner_quartz_chiseled", prob=254, param2=0},
		{name="stairs:stair_outer_quartz_chiseled", prob=254, param2=0},
		{name="air", prob=0, param2=0},
		{name="air", prob=0, param2=0},
		{name="air", prob=0, param2=0},
		{name="air", prob=0, param2=0},
		{name="stairs:stair_quartz_chiseled", prob=254, param2=1},
		{name="everness:quartz_chiseled", prob=254, param2=0},
		{name="stairs:stair_inner_quartz_chiseled", prob=254, param2=22},
		{name="stairs:stair_outer_quartz_chiseled", prob=254, param2=22},
		{name="air", prob=254, param2=0},
		{name="air", prob=254, param2=0},
		{name="stairs:stair_outer_quartz_chiseled", prob=254, param2=23},
		{name="stairs:stair_inner_quartz_chiseled", prob=254, param2=23},
		{name="everness:quartz_chiseled", prob=254, param2=0},
		{name="stairs:stair_quartz_chiseled", prob=254, param2=3},
		{name="air", prob=0, param2=0},
		{name="air", prob=0, param2=0},
		{name="air", prob=0, param2=0},
		{name="air", prob=0, param2=0},
		{name="air", prob=0, param2=0},
		{name="air", prob=0, param2=0},
		{name="air", prob=0, param2=0},
		{name="stairs:stair_outer_quartz_chiseled", prob=254, param2=1},
		{name="stairs:stair_inner_quartz_chiseled", prob=254, param2=1},
		{name="everness:quartz_chiseled", prob=254, param2=0},
		{name="stairs:stair_inner_quartz_chiseled", prob=254, param2=22},
		{name="stairs:stair_inner_quartz_chiseled", prob=254, param2=23},
		{name="everness:quartz_chiseled", prob=254, param2=0},
		{name="stairs:stair_inner_quartz_chiseled", prob=254, param2=0},
		{name="stairs:stair_outer_quartz_chiseled", prob=254, param2=0},
		{name="air", prob=0, param2=0},
		{name="air", prob=0, param2=0},
		{name="air", prob=0, param2=0},
		{name="air", prob=0, param2=0},
		{name="air", prob=0, param2=0},
		{name="air", prob=0, param2=0},
		{name="air", prob=0, param2=0},
		{name="air", prob=0, param2=0},
		{name="air", prob=0, param2=0},
		{name="air", prob=0, param2=0},
		{name="stairs:slab_quartz_chiseled", prob=254, param2=1},
		{name="everness:quartz_chiseled", prob=254, param2=0},
		{name="everness:quartz_chiseled", prob=254, param2=0},
		{name="stairs:slab_quartz_chiseled", prob=254, param2=0},
		{name="air", prob=0, param2=0},
		{name="air", prob=0, param2=0},
		{name="air", prob=0, param2=0},
		{name="air", prob=0, param2=0},
		{name="air", prob=0, param2=0},
		{name="air", prob=0, param2=0},
		{name="air", prob=0, param2=0},
		{name="air", prob=0, param2=0},
		{name="air", prob=0, param2=0},
		{name="air", prob=0, param2=0},
		{name="air", prob=0, param2=0},
		{name="air", prob=0, param2=0},
		{name="air", prob=0, param2=0},
		{name="air", prob=0, param2=0},
		{name="air", prob=0, param2=0},
		{name="air", prob=0, param2=0},
		{name="air", prob=0, param2=0},
		{name="air", prob=0, param2=0},
		{name="air", prob=0, param2=0},
		{name="air", prob=0, param2=0},
		{name="air", prob=0, param2=0},
		{name="air", prob=0, param2=0},
		{name="everness:quartz_chiseled", prob=254, param2=0},
		{name="everness:quartz_chiseled", prob=254, param2=0},
		{name="everness:quartz_chiseled", prob=254, param2=0},
		{name="everness:quartz_chiseled", prob=254, param2=0},
		{name="everness:quartz_chiseled", prob=254, param2=0},
		{name="everness:quartz_chiseled", prob=254, param2=0},
		{name="everness:quartz_chiseled", prob=254, param2=0},
		{name="everness:quartz_pillar", prob=254, param2=3},
		{name="everness:chest", prob=254, param2=2},
		{name="everness:quartz_chiseled", prob=254, param2=0},
		{name="everness:quartz_chiseled", prob=254, param2=0},
		{name="everness:quartz_chiseled", prob=254, param2=0},
		{name="everness:quartz_chiseled", prob=254, param2=0},
		{name="everness:quartz_chiseled", prob=254, param2=0},
		{name="everness:quartz_chiseled", prob=254, param2=0},
		{name="everness:quartz_chiseled", prob=254, param2=0},
		{name="stairs:stair_quartz_chiseled", prob=254, param2=1},
		{name="everness:quartz_chiseled", prob=254, param2=0},
		{name="everness:quartz_chiseled", prob=254, param2=0},
		{name="everness:quartz_chiseled", prob=254, param2=0},
		{name="everness:quartz_chiseled", prob=254, param2=0},
		{name="everness:quartz_chiseled", prob=254, param2=0},
		{name="everness:quartz_chiseled", prob=254, param2=0},
		{name="everness:quartz_pillar", prob=254, param2=2},
		{name="everness:quartz_pillar", prob=254, param2=3},
		{name="everness:quartz_chiseled", prob=254, param2=0},
		{name="everness:quartz_chiseled", prob=254, param2=0},
		{name="everness:quartz_chiseled", prob=254, param2=0},
		{name="everness:quartz_chiseled", prob=254, param2=0},
		{name="everness:quartz_chiseled", prob=254, param2=0},
		{name="everness:quartz_chiseled", prob=254, param2=0},
		{name="stairs:stair_quartz_chiseled", prob=254, param2=3},
		{name="air", prob=254, param2=0},
		{name="air", prob=254, param2=0},
		{name="air", prob=254, param2=0},
		{name="air", prob=254, param2=0},
		{name="air", prob=254, param2=0},
		{name="air", prob=254, param2=0},
		{name="air", prob=254, param2=0},
		{name="air", prob=254, param2=0},
		{name="air", prob=254, param2=0},
		{name="air", prob=254, param2=0},
		{name="air", prob=254, param2=0},
		{name="air", prob=254, param2=0},
		{name="air", prob=254, param2=0},
		{name="air", prob=254, param2=0},
		{name="air", prob=254, param2=0},
		{name="air", prob=254, param2=0},
		{name="air", prob=254, param2=0},
		{name="air", prob=254, param2=0},
		{name="air", prob=254, param2=0},
		{name="air", prob=254, param2=0},
		{name="air", prob=254, param2=0},
		{name="air", prob=254, param2=0},
		{name="air", prob=254, param2=0},
		{name="air", prob=254, param2=0},
		{name="air", prob=254, param2=0},
		{name="air", prob=254, param2=0},
		{name="air", prob=254, param2=0},
		{name="air", prob=254, param2=0},
		{name="air", prob=254, param2=0},
		{name="air", prob=254, param2=0},
		{name="air", prob=254, param2=0},
		{name="air", prob=254, param2=0},
		{name="air", prob=254, param2=0},
		{name="air", prob=254, param2=0},
		{name="air", prob=254, param2=0},
		{name="air", prob=254, param2=0},
		{name="air", prob=254, param2=0},
		{name="air", prob=254, param2=0},
		{name="air", prob=254, param2=0},
		{name="air", prob=254, param2=0},
		{name="air", prob=254, param2=0},
		{name="air", prob=254, param2=0},
		{name="air", prob=254, param2=0},
		{name="air", prob=254, param2=0},
		{name="air", prob=254, param2=0},
		{name="air", prob=254, param2=0},
		{name="air", prob=254, param2=0},
		{name="air", prob=254, param2=0},
		{name="air", prob=254, param2=0},
		{name="air", prob=254, param2=0},
		{name="air", prob=254, param2=0},
		{name="air", prob=254, param2=0},
		{name="air", prob=254, param2=0},
		{name="air", prob=254, param2=0},
		{name="everness:quartz_block", prob=254, param2=0},
		{name="air", prob=254, param2=0},
		{name="air", prob=254, param2=0},
		{name="everness:quartz_block", prob=254, param2=0},
		{name="air", prob=254, param2=0},
		{name="air", prob=254, param2=0},
		{name="air", prob=254, param2=0},
		{name="air", prob=254, param2=0},
		{name="air", prob=254, param2=0},
		{name="air", prob=254, param2=0},
		{name="air", prob=254, param2=0},
		{name="air", prob=254, param2=0},
		{name="air", prob=254, param2=0},
		{name="air", prob=254, param2=0},
		{name="air", prob=254, param2=0},
		{name="air", prob=254, param2=0},
		{name="air", prob=254, param2=0},
		{name="air", prob=254, param2=0},
		{name="air", prob=254, param2=0},
		{name="air", prob=254, param2=0},
		{name="air", prob=254, param2=0},
		{name="air", prob=254, param2=0},
		{name="air", prob=254, param2=0},
		{name="air", prob=254, param2=0},
		{name="air", prob=254, param2=0},
		{name="air", prob=254, param2=0},
		{name="stairs:stair_quartz_chiseled", prob=254, param2=23},
		{name="everness:quartz_chiseled", prob=254, param2=0},
		{name="stairs:stair_inner_quartz_chiseled", prob=254, param2=22},
		{name="stairs:stair_outer_quartz_chiseled", prob=254, param2=22},
		{name="air", prob=254, param2=0},
		{name="air", prob=254, param2=0},
		{name="air", prob=254, param2=0},
		{name="air", prob=254, param2=0},
		{name="air", prob=254, param2=0},
		{name="air", prob=254, param2=0},
		{name="air", prob=254, param2=0},
		{name="air", prob=254, param2=0},
		{name="stairs:stair_outer_quartz_chiseled", prob=254, param2=23},
		{name="stairs:stair_inner_quartz_chiseled", prob=254, param2=23},
		{name="everness:quartz_chiseled", prob=254, param2=0},
		{name="stairs:stair_quartz_chiseled", prob=254, param2=21},
		{name="air", prob=0, param2=0},
		{name="stairs:stair_quartz_chiseled", prob=254, param2=1},
		{name="everness:quartz_chiseled", prob=254, param2=0},
		{name="everness:quartz_chiseled", prob=254, param2=0},
		{name="stairs:stair_quartz_chiseled", prob=254, param2=21},
		{name="air", prob=254, param2=0},
		{name="air", prob=254, param2=0},
		{name="air", prob=254, param2=0},
		{name="air", prob=254, param2=0},
		{name="air", prob=254, param2=0},
		{name="air", prob=254, param2=0},
		{name="stairs:stair_quartz_chiseled", prob=254, param2=23},
		{name="everness:quartz_chiseled", prob=254, param2=0},
		{name="everness:quartz_chiseled", prob=254, param2=0},
		{name="stairs:stair_quartz_chiseled", prob=254, param2=3},
		{name="air", prob=0, param2=0},
		{name="air", prob=0, param2=0},
		{name="air", prob=0, param2=0},
		{name="stairs:stair_outer_quartz_chiseled", prob=254, param2=1},
		{name="stairs:stair_inner_quartz_chiseled", prob=254, param2=1},
		{name="everness:quartz_chiseled", prob=254, param2=0},
		{name="stairs:stair_quartz_chiseled", prob=254, param2=21},
		{name="air", prob=254, param2=0},
		{name="air", prob=254, param2=0},
		{name="air", prob=254, param2=0},
		{name="air", prob=254, param2=0},
		{name="stairs:stair_quartz_chiseled", prob=254, param2=23},
		{name="everness:quartz_chiseled", prob=254, param2=0},
		{name="stairs:stair_inner_quartz_chiseled", prob=254, param2=0},
		{name="stairs:stair_outer_quartz_chiseled", prob=254, param2=0},
		{name="air", prob=0, param2=0},
		{name="air", prob=0, param2=0},
		{name="air", prob=0, param2=0},
		{name="air", prob=0, param2=0},
		{name="air", prob=0, param2=0},
		{name="air", prob=0, param2=0},
		{name="stairs:stair_quartz_chiseled", prob=254, param2=1},
		{name="everness:quartz_chiseled", prob=254, param2=0},
		{name="stairs:stair_inner_quartz_chiseled", prob=254, param2=22},
		{name="stairs:stair_outer_quartz_chiseled", prob=254, param2=22},
		{name="stairs:stair_outer_quartz_chiseled", prob=254, param2=23},
		{name="stairs:stair_inner_quartz_chiseled", prob=254, param2=23},
		{name="everness:quartz_chiseled", prob=254, param2=0},
		{name="stairs:stair_quartz_chiseled", prob=254, param2=3},
		{name="air", prob=0, param2=0},
		{name="air", prob=0, param2=0},
		{name="air", prob=0, param2=0},
		{name="air", prob=0, param2=0},
		{name="air", prob=0, param2=0},
		{name="air", prob=0, param2=0},
		{name="air", prob=0, param2=0},
		{name="air", prob=0, param2=0},
		{name="air", prob=0, param2=0},
		{name="stairs:slab_quartz_chiseled", prob=254, param2=1},
		{name="everness:quartz_chiseled", prob=254, param2=0},
		{name="everness:quartz_chiseled", prob=254, param2=0},
		{name="everness:quartz_chiseled", prob=254, param2=0},
		{name="everness:quartz_chiseled", prob=254, param2=0},
		{name="stairs:slab_quartz_chiseled", prob=254, param2=0},
		{name="air", prob=0, param2=0},
		{name="air", prob=0, param2=0},
		{name="air", prob=0, param2=0},
		{name="air", prob=0, param2=0},
		{name="air", prob=0, param2=0},
		{name="air", prob=0, param2=0},
		{name="air", prob=0, param2=0},
		{name="air", prob=0, param2=0},
		{name="air", prob=0, param2=0},
		{name="air", prob=0, param2=0},
		{name="air", prob=0, param2=0},
		{name="air", prob=0, param2=0},
		{name="stairs:slab_quartz_chiseled", prob=254, param2=3},
		{name="stairs:slab_quartz_chiseled", prob=254, param2=2},
		{name="air", prob=0, param2=0},
		{name="air", prob=0, param2=0},
		{name="air", prob=0, param2=0},
		{name="air", prob=0, param2=0},
		{name="air", prob=0, param2=0},
		{name="air", prob=0, param2=0},
		{name="air", prob=0, param2=0},
		{name="everness:quartz_chiseled", prob=254, param2=0},
		{name="everness:quartz_chiseled", prob=254, param2=0},
		{name="everness:quartz_chiseled", prob=254, param2=0},
		{name="everness:quartz_chiseled", prob=254, param2=0},
		{name="everness:quartz_chiseled", prob=254, param2=0},
		{name="everness:quartz_chiseled", prob=254, param2=0},
		{name="everness:quartz_chiseled", prob=254, param2=0},
		{name="everness:quartz_pillar", prob=254, param2=3},
		{name="everness:quartz_pillar", prob=254, param2=3},
		{name="everness:quartz_chiseled", prob=254, param2=0},
		{name="everness:quartz_chiseled", prob=254, param2=0},
		{name="everness:quartz_chiseled", prob=254, param2=0},
		{name="everness:quartz_chiseled", prob=254, param2=0},
		{name="everness:quartz_chiseled", prob=254, param2=0},
		{name="everness:quartz_chiseled", prob=254, param2=0},
		{name="everness:quartz_chiseled", prob=254, param2=0},
		{name="stairs:stair_quartz_chiseled", prob=254, param2=1},
		{name="everness:quartz_chiseled", prob=254, param2=0},
		{name="everness:quartz_chiseled", prob=254, param2=0},
		{name="everness:quartz_chiseled", prob=254, param2=0},
		{name="everness:quartz_chiseled", prob=254, param2=0},
		{name="everness:quartz_chiseled", prob=254, param2=0},
		{name="everness:quartz_chiseled", prob=254, param2=0},
		{name="everness:quartz_pillar", prob=254, param2=3},
		{name="everness:quartz_pillar", prob=254, param2=3},
		{name="everness:quartz_chiseled", prob=254, param2=0},
		{name="everness:quartz_chiseled", prob=254, param2=0},
		{name="everness:quartz_chiseled", prob=254, param2=0},
		{name="everness:quartz_chiseled", prob=254, param2=0},
		{name="everness:quartz_chiseled", prob=254, param2=0},
		{name="everness:quartz_chiseled", prob=254, param2=0},
		{name="stairs:stair_quartz_chiseled", prob=254, param2=3},
		{name="air", prob=254, param2=0},
		{name="air", prob=254, param2=0},
		{name="air", prob=254, param2=0},
		{name="air", prob=254, param2=0},
		{name="air", prob=254, param2=0},
		{name="air", prob=254, param2=0},
		{name="air", prob=254, param2=0},
		{name="air", prob=254, param2=0},
		{name="air", prob=254, param2=0},
		{name="air", prob=254, param2=0},
		{name="air", prob=254, param2=0},
		{name="air", prob=254, param2=0},
		{name="air", prob=254, param2=0},
		{name="air", prob=254, param2=0},
		{name="air", prob=254, param2=0},
		{name="air", prob=254, param2=0},
		{name="air", prob=254, param2=0},
		{name="air", prob=254, param2=0},
		{name="air", prob=254, param2=0},
		{name="air", prob=254, param2=0},
		{name="air", prob=254, param2=0},
		{name="air", prob=254, param2=0},
		{name="air", prob=254, param2=0},
		{name="air", prob=254, param2=0},
		{name="air", prob=254, param2=0},
		{name="air", prob=254, param2=0},
		{name="air", prob=254, param2=0},
		{name="air", prob=254, param2=0},
		{name="air", prob=254, param2=0},
		{name="air", prob=254, param2=0},
		{name="air", prob=254, param2=0},
		{name="air", prob=254, param2=0},
		{name="air", prob=254, param2=0},
		{name="air", prob=254, param2=0},
		{name="air", prob=254, param2=0},
		{name="air", prob=254, param2=0},
		{name="air", prob=254, param2=0},
		{name="air", prob=254, param2=0},
		{name="air", prob=254, param2=0},
		{name="air", prob=254, param2=0},
		{name="air", prob=254, param2=0},
		{name="air", prob=254, param2=0},
		{name="air", prob=254, param2=0},
		{name="air", prob=254, param2=0},
		{name="air", prob=254, param2=0},
		{name="air", prob=254, param2=0},
		{name="air", prob=254, param2=0},
		{name="air", prob=254, param2=0},
		{name="air", prob=254, param2=0},
		{name="air", prob=254, param2=0},
		{name="air", prob=254, param2=0},
		{name="air", prob=254, param2=0},
		{name="air", prob=254, param2=0},
		{name="air", prob=254, param2=0},
		{name="everness:quartz_block", prob=254, param2=0},
		{name="air", prob=254, param2=0},
		{name="air", prob=254, param2=0},
		{name="everness:quartz_block", prob=254, param2=0},
		{name="air", prob=254, param2=0},
		{name="air", prob=254, param2=0},
		{name="air", prob=254, param2=0},
		{name="air", prob=254, param2=0},
		{name="air", prob=254, param2=0},
		{name="air", prob=254, param2=0},
		{name="air", prob=254, param2=0},
		{name="air", prob=254, param2=0},
		{name="air", prob=254, param2=0},
		{name="air", prob=254, param2=0},
		{name="air", prob=254, param2=0},
		{name="air", prob=254, param2=0},
		{name="air", prob=254, param2=0},
		{name="air", prob=254, param2=0},
		{name="air", prob=254, param2=0},
		{name="air", prob=254, param2=0},
		{name="air", prob=254, param2=0},
		{name="air", prob=254, param2=0},
		{name="air", prob=254, param2=0},
		{name="air", prob=254, param2=0},
		{name="air", prob=254, param2=0},
		{name="air", prob=254, param2=0},
		{name="stairs:stair_quartz_chiseled", prob=254, param2=23},
		{name="everness:quartz_chiseled", prob=254, param2=0},
		{name="stairs:stair_inner_quartz_chiseled", prob=254, param2=21},
		{name="stairs:stair_outer_quartz_chiseled", prob=254, param2=21},
		{name="air", prob=254, param2=0},
		{name="air", prob=254, param2=0},
		{name="air", prob=254, param2=0},
		{name="air", prob=254, param2=0},
		{name="air", prob=254, param2=0},
		{name="air", prob=254, param2=0},
		{name="air", prob=254, param2=0},
		{name="air", prob=254, param2=0},
		{name="stairs:stair_outer_quartz_chiseled", prob=254, param2=20},
		{name="stairs:stair_inner_quartz_chiseled", prob=254, param2=20},
		{name="everness:quartz_chiseled", prob=254, param2=0},
		{name="stairs:stair_quartz_chiseled", prob=254, param2=21},
		{name="air", prob=0, param2=0},
		{name="stairs:stair_quartz_chiseled", prob=254, param2=1},
		{name="everness:quartz_chiseled", prob=254, param2=0},
		{name="everness:quartz_chiseled", prob=254, param2=0},
		{name="stairs:stair_quartz_chiseled", prob=254, param2=21},
		{name="air", prob=254, param2=0},
		{name="air", prob=254, param2=0},
		{name="air", prob=254, param2=0},
		{name="air", prob=254, param2=0},
		{name="air", prob=254, param2=0},
		{name="air", prob=254, param2=0},
		{name="stairs:stair_quartz_chiseled", prob=254, param2=23},
		{name="everness:quartz_chiseled", prob=254, param2=0},
		{name="everness:quartz_chiseled", prob=254, param2=0},
		{name="stairs:stair_quartz_chiseled", prob=254, param2=3},
		{name="air", prob=0, param2=0},
		{name="air", prob=0, param2=0},
		{name="air", prob=0, param2=0},
		{name="stairs:stair_outer_quartz_chiseled", prob=254, param2=2},
		{name="stairs:stair_inner_quartz_chiseled", prob=254, param2=2},
		{name="everness:quartz_chiseled", prob=254, param2=0},
		{name="stairs:stair_quartz_chiseled", prob=254, param2=21},
		{name="air", prob=254, param2=0},
		{name="air", prob=254, param2=0},
		{name="air", prob=254, param2=0},
		{name="air", prob=254, param2=0},
		{name="stairs:stair_quartz_chiseled", prob=254, param2=23},
		{name="everness:quartz_chiseled", prob=254, param2=0},
		{name="stairs:stair_inner_quartz_chiseled", prob=254, param2=3},
		{name="stairs:stair_outer_quartz_chiseled", prob=254, param2=3},
		{name="air", prob=0, param2=0},
		{name="air", prob=0, param2=0},
		{name="air", prob=0, param2=0},
		{name="air", prob=0, param2=0},
		{name="air", prob=0, param2=0},
		{name="air", prob=0, param2=0},
		{name="stairs:stair_quartz_chiseled", prob=254, param2=1},
		{name="everness:quartz_chiseled", prob=254, param2=0},
		{name="stairs:stair_inner_quartz_chiseled", prob=254, param2=21},
		{name="stairs:stair_outer_quartz_chiseled", prob=254, param2=21},
		{name="stairs:stair_outer_quartz_chiseled", prob=254, param2=20},
		{name="stairs:stair_inner_quartz_chiseled", prob=254, param2=20},
		{name="everness:quartz_chiseled", prob=254, param2=0},
		{name="stairs:stair_quartz_chiseled", prob=254, param2=3},
		{name="air", prob=0, param2=0},
		{name="air", prob=0, param2=0},
		{name="air", prob=0, param2=0},
		{name="air", prob=0, param2=0},
		{name="air", prob=0, param2=0},
		{name="air", prob=0, param2=0},
		{name="air", prob=0, param2=0},
		{name="air", prob=0, param2=0},
		{name="air", prob=0, param2=0},
		{name="stairs:slab_quartz_chiseled", prob=254, param2=1},
		{name="everness:quartz_chiseled", prob=254, param2=0},
		{name="everness:quartz_chiseled", prob=254, param2=0},
		{name="everness:quartz_chiseled", prob=254, param2=0},
		{name="everness:quartz_chiseled", prob=254, param2=0},
		{name="stairs:slab_quartz_chiseled", prob=254, param2=1},
		{name="air", prob=0, param2=0},
		{name="air", prob=0, param2=0},
		{name="air", prob=0, param2=0},
		{name="air", prob=0, param2=0},
		{name="air", prob=0, param2=0},
		{name="air", prob=0, param2=0},
		{name="air", prob=0, param2=0},
		{name="air", prob=0, param2=0},
		{name="air", prob=0, param2=0},
		{name="air", prob=0, param2=0},
		{name="air", prob=0, param2=0},
		{name="air", prob=0, param2=0},
		{name="stairs:slab_quartz_chiseled", prob=254, param2=3},
		{name="stairs:slab_quartz_chiseled", prob=254, param2=3},
		{name="air", prob=0, param2=0},
		{name="air", prob=0, param2=0},
		{name="air", prob=0, param2=0},
		{name="air", prob=0, param2=0},
		{name="air", prob=0, param2=0},
		{name="air", prob=0, param2=0},
		{name="air", prob=0, param2=0},
		{name="everness:quartz_chiseled", prob=254, param2=0},
		{name="everness:quartz_chiseled", prob=254, param2=0},
		{name="everness:quartz_chiseled", prob=254, param2=0},
		{name="everness:quartz_chiseled", prob=254, param2=0},
		{name="everness:quartz_chiseled", prob=254, param2=0},
		{name="everness:quartz_chiseled", prob=254, param2=0},
		{name="everness:quartz_chiseled", prob=254, param2=0},
		{name="everness:quartz_chiseled", prob=254, param2=0},
		{name="everness:quartz_chiseled", prob=254, param2=0},
		{name="everness:quartz_chiseled", prob=254, param2=0},
		{name="everness:quartz_chiseled", prob=254, param2=0},
		{name="everness:quartz_chiseled", prob=254, param2=0},
		{name="everness:quartz_chiseled", prob=254, param2=0},
		{name="everness:quartz_chiseled", prob=254, param2=0},
		{name="everness:quartz_chiseled", prob=254, param2=0},
		{name="everness:quartz_chiseled", prob=254, param2=0},
		{name="stairs:stair_quartz_chiseled", prob=254, param2=1},
		{name="everness:quartz_chiseled", prob=254, param2=0},
		{name="everness:quartz_chiseled", prob=254, param2=0},
		{name="everness:quartz_chiseled", prob=254, param2=0},
		{name="everness:quartz_chiseled", prob=254, param2=0},
		{name="everness:quartz_chiseled", prob=254, param2=0},
		{name="everness:quartz_chiseled", prob=254, param2=0},
		{name="everness:quartz_chiseled", prob=254, param2=0},
		{name="everness:quartz_chiseled", prob=254, param2=0},
		{name="everness:quartz_chiseled", prob=254, param2=0},
		{name="everness:quartz_chiseled", prob=254, param2=0},
		{name="everness:quartz_chiseled", prob=254, param2=0},
		{name="everness:quartz_chiseled", prob=254, param2=0},
		{name="everness:quartz_chiseled", prob=254, param2=0},
		{name="everness:quartz_chiseled", prob=254, param2=0},
		{name="stairs:stair_quartz_chiseled", prob=254, param2=3},
		{name="air", prob=0, param2=0},
		{name="everness:quartz_pillar", prob=254, param2=1},
		{name="air", prob=254, param2=0},
		{name="air", prob=254, param2=0},
		{name="air", prob=254, param2=0},
		{name="air", prob=254, param2=0},
		{name="everness:quartz_pillar", prob=254, param2=2},
		{name="air", prob=254, param2=0},
		{name="air", prob=254, param2=0},
		{name="everness:quartz_pillar", prob=254, param2=2},
		{name="air", prob=254, param2=0},
		{name="air", prob=254, param2=0},
		{name="air", prob=254, param2=0},
		{name="air", prob=254, param2=0},
		{name="everness:quartz_pillar", prob=254, param2=1},
		{name="air", prob=0, param2=0},
		{name="air", prob=0, param2=0},
		{name="everness:quartz_pillar", prob=254, param2=1},
		{name="air", prob=254, param2=0},
		{name="air", prob=254, param2=0},
		{name="air", prob=254, param2=0},
		{name="air", prob=254, param2=0},
		{name="everness:quartz_pillar", prob=254, param2=2},
		{name="air", prob=254, param2=0},
		{name="air", prob=254, param2=0},
		{name="everness:quartz_pillar", prob=254, param2=2},
		{name="air", prob=254, param2=0},
		{name="air", prob=254, param2=0},
		{name="air", prob=254, param2=0},
		{name="air", prob=254, param2=0},
		{name="everness:quartz_pillar", prob=254, param2=1},
		{name="air", prob=0, param2=0},
		{name="air", prob=0, param2=0},
		{name="everness:quartz_pillar", prob=254, param2=1},
		{name="air", prob=254, param2=0},
		{name="air", prob=254, param2=0},
		{name="air", prob=254, param2=0},
		{name="air", prob=254, param2=0},
		{name="everness:quartz_pillar", prob=254, param2=2},
		{name="air", prob=254, param2=0},
		{name="air", prob=254, param2=0},
		{name="everness:quartz_pillar", prob=254, param2=2},
		{name="air", prob=254, param2=0},
		{name="air", prob=254, param2=0},
		{name="air", prob=254, param2=0},
		{name="air", prob=254, param2=0},
		{name="everness:quartz_pillar", prob=254, param2=1},
		{name="air", prob=0, param2=0},
		{name="air", prob=0, param2=0},
		{name="everness:quartz_pillar", prob=254, param2=1},
		{name="air", prob=254, param2=0},
		{name="air", prob=254, param2=0},
		{name="air", prob=254, param2=0},
		{name="air", prob=254, param2=0},
		{name="everness:quartz_pillar", prob=254, param2=0},
		{name="everness:quartz_block", prob=254, param2=0},
		{name="everness:quartz_block", prob=254, param2=0},
		{name="everness:quartz_pillar", prob=254, param2=0},
		{name="air", prob=254, param2=0},
		{name="air", prob=254, param2=0},
		{name="air", prob=254, param2=0},
		{name="air", prob=254, param2=0},
		{name="everness:quartz_pillar", prob=254, param2=1},
		{name="air", prob=0, param2=0},
		{name="air", prob=0, param2=0},
		{name="everness:quartz_pillar", prob=254, param2=1},
		{name="air", prob=254, param2=0},
		{name="air", prob=254, param2=0},
		{name="air", prob=254, param2=0},
		{name="air", prob=254, param2=0},
		{name="air", prob=254, param2=0},
		{name="air", prob=254, param2=0},
		{name="air", prob=254, param2=0},
		{name="air", prob=254, param2=0},
		{name="air", prob=254, param2=0},
		{name="air", prob=254, param2=0},
		{name="air", prob=254, param2=0},
		{name="air", prob=254, param2=0},
		{name="everness:quartz_pillar", prob=254, param2=1},
		{name="air", prob=0, param2=0},
		{name="stairs:stair_quartz_chiseled", prob=254, param2=23},
		{name="everness:quartz_chiseled", prob=254, param2=0},
		{name="everness:quartz_chiseled", prob=254, param2=0},
		{name="stairs:stair_quartz_chiseled", prob=254, param2=21},
		{name="air", prob=254, param2=0},
		{name="air", prob=254, param2=0},
		{name="air", prob=254, param2=0},
		{name="air", prob=254, param2=0},
		{name="air", prob=254, param2=0},
		{name="air", prob=254, param2=0},
		{name="air", prob=254, param2=0},
		{name="air", prob=254, param2=0},
		{name="stairs:stair_quartz_chiseled", prob=254, param2=23},
		{name="everness:quartz_chiseled", prob=254, param2=0},
		{name="everness:quartz_chiseled", prob=254, param2=0},
		{name="stairs:stair_quartz_chiseled", prob=254, param2=21},
		{name="air", prob=0, param2=0},
		{name="stairs:stair_outer_quartz_chiseled", prob=254, param2=2},
		{name="stairs:stair_inner_quartz_chiseled", prob=254, param2=2},
		{name="everness:quartz_chiseled", prob=254, param2=0},
		{name="stairs:stair_quartz_chiseled", prob=254, param2=21},
		{name="air", prob=254, param2=0},
		{name="air", prob=254, param2=0},
		{name="air", prob=254, param2=0},
		{name="air", prob=254, param2=0},
		{name="air", prob=254, param2=0},
		{name="air", prob=254, param2=0},
		{name="stairs:stair_quartz_chiseled", prob=254, param2=23},
		{name="everness:quartz_chiseled", prob=254, param2=0},
		{name="stairs:stair_inner_quartz_chiseled", prob=254, param2=3},
		{name="stairs:stair_outer_quartz_chiseled", prob=254, param2=3},
		{name="air", prob=0, param2=0},
		{name="air", prob=0, param2=0},
		{name="air", prob=0, param2=0},
		{name="air", prob=0, param2=0},
		{name="stairs:stair_quartz_chiseled", prob=254, param2=1},
		{name="everness:quartz_chiseled", prob=254, param2=0},
		{name="stairs:stair_inner_quartz_chiseled", prob=254, param2=21},
		{name="stairs:stair_outer_quartz_chiseled", prob=254, param2=21},
		{name="air", prob=254, param2=0},
		{name="air", prob=254, param2=0},
		{name="stairs:stair_outer_quartz_chiseled", prob=254, param2=20},
		{name="stairs:stair_inner_quartz_chiseled", prob=254, param2=20},
		{name="everness:quartz_chiseled", prob=254, param2=0},
		{name="stairs:stair_quartz_chiseled", prob=254, param2=3},
		{name="air", prob=0, param2=0},
		{name="air", prob=0, param2=0},
		{name="air", prob=0, param2=0},
		{name="air", prob=0, param2=0},
		{name="air", prob=0, param2=0},
		{name="air", prob=0, param2=0},
		{name="air", prob=0, param2=0},
		{name="stairs:stair_outer_quartz_chiseled", prob=254, param2=2},
		{name="stairs:stair_inner_quartz_chiseled", prob=254, param2=2},
		{name="everness:quartz_chiseled", prob=254, param2=0},
		{name="stairs:stair_inner_quartz_chiseled", prob=254, param2=21},
		{name="stairs:stair_inner_quartz_chiseled", prob=254, param2=20},
		{name="everness:quartz_chiseled", prob=254, param2=0},
		{name="stairs:stair_inner_quartz_chiseled", prob=254, param2=3},
		{name="stairs:stair_outer_quartz_chiseled", prob=254, param2=3},
		{name="air", prob=0, param2=0},
		{name="air", prob=0, param2=0},
		{name="air", prob=0, param2=0},
		{name="air", prob=0, param2=0},
		{name="air", prob=0, param2=0},
		{name="air", prob=0, param2=0},
		{name="air", prob=0, param2=0},
		{name="air", prob=0, param2=0},
		{name="air", prob=0, param2=0},
		{name="air", prob=0, param2=0},
		{name="stairs:slab_quartz_chiseled", prob=254, param2=1},
		{name="everness:quartz_chiseled", prob=254, param2=0},
		{name="everness:quartz_chiseled", prob=254, param2=0},
		{name="stairs:slab_quartz_chiseled", prob=254, param2=3},
		{name="air", prob=0, param2=0},
		{name="air", prob=0, param2=0},
		{name="air", prob=0, param2=0},
		{name="air", prob=0, param2=0},
		{name="air", prob=0, param2=0},
		{name="air", prob=0, param2=0},
		{name="air", prob=0, param2=0},
		{name="air", prob=0, param2=0},
		{name="air", prob=0, param2=0},
		{name="air", prob=0, param2=0},
		{name="air", prob=0, param2=0},
		{name="air", prob=0, param2=0},
		{name="air", prob=0, param2=0},
		{name="air", prob=0, param2=0},
		{name="air", prob=0, param2=0},
		{name="air", prob=0, param2=0},
		{name="air", prob=0, param2=0},
		{name="air", prob=0, param2=0},
		{name="air", prob=0, param2=0},
		{name="air", prob=0, param2=0},
		{name="air", prob=0, param2=0},
		{name="air", prob=0, param2=0},
		{name="everness:quartz_chiseled", prob=254, param2=0},
		{name="everness:quartz_chiseled", prob=254, param2=0},
		{name="everness:quartz_chiseled", prob=254, param2=0},
		{name="everness:quartz_chiseled", prob=254, param2=0},
		{name="everness:quartz_chiseled", prob=254, param2=0},
		{name="everness:quartz_chiseled", prob=254, param2=0},
		{name="everness:quartz_chiseled", prob=254, param2=0},
		{name="everness:quartz_chiseled", prob=254, param2=0},
		{name="everness:quartz_chiseled", prob=254, param2=0},
		{name="everness:quartz_chiseled", prob=254, param2=0},
		{name="everness:quartz_chiseled", prob=254, param2=0},
		{name="everness:quartz_chiseled", prob=254, param2=0},
		{name="everness:quartz_chiseled", prob=254, param2=0},
		{name="everness:quartz_chiseled", prob=254, param2=0},
		{name="everness:quartz_chiseled", prob=254, param2=0},
		{name="everness:quartz_chiseled", prob=254, param2=0},
		{name="stairs:stair_outer_quartz_chiseled", prob=254, param2=2},
		{name="stairs:stair_inner_quartz_chiseled", prob=254, param2=2},
		{name="everness:quartz_chiseled", prob=254, param2=0},
		{name="everness:quartz_chiseled", prob=254, param2=0},
		{name="everness:quartz_chiseled", prob=254, param2=0},
		{name="everness:quartz_chiseled", prob=254, param2=0},
		{name="everness:quartz_chiseled", prob=254, param2=0},
		{name="everness:quartz_chiseled", prob=254, param2=0},
		{name="everness:quartz_chiseled", prob=254, param2=0},
		{name="everness:quartz_chiseled", prob=254, param2=0},
		{name="everness:quartz_chiseled", prob=254, param2=0},
		{name="everness:quartz_chiseled", prob=254, param2=0},
		{name="everness:quartz_chiseled", prob=254, param2=0},
		{name="everness:quartz_chiseled", prob=254, param2=0},
		{name="stairs:stair_inner_quartz_chiseled", prob=254, param2=3},
		{name="stairs:stair_outer_quartz_chiseled", prob=254, param2=3},
		{name="air", prob=0, param2=0},
		{name="air", prob=0, param2=0},
		{name="air", prob=254, param2=0},
		{name="air", prob=254, param2=0},
		{name="air", prob=254, param2=0},
		{name="air", prob=254, param2=0},
		{name="air", prob=254, param2=0},
		{name="air", prob=254, param2=0},
		{name="air", prob=254, param2=0},
		{name="air", prob=254, param2=0},
		{name="air", prob=254, param2=0},
		{name="air", prob=254, param2=0},
		{name="air", prob=254, param2=0},
		{name="air", prob=254, param2=0},
		{name="air", prob=0, param2=0},
		{name="air", prob=0, param2=0},
		{name="air", prob=0, param2=0},
		{name="air", prob=0, param2=0},
		{name="air", prob=254, param2=0},
		{name="air", prob=254, param2=0},
		{name="air", prob=254, param2=0},
		{name="air", prob=254, param2=0},
		{name="air", prob=254, param2=0},
		{name="air", prob=254, param2=0},
		{name="air", prob=254, param2=0},
		{name="air", prob=254, param2=0},
		{name="air", prob=254, param2=0},
		{name="air", prob=254, param2=0},
		{name="air", prob=254, param2=0},
		{name="air", prob=254, param2=0},
		{name="air", prob=0, param2=0},
		{name="air", prob=0, param2=0},
		{name="air", prob=0, param2=0},
		{name="air", prob=0, param2=0},
		{name="air", prob=254, param2=0},
		{name="air", prob=254, param2=0},
		{name="air", prob=254, param2=0},
		{name="air", prob=254, param2=0},
		{name="air", prob=254, param2=0},
		{name="air", prob=254, param2=0},
		{name="air", prob=254, param2=0},
		{name="air", prob=254, param2=0},
		{name="air", prob=254, param2=0},
		{name="air", prob=254, param2=0},
		{name="air", prob=254, param2=0},
		{name="air", prob=254, param2=0},
		{name="air", prob=0, param2=0},
		{name="air", prob=0, param2=0},
		{name="air", prob=0, param2=0},
		{name="air", prob=0, param2=0},
		{name="air", prob=254, param2=0},
		{name="air", prob=254, param2=0},
		{name="air", prob=254, param2=0},
		{name="air", prob=254, param2=0},
		{name="air", prob=254, param2=0},
		{name="air", prob=254, param2=0},
		{name="air", prob=254, param2=0},
		{name="air", prob=254, param2=0},
		{name="air", prob=254, param2=0},
		{name="air", prob=254, param2=0},
		{name="air", prob=254, param2=0},
		{name="air", prob=254, param2=0},
		{name="air", prob=0, param2=0},
		{name="air", prob=0, param2=0},
		{name="air", prob=0, param2=0},
		{name="air", prob=0, param2=0},
		{name="air", prob=254, param2=0},
		{name="air", prob=254, param2=0},
		{name="air", prob=254, param2=0},
		{name="air", prob=254, param2=0},
		{name="air", prob=254, param2=0},
		{name="air", prob=254, param2=0},
		{name="air", prob=254, param2=0},
		{name="air", prob=254, param2=0},
		{name="air", prob=254, param2=0},
		{name="air", prob=254, param2=0},
		{name="air", prob=254, param2=0},
		{name="air", prob=254, param2=0},
		{name="air", prob=0, param2=0},
		{name="air", prob=0, param2=0},
		{name="stairs:stair_outer_quartz_chiseled", prob=254, param2=23},
		{name="stairs:stair_inner_quartz_chiseled", prob=254, param2=23},
		{name="everness:quartz_chiseled", prob=254, param2=0},
		{name="stairs:stair_quartz_chiseled", prob=254, param2=21},
		{name="air", prob=254, param2=0},
		{name="air", prob=254, param2=0},
		{name="air", prob=254, param2=0},
		{name="air", prob=254, param2=0},
		{name="air", prob=254, param2=0},
		{name="air", prob=254, param2=0},
		{name="air", prob=254, param2=0},
		{name="air", prob=254, param2=0},
		{name="stairs:stair_quartz_chiseled", prob=254, param2=23},
		{name="everness:quartz_chiseled", prob=254, param2=0},
		{name="stairs:stair_inner_quartz_chiseled", prob=254, param2=22},
		{name="stairs:stair_outer_quartz_chiseled", prob=254, param2=22},
		{name="air", prob=0, param2=0},
		{name="air", prob=0, param2=0},
		{name="stairs:stair_quartz_chiseled", prob=254, param2=1},
		{name="everness:quartz_chiseled", prob=254, param2=0},
		{name="stairs:stair_inner_quartz_chiseled", prob=254, param2=21},
		{name="stairs:stair_outer_quartz_chiseled", prob=254, param2=21},
		{name="air", prob=254, param2=0},
		{name="air", prob=254, param2=0},
		{name="air", prob=254, param2=0},
		{name="air", prob=254, param2=0},
		{name="stairs:stair_outer_quartz_chiseled", prob=254, param2=20},
		{name="stairs:stair_inner_quartz_chiseled", prob=254, param2=20},
		{name="everness:quartz_chiseled", prob=254, param2=0},
		{name="stairs:stair_quartz_chiseled", prob=254, param2=3},
		{name="air", prob=0, param2=0},
		{name="air", prob=0, param2=0},
		{name="air", prob=0, param2=0},
		{name="air", prob=0, param2=0},
		{name="air", prob=0, param2=0},
		{name="stairs:stair_outer_quartz_chiseled", prob=254, param2=2},
		{name="stairs:stair_inner_quartz_chiseled", prob=254, param2=2},
		{name="everness:quartz_chiseled", prob=254, param2=0},
		{name="stairs:stair_inner_quartz_chiseled", prob=254, param2=21},
		{name="stairs:stair_quartz_chiseled", prob=254, param2=20},
		{name="stairs:stair_quartz_chiseled", prob=254, param2=20},
		{name="stairs:stair_inner_quartz_chiseled", prob=254, param2=20},
		{name="everness:quartz_chiseled", prob=254, param2=0},
		{name="stairs:stair_inner_quartz_chiseled", prob=254, param2=3},
		{name="stairs:stair_outer_quartz_chiseled", prob=254, param2=3},
		{name="air", prob=0, param2=0},
		{name="air", prob=0, param2=0},
		{name="air", prob=0, param2=0},
		{name="air", prob=0, param2=0},
		{name="air", prob=0, param2=0},
		{name="air", prob=0, param2=0},
		{name="air", prob=0, param2=0},
		{name="air", prob=0, param2=0},
		{name="stairs:stair_outer_quartz_chiseled", prob=254, param2=2},
		{name="stairs:stair_inner_quartz_chiseled", prob=254, param2=2},
		{name="everness:quartz_chiseled", prob=254, param2=0},
		{name="everness:quartz_chiseled", prob=254, param2=0},
		{name="stairs:stair_inner_quartz_chiseled", prob=254, param2=3},
		{name="stairs:stair_outer_quartz_chiseled", prob=254, param2=3},
		{name="air", prob=0, param2=0},
		{name="air", prob=0, param2=0},
		{name="air", prob=0, param2=0},
		{name="air", prob=0, param2=0},
		{name="air", prob=0, param2=0},
		{name="air", prob=0, param2=0},
		{name="air", prob=0, param2=0},
		{name="air", prob=0, param2=0},
		{name="air", prob=0, param2=0},
		{name="air", prob=0, param2=0},
		{name="air", prob=0, param2=0},
		{name="air", prob=0, param2=0},
		{name="stairs:slab_quartz_chiseled", prob=254, param2=3},
		{name="stairs:slab_quartz_chiseled", prob=254, param2=3},
		{name="air", prob=0, param2=0},
		{name="air", prob=0, param2=0},
		{name="air", prob=0, param2=0},
		{name="air", prob=0, param2=0},
		{name="air", prob=0, param2=0},
		{name="air", prob=0, param2=0},
		{name="air", prob=0, param2=0},
		{name="air", prob=0, param2=0},
		{name="air", prob=0, param2=0},
		{name="air", prob=0, param2=0},
		{name="air", prob=0, param2=0},
		{name="air", prob=0, param2=0},
		{name="air", prob=0, param2=0},
		{name="air", prob=0, param2=0},
		{name="air", prob=0, param2=0},
		{name="air", prob=0, param2=0},
		{name="air", prob=0, param2=0},
		{name="air", prob=0, param2=0},
		{name="air", prob=0, param2=0},
		{name="air", prob=0, param2=0},
		{name="air", prob=0, param2=0},
		{name="air", prob=0, param2=0},
		{name="air", prob=0, param2=0},
		{name="air", prob=0, param2=0},
		{name="everness:quartz_chiseled", prob=254, param2=0},
		{name="everness:quartz_chiseled", prob=254, param2=0},
		{name="everness:quartz_chiseled", prob=254, param2=0},
		{name="everness:quartz_chiseled", prob=254, param2=0},
		{name="everness:quartz_chiseled", prob=254, param2=0},
		{name="everness:quartz_chiseled", prob=254, param2=0},
		{name="everness:quartz_chiseled", prob=254, param2=0},
		{name="everness:quartz_chiseled", prob=254, param2=0},
		{name="everness:quartz_chiseled", prob=254, param2=0},
		{name="everness:quartz_chiseled", prob=254, param2=0},
		{name="everness:quartz_chiseled", prob=254, param2=0},
		{name="everness:quartz_chiseled", prob=254, param2=0},
		{name="everness:quartz_chiseled", prob=254, param2=0},
		{name="everness:quartz_chiseled", prob=254, param2=0},
		{name="air", prob=0, param2=0},
		{name="air", prob=0, param2=0},
		{name="stairs:stair_quartz_chiseled", prob=254, param2=1},
		{name="everness:quartz_chiseled", prob=254, param2=0},
		{name="everness:quartz_chiseled", prob=254, param2=0},
		{name="everness:quartz_chiseled", prob=254, param2=0},
		{name="everness:quartz_chiseled", prob=254, param2=0},
		{name="everness:quartz_chiseled", prob=254, param2=0},
		{name="everness:quartz_chiseled", prob=254, param2=0},
		{name="everness:quartz_chiseled", prob=254, param2=0},
		{name="everness:quartz_chiseled", prob=254, param2=0},
		{name="everness:quartz_chiseled", prob=254, param2=0},
		{name="everness:quartz_chiseled", prob=254, param2=0},
		{name="everness:quartz_chiseled", prob=254, param2=0},
		{name="everness:quartz_chiseled", prob=254, param2=0},
		{name="stairs:stair_quartz_chiseled", prob=254, param2=3},
		{name="air", prob=0, param2=0},
		{name="air", prob=0, param2=0},
		{name="air", prob=0, param2=0},
		{name="air", prob=254, param2=0},
		{name="air", prob=254, param2=0},
		{name="air", prob=254, param2=0},
		{name="air", prob=254, param2=0},
		{name="air", prob=254, param2=0},
		{name="air", prob=254, param2=0},
		{name="air", prob=254, param2=0},
		{name="air", prob=254, param2=0},
		{name="air", prob=254, param2=0},
		{name="air", prob=254, param2=0},
		{name="air", prob=254, param2=0},
		{name="air", prob=254, param2=0},
		{name="air", prob=0, param2=0},
		{name="air", prob=0, param2=0},
		{name="air", prob=0, param2=0},
		{name="air", prob=0, param2=0},
		{name="air", prob=254, param2=0},
		{name="air", prob=254, param2=0},
		{name="air", prob=254, param2=0},
		{name="air", prob=254, param2=0},
		{name="air", prob=254, param2=0},
		{name="air", prob=254, param2=0},
		{name="air", prob=254, param2=0},
		{name="air", prob=254, param2=0},
