schematic = {
	size = {x=11, y=13, z=13},
	yslice_prob = {
		{ypos=0, prob=254},
		{ypos=1, prob=254},
		{ypos=2, prob=254},
		{ypos=3, prob=254},
		{ypos=4, prob=254},
		{ypos=5, prob=254},
		{ypos=6, prob=254},
		{ypos=7, prob=254},
		{ypos=8, prob=254},
		{ypos=9, prob=254},
		{ypos=10, prob=254},
		{ypos=11, prob=254},
		{ypos=12, prob=254},
	},
	data = {
		{name="everness:forsaken_desert_brick", prob=254, param2=0},
		{name="everness:forsaken_desert_cobble", prob=254, param2=0},
		{name="everness:forsaken_desert_brick", prob=254, param2=0},
		{name="everness:forsaken_desert_cobble", prob=254, param2=0},
		{name="everness:forsaken_desert_brick", prob=254, param2=0},
		{name="everness:forsaken_desert_brick", prob=254, param2=0},
		{name="everness:forsaken_desert_cobble", prob=254, param2=0},
		{name="everness:forsaken_desert_cobble", prob=254, param2=0},
		{name="everness:forsaken_desert_brick", prob=254, param2=0},
		{name="everness:forsaken_desert_cobble", prob=254, param2=0},
		{name="everness:forsaken_desert_cobble", prob=254, param2=0},
		{name="everness:forsaken_desert_cobble", prob=254, param2=0},
		{name="everness:forsaken_desert_cobble", prob=254, param2=0},
		{name="everness:forsaken_desert_cobble", prob=254, param2=0},
		{name="everness:forsaken_desert_brick", prob=254, param2=0},
		{name="everness:forsaken_desert_brick", prob=254, param2=0},
		{name="everness:forsaken_desert_cobble", prob=254, param2=0},
		{name="everness:forsaken_desert_brick", prob=254, param2=0},
		{name="everness:forsaken_desert_cobble", prob=254, param2=0},
		{name="everness:forsaken_desert_brick", prob=254, param2=0},
		{name="everness:forsaken_desert_cobble", prob=254, param2=0},
		{name="everness:forsaken_desert_cobble", prob=254, param2=0},
		{name="air", prob=0, param2=0},
		{name="air", prob=0, param2=0},
		{name="air", prob=0, param2=0},
		{name="air", prob=0, param2=0},
		{name="air", prob=0, param2=0},
		{name="air", prob=0, param2=0},
		{name="air", prob=0, param2=0},
		{name="air", prob=0, param2=0},
		{name="air", prob=0, param2=0},
		{name="air", prob=0, param2=0},
		{name="air", prob=0, param2=0},
		{name="air", prob=0, param2=0},
		{name="air", prob=0, param2=0},
		{name="air", prob=0, param2=0},
		{name="air", prob=0, param2=0},
		{name="air", prob=0, param2=0},
		{name="air", prob=0, param2=0},
		{name="air", prob=0, param2=0},
		{name="air", prob=0, param2=0},
		{name="air", prob=0, param2=0},
		{name="air", prob=0, param2=0},
		{name="air", prob=0, param2=0},
		{name="air", prob=0, param2=0},
		{name="air", prob=0, param2=0},
		{name="air", prob=0, param2=0},
		{name="air", prob=0, param2=0},
		{name="air", prob=0, param2=0},
		{name="air", prob=0, param2=0},
		{name="air", prob=0, param2=0},
		{name="air", prob=0, param2=0},
		{name="air", prob=0, param2=0},
		{name="air", prob=0, param2=0},
		{name="air", prob=0, param2=0},
		{name="air", prob=0, param2=0},
		{name="air", prob=0, param2=0},
		{name="air", prob=0, param2=0},
		{name="air", prob=0, param2=0},
		{name="air", prob=0, param2=0},
		{name="air", prob=0, param2=0},
		{name="air", prob=0, param2=0},
		{name="air", prob=0, param2=0},
		{name="air", prob=0, param2=0},
		{name="air", prob=0, param2=0},
		{name="air", prob=0, param2=0},
		{name="air", prob=0, param2=0},
		{name="air", prob=0, param2=0},
		{name="air", prob=0, param2=0},
		{name="air", prob=0, param2=0},
		{name="air", prob=0, param2=0},
		{name="air", prob=0, param2=0},
		{name="air", prob=0, param2=0},
		{name="air", prob=0, param2=0},
		{name="air", prob=0, param2=0},
		{name="air", prob=0, param2=0},
		{name="air", prob=0, param2=0},
		{name="air", prob=0, param2=0},
		{name="stairs:stair_forsaken_desert_chiseled_stone", prob=254, param2=20},
		{name="air", prob=0, param2=0},
		{name="stairs:stair_forsaken_desert_chiseled_stone", prob=254, param2=20},
		{name="air", prob=0, param2=0},
		{name="stairs:stair_forsaken_desert_chiseled_stone", prob=254, param2=20},
		{name="air", prob=0, param2=0},
		{name="stairs:stair_forsaken_desert_chiseled_stone", prob=254, param2=20},
		{name="air", prob=0, param2=0},
		{name="stairs:stair_forsaken_desert_chiseled_stone", prob=254, param2=20},
		{name="air", prob=0, param2=0},
		{name="everness:forsaken_desert_cobble", prob=254, param2=0},
		{name="everness:forsaken_desert_cobble", prob=254, param2=0},
		{name="everness:forsaken_desert_cobble", prob=254, param2=0},
		{name="everness:forsaken_desert_cobble", prob=254, param2=0},
		{name="everness:forsaken_desert_brick", prob=254, param2=0},
		{name="everness:forsaken_desert_cobble", prob=254, param2=0},
		{name="everness:forsaken_desert_cobble", prob=254, param2=0},
		{name="everness:forsaken_desert_cobble", prob=254, param2=0},
		{name="everness:forsaken_desert_cobble", prob=254, param2=0},
		{name="everness:forsaken_desert_cobble", prob=254, param2=0},
		{name="everness:forsaken_desert_cobble", prob=254, param2=0},
		{name="air", prob=0, param2=0},
		{name="air", prob=0, param2=0},
		{name="air", prob=0, param2=0},
		{name="air", prob=0, param2=0},
		{name="air", prob=0, param2=0},
		{name="air", prob=0, param2=0},
		{name="air", prob=0, param2=0},
		{name="air", prob=0, param2=0},
		{name="air", prob=0, param2=0},
		{name="air", prob=0, param2=0},
		{name="air", prob=0, param2=0},
		{name="air", prob=0, param2=0},
		{name="air", prob=0, param2=0},
		{name="air", prob=0, param2=0},
		{name="air", prob=0, param2=0},
		{name="air", prob=0, param2=0},
		{name="air", prob=0, param2=0},
		{name="air", prob=0, param2=0},
		{name="air", prob=0, param2=0},
		{name="air", prob=0, param2=0},
		{name="air", prob=0, param2=0},
		{name="air", prob=0, param2=0},
		{name="air", prob=0, param2=0},
		{name="air", prob=0, param2=0},
		{name="air", prob=0, param2=0},
		{name="air", prob=0, param2=0},
		{name="air", prob=0, param2=0},
		{name="air", prob=0, param2=0},
		{name="air", prob=0, param2=0},
		{name="air", prob=0, param2=0},
		{name="air", prob=0, param2=0},
		{name="air", prob=0, param2=0},
		{name="air", prob=0, param2=0},
		{name="air", prob=0, param2=0},
		{name="air", prob=0, param2=0},
		{name="air", prob=0, param2=0},
		{name="air", prob=0, param2=0},
		{name="air", prob=0, param2=0},
		{name="air", prob=0, param2=0},
		{name="air", prob=0, param2=0},
		{name="air", prob=0, param2=0},
		{name="air", prob=0, param2=0},
		{name="air", prob=0, param2=0},
		{name="air", prob=0, param2=0},
		{name="everness:forsaken_desert_brick", prob=254, param2=0},
		{name="everness:forsaken_desert_brick", prob=254, param2=0},
		{name="everness:forsaken_desert_brick", prob=254, param2=0},
		{name="everness:forsaken_desert_cobble", prob=254, param2=0},
		{name="everness:forsaken_desert_cobble", prob=254, param2=0},
		{name="everness:forsaken_desert_brick", prob=254, param2=0},
		{name="everness:forsaken_desert_brick", prob=254, param2=0},
		{name="everness:forsaken_desert_brick", prob=254, param2=0},
		{name="everness:forsaken_desert_cobble", prob=254, param2=0},
		{name="everness:forsaken_desert_cobble", prob=254, param2=0},
		{name="everness:forsaken_desert_cobble", prob=254, param2=0},
		{name="everness:forsaken_desert_cobble", prob=254, param2=0},
		{name="everness:forsaken_desert_cobble", prob=254, param2=0},
		{name="everness:forsaken_desert_cobble", prob=254, param2=0},
		{name="everness:forsaken_desert_cobble", prob=254, param2=0},
		{name="everness:forsaken_desert_brick", prob=254, param2=0},
		{name="everness:forsaken_desert_cobble", prob=254, param2=0},
		{name="everness:forsaken_desert_cobble", prob=254, param2=0},
		{name="everness:forsaken_desert_cobble", prob=254, param2=0},
		{name="everness:forsaken_desert_cobble", prob=254, param2=0},
		{name="everness:forsaken_desert_brick", prob=254, param2=0},
		{name="everness:forsaken_desert_brick", prob=254, param2=0},
		{name="air", prob=0, param2=0},
		{name="everness:forsaken_desert_brick_red", prob=254, param2=0},
		{name="air", prob=0, param2=0},
		{name="everness:forsaken_desert_brick_red", prob=254, param2=0},
		{name="air", prob=0, param2=0},
		{name="air", prob=0, param2=0},
		{name="air", prob=0, param2=0},
		{name="everness:forsaken_desert_brick_red", prob=254, param2=0},
		{name="air", prob=0, param2=0},
		{name="everness:forsaken_desert_brick_red", prob=254, param2=0},
		{name="air", prob=0, param2=0},
		{name="air", prob=0, param2=0},
		{name="everness:forsaken_desert_cobble", prob=254, param2=0},
		{name="air", prob=0, param2=0},
		{name="everness:forsaken_desert_brick", prob=254, param2=0},
		{name="air", prob=0, param2=0},
		{name="air", prob=0, param2=0},
		{name="air", prob=0, param2=0},
		{name="everness:forsaken_desert_brick", prob=254, param2=0},
		{name="air", prob=0, param2=0},
		{name="everness:forsaken_desert_cobble", prob=254, param2=0},
		{name="air", prob=0, param2=0},
		{name="air", prob=0, param2=0},
		{name="everness:forsaken_desert_cobble", prob=254, param2=0},
		{name="air", prob=0, param2=0},
		{name="everness:forsaken_desert_cobble", prob=254, param2=0},
		{name="air", prob=0, param2=0},
		{name="air", prob=0, param2=0},
		{name="air", prob=0, param2=0},
		{name="everness:forsaken_desert_cobble", prob=254, param2=0},
		{name="air", prob=0, param2=0},
		{name="everness:forsaken_desert_brick", prob=254, param2=0},
		{name="air", prob=0, param2=0},
		{name="air", prob=0, param2=0},
		{name="everness:forsaken_desert_cobble", prob=254, param2=0},
		{name="air", prob=0, param2=0},
		{name="everness:forsaken_desert_cobble", prob=254, param2=0},
		{name="air", prob=0, param2=0},
		{name="air", prob=0, param2=0},
		{name="air", prob=0, param2=0},
		{name="everness:forsaken_desert_brick", prob=254, param2=0},
		{name="air", prob=0, param2=0},
		{name="everness:forsaken_desert_brick", prob=254, param2=0},
		{name="air", prob=0, param2=0},
		{name="air", prob=0, param2=0},
		{name="everness:forsaken_desert_brick_red", prob=254, param2=0},
		{name="air", prob=0, param2=0},
		{name="everness:forsaken_desert_brick_red", prob=254, param2=0},
		{name="air", prob=0, param2=0},
		{name="air", prob=0, param2=0},
		{name="air", prob=0, param2=0},
		{name="everness:forsaken_desert_brick_red", prob=254, param2=0},
		{name="air", prob=0, param2=0},
		{name="everness:forsaken_desert_brick_red", prob=254, param2=0},
		{name="air", prob=0, param2=0},
		{name="stairs:stair_forsaken_desert_chiseled_stone", prob=254, param2=23},
		{name="everness:forsaken_desert_engraved_stone", prob=254, param2=0},
		{name="everness:forsaken_desert_engraved_stone", prob=254, param2=0},
		{name="everness:forsaken_desert_engraved_stone", prob=254, param2=0},
		{name="everness:forsaken_desert_engraved_stone", prob=254, param2=0},
		{name="everness:forsaken_desert_engraved_stone", prob=254, param2=0},
		{name="everness:forsaken_desert_engraved_stone", prob=254, param2=0},
		{name="everness:forsaken_desert_engraved_stone", prob=254, param2=0},
		{name="everness:forsaken_desert_engraved_stone", prob=254, param2=0},
		{name="everness:forsaken_desert_engraved_stone", prob=254, param2=0},
		{name="stairs:stair_forsaken_desert_chiseled_stone", prob=254, param2=21},
		{name="everness:forsaken_desert_brick", prob=254, param2=0},
		{name="everness:forsaken_desert_cobble", prob=254, param2=0},
		{name="everness:forsaken_desert_cobble", prob=254, param2=0},
		{name="everness:forsaken_desert_cobble", prob=254, param2=0},
		{name="everness:forsaken_desert_cobble", prob=254, param2=0},
		{name="everness:forsaken_desert_cobble", prob=254, param2=0},
		{name="everness:forsaken_desert_brick", prob=254, param2=0},
		{name="everness:forsaken_desert_cobble", prob=254, param2=0},
		{name="everness:forsaken_desert_cobble", prob=254, param2=0},
		{name="everness:forsaken_desert_cobble", prob=254, param2=0},
		{name="everness:forsaken_desert_cobble", prob=254, param2=0},
		{name="air", prob=0, param2=0},
		{name="air", prob=0, param2=0},
		{name="air", prob=0, param2=0},
		{name="air", prob=0, param2=0},
		{name="air", prob=0, param2=0},
		{name="air", prob=0, param2=0},
		{name="air", prob=0, param2=0},
		{name="air", prob=0, param2=0},
		{name="air", prob=0, param2=0},
		{name="air", prob=0, param2=0},
		{name="air", prob=0, param2=0},
		{name="air", prob=0, param2=0},
		{name="air", prob=0, param2=0},
		{name="air", prob=0, param2=0},
		{name="air", prob=0, param2=0},
		{name="air", prob=0, param2=0},
		{name="air", prob=0, param2=0},
		{name="air", prob=0, param2=0},
		{name="air", prob=0, param2=0},
		{name="air", prob=0, param2=0},
		{name="air", prob=0, param2=0},
		{name="air", prob=0, param2=0},
		{name="air", prob=0, param2=0},
		{name="air", prob=0, param2=0},
		{name="air", prob=0, param2=0},
		{name="air", prob=0, param2=0},
		{name="air", prob=0, param2=0},
		{name="air", prob=0, param2=0},
		{name="air", prob=0, param2=0},
		{name="air", prob=0, param2=0},
		{name="air", prob=0, param2=0},
		{name="air", prob=0, param2=0},
		{name="air", prob=0, param2=0},
		{name="air", prob=0, param2=0},
		{name="air", prob=0, param2=0},
		{name="air", prob=0, param2=0},
		{name="air", prob=0, param2=0},
		{name="air", prob=0, param2=0},
		{name="air", prob=0, param2=0},
		{name="air", prob=0, param2=0},
		{name="air", prob=0, param2=0},
		{name="air", prob=0, param2=0},
		{name="air", prob=0, param2=0},
		{name="air", prob=0, param2=0},
		{name="everness:forsaken_desert_cobble", prob=254, param2=0},
		{name="everness:forsaken_desert_brick", prob=254, param2=0},
		{name="everness:forsaken_desert_cobble", prob=254, param2=0},
		{name="everness:forsaken_desert_brick", prob=254, param2=0},
		{name="everness:forsaken_desert_brick", prob=254, param2=0},
		{name="everness:forsaken_desert_cobble", prob=254, param2=0},
		{name="everness:forsaken_desert_brick", prob=254, param2=0},
		{name="everness:forsaken_desert_cobble", prob=254, param2=0},
		{name="everness:forsaken_desert_brick", prob=254, param2=0},
		{name="everness:forsaken_desert_cobble", prob=254, param2=0},
		{name="everness:forsaken_desert_brick", prob=254, param2=0},
		{name="everness:forsaken_desert_cobble", prob=254, param2=0},
		{name="everness:forsaken_desert_brick", prob=254, param2=0},
		{name="everness:forsaken_desert_cobble", prob=254, param2=0},
		{name="everness:forsaken_desert_brick", prob=254, param2=0},
		{name="everness:forsaken_desert_cobble", prob=254, param2=0},
		{name="everness:forsaken_desert_cobble", prob=254, param2=0},
		{name="everness:forsaken_desert_cobble", prob=254, param2=0},
		{name="everness:forsaken_desert_brick", prob=254, param2=0},
		{name="everness:forsaken_desert_cobble", prob=254, param2=0},
		{name="everness:forsaken_desert_cobble", prob=254, param2=0},
		{name="everness:forsaken_desert_cobble", prob=254, param2=0},
		{name="air", prob=0, param2=0},
		{name="air", prob=0, param2=0},
		{name="everness:forsaken_desert_engraved_stone", prob=254, param2=0},
		{name="everness:forsaken_desert_engraved_stone", prob=254, param2=0},
		{name="everness:forsaken_desert_engraved_stone", prob=254, param2=0},
		{name="everness:forsaken_desert_engraved_stone", prob=254, param2=0},
		{name="everness:forsaken_desert_engraved_stone", prob=254, param2=0},
		{name="everness:forsaken_desert_engraved_stone", prob=254, param2=0},
		{name="everness:forsaken_desert_engraved_stone", prob=254, param2=0},
		{name="air", prob=0, param2=0},
		{name="air", prob=0, param2=0},
		{name="air", prob=0, param2=0},
		{name="air", prob=0, param2=0},
		{name="everness:forsaken_desert_cobble", prob=254, param2=0},
		{name="everness:forsaken_desert_cobble", prob=254, param2=0},
		{name="everness:forsaken_desert_brick", prob=254, param2=0},
		{name="everness:forsaken_desert_brick", prob=254, param2=0},
		{name="everness:forsaken_desert_cobble", prob=254, param2=0},
		{name="everness:forsaken_desert_cobble", prob=254, param2=0},
		{name="everness:forsaken_desert_brick", prob=254, param2=0},
		{name="air", prob=0, param2=0},
		{name="air", prob=0, param2=0},
		{name="air", prob=0, param2=0},
		{name="air", prob=0, param2=0},
		{name="everness:forsaken_desert_brick", prob=254, param2=0},
		{name="everness:forsaken_desert_cobble", prob=254, param2=0},
		{name="everness:forsaken_desert_cobble", prob=254, param2=0},
		{name="everness:forsaken_desert_cobble", prob=254, param2=0},
		{name="everness:forsaken_desert_brick", prob=254, param2=0},
		{name="everness:forsaken_desert_brick", prob=254, param2=0},
		{name="everness:forsaken_desert_brick", prob=254, param2=0},
		{name="air", prob=0, param2=0},
		{name="air", prob=0, param2=0},
		{name="air", prob=0, param2=0},
		{name="air", prob=0, param2=0},
		{name="everness:forsaken_desert_cobble", prob=254, param2=0},
		{name="everness:forsaken_desert_brick", prob=254, param2=0},
		{name="everness:forsaken_desert_cobble", prob=254, param2=0},
		{name="everness:forsaken_desert_brick", prob=254, param2=0},
		{name="everness:forsaken_desert_brick", prob=254, param2=0},
		{name="everness:forsaken_desert_cobble", prob=254, param2=0},
		{name="everness:forsaken_desert_cobble", prob=254, param2=0},
		{name="air", prob=0, param2=0},
		{name="air", prob=0, param2=0},
		{name="air", prob=0, param2=0},
		{name="air", prob=0, param2=0},
		{name="everness:forsaken_desert_brick", prob=254, param2=0},
		{name="everness:forsaken_desert_brick", prob=254, param2=0},
		{name="everness:forsaken_desert_cobble", prob=254, param2=0},
		{name="everness:forsaken_desert_brick", prob=254, param2=0},
		{name="everness:forsaken_desert_cobble", prob=254, param2=0},
		{name="everness:forsaken_desert_brick", prob=254, param2=0},
		{name="everness:forsaken_desert_cobble", prob=254, param2=0},
		{name="air", prob=0, param2=0},
		{name="air", prob=0, param2=0},
		{name="air", prob=0, param2=0},
		{name="everness:forsaken_desert_engraved_stone", prob=254, param2=0},
		{name="everness:mineral_torch", prob=126, param2=1},
		{name="air", prob=254, param2=0},
		{name="air", prob=254, param2=0},
		{name="air", prob=254, param2=0},
		{name="air", prob=254, param2=0},
		{name="air", prob=254, param2=0},
		{name="everness:mineral_torch", prob=126, param2=1},
		{name="everness:forsaken_desert_engraved_stone", prob=254, param2=0},
		{name="air", prob=0, param2=0},
		{name="everness:forsaken_desert_brick", prob=254, param2=0},
		{name="everness:forsaken_desert_brick", prob=254, param2=0},
		{name="air", prob=254, param2=0},
		{name="air", prob=254, param2=0},
		{name="air", prob=254, param2=0},
		{name="air", prob=254, param2=0},
		{name="air", prob=254, param2=0},
		{name="air", prob=254, param2=0},
		{name="air", prob=254, param2=0},
		{name="everness:forsaken_desert_cobble", prob=254, param2=0},
		{name="everness:forsaken_desert_cobble", prob=254, param2=0},
		{name="air", prob=0, param2=0},
		{name="air", prob=0, param2=0},
		{name="everness:forsaken_desert_brick", prob=254, param2=0},
		{name="everness:forsaken_desert_cobble", prob=254, param2=0},
		{name="everness:forsaken_desert_brick", prob=254, param2=0},
		{name="everness:forsaken_desert_brick", prob=254, param2=0},
		{name="everness:forsaken_desert_brick", prob=254, param2=0},
		{name="everness:forsaken_desert_cobble", prob=254, param2=0},
		{name="everness:forsaken_desert_cobble", prob=254, param2=0},
		{name="air", prob=0, param2=0},
		{name="air", prob=0, param2=0},
		{name="air", prob=0, param2=0},
		{name="air", prob=0, param2=0},
		{name="air", prob=0, param2=0},
		{name="air", prob=0, param2=0},
		{name="air", prob=0, param2=0},
		{name="air", prob=0, param2=0},
		{name="air", prob=0, param2=0},
		{name="air", prob=0, param2=0},
		{name="air", prob=0, param2=0},
		{name="air", prob=0, param2=0},
		{name="air", prob=0, param2=0},
		{name="air", prob=0, param2=0},
		{name="air", prob=0, param2=0},
		{name="air", prob=0, param2=0},
		{name="air", prob=0, param2=0},
		{name="air", prob=0, param2=0},
		{name="air", prob=0, param2=0},
		{name="air", prob=0, param2=0},
		{name="air", prob=0, param2=0},
		{name="air", prob=0, param2=0},
		{name="air", prob=0, param2=0},
		{name="air", prob=0, param2=0},
		{name="air", prob=0, param2=0},
		{name="air", prob=0, param2=0},
		{name="air", prob=0, param2=0},
		{name="air", prob=0, param2=0},
		{name="air", prob=0, param2=0},
		{name="air", prob=0, param2=0},
		{name="air", prob=0, param2=0},
		{name="air", prob=0, param2=0},
		{name="air", prob=0, param2=0},
		{name="air", prob=0, param2=0},
		{name="air", prob=0, param2=0},
		{name="everness:forsaken_desert_cobble", prob=254, param2=0},
		{name="everness:forsaken_desert_cobble", prob=254, param2=0},
		{name="everness:forsaken_desert_brick", prob=254, param2=0},
		{name="everness:forsaken_desert_cobble", prob=254, param2=0},
		{name="everness:forsaken_desert_brick", prob=254, param2=0},
		{name="everness:forsaken_desert_brick", prob=254, param2=0},
		{name="everness:forsaken_desert_brick", prob=254, param2=0},
		{name="everness:forsaken_desert_cobble", prob=254, param2=0},
		{name="everness:forsaken_desert_brick", prob=254, param2=0},
		{name="everness:forsaken_desert_brick", prob=254, param2=0},
		{name="everness:forsaken_desert_brick", prob=254, param2=0},
		{name="everness:forsaken_desert_brick", prob=254, param2=0},
		{name="everness:forsaken_desert_brick", prob=254, param2=0},
		{name="everness:forsaken_desert_brick", prob=254, param2=0},
		{name="everness:forsaken_desert_cobble", prob=254, param2=0},
		{name="everness:forsaken_desert_brick", prob=254, param2=0},
		{name="everness:forsaken_desert_cobble", prob=254, param2=0},
		{name="everness:forsaken_desert_cobble", prob=254, param2=0},
		{name="everness:forsaken_desert_cobble", prob=254, param2=0},
		{name="everness:forsaken_desert_brick", prob=254, param2=0},
		{name="everness:forsaken_desert_cobble", prob=254, param2=0},
		{name="everness:forsaken_desert_brick", prob=254, param2=0},
		{name="air", prob=0, param2=0},
		{name="everness:forsaken_desert_brick_red", prob=254, param2=0},
		{name="everness:forsaken_desert_engraved_stone", prob=254, param2=0},
		{name="air", prob=254, param2=0},
		{name="air", prob=254, param2=0},
		{name="air", prob=254, param2=0},
		{name="air", prob=254, param2=0},
		{name="air", prob=254, param2=0},
		{name="everness:forsaken_desert_engraved_stone", prob=254, param2=0},
		{name="everness:forsaken_desert_brick_red", prob=254, param2=0},
		{name="air", prob=0, param2=0},
		{name="air", prob=0, param2=0},
		{name="everness:forsaken_desert_cobble", prob=254, param2=0},
		{name="everness:forsaken_desert_brick", prob=254, param2=0},
		{name="stairs:slab_forsaken_desert_chiseled_stone", prob=254, param2=2},
		{name="stairs:slab_forsaken_desert_chiseled_stone", prob=254, param2=2},
		{name="stairs:slab_forsaken_desert_chiseled_stone", prob=254, param2=2},
		{name="stairs:slab_forsaken_desert_chiseled_stone", prob=254, param2=2},
		{name="stairs:slab_forsaken_desert_chiseled_stone", prob=254, param2=2},
		{name="everness:forsaken_desert_cobble", prob=254, param2=0},
		{name="everness:forsaken_desert_brick", prob=254, param2=0},
		{name="air", prob=0, param2=0},
		{name="air", prob=0, param2=0},
		{name="everness:forsaken_desert_cobble", prob=254, param2=0},
		{name="everness:forsaken_desert_cobble", prob=254, param2=0},
		{name="stairs:slab_forsaken_desert_chiseled_stone", prob=254, param2=22},
		{name="stairs:slab_forsaken_desert_chiseled_stone", prob=254, param2=22},
		{name="stairs:slab_forsaken_desert_chiseled_stone", prob=254, param2=22},
		{name="stairs:slab_forsaken_desert_chiseled_stone", prob=254, param2=22},
		{name="stairs:slab_forsaken_desert_chiseled_stone", prob=254, param2=22},
		{name="everness:forsaken_desert_brick", prob=254, param2=0},
		{name="everness:forsaken_desert_brick", prob=254, param2=0},
		{name="air", prob=0, param2=0},
		{name="air", prob=0, param2=0},
		{name="everness:forsaken_desert_cobble", prob=254, param2=0},
		{name="everness:forsaken_desert_cobble", prob=254, param2=0},
		{name="air", prob=254, param2=0},
		{name="air", prob=254, param2=0},
		{name="air", prob=254, param2=0},
		{name="air", prob=254, param2=0},
		{name="air", prob=254, param2=0},
		{name="everness:forsaken_desert_brick", prob=254, param2=0},
		{name="everness:forsaken_desert_cobble", prob=254, param2=0},
		{name="air", prob=0, param2=0},
		{name="air", prob=0, param2=0},
		{name="everness:forsaken_desert_brick_red", prob=254, param2=0},
		{name="everness:forsaken_desert_cobble", prob=254, param2=0},
		{name="air", prob=254, param2=0},
		{name="air", prob=254, param2=0},
		{name="air", prob=254, param2=0},
		{name="air", prob=254, param2=0},
		{name="air", prob=254, param2=0},
		{name="everness:forsaken_desert_cobble", prob=254, param2=0},
		{name="everness:forsaken_desert_brick_red", prob=254, param2=0},
		{name="air", prob=0, param2=0},
		{name="stairs:stair_forsaken_desert_chiseled_stone", prob=254, param2=23},
		{name="everness:forsaken_desert_engraved_stone", prob=254, param2=0},
		{name="air", prob=254, param2=0},
		{name="air", prob=254, param2=0},
		{name="air", prob=254, param2=0},
		{name="air", prob=254, param2=0},
		{name="air", prob=254, param2=0},
		{name="air", prob=254, param2=0},
		{name="air", prob=254, param2=0},
		{name="everness:forsaken_desert_engraved_stone", prob=254, param2=0},
		{name="stairs:stair_forsaken_desert_chiseled_stone", prob=254, param2=21},
		{name="everness:forsaken_desert_cobble", prob=254, param2=0},
		{name="everness:forsaken_desert_cobble", prob=254, param2=0},
		{name="air", prob=254, param2=0},
		{name="air", prob=254, param2=0},
		{name="air", prob=254, param2=0},
		{name="air", prob=254, param2=0},
		{name="air", prob=254, param2=0},
		{name="air", prob=254, param2=0},
		{name="air", prob=254, param2=0},
		{name="everness:forsaken_desert_brick", prob=254, param2=0},
		{name="everness:forsaken_desert_brick", prob=254, param2=0},
		{name="air", prob=0, param2=0},
		{name="air", prob=0, param2=0},
		{name="everness:forsaken_desert_brick", prob=254, param2=0},
		{name="air", prob=254, param2=0},
		{name="air", prob=254, param2=0},
		{name="air", prob=254, param2=0},
		{name="air", prob=254, param2=0},
		{name="air", prob=254, param2=0},
		{name="everness:forsaken_desert_brick", prob=254, param2=0},
		{name="air", prob=0, param2=0},
		{name="air", prob=0, param2=0},
		{name="air", prob=0, param2=0},
		{name="air", prob=0, param2=0},
		{name="air", prob=0, param2=0},
		{name="everness:forsaken_desert_brick", prob=254, param2=0},
		{name="everness:forsaken_desert_cobble", prob=254, param2=0},
		{name="everness:forsaken_desert_brick", prob=254, param2=0},
		{name="everness:forsaken_desert_brick", prob=254, param2=0},
		{name="everness:forsaken_desert_cobble", prob=254, param2=0},
		{name="air", prob=0, param2=0},
		{name="air", prob=0, param2=0},
		{name="air", prob=0, param2=0},
		{name="air", prob=0, param2=0},
		{name="air", prob=0, param2=0},
		{name="air", prob=0, param2=0},
		{name="air", prob=0, param2=0},
		{name="air", prob=0, param2=0},
		{name="air", prob=0, param2=0},
		{name="air", prob=0, param2=0},
		{name="air", prob=0, param2=0},
		{name="air", prob=0, param2=0},
		{name="air", prob=0, param2=0},
		{name="air", prob=0, param2=0},
		{name="air", prob=0, param2=0},
		{name="air", prob=0, param2=0},
		{name="air", prob=0, param2=0},
		{name="air", prob=0, param2=0},
		{name="air", prob=0, param2=0},
		{name="air", prob=0, param2=0},
		{name="air", prob=0, param2=0},
		{name="air", prob=0, param2=0},
		{name="air", prob=0, param2=0},
		{name="air", prob=0, param2=0},
		{name="air", prob=0, param2=0},
		{name="everness:forsaken_desert_brick", prob=254, param2=0},
		{name="everness:forsaken_desert_cobble", prob=254, param2=0},
		{name="everness:forsaken_desert_brick", prob=254, param2=0},
		{name="everness:forsaken_desert_brick", prob=254, param2=0},
		{name="everness:forsaken_desert_brick", prob=254, param2=0},
		{name="everness:forsaken_desert_cobble", prob=254, param2=0},
		{name="everness:forsaken_desert_brick", prob=254, param2=0},
		{name="everness:forsaken_desert_cobble", prob=254, param2=0},
		{name="everness:forsaken_desert_cobble", prob=254, param2=0},
		{name="everness:forsaken_desert_brick", prob=254, param2=0},
		{name="everness:forsaken_desert_cobble", prob=254, param2=0},
		{name="everness:forsaken_desert_brick", prob=254, param2=0},
		{name="everness:forsaken_desert_cobble", prob=254, param2=0},
		{name="everness:forsaken_desert_brick", prob=254, param2=0},
		{name="everness:forsaken_desert_cobble", prob=254, param2=0},
		{name="everness:forsaken_desert_brick", prob=254, param2=0},
		{name="everness:forsaken_desert_cobble", prob=254, param2=0},
		{name="everness:forsaken_desert_cobble", prob=254, param2=0},
		{name="everness:forsaken_desert_brick", prob=254, param2=0},
		{name="everness:forsaken_desert_cobble", prob=254, param2=0},
		{name="everness:forsaken_desert_cobble", prob=254, param2=0},
		{name="everness:forsaken_desert_brick", prob=254, param2=0},
		{name="air", prob=0, param2=0},
		{name="air", prob=0, param2=0},
		{name="everness:forsaken_desert_engraved_stone", prob=254, param2=0},
		{name="air", prob=254, param2=0},
		{name="air", prob=254, param2=0},
		{name="air", prob=254, param2=0},
		{name="air", prob=254, param2=0},
		{name="air", prob=254, param2=0},
		{name="everness:forsaken_desert_engraved_stone", prob=254, param2=0},
		{name="air", prob=0, param2=0},
		{name="air", prob=0, param2=0},
		{name="air", prob=0, param2=0},
		{name="air", prob=0, param2=0},
		{name="everness:forsaken_desert_cobble", prob=254, param2=0},
		{name="stairs:slab_forsaken_desert_chiseled_stone", prob=254, param2=3},
		{name="air", prob=254, param2=0},
		{name="air", prob=254, param2=0},
		{name="air", prob=254, param2=0},
		{name="stairs:slab_forsaken_desert_chiseled_stone", prob=254, param2=1},
		{name="everness:forsaken_desert_cobble", prob=254, param2=0},
		{name="air", prob=0, param2=0},
		{name="air", prob=0, param2=0},
		{name="air", prob=0, param2=0},
		{name="air", prob=0, param2=0},
		{name="everness:forsaken_desert_brick", prob=254, param2=0},
		{name="air", prob=254, param2=0},
		{name="air", prob=254, param2=0},
		{name="air", prob=254, param2=0},
		{name="air", prob=254, param2=0},
		{name="air", prob=254, param2=0},
		{name="everness:forsaken_desert_brick", prob=254, param2=0},
		{name="air", prob=0, param2=0},
		{name="air", prob=0, param2=0},
		{name="air", prob=0, param2=0},
		{name="air", prob=0, param2=0},
		{name="everness:forsaken_desert_brick", prob=254, param2=0},
		{name="air", prob=254, param2=0},
		{name="air", prob=254, param2=0},
		{name="air", prob=254, param2=0},
		{name="air", prob=254, param2=0},
		{name="air", prob=254, param2=0},
		{name="everness:forsaken_desert_brick", prob=254, param2=0},
		{name="air", prob=0, param2=0},
		{name="air", prob=0, param2=0},
		{name="air", prob=0, param2=0},
		{name="air", prob=0, param2=0},
		{name="everness:forsaken_desert_brick", prob=254, param2=0},
		{name="air", prob=254, param2=0},
		{name="air", prob=254, param2=0},
		{name="air", prob=254, param2=0},
		{name="air", prob=254, param2=0},
		{name="air", prob=254, param2=0},
		{name="everness:forsaken_desert_brick", prob=254, param2=0},
		{name="air", prob=0, param2=0},
		{name="air", prob=0, param2=0},
		{name="air", prob=0, param2=0},
		{name="everness:forsaken_desert_engraved_stone", prob=254, param2=0},
		{name="air", prob=254, param2=0},
		{name="air", prob=254, param2=0},
		{name="air", prob=254, param2=0},
		{name="air", prob=254, param2=0},
		{name="air", prob=254, param2=0},
		{name="air", prob=254, param2=0},
		{name="air", prob=254, param2=0},
		{name="everness:forsaken_desert_engraved_stone", prob=254, param2=0},
		{name="air", prob=0, param2=0},
		{name="everness:forsaken_desert_brick", prob=254, param2=0},
		{name="everness:forsaken_desert_brick", prob=254, param2=0},
		{name="air", prob=254, param2=0},
		{name="air", prob=254, param2=0},
		{name="air", prob=254, param2=0},
		{name="air", prob=254, param2=0},
		{name="air", prob=254, param2=0},
		{name="air", prob=254, param2=0},
		{name="air", prob=254, param2=0},
		{name="everness:forsaken_desert_brick", prob=254, param2=0},
		{name="everness:forsaken_desert_cobble", prob=254, param2=0},
		{name="air", prob=0, param2=0},
		{name="air", prob=0, param2=0},
		{name="everness:forsaken_desert_brick", prob=254, param2=0},
		{name="air", prob=254, param2=0},
		{name="air", prob=254, param2=0},
		{name="air", prob=254, param2=0},
		{name="air", prob=254, param2=0},
		{name="air", prob=254, param2=0},
		{name="everness:forsaken_desert_cobble", prob=254, param2=0},
		{name="air", prob=0, param2=0},
		{name="air", prob=0, param2=0},
		{name="air", prob=0, param2=0},
		{name="air", prob=0, param2=0},
		{name="air", prob=0, param2=0},
		{name="everness:forsaken_desert_brick", prob=254, param2=0},
		{name="air", prob=254, param2=0},
		{name="air", prob=254, param2=0},
		{name="air", prob=254, param2=0},
		{name="everness:forsaken_desert_brick", prob=254, param2=0},
		{name="air", prob=0, param2=0},
		{name="air", prob=0, param2=0},
		{name="air", prob=0, param2=0},
		{name="air", prob=0, param2=0},
		{name="air", prob=0, param2=0},
		{name="air", prob=0, param2=0},
		{name="air", prob=0, param2=0},
		{name="everness:forsaken_desert_cobble", prob=254, param2=0},
		{name="everness:forsaken_desert_brick", prob=254, param2=0},
		{name="everness:forsaken_desert_brick", prob=254, param2=0},
		{name="air", prob=0, param2=0},
		{name="air", prob=0, param2=0},
		{name="air", prob=0, param2=0},
		{name="air", prob=0, param2=0},
		{name="air", prob=0, param2=0},
		{name="air", prob=0, param2=0},
		{name="air", prob=0, param2=0},
		{name="air", prob=0, param2=0},
		{name="air", prob=0, param2=0},
		{name="air", prob=0, param2=0},
		{name="air", prob=0, param2=0},
		{name="air", prob=0, param2=0},
		{name="air", prob=0, param2=0},
		{name="air", prob=0, param2=0},
		{name="air", prob=0, param2=0},
		{name="everness:forsaken_desert_brick", prob=254, param2=0},
		{name="everness:forsaken_desert_cobble", prob=254, param2=0},
		{name="everness:forsaken_desert_brick", prob=254, param2=0},
		{name="everness:forsaken_desert_cobble", prob=254, param2=0},
		{name="everness:forsaken_desert_brick", prob=254, param2=0},
		{name="everness:forsaken_desert_cobble", prob=254, param2=0},
		{name="everness:forsaken_desert_brick", prob=254, param2=0},
		{name="everness:forsaken_desert_brick", prob=254, param2=0},
		{name="everness:forsaken_desert_brick", prob=254, param2=0},
		{name="everness:forsaken_desert_brick", prob=254, param2=0},
		{name="everness:forsaken_desert_cobble", prob=254, param2=0},
		{name="everness:forsaken_desert_cobble", prob=254, param2=0},
		{name="everness:forsaken_desert_brick", prob=254, param2=0},
		{name="everness:forsaken_desert_cobble", prob=254, param2=0},
		{name="everness:forsaken_desert_brick", prob=254, param2=0},
		{name="everness:forsaken_desert_brick", prob=254, param2=0},
		{name="everness:forsaken_desert_brick", prob=254, param2=0},
		{name="everness:forsaken_desert_cobble", prob=254, param2=0},
		{name="everness:forsaken_desert_brick", prob=254, param2=0},
		{name="everness:forsaken_desert_brick", prob=254, param2=0},
		{name="everness:forsaken_desert_brick", prob=254, param2=0},
		{name="everness:forsaken_desert_cobble", prob=254, param2=0},
		{name="air", prob=0, param2=0},
		{name="air", prob=0, param2=0},
		{name="everness:forsaken_desert_engraved_stone", prob=254, param2=0},
		{name="air", prob=254, param2=0},
		{name="air", prob=254, param2=0},
		{name="air", prob=254, param2=0},
		{name="air", prob=254, param2=0},
		{name="air", prob=254, param2=0},
		{name="everness:forsaken_desert_engraved_stone", prob=254, param2=0},
		{name="air", prob=0, param2=0},
		{name="air", prob=0, param2=0},
		{name="air", prob=0, param2=0},
		{name="air", prob=0, param2=0},
		{name="everness:forsaken_desert_brick", prob=254, param2=0},
		{name="stairs:slab_forsaken_desert_chiseled_stone", prob=254, param2=3},
		{name="air", prob=254, param2=0},
		{name="air", prob=254, param2=0},
		{name="air", prob=254, param2=0},
		{name="stairs:slab_forsaken_desert_chiseled_stone", prob=254, param2=1},
		{name="everness:forsaken_desert_brick", prob=254, param2=0},
		{name="air", prob=0, param2=0},
		{name="air", prob=0, param2=0},
		{name="air", prob=0, param2=0},
		{name="air", prob=0, param2=0},
		{name="everness:forsaken_desert_brick", prob=254, param2=0},
		{name="air", prob=254, param2=0},
		{name="air", prob=254, param2=0},
		{name="air", prob=254, param2=0},
		{name="air", prob=254, param2=0},
		{name="air", prob=254, param2=0},
		{name="everness:forsaken_desert_cobble", prob=254, param2=0},
		{name="air", prob=0, param2=0},
		{name="air", prob=0, param2=0},
		{name="air", prob=0, param2=0},
		{name="air", prob=0, param2=0},
		{name="everness:forsaken_desert_cobble", prob=254, param2=0},
		{name="air", prob=254, param2=0},
		{name="air", prob=254, param2=0},
		{name="air", prob=254, param2=0},
		{name="air", prob=254, param2=0},
		{name="air", prob=254, param2=0},
		{name="everness:forsaken_desert_cobble", prob=254, param2=0},
		{name="air", prob=0, param2=0},
		{name="air", prob=0, param2=0},
		{name="air", prob=0, param2=0},
		{name="air", prob=0, param2=0},
		{name="everness:forsaken_desert_cobble", prob=254, param2=0},
		{name="air", prob=254, param2=0},
		{name="air", prob=254, param2=0},
		{name="air", prob=254, param2=0},
		{name="air", prob=254, param2=0},
		{name="air", prob=254, param2=0},
		{name="everness:forsaken_desert_brick", prob=254, param2=0},
		{name="air", prob=0, param2=0},
		{name="air", prob=0, param2=0},
		{name="stairs:stair_forsaken_desert_chiseled_stone", prob=254, param2=23},
		{name="everness:forsaken_desert_engraved_stone", prob=254, param2=0},
		{name="air", prob=254, param2=0},
		{name="air", prob=254, param2=0},
		{name="air", prob=254, param2=0},
		{name="air", prob=254, param2=0},
		{name="air", prob=254, param2=0},
		{name="air", prob=254, param2=0},
		{name="air", prob=254, param2=0},
		{name="everness:forsaken_desert_engraved_stone", prob=254, param2=0},
		{name="stairs:stair_forsaken_desert_chiseled_stone", prob=254, param2=21},
		{name="everness:forsaken_desert_brick", prob=254, param2=0},
		{name="everness:forsaken_desert_brick", prob=254, param2=0},
		{name="air", prob=254, param2=0},
		{name="air", prob=254, param2=0},
		{name="air", prob=254, param2=0},
		{name="air", prob=254, param2=0},
		{name="air", prob=254, param2=0},
		{name="air", prob=254, param2=0},
		{name="air", prob=254, param2=0},
		{name="everness:forsaken_desert_brick", prob=254, param2=0},
		{name="everness:forsaken_desert_cobble", prob=254, param2=0},
		{name="air", prob=0, param2=0},
		{name="air", prob=0, param2=0},
		{name="everness:forsaken_desert_brick", prob=254, param2=0},
		{name="air", prob=254, param2=0},
		{name="air", prob=254, param2=0},
		{name="air", prob=254, param2=0},
		{name="air", prob=254, param2=0},
		{name="air", prob=254, param2=0},
		{name="everness:forsaken_desert_cobble", prob=254, param2=0},
		{name="air", prob=0, param2=0},
		{name="air", prob=0, param2=0},
		{name="air", prob=0, param2=0},
		{name="air", prob=0, param2=0},
		{name="air", prob=0, param2=0},
		{name="everness:forsaken_desert_cobble", prob=254, param2=0},
		{name="air", prob=254, param2=0},
		{name="air", prob=254, param2=0},
		{name="air", prob=254, param2=0},
		{name="everness:forsaken_desert_cobble", prob=254, param2=0},
		{name="air", prob=0, param2=0},
		{name="air", prob=0, param2=0},
		{name="air", prob=0, param2=0},
		{name="air", prob=0, param2=0},
		{name="air", prob=0, param2=0},
		{name="air", prob=0, param2=0},
		{name="air", prob=0, param2=0},
		{name="everness:forsaken_desert_cobble", prob=254, param2=0},
		{name="everness:forsaken_desert_brick", prob=254, param2=0},
		{name="everness:forsaken_desert_cobble", prob=254, param2=0},
		{name="air", prob=0, param2=0},
		{name="air", prob=0, param2=0},
		{name="air", prob=0, param2=0},
		{name="air", prob=0, param2=0},
		{name="air", prob=0, param2=0},
		{name="air", prob=0, param2=0},
		{name="air", prob=0, param2=0},
		{name="air", prob=0, param2=0},
		{name="air", prob=0, param2=0},
		{name="everness:forsaken_desert_brick", prob=254, param2=0},
		{name="air", prob=0, param2=0},
		{name="air", prob=0, param2=0},
		{name="air", prob=0, param2=0},
		{name="air", prob=0, param2=0},
		{name="air", prob=0, param2=0},
		{name="everness:forsaken_desert_brick", prob=254, param2=0},
		{name="everness:forsaken_desert_cobble", prob=254, param2=0},
		{name="everness:forsaken_desert_cobble", prob=254, param2=0},
		{name="everness:forsaken_desert_brick", prob=254, param2=0},
		{name="everness:forsaken_desert_cobble", prob=254, param2=0},
		{name="everness:forsaken_desert_cobble", prob=254, param2=0},
		{name="everness:forsaken_desert_brick", prob=254, param2=0},
		{name="everness:forsaken_desert_cobble", prob=254, param2=0},
		{name="everness:forsaken_desert_brick", prob=254, param2=0},
		{name="everness:forsaken_desert_cobble", prob=254, param2=0},
		{name="everness:forsaken_desert_brick", prob=254, param2=0},
		{name="everness:forsaken_desert_brick", prob=254, param2=0},
		{name="everness:forsaken_desert_brick", prob=254, param2=0},
		{name="everness:forsaken_desert_brick", prob=254, param2=0},
		{name="everness:forsaken_desert_brick", prob=254, param2=0},
		{name="everness:forsaken_desert_cobble", prob=254, param2=0},
		{name="everness:forsaken_desert_cobble", prob=254, param2=0},
		{name="everness:forsaken_desert_brick", prob=254, param2=0},
		{name="everness:forsaken_desert_brick", prob=254, param2=0},
		{name="everness:forsaken_desert_brick", prob=254, param2=0},
		{name="everness:forsaken_desert_cobble", prob=254, param2=0},
		{name="everness:forsaken_desert_cobble", prob=254, param2=0},
		{name="air", prob=0, param2=0},
		{name="air", prob=0, param2=0},
		{name="everness:forsaken_desert_engraved_stone", prob=254, param2=0},
		{name="air", prob=254, param2=0},
		{name="air", prob=254, param2=0},
		{name="air", prob=254, param2=0},
		{name="air", prob=254, param2=0},
		{name="air", prob=254, param2=0},
		{name="everness:forsaken_desert_engraved_stone", prob=254, param2=0},
		{name="air", prob=0, param2=0},
		{name="air", prob=0, param2=0},
		{name="air", prob=0, param2=0},
		{name="air", prob=0, param2=0},
		{name="everness:forsaken_desert_cobble", prob=254, param2=0},
		{name="stairs:slab_forsaken_desert_chiseled_stone", prob=254, param2=3},
		{name="air", prob=254, param2=0},
		{name="air", prob=254, param2=0},
		{name="air", prob=254, param2=0},
		{name="stairs:slab_forsaken_desert_chiseled_stone", prob=254, param2=1},
		{name="everness:forsaken_desert_brick", prob=254, param2=0},
		{name="air", prob=0, param2=0},
		{name="air", prob=0, param2=0},
		{name="air", prob=0, param2=0},
		{name="air", prob=0, param2=0},
		{name="everness:forsaken_desert_brick", prob=254, param2=0},
		{name="air", prob=254, param2=0},
		{name="air", prob=254, param2=0},
		{name="air", prob=254, param2=0},
		{name="air", prob=254, param2=0},
		{name="air", prob=254, param2=0},
		{name="everness:forsaken_desert_brick", prob=254, param2=0},
		{name="air", prob=0, param2=0},
		{name="air", prob=0, param2=0},
		{name="air", prob=0, param2=0},
		{name="air", prob=0, param2=0},
		{name="everness:forsaken_desert_cobble", prob=254, param2=0},
		{name="air", prob=254, param2=0},
		{name="air", prob=254, param2=0},
		{name="air", prob=254, param2=0},
		{name="air", prob=254, param2=0},
		{name="air", prob=254, param2=0},
		{name="everness:forsaken_desert_brick", prob=254, param2=0},
		{name="air", prob=0, param2=0},
		{name="air", prob=0, param2=0},
		{name="air", prob=0, param2=0},
		{name="air", prob=0, param2=0},
		{name="everness:forsaken_desert_cobble", prob=254, param2=0},
		{name="air", prob=254, param2=0},
		{name="air", prob=254, param2=0},
		{name="air", prob=254, param2=0},
		{name="air", prob=254, param2=0},
		{name="air", prob=254, param2=0},
		{name="everness:forsaken_desert_cobble", prob=254, param2=0},
		{name="air", prob=0, param2=0},
		{name="air", prob=0, param2=0},
		{name="air", prob=0, param2=0},
		{name="everness:forsaken_desert_engraved_stone", prob=254, param2=0},
		{name="air", prob=254, param2=0},
		{name="air", prob=254, param2=0},
		{name="air", prob=254, param2=0},
		{name="air", prob=254, param2=0},
		{name="air", prob=254, param2=0},
		{name="air", prob=254, param2=0},
		{name="air", prob=254, param2=0},
		{name="everness:forsaken_desert_engraved_stone", prob=254, param2=0},
		{name="air", prob=0, param2=0},
		{name="everness:forsaken_desert_brick", prob=254, param2=0},
		{name="everness:forsaken_desert_brick", prob=254, param2=0},
		{name="air", prob=254, param2=0},
		{name="air", prob=254, param2=0},
		{name="air", prob=254, param2=0},
		{name="air", prob=254, param2=0},
		{name="air", prob=254, param2=0},
		{name="air", prob=254, param2=0},
		{name="air", prob=254, param2=0},
		{name="everness:forsaken_desert_cobble", prob=254, param2=0},
		{name="everness:forsaken_desert_brick", prob=254, param2=0},
		{name="air", prob=0, param2=0},
		{name="air", prob=0, param2=0},
		{name="everness:forsaken_desert_cobble", prob=254, param2=0},
		{name="air", prob=254, param2=0},
		{name="air", prob=254, param2=0},
		{name="air", prob=254, param2=0},
		{name="air", prob=254, param2=0},
		{name="air", prob=254, param2=0},
		{name="everness:forsaken_desert_cobble", prob=254, param2=0},
		{name="air", prob=0, param2=0},
		{name="air", prob=0, param2=0},
		{name="air", prob=0, param2=0},
		{name="air", prob=0, param2=0},
		{name="air", prob=0, param2=0},
		{name="everness:forsaken_desert_cobble", prob=254, param2=0},
		{name="air", prob=254, param2=0},
		{name="air", prob=254, param2=0},
		{name="air", prob=254, param2=0},
		{name="everness:forsaken_desert_cobble", prob=254, param2=0},
		{name="air", prob=0, param2=0},
		{name="air", prob=0, param2=0},
		{name="air", prob=0, param2=0},
		{name="air", prob=0, param2=0},
		{name="air", prob=0, param2=0},
		{name="air", prob=0, param2=0},
		{name="air", prob=0, param2=0},
		{name="everness:forsaken_desert_cobble", prob=254, param2=0},
		{name="everness:forsaken_desert_cobble", prob=254, param2=0},
		{name="everness:forsaken_desert_cobble", prob=254, param2=0},
		{name="air", prob=0, param2=0},
		{name="air", prob=0, param2=0},
		{name="air", prob=0, param2=0},
		{name="air", prob=0, param2=0},
		{name="air", prob=0, param2=0},
		{name="air", prob=0, param2=0},
		{name="air", prob=0, param2=0},
		{name="air", prob=0, param2=0},
		{name="air", prob=0, param2=0},
		{name="air", prob=0, param2=0},
		{name="air", prob=0, param2=0},
		{name="air", prob=0, param2=0},
		{name="air", prob=0, param2=0},
		{name="air", prob=0, param2=0},
		{name="air", prob=0, param2=0},
		{name="everness:forsaken_desert_cobble", prob=254, param2=0},
		{name="everness:forsaken_desert_brick", prob=254, param2=0},
		{name="everness:forsaken_desert_cobble", prob=254, param2=0},
		{name="everness:forsaken_desert_brick", prob=254, param2=0},
		{name="everness:forsaken_desert_brick", prob=254, param2=0},
		{name="everness:forsaken_desert_brick", prob=254, param2=0},
		{name="everness:forsaken_desert_brick", prob=254, param2=0},
		{name="everness:forsaken_desert_cobble", prob=254, param2=0},
		{name="everness:forsaken_desert_cobble", prob=254, param2=0},
		{name="everness:forsaken_desert_cobble", prob=254, param2=0},
		{name="everness:forsaken_desert_cobble", prob=254, param2=0},
		{name="everness:forsaken_desert_brick", prob=254, param2=0},
		{name="everness:forsaken_desert_brick", prob=254, param2=0},
		{name="everness:forsaken_desert_cobble", prob=254, param2=0},
		{name="everness:forsaken_desert_cobble", prob=254, param2=0},
		{name="everness:forsaken_desert_brick", prob=254, param2=0},
		{name="everness:forsaken_desert_cobble", prob=254, param2=0},
		{name="everness:forsaken_desert_cobble", prob=254, param2=0},
		{name="everness:forsaken_desert_brick", prob=254, param2=0},
		{name="everness:forsaken_desert_brick", prob=254, param2=0},
		{name="everness:forsaken_desert_brick", prob=254, param2=0},
		{name="everness:forsaken_desert_cobble", prob=254, param2=0},
		{name="air", prob=0, param2=0},
		{name="everness:forsaken_desert_brick_red", prob=254, param2=0},
		{name="everness:forsaken_desert_engraved_stone", prob=254, param2=0},
		{name="everness:chest", prob=126, param2=3},
		{name="air", prob=254, param2=0},
		{name="air", prob=254, param2=0},
		{name="air", prob=254, param2=0},
		{name="everness:chest", prob=126, param2=1},
		{name="everness:forsaken_desert_engraved_stone", prob=254, param2=0},
		{name="everness:forsaken_desert_brick_red", prob=254, param2=0},
		{name="air", prob=0, param2=0},
		{name="air", prob=0, param2=0},
		{name="everness:forsaken_desert_cobble", prob=254, param2=0},
		{name="everness:forsaken_desert_cobble", prob=254, param2=0},
		{name="stairs:slab_forsaken_desert_chiseled_stone", prob=254, param2=3},
		{name="air", prob=254, param2=0},
		{name="air", prob=254, param2=0},
		{name="air", prob=254, param2=0},
		{name="stairs:slab_forsaken_desert_chiseled_stone", prob=254, param2=1},
		{name="everness:forsaken_desert_brick", prob=254, param2=0},
		{name="everness:forsaken_desert_brick", prob=254, param2=0},
		{name="air", prob=0, param2=0},
		{name="air", prob=0, param2=0},
		{name="everness:forsaken_desert_cobble", prob=254, param2=0},
		{name="everness:forsaken_desert_cobble", prob=254, param2=0},
		{name="air", prob=254, param2=0},
		{name="air", prob=254, param2=0},
		{name="air", prob=254, param2=0},
		{name="air", prob=254, param2=0},
		{name="air", prob=254, param2=0},
		{name="everness:forsaken_desert_cobble", prob=254, param2=0},
		{name="everness:forsaken_desert_cobble", prob=254, param2=0},
		{name="air", prob=0, param2=0},
		{name="air", prob=0, param2=0},
		{name="everness:forsaken_desert_cobble", prob=254, param2=0},
		{name="everness:forsaken_desert_brick", prob=254, param2=0},
		{name="air", prob=254, param2=0},
		{name="air", prob=254, param2=0},
		{name="air", prob=254, param2=0},
		{name="air", prob=254, param2=0},
		{name="air", prob=254, param2=0},
		{name="everness:forsaken_desert_cobble", prob=254, param2=0},
		{name="everness:forsaken_desert_brick", prob=254, param2=0},
		{name="air", prob=0, param2=0},
		{name="air", prob=0, param2=0},
		{name="everness:forsaken_desert_brick_red", prob=254, param2=0},
		{name="everness:forsaken_desert_brick", prob=254, param2=0},
		{name="air", prob=254, param2=0},
		{name="air", prob=254, param2=0},
		{name="air", prob=254, param2=0},
		{name="air", prob=254, param2=0},
		{name="air", prob=254, param2=0},
		{name="everness:forsaken_desert_brick", prob=254, param2=0},
		{name="everness:forsaken_desert_brick_red", prob=254, param2=0},
		{name="air", prob=0, param2=0},
		{name="stairs:stair_forsaken_desert_chiseled_stone", prob=254, param2=23},
		{name="everness:forsaken_desert_engraved_stone", prob=254, param2=0},
		{name="air", prob=254, param2=0},
		{name="air", prob=254, param2=0},
		{name="air", prob=254, param2=0},
		{name="air", prob=254, param2=0},
		{name="air", prob=254, param2=0},
		{name="air", prob=254, param2=0},
		{name="air", prob=254, param2=0},
		{name="everness:forsaken_desert_engraved_stone", prob=254, param2=0},
		{name="stairs:stair_forsaken_desert_chiseled_stone", prob=254, param2=21},
		{name="everness:forsaken_desert_cobble", prob=254, param2=0},
		{name="everness:forsaken_desert_cobble", prob=254, param2=0},
		{name="air", prob=254, param2=0},
		{name="air", prob=254, param2=0},
		{name="air", prob=254, param2=0},
		{name="air", prob=254, param2=0},
		{name="air", prob=254, param2=0},
		{name="air", prob=254, param2=0},
		{name="air", prob=254, param2=0},
		{name="everness:forsaken_desert_brick", prob=254, param2=0},
		{name="everness:forsaken_desert_brick", prob=254, param2=0},
		{name="air", prob=0, param2=0},
		{name="air", prob=0, param2=0},
		{name="everness:forsaken_desert_brick", prob=254, param2=0},
		{name="air", prob=254, param2=0},
		{name="air", prob=254, param2=0},
		{name="air", prob=254, param2=0},
		{name="air", prob=254, param2=0},
		{name="air", prob=254, param2=0},
		{name="everness:forsaken_desert_cobble", prob=254, param2=0},
		{name="air", prob=0, param2=0},
		{name="air", prob=0, param2=0},
		{name="air", prob=0, param2=0},
		{name="air", prob=0, param2=0},
		{name="air", prob=0, param2=0},
		{name="everness:forsaken_desert_cobble", prob=254, param2=0},
		{name="everness:forsaken_desert_brick", prob=254, param2=0},
		{name="everness:forsaken_desert_brick", prob=254, param2=0},
		{name="everness:forsaken_desert_cobble", prob=254, param2=0},
		{name="everness:forsaken_desert_cobble", prob=254, param2=0},
		{name="air", prob=0, param2=0},
		{name="air", prob=0, param2=0},
		{name="air", prob=0, param2=0},
		{name="air", prob=0, param2=0},
		{name="air", prob=0, param2=0},
		{name="air", prob=0, param2=0},
		{name="air", prob=0, param2=0},
		{name="air", prob=0, param2=0},
		{name="air", prob=0, param2=0},
		{name="air", prob=0, param2=0},
		{name="air", prob=0, param2=0},
		{name="air", prob=0, param2=0},
		{name="air", prob=0, param2=0},
		{name="air", prob=0, param2=0},
		{name="air", prob=0, param2=0},
		{name="air", prob=0, param2=0},
		{name="air", prob=0, param2=0},
		{name="air", prob=0, param2=0},
		{name="air", prob=0, param2=0},
		{name="air", prob=0, param2=0},
		{name="air", prob=0, param2=0},
		{name="air", prob=0, param2=0},
		{name="air", prob=0, param2=0},
		{name="air", prob=0, param2=0},
		{name="air", prob=0, param2=0},
		{name="everness:forsaken_desert_cobble", prob=254, param2=0},
		{name="everness:forsaken_desert_cobble", prob=254, param2=0},
		{name="everness:forsaken_desert_cobble", prob=254, param2=0},
		{name="everness:forsaken_desert_cobble", prob=254, param2=0},
		{name="everness:forsaken_desert_cobble", prob=254, param2=0},
		{name="everness:forsaken_desert_brick", prob=254, param2=0},
		{name="everness:forsaken_desert_brick", prob=254, param2=0},
		{name="everness:forsaken_desert_brick", prob=254, param2=0},
		{name="everness:forsaken_desert_brick", prob=254, param2=0},
		{name="everness:forsaken_desert_brick", prob=254, param2=0},
		{name="everness:forsaken_desert_cobble", prob=254, param2=0},
		{name="everness:forsaken_desert_cobble", prob=254, param2=0},
		{name="everness:forsaken_desert_cobble", prob=254, param2=0},
		{name="everness:forsaken_desert_cobble", prob=254, param2=0},
		{name="everness:forsaken_desert_brick", prob=254, param2=0},
		{name="everness:forsaken_desert_brick", prob=254, param2=0},
		{name="everness:forsaken_desert_cobble", prob=254, param2=0},
		{name="everness:forsaken_desert_brick", prob=254, param2=0},
		{name="everness:forsaken_desert_cobble", prob=254, param2=0},
		{name="everness:forsaken_desert_cobble", prob=254, param2=0},
		{name="everness:forsaken_desert_cobble", prob=254, param2=0},
		{name="everness:forsaken_desert_cobble", prob=254, param2=0},
		{name="air", prob=0, param2=0},
		{name="air", prob=0, param2=0},
		{name="everness:forsaken_desert_engraved_stone", prob=254, param2=0},
		{name="everness:forsaken_desert_engraved_stone", prob=254, param2=0},
		{name="everness:forsaken_desert_engraved_stone", prob=254, param2=0},
		{name="air", prob=254, param2=0},
		{name="everness:forsaken_desert_engraved_stone", prob=254, param2=0},
		{name="everness:forsaken_desert_engraved_stone", prob=254, param2=0},
		{name="everness:forsaken_desert_engraved_stone", prob=254, param2=0},
		{name="air", prob=0, param2=0},
		{name="air", prob=0, param2=0},
		{name="air", prob=0, param2=0},
		{name="air", prob=0, param2=0},
		{name="everness:forsaken_desert_cobble", prob=254, param2=0},
		{name="everness:forsaken_desert_cobble", prob=254, param2=0},
		{name="everness:forsaken_desert_cobble", prob=254, param2=0},
		{name="air", prob=254, param2=0},
		{name="everness:forsaken_desert_brick", prob=254, param2=0},
		{name="everness:forsaken_desert_cobble", prob=254, param2=0},
		{name="everness:forsaken_desert_cobble", prob=254, param2=0},
		{name="air", prob=0, param2=0},
		{name="air", prob=0, param2=0},
		{name="air", prob=0, param2=0},
		{name="air", prob=0, param2=0},
		{name="everness:forsaken_desert_cobble", prob=254, param2=0},
		{name="everness:forsaken_desert_brick", prob=254, param2=0},
		{name="everness:forsaken_desert_brick", prob=254, param2=0},
		{name="everness:forsaken_desert_brick", prob=254, param2=0},
		{name="everness:forsaken_desert_cobble", prob=254, param2=0},
		{name="everness:forsaken_desert_cobble", prob=254, param2=0},
		{name="everness:forsaken_desert_cobble", prob=254, param2=0},
		{name="air", prob=0, param2=0},
		{name="air", prob=0, param2=0},
		{name="air", prob=0, param2=0},
		{name="air", prob=0, param2=0},
		{name="everness:forsaken_desert_cobble", prob=254, param2=0},
		{name="everness:forsaken_desert_brick", prob=254, param2=0},
		{name="everness:forsaken_desert_engraved_stone", prob=254, param2=0},
		{name="everness:forsaken_desert_engraved_stone", prob=254, param2=0},
		{name="everness:forsaken_desert_engraved_stone", prob=254, param2=0},
		{name="everness:forsaken_desert_brick", prob=254, param2=0},
		{name="everness:forsaken_desert_brick", prob=254, param2=0},
		{name="air", prob=0, param2=0},
		{name="air", prob=0, param2=0},
		{name="air", prob=0, param2=0},
		{name="air", prob=0, param2=0},
		{name="everness:forsaken_desert_cobble", prob=254, param2=0},
		{name="everness:forsaken_desert_brick", prob=254, param2=0},
		{name="everness:forsaken_desert_brick", prob=254, param2=0},
		{name="everness:forsaken_desert_cobble", prob=254, param2=0},
		{name="everness:forsaken_desert_cobble", prob=254, param2=0},
		{name="everness:forsaken_desert_brick", prob=254, param2=0},
		{name="everness:forsaken_desert_brick", prob=254, param2=0},
		{name="air", prob=0, param2=0},
		{name="air", prob=0, param2=0},
		{name="air", prob=0, param2=0},
		{name="everness:forsaken_desert_engraved_stone", prob=254, param2=0},
		{name="everness:mineral_torch", prob=126, param2=1},
		{name="air", prob=254, param2=0},
		{name="air", prob=254, param2=0},
		{name="air", prob=254, param2=0},
		{name="air", prob=254, param2=0},
		{name="air", prob=254, param2=0},
		{name="everness:mineral_torch", prob=126, param2=1},
		{name="everness:forsaken_desert_engraved_stone", prob=254, param2=0},
		{name="air", prob=0, param2=0},
		{name="everness:forsaken_desert_brick", prob=254, param2=0},
		{name="everness:forsaken_desert_brick", prob=254, param2=0},
		{name="air", prob=254, param2=0},
		{name="air", prob=254, param2=0},
		{name="air", prob=254, param2=0},
		{name="air", prob=254, param2=0},
		{name="air", prob=254, param2=0},
		{name="air", prob=254, param2=0},
		{name="air", prob=254, param2=0},
		{name="everness:forsaken_desert_cobble", prob=254, param2=0},
		{name="everness:forsaken_desert_cobble", prob=254, param2=0},
		{name="air", prob=0, param2=0},
		{name="air", prob=0, param2=0},
		{name="everness:forsaken_desert_brick", prob=254, param2=0},
		{name="everness:forsaken_desert_cobble", prob=254, param2=0},
		{name="everness:forsaken_desert_brick", prob=254, param2=0},
		{name="everness:forsaken_desert_brick", prob=254, param2=0},
		{name="everness:forsaken_desert_brick", prob=254, param2=0},
		{name="everness:forsaken_desert_cobble", prob=254, param2=0},
		{name="everness:forsaken_desert_cobble", prob=254, param2=0},
		{name="air", prob=0, param2=0},
		{name="air", prob=0, param2=0},
		{name="air", prob=0, param2=0},
		{name="air", prob=0, param2=0},
		{name="air", prob=0, param2=0},
		{name="air", prob=0, param2=0},
		{name="air", prob=0, param2=0},
		{name="air", prob=0, param2=0},
		{name="air", prob=0, param2=0},
		{name="air", prob=0, param2=0},
		{name="air", prob=0, param2=0},
		{name="air", prob=0, param2=0},
		{name="air", prob=0, param2=0},
		{name="air", prob=0, param2=0},
		{name="air", prob=0, param2=0},
		{name="air", prob=0, param2=0},
		{name="air", prob=0, param2=0},
		{name="air", prob=0, param2=0},
		{name="air", prob=0, param2=0},
		{name="air", prob=0, param2=0},
		{name="air", prob=0, param2=0},
		{name="air", prob=0, param2=0},
		{name="air", prob=0, param2=0},
		{name="air", prob=0, param2=0},
		{name="air", prob=0, param2=0},
		{name="air", prob=0, param2=0},
		{name="air", prob=0, param2=0},
		{name="air", prob=0, param2=0},
		{name="air", prob=0, param2=0},
		{name="air", prob=0, param2=0},
		{name="air", prob=0, param2=0},
		{name="air", prob=0, param2=0},
		{name="air", prob=0, param2=0},
		{name="air", prob=0, param2=0},
		{name="air", prob=0, param2=0},
		{name="everness:forsaken_desert_cobble", prob=254, param2=0},
		{name="everness:forsaken_desert_cobble", prob=254, param2=0},
		{name="everness:forsaken_desert_cobble", prob=254, param2=0},
		{name="everness:forsaken_desert_cobble", prob=254, param2=0},
		{name="everness:forsaken_desert_cobble", prob=254, param2=0},
		{name="everness:forsaken_desert_brick", prob=254, param2=0},
		{name="everness:forsaken_desert_cobble", prob=254, param2=0},
		{name="everness:forsaken_desert_brick", prob=254, param2=0},
		{name="everness:forsaken_desert_cobble", prob=254, param2=0},
		{name="everness:forsaken_desert_cobble", prob=254, param2=0},
		{name="everness:forsaken_desert_brick", prob=254, param2=0},
		{name="everness:forsaken_desert_cobble", prob=254, param2=0},
		{name="everness:forsaken_desert_brick", prob=254, param2=0},
		{name="everness:forsaken_desert_cobble", prob=254, param2=0},
		{name="everness:forsaken_desert_brick", prob=254, param2=0},
		{name="everness:forsaken_desert_brick", prob=254, param2=0},
		{name="everness:forsaken_desert_brick", prob=254, param2=0},
		{name="everness:forsaken_desert_brick", prob=254, param2=0},
		{name="everness:forsaken_desert_brick", prob=254, param2=0},
		{name="everness:forsaken_desert_brick", prob=254, param2=0},
		{name="everness:forsaken_desert_cobble", prob=254, param2=0},
		{name="everness:forsaken_desert_brick", prob=254, param2=0},
		{name="air", prob=0, param2=0},
		{name="everness:forsaken_desert_brick_red", prob=254, param2=0},
		{name="air", prob=0, param2=0},
		{name="everness:forsaken_desert_brick_red", prob=254, param2=0},
		{name="air", prob=0, param2=0},
		{name="air", prob=254, param2=0},
		{name="air", prob=0, param2=0},
		{name="everness:forsaken_desert_brick_red", prob=254, param2=0},
		{name="air", prob=0, param2=0},
		{name="everness:forsaken_desert_brick_red", prob=254, param2=0},
		{name="air", prob=0, param2=0},
		{name="air", prob=0, param2=0},
		{name="everness:forsaken_desert_cobble", prob=254, param2=0},
		{name="air", prob=0, param2=0},
		{name="everness:forsaken_desert_brick", prob=254, param2=0},
		{name="air", prob=0, param2=0},
		{name="air", prob=254, param2=0},
		{name="air", prob=0, param2=0},
		{name="everness:forsaken_desert_cobble", prob=254, param2=0},
		{name="air", prob=0, param2=0},
		{name="everness:forsaken_desert_brick", prob=254, param2=0},
		{name="air", prob=0, param2=0},
		{name="air", prob=0, param2=0},
		{name="everness:forsaken_desert_brick", prob=254, param2=0},
		{name="air", prob=0, param2=0},
		{name="everness:forsaken_desert_cobble", prob=254, param2=0},
		{name="air", prob=0, param2=0},
		{name="air", prob=0, param2=0},
		{name="air", prob=0, param2=0},
		{name="everness:forsaken_desert_brick", prob=254, param2=0},
		{name="air", prob=0, param2=0},
		{name="everness:forsaken_desert_cobble", prob=254, param2=0},
		{name="air", prob=0, param2=0},
		{name="air", prob=0, param2=0},
		{name="everness:forsaken_desert_brick", prob=254, param2=0},
		{name="air", prob=0, param2=0},
		{name="everness:forsaken_desert_cobble", prob=254, param2=0},
		{name="air", prob=0, param2=0},
		{name="air", prob=0, param2=0},
		{name="air", prob=0, param2=0},
		{name="everness:forsaken_desert_brick", prob=254, param2=0},
		{name="air", prob=0, param2=0},
		{name="everness:forsaken_desert_cobble", prob=254, param2=0},
		{name="air", prob=0, param2=0},
		{name="air", prob=0, param2=0},
		{name="everness:forsaken_desert_brick_red", prob=254, param2=0},
		{name="air", prob=0, param2=0},
		{name="everness:forsaken_desert_brick_red", prob=254, param2=0},
		{name="air", prob=0, param2=0},
		{name="air", prob=0, param2=0},
		{name="air", prob=0, param2=0},
		{name="everness:forsaken_desert_brick_red", prob=254, param2=0},
		{name="air", prob=0, param2=0},
		{name="everness:forsaken_desert_brick_red", prob=254, param2=0},
		{name="air", prob=0, param2=0},
		{name="stairs:stair_forsaken_desert_chiseled_stone", prob=254, param2=23},
		{name="everness:forsaken_desert_engraved_stone", prob=254, param2=0},
		{name="everness:forsaken_desert_engraved_stone", prob=254, param2=0},
		{name="everness:forsaken_desert_engraved_stone", prob=254, param2=0},
		{name="everness:forsaken_desert_engraved_stone", prob=254, param2=0},
		{name="everness:forsaken_desert_engraved_stone", prob=254, param2=0},
		{name="everness:forsaken_desert_engraved_stone", prob=254, param2=0},
		{name="everness:forsaken_desert_engraved_stone", prob=254, param2=0},
		{name="everness:forsaken_desert_engraved_stone", prob=254, param2=0},
		{name="everness:forsaken_desert_engraved_stone", prob=254, param2=0},
		{name="stairs:stair_forsaken_desert_chiseled_stone", prob=254, param2=21},
		{name="everness:forsaken_desert_cobble", prob=254, param2=0},
		{name="everness:forsaken_desert_cobble", prob=254, param2=0},
		{name="everness:forsaken_desert_cobble", prob=254, param2=0},
		{name="everness:forsaken_desert_cobble", prob=254, param2=0},
		{name="everness:forsaken_desert_brick", prob=254, param2=0},
		{name="everness:forsaken_desert_brick", prob=254, param2=0},
		{name="everness:forsaken_desert_brick", prob=254, param2=0},
		{name="everness:forsaken_desert_cobble", prob=254, param2=0},
		{name="everness:forsaken_desert_cobble", prob=254, param2=0},
		{name="everness:forsaken_desert_brick", prob=254, param2=0},
		{name="everness:forsaken_desert_brick", prob=254, param2=0},
		{name="air", prob=0, param2=0},
		{name="air", prob=0, param2=0},
		{name="air", prob=0, param2=0},
		{name="air", prob=0, param2=0},
		{name="air", prob=0, param2=0},
		{name="air", prob=0, param2=0},
		{name="air", prob=0, param2=0},
		{name="air", prob=0, param2=0},
		{name="air", prob=0, param2=0},
		{name="air", prob=0, param2=0},
		{name="air", prob=0, param2=0},
		{name="air", prob=0, param2=0},
		{name="air", prob=0, param2=0},
		{name="air", prob=0, param2=0},
		{name="air", prob=0, param2=0},
		{name="air", prob=0, param2=0},
		{name="air", prob=0, param2=0},
		{name="air", prob=0, param2=0},
		{name="air", prob=0, param2=0},
		{name="air", prob=0, param2=0},
		{name="air", prob=0, param2=0},
		{name="air", prob=0, param2=0},
		{name="air", prob=0, param2=0},
		{name="air", prob=0, param2=0},
		{name="air", prob=0, param2=0},
		{name="air", prob=0, param2=0},
		{name="air", prob=0, param2=0},
		{name="air", prob=0, param2=0},
		{name="air", prob=0, param2=0},
		{name="air", prob=0, param2=0},
		{name="air", prob=0, param2=0},
		{name="air", prob=0, param2=0},
		{name="air", prob=0, param2=0},
		{name="air", prob=0, param2=0},
		{name="air", prob=0, param2=0},
		{name="air", prob=0, param2=0},
		{name="air", prob=0, param2=0},
		{name="air", prob=0, param2=0},
		{name="air", prob=0, param2=0},
		{name="air", prob=0, param2=0},
		{name="air", prob=0, param2=0},
		{name="air", prob=0, param2=0},
		{name="air", prob=0, param2=0},
		{name="air", prob=0, param2=0},
		{name="everness:forsaken_desert_cobble", prob=254, param2=0},
		{name="everness:forsaken_desert_brick", prob=254, param2=0},
		{name="everness:forsaken_desert_cobble", prob=254, param2=0},
		{name="everness:forsaken_desert_cobble", prob=254, param2=0},
		{name="everness:forsaken_desert_cobble", prob=254, param2=0},
		{name="everness:forsaken_desert_cobble", prob=254, param2=0},
		{name="everness:forsaken_desert_cobble", prob=254, param2=0},
		{name="everness:forsaken_desert_brick", prob=254, param2=0},
		{name="everness:forsaken_desert_brick", prob=254, param2=0},
		{name="everness:forsaken_desert_brick", prob=254, param2=0},
		{name="everness:forsaken_desert_cobble", prob=254, param2=0},
		{name="everness:forsaken_desert_cobble", prob=254, param2=0},
		{name="everness:forsaken_desert_brick", prob=254, param2=0},
		{name="everness:forsaken_desert_brick", prob=254, param2=0},
		{name="everness:forsaken_desert_brick", prob=254, param2=0},
		{name="everness:forsaken_desert_brick", prob=254, param2=0},
		{name="everness:forsaken_desert_cobble", prob=254, param2=0},
		{name="everness:forsaken_desert_brick", prob=254, param2=0},
		{name="everness:forsaken_desert_cobble", prob=254, param2=0},
		{name="everness:forsaken_desert_cobble", prob=254, param2=0},
		{name="everness:forsaken_desert_cobble", prob=254, param2=0},
		{name="everness:forsaken_desert_brick", prob=254, param2=0},
		{name="air", prob=0, param2=0},
		{name="air", prob=0, param2=0},
		{name="air", prob=0, param2=0},
		{name="air", prob=0, param2=0},
		{name="air", prob=0, param2=0},
		{name="air", prob=254, param2=0},
		{name="air", prob=0, param2=0},
		{name="air", prob=0, param2=0},
		{name="air", prob=0, param2=0},
		{name="air", prob=0, param2=0},
		{name="air", prob=0, param2=0},
		{name="air", prob=0, param2=0},
		{name="air", prob=0, param2=0},
		{name="air", prob=0, param2=0},
		{name="air", prob=0, param2=0},
		{name="air", prob=0, param2=0},
		{name="air", prob=254, param2=0},
		{name="air", prob=0, param2=0},
		{name="air", prob=0, param2=0},
		{name="air", prob=0, param2=0},
		{name="air", prob=0, param2=0},
		{name="air", prob=0, param2=0},
		{name="air", prob=0, param2=0},
		{name="air", prob=0, param2=0},
		{name="air", prob=0, param2=0},
		{name="air", prob=0, param2=0},
		{name="air", prob=0, param2=0},
		{name="air", prob=0, param2=0},
		{name="air", prob=0, param2=0},
		{name="air", prob=0, param2=0},
		{name="air", prob=0, param2=0},
		{name="air", prob=0, param2=0},
		{name="air", prob=0, param2=0},
		{name="air", prob=0, param2=0},
		{name="air", prob=0, param2=0},
		{name="air", prob=0, param2=0},
		{name="air", prob=0, param2=0},
		{name="air", prob=0, param2=0},
		{name="air", prob=0, param2=0},
		{name="air", prob=0, param2=0},
		{name="air", prob=0, param2=0},
		{name="air", prob=0, param2=0},
		{name="air", prob=0, param2=0},
		{name="air", prob=0, param2=0},
		{name="air", prob=0, param2=0},
		{name="air", prob=0, param2=0},
		{name="air", prob=0, param2=0},
		{name="air", prob=0, param2=0},
		{name="air", prob=0, param2=0},
		{name="air", prob=0, param2=0},
		{name="air", prob=0, param2=0},
		{name="air", prob=0, param2=0},
		{name="air", prob=0, param2=0},
		{name="air", prob=0, param2=0},
		{name="air", prob=0, param2=0},
		{name="air", prob=0, param2=0},
		{name="stairs:stair_forsaken_desert_chiseled_stone", prob=254, param2=22},
		{name="air", prob=0, param2=0},
		{name="stairs:stair_forsaken_desert_chiseled_stone", prob=254, param2=22},
		{name="air", prob=0, param2=0},
		{name="stairs:stair_forsaken_desert_chiseled_stone", prob=254, param2=22},
		{name="air", prob=0, param2=0},
		{name="stairs:stair_forsaken_desert_chiseled_stone", prob=254, param2=22},
		{name="air", prob=0, param2=0},
		{name="stairs:stair_forsaken_desert_chiseled_stone", prob=254, param2=22},
		{name="air", prob=0, param2=0},
		{name="everness:forsaken_desert_brick", prob=254, param2=0},
		{name="everness:forsaken_desert_brick", prob=254, param2=0},
		{name="everness:forsaken_desert_cobble", prob=254, param2=0},
		{name="everness:forsaken_desert_cobble", prob=254, param2=0},
		{name="everness:forsaken_desert_brick", prob=254, param2=0},
		{name="everness:forsaken_desert_brick", prob=254, param2=0},
		{name="everness:forsaken_desert_cobble", prob=254, param2=0},
		{name="everness:forsaken_desert_cobble", prob=254, param2=0},
		{name="everness:forsaken_desert_brick", prob=254, param2=0},
		{name="everness:forsaken_desert_cobble", prob=254, param2=0},
		{name="everness:forsaken_desert_cobble", prob=254, param2=0},
		{name="air", prob=0, param2=0},
		{name="air", prob=0, param2=0},
		{name="air", prob=0, param2=0},
		{name="air", prob=0, param2=0},
		{name="air", prob=0, param2=0},
		{name="air", prob=0, param2=0},
		{name="air", prob=0, param2=0},
		{name="air", prob=0, param2=0},
		{name="air", prob=0, param2=0},
		{name="air", prob=0, param2=0},
		{name="air", prob=0, param2=0},
		{name="air", prob=0, param2=0},
		{name="air", prob=0, param2=0},
		{name="air", prob=0, param2=0},
		{name="air", prob=0, param2=0},
		{name="air", prob=0, param2=0},
		{name="air", prob=0, param2=0},
		{name="air", prob=0, param2=0},
		{name="air", prob=0, param2=0},
		{name="air", prob=0, param2=0},
		{name="air", prob=0, param2=0},
		{name="air", prob=0, param2=0},
		{name="air", prob=0, param2=0},
		{name="air", prob=0, param2=0},
		{name="air", prob=0, param2=0},
		{name="air", prob=0, param2=0},
		{name="air", prob=0, param2=0},
		{name="air", prob=0, param2=0},
		{name="air", prob=0, param2=0},
		{name="air", prob=0, param2=0},
		{name="air", prob=0, param2=0},
		{name="air", prob=0, param2=0},
		{name="air", prob=0, param2=0},
		{name="air", prob=0, param2=0},
		{name="air", prob=0, param2=0},
		{name="air", prob=0, param2=0},
		{name="air", prob=0, param2=0},
		{name="air", prob=0, param2=0},
		{name="air", prob=0, param2=0},
		{name="air", prob=0, param2=0},
		{name="air", prob=0, param2=0},
		{name="air", prob=0, param2=0},
		{name="air", prob=0, param2=0},
		{name="air", prob=0, param2=0},
		{name="air", prob=0, param2=0},
		{name="air", prob=0, param2=0},
		{name="air", prob=0, param2=0},
		{name="air", prob=0, param2=0},
		{name="everness:forsaken_desert_cobble", prob=254, param2=0},
		{name="everness:forsaken_desert_cobble", prob=254, param2=0},
		{name="everness:forsaken_desert_cobble", prob=254, param2=0},
		{name="air", prob=0, param2=0},
		{name="air", prob=0, param2=0},
		{name="air", prob=0, param2=0},
		{name="air", prob=0, param2=0},
		{name="air", prob=0, param2=0},
		{name="air", prob=0, param2=0},
		{name="air", prob=0, param2=0},
		{name="air", prob=0, param2=0},
		{name="stairs:stair_forsaken_desert_cobble", prob=254, param2=2},
		{name="stairs:stair_forsaken_desert_cobble", prob=254, param2=2},
		{name="stairs:stair_forsaken_desert_cobble", prob=254, param2=2},
		{name="air", prob=0, param2=0},
		{name="air", prob=0, param2=0},
		{name="air", prob=0, param2=0},
		{name="air", prob=0, param2=0},
		{name="air", prob=0, param2=0},
		{name="air", prob=0, param2=0},
		{name="air", prob=0, param2=0},
		{name="air", prob=0, param2=0},
		{name="air", prob=0, param2=0},
		{name="air", prob=254, param2=0},
		{name="air", prob=0, param2=0},
		{name="air", prob=0, param2=0},
		{name="air", prob=0, param2=0},
		{name="air", prob=0, param2=0},
		{name="air", prob=0, param2=0},
		{name="air", prob=0, param2=0},
		{name="air", prob=0, param2=0},
		{name="air", prob=0, param2=0},
		{name="air", prob=0, param2=0},
		{name="air", prob=0, param2=0},
		{name="air", prob=254, param2=0},
		{name="air", prob=0, param2=0},
		{name="air", prob=0, param2=0},
		{name="air", prob=0, param2=0},
		{name="air", prob=0, param2=0},
		{name="air", prob=0, param2=0},
		{name="air", prob=0, param2=0},
		{name="air", prob=0, param2=0},
		{name="air", prob=0, param2=0},
		{name="air", prob=0, param2=0},
		{name="air", prob=0, param2=0},
		{name="air", prob=0, param2=0},
		{name="air", prob=0, param2=0},
		{name="air", prob=0, param2=0},
		{name="air", prob=0, param2=0},
		{name="air", prob=0, param2=0},
		{name="air", prob=0, param2=0},
		{name="air", prob=0, param2=0},
		{name="air", prob=0, param2=0},
		{name="air", prob=0, param2=0},
		{name="air", prob=0, param2=0},
		{name="air", prob=0, param2=0},
		{name="air", prob=0, param2=0},
		{name="air", prob=0, param2=0},
		{name="air", prob=0, param2=0},
		{name="air", prob=0, param2=0},
		{name="air", prob=0, param2=0},
		{name="air", prob=0, param2=0},
		{name="air", prob=0, param2=0},
		{name="air", prob=0, param2=0},
		{name="air", prob=0, param2=0},
		{name="air", prob=0, param2=0},
		{name="air", prob=0, param2=0},
		{name="air", prob=0, param2=0},
		{name="air", prob=0, param2=0},
		{name="air", prob=0, param2=0},
		{name="air", prob=0, param2=0},
		{name="air", prob=0, param2=0},
		{name="air", prob=0, param2=0},
		{name="air", prob=0, param2=0},
		{name="air", prob=0, param2=0},
		{name="air", prob=0, param2=0},
		{name="air", prob=0, param2=0},
		{name="air", prob=0, param2=0},
		{name="air", prob=0, param2=0},
		{name="air", prob=0, param2=0},
		{name="air", prob=0, param2=0},
		{name="air", prob=0, param2=0},
		{name="air", prob=0, param2=0},
		{name="air", prob=0, param2=0},
		{name="air", prob=0, param2=0},
		{name="air", prob=0, param2=0},
		{name="air", prob=0, param2=0},
		{name="air", prob=0, param2=0},
		{name="air", prob=0, param2=0},
		{name="air", prob=0, param2=0},
		{name="air", prob=0, param2=0},
		{name="air", prob=0, param2=0},
		{name="air", prob=0, param2=0},
		{name="air", prob=0, param2=0},
		{name="air", prob=0, param2=0},
		{name="air", prob=0, param2=0},
		{name="air", prob=0, param2=0},
		{name="air", prob=0, param2=0},
		{name="air", prob=0, param2=0},
		{name="air", prob=0, param2=0},
		{name="air", prob=0, param2=0},
		{name="air", prob=0, param2=0},
		{name="air", prob=0, param2=0},
		{name="air", prob=0, param2=0},
		{name="air", prob=0, param2=0},
		{name="air", prob=0, param2=0},
		{name="air", prob=0, param2=0},
		{name="air", prob=0, param2=0},
		{name="air", prob=0, param2=0},
		{name="air", prob=0, param2=0},
		{name="air", prob=0, param2=0},
		{name="air", prob=0, param2=0},
		{name="air", prob=0, param2=0},
		{name="air", prob=0, param2=0},
		{name="air", prob=0, param2=0},
		{name="air", prob=0, param2=0},
		{name="air", prob=0, param2=0},
		{name="air", prob=0, param2=0},
		{name="air", prob=0, param2=0},
		{name="air", prob=0, param2=0},
		{name="air", prob=0, param2=0},
		{name="air", prob=0, param2=0},
		{name="air", prob=0, param2=0},
		{name="air", prob=0, param2=0},
		{name="air", prob=0, param2=0},
		{name="air", prob=0, param2=0},
		{name="air", prob=0, param2=0},
		{name="air", prob=0, param2=0},
		{name="air", prob=0, param2=0},
		{name="air", prob=0, param2=0},
		{name="air", prob=0, param2=0},
		{name="air", prob=0, param2=0},
		{name="air", prob=0, param2=0},
		{name="air", prob=0, param2=0},
		{name="air", prob=0, param2=0},
		{name="air", prob=0, param2=0},
		{name="air", prob=0, param2=0},
		{name="air", prob=0, param2=0},
		{name="air", prob=0, param2=0},
		{name="air", prob=0, param2=0},
		{name="air", prob=0, param2=0},
		{name="air", prob=0, param2=0},
		{name="air", prob=0, param2=0},
		{name="stairs:stair_forsaken_desert_cobble", prob=254, param2=2},
		{name="stairs:stair_forsaken_desert_cobble", prob=254, param2=2},
		{name="stairs:stair_forsaken_desert_cobble", prob=254, param2=2},
		{name="air", prob=0, param2=0},
		{name="air", prob=0, param2=0},
		{name="air", prob=0, param2=0},
		{name="air", prob=0, param2=0},
		{name="air", prob=0, param2=0},
		{name="air", prob=0, param2=0},
		{name="air", prob=0, param2=0},
		{name="air", prob=0, param2=0},
		{name="air", prob=0, param2=0},
		{name="air", prob=0, param2=0},
		{name="air", prob=0, param2=0},
		{name="air", prob=0, param2=0},
		{name="air", prob=0, param2=0},
		{name="air", prob=0, param2=0},
		{name="air", prob=0, param2=0},
		{name="air", prob=0, param2=0},
		{name="air", prob=0, param2=0},
		{name="air", prob=0, param2=0},
		{name="air", prob=0, param2=0},
		{name="air", prob=0, param2=0},
		{name="air", prob=254, param2=0},
		{name="air", prob=0, param2=0},
		{name="air", prob=0, param2=0},
		{name="air", prob=0, param2=0},
		{name="air", prob=0, param2=0},
		{name="air", prob=0, param2=0},
		{name="air", prob=0, param2=0},
		{name="air", prob=0, param2=0},
		{name="air", prob=0, param2=0},
		{name="air", prob=0, param2=0},
		{name="air", prob=0, param2=0},
		{name="air", prob=254, param2=0},
		{name="air", prob=0, param2=0},
		{name="air", prob=0, param2=0},
		{name="air", prob=0, param2=0},
		{name="air", prob=0, param2=0},
		{name="air", prob=0, param2=0},
		{name="air", prob=0, param2=0},
		{name="air", prob=0, param2=0},
		{name="air", prob=0, param2=0},
		{name="air", prob=0, param2=0},
		{name="air", prob=0, param2=0},
		{name="air", prob=0, param2=0},
		{name="air", prob=0, param2=0},
		{name="air", prob=0, param2=0},
		{name="air", prob=0, param2=0},
		{name="air", prob=0, param2=0},
		{name="air", prob=0, param2=0},
		{name="air", prob=0, param2=0},
		{name="air", prob=0, param2=0},
		{name="air", prob=0, param2=0},
		{name="air", prob=0, param2=0},
		{name="air", prob=0, param2=0},
		{name="air", prob=0, param2=0},
		{name="air", prob=0, param2=0},
		{name="air", prob=0, param2=0},
		{name="air", prob=0, param2=0},
		{name="air", prob=0, param2=0},
		{name="air", prob=0, param2=0},
		{name="air", prob=0, param2=0},
		{name="air", prob=0, param2=0},
		{name="air", prob=0, param2=0},
		{name="air", prob=0, param2=0},
		{name="air", prob=0, param2=0},
		{name="air", prob=0, param2=0},
		{name="air", prob=0, param2=0},
		{name="air", prob=0, param2=0},
		{name="air", prob=0, param2=0},
		{name="air", prob=0, param2=0},
		{name="air", prob=0, param2=0},
		{name="air", prob=0, param2=0},
		{name="air", prob=0, param2=0},
		{name="air", prob=0, param2=0},
		{name="air", prob=0, param2=0},
		{name="air", prob=0, param2=0},
		{name="air", prob=0, param2=0},
		{name="air", prob=0, param2=0},
		{name="air", prob=0, param2=0},
		{name="air", prob=0, param2=0},
		{name="air", prob=0, param2=0},
		{name="air", prob=0, param2=0},
		{name="air", prob=0, param2=0},
		{name="air", prob=0, param2=0},
		{name="air", prob=0, param2=0},
		{name="air", prob=0, param2=0},
		{name="air", prob=0, param2=0},
		{name="air", prob=0, param2=0},
		{name="air", prob=0, param2=0},
		{name="air", prob=0, param2=0},
		{name="air", prob=0, param2=0},
		{name="air", prob=0, param2=0},
		{name="air", prob=0, param2=0},
		{name="air", prob=0, param2=0},
		{name="air", prob=0, param2=0},
		{name="air", prob=0, param2=0},
		{name="air", prob=0, param2=0},
		{name="air", prob=0, param2=0},
		{name="air", prob=0, param2=0},
		{name="air", prob=0, param2=0},
		{name="air", prob=0, param2=0},
		{name="air", prob=0, param2=0},
		{name="air", prob=0, param2=0},
		{name="air", prob=0, param2=0},
		{name="air", prob=0, param2=0},
		{name="air", prob=0, param2=0},
		{name="air", prob=0, param2=0},
		{name="air", prob=0, param2=0},
		{name="air", prob=0, param2=0},
		{name="air", prob=0, param2=0},
		{name="air", prob=0, param2=0},
		{name="air", prob=0, param2=0},
		{name="air", prob=0, param2=0},
		{name="air", prob=0, param2=0},
		{name="air", prob=0, param2=0},
		{name="air", prob=0, param2=0},
		{name="air", prob=0, param2=0},
		{name="air", prob=0, param2=0},
		{name="air", prob=0, param2=0},
		{name="air", prob=0, param2=0},
		{name="air", prob=0, param2=0},
		{name="air", prob=0, param2=0},
		{name="air", prob=0, param2=0},
		{name="air", prob=0, param2=0},
		{name="air", prob=0, param2=0},
		{name="air", prob=0, param2=0},
		{name="air", prob=0, param2=0},
		{name="air", prob=0, param2=0},
		{name="air", prob=0, param2=0},
		{name="air", prob=0, param2=0},
		{name="air", prob=0, param2=0},
		{name="air", prob=0, param2=0},
		{name="air", prob=0, param2=0},
		{name="air", prob=0, param2=0},
		{name="air", prob=0, param2=0},
		{name="air", prob=0, param2=0},
		{name="air", prob=0, param2=0},
	},
}
