schematic = {
	size = {x=7, y=7, z=7},
	yslice_prob = {
		{ypos=0, prob=254},
		{ypos=1, prob=254},
		{ypos=2, prob=254},
		{ypos=3, prob=254},
		{ypos=4, prob=254},
		{ypos=5, prob=254},
		{ypos=6, prob=254},
	},
	data = {
		{name="everness:volcanic_sulfur", prob=126, param2=0, force_place=true},
		{name="everness:volcanic_sulfur", prob=126, param2=0, force_place=true},
		{name="everness:volcanic_sulfur", prob=126, param2=0, force_place=true},
		{name="everness:volcanic_sulfur", prob=126, param2=0, force_place=true},
		{name="everness:volcanic_sulfur", prob=126, param2=0, force_place=true},
		{name="everness:volcanic_sulfur", prob=126, param2=0, force_place=true},
		{name="everness:volcanic_sulfur", prob=126, param2=0, force_place=true},
		{name="air", prob=254, param2=0},
		{name="air", prob=254, param2=0},
		{name="air", prob=254, param2=0},
		{name="air", prob=254, param2=0},
		{name="air", prob=254, param2=0},
		{name="air", prob=254, param2=0},
		{name="air", prob=254, param2=0},
		{name="air", prob=254, param2=0},
		{name="air", prob=254, param2=0},
		{name="air", prob=254, param2=0},
		{name="air", prob=254, param2=0},
		{name="air", prob=254, param2=0},
		{name="air", prob=254, param2=0},
		{name="air", prob=254, param2=0},
		{name="air", prob=254, param2=0},
		{name="air", prob=254, param2=0},
		{name="air", prob=254, param2=0},
		{name="air", prob=254, param2=0},
		{name="air", prob=254, param2=0},
		{name="air", prob=254, param2=0},
		{name="air", prob=254, param2=0},
		{name="air", prob=254, param2=0},
		{name="air", prob=254, param2=0},
		{name="air", prob=254, param2=0},
		{name="air", prob=254, param2=0},
		{name="air", prob=254, param2=0},
		{name="air", prob=254, param2=0},
		{name="air", prob=254, param2=0},
		{name="air", prob=254, param2=0},
		{name="air", prob=254, param2=0},
		{name="air", prob=254, param2=0},
		{name="air", prob=254, param2=0},
		{name="air", prob=254, param2=0},
		{name="air", prob=254, param2=0},
		{name="air", prob=254, param2=0},
		{name="air", prob=254, param2=0},
		{name="air", prob=254, param2=0},
		{name="air", prob=254, param2=0},
		{name="air", prob=254, param2=0},
		{name="air", prob=254, param2=0},
		{name="air", prob=254, param2=0},
		{name="air", prob=254, param2=0},
		{name="everness:volcanic_sulfur", prob=126, param2=0, force_place=true},
		{name="everness:volcanic_sulfur", prob=126, param2=0, force_place=true},
		{name="everness:volcanic_sulfur", prob=126, param2=0, force_place=true},
		{name="everness:volcanic_sulfur", prob=126, param2=0, force_place=true},
		{name="everness:volcanic_sulfur", prob=126, param2=0, force_place=true},
		{name="everness:volcanic_sulfur", prob=126, param2=0, force_place=true},
		{name="everness:volcanic_sulfur", prob=126, param2=0, force_place=true},
		{name="air", prob=254, param2=0},
		{name="air", prob=254, param2=0},
		{name="everness:volcanic_sulfur", prob=254, param2=0, force_place=true},
		{name="everness:volcanic_sulfur", prob=254, param2=0, force_place=true},
		{name="air", prob=254, param2=0},
		{name="air", prob=254, param2=0},
		{name="air", prob=254, param2=0},
		{name="air", prob=254, param2=0},
		{name="air", prob=254, param2=0},
		{name="everness:volcanic_sulfur", prob=254, param2=0},
		{name="everness:volcanic_sulfur", prob=254, param2=0},
		{name="air", prob=254, param2=0},
		{name="air", prob=254, param2=0},
		{name="air", prob=254, param2=0},
		{name="air", prob=254, param2=0},
		{name="air", prob=254, param2=0},
		{name="everness:volcanic_sulfur", prob=126, param2=0},
		{name="everness:volcanic_sulfur", prob=126, param2=0},
		{name="air", prob=254, param2=0},
		{name="air", prob=254, param2=0},
		{name="air", prob=254, param2=0},
		{name="air", prob=254, param2=0},
		{name="air", prob=254, param2=0},
		{name="air", prob=254, param2=0},
		{name="air", prob=254, param2=0},
		{name="air", prob=254, param2=0},
		{name="air", prob=254, param2=0},
		{name="air", prob=254, param2=0},
		{name="air", prob=254, param2=0},
		{name="air", prob=254, param2=0},
		{name="air", prob=254, param2=0},
		{name="air", prob=254, param2=0},
		{name="air", prob=254, param2=0},
		{name="air", prob=254, param2=0},
		{name="air", prob=254, param2=0},
		{name="air", prob=254, param2=0},
		{name="air", prob=254, param2=0},
		{name="air", prob=254, param2=0},
		{name="air", prob=254, param2=0},
		{name="air", prob=254, param2=0},
		{name="air", prob=254, param2=0},
		{name="air", prob=254, param2=0},
		{name="everness:volcanic_sulfur", prob=126, param2=0, force_place=true},
		{name="everness:volcanic_sulfur", prob=126, param2=0, force_place=true},
		{name="everness:volcanic_sulfur", prob=126, param2=0, force_place=true},
		{name="everness:volcanic_sulfur", prob=126, param2=0, force_place=true},
		{name="everness:volcanic_sulfur", prob=126, param2=0, force_place=true},
		{name="everness:volcanic_sulfur", prob=126, param2=0, force_place=true},
		{name="everness:volcanic_sulfur", prob=126, param2=0, force_place=true},
		{name="air", prob=254, param2=0},
		{name="everness:volcanic_sulfur", prob=254, param2=0, force_place=true},
		{name="everness:volcanic_sulfur", prob=254, param2=0, force_place=true},
		{name="everness:volcanic_sulfur", prob=254, param2=0, force_place=true},
		{name="everness:volcanic_sulfur", prob=254, param2=0, force_place=true},
		{name="everness:volcanic_sulfur", prob=254, param2=0, force_place=true},
		{name="air", prob=254, param2=0},
		{name="air", prob=254, param2=0},
		{name="everness:volcanic_sulfur", prob=254, param2=0},
		{name="everness:volcanic_sulfur", prob=254, param2=0},
		{name="everness:volcanic_sulfur", prob=254, param2=0},
		{name="everness:volcanic_sulfur", prob=254, param2=0},
		{name="everness:volcanic_sulfur", prob=126, param2=0},
		{name="air", prob=254, param2=0},
		{name="air", prob=254, param2=0},
		{name="everness:volcanic_sulfur", prob=126, param2=0},
		{name="everness:volcanic_sulfur", prob=254, param2=0},
		{name="everness:volcanic_sulfur", prob=254, param2=0},
		{name="everness:volcanic_sulfur", prob=126, param2=0},
		{name="air", prob=254, param2=0},
		{name="air", prob=254, param2=0},
		{name="air", prob=254, param2=0},
		{name="air", prob=254, param2=0},
		{name="everness:volcanic_sulfur", prob=126, param2=0},
		{name="everness:volcanic_sulfur", prob=254, param2=0},
		{name="air", prob=254, param2=0},
		{name="air", prob=254, param2=0},
		{name="air", prob=254, param2=0},
		{name="air", prob=254, param2=0},
		{name="air", prob=254, param2=0},
		{name="air", prob=254, param2=0},
		{name="everness:volcanic_sulfur", prob=254, param2=0},
		{name="air", prob=254, param2=0},
		{name="air", prob=254, param2=0},
		{name="air", prob=254, param2=0},
		{name="air", prob=254, param2=0},
		{name="air", prob=254, param2=0},
		{name="air", prob=254, param2=0},
		{name="everness:volcanic_sulfur", prob=254, param2=0},
		{name="air", prob=254, param2=0},
		{name="air", prob=254, param2=0},
		{name="air", prob=254, param2=0},
		{name="everness:volcanic_sulfur", prob=126, param2=0, force_place=true},
		{name="everness:volcanic_sulfur", prob=126, param2=0, force_place=true},
		{name="everness:volcanic_sulfur", prob=126, param2=0, force_place=true},
		{name="everness:volcanic_sulfur", prob=126, param2=0, force_place=true},
		{name="everness:volcanic_sulfur", prob=126, param2=0, force_place=true},
		{name="everness:volcanic_sulfur", prob=126, param2=0, force_place=true},
		{name="everness:volcanic_sulfur", prob=126, param2=0, force_place=true},
		{name="air", prob=254, param2=0},
		{name="everness:volcanic_sulfur", prob=254, param2=0, force_place=true},
		{name="everness:volcanic_sulfur", prob=254, param2=0, force_place=true},
		{name="everness:volcanic_sulfur", prob=254, param2=0, force_place=true},
		{name="everness:volcanic_sulfur", prob=254, param2=0, force_place=true},
		{name="everness:volcanic_sulfur", prob=254, param2=0, force_place=true},
		{name="air", prob=254, param2=0},
		{name="air", prob=254, param2=0},
		{name="everness:volcanic_sulfur", prob=254, param2=0},
		{name="everness:volcanic_sulfur", prob=254, param2=0},
		{name="everness:volcanic_sulfur", prob=254, param2=0},
		{name="everness:volcanic_sulfur", prob=254, param2=0},
		{name="everness:volcanic_sulfur", prob=254, param2=0},
		{name="air", prob=254, param2=0},
		{name="air", prob=254, param2=0},
		{name="everness:volcanic_sulfur", prob=126, param2=0},
		{name="everness:volcanic_sulfur", prob=254, param2=0},
		{name="everness:volcanic_sulfur", prob=254, param2=0},
		{name="everness:volcanic_sulfur", prob=254, param2=0},
		{name="everness:volcanic_sulfur", prob=126, param2=0},
		{name="air", prob=254, param2=0},
		{name="air", prob=254, param2=0},
		{name="air", prob=254, param2=0},
		{name="everness:volcanic_sulfur", prob=254, param2=0},
		{name="everness:volcanic_sulfur", prob=254, param2=0},
		{name="everness:volcanic_sulfur", prob=254, param2=0},
		{name="air", prob=254, param2=0},
		{name="air", prob=254, param2=0},
		{name="air", prob=254, param2=0},
		{name="air", prob=254, param2=0},
		{name="everness:volcanic_sulfur", prob=254, param2=0},
		{name="everness:sulfur_stone", prob=254, param2=0},
		{name="everness:volcanic_sulfur", prob=254, param2=0},
		{name="air", prob=254, param2=0},
		{name="air", prob=254, param2=0},
		{name="air", prob=254, param2=0},
		{name="air", prob=254, param2=0},
		{name="everness:volcanic_sulfur", prob=254, param2=0},
		{name="air", prob=254, param2=0},
		{name="everness:volcanic_sulfur", prob=254, param2=0},
		{name="air", prob=254, param2=0},
		{name="air", prob=254, param2=0},
		{name="everness:volcanic_sulfur", prob=126, param2=0, force_place=true},
		{name="everness:volcanic_sulfur", prob=126, param2=0, force_place=true},
		{name="everness:volcanic_sulfur", prob=126, param2=0, force_place=true},
		{name="everness:volcanic_sulfur", prob=126, param2=0, force_place=true},
		{name="everness:volcanic_sulfur", prob=126, param2=0, force_place=true},
		{name="everness:volcanic_sulfur", prob=126, param2=0, force_place=true},
		{name="everness:volcanic_sulfur", prob=126, param2=0, force_place=true},
		{name="air", prob=254, param2=0},
		{name="everness:volcanic_sulfur", prob=254, param2=0, force_place=true},
		{name="everness:volcanic_sulfur", prob=254, param2=0, force_place=true},
		{name="everness:volcanic_sulfur", prob=254, param2=0, force_place=true},
		{name="everness:volcanic_sulfur", prob=254, param2=0, force_place=true},
		{name="everness:volcanic_sulfur", prob=254, param2=0, force_place=true},
		{name="air", prob=254, param2=0},
		{name="air", prob=254, param2=0},
		{name="everness:volcanic_sulfur", prob=126, param2=0},
		{name="everness:volcanic_sulfur", prob=254, param2=0},
		{name="everness:volcanic_sulfur", prob=254, param2=0},
		{name="everness:volcanic_sulfur", prob=254, param2=0},
		{name="everness:volcanic_sulfur", prob=254, param2=0},
		{name="air", prob=254, param2=0},
		{name="air", prob=254, param2=0},
		{name="air", prob=254, param2=0},
		{name="everness:volcanic_sulfur", prob=126, param2=0},
		{name="everness:volcanic_sulfur", prob=254, param2=0},
		{name="everness:volcanic_sulfur", prob=254, param2=0},
		{name="everness:volcanic_sulfur", prob=126, param2=0},
		{name="air", prob=254, param2=0},
		{name="air", prob=254, param2=0},
		{name="air", prob=254, param2=0},
		{name="air", prob=254, param2=0},
		{name="everness:volcanic_sulfur", prob=254, param2=0},
		{name="everness:volcanic_sulfur", prob=126, param2=0},
		{name="air", prob=254, param2=0},
		{name="air", prob=254, param2=0},
		{name="air", prob=254, param2=0},
		{name="air", prob=254, param2=0},
		{name="air", prob=254, param2=0},
		{name="everness:volcanic_sulfur", prob=254, param2=0},
		{name="air", prob=254, param2=0},
		{name="air", prob=254, param2=0},
		{name="air", prob=254, param2=0},
		{name="air", prob=254, param2=0},
		{name="air", prob=254, param2=0},
		{name="air", prob=254, param2=0},
		{name="everness:volcanic_sulfur", prob=254, param2=0},
		{name="air", prob=254, param2=0},
		{name="air", prob=254, param2=0},
		{name="air", prob=254, param2=0},
		{name="everness:volcanic_sulfur", prob=126, param2=0, force_place=true},
		{name="everness:volcanic_sulfur", prob=126, param2=0, force_place=true},
		{name="everness:volcanic_sulfur", prob=126, param2=0, force_place=true},
		{name="everness:volcanic_sulfur", prob=126, param2=0, force_place=true},
		{name="everness:volcanic_sulfur", prob=126, param2=0, force_place=true},
		{name="everness:volcanic_sulfur", prob=126, param2=0, force_place=true},
		{name="everness:volcanic_sulfur", prob=126, param2=0, force_place=true},
		{name="air", prob=254, param2=0},
		{name="air", prob=254, param2=0},
		{name="air", prob=254, param2=0},
		{name="everness:volcanic_sulfur", prob=254, param2=0, force_place=true},
		{name="everness:volcanic_sulfur", prob=254, param2=0, force_place=true},
		{name="air", prob=254, param2=0},
		{name="air", prob=254, param2=0},
		{name="air", prob=254, param2=0},
		{name="air", prob=254, param2=0},
		{name="air", prob=254, param2=0},
		{name="everness:volcanic_sulfur", prob=254, param2=0},
		{name="everness:volcanic_sulfur", prob=254, param2=0},
		{name="air", prob=254, param2=0},
		{name="air", prob=254, param2=0},
		{name="air", prob=254, param2=0},
		{name="air", prob=254, param2=0},
		{name="air", prob=254, param2=0},
		{name="everness:volcanic_sulfur", prob=126, param2=0},
		{name="everness:volcanic_sulfur", prob=254, param2=0},
		{name="air", prob=254, param2=0},
		{name="air", prob=254, param2=0},
		{name="air", prob=254, param2=0},
		{name="air", prob=254, param2=0},
		{name="air", prob=254, param2=0},
		{name="air", prob=254, param2=0},
		{name="air", prob=254, param2=0},
		{name="air", prob=254, param2=0},
		{name="air", prob=254, param2=0},
		{name="air", prob=254, param2=0},
		{name="air", prob=254, param2=0},
		{name="air", prob=254, param2=0},
		{name="air", prob=254, param2=0},
		{name="air", prob=254, param2=0},
		{name="air", prob=254, param2=0},
		{name="air", prob=254, param2=0},
		{name="air", prob=254, param2=0},
		{name="air", prob=254, param2=0},
		{name="air", prob=254, param2=0},
		{name="air", prob=254, param2=0},
		{name="air", prob=254, param2=0},
		{name="air", prob=254, param2=0},
		{name="air", prob=254, param2=0},
		{name="everness:volcanic_sulfur", prob=126, param2=0, force_place=true},
		{name="everness:volcanic_sulfur", prob=126, param2=0, force_place=true},
		{name="everness:volcanic_sulfur", prob=126, param2=0, force_place=true},
		{name="everness:volcanic_sulfur", prob=126, param2=0, force_place=true},
		{name="everness:volcanic_sulfur", prob=126, param2=0, force_place=true},
		{name="everness:volcanic_sulfur", prob=126, param2=0, force_place=true},
		{name="everness:volcanic_sulfur", prob=126, param2=0, force_place=true},
		{name="air", prob=254, param2=0},
		{name="air", prob=254, param2=0},
		{name="air", prob=254, param2=0},
		{name="air", prob=254, param2=0},
		{name="air", prob=254, param2=0},
		{name="air", prob=254, param2=0},
		{name="air", prob=254, param2=0},
		{name="air", prob=254, param2=0},
		{name="air", prob=254, param2=0},
		{name="air", prob=254, param2=0},
		{name="air", prob=254, param2=0},
		{name="air", prob=254, param2=0},
		{name="air", prob=254, param2=0},
		{name="air", prob=254, param2=0},
		{name="air", prob=254, param2=0},
		{name="air", prob=254, param2=0},
		{name="air", prob=254, param2=0},
		{name="air", prob=254, param2=0},
		{name="air", prob=254, param2=0},
		{name="air", prob=254, param2=0},
		{name="air", prob=254, param2=0},
		{name="air", prob=254, param2=0},
		{name="air", prob=254, param2=0},
		{name="air", prob=254, param2=0},
		{name="air", prob=254, param2=0},
		{name="air", prob=254, param2=0},
		{name="air", prob=254, param2=0},
		{name="air", prob=254, param2=0},
		{name="air", prob=254, param2=0},
		{name="air", prob=254, param2=0},
		{name="air", prob=254, param2=0},
		{name="air", prob=254, param2=0},
		{name="air", prob=254, param2=0},
		{name="air", prob=254, param2=0},
		{name="air", prob=254, param2=0},
		{name="air", prob=254, param2=0},
		{name="air", prob=254, param2=0},
		{name="air", prob=254, param2=0},
		{name="air", prob=254, param2=0},
		{name="air", prob=254, param2=0},
		{name="air", prob=254, param2=0},
		{name="air", prob=254, param2=0},
	},
}
