schematic = {
	size = {x=2, y=19, z=2},
	yslice_prob = {
		{ypos=0, prob=254},
		{ypos=1, prob=254},
		{ypos=2, prob=254},
		{ypos=3, prob=254},
		{ypos=4, prob=254},
		{ypos=5, prob=254},
		{ypos=6, prob=254},
		{ypos=7, prob=254},
		{ypos=8, prob=254},
		{ypos=9, prob=254},
		{ypos=10, prob=254},
		{ypos=11, prob=254},
		{ypos=12, prob=254},
		{ypos=13, prob=254},
		{ypos=14, prob=254},
		{ypos=15, prob=254},
		{ypos=16, prob=254},
		{ypos=17, prob=254},
		{ypos=18, prob=254},
	},
	data = {
		{name="air", prob=254, param2=0},
		{name="air", prob=254, param2=0},
		{name="air", prob=254, param2=0},
		{name="air", prob=254, param2=0},
		{name="air", prob=254, param2=0},
		{name="air", prob=254, param2=0},
		{name="air", prob=254, param2=0},
		{name="air", prob=254, param2=0},
		{name="air", prob=254, param2=0},
		{name="air", prob=254, param2=0},
		{name="air", prob=254, param2=0},
		{name="air", prob=254, param2=0},
		{name="air", prob=254, param2=0},
		{name="everness:frosted_cave_ice_illuminating", prob=254, param2=0},
		{name="air", prob=254, param2=0},
		{name="everness:frosted_cave_ice_illuminating", prob=254, param2=0},
		{name="air", prob=254, param2=0},
		{name="everness:frosted_cave_ice_illuminating", prob=254, param2=0},
		{name="everness:frosted_cave_ice_illuminating", prob=254, param2=0},
		{name="everness:frosted_cave_ice_illuminating", prob=254, param2=0},
		{name="everness:frosted_cave_ice_illuminating", prob=254, param2=0},
		{name="air", prob=254, param2=0},
		{name="everness:frosted_cave_ice_illuminating", prob=254, param2=0},
		{name="air", prob=254, param2=0},
		{name="air", prob=254, param2=0},
		{name="air", prob=254, param2=0},
		{name="air", prob=254, param2=0},
		{name="air", prob=254, param2=0},
		{name="air", prob=254, param2=0},
		{name="everness:frosted_cave_ice_illuminating", prob=254, param2=0},
		{name="air", prob=254, param2=0},
		{name="everness:frosted_cave_ice_illuminating", prob=254, param2=0},
		{name="everness:frosted_cave_ice_illuminating", prob=254, param2=0},
		{name="everness:frosted_cave_ice_illuminating", prob=254, param2=0},
		{name="air", prob=254, param2=0},
		{name="air", prob=254, param2=0},
		{name="air", prob=254, param2=0},
		{name="air", prob=254, param2=0},
		{name="everness:frosted_icicle_large_ceiling_marker", prob=254, param2=2},
		{name="air", prob=254, param2=0},
		{name="everness:frosted_cave_ice_illuminating", prob=254, param2=0},
		{name="air", prob=254, param2=0},
		{name="everness:frosted_cave_ice_illuminating", prob=254, param2=0},
		{name="air", prob=254, param2=0},
		{name="everness:frosted_cave_ice_illuminating", prob=254, param2=0},
		{name="everness:frosted_cave_ice_illuminating", prob=254, param2=0},
		{name="air", prob=254, param2=0},
		{name="everness:frosted_cave_ice_illuminating", prob=254, param2=0},
		{name="air", prob=254, param2=0},
		{name="everness:frosted_cave_ice_illuminating", prob=254, param2=0},
		{name="air", prob=254, param2=0},
		{name="everness:frosted_cave_ice_illuminating", prob=254, param2=0},
		{name="air", prob=254, param2=0},
		{name="air", prob=254, param2=0},
		{name="air", prob=254, param2=0},
		{name="air", prob=254, param2=0},
		{name="air", prob=254, param2=0},
		{name="air", prob=254, param2=0},
		{name="air", prob=254, param2=0},
		{name="air", prob=254, param2=0},
		{name="everness:frosted_cave_ice_illuminating", prob=254, param2=0},
		{name="everness:frosted_cave_ice_illuminating", prob=254, param2=0},
		{name="air", prob=254, param2=0},
		{name="everness:frosted_cave_ice_illuminating", prob=254, param2=0},
		{name="air", prob=254, param2=0},
		{name="everness:frosted_cave_ice_illuminating", prob=254, param2=0},
		{name="air", prob=254, param2=0},
		{name="everness:frosted_cave_ice_illuminating", prob=254, param2=0},
		{name="air", prob=254, param2=0},
		{name="air", prob=254, param2=0},
		{name="everness:frosted_cave_ice_illuminating", prob=254, param2=0},
		{name="air", prob=254, param2=0},
		{name="everness:frosted_cave_ice_illuminating", prob=254, param2=0},
		{name="air", prob=254, param2=0},
		{name="everness:frosted_cave_ice_illuminating", prob=254, param2=0},
		{name="air", prob=254, param2=0},
	},
}
