schematic = {
	size = {x=12, y=14, z=15},
	yslice_prob = {
		{ypos=0, prob=254},
		{ypos=1, prob=254},
		{ypos=2, prob=254},
		{ypos=3, prob=254},
		{ypos=4, prob=254},
		{ypos=5, prob=254},
		{ypos=6, prob=254},
		{ypos=7, prob=254},
		{ypos=8, prob=254},
		{ypos=9, prob=254},
		{ypos=10, prob=254},
		{ypos=11, prob=254},
		{ypos=12, prob=254},
		{ypos=13, prob=254},
	},
	data = {
		{name="everness:forsaken_tundra_cobble", prob=254, param2=0},
		{name="everness:forsaken_tundra_brick", prob=254, param2=0},
		{name="everness:forsaken_tundra_brick", prob=254, param2=0},
		{name="everness:forsaken_tundra_cobble", prob=254, param2=0},
		{name="everness:forsaken_tundra_cobble", prob=254, param2=0},
		{name="everness:forsaken_tundra_brick", prob=254, param2=0},
		{name="everness:forsaken_tundra_brick", prob=254, param2=0},
		{name="everness:forsaken_tundra_brick", prob=254, param2=0},
		{name="everness:forsaken_tundra_brick", prob=254, param2=0},
		{name="everness:forsaken_tundra_brick", prob=254, param2=0},
		{name="everness:forsaken_tundra_brick", prob=254, param2=0},
		{name="everness:forsaken_tundra_brick", prob=254, param2=0},
		{name="everness:forsaken_tundra_cobble", prob=254, param2=0},
		{name="everness:forsaken_tundra_brick", prob=254, param2=0},
		{name="everness:forsaken_tundra_cobble", prob=254, param2=0},
		{name="everness:forsaken_tundra_brick", prob=254, param2=0},
		{name="everness:forsaken_tundra_cobble", prob=254, param2=0},
		{name="everness:forsaken_tundra_brick", prob=254, param2=0},
		{name="everness:forsaken_tundra_brick", prob=254, param2=0},
		{name="everness:forsaken_tundra_cobble", prob=254, param2=0},
		{name="everness:forsaken_tundra_cobble", prob=254, param2=0},
		{name="everness:forsaken_tundra_cobble", prob=254, param2=0},
		{name="everness:forsaken_tundra_cobble", prob=254, param2=0},
		{name="everness:forsaken_tundra_brick", prob=254, param2=0},
		{name="everness:forsaken_tundra_brick", prob=254, param2=0},
		{name="everness:forsaken_tundra_cobble", prob=254, param2=0},
		{name="everness:forsaken_tundra_brick", prob=254, param2=0},
		{name="everness:forsaken_tundra_cobble", prob=254, param2=0},
		{name="everness:forsaken_tundra_brick", prob=254, param2=0},
		{name="everness:forsaken_tundra_brick", prob=254, param2=0},
		{name="everness:forsaken_tundra_cobble", prob=254, param2=0},
		{name="everness:forsaken_tundra_brick", prob=254, param2=0},
		{name="everness:forsaken_tundra_brick", prob=254, param2=0},
		{name="everness:forsaken_tundra_cobble", prob=254, param2=0},
		{name="everness:forsaken_tundra_cobble", prob=254, param2=0},
		{name="everness:forsaken_tundra_brick", prob=254, param2=0},
		{name="everness:forsaken_tundra_brick", prob=254, param2=0},
		{name="everness:forsaken_tundra_brick", prob=254, param2=0},
		{name="everness:forsaken_tundra_cobble", prob=254, param2=0},
		{name="everness:forsaken_tundra_cobble", prob=254, param2=0},
		{name="everness:forsaken_tundra_brick", prob=254, param2=0},
		{name="everness:forsaken_tundra_brick", prob=254, param2=0},
		{name="everness:forsaken_tundra_brick", prob=254, param2=0},
		{name="everness:forsaken_tundra_brick", prob=254, param2=0},
		{name="everness:forsaken_tundra_brick", prob=254, param2=0},
		{name="everness:forsaken_tundra_cobble", prob=254, param2=0},
		{name="everness:forsaken_tundra_brick", prob=254, param2=0},
		{name="everness:forsaken_tundra_brick", prob=254, param2=0},
		{name="everness:forsaken_tundra_brick", prob=254, param2=0},
		{name="everness:forsaken_tundra_cobble", prob=254, param2=0},
		{name="everness:forsaken_tundra_cobble", prob=254, param2=0},
		{name="everness:forsaken_tundra_brick", prob=254, param2=0},
		{name="stairs:stair_forsaken_tundra_cobble", prob=254, param2=0},
		{name="stairs:stair_forsaken_tundra_cobble", prob=254, param2=0},
		{name="stairs:stair_forsaken_tundra_cobble", prob=254, param2=0},
		{name="stairs:stair_forsaken_tundra_cobble", prob=254, param2=0},
		{name="everness:forsaken_tundra_cobble", prob=254, param2=0},
		{name="everness:forsaken_tundra_brick", prob=254, param2=0},
		{name="everness:forsaken_tundra_brick", prob=254, param2=0},
		{name="everness:forsaken_tundra_cobble", prob=254, param2=0},
		{name="air", prob=0, param2=0},
		{name="air", prob=0, param2=0},
		{name="air", prob=0, param2=0},
		{name="air", prob=0, param2=0},
		{name="air", prob=0, param2=0},
		{name="air", prob=254, param2=0},
		{name="air", prob=254, param2=0},
		{name="air", prob=0, param2=0},
		{name="air", prob=0, param2=0},
		{name="air", prob=0, param2=0},
		{name="air", prob=0, param2=0},
		{name="air", prob=0, param2=0},
		{name="air", prob=0, param2=0},
		{name="air", prob=0, param2=0},
		{name="air", prob=0, param2=0},
		{name="air", prob=0, param2=0},
		{name="air", prob=0, param2=0},
		{name="air", prob=254, param2=0},
		{name="air", prob=254, param2=0},
		{name="air", prob=0, param2=0},
		{name="air", prob=0, param2=0},
		{name="air", prob=0, param2=0},
		{name="air", prob=0, param2=0},
		{name="air", prob=0, param2=0},
		{name="air", prob=0, param2=0},
		{name="air", prob=0, param2=0},
		{name="air", prob=0, param2=0},
		{name="air", prob=0, param2=0},
		{name="air", prob=0, param2=0},
		{name="air", prob=0, param2=0},
		{name="air", prob=0, param2=0},
		{name="air", prob=0, param2=0},
		{name="air", prob=0, param2=0},
		{name="air", prob=0, param2=0},
		{name="air", prob=0, param2=0},
		{name="air", prob=0, param2=0},
		{name="air", prob=0, param2=0},
		{name="air", prob=0, param2=0},
		{name="everness:forsaken_tundra_brick", prob=254, param2=0},
		{name="air", prob=0, param2=0},
		{name="everness:forsaken_tundra_cobble", prob=254, param2=0},
		{name="air", prob=0, param2=0},
		{name="air", prob=0, param2=0},
		{name="everness:forsaken_tundra_brick", prob=254, param2=0},
		{name="air", prob=0, param2=0},
		{name="everness:forsaken_tundra_brick", prob=254, param2=0},
		{name="air", prob=0, param2=0},
		{name="air", prob=0, param2=0},
		{name="air", prob=0, param2=0},
		{name="air", prob=0, param2=0},
		{name="everness:forsaken_tundra_cobble", prob=254, param2=0},
		{name="air", prob=0, param2=0},
		{name="everness:forsaken_tundra_brick", prob=254, param2=0},
		{name="air", prob=0, param2=0},
		{name="air", prob=0, param2=0},
		{name="everness:forsaken_tundra_cobble", prob=254, param2=0},
		{name="air", prob=0, param2=0},
		{name="everness:forsaken_tundra_cobble", prob=254, param2=0},
		{name="air", prob=0, param2=0},
		{name="air", prob=0, param2=0},
		{name="air", prob=0, param2=0},
		{name="air", prob=0, param2=0},
		{name="air", prob=0, param2=0},
		{name="air", prob=0, param2=0},
		{name="air", prob=0, param2=0},
		{name="everness:forsaken_tundra_cobble", prob=254, param2=0},
		{name="everness:forsaken_tundra_brick", prob=254, param2=0},
		{name="air", prob=0, param2=0},
		{name="air", prob=0, param2=0},
		{name="air", prob=0, param2=0},
		{name="air", prob=0, param2=0},
		{name="air", prob=0, param2=0},
		{name="air", prob=0, param2=0},
		{name="air", prob=0, param2=0},
		{name="air", prob=0, param2=0},
		{name="air", prob=0, param2=0},
		{name="air", prob=0, param2=0},
		{name="air", prob=0, param2=0},
		{name="air", prob=0, param2=0},
		{name="air", prob=0, param2=0},
		{name="air", prob=0, param2=0},
		{name="air", prob=0, param2=0},
		{name="air", prob=0, param2=0},
		{name="air", prob=0, param2=0},
		{name="air", prob=0, param2=0},
		{name="air", prob=0, param2=0},
		{name="air", prob=0, param2=0},
		{name="air", prob=0, param2=0},
		{name="air", prob=0, param2=0},
		{name="air", prob=0, param2=0},
		{name="air", prob=0, param2=0},
		{name="air", prob=0, param2=0},
		{name="air", prob=0, param2=0},
		{name="air", prob=0, param2=0},
		{name="air", prob=0, param2=0},
		{name="air", prob=0, param2=0},
		{name="air", prob=0, param2=0},
		{name="air", prob=0, param2=0},
		{name="air", prob=0, param2=0},
		{name="air", prob=0, param2=0},
		{name="air", prob=0, param2=0},
		{name="air", prob=0, param2=0},
		{name="air", prob=0, param2=0},
		{name="air", prob=0, param2=0},
		{name="air", prob=0, param2=0},
		{name="air", prob=0, param2=0},
		{name="air", prob=0, param2=0},
		{name="air", prob=0, param2=0},
		{name="everness:forsaken_tundra_brick", prob=254, param2=0},
		{name="everness:forsaken_tundra_brick", prob=254, param2=0},
		{name="everness:forsaken_tundra_brick", prob=254, param2=0},
		{name="everness:forsaken_tundra_brick", prob=254, param2=0},
		{name="everness:forsaken_tundra_cobble", prob=254, param2=0},
		{name="everness:forsaken_tundra_brick", prob=254, param2=0},
		{name="everness:forsaken_tundra_cobble", prob=254, param2=0},
		{name="everness:forsaken_tundra_brick", prob=254, param2=0},
		{name="everness:forsaken_tundra_cobble", prob=254, param2=0},
		{name="everness:forsaken_tundra_cobble", prob=254, param2=0},
		{name="everness:forsaken_tundra_cobble", prob=254, param2=0},
		{name="everness:forsaken_tundra_brick", prob=254, param2=0},
		{name="everness:forsaken_tundra_brick", prob=254, param2=0},
		{name="everness:forsaken_tundra_brick", prob=254, param2=0},
		{name="air", prob=0, param2=0},
		{name="everness:forsaken_tundra_brick", prob=254, param2=0},
		{name="air", prob=254, param2=0},
		{name="everness:forsaken_tundra_cobble", prob=254, param2=0},
		{name="air", prob=254, param2=0},
		{name="air", prob=254, param2=0},
		{name="everness:forsaken_tundra_brick", prob=254, param2=0},
		{name="air", prob=254, param2=0},
		{name="everness:forsaken_tundra_brick", prob=254, param2=0},
		{name="everness:forsaken_tundra_brick", prob=254, param2=0},
		{name="everness:forsaken_tundra_brick", prob=254, param2=0},
		{name="everness:forsaken_tundra_brick", prob=254, param2=0},
		{name="everness:forsaken_tundra_cobble", prob=254, param2=0},
		{name="everness:forsaken_tundra_brick", prob=254, param2=0},
		{name="everness:forsaken_tundra_cobble", prob=254, param2=0},
		{name="air", prob=254, param2=0},
		{name="everness:forsaken_tundra_cobble", prob=254, param2=0},
		{name="everness:forsaken_tundra_brick", prob=254, param2=0},
		{name="air", prob=254, param2=0},
		{name="everness:forsaken_tundra_cobble", prob=254, param2=0},
		{name="everness:forsaken_tundra_brick", prob=254, param2=0},
		{name="everness:forsaken_tundra_brick", prob=254, param2=0},
		{name="everness:forsaken_tundra_cobble", prob=254, param2=0},
		{name="everness:forsaken_tundra_cobble", prob=254, param2=0},
		{name="everness:forsaken_tundra_cobble", prob=254, param2=0},
		{name="air", prob=254, param2=0},
		{name="air", prob=254, param2=0},
		{name="everness:forsaken_tundra_cobble", prob=254, param2=0},
		{name="air", prob=254, param2=0},
		{name="air", prob=254, param2=0},
		{name="air", prob=254, param2=0},
		{name="air", prob=254, param2=0},
		{name="air", prob=254, param2=0},
		{name="everness:forsaken_tundra_brick", prob=254, param2=0},
		{name="everness:forsaken_tundra_brick", prob=254, param2=0},
		{name="everness:forsaken_tundra_brick", prob=254, param2=0},
		{name="everness:forsaken_tundra_brick", prob=254, param2=0},
		{name="everness:forsaken_tundra_brick", prob=254, param2=0},
		{name="everness:forsaken_tundra_brick", prob=254, param2=0},
		{name="everness:forsaken_tundra_cobble", prob=254, param2=0},
		{name="everness:forsaken_tundra_brick", prob=254, param2=0},
		{name="everness:forsaken_tundra_cobble", prob=254, param2=0},
		{name="everness:forsaken_tundra_brick", prob=254, param2=0},
		{name="everness:forsaken_tundra_cobble", prob=254, param2=0},
		{name="everness:forsaken_tundra_brick", prob=254, param2=0},
		{name="everness:forsaken_tundra_cobble", prob=254, param2=0},
		{name="air", prob=0, param2=0},
		{name="air", prob=0, param2=0},
		{name="air", prob=0, param2=0},
		{name="air", prob=0, param2=0},
		{name="air", prob=0, param2=0},
		{name="air", prob=254, param2=0},
		{name="air", prob=254, param2=0},
		{name="air", prob=0, param2=0},
		{name="air", prob=0, param2=0},
		{name="air", prob=0, param2=0},
		{name="air", prob=0, param2=0},
		{name="air", prob=0, param2=0},
		{name="air", prob=0, param2=0},
		{name="air", prob=0, param2=0},
		{name="air", prob=0, param2=0},
		{name="air", prob=0, param2=0},
		{name="air", prob=0, param2=0},
		{name="air", prob=254, param2=0},
		{name="air", prob=254, param2=0},
		{name="air", prob=0, param2=0},
		{name="air", prob=0, param2=0},
		{name="air", prob=0, param2=0},
		{name="air", prob=0, param2=0},
		{name="air", prob=0, param2=0},
		{name="air", prob=0, param2=0},
		{name="everness:forsaken_tundra_cobble", prob=254, param2=0},
		{name="everness:forsaken_tundra_brick", prob=254, param2=0},
		{name="everness:forsaken_tundra_cobble", prob=254, param2=0},
		{name="everness:forsaken_tundra_cobble", prob=254, param2=0},
		{name="everness:forsaken_tundra_cobble", prob=254, param2=0},
		{name="everness:forsaken_tundra_brick", prob=254, param2=0},
		{name="everness:forsaken_tundra_cobble", prob=254, param2=0},
		{name="everness:forsaken_tundra_brick", prob=254, param2=0},
		{name="everness:forsaken_tundra_cobble", prob=254, param2=0},
		{name="everness:forsaken_tundra_cobble", prob=254, param2=0},
		{name="air", prob=0, param2=0},
		{name="air", prob=0, param2=0},
		{name="everness:forsaken_tundra_brick", prob=254, param2=0},
		{name="everness:forsaken_tundra_cobble", prob=254, param2=0},
		{name="everness:forsaken_tundra_cobble", prob=254, param2=0},
		{name="everness:forsaken_tundra_brick", prob=254, param2=0},
		{name="everness:forsaken_tundra_brick", prob=254, param2=0},
		{name="everness:forsaken_tundra_brick", prob=254, param2=0},
		{name="everness:forsaken_tundra_brick", prob=254, param2=0},
		{name="everness:forsaken_tundra_cobble", prob=254, param2=0},
		{name="everness:forsaken_tundra_brick", prob=254, param2=0},
		{name="everness:forsaken_tundra_brick", prob=254, param2=0},
		{name="air", prob=0, param2=0},
		{name="air", prob=0, param2=0},
		{name="everness:forsaken_tundra_brick", prob=254, param2=0},
		{name="everness:forsaken_tundra_cobble", prob=254, param2=0},
		{name="everness:forsaken_tundra_brick", prob=254, param2=0},
		{name="everness:forsaken_tundra_brick", prob=254, param2=0},
		{name="air", prob=254, param2=0},
		{name="air", prob=254, param2=0},
		{name="everness:forsaken_tundra_brick", prob=254, param2=0},
		{name="everness:forsaken_tundra_cobble", prob=254, param2=0},
		{name="everness:forsaken_tundra_brick", prob=254, param2=0},
		{name="everness:forsaken_tundra_brick", prob=254, param2=0},
		{name="air", prob=0, param2=0},
		{name="air", prob=0, param2=0},
		{name="everness:forsaken_tundra_cobble", prob=254, param2=0},
		{name="everness:forsaken_tundra_brick", prob=254, param2=0},
		{name="everness:forsaken_tundra_brick", prob=254, param2=0},
		{name="everness:forsaken_tundra_cobble", prob=254, param2=0},
		{name="everness:forsaken_tundra_brick", prob=254, param2=0},
		{name="everness:forsaken_tundra_cobble", prob=254, param2=0},
		{name="everness:forsaken_tundra_cobble", prob=254, param2=0},
		{name="everness:forsaken_tundra_cobble", prob=254, param2=0},
		{name="everness:forsaken_tundra_cobble", prob=254, param2=0},
		{name="everness:forsaken_tundra_brick", prob=254, param2=0},
		{name="air", prob=0, param2=0},
		{name="air", prob=0, param2=0},
		{name="air", prob=0, param2=0},
		{name="air", prob=0, param2=0},
		{name="air", prob=0, param2=0},
		{name="air", prob=0, param2=0},
		{name="air", prob=0, param2=0},
		{name="air", prob=0, param2=0},
		{name="air", prob=0, param2=0},
		{name="air", prob=0, param2=0},
		{name="air", prob=0, param2=0},
		{name="air", prob=0, param2=0},
		{name="air", prob=0, param2=0},
		{name="air", prob=0, param2=0},
		{name="air", prob=0, param2=0},
		{name="air", prob=0, param2=0},
		{name="air", prob=0, param2=0},
		{name="air", prob=0, param2=0},
		{name="air", prob=0, param2=0},
		{name="air", prob=0, param2=0},
		{name="air", prob=0, param2=0},
		{name="air", prob=0, param2=0},
		{name="air", prob=0, param2=0},
		{name="air", prob=0, param2=0},
		{name="air", prob=0, param2=0},
		{name="air", prob=0, param2=0},
		{name="air", prob=0, param2=0},
		{name="air", prob=0, param2=0},
		{name="air", prob=0, param2=0},
		{name="air", prob=0, param2=0},
		{name="air", prob=0, param2=0},
		{name="air", prob=0, param2=0},
		{name="air", prob=0, param2=0},
		{name="air", prob=0, param2=0},
		{name="air", prob=0, param2=0},
		{name="air", prob=0, param2=0},
		{name="air", prob=0, param2=0},
		{name="everness:forsaken_tundra_cobble", prob=254, param2=0},
		{name="everness:forsaken_tundra_cobble", prob=254, param2=0},
		{name="everness:forsaken_tundra_brick", prob=254, param2=0},
		{name="everness:forsaken_tundra_brick", prob=254, param2=0},
		{name="everness:forsaken_tundra_cobble", prob=254, param2=0},
		{name="everness:forsaken_tundra_brick", prob=254, param2=0},
		{name="everness:forsaken_tundra_brick", prob=254, param2=0},
		{name="everness:forsaken_tundra_cobble", prob=254, param2=0},
		{name="everness:forsaken_tundra_cobble", prob=254, param2=0},
		{name="everness:forsaken_tundra_cobble", prob=254, param2=0},
		{name="everness:forsaken_tundra_brick", prob=254, param2=0},
		{name="everness:forsaken_tundra_brick", prob=254, param2=0},
		{name="everness:forsaken_tundra_brick", prob=254, param2=0},
		{name="everness:forsaken_tundra_cobble", prob=254, param2=0},
		{name="everness:forsaken_tundra_brick", prob=254, param2=0},
		{name="air", prob=254, param2=0},
		{name="air", prob=254, param2=0},
		{name="air", prob=254, param2=0},
		{name="air", prob=254, param2=0},
		{name="air", prob=254, param2=0},
		{name="air", prob=254, param2=0},
		{name="air", prob=254, param2=0},
		{name="air", prob=254, param2=0},
		{name="everness:forsaken_tundra_cobble", prob=254, param2=0},
		{name="everness:forsaken_tundra_cobble", prob=254, param2=0},
		{name="everness:forsaken_tundra_cobble", prob=254, param2=0},
		{name="air", prob=254, param2=0},
		{name="air", prob=254, param2=0},
		{name="air", prob=254, param2=0},
		{name="air", prob=254, param2=0},
		{name="air", prob=254, param2=0},
		{name="air", prob=254, param2=0},
		{name="air", prob=254, param2=0},
		{name="air", prob=254, param2=0},
		{name="air", prob=254, param2=0},
		{name="everness:forsaken_tundra_cobble", prob=254, param2=0},
		{name="everness:forsaken_tundra_brick", prob=254, param2=0},
		{name="everness:forsaken_tundra_brick", prob=254, param2=0},
		{name="everness:forsaken_tundra_brick", prob=254, param2=0},
		{name="air", prob=254, param2=0},
		{name="air", prob=254, param2=0},
		{name="air", prob=254, param2=0},
		{name="air", prob=254, param2=0},
		{name="air", prob=254, param2=0},
		{name="everness:forsaken_tundra_brick", prob=254, param2=0},
		{name="everness:forsaken_tundra_brick", prob=254, param2=0},
		{name="everness:forsaken_tundra_brick", prob=254, param2=0},
		{name="everness:forsaken_tundra_cobble", prob=254, param2=0},
		{name="everness:forsaken_tundra_cobble", prob=254, param2=0},
		{name="everness:forsaken_tundra_cobble", prob=254, param2=0},
		{name="everness:forsaken_tundra_brick", prob=254, param2=0},
		{name="everness:forsaken_tundra_cobble", prob=254, param2=0},
		{name="everness:forsaken_tundra_cobble", prob=254, param2=0},
		{name="everness:forsaken_tundra_brick", prob=254, param2=0},
		{name="everness:forsaken_tundra_brick", prob=254, param2=0},
		{name="everness:forsaken_tundra_cobble", prob=254, param2=0},
		{name="everness:forsaken_tundra_cobble", prob=254, param2=0},
		{name="everness:forsaken_tundra_cobble", prob=254, param2=0},
		{name="everness:forsaken_tundra_brick", prob=254, param2=0},
		{name="everness:forsaken_tundra_brick", prob=254, param2=0},
		{name="air", prob=0, param2=0},
		{name="air", prob=0, param2=0},
		{name="everness:forsaken_tundra_cobble", prob=254, param2=0},
		{name="everness:forsaken_tundra_cobble", prob=254, param2=0},
		{name="everness:forsaken_tundra_brick", prob=254, param2=0},
		{name="air", prob=254, param2=0},
		{name="air", prob=254, param2=0},
		{name="everness:forsaken_tundra_brick", prob=254, param2=0},
		{name="everness:forsaken_tundra_cobble", prob=254, param2=0},
		{name="everness:forsaken_tundra_cobble", prob=254, param2=0},
		{name="air", prob=0, param2=0},
		{name="air", prob=0, param2=0},
		{name="air", prob=0, param2=0},
		{name="air", prob=0, param2=0},
		{name="everness:forsaken_tundra_cobble", prob=254, param2=0},
		{name="everness:forsaken_tundra_brick", prob=254, param2=0},
		{name="everness:forsaken_tundra_cobble", prob=254, param2=0},
		{name="air", prob=254, param2=0},
		{name="air", prob=254, param2=0},
		{name="everness:forsaken_tundra_cobble", prob=254, param2=0},
		{name="everness:forsaken_tundra_brick", prob=254, param2=0},
		{name="everness:forsaken_tundra_cobble", prob=254, param2=0},
		{name="air", prob=0, param2=0},
		{name="air", prob=0, param2=0},
		{name="air", prob=0, param2=0},
		{name="everness:forsaken_tundra_cobble", prob=254, param2=0},
		{name="everness:forsaken_tundra_brick", prob=254, param2=0},
		{name="everness:forsaken_tundra_cobble", prob=254, param2=0},
		{name="everness:forsaken_tundra_cobble", prob=254, param2=0},
		{name="everness:forsaken_tundra_cobble", prob=254, param2=0},
		{name="everness:forsaken_tundra_cobble", prob=254, param2=0},
		{name="everness:forsaken_tundra_brick", prob=254, param2=0},
		{name="everness:forsaken_tundra_cobble", prob=254, param2=0},
		{name="everness:forsaken_tundra_cobble", prob=254, param2=0},
		{name="everness:forsaken_tundra_cobble", prob=254, param2=0},
		{name="air", prob=0, param2=0},
		{name="everness:forsaken_tundra_brick", prob=254, param2=0},
		{name="everness:forsaken_tundra_cobble", prob=254, param2=0},
		{name="air", prob=254, param2=0},
		{name="air", prob=254, param2=0},
		{name="air", prob=254, param2=0},
		{name="air", prob=254, param2=0},
		{name="air", prob=254, param2=0},
		{name="air", prob=254, param2=0},
		{name="air", prob=254, param2=0},
		{name="air", prob=254, param2=0},
		{name="everness:forsaken_tundra_cobble", prob=254, param2=0},
		{name="everness:forsaken_tundra_cobble", prob=254, param2=0},
		{name="everness:forsaken_tundra_brick", prob=254, param2=0},
		{name="everness:forsaken_tundra_cobble", prob=254, param2=0},
		{name="air", prob=254, param2=0},
		{name="air", prob=254, param2=0},
		{name="air", prob=254, param2=0},
		{name="air", prob=254, param2=0},
		{name="air", prob=254, param2=0},
		{name="air", prob=254, param2=0},
		{name="air", prob=254, param2=0},
		{name="air", prob=254, param2=0},
		{name="everness:forsaken_tundra_cobble", prob=254, param2=0},
		{name="everness:forsaken_tundra_brick", prob=254, param2=0},
		{name="air", prob=0, param2=0},
		{name="everness:forsaken_tundra_cobble", prob=254, param2=0},
		{name="everness:forsaken_tundra_cobble", prob=254, param2=0},
		{name="everness:forsaken_tundra_cobble", prob=254, param2=0},
		{name="everness:forsaken_tundra_cobble", prob=254, param2=0},
		{name="everness:forsaken_tundra_brick", prob=254, param2=0},
		{name="everness:forsaken_tundra_cobble", prob=254, param2=0},
		{name="everness:forsaken_tundra_brick", prob=254, param2=0},
		{name="everness:forsaken_tundra_cobble", prob=254, param2=0},
		{name="everness:forsaken_tundra_cobble", prob=254, param2=0},
		{name="everness:forsaken_tundra_brick", prob=254, param2=0},
		{name="air", prob=0, param2=0},
		{name="air", prob=0, param2=0},
		{name="air", prob=0, param2=0},
		{name="everness:forsaken_tundra_cobble", prob=254, param2=0},
		{name="air", prob=0, param2=0},
		{name="air", prob=0, param2=0},
		{name="air", prob=0, param2=0},
		{name="air", prob=0, param2=0},
		{name="air", prob=0, param2=0},
		{name="air", prob=0, param2=0},
		{name="everness:forsaken_tundra_cobble", prob=254, param2=0},
		{name="air", prob=0, param2=0},
		{name="air", prob=0, param2=0},
		{name="air", prob=0, param2=0},
		{name="air", prob=0, param2=0},
		{name="everness:forsaken_tundra_cobble", prob=254, param2=0},
		{name="air", prob=0, param2=0},
		{name="air", prob=0, param2=0},
		{name="air", prob=0, param2=0},
		{name="air", prob=0, param2=0},
		{name="air", prob=0, param2=0},
		{name="air", prob=0, param2=0},
		{name="everness:forsaken_tundra_cobble", prob=254, param2=0},
		{name="air", prob=0, param2=0},
		{name="air", prob=0, param2=0},
		{name="air", prob=0, param2=0},
		{name="air", prob=0, param2=0},
		{name="everness:forsaken_tundra_brick", prob=254, param2=0},
		{name="air", prob=0, param2=0},
		{name="air", prob=0, param2=0},
		{name="air", prob=0, param2=0},
		{name="air", prob=0, param2=0},
		{name="air", prob=0, param2=0},
		{name="air", prob=0, param2=0},
		{name="everness:forsaken_tundra_brick", prob=254, param2=0},
		{name="air", prob=0, param2=0},
		{name="air", prob=0, param2=0},
		{name="everness:forsaken_tundra_brick", prob=254, param2=0},
		{name="everness:forsaken_tundra_brick", prob=254, param2=0},
		{name="everness:forsaken_tundra_cobble", prob=254, param2=0},
		{name="everness:forsaken_tundra_cobble", prob=254, param2=0},
		{name="everness:forsaken_tundra_cobble", prob=254, param2=0},
		{name="everness:forsaken_tundra_cobble", prob=254, param2=0},
		{name="everness:forsaken_tundra_cobble", prob=254, param2=0},
		{name="everness:forsaken_tundra_cobble", prob=254, param2=0},
		{name="everness:forsaken_tundra_cobble", prob=254, param2=0},
		{name="everness:forsaken_tundra_brick", prob=254, param2=0},
		{name="everness:forsaken_tundra_cobble", prob=254, param2=0},
		{name="everness:forsaken_tundra_cobble", prob=254, param2=0},
		{name="everness:forsaken_tundra_brick", prob=254, param2=0},
		{name="everness:forsaken_tundra_brick", prob=254, param2=0},
		{name="air", prob=254, param2=0},
		{name="everness:chest", prob=254, param2=3},
		{name="air", prob=254, param2=0},
		{name="air", prob=254, param2=0},
		{name="air", prob=254, param2=0},
		{name="air", prob=254, param2=0},
		{name="air", prob=254, param2=0},
		{name="air", prob=254, param2=0},
		{name="everness:forsaken_tundra_brick", prob=254, param2=0},
		{name="everness:forsaken_tundra_brick", prob=254, param2=0},
		{name="everness:forsaken_tundra_cobble", prob=254, param2=0},
		{name="everness:forsaken_tundra_brick", prob=254, param2=0},
		{name="air", prob=254, param2=0},
		{name="air", prob=254, param2=0},
		{name="air", prob=254, param2=0},
		{name="air", prob=254, param2=0},
		{name="air", prob=254, param2=0},
		{name="air", prob=254, param2=0},
		{name="air", prob=254, param2=0},
		{name="air", prob=254, param2=0},
		{name="everness:forsaken_tundra_brick", prob=254, param2=0},
		{name="everness:forsaken_tundra_brick", prob=254, param2=0},
		{name="everness:forsaken_tundra_brick", prob=254, param2=0},
		{name="everness:forsaken_tundra_cobble", prob=254, param2=0},
		{name="everness:forsaken_tundra_cobble", prob=254, param2=0},
		{name="air", prob=254, param2=0},
		{name="air", prob=254, param2=0},
		{name="air", prob=254, param2=0},
		{name="air", prob=254, param2=0},
		{name="air", prob=254, param2=0},
		{name="air", prob=254, param2=0},
		{name="air", prob=254, param2=0},
		{name="air", prob=254, param2=0},
		{name="everness:forsaken_tundra_brick", prob=254, param2=0},
		{name="everness:forsaken_tundra_brick", prob=254, param2=0},
		{name="everness:forsaken_tundra_brick", prob=254, param2=0},
		{name="everness:forsaken_tundra_cobble", prob=254, param2=0},
		{name="everness:forsaken_tundra_brick", prob=254, param2=0},
		{name="everness:forsaken_tundra_brick", prob=254, param2=0},
		{name="everness:forsaken_tundra_brick", prob=254, param2=0},
		{name="everness:forsaken_tundra_brick", prob=254, param2=0},
		{name="everness:forsaken_tundra_cobble", prob=254, param2=0},
		{name="everness:forsaken_tundra_cobble", prob=254, param2=0},
		{name="everness:forsaken_tundra_cobble", prob=254, param2=0},
		{name="everness:forsaken_tundra_cobble", prob=254, param2=0},
		{name="everness:forsaken_tundra_cobble", prob=254, param2=0},
		{name="air", prob=0, param2=0},
		{name="air", prob=0, param2=0},
		{name="everness:forsaken_tundra_brick", prob=254, param2=0},
		{name="air", prob=254, param2=0},
		{name="air", prob=254, param2=0},
		{name="air", prob=254, param2=0},
		{name="air", prob=254, param2=0},
		{name="air", prob=254, param2=0},
		{name="air", prob=254, param2=0},
		{name="everness:forsaken_tundra_brick", prob=254, param2=0},
		{name="air", prob=0, param2=0},
		{name="air", prob=0, param2=0},
		{name="air", prob=0, param2=0},
		{name="air", prob=0, param2=0},
		{name="everness:forsaken_tundra_cobble", prob=254, param2=0},
		{name="air", prob=254, param2=0},
		{name="air", prob=254, param2=0},
		{name="air", prob=254, param2=0},
		{name="air", prob=254, param2=0},
		{name="air", prob=254, param2=0},
		{name="air", prob=254, param2=0},
		{name="everness:forsaken_tundra_cobble", prob=254, param2=0},
		{name="air", prob=0, param2=0},
		{name="air", prob=0, param2=0},
		{name="air", prob=0, param2=0},
		{name="everness:forsaken_tundra_brick", prob=254, param2=0},
		{name="everness:forsaken_tundra_cobble", prob=254, param2=0},
		{name="everness:forsaken_tundra_cobble", prob=254, param2=0},
		{name="everness:forsaken_tundra_brick", prob=254, param2=0},
		{name="everness:forsaken_tundra_brick", prob=254, param2=0},
		{name="everness:forsaken_tundra_brick", prob=254, param2=0},
		{name="everness:forsaken_tundra_cobble", prob=254, param2=0},
		{name="everness:forsaken_tundra_brick", prob=254, param2=0},
		{name="everness:forsaken_tundra_cobble", prob=254, param2=0},
		{name="everness:forsaken_tundra_brick", prob=254, param2=0},
		{name="air", prob=0, param2=0},
		{name="air", prob=0, param2=0},
		{name="everness:forsaken_tundra_brick", prob=254, param2=0},
		{name="air", prob=254, param2=0},
		{name="air", prob=254, param2=0},
		{name="air", prob=254, param2=0},
		{name="air", prob=254, param2=0},
		{name="air", prob=254, param2=0},
		{name="air", prob=254, param2=0},
		{name="air", prob=254, param2=0},
		{name="air", prob=254, param2=0},
		{name="everness:forsaken_tundra_cobble", prob=254, param2=0},
		{name="air", prob=0, param2=0},
		{name="air", prob=0, param2=0},
		{name="everness:forsaken_tundra_brick", prob=254, param2=0},
		{name="air", prob=254, param2=0},
		{name="air", prob=254, param2=0},
		{name="air", prob=254, param2=0},
		{name="air", prob=254, param2=0},
		{name="air", prob=254, param2=0},
		{name="air", prob=254, param2=0},
		{name="air", prob=254, param2=0},
		{name="air", prob=254, param2=0},
		{name="everness:forsaken_tundra_brick", prob=254, param2=0},
		{name="air", prob=0, param2=0},
		{name="air", prob=0, param2=0},
		{name="everness:forsaken_tundra_brick", prob=254, param2=0},
		{name="everness:forsaken_tundra_brick", prob=254, param2=0},
		{name="everness:forsaken_tundra_brick", prob=254, param2=0},
		{name="everness:forsaken_tundra_cobble", prob=254, param2=0},
		{name="everness:forsaken_tundra_brick", prob=254, param2=0},
		{name="everness:forsaken_tundra_brick", prob=254, param2=0},
		{name="everness:forsaken_tundra_brick", prob=254, param2=0},
		{name="everness:forsaken_tundra_cobble", prob=254, param2=0},
		{name="everness:forsaken_tundra_brick", prob=254, param2=0},
		{name="everness:forsaken_tundra_cobble", prob=254, param2=0},
		{name="air", prob=0, param2=0},
		{name="air", prob=0, param2=0},
		{name="air", prob=0, param2=0},
		{name="air", prob=0, param2=0},
		{name="everness:forsaken_tundra_cobble", prob=254, param2=0},
		{name="everness:forsaken_tundra_cobble", prob=254, param2=0},
		{name="everness:forsaken_tundra_cobble", prob=254, param2=0},
		{name="everness:forsaken_tundra_brick", prob=254, param2=0},
		{name="everness:forsaken_tundra_cobble", prob=254, param2=0},
		{name="everness:forsaken_tundra_brick", prob=254, param2=0},
		{name="air", prob=0, param2=0},
		{name="air", prob=0, param2=0},
		{name="air", prob=0, param2=0},
		{name="air", prob=0, param2=0},
		{name="air", prob=0, param2=0},
		{name="air", prob=0, param2=0},
		{name="air", prob=0, param2=0},
		{name="air", prob=0, param2=0},
		{name="air", prob=0, param2=0},
		{name="air", prob=0, param2=0},
		{name="air", prob=0, param2=0},
		{name="air", prob=0, param2=0},
		{name="air", prob=0, param2=0},
		{name="air", prob=0, param2=0},
		{name="air", prob=0, param2=0},
		{name="air", prob=0, param2=0},
		{name="air", prob=0, param2=0},
		{name="air", prob=0, param2=0},
		{name="air", prob=0, param2=0},
		{name="air", prob=0, param2=0},
		{name="air", prob=0, param2=0},
		{name="air", prob=0, param2=0},
		{name="air", prob=0, param2=0},
		{name="air", prob=0, param2=0},
		{name="air", prob=0, param2=0},
		{name="air", prob=0, param2=0},
		{name="air", prob=0, param2=0},
		{name="everness:forsaken_tundra_cobble", prob=254, param2=0},
		{name="everness:forsaken_tundra_brick", prob=254, param2=0},
		{name="everness:forsaken_tundra_brick", prob=254, param2=0},
		{name="everness:forsaken_tundra_brick", prob=254, param2=0},
		{name="everness:forsaken_tundra_brick", prob=254, param2=0},
		{name="everness:forsaken_tundra_cobble", prob=254, param2=0},
		{name="everness:forsaken_tundra_brick", prob=254, param2=0},
		{name="everness:forsaken_tundra_brick", prob=254, param2=0},
		{name="everness:forsaken_tundra_cobble", prob=254, param2=0},
		{name="everness:forsaken_tundra_cobble", prob=254, param2=0},
		{name="everness:forsaken_tundra_cobble", prob=254, param2=0},
		{name="everness:forsaken_tundra_cobble", prob=254, param2=0},
		{name="everness:forsaken_tundra_brick", prob=254, param2=0},
		{name="everness:forsaken_tundra_brick", prob=254, param2=0},
		{name="everness:forsaken_tundra_brick", prob=254, param2=0},
		{name="air", prob=254, param2=0},
		{name="air", prob=254, param2=0},
		{name="air", prob=254, param2=0},
		{name="air", prob=254, param2=0},
		{name="air", prob=254, param2=0},
		{name="air", prob=254, param2=0},
		{name="air", prob=254, param2=0},
		{name="air", prob=254, param2=0},
		{name="everness:forsaken_tundra_brick", prob=254, param2=0},
		{name="everness:forsaken_tundra_brick", prob=254, param2=0},
		{name="everness:forsaken_tundra_brick", prob=254, param2=0},
		{name="air", prob=254, param2=0},
		{name="air", prob=254, param2=0},
		{name="air", prob=254, param2=0},
		{name="air", prob=254, param2=0},
		{name="air", prob=254, param2=0},
		{name="air", prob=254, param2=0},
		{name="air", prob=254, param2=0},
		{name="air", prob=254, param2=0},
		{name="air", prob=254, param2=0},
		{name="everness:forsaken_tundra_cobble", prob=254, param2=0},
		{name="everness:forsaken_tundra_brick", prob=254, param2=0},
		{name="everness:forsaken_tundra_brick", prob=254, param2=0},
		{name="everness:forsaken_tundra_brick", prob=254, param2=0},
		{name="air", prob=254, param2=0},
		{name="air", prob=254, param2=0},
		{name="air", prob=254, param2=0},
		{name="air", prob=254, param2=0},
		{name="air", prob=254, param2=0},
		{name="everness:forsaken_tundra_cobble", prob=254, param2=0},
		{name="everness:forsaken_tundra_cobble", prob=254, param2=0},
		{name="everness:forsaken_tundra_brick", prob=254, param2=0},
		{name="everness:forsaken_tundra_cobble", prob=254, param2=0},
		{name="everness:forsaken_tundra_cobble", prob=254, param2=0},
		{name="everness:forsaken_tundra_brick", prob=254, param2=0},
		{name="everness:forsaken_tundra_cobble", prob=254, param2=0},
		{name="everness:forsaken_tundra_cobble", prob=254, param2=0},
		{name="everness:forsaken_tundra_cobble", prob=254, param2=0},
		{name="everness:forsaken_tundra_cobble", prob=254, param2=0},
		{name="everness:forsaken_tundra_brick", prob=254, param2=0},
		{name="everness:forsaken_tundra_cobble", prob=254, param2=0},
		{name="everness:forsaken_tundra_cobble", prob=254, param2=0},
		{name="everness:forsaken_tundra_brick", prob=254, param2=0},
		{name="everness:forsaken_tundra_cobble", prob=254, param2=0},
		{name="everness:forsaken_tundra_cobble", prob=254, param2=0},
		{name="air", prob=0, param2=0},
		{name="air", prob=0, param2=0},
		{name="everness:forsaken_tundra_cobble", prob=254, param2=0},
		{name="air", prob=254, param2=0},
		{name="air", prob=254, param2=0},
		{name="air", prob=254, param2=0},
		{name="air", prob=254, param2=0},
		{name="air", prob=254, param2=0},
		{name="air", prob=254, param2=0},
		{name="everness:forsaken_tundra_cobble", prob=254, param2=0},
		{name="air", prob=0, param2=0},
		{name="air", prob=0, param2=0},
		{name="air", prob=0, param2=0},
		{name="air", prob=0, param2=0},
		{name="everness:forsaken_tundra_brick", prob=254, param2=0},
		{name="air", prob=254, param2=0},
		{name="air", prob=254, param2=0},
		{name="air", prob=254, param2=0},
		{name="air", prob=254, param2=0},
		{name="air", prob=254, param2=0},
		{name="air", prob=254, param2=0},
		{name="everness:forsaken_tundra_cobble", prob=254, param2=0},
		{name="air", prob=0, param2=0},
		{name="air", prob=0, param2=0},
		{name="air", prob=0, param2=0},
		{name="everness:forsaken_tundra_brick", prob=254, param2=0},
		{name="everness:forsaken_tundra_cobble", prob=254, param2=0},
		{name="everness:forsaken_tundra_cobble", prob=254, param2=0},
		{name="everness:forsaken_tundra_cobble", prob=254, param2=0},
		{name="everness:forsaken_tundra_cobble", prob=254, param2=0},
		{name="everness:forsaken_tundra_cobble", prob=254, param2=0},
		{name="everness:forsaken_tundra_brick", prob=254, param2=0},
		{name="everness:forsaken_tundra_cobble", prob=254, param2=0},
		{name="everness:forsaken_tundra_brick", prob=254, param2=0},
		{name="everness:forsaken_tundra_brick", prob=254, param2=0},
		{name="air", prob=0, param2=0},
		{name="everness:forsaken_tundra_brick", prob=254, param2=0},
		{name="everness:forsaken_tundra_cobble", prob=254, param2=0},
		{name="air", prob=254, param2=0},
		{name="air", prob=254, param2=0},
		{name="air", prob=254, param2=0},
		{name="air", prob=254, param2=0},
		{name="air", prob=254, param2=0},
		{name="air", prob=254, param2=0},
		{name="air", prob=254, param2=0},
		{name="air", prob=254, param2=0},
		{name="everness:forsaken_tundra_brick", prob=254, param2=0},
		{name="everness:forsaken_tundra_brick", prob=254, param2=0},
		{name="everness:forsaken_tundra_brick", prob=254, param2=0},
		{name="everness:forsaken_tundra_brick", prob=254, param2=0},
		{name="air", prob=254, param2=0},
		{name="air", prob=254, param2=0},
		{name="air", prob=254, param2=0},
		{name="air", prob=254, param2=0},
		{name="air", prob=254, param2=0},
		{name="air", prob=254, param2=0},
		{name="air", prob=254, param2=0},
		{name="air", prob=254, param2=0},
		{name="everness:forsaken_tundra_cobble", prob=254, param2=0},
		{name="everness:forsaken_tundra_cobble", prob=254, param2=0},
		{name="air", prob=0, param2=0},
		{name="everness:forsaken_tundra_brick", prob=254, param2=0},
		{name="everness:forsaken_tundra_cobble", prob=254, param2=0},
		{name="everness:forsaken_tundra_cobble", prob=254, param2=0},
		{name="everness:forsaken_tundra_brick", prob=254, param2=0},
		{name="everness:forsaken_tundra_brick", prob=254, param2=0},
		{name="everness:forsaken_tundra_brick", prob=254, param2=0},
		{name="everness:forsaken_tundra_cobble", prob=254, param2=0},
		{name="everness:forsaken_tundra_brick", prob=254, param2=0},
		{name="everness:forsaken_tundra_cobble", prob=254, param2=0},
		{name="everness:forsaken_tundra_brick", prob=254, param2=0},
		{name="air", prob=0, param2=0},
		{name="air", prob=0, param2=0},
		{name="air", prob=0, param2=0},
		{name="air", prob=0, param2=0},
		{name="everness:forsaken_tundra_cobble", prob=254, param2=0},
		{name="everness:forsaken_tundra_cobble", prob=254, param2=0},
		{name="everness:forsaken_tundra_brick", prob=254, param2=0},
		{name="everness:forsaken_tundra_brick", prob=254, param2=0},
		{name="everness:forsaken_tundra_brick", prob=254, param2=0},
		{name="everness:forsaken_tundra_brick", prob=254, param2=0},
		{name="air", prob=0, param2=0},
		{name="air", prob=0, param2=0},
		{name="air", prob=0, param2=0},
		{name="air", prob=0, param2=0},
		{name="air", prob=0, param2=0},
		{name="air", prob=0, param2=0},
		{name="air", prob=0, param2=0},
		{name="everness:forsaken_tundra_brick", prob=254, param2=0},
		{name="everness:forsaken_tundra_brick", prob=254, param2=0},
		{name="everness:forsaken_tundra_cobble", prob=254, param2=0},
		{name="everness:forsaken_tundra_brick", prob=254, param2=0},
		{name="air", prob=0, param2=0},
		{name="air", prob=0, param2=0},
		{name="air", prob=0, param2=0},
		{name="air", prob=0, param2=0},
		{name="air", prob=0, param2=0},
		{name="air", prob=0, param2=0},
		{name="air", prob=0, param2=0},
		{name="air", prob=0, param2=0},
		{name="air", prob=0, param2=0},
		{name="air", prob=0, param2=0},
		{name="air", prob=0, param2=0},
		{name="air", prob=0, param2=0},
		{name="air", prob=0, param2=0},
		{name="air", prob=0, param2=0},
		{name="air", prob=0, param2=0},
		{name="air", prob=0, param2=0},
		{name="everness:forsaken_tundra_brick", prob=254, param2=0},
		{name="everness:forsaken_tundra_cobble", prob=254, param2=0},
		{name="everness:forsaken_tundra_cobble", prob=254, param2=0},
		{name="everness:forsaken_tundra_brick", prob=254, param2=0},
		{name="everness:forsaken_tundra_cobble", prob=254, param2=0},
		{name="everness:forsaken_tundra_cobble", prob=254, param2=0},
		{name="everness:forsaken_tundra_cobble", prob=254, param2=0},
		{name="everness:forsaken_tundra_brick", prob=254, param2=0},
		{name="everness:forsaken_tundra_brick", prob=254, param2=0},
		{name="everness:forsaken_tundra_cobble", prob=254, param2=0},
		{name="everness:forsaken_tundra_brick", prob=254, param2=0},
		{name="everness:forsaken_tundra_brick", prob=254, param2=0},
		{name="everness:forsaken_tundra_cobble", prob=254, param2=0},
		{name="everness:forsaken_tundra_brick", prob=254, param2=0},
		{name="air", prob=254, param2=0},
		{name="everness:forsaken_tundra_cobble", prob=254, param2=0},
		{name="air", prob=254, param2=0},
		{name="everness:forsaken_tundra_cobble", prob=254, param2=0},
		{name="air", prob=254, param2=0},
		{name="everness:forsaken_tundra_cobble", prob=254, param2=0},
		{name="air", prob=254, param2=0},
		{name="air", prob=254, param2=0},
		{name="everness:forsaken_tundra_cobble", prob=254, param2=0},
		{name="everness:forsaken_tundra_brick", prob=254, param2=0},
		{name="everness:forsaken_tundra_cobble", prob=254, param2=0},
		{name="everness:forsaken_tundra_brick", prob=254, param2=0},
		{name="air", prob=254, param2=0},
		{name="air", prob=254, param2=0},
		{name="everness:forsaken_tundra_brick", prob=254, param2=0},
		{name="air", prob=254, param2=0},
		{name="everness:forsaken_tundra_brick", prob=254, param2=0},
		{name="air", prob=254, param2=0},
		{name="air", prob=254, param2=0},
		{name="air", prob=254, param2=0},
		{name="everness:forsaken_tundra_brick", prob=254, param2=0},
		{name="everness:forsaken_tundra_brick", prob=254, param2=0},
		{name="everness:forsaken_tundra_brick", prob=254, param2=0},
		{name="everness:forsaken_tundra_brick", prob=254, param2=0},
		{name="everness:forsaken_tundra_brick", prob=254, param2=0},
		{name="air", prob=254, param2=0},
		{name="everness:forsaken_tundra_brick", prob=254, param2=0},
		{name="air", prob=254, param2=0},
		{name="everness:forsaken_tundra_brick", prob=254, param2=0},
		{name="air", prob=254, param2=0},
		{name="air", prob=254, param2=0},
		{name="air", prob=254, param2=0},
		{name="air", prob=254, param2=0},
		{name="everness:forsaken_tundra_cobble", prob=254, param2=0},
		{name="everness:forsaken_tundra_cobble", prob=254, param2=0},
		{name="everness:forsaken_tundra_brick", prob=254, param2=0},
		{name="everness:forsaken_tundra_brick", prob=254, param2=0},
		{name="everness:forsaken_tundra_brick", prob=254, param2=0},
		{name="everness:forsaken_tundra_cobble", prob=254, param2=0},
		{name="everness:forsaken_tundra_cobble", prob=254, param2=0},
		{name="everness:forsaken_tundra_brick", prob=254, param2=0},
		{name="everness:forsaken_tundra_brick", prob=254, param2=0},
		{name="everness:forsaken_tundra_brick", prob=254, param2=0},
		{name="everness:forsaken_tundra_cobble", prob=254, param2=0},
		{name="everness:forsaken_tundra_brick", prob=254, param2=0},
		{name="everness:forsaken_tundra_cobble", prob=254, param2=0},
		{name="air", prob=0, param2=0},
		{name="air", prob=0, param2=0},
		{name="everness:forsaken_tundra_cobble", prob=254, param2=0},
		{name="air", prob=254, param2=0},
		{name="air", prob=254, param2=0},
		{name="air", prob=254, param2=0},
		{name="air", prob=254, param2=0},
		{name="air", prob=254, param2=0},
		{name="air", prob=254, param2=0},
		{name="everness:forsaken_tundra_cobble", prob=254, param2=0},
		{name="air", prob=0, param2=0},
		{name="air", prob=0, param2=0},
		{name="air", prob=0, param2=0},
		{name="air", prob=0, param2=0},
		{name="everness:forsaken_tundra_cobble", prob=254, param2=0},
		{name="air", prob=254, param2=0},
		{name="air", prob=254, param2=0},
		{name="air", prob=254, param2=0},
		{name="air", prob=254, param2=0},
		{name="air", prob=254, param2=0},
		{name="air", prob=254, param2=0},
		{name="everness:forsaken_tundra_cobble", prob=254, param2=0},
		{name="air", prob=0, param2=0},
		{name="air", prob=0, param2=0},
		{name="air", prob=0, param2=0},
		{name="everness:forsaken_tundra_cobble", prob=254, param2=0},
		{name="everness:forsaken_tundra_brick", prob=254, param2=0},
		{name="everness:forsaken_tundra_cobble", prob=254, param2=0},
		{name="everness:forsaken_tundra_brick", prob=254, param2=0},
		{name="everness:forsaken_tundra_cobble", prob=254, param2=0},
		{name="everness:forsaken_tundra_cobble", prob=254, param2=0},
		{name="everness:forsaken_tundra_brick", prob=254, param2=0},
		{name="everness:forsaken_tundra_brick", prob=254, param2=0},
		{name="everness:forsaken_tundra_cobble", prob=254, param2=0},
		{name="everness:forsaken_tundra_cobble", prob=254, param2=0},
		{name="air", prob=0, param2=0},
		{name="air", prob=0, param2=0},
		{name="everness:forsaken_tundra_brick", prob=254, param2=0},
		{name="air", prob=254, param2=0},
		{name="air", prob=254, param2=0},
		{name="stairs:stair_forsaken_tundra_cobble", prob=254, param2=1},
		{name="everness:forsaken_tundra_cobble", prob=254, param2=0},
		{name="everness:forsaken_tundra_cobble", prob=254, param2=0},
		{name="stairs:stair_forsaken_tundra_cobble", prob=254, param2=3},
		{name="air", prob=254, param2=0},
		{name="air", prob=254, param2=0},
		{name="everness:forsaken_tundra_cobble", prob=254, param2=0},
		{name="air", prob=0, param2=0},
		{name="air", prob=0, param2=0},
		{name="air", prob=254, param2=0},
		{name="air", prob=254, param2=0},
		{name="air", prob=254, param2=0},
		{name="air", prob=254, param2=0},
		{name="air", prob=254, param2=0},
		{name="air", prob=254, param2=0},
		{name="air", prob=254, param2=0},
		{name="air", prob=254, param2=0},
		{name="air", prob=254, param2=0},
		{name="air", prob=254, param2=0},
		{name="air", prob=0, param2=0},
		{name="everness:forsaken_tundra_brick", prob=254, param2=0},
		{name="everness:forsaken_tundra_cobble", prob=254, param2=0},
		{name="everness:forsaken_tundra_brick", prob=254, param2=0},
		{name="everness:forsaken_tundra_cobble", prob=254, param2=0},
		{name="air", prob=254, param2=0},
		{name="air", prob=254, param2=0},
		{name="air", prob=254, param2=0},
		{name="air", prob=254, param2=0},
		{name="everness:forsaken_tundra_brick", prob=254, param2=0},
		{name="everness:forsaken_tundra_cobble", prob=254, param2=0},
		{name="everness:forsaken_tundra_brick", prob=254, param2=0},
		{name="everness:forsaken_tundra_brick", prob=254, param2=0},
		{name="air", prob=0, param2=0},
		{name="air", prob=0, param2=0},
		{name="air", prob=0, param2=0},
		{name="everness:forsaken_tundra_cobble", prob=254, param2=0},
		{name="everness:forsaken_tundra_cobble", prob=254, param2=0},
		{name="everness:forsaken_tundra_cobble", prob=254, param2=0},
		{name="everness:forsaken_tundra_brick", prob=254, param2=0},
		{name="everness:forsaken_tundra_brick", prob=254, param2=0},
		{name="everness:forsaken_tundra_cobble", prob=254, param2=0},
		{name="air", prob=0, param2=0},
		{name="air", prob=0, param2=0},
		{name="air", prob=0, param2=0},
		{name="air", prob=0, param2=0},
		{name="air", prob=0, param2=0},
		{name="air", prob=0, param2=0},
		{name="air", prob=0, param2=0},
		{name="everness:forsaken_tundra_cobble", prob=254, param2=0},
		{name="everness:forsaken_tundra_brick", prob=254, param2=0},
		{name="everness:forsaken_tundra_brick", prob=254, param2=0},
		{name="everness:forsaken_tundra_brick", prob=254, param2=0},
		{name="air", prob=0, param2=0},
		{name="air", prob=0, param2=0},
		{name="air", prob=0, param2=0},
		{name="air", prob=0, param2=0},
		{name="air", prob=0, param2=0},
		{name="air", prob=0, param2=0},
		{name="air", prob=0, param2=0},
		{name="air", prob=0, param2=0},
		{name="air", prob=0, param2=0},
		{name="air", prob=0, param2=0},
		{name="air", prob=0, param2=0},
		{name="air", prob=0, param2=0},
		{name="air", prob=0, param2=0},
		{name="air", prob=0, param2=0},
		{name="air", prob=0, param2=0},
		{name="air", prob=0, param2=0},
		{name="everness:forsaken_tundra_cobble", prob=254, param2=0},
		{name="everness:forsaken_tundra_brick", prob=254, param2=0},
		{name="everness:forsaken_tundra_cobble", prob=254, param2=0},
		{name="everness:forsaken_tundra_brick", prob=254, param2=0},
		{name="everness:forsaken_tundra_cobble", prob=254, param2=0},
		{name="everness:forsaken_tundra_brick", prob=254, param2=0},
		{name="everness:forsaken_tundra_brick", prob=254, param2=0},
		{name="everness:forsaken_tundra_brick", prob=254, param2=0},
		{name="everness:forsaken_tundra_cobble", prob=254, param2=0},
		{name="everness:forsaken_tundra_cobble", prob=254, param2=0},
		{name="everness:forsaken_tundra_brick", prob=254, param2=0},
		{name="everness:forsaken_tundra_cobble", prob=254, param2=0},
		{name="everness:forsaken_tundra_cobble", prob=254, param2=0},
		{name="everness:forsaken_tundra_cobble", prob=254, param2=0},
		{name="air", prob=254, param2=0},
		{name="air", prob=254, param2=0},
		{name="everness:forsaken_tundra_cobble", prob=254, param2=0},
		{name="everness:forsaken_tundra_cobble", prob=254, param2=0},
		{name="air", prob=254, param2=0},
		{name="everness:forsaken_tundra_brick", prob=254, param2=0},
		{name="air", prob=254, param2=0},
		{name="air", prob=254, param2=0},
		{name="air", prob=254, param2=0},
		{name="everness:forsaken_tundra_cobble", prob=254, param2=0},
		{name="everness:forsaken_tundra_cobble", prob=254, param2=0},
		{name="everness:forsaken_tundra_cobble", prob=254, param2=0},
		{name="everness:forsaken_tundra_cobble", prob=254, param2=0},
		{name="everness:forsaken_tundra_cobble", prob=254, param2=0},
		{name="everness:forsaken_tundra_brick", prob=254, param2=0},
		{name="everness:forsaken_tundra_brick", prob=254, param2=0},
		{name="everness:forsaken_tundra_cobble", prob=254, param2=0},
		{name="everness:forsaken_tundra_brick", prob=254, param2=0},
		{name="air", prob=254, param2=0},
		{name="air", prob=254, param2=0},
		{name="air", prob=254, param2=0},
		{name="everness:forsaken_tundra_cobble", prob=254, param2=0},
		{name="everness:forsaken_tundra_brick", prob=254, param2=0},
		{name="everness:forsaken_tundra_brick", prob=254, param2=0},
		{name="everness:forsaken_tundra_cobble", prob=254, param2=0},
		{name="everness:forsaken_tundra_brick", prob=254, param2=0},
		{name="everness:forsaken_tundra_cobble", prob=254, param2=0},
		{name="everness:forsaken_tundra_cobble", prob=254, param2=0},
		{name="everness:forsaken_tundra_cobble", prob=254, param2=0},
		{name="everness:forsaken_tundra_brick", prob=254, param2=0},
		{name="everness:forsaken_tundra_cobble", prob=254, param2=0},
		{name="everness:forsaken_tundra_brick", prob=254, param2=0},
		{name="everness:forsaken_tundra_brick", prob=254, param2=0},
		{name="everness:forsaken_tundra_brick", prob=254, param2=0},
		{name="everness:forsaken_tundra_cobble", prob=254, param2=0},
		{name="everness:forsaken_tundra_cobble", prob=254, param2=0},
		{name="everness:forsaken_tundra_brick", prob=254, param2=0},
		{name="everness:forsaken_tundra_cobble", prob=254, param2=0},
		{name="everness:forsaken_tundra_cobble", prob=254, param2=0},
		{name="stairs:stair_forsaken_tundra_cobble", prob=254, param2=2},
		{name="stairs:stair_forsaken_tundra_cobble", prob=254, param2=2},
		{name="everness:forsaken_tundra_cobble", prob=254, param2=0},
		{name="everness:forsaken_tundra_cobble", prob=254, param2=0},
		{name="everness:forsaken_tundra_brick", prob=254, param2=0},
		{name="everness:forsaken_tundra_cobble", prob=254, param2=0},
		{name="everness:forsaken_tundra_brick", prob=254, param2=0},
		{name="air", prob=0, param2=0},
		{name="air", prob=0, param2=0},
		{name="everness:forsaken_tundra_brick", prob=254, param2=0},
		{name="air", prob=254, param2=0},
		{name="air", prob=254, param2=0},
		{name="air", prob=254, param2=0},
		{name="air", prob=254, param2=0},
		{name="air", prob=254, param2=0},
		{name="air", prob=254, param2=0},
		{name="everness:forsaken_tundra_brick", prob=254, param2=0},
		{name="air", prob=0, param2=0},
		{name="air", prob=0, param2=0},
		{name="air", prob=0, param2=0},
		{name="air", prob=0, param2=0},
		{name="everness:forsaken_tundra_cobble", prob=254, param2=0},
		{name="air", prob=254, param2=0},
		{name="air", prob=254, param2=0},
		{name="air", prob=254, param2=0},
		{name="air", prob=254, param2=0},
		{name="air", prob=254, param2=0},
		{name="air", prob=254, param2=0},
		{name="everness:forsaken_tundra_brick", prob=254, param2=0},
		{name="air", prob=0, param2=0},
		{name="air", prob=0, param2=0},
		{name="air", prob=0, param2=0},
		{name="everness:forsaken_tundra_cobble", prob=254, param2=0},
		{name="everness:forsaken_tundra_brick", prob=254, param2=0},
		{name="everness:forsaken_tundra_brick", prob=254, param2=0},
		{name="air", prob=254, param2=0},
		{name="air", prob=254, param2=0},
		{name="air", prob=254, param2=0},
		{name="air", prob=254, param2=0},
		{name="everness:forsaken_tundra_brick", prob=254, param2=0},
		{name="everness:forsaken_tundra_cobble", prob=254, param2=0},
		{name="everness:forsaken_tundra_brick", prob=254, param2=0},
		{name="air", prob=0, param2=0},
		{name="everness:forsaken_tundra_brick", prob=254, param2=0},
		{name="everness:forsaken_tundra_brick", prob=254, param2=0},
		{name="air", prob=254, param2=0},
		{name="air", prob=254, param2=0},
		{name="air", prob=254, param2=0},
		{name="air", prob=254, param2=0},
		{name="air", prob=254, param2=0},
		{name="air", prob=254, param2=0},
		{name="air", prob=254, param2=0},
		{name="air", prob=254, param2=0},
		{name="everness:forsaken_tundra_brick", prob=254, param2=0},
		{name="everness:forsaken_tundra_cobble", prob=254, param2=0},
		{name="everness:forsaken_tundra_brick", prob=254, param2=0},
		{name="everness:forsaken_tundra_brick", prob=254, param2=0},
		{name="air", prob=254, param2=0},
		{name="air", prob=254, param2=0},
		{name="air", prob=254, param2=0},
		{name="air", prob=254, param2=0},
		{name="air", prob=254, param2=0},
		{name="air", prob=254, param2=0},
		{name="air", prob=254, param2=0},
		{name="air", prob=254, param2=0},
		{name="everness:forsaken_tundra_brick", prob=254, param2=0},
		{name="everness:forsaken_tundra_brick", prob=254, param2=0},
		{name="air", prob=0, param2=0},
		{name="everness:forsaken_tundra_cobble", prob=254, param2=0},
		{name="everness:forsaken_tundra_cobble", prob=254, param2=0},
		{name="everness:forsaken_tundra_cobble", prob=254, param2=0},
		{name="air", prob=254, param2=0},
		{name="air", prob=254, param2=0},
		{name="air", prob=254, param2=0},
		{name="air", prob=254, param2=0},
		{name="everness:forsaken_tundra_brick", prob=254, param2=0},
		{name="everness:forsaken_tundra_cobble", prob=254, param2=0},
		{name="everness:forsaken_tundra_brick", prob=254, param2=0},
		{name="air", prob=0, param2=0},
		{name="air", prob=0, param2=0},
		{name="air", prob=0, param2=0},
		{name="air", prob=0, param2=0},
		{name="everness:forsaken_tundra_cobble", prob=254, param2=0},
		{name="everness:forsaken_tundra_brick", prob=254, param2=0},
		{name="air", prob=254, param2=0},
		{name="air", prob=254, param2=0},
		{name="everness:forsaken_tundra_brick", prob=254, param2=0},
		{name="everness:forsaken_tundra_brick", prob=254, param2=0},
		{name="air", prob=0, param2=0},
		{name="air", prob=0, param2=0},
		{name="air", prob=0, param2=0},
		{name="air", prob=0, param2=0},
		{name="air", prob=0, param2=0},
		{name="air", prob=0, param2=0},
		{name="air", prob=0, param2=0},
		{name="everness:forsaken_tundra_brick", prob=254, param2=0},
		{name="everness:forsaken_tundra_cobble", prob=254, param2=0},
		{name="everness:forsaken_tundra_brick", prob=254, param2=0},
		{name="everness:forsaken_tundra_cobble", prob=254, param2=0},
		{name="air", prob=0, param2=0},
		{name="air", prob=0, param2=0},
		{name="air", prob=0, param2=0},
		{name="air", prob=0, param2=0},
		{name="air", prob=0, param2=0},
		{name="air", prob=0, param2=0},
		{name="air", prob=0, param2=0},
		{name="air", prob=0, param2=0},
		{name="air", prob=0, param2=0},
		{name="stairs:stair_forsaken_tundra_cobble", prob=254, param2=0},
		{name="stairs:stair_forsaken_tundra_cobble", prob=254, param2=0},
		{name="air", prob=0, param2=0},
		{name="air", prob=0, param2=0},
		{name="air", prob=0, param2=0},
		{name="air", prob=0, param2=0},
		{name="air", prob=0, param2=0},
		{name="everness:forsaken_tundra_cobble", prob=254, param2=0},
		{name="everness:forsaken_tundra_brick", prob=254, param2=0},
		{name="everness:forsaken_tundra_brick", prob=254, param2=0},
		{name="everness:forsaken_tundra_cobble", prob=254, param2=0},
		{name="everness:forsaken_tundra_cobble", prob=254, param2=0},
		{name="everness:forsaken_tundra_cobble", prob=254, param2=0},
		{name="everness:forsaken_tundra_brick", prob=254, param2=0},
		{name="everness:forsaken_tundra_cobble", prob=254, param2=0},
		{name="everness:forsaken_tundra_cobble", prob=254, param2=0},
		{name="everness:forsaken_tundra_brick", prob=254, param2=0},
		{name="everness:forsaken_tundra_brick", prob=254, param2=0},
		{name="everness:forsaken_tundra_brick", prob=254, param2=0},
		{name="everness:forsaken_tundra_cobble", prob=254, param2=0},
		{name="everness:forsaken_tundra_cobble", prob=254, param2=0},
		{name="everness:forsaken_tundra_cobble", prob=254, param2=0},
		{name="everness:forsaken_tundra_cobble", prob=254, param2=0},
		{name="everness:forsaken_tundra_brick", prob=254, param2=0},
		{name="everness:forsaken_tundra_cobble", prob=254, param2=0},
		{name="air", prob=254, param2=0},
		{name="everness:forsaken_tundra_cobble", prob=254, param2=0},
		{name="air", prob=254, param2=0},
		{name="air", prob=254, param2=0},
		{name="everness:forsaken_tundra_brick", prob=254, param2=0},
		{name="everness:forsaken_tundra_cobble", prob=254, param2=0},
		{name="everness:forsaken_tundra_brick", prob=254, param2=0},
		{name="everness:forsaken_tundra_brick", prob=254, param2=0},
		{name="everness:forsaken_tundra_brick", prob=254, param2=0},
		{name="everness:forsaken_tundra_cobble", prob=254, param2=0},
		{name="everness:forsaken_tundra_cobble", prob=254, param2=0},
		{name="everness:forsaken_tundra_cobble", prob=254, param2=0},
		{name="everness:forsaken_tundra_cobble", prob=254, param2=0},
		{name="everness:forsaken_tundra_cobble", prob=254, param2=0},
		{name="air", prob=254, param2=0},
		{name="air", prob=254, param2=0},
		{name="everness:forsaken_tundra_brick", prob=254, param2=0},
		{name="everness:forsaken_tundra_cobble", prob=254, param2=0},
		{name="everness:forsaken_tundra_cobble", prob=254, param2=0},
		{name="everness:forsaken_tundra_brick", prob=254, param2=0},
		{name="everness:forsaken_tundra_cobble", prob=254, param2=0},
		{name="everness:forsaken_tundra_cobble", prob=254, param2=0},
		{name="everness:forsaken_tundra_brick", prob=254, param2=0},
		{name="stairs:stair_forsaken_tundra_cobble", prob=254, param2=2},
		{name="stairs:stair_forsaken_tundra_cobble", prob=254, param2=2},
		{name="everness:forsaken_tundra_brick", prob=254, param2=0},
		{name="air", prob=254, param2=0},
		{name="air", prob=254, param2=0},
		{name="air", prob=254, param2=0},
		{name="everness:forsaken_tundra_brick", prob=254, param2=0},
		{name="everness:forsaken_tundra_brick", prob=254, param2=0},
		{name="everness:forsaken_tundra_brick", prob=254, param2=0},
		{name="everness:forsaken_tundra_cobble", prob=254, param2=0},
		{name="everness:forsaken_tundra_brick", prob=254, param2=0},
		{name="everness:forsaken_tundra_brick", prob=254, param2=0},
		{name="air", prob=254, param2=0},
		{name="air", prob=254, param2=0},
		{name="everness:forsaken_tundra_brick", prob=254, param2=0},
		{name="everness:forsaken_tundra_brick", prob=254, param2=0},
		{name="everness:forsaken_tundra_brick", prob=254, param2=0},
		{name="everness:forsaken_tundra_cobble", prob=254, param2=0},
		{name="everness:forsaken_tundra_cobble", prob=254, param2=0},
		{name="air", prob=0, param2=0},
		{name="air", prob=0, param2=0},
		{name="everness:forsaken_tundra_brick", prob=254, param2=0},
		{name="air", prob=254, param2=0},
		{name="air", prob=254, param2=0},
		{name="air", prob=254, param2=0},
		{name="air", prob=254, param2=0},
		{name="air", prob=254, param2=0},
		{name="air", prob=254, param2=0},
		{name="everness:forsaken_tundra_brick", prob=254, param2=0},
		{name="air", prob=0, param2=0},
		{name="air", prob=0, param2=0},
		{name="air", prob=0, param2=0},
		{name="air", prob=0, param2=0},
		{name="everness:forsaken_tundra_brick", prob=254, param2=0},
		{name="air", prob=254, param2=0},
		{name="air", prob=254, param2=0},
		{name="air", prob=254, param2=0},
		{name="air", prob=254, param2=0},
		{name="air", prob=254, param2=0},
		{name="air", prob=254, param2=0},
		{name="everness:forsaken_tundra_brick", prob=254, param2=0},
		{name="air", prob=0, param2=0},
		{name="air", prob=0, param2=0},
		{name="air", prob=0, param2=0},
		{name="everness:forsaken_tundra_cobble", prob=254, param2=0},
		{name="everness:forsaken_tundra_cobble", prob=254, param2=0},
		{name="everness:forsaken_tundra_cobble", prob=254, param2=0},
		{name="air", prob=254, param2=0},
		{name="air", prob=254, param2=0},
		{name="air", prob=254, param2=0},
		{name="air", prob=254, param2=0},
		{name="everness:forsaken_tundra_cobble", prob=254, param2=0},
		{name="everness:forsaken_tundra_cobble", prob=254, param2=0},
		{name="everness:forsaken_tundra_cobble", prob=254, param2=0},
		{name="air", prob=0, param2=0},
		{name="air", prob=0, param2=0},
		{name="everness:forsaken_tundra_brick", prob=254, param2=0},
		{name="air", prob=254, param2=0},
		{name="air", prob=254, param2=0},
		{name="air", prob=254, param2=0},
		{name="air", prob=254, param2=0},
		{name="air", prob=254, param2=0},
		{name="air", prob=254, param2=0},
		{name="air", prob=254, param2=0},
		{name="air", prob=254, param2=0},
		{name="everness:forsaken_tundra_brick", prob=254, param2=0},
		{name="air", prob=0, param2=0},
		{name="air", prob=0, param2=0},
		{name="everness:forsaken_tundra_brick", prob=254, param2=0},
		{name="air", prob=254, param2=0},
		{name="air", prob=254, param2=0},
		{name="air", prob=254, param2=0},
		{name="air", prob=254, param2=0},
		{name="air", prob=254, param2=0},
		{name="air", prob=254, param2=0},
		{name="air", prob=254, param2=0},
		{name="air", prob=254, param2=0},
		{name="everness:forsaken_tundra_brick", prob=254, param2=0},
		{name="air", prob=0, param2=0},
		{name="air", prob=0, param2=0},
		{name="everness:forsaken_tundra_brick", prob=254, param2=0},
		{name="everness:forsaken_tundra_cobble", prob=254, param2=0},
		{name="everness:forsaken_tundra_cobble", prob=254, param2=0},
		{name="air", prob=254, param2=0},
		{name="air", prob=254, param2=0},
		{name="air", prob=254, param2=0},
		{name="air", prob=254, param2=0},
		{name="everness:forsaken_tundra_brick", prob=254, param2=0},
		{name="everness:forsaken_tundra_brick", prob=254, param2=0},
		{name="everness:forsaken_tundra_cobble", prob=254, param2=0},
		{name="air", prob=0, param2=0},
		{name="air", prob=0, param2=0},
		{name="air", prob=0, param2=0},
		{name="air", prob=0, param2=0},
		{name="everness:forsaken_tundra_cobble", prob=254, param2=0},
		{name="everness:forsaken_tundra_brick", prob=254, param2=0},
		{name="air", prob=254, param2=0},
		{name="air", prob=254, param2=0},
		{name="everness:forsaken_tundra_brick", prob=254, param2=0},
		{name="everness:forsaken_tundra_brick", prob=254, param2=0},
		{name="air", prob=0, param2=0},
		{name="air", prob=0, param2=0},
		{name="air", prob=0, param2=0},
		{name="air", prob=0, param2=0},
		{name="air", prob=0, param2=0},
		{name="air", prob=0, param2=0},
		{name="air", prob=0, param2=0},
		{name="everness:forsaken_tundra_cobble", prob=254, param2=0},
		{name="everness:forsaken_tundra_cobble", prob=254, param2=0},
		{name="everness:forsaken_tundra_cobble", prob=254, param2=0},
		{name="everness:forsaken_tundra_brick", prob=254, param2=0},
		{name="air", prob=0, param2=0},
		{name="air", prob=0, param2=0},
		{name="air", prob=0, param2=0},
		{name="air", prob=0, param2=0},
		{name="air", prob=0, param2=0},
		{name="air", prob=0, param2=0},
		{name="air", prob=0, param2=0},
		{name="air", prob=0, param2=0},
		{name="air", prob=0, param2=0},
		{name="everness:forsaken_tundra_cobble", prob=254, param2=0},
		{name="everness:forsaken_tundra_brick", prob=254, param2=0},
		{name="air", prob=0, param2=0},
		{name="air", prob=0, param2=0},
		{name="air", prob=0, param2=0},
		{name="air", prob=0, param2=0},
		{name="air", prob=0, param2=0},
		{name="everness:forsaken_tundra_brick", prob=254, param2=0},
		{name="everness:forsaken_tundra_brick", prob=254, param2=0},
		{name="everness:forsaken_tundra_cobble", prob=254, param2=0},
		{name="everness:forsaken_tundra_brick", prob=254, param2=0},
		{name="everness:forsaken_tundra_cobble", prob=254, param2=0},
		{name="everness:forsaken_tundra_cobble", prob=254, param2=0},
		{name="everness:forsaken_tundra_cobble", prob=254, param2=0},
		{name="everness:forsaken_tundra_cobble", prob=254, param2=0},
		{name="everness:forsaken_tundra_brick", prob=254, param2=0},
		{name="everness:forsaken_tundra_cobble", prob=254, param2=0},
		{name="everness:forsaken_tundra_brick", prob=254, param2=0},
		{name="everness:forsaken_tundra_cobble", prob=254, param2=0},
		{name="everness:forsaken_tundra_brick", prob=254, param2=0},
		{name="everness:forsaken_tundra_brick", prob=254, param2=0},
		{name="air", prob=254, param2=0},
		{name="everness:forsaken_tundra_brick", prob=254, param2=0},
		{name="everness:forsaken_tundra_brick", prob=254, param2=0},
		{name="everness:forsaken_tundra_cobble", prob=254, param2=0},
		{name="everness:forsaken_tundra_cobble", prob=254, param2=0},
		{name="air", prob=254, param2=0},
		{name="air", prob=254, param2=0},
		{name="air", prob=254, param2=0},
		{name="air", prob=254, param2=0},
		{name="everness:forsaken_tundra_brick", prob=254, param2=0},
		{name="everness:forsaken_tundra_brick", prob=254, param2=0},
		{name="air", prob=254, param2=0},
		{name="air", prob=254, param2=0},
		{name="air", prob=254, param2=0},
		{name="everness:forsaken_tundra_cobble", prob=254, param2=0},
		{name="stairs:stair_forsaken_tundra_cobble", prob=254, param2=2},
		{name="stairs:stair_forsaken_tundra_cobble", prob=254, param2=2},
		{name="everness:forsaken_tundra_cobble", prob=254, param2=0},
		{name="air", prob=254, param2=0},
		{name="air", prob=254, param2=0},
		{name="air", prob=254, param2=0},
		{name="everness:forsaken_tundra_brick", prob=254, param2=0},
		{name="everness:forsaken_tundra_cobble", prob=254, param2=0},
		{name="air", prob=254, param2=0},
		{name="air", prob=254, param2=0},
		{name="air", prob=254, param2=0},
		{name="everness:forsaken_tundra_cobble", prob=254, param2=0},
		{name="air", prob=254, param2=0},
		{name="air", prob=254, param2=0},
		{name="everness:forsaken_tundra_brick", prob=254, param2=0},
		{name="everness:forsaken_tundra_cobble", prob=254, param2=0},
		{name="everness:forsaken_tundra_cobble", prob=254, param2=0},
		{name="everness:forsaken_tundra_brick", prob=254, param2=0},
		{name="everness:forsaken_tundra_cobble", prob=254, param2=0},
		{name="everness:forsaken_tundra_brick", prob=254, param2=0},
		{name="everness:forsaken_tundra_brick", prob=254, param2=0},
		{name="everness:forsaken_tundra_brick", prob=254, param2=0},
		{name="everness:forsaken_tundra_cobble", prob=254, param2=0},
		{name="everness:forsaken_tundra_cobble", prob=254, param2=0},
		{name="air", prob=254, param2=0},
		{name="air", prob=254, param2=0},
		{name="everness:forsaken_tundra_cobble", prob=254, param2=0},
		{name="everness:forsaken_tundra_brick", prob=254, param2=0},
		{name="everness:forsaken_tundra_brick", prob=254, param2=0},
		{name="everness:forsaken_tundra_brick", prob=254, param2=0},
		{name="everness:forsaken_tundra_cobble", prob=254, param2=0},
		{name="air", prob=0, param2=0},
		{name="air", prob=0, param2=0},
		{name="everness:forsaken_tundra_brick", prob=254, param2=0},
		{name="air", prob=254, param2=0},
		{name="stairs:stair_forsaken_tundra_cobble", prob=254, param2=0},
		{name="air", prob=254, param2=0},
		{name="air", prob=254, param2=0},
		{name="stairs:stair_forsaken_tundra_cobble", prob=254, param2=0},
		{name="air", prob=254, param2=0},
		{name="everness:forsaken_tundra_brick", prob=254, param2=0},
		{name="air", prob=0, param2=0},
		{name="air", prob=0, param2=0},
		{name="air", prob=0, param2=0},
		{name="air", prob=0, param2=0},
		{name="everness:forsaken_tundra_cobble", prob=254, param2=0},
		{name="air", prob=254, param2=0},
		{name="air", prob=254, param2=0},
		{name="air", prob=254, param2=0},
		{name="air", prob=254, param2=0},
		{name="air", prob=254, param2=0},
		{name="air", prob=254, param2=0},
		{name="everness:forsaken_tundra_brick", prob=254, param2=0},
		{name="air", prob=0, param2=0},
		{name="air", prob=0, param2=0},
		{name="air", prob=0, param2=0},
		{name="everness:forsaken_tundra_brick", prob=254, param2=0},
		{name="everness:forsaken_tundra_brick", prob=254, param2=0},
		{name="everness:forsaken_tundra_cobble", prob=254, param2=0},
		{name="air", prob=254, param2=0},
		{name="air", prob=254, param2=0},
		{name="air", prob=254, param2=0},
		{name="air", prob=254, param2=0},
		{name="everness:forsaken_tundra_brick", prob=254, param2=0},
		{name="everness:forsaken_tundra_cobble", prob=254, param2=0},
		{name="everness:forsaken_tundra_cobble", prob=254, param2=0},
		{name="air", prob=0, param2=0},
		{name="everness:forsaken_tundra_cobble", prob=254, param2=0},
		{name="everness:forsaken_tundra_brick", prob=254, param2=0},
		{name="air", prob=254, param2=0},
		{name="air", prob=254, param2=0},
		{name="air", prob=254, param2=0},
		{name="air", prob=254, param2=0},
		{name="air", prob=254, param2=0},
		{name="air", prob=254, param2=0},
		{name="air", prob=254, param2=0},
		{name="air", prob=254, param2=0},
		{name="everness:forsaken_tundra_brick", prob=254, param2=0},
		{name="everness:forsaken_tundra_brick", prob=254, param2=0},
		{name="everness:forsaken_tundra_brick", prob=254, param2=0},
		{name="everness:forsaken_tundra_brick", prob=254, param2=0},
		{name="air", prob=254, param2=0},
		{name="air", prob=254, param2=0},
		{name="air", prob=254, param2=0},
		{name="air", prob=254, param2=0},
		{name="air", prob=254, param2=0},
		{name="air", prob=254, param2=0},
		{name="air", prob=254, param2=0},
		{name="air", prob=254, param2=0},
		{name="everness:forsaken_tundra_cobble", prob=254, param2=0},
		{name="everness:forsaken_tundra_brick", prob=254, param2=0},
		{name="air", prob=0, param2=0},
		{name="everness:forsaken_tundra_brick", prob=254, param2=0},
		{name="everness:forsaken_tundra_cobble", prob=254, param2=0},
		{name="everness:forsaken_tundra_cobble", prob=254, param2=0},
		{name="air", prob=254, param2=0},
		{name="air", prob=254, param2=0},
		{name="air", prob=254, param2=0},
		{name="air", prob=254, param2=0},
		{name="everness:forsaken_tundra_brick", prob=254, param2=0},
		{name="everness:forsaken_tundra_brick", prob=254, param2=0},
		{name="everness:forsaken_tundra_brick", prob=254, param2=0},
		{name="air", prob=0, param2=0},
		{name="air", prob=0, param2=0},
		{name="air", prob=0, param2=0},
		{name="air", prob=0, param2=0},
		{name="everness:forsaken_tundra_cobble", prob=254, param2=0},
		{name="everness:forsaken_tundra_brick", prob=254, param2=0},
		{name="air", prob=254, param2=0},
		{name="air", prob=254, param2=0},
		{name="everness:forsaken_tundra_cobble", prob=254, param2=0},
		{name="everness:forsaken_tundra_brick", prob=254, param2=0},
		{name="air", prob=0, param2=0},
		{name="air", prob=0, param2=0},
		{name="air", prob=0, param2=0},
		{name="air", prob=0, param2=0},
		{name="air", prob=0, param2=0},
		{name="air", prob=0, param2=0},
		{name="air", prob=0, param2=0},
		{name="everness:forsaken_tundra_cobble", prob=254, param2=0},
		{name="everness:forsaken_tundra_cobble", prob=254, param2=0},
		{name="everness:forsaken_tundra_brick", prob=254, param2=0},
		{name="everness:forsaken_tundra_brick", prob=254, param2=0},
		{name="air", prob=0, param2=0},
		{name="air", prob=0, param2=0},
		{name="air", prob=0, param2=0},
		{name="air", prob=0, param2=0},
		{name="air", prob=0, param2=0},
		{name="air", prob=0, param2=0},
		{name="air", prob=0, param2=0},
		{name="air", prob=0, param2=0},
		{name="air", prob=0, param2=0},
		{name="stairs:stair_forsaken_tundra_cobble", prob=254, param2=2},
		{name="stairs:stair_forsaken_tundra_cobble", prob=254, param2=2},
		{name="air", prob=0, param2=0},
		{name="air", prob=0, param2=0},
		{name="air", prob=0, param2=0},
		{name="air", prob=0, param2=0},
		{name="air", prob=0, param2=0},
		{name="everness:forsaken_tundra_brick", prob=254, param2=0},
		{name="everness:forsaken_tundra_cobble", prob=254, param2=0},
		{name="everness:forsaken_tundra_brick", prob=254, param2=0},
		{name="everness:forsaken_tundra_brick", prob=254, param2=0},
		{name="everness:forsaken_tundra_brick", prob=254, param2=0},
		{name="everness:forsaken_tundra_cobble", prob=254, param2=0},
		{name="everness:forsaken_tundra_brick", prob=254, param2=0},
		{name="everness:forsaken_tundra_cobble", prob=254, param2=0},
		{name="everness:forsaken_tundra_brick", prob=254, param2=0},
		{name="everness:forsaken_tundra_brick", prob=254, param2=0},
		{name="everness:forsaken_tundra_cobble", prob=254, param2=0},
		{name="everness:forsaken_tundra_cobble", prob=254, param2=0},
		{name="everness:forsaken_tundra_brick", prob=254, param2=0},
		{name="everness:forsaken_tundra_brick", prob=254, param2=0},
		{name="air", prob=254, param2=0},
		{name="everness:forsaken_tundra_cobble", prob=254, param2=0},
		{name="everness:forsaken_tundra_cobble", prob=254, param2=0},
		{name="stairs:stair_forsaken_tundra_cobble", prob=254, param2=2},
		{name="stairs:stair_forsaken_tundra_cobble", prob=254, param2=2},
		{name="everness:forsaken_tundra_cobble", prob=254, param2=0},
		{name="air", prob=254, param2=0},
		{name="air", prob=254, param2=0},
		{name="everness:forsaken_tundra_brick", prob=254, param2=0},
		{name="everness:forsaken_tundra_brick", prob=254, param2=0},
		{name="everness:forsaken_tundra_brick", prob=254, param2=0},
		{name="everness:forsaken_tundra_cobble", prob=254, param2=0},
		{name="air", prob=254, param2=0},
		{name="air", prob=254, param2=0},
		{name="everness:forsaken_tundra_brick", prob=254, param2=0},
		{name="air", prob=254, param2=0},
		{name="air", prob=254, param2=0},
		{name="everness:forsaken_tundra_brick", prob=254, param2=0},
		{name="air", prob=254, param2=0},
		{name="air", prob=254, param2=0},
		{name="everness:forsaken_tundra_brick", prob=254, param2=0},
		{name="everness:forsaken_tundra_brick", prob=254, param2=0},
		{name="everness:forsaken_tundra_cobble", prob=254, param2=0},
		{name="air", prob=254, param2=0},
		{name="air", prob=254, param2=0},
		{name="air", prob=254, param2=0},
		{name="everness:forsaken_tundra_cobble", prob=254, param2=0},
		{name="air", prob=254, param2=0},
		{name="air", prob=254, param2=0},
		{name="everness:forsaken_tundra_cobble", prob=254, param2=0},
		{name="air", prob=254, param2=0},
		{name="air", prob=254, param2=0},
		{name="air", prob=254, param2=0},
		{name="everness:forsaken_tundra_brick", prob=254, param2=0},
		{name="everness:forsaken_tundra_cobble", prob=254, param2=0},
		{name="everness:forsaken_tundra_brick", prob=254, param2=0},
		{name="everness:forsaken_tundra_cobble", prob=254, param2=0},
		{name="everness:forsaken_tundra_cobble", prob=254, param2=0},
		{name="everness:forsaken_tundra_brick", prob=254, param2=0},
		{name="air", prob=254, param2=0},
		{name="air", prob=254, param2=0},
		{name="everness:forsaken_tundra_cobble", prob=254, param2=0},
		{name="everness:forsaken_tundra_brick", prob=254, param2=0},
		{name="everness:forsaken_tundra_brick", prob=254, param2=0},
		{name="everness:forsaken_tundra_brick", prob=254, param2=0},
		{name="everness:forsaken_tundra_brick", prob=254, param2=0},
		{name="air", prob=0, param2=0},
		{name="air", prob=0, param2=0},
		{name="everness:forsaken_tundra_cobble", prob=254, param2=0},
		{name="air", prob=254, param2=0},
		{name="everness:forsaken_tundra_brick", prob=254, param2=0},
		{name="air", prob=254, param2=0},
		{name="air", prob=254, param2=0},
		{name="everness:forsaken_tundra_brick", prob=254, param2=0},
		{name="air", prob=254, param2=0},
		{name="everness:forsaken_tundra_brick", prob=254, param2=0},
		{name="air", prob=0, param2=0},
		{name="air", prob=0, param2=0},
		{name="air", prob=0, param2=0},
		{name="air", prob=0, param2=0},
		{name="everness:forsaken_tundra_brick", prob=254, param2=0},
		{name="air", prob=254, param2=0},
		{name="stairs:stair_forsaken_tundra_cobble", prob=254, param2=0},
		{name="air", prob=254, param2=0},
		{name="air", prob=254, param2=0},
		{name="stairs:stair_forsaken_tundra_cobble", prob=254, param2=0},
		{name="air", prob=254, param2=0},
		{name="everness:forsaken_tundra_cobble", prob=254, param2=0},
		{name="air", prob=0, param2=0},
		{name="air", prob=0, param2=0},
		{name="air", prob=0, param2=0},
		{name="everness:forsaken_tundra_brick", prob=254, param2=0},
		{name="everness:forsaken_tundra_brick", prob=254, param2=0},
		{name="everness:forsaken_tundra_cobble", prob=254, param2=0},
		{name="air", prob=254, param2=0},
		{name="air", prob=254, param2=0},
		{name="air", prob=254, param2=0},
		{name="air", prob=254, param2=0},
		{name="everness:forsaken_tundra_brick", prob=254, param2=0},
		{name="everness:forsaken_tundra_brick", prob=254, param2=0},
		{name="everness:forsaken_tundra_cobble", prob=254, param2=0},
		{name="air", prob=0, param2=0},
		{name="air", prob=0, param2=0},
		{name="everness:forsaken_tundra_cobble", prob=254, param2=0},
		{name="air", prob=254, param2=0},
		{name="air", prob=254, param2=0},
		{name="air", prob=254, param2=0},
		{name="air", prob=254, param2=0},
		{name="air", prob=254, param2=0},
		{name="air", prob=254, param2=0},
		{name="air", prob=254, param2=0},
		{name="air", prob=254, param2=0},
		{name="everness:forsaken_tundra_cobble", prob=254, param2=0},
		{name="air", prob=0, param2=0},
		{name="air", prob=0, param2=0},
		{name="air", prob=254, param2=0},
		{name="air", prob=254, param2=0},
		{name="air", prob=254, param2=0},
		{name="air", prob=254, param2=0},
		{name="air", prob=254, param2=0},
		{name="air", prob=254, param2=0},
		{name="air", prob=254, param2=0},
		{name="air", prob=254, param2=0},
		{name="air", prob=254, param2=0},
		{name="air", prob=254, param2=0},
		{name="air", prob=0, param2=0},
		{name="everness:forsaken_tundra_brick", prob=254, param2=0},
		{name="everness:forsaken_tundra_cobble", prob=254, param2=0},
		{name="everness:forsaken_tundra_cobble", prob=254, param2=0},
		{name="everness:forsaken_tundra_cobble", prob=254, param2=0},
		{name="air", prob=254, param2=0},
		{name="air", prob=254, param2=0},
		{name="air", prob=254, param2=0},
		{name="air", prob=254, param2=0},
		{name="everness:forsaken_tundra_cobble", prob=254, param2=0},
		{name="everness:forsaken_tundra_cobble", prob=254, param2=0},
		{name="everness:forsaken_tundra_brick", prob=254, param2=0},
		{name="everness:forsaken_tundra_brick", prob=254, param2=0},
		{name="air", prob=0, param2=0},
		{name="air", prob=0, param2=0},
		{name="air", prob=0, param2=0},
		{name="everness:forsaken_tundra_cobble", prob=254, param2=0},
		{name="everness:forsaken_tundra_cobble", prob=254, param2=0},
		{name="everness:forsaken_tundra_cobble", prob=254, param2=0},
		{name="everness:forsaken_tundra_cobble", prob=254, param2=0},
		{name="everness:forsaken_tundra_brick", prob=254, param2=0},
		{name="everness:forsaken_tundra_cobble", prob=254, param2=0},
		{name="air", prob=0, param2=0},
		{name="air", prob=0, param2=0},
		{name="air", prob=0, param2=0},
		{name="air", prob=0, param2=0},
		{name="air", prob=0, param2=0},
		{name="air", prob=0, param2=0},
		{name="air", prob=0, param2=0},
		{name="everness:forsaken_tundra_brick", prob=254, param2=0},
		{name="everness:forsaken_tundra_brick", prob=254, param2=0},
		{name="everness:forsaken_tundra_cobble", prob=254, param2=0},
		{name="everness:forsaken_tundra_brick", prob=254, param2=0},
		{name="air", prob=0, param2=0},
		{name="air", prob=0, param2=0},
		{name="air", prob=0, param2=0},
		{name="air", prob=0, param2=0},
		{name="air", prob=0, param2=0},
		{name="air", prob=0, param2=0},
		{name="air", prob=0, param2=0},
		{name="air", prob=0, param2=0},
		{name="air", prob=0, param2=0},
		{name="air", prob=0, param2=0},
		{name="air", prob=0, param2=0},
		{name="air", prob=0, param2=0},
		{name="air", prob=0, param2=0},
		{name="air", prob=0, param2=0},
		{name="air", prob=0, param2=0},
		{name="air", prob=0, param2=0},
		{name="everness:forsaken_tundra_cobble", prob=254, param2=0},
		{name="everness:forsaken_tundra_cobble", prob=254, param2=0},
		{name="everness:forsaken_tundra_brick", prob=254, param2=0},
		{name="everness:forsaken_tundra_brick", prob=254, param2=0},
		{name="everness:forsaken_tundra_brick", prob=254, param2=0},
		{name="everness:forsaken_tundra_brick", prob=254, param2=0},
		{name="everness:forsaken_tundra_cobble", prob=254, param2=0},
		{name="everness:forsaken_tundra_brick", prob=254, param2=0},
		{name="everness:forsaken_tundra_cobble", prob=254, param2=0},
		{name="everness:forsaken_tundra_cobble", prob=254, param2=0},
		{name="everness:forsaken_tundra_brick", prob=254, param2=0},
		{name="everness:forsaken_tundra_cobble", prob=254, param2=0},
		{name="everness:forsaken_tundra_brick", prob=254, param2=0},
		{name="everness:forsaken_tundra_cobble", prob=254, param2=0},
		{name="everness:chest", prob=254, param2=0},
		{name="everness:forsaken_tundra_brick", prob=254, param2=0},
		{name="everness:forsaken_tundra_cobble", prob=254, param2=0},
		{name="air", prob=254, param2=0},
		{name="air", prob=254, param2=0},
		{name="everness:forsaken_tundra_brick", prob=254, param2=0},
		{name="air", prob=254, param2=0},
		{name="air", prob=254, param2=0},
		{name="air", prob=254, param2=0},
		{name="everness:forsaken_tundra_cobble", prob=254, param2=0},
		{name="everness:forsaken_tundra_cobble", prob=254, param2=0},
		{name="air", prob=254, param2=0},
		{name="air", prob=254, param2=0},
		{name="air", prob=254, param2=0},
		{name="everness:forsaken_tundra_brick", prob=254, param2=0},
		{name="air", prob=254, param2=0},
		{name="air", prob=254, param2=0},
		{name="everness:forsaken_tundra_brick", prob=254, param2=0},
		{name="air", prob=254, param2=0},
		{name="air", prob=254, param2=0},
		{name="air", prob=254, param2=0},
		{name="everness:forsaken_tundra_cobble", prob=254, param2=0},
		{name="everness:forsaken_tundra_brick", prob=254, param2=0},
		{name="air", prob=254, param2=0},
		{name="air", prob=254, param2=0},
		{name="air", prob=254, param2=0},
		{name="everness:forsaken_tundra_cobble", prob=254, param2=0},
		{name="air", prob=254, param2=0},
		{name="air", prob=254, param2=0},
		{name="everness:forsaken_tundra_brick", prob=254, param2=0},
		{name="everness:forsaken_tundra_cobble", prob=254, param2=0},
		{name="everness:forsaken_tundra_brick", prob=254, param2=0},
		{name="everness:forsaken_tundra_brick", prob=254, param2=0},
		{name="everness:forsaken_tundra_cobble", prob=254, param2=0},
		{name="everness:forsaken_tundra_brick", prob=254, param2=0},
		{name="everness:forsaken_tundra_cobble", prob=254, param2=0},
		{name="everness:forsaken_tundra_brick", prob=254, param2=0},
		{name="everness:forsaken_tundra_brick", prob=254, param2=0},
		{name="everness:forsaken_tundra_brick", prob=254, param2=0},
		{name="everness:forsaken_tundra_cobble", prob=254, param2=0},
		{name="everness:forsaken_tundra_brick", prob=254, param2=0},
		{name="everness:forsaken_tundra_brick", prob=254, param2=0},
		{name="everness:forsaken_tundra_brick", prob=254, param2=0},
		{name="everness:forsaken_tundra_brick", prob=254, param2=0},
		{name="everness:forsaken_tundra_cobble", prob=254, param2=0},
		{name="everness:forsaken_tundra_brick", prob=254, param2=0},
		{name="air", prob=0, param2=0},
		{name="air", prob=0, param2=0},
		{name="everness:forsaken_tundra_cobble", prob=254, param2=0},
		{name="air", prob=254, param2=0},
		{name="everness:forsaken_tundra_brick", prob=254, param2=0},
		{name="everness:forsaken_tundra_brick", prob=254, param2=0},
		{name="everness:forsaken_tundra_cobble", prob=254, param2=0},
		{name="everness:forsaken_tundra_cobble", prob=254, param2=0},
		{name="air", prob=254, param2=0},
		{name="everness:forsaken_tundra_brick", prob=254, param2=0},
		{name="air", prob=0, param2=0},
		{name="air", prob=0, param2=0},
		{name="air", prob=0, param2=0},
		{name="air", prob=0, param2=0},
		{name="everness:forsaken_tundra_brick", prob=254, param2=0},
		{name="air", prob=254, param2=0},
		{name="everness:forsaken_tundra_brick", prob=254, param2=0},
		{name="everness:forsaken_tundra_brick", prob=254, param2=0},
		{name="everness:forsaken_tundra_cobble", prob=254, param2=0},
		{name="everness:forsaken_tundra_cobble", prob=254, param2=0},
		{name="air", prob=254, param2=0},
		{name="everness:forsaken_tundra_cobble", prob=254, param2=0},
		{name="air", prob=0, param2=0},
		{name="air", prob=0, param2=0},
		{name="air", prob=0, param2=0},
		{name="everness:forsaken_tundra_brick", prob=254, param2=0},
		{name="everness:forsaken_tundra_cobble", prob=254, param2=0},
		{name="everness:forsaken_tundra_brick", prob=254, param2=0},
		{name="stairs:stair_forsaken_tundra_cobble", prob=254, param2=0},
		{name="everness:forsaken_tundra_cobble", prob=254, param2=0},
		{name="everness:forsaken_tundra_brick", prob=254, param2=0},
		{name="stairs:stair_forsaken_tundra_cobble", prob=254, param2=0},
		{name="everness:forsaken_tundra_brick", prob=254, param2=0},
		{name="everness:forsaken_tundra_brick", prob=254, param2=0},
		{name="everness:forsaken_tundra_brick", prob=254, param2=0},
		{name="air", prob=0, param2=0},
		{name="everness:forsaken_tundra_brick", prob=254, param2=0},
		{name="everness:forsaken_tundra_brick", prob=254, param2=0},
		{name="air", prob=254, param2=0},
		{name="air", prob=254, param2=0},
		{name="air", prob=254, param2=0},
		{name="air", prob=254, param2=0},
		{name="air", prob=254, param2=0},
		{name="air", prob=254, param2=0},
		{name="air", prob=254, param2=0},
		{name="air", prob=254, param2=0},
		{name="everness:forsaken_tundra_cobble", prob=254, param2=0},
		{name="everness:forsaken_tundra_brick", prob=254, param2=0},
		{name="everness:forsaken_tundra_cobble", prob=254, param2=0},
		{name="everness:forsaken_tundra_brick", prob=254, param2=0},
		{name="air", prob=254, param2=0},
		{name="air", prob=254, param2=0},
		{name="air", prob=254, param2=0},
		{name="air", prob=254, param2=0},
		{name="air", prob=254, param2=0},
		{name="air", prob=254, param2=0},
		{name="air", prob=254, param2=0},
		{name="air", prob=254, param2=0},
		{name="everness:forsaken_tundra_brick", prob=254, param2=0},
		{name="everness:forsaken_tundra_brick", prob=254, param2=0},
		{name="air", prob=0, param2=0},
		{name="everness:forsaken_tundra_brick", prob=254, param2=0},
		{name="everness:forsaken_tundra_brick", prob=254, param2=0},
		{name="everness:forsaken_tundra_brick", prob=254, param2=0},
		{name="everness:forsaken_tundra_cobble", prob=254, param2=0},
		{name="everness:forsaken_tundra_brick", prob=254, param2=0},
		{name="everness:forsaken_tundra_brick", prob=254, param2=0},
		{name="everness:forsaken_tundra_brick", prob=254, param2=0},
		{name="everness:forsaken_tundra_cobble", prob=254, param2=0},
		{name="everness:forsaken_tundra_cobble", prob=254, param2=0},
		{name="everness:forsaken_tundra_cobble", prob=254, param2=0},
		{name="air", prob=0, param2=0},
		{name="air", prob=0, param2=0},
		{name="air", prob=0, param2=0},
		{name="air", prob=0, param2=0},
		{name="everness:forsaken_tundra_brick", prob=254, param2=0},
		{name="everness:forsaken_tundra_cobble", prob=254, param2=0},
		{name="everness:forsaken_tundra_brick", prob=254, param2=0},
		{name="everness:forsaken_tundra_brick", prob=254, param2=0},
		{name="everness:forsaken_tundra_brick", prob=254, param2=0},
		{name="everness:forsaken_tundra_cobble", prob=254, param2=0},
		{name="air", prob=0, param2=0},
		{name="air", prob=0, param2=0},
		{name="air", prob=0, param2=0},
		{name="air", prob=0, param2=0},
		{name="air", prob=0, param2=0},
		{name="air", prob=0, param2=0},
		{name="air", prob=0, param2=0},
		{name="everness:forsaken_tundra_brick", prob=254, param2=0},
		{name="everness:forsaken_tundra_cobble", prob=254, param2=0},
		{name="everness:forsaken_tundra_cobble", prob=254, param2=0},
		{name="everness:forsaken_tundra_cobble", prob=254, param2=0},
		{name="air", prob=0, param2=0},
		{name="air", prob=0, param2=0},
		{name="air", prob=0, param2=0},
		{name="air", prob=0, param2=0},
		{name="air", prob=0, param2=0},
		{name="air", prob=0, param2=0},
		{name="air", prob=0, param2=0},
		{name="air", prob=0, param2=0},
		{name="air", prob=0, param2=0},
		{name="air", prob=0, param2=0},
		{name="air", prob=0, param2=0},
		{name="air", prob=0, param2=0},
		{name="air", prob=0, param2=0},
		{name="air", prob=0, param2=0},
		{name="air", prob=0, param2=0},
		{name="air", prob=0, param2=0},
		{name="everness:forsaken_tundra_brick", prob=254, param2=0},
		{name="everness:forsaken_tundra_cobble", prob=254, param2=0},
		{name="everness:forsaken_tundra_brick", prob=254, param2=0},
		{name="everness:forsaken_tundra_cobble", prob=254, param2=0},
		{name="everness:forsaken_tundra_brick", prob=254, param2=0},
		{name="everness:forsaken_tundra_cobble", prob=254, param2=0},
		{name="everness:forsaken_tundra_brick", prob=254, param2=0},
		{name="everness:forsaken_tundra_brick", prob=254, param2=0},
		{name="everness:forsaken_tundra_cobble", prob=254, param2=0},
		{name="everness:forsaken_tundra_brick", prob=254, param2=0},
		{name="everness:forsaken_tundra_cobble", prob=254, param2=0},
		{name="everness:forsaken_tundra_brick", prob=254, param2=0},
		{name="everness:forsaken_tundra_brick", prob=254, param2=0},
		{name="everness:forsaken_tundra_brick", prob=254, param2=0},
		{name="everness:forsaken_tundra_cobble", prob=254, param2=0},
		{name="everness:forsaken_tundra_brick", prob=254, param2=0},
		{name="everness:forsaken_tundra_brick", prob=254, param2=0},
		{name="air", prob=254, param2=0},
		{name="air", prob=254, param2=0},
		{name="everness:forsaken_tundra_cobble", prob=254, param2=0},
		{name="air", prob=254, param2=0},
		{name="air", prob=254, param2=0},
		{name="everness:forsaken_tundra_brick", prob=254, param2=0},
		{name="everness:forsaken_tundra_cobble", prob=254, param2=0},
		{name="everness:forsaken_tundra_brick", prob=254, param2=0},
		{name="everness:forsaken_tundra_brick", prob=254, param2=0},
		{name="everness:forsaken_tundra_cobble", prob=254, param2=0},
		{name="everness:forsaken_tundra_brick", prob=254, param2=0},
		{name="everness:forsaken_tundra_cobble", prob=254, param2=0},
		{name="air", prob=254, param2=0},
		{name="air", prob=254, param2=0},
		{name="everness:forsaken_tundra_cobble", prob=254, param2=0},
		{name="air", prob=254, param2=0},
		{name="air", prob=254, param2=0},
		{name="everness:forsaken_tundra_brick", prob=254, param2=0},
		{name="everness:forsaken_tundra_cobble", prob=254, param2=0},
		{name="everness:forsaken_tundra_brick", prob=254, param2=0},
		{name="everness:forsaken_tundra_brick", prob=254, param2=0},
		{name="everness:forsaken_tundra_brick", prob=254, param2=0},
		{name="everness:forsaken_tundra_brick", prob=254, param2=0},
		{name="everness:forsaken_tundra_brick", prob=254, param2=0},
		{name="everness:forsaken_tundra_cobble", prob=254, param2=0},
		{name="everness:forsaken_tundra_cobble", prob=254, param2=0},
		{name="everness:forsaken_tundra_brick", prob=254, param2=0},
		{name="air", prob=254, param2=0},
		{name="air", prob=254, param2=0},
		{name="air", prob=254, param2=0},
		{name="everness:forsaken_tundra_cobble", prob=254, param2=0},
		{name="everness:forsaken_tundra_brick", prob=254, param2=0},
		{name="everness:forsaken_tundra_cobble", prob=254, param2=0},
		{name="everness:forsaken_tundra_cobble", prob=254, param2=0},
		{name="everness:forsaken_tundra_brick", prob=254, param2=0},
		{name="everness:forsaken_tundra_cobble", prob=254, param2=0},
		{name="everness:forsaken_tundra_cobble", prob=254, param2=0},
		{name="everness:forsaken_tundra_brick", prob=254, param2=0},
		{name="everness:forsaken_tundra_brick", prob=254, param2=0},
		{name="everness:forsaken_tundra_cobble", prob=254, param2=0},
		{name="everness:forsaken_tundra_brick", prob=254, param2=0},
		{name="everness:forsaken_tundra_cobble", prob=254, param2=0},
		{name="everness:forsaken_tundra_cobble", prob=254, param2=0},
		{name="air", prob=0, param2=0},
		{name="air", prob=0, param2=0},
		{name="everness:forsaken_tundra_brick", prob=254, param2=0},
		{name="air", prob=254, param2=0},
		{name="air", prob=254, param2=0},
		{name="air", prob=254, param2=0},
		{name="air", prob=254, param2=0},
		{name="air", prob=254, param2=0},
		{name="air", prob=254, param2=0},
		{name="everness:forsaken_tundra_brick", prob=254, param2=0},
		{name="air", prob=0, param2=0},
		{name="air", prob=0, param2=0},
		{name="air", prob=0, param2=0},
		{name="air", prob=0, param2=0},
		{name="everness:forsaken_tundra_brick", prob=254, param2=0},
		{name="air", prob=254, param2=0},
		{name="air", prob=254, param2=0},
		{name="air", prob=254, param2=0},
		{name="air", prob=254, param2=0},
		{name="air", prob=254, param2=0},
		{name="air", prob=254, param2=0},
		{name="everness:forsaken_tundra_cobble", prob=254, param2=0},
		{name="air", prob=0, param2=0},
		{name="air", prob=0, param2=0},
		{name="air", prob=0, param2=0},
		{name="everness:forsaken_tundra_brick", prob=254, param2=0},
		{name="everness:forsaken_tundra_brick", prob=254, param2=0},
		{name="everness:forsaken_tundra_cobble", prob=254, param2=0},
		{name="everness:forsaken_tundra_brick", prob=254, param2=0},
		{name="everness:forsaken_tundra_cobble", prob=254, param2=0},
		{name="everness:forsaken_tundra_cobble", prob=254, param2=0},
		{name="everness:forsaken_tundra_brick", prob=254, param2=0},
		{name="everness:forsaken_tundra_cobble", prob=254, param2=0},
		{name="everness:forsaken_tundra_cobble", prob=254, param2=0},
		{name="everness:forsaken_tundra_cobble", prob=254, param2=0},
		{name="air", prob=0, param2=0},
		{name="air", prob=0, param2=0},
		{name="everness:forsaken_tundra_brick", prob=254, param2=0},
		{name="air", prob=254, param2=0},
		{name="air", prob=254, param2=0},
		{name="air", prob=254, param2=0},
		{name="air", prob=254, param2=0},
		{name="air", prob=254, param2=0},
		{name="air", prob=254, param2=0},
		{name="air", prob=254, param2=0},
		{name="air", prob=254, param2=0},
		{name="everness:forsaken_tundra_brick", prob=254, param2=0},
		{name="air", prob=0, param2=0},
		{name="air", prob=0, param2=0},
		{name="everness:forsaken_tundra_cobble", prob=254, param2=0},
		{name="air", prob=254, param2=0},
		{name="air", prob=254, param2=0},
		{name="air", prob=254, param2=0},
		{name="air", prob=254, param2=0},
		{name="air", prob=254, param2=0},
		{name="air", prob=254, param2=0},
		{name="air", prob=254, param2=0},
		{name="air", prob=254, param2=0},
		{name="everness:forsaken_tundra_cobble", prob=254, param2=0},
		{name="air", prob=0, param2=0},
		{name="air", prob=0, param2=0},
		{name="everness:forsaken_tundra_cobble", prob=254, param2=0},
		{name="everness:forsaken_tundra_cobble", prob=254, param2=0},
		{name="everness:forsaken_tundra_cobble", prob=254, param2=0},
		{name="everness:forsaken_tundra_cobble", prob=254, param2=0},
		{name="everness:forsaken_tundra_brick", prob=254, param2=0},
		{name="everness:forsaken_tundra_brick", prob=254, param2=0},
		{name="everness:forsaken_tundra_cobble", prob=254, param2=0},
		{name="everness:forsaken_tundra_cobble", prob=254, param2=0},
		{name="everness:forsaken_tundra_brick", prob=254, param2=0},
		{name="everness:forsaken_tundra_cobble", prob=254, param2=0},
		{name="air", prob=0, param2=0},
		{name="air", prob=0, param2=0},
		{name="air", prob=0, param2=0},
		{name="air", prob=0, param2=0},
		{name="everness:forsaken_tundra_brick", prob=254, param2=0},
		{name="everness:forsaken_tundra_brick", prob=254, param2=0},
		{name="everness:forsaken_tundra_brick", prob=254, param2=0},
		{name="everness:forsaken_tundra_cobble", prob=254, param2=0},
		{name="everness:forsaken_tundra_brick", prob=254, param2=0},
		{name="everness:forsaken_tundra_brick", prob=254, param2=0},
		{name="air", prob=0, param2=0},
		{name="air", prob=0, param2=0},
		{name="air", prob=0, param2=0},
		{name="air", prob=0, param2=0},
		{name="air", prob=0, param2=0},
		{name="air", prob=0, param2=0},
		{name="air", prob=0, param2=0},
		{name="air", prob=0, param2=0},
		{name="air", prob=0, param2=0},
		{name="air", prob=0, param2=0},
		{name="air", prob=0, param2=0},
		{name="air", prob=0, param2=0},
		{name="air", prob=0, param2=0},
		{name="air", prob=0, param2=0},
		{name="air", prob=0, param2=0},
		{name="air", prob=0, param2=0},
		{name="air", prob=0, param2=0},
		{name="air", prob=0, param2=0},
		{name="air", prob=0, param2=0},
		{name="air", prob=0, param2=0},
		{name="air", prob=0, param2=0},
		{name="air", prob=0, param2=0},
		{name="air", prob=0, param2=0},
		{name="air", prob=0, param2=0},
		{name="air", prob=0, param2=0},
		{name="air", prob=0, param2=0},
		{name="air", prob=0, param2=0},
		{name="everness:forsaken_tundra_brick", prob=254, param2=0},
		{name="everness:forsaken_tundra_brick", prob=254, param2=0},
		{name="everness:forsaken_tundra_cobble", prob=254, param2=0},
		{name="everness:forsaken_tundra_cobble", prob=254, param2=0},
		{name="everness:forsaken_tundra_cobble", prob=254, param2=0},
		{name="everness:forsaken_tundra_cobble", prob=254, param2=0},
		{name="everness:forsaken_tundra_cobble", prob=254, param2=0},
		{name="everness:forsaken_tundra_brick", prob=254, param2=0},
		{name="everness:forsaken_tundra_cobble", prob=254, param2=0},
		{name="everness:forsaken_tundra_brick", prob=254, param2=0},
		{name="everness:forsaken_tundra_brick", prob=254, param2=0},
		{name="everness:forsaken_tundra_cobble", prob=254, param2=0},
		{name="everness:forsaken_tundra_cobble", prob=254, param2=0},
		{name="air", prob=254, param2=0},
		{name="air", prob=254, param2=0},
		{name="air", prob=254, param2=0},
		{name="air", prob=254, param2=0},
		{name="air", prob=254, param2=0},
		{name="air", prob=254, param2=0},
		{name="air", prob=254, param2=0},
		{name="air", prob=254, param2=0},
		{name="air", prob=254, param2=0},
		{name="air", prob=254, param2=0},
		{name="everness:forsaken_tundra_brick", prob=254, param2=0},
		{name="everness:forsaken_tundra_cobble", prob=254, param2=0},
		{name="air", prob=254, param2=0},
		{name="air", prob=254, param2=0},
		{name="air", prob=254, param2=0},
		{name="air", prob=254, param2=0},
		{name="air", prob=254, param2=0},
		{name="air", prob=254, param2=0},
		{name="air", prob=254, param2=0},
		{name="air", prob=254, param2=0},
