schematic = {
	size = {x=14, y=12, z=9},
	yslice_prob = {
		{ypos=0, prob=254},
		{ypos=1, prob=254},
		{ypos=2, prob=254},
		{ypos=3, prob=254},
		{ypos=4, prob=254},
		{ypos=5, prob=254},
		{ypos=6, prob=254},
		{ypos=7, prob=254},
		{ypos=8, prob=254},
		{ypos=9, prob=254},
		{ypos=10, prob=254},
		{ypos=11, prob=254},
	},
	data = {
		{name="everness:crystal_forest_deep_ocean_sandstone_brick", prob=126, param2=0},
		{name="everness:crystal_forest_deep_ocean_sandstone_brick", prob=126, param2=0},
		{name="everness:crystal_forest_deep_ocean_sandstone_brick", prob=126, param2=0},
		{name="everness:crystal_forest_deep_ocean_sandstone_brick", prob=126, param2=0},
		{name="everness:crystal_forest_deep_ocean_sandstone_brick", prob=126, param2=0},
		{name="everness:crystal_forest_deep_ocean_sandstone_brick", prob=126, param2=0},
		{name="everness:crystal_forest_deep_ocean_sandstone_brick", prob=126, param2=0},
		{name="everness:crystal_forest_deep_ocean_sandstone_brick", prob=126, param2=0},
		{name="everness:crystal_forest_deep_ocean_sandstone_brick", prob=126, param2=0},
		{name="everness:crystal_forest_deep_ocean_sandstone_brick", prob=126, param2=0},
		{name="everness:crystal_forest_deep_ocean_sandstone_brick", prob=126, param2=0},
		{name="everness:crystal_forest_deep_ocean_sandstone_brick", prob=126, param2=0},
		{name="everness:crystal_forest_deep_ocean_sandstone_brick", prob=126, param2=0},
		{name="everness:crystal_forest_deep_ocean_sandstone_brick", prob=126, param2=0},
		{name="air", prob=0, param2=0},
		{name="air", prob=0, param2=0},
		{name="air", prob=0, param2=0},
		{name="air", prob=0, param2=0},
		{name="air", prob=0, param2=0},
		{name="air", prob=0, param2=0},
		{name="air", prob=0, param2=0},
		{name="air", prob=0, param2=0},
		{name="air", prob=0, param2=0},
		{name="air", prob=0, param2=0},
		{name="air", prob=0, param2=0},
		{name="air", prob=0, param2=0},
		{name="air", prob=0, param2=0},
		{name="air", prob=0, param2=0},
		{name="air", prob=0, param2=0},
		{name="air", prob=0, param2=0},
		{name="air", prob=0, param2=0},
		{name="air", prob=0, param2=0},
		{name="air", prob=0, param2=0},
		{name="air", prob=0, param2=0},
		{name="air", prob=0, param2=0},
		{name="air", prob=0, param2=0},
		{name="air", prob=0, param2=0},
		{name="air", prob=0, param2=0},
		{name="air", prob=0, param2=0},
		{name="air", prob=0, param2=0},
		{name="air", prob=0, param2=0},
		{name="air", prob=0, param2=0},
		{name="air", prob=0, param2=0},
		{name="air", prob=0, param2=0},
		{name="air", prob=0, param2=0},
		{name="air", prob=0, param2=0},
		{name="air", prob=0, param2=0},
		{name="air", prob=0, param2=0},
		{name="air", prob=0, param2=0},
		{name="air", prob=0, param2=0},
		{name="air", prob=0, param2=0},
		{name="air", prob=0, param2=0},
		{name="air", prob=0, param2=0},
		{name="air", prob=0, param2=0},
		{name="air", prob=0, param2=0},
		{name="air", prob=0, param2=0},
		{name="air", prob=0, param2=0},
		{name="air", prob=0, param2=0},
		{name="air", prob=0, param2=0},
		{name="air", prob=0, param2=0},
		{name="air", prob=0, param2=0},
		{name="air", prob=0, param2=0},
		{name="air", prob=0, param2=0},
		{name="air", prob=0, param2=0},
		{name="air", prob=0, param2=0},
		{name="air", prob=0, param2=0},
		{name="air", prob=0, param2=0},
		{name="air", prob=0, param2=0},
		{name="air", prob=0, param2=0},
		{name="air", prob=0, param2=0},
		{name="air", prob=0, param2=0},
		{name="air", prob=0, param2=0},
		{name="air", prob=0, param2=0},
		{name="air", prob=0, param2=0},
		{name="air", prob=0, param2=0},
		{name="air", prob=0, param2=0},
		{name="air", prob=0, param2=0},
		{name="air", prob=0, param2=0},
		{name="air", prob=0, param2=0},
		{name="air", prob=0, param2=0},
		{name="air", prob=0, param2=0},
		{name="air", prob=0, param2=0},
		{name="air", prob=0, param2=0},
		{name="air", prob=0, param2=0},
		{name="air", prob=0, param2=0},
		{name="air", prob=0, param2=0},
		{name="air", prob=0, param2=0},
		{name="air", prob=0, param2=0},
		{name="air", prob=0, param2=0},
		{name="air", prob=0, param2=0},
		{name="air", prob=0, param2=0},
		{name="air", prob=0, param2=0},
		{name="air", prob=0, param2=0},
		{name="air", prob=0, param2=0},
		{name="air", prob=0, param2=0},
		{name="air", prob=0, param2=0},
		{name="air", prob=0, param2=0},
		{name="air", prob=0, param2=0},
		{name="air", prob=0, param2=0},
		{name="air", prob=0, param2=0},
		{name="air", prob=0, param2=0},
		{name="air", prob=0, param2=0},
		{name="air", prob=0, param2=0},
		{name="air", prob=0, param2=0},
		{name="air", prob=0, param2=0},
		{name="air", prob=0, param2=0},
		{name="air", prob=0, param2=0},
		{name="air", prob=0, param2=0},
		{name="air", prob=0, param2=0},
		{name="air", prob=0, param2=0},
		{name="air", prob=0, param2=0},
		{name="air", prob=0, param2=0},
		{name="air", prob=0, param2=0},
		{name="air", prob=0, param2=0},
		{name="air", prob=0, param2=0},
		{name="air", prob=0, param2=0},
		{name="air", prob=0, param2=0},
		{name="air", prob=0, param2=0},
		{name="air", prob=0, param2=0},
		{name="air", prob=0, param2=0},
		{name="air", prob=0, param2=0},
		{name="air", prob=0, param2=0},
		{name="air", prob=0, param2=0},
		{name="air", prob=0, param2=0},
		{name="air", prob=0, param2=0},
		{name="air", prob=0, param2=0},
		{name="air", prob=0, param2=0},
		{name="air", prob=0, param2=0},
		{name="air", prob=0, param2=0},
		{name="air", prob=0, param2=0},
		{name="air", prob=0, param2=0},
		{name="air", prob=0, param2=0},
		{name="air", prob=0, param2=0},
		{name="air", prob=0, param2=0},
		{name="air", prob=0, param2=0},
		{name="air", prob=0, param2=0},
		{name="air", prob=0, param2=0},
		{name="air", prob=0, param2=0},
		{name="air", prob=0, param2=0},
		{name="air", prob=0, param2=0},
		{name="air", prob=0, param2=0},
		{name="air", prob=0, param2=0},
		{name="air", prob=0, param2=0},
		{name="air", prob=0, param2=0},
		{name="air", prob=0, param2=0},
		{name="air", prob=0, param2=0},
		{name="air", prob=0, param2=0},
		{name="air", prob=0, param2=0},
		{name="air", prob=0, param2=0},
		{name="air", prob=0, param2=0},
		{name="air", prob=0, param2=0},
		{name="air", prob=0, param2=0},
		{name="air", prob=0, param2=0},
		{name="air", prob=0, param2=0},
		{name="air", prob=0, param2=0},
		{name="air", prob=0, param2=0},
		{name="air", prob=0, param2=0},
		{name="air", prob=0, param2=0},
		{name="air", prob=0, param2=0},
		{name="air", prob=0, param2=0},
		{name="air", prob=0, param2=0},
		{name="air", prob=0, param2=0},
		{name="air", prob=0, param2=0},
		{name="air", prob=0, param2=0},
		{name="air", prob=0, param2=0},
		{name="air", prob=0, param2=0},
		{name="air", prob=0, param2=0},
		{name="air", prob=0, param2=0},
		{name="everness:crystal_forest_deep_ocean_sandstone_brick", prob=126, param2=0},
		{name="everness:crystal_forest_deep_ocean_sandstone_brick", prob=254, param2=0},
		{name="everness:crystal_forest_deep_ocean_sandstone_brick", prob=254, param2=0},
		{name="everness:crystal_forest_deep_ocean_sandstone_brick", prob=254, param2=0},
		{name="everness:crystal_forest_deep_ocean_sandstone_brick", prob=254, param2=0},
		{name="everness:crystal_forest_deep_ocean_sandstone_brick", prob=254, param2=0},
		{name="everness:crystal_forest_deep_ocean_sandstone_brick", prob=254, param2=0},
		{name="everness:crystal_forest_deep_ocean_sandstone_brick", prob=254, param2=0},
		{name="everness:crystal_forest_deep_ocean_sandstone_brick", prob=126, param2=0},
		{name="everness:crystal_forest_deep_ocean_sandstone_brick", prob=126, param2=0},
		{name="everness:crystal_forest_deep_ocean_sandstone_brick", prob=126, param2=0},
		{name="everness:crystal_forest_deep_ocean_sandstone_brick", prob=126, param2=0},
		{name="everness:crystal_forest_deep_ocean_sandstone_block", prob=126, param2=0},
		{name="everness:crystal_forest_deep_ocean_sandstone_block", prob=126, param2=0},
		{name="air", prob=0, param2=0},
		{name="everness:crystal_forest_deep_ocean_sandstone_block", prob=254, param2=0},
		{name="everness:crystal_forest_deep_ocean_sandstone_block", prob=254, param2=0},
		{name="everness:crystal_forest_deep_ocean_sandstone_block", prob=254, param2=0},
		{name="everness:crystal_forest_deep_ocean_sandstone_block", prob=254, param2=0},
		{name="everness:crystal_forest_deep_ocean_sandstone_block", prob=254, param2=0},
		{name="everness:crystal_forest_deep_ocean_sandstone_block", prob=254, param2=0},
		{name="everness:crystal_forest_deep_ocean_sandstone_block", prob=254, param2=0},
		{name="air", prob=0, param2=0},
		{name="air", prob=0, param2=0},
		{name="air", prob=0, param2=0},
		{name="air", prob=0, param2=0},
		{name="air", prob=0, param2=0},
		{name="air", prob=0, param2=0},
		{name="air", prob=0, param2=0},
		{name="everness:crystal_forest_deep_ocean_sandstone_block", prob=254, param2=0},
		{name="air", prob=0, param2=0},
		{name="stairs:stair_crystal_forest_deep_ocean_sandstone_block", prob=254, param2=1},
		{name="everness:crystal_forest_deep_ocean_sandstone_block", prob=254, param2=0},
		{name="stairs:stair_crystal_forest_deep_ocean_sandstone_block", prob=254, param2=3},
		{name="air", prob=0, param2=0},
		{name="everness:crystal_forest_deep_ocean_sandstone_block", prob=254, param2=0},
		{name="air", prob=0, param2=0},
		{name="air", prob=0, param2=0},
		{name="air", prob=0, param2=0},
		{name="air", prob=0, param2=0},
		{name="air", prob=0, param2=0},
		{name="air", prob=0, param2=0},
		{name="air", prob=0, param2=0},
		{name="everness:crystal_forest_deep_ocean_sandstone_block", prob=254, param2=0},
		{name="air", prob=0, param2=0},
		{name="air", prob=0, param2=0},
		{name="everness:crystal_forest_deep_ocean_sandstone_block", prob=254, param2=0},
		{name="air", prob=0, param2=0},
		{name="air", prob=0, param2=0},
		{name="everness:crystal_forest_deep_ocean_sandstone_block", prob=254, param2=0},
		{name="air", prob=0, param2=0},
		{name="air", prob=0, param2=0},
		{name="air", prob=0, param2=0},
		{name="air", prob=0, param2=0},
		{name="air", prob=0, param2=0},
		{name="air", prob=0, param2=0},
		{name="air", prob=0, param2=0},
		{name="everness:crystal_forest_deep_ocean_sandstone_block", prob=254, param2=0},
		{name="everness:crystal_forest_deep_ocean_sandstone_brick", prob=254, param2=0},
		{name="everness:crystal_forest_deep_ocean_sandstone_brick", prob=254, param2=0},
		{name="everness:crystal_forest_deep_ocean_sandstone_brick", prob=254, param2=0},
		{name="everness:crystal_forest_deep_ocean_sandstone_brick", prob=254, param2=0},
		{name="everness:crystal_forest_deep_ocean_sandstone_brick", prob=254, param2=0},
		{name="everness:crystal_forest_deep_ocean_sandstone_block", prob=254, param2=0},
		{name="air", prob=0, param2=0},
		{name="air", prob=0, param2=0},
		{name="air", prob=0, param2=0},
		{name="air", prob=0, param2=0},
		{name="air", prob=0, param2=0},
		{name="air", prob=0, param2=0},
		{name="air", prob=0, param2=0},
		{name="everness:crystal_forest_deep_ocean_sandstone_block", prob=254, param2=0},
		{name="air", prob=0, param2=0},
		{name="air", prob=0, param2=0},
		{name="everness:crystal_forest_deep_ocean_sandstone_brick", prob=254, param2=0},
		{name="air", prob=0, param2=0},
		{name="air", prob=0, param2=0},
		{name="everness:crystal_forest_deep_ocean_sandstone_block", prob=254, param2=0},
		{name="air", prob=0, param2=0},
		{name="air", prob=0, param2=0},
		{name="air", prob=0, param2=0},
		{name="air", prob=0, param2=0},
		{name="air", prob=0, param2=0},
		{name="air", prob=0, param2=0},
		{name="air", prob=0, param2=0},
		{name="everness:crystal_forest_deep_ocean_sandstone_block", prob=254, param2=0},
		{name="air", prob=0, param2=0},
		{name="air", prob=0, param2=0},
		{name="everness:crystal_forest_deep_ocean_sandstone_brick", prob=254, param2=0},
		{name="air", prob=0, param2=0},
		{name="air", prob=0, param2=0},
		{name="everness:crystal_forest_deep_ocean_sandstone_block", prob=254, param2=0},
		{name="air", prob=0, param2=0},
		{name="air", prob=0, param2=0},
		{name="air", prob=0, param2=0},
		{name="air", prob=0, param2=0},
		{name="air", prob=0, param2=0},
		{name="air", prob=0, param2=0},
		{name="air", prob=0, param2=0},
		{name="everness:crystal_forest_deep_ocean_sandstone_block", prob=254, param2=0},
		{name="air", prob=0, param2=0},
		{name="air", prob=0, param2=0},
		{name="everness:crystal_forest_deep_ocean_sandstone_brick", prob=254, param2=0},
		{name="air", prob=0, param2=0},
		{name="air", prob=0, param2=0},
		{name="everness:crystal_forest_deep_ocean_sandstone_block", prob=254, param2=0},
		{name="air", prob=0, param2=0},
		{name="air", prob=0, param2=0},
		{name="air", prob=0, param2=0},
		{name="air", prob=0, param2=0},
		{name="air", prob=0, param2=0},
		{name="air", prob=0, param2=0},
		{name="air", prob=0, param2=0},
		{name="everness:crystal_forest_deep_ocean_sandstone_block", prob=254, param2=0},
		{name="stairs:stair_crystal_forest_deep_ocean_sandstone_brick", prob=254, param2=21},
		{name="stairs:stair_crystal_forest_deep_ocean_sandstone_brick", prob=254, param2=23},
		{name="everness:crystal_forest_deep_ocean_sandstone_brick", prob=254, param2=0},
		{name="stairs:stair_crystal_forest_deep_ocean_sandstone_brick", prob=254, param2=21},
		{name="stairs:stair_crystal_forest_deep_ocean_sandstone_brick", prob=254, param2=23},
		{name="everness:crystal_forest_deep_ocean_sandstone_block", prob=254, param2=0},
		{name="air", prob=0, param2=0},
		{name="air", prob=0, param2=0},
		{name="air", prob=0, param2=0},
		{name="air", prob=0, param2=0},
		{name="air", prob=0, param2=0},
		{name="air", prob=0, param2=0},
		{name="air", prob=0, param2=0},
		{name="everness:crystal_forest_deep_ocean_sandstone_block", prob=254, param2=0},
		{name="everness:crystal_forest_deep_ocean_sandstone_brick", prob=254, param2=0},
		{name="everness:crystal_forest_deep_ocean_sandstone_brick", prob=254, param2=0},
		{name="everness:crystal_forest_deep_ocean_sandstone_brick", prob=254, param2=0},
		{name="everness:crystal_forest_deep_ocean_sandstone_brick", prob=254, param2=0},
		{name="everness:crystal_forest_deep_ocean_sandstone_brick", prob=254, param2=0},
		{name="everness:crystal_forest_deep_ocean_sandstone_block", prob=254, param2=0},
		{name="air", prob=0, param2=0},
		{name="air", prob=0, param2=0},
		{name="air", prob=0, param2=0},
		{name="air", prob=0, param2=0},
		{name="air", prob=0, param2=0},
		{name="air", prob=0, param2=0},
		{name="air", prob=0, param2=0},
		{name="everness:crystal_forest_deep_ocean_sandstone_block", prob=254, param2=0},
		{name="stairs:slab_crystal_forest_deep_ocean_sandstone_block", prob=254, param2=3},
		{name="stairs:stair_crystal_forest_deep_ocean_sandstone_block", prob=254, param2=1},
		{name="everness:crystal_forest_deep_ocean_sandstone_block", prob=254, param2=0},
		{name="stairs:stair_crystal_forest_deep_ocean_sandstone_block", prob=254, param2=3},
		{name="stairs:slab_crystal_forest_deep_ocean_sandstone_block", prob=254, param2=2},
		{name="everness:crystal_forest_deep_ocean_sandstone_block", prob=254, param2=0},
		{name="air", prob=0, param2=0},
		{name="air", prob=0, param2=0},
		{name="air", prob=0, param2=0},
		{name="air", prob=0, param2=0},
		{name="air", prob=0, param2=0},
		{name="air", prob=0, param2=0},
		{name="air", prob=0, param2=0},
		{name="everness:crystal_forest_deep_ocean_sandstone_block", prob=254, param2=0},
		{name="air", prob=0, param2=0},
		{name="air", prob=0, param2=0},
		{name="stairs:slab_crystal_forest_deep_ocean_sandstone_block", prob=254, param2=1},
		{name="air", prob=0, param2=0},
		{name="air", prob=0, param2=0},
		{name="everness:crystal_forest_deep_ocean_sandstone_block", prob=254, param2=0},
		{name="air", prob=0, param2=0},
		{name="air", prob=0, param2=0},
		{name="air", prob=0, param2=0},
		{name="air", prob=0, param2=0},
		{name="air", prob=0, param2=0},
		{name="air", prob=0, param2=0},
		{name="everness:crystal_forest_deep_ocean_sandstone_brick", prob=126, param2=0},
		{name="everness:crystal_forest_deep_ocean_sandstone_brick", prob=254, param2=0},
		{name="everness:crystal_forest_deep_ocean_sandstone_brick", prob=254, param2=0},
		{name="everness:crystal_forest_deep_ocean_sandstone_brick", prob=254, param2=0},
		{name="everness:crystal_forest_deep_ocean_sandstone_brick", prob=254, param2=0},
		{name="everness:crystal_forest_deep_ocean_sandstone_brick", prob=254, param2=0},
		{name="everness:crystal_forest_deep_ocean_sandstone_brick", prob=254, param2=0},
		{name="everness:crystal_forest_deep_ocean_sandstone_brick", prob=254, param2=0},
		{name="everness:crystal_forest_deep_ocean_sandstone_brick", prob=254, param2=0},
		{name="everness:crystal_forest_deep_ocean_sandstone_brick", prob=254, param2=0},
		{name="everness:crystal_forest_deep_ocean_sandstone_brick", prob=254, param2=0},
		{name="everness:crystal_forest_deep_ocean_sandstone_brick", prob=254, param2=0},
		{name="everness:crystal_forest_deep_ocean_sandstone_brick", prob=254, param2=0},
		{name="everness:crystal_forest_deep_ocean_sandstone_block", prob=126, param2=0},
		{name="air", prob=0, param2=0},
		{name="everness:crystal_forest_deep_ocean_sandstone_block", prob=254, param2=0},
		{name="everness:crystal_forest_deep_ocean_sandstone_block", prob=254, param2=0},
		{name="everness:crystal_forest_deep_ocean_sandstone_block", prob=254, param2=0},
		{name="everness:crystal_forest_deep_ocean_sandstone_block", prob=254, param2=0},
		{name="everness:crystal_forest_deep_ocean_sandstone_block", prob=254, param2=0},
		{name="everness:crystal_forest_deep_ocean_sandstone_block", prob=254, param2=0},
		{name="everness:crystal_forest_deep_ocean_sandstone_block", prob=254, param2=0},
		{name="everness:crystal_forest_deep_ocean_sandstone_block", prob=254, param2=0},
		{name="everness:crystal_forest_deep_ocean_sandstone_block", prob=254, param2=0},
		{name="everness:crystal_forest_deep_ocean_sandstone_block", prob=254, param2=0},
		{name="everness:crystal_forest_deep_ocean_sandstone_block", prob=254, param2=0},
		{name="everness:crystal_forest_deep_ocean_sandstone_block", prob=254, param2=0},
		{name="air", prob=0, param2=0},
		{name="air", prob=0, param2=0},
		{name="air", prob=0, param2=0},
		{name="everness:crystal_forest_deep_ocean_sandstone_brick", prob=254, param2=0},
		{name="everness:crystal_forest_deep_ocean_sandstone_brick", prob=254, param2=0},
		{name="everness:crystal_forest_deep_ocean_sandstone_brick", prob=254, param2=0},
		{name="everness:crystal_forest_deep_ocean_sandstone_brick", prob=254, param2=0},
		{name="everness:crystal_forest_deep_ocean_sandstone_brick", prob=254, param2=0},
		{name="everness:crystal_forest_deep_ocean_sandstone_brick", prob=254, param2=0},
		{name="everness:crystal_forest_deep_ocean_sandstone_block", prob=254, param2=0},
		{name="everness:crystal_forest_deep_ocean_sandstone_block", prob=254, param2=0},
		{name="everness:crystal_forest_deep_ocean_sandstone_block", prob=254, param2=0},
		{name="everness:crystal_forest_deep_ocean_sandstone_block", prob=254, param2=0},
		{name="everness:crystal_forest_deep_ocean_sandstone_block", prob=254, param2=0},
		{name="air", prob=0, param2=0},
		{name="air", prob=0, param2=0},
		{name="air", prob=0, param2=0},
		{name="everness:crystal_forest_deep_ocean_sandstone_brick", prob=254, param2=0},
		{name="everness:crystal_forest_deep_ocean_sandstone_brick", prob=254, param2=0},
		{name="everness:crystal_forest_deep_ocean_sandstone_brick", prob=254, param2=0},
		{name="everness:crystal_forest_deep_ocean_sandstone_brick", prob=254, param2=0},
		{name="everness:crystal_forest_deep_ocean_sandstone_brick", prob=254, param2=0},
		{name="everness:crystal_forest_deep_ocean_sandstone_brick", prob=254, param2=0},
		{name="everness:crystal_forest_deep_ocean_sandstone_block", prob=254, param2=0},
		{name="everness:crystal_forest_deep_ocean_sandstone_block", prob=254, param2=0},
		{name="everness:crystal_forest_deep_ocean_sandstone_block", prob=254, param2=0},
		{name="everness:crystal_forest_deep_ocean_sandstone_block", prob=254, param2=0},
		{name="everness:crystal_forest_deep_ocean_sandstone_block", prob=254, param2=0},
		{name="air", prob=0, param2=0},
		{name="air", prob=0, param2=0},
		{name="everness:crystal_forest_deep_ocean_sandstone_brick", prob=254, param2=0},
		{name="everness:crystal_forest_deep_ocean_sandstone_block", prob=254, param2=0},
		{name="everness:crystal_forest_deep_ocean_sandstone_block", prob=254, param2=0},
		{name="everness:crystal_forest_deep_ocean_sandstone_block", prob=254, param2=0},
		{name="everness:crystal_forest_deep_ocean_sandstone_block", prob=254, param2=0},
		{name="everness:crystal_forest_deep_ocean_sandstone_block", prob=254, param2=0},
		{name="everness:crystal_forest_deep_ocean_sandstone_brick", prob=254, param2=0},
		{name="everness:crystal_forest_deep_ocean_sandstone_block", prob=254, param2=0},
		{name="stairs:stair_crystal_forest_deep_ocean_sandstone_block", prob=254, param2=1},
		{name="everness:crystal_forest_deep_ocean_sandstone_block", prob=254, param2=0},
		{name="stairs:stair_crystal_forest_deep_ocean_sandstone_block", prob=254, param2=3},
		{name="everness:crystal_forest_deep_ocean_sandstone_block", prob=254, param2=0},
		{name="air", prob=0, param2=0},
		{name="air", prob=0, param2=0},
		{name="air", prob=0, param2=0},
		{name="everness:crystal_forest_deep_ocean_sandstone_block", prob=254, param2=0},
		{name="everness:crystal_forest_deep_ocean_sandstone_block", prob=254, param2=0},
		{name="everness:crystal_forest_deep_ocean_sandstone_block", prob=254, param2=0},
		{name="everness:crystal_forest_deep_ocean_sandstone_block", prob=254, param2=0},
		{name="everness:crystal_forest_deep_ocean_sandstone_block", prob=254, param2=0},
		{name="air", prob=0, param2=0},
		{name="stairs:slab_crystal_forest_deep_ocean_sandstone_block", prob=254, param2=3},
		{name="air", prob=0, param2=0},
		{name="air", prob=0, param2=0},
		{name="air", prob=0, param2=0},
		{name="stairs:slab_crystal_forest_deep_ocean_sandstone_block", prob=254, param2=3},
		{name="air", prob=0, param2=0},
		{name="air", prob=0, param2=0},
		{name="air", prob=0, param2=0},
		{name="everness:crystal_forest_deep_ocean_sandstone_block", prob=254, param2=0},
		{name="everness:crystal_forest_deep_ocean_sandstone_block", prob=254, param2=0},
		{name="everness:crystal_forest_deep_ocean_sandstone_block", prob=254, param2=0},
		{name="everness:crystal_forest_deep_ocean_sandstone_block", prob=254, param2=0},
		{name="everness:crystal_forest_deep_ocean_sandstone_block", prob=254, param2=0},
		{name="air", prob=0, param2=0},
		{name="air", prob=0, param2=0},
		{name="air", prob=0, param2=0},
		{name="air", prob=0, param2=0},
		{name="air", prob=0, param2=0},
		{name="air", prob=0, param2=0},
		{name="air", prob=0, param2=0},
		{name="air", prob=0, param2=0},
		{name="air", prob=0, param2=0},
		{name="everness:crystal_forest_deep_ocean_sandstone_block", prob=254, param2=0},
		{name="everness:crystal_forest_deep_ocean_sandstone_block", prob=254, param2=0},
		{name="everness:crystal_forest_deep_ocean_sandstone_block", prob=254, param2=0},
		{name="everness:crystal_forest_deep_ocean_sandstone_block", prob=254, param2=0},
		{name="everness:crystal_forest_deep_ocean_sandstone_block", prob=254, param2=0},
		{name="air", prob=0, param2=0},
		{name="air", prob=0, param2=0},
		{name="air", prob=0, param2=0},
		{name="air", prob=0, param2=0},
		{name="air", prob=0, param2=0},
		{name="air", prob=0, param2=0},
		{name="air", prob=0, param2=0},
		{name="air", prob=0, param2=0},
		{name="stairs:stair_crystal_forest_deep_ocean_sandstone_brick", prob=254, param2=22},
		{name="everness:crystal_forest_deep_ocean_sandstone_block", prob=254, param2=0},
		{name="stairs:stair_crystal_forest_deep_ocean_sandstone_block", prob=254, param2=2},
		{name="everness:crystal_forest_deep_ocean_sandstone_block", prob=254, param2=0},
		{name="everness:crystal_forest_deep_ocean_sandstone_block", prob=254, param2=0},
		{name="everness:crystal_forest_deep_ocean_sandstone_block", prob=254, param2=0},
		{name="stairs:stair_crystal_forest_deep_ocean_sandstone_brick", prob=254, param2=22},
		{name="air", prob=0, param2=0},
		{name="air", prob=0, param2=0},
		{name="air", prob=0, param2=0},
		{name="air", prob=0, param2=0},
		{name="air", prob=0, param2=0},
		{name="air", prob=0, param2=0},
		{name="air", prob=0, param2=0},
		{name="everness:crystal_forest_deep_ocean_sandstone_brick", prob=254, param2=0},
		{name="air", prob=0, param2=0},
		{name="air", prob=0, param2=0},
		{name="air", prob=0, param2=0},
		{name="air", prob=0, param2=0},
		{name="stairs:slab_crystal_forest_deep_ocean_sandstone_brick", prob=254, param2=2},
		{name="everness:crystal_forest_deep_ocean_sandstone_brick", prob=254, param2=0},
		{name="air", prob=0, param2=0},
		{name="air", prob=0, param2=0},
		{name="air", prob=0, param2=0},
		{name="air", prob=0, param2=0},
		{name="air", prob=0, param2=0},
		{name="air", prob=0, param2=0},
		{name="air", prob=0, param2=0},
		{name="stairs:slab_crystal_forest_deep_ocean_sandstone_block", prob=254, param2=3},
		{name="air", prob=0, param2=0},
		{name="air", prob=0, param2=0},
		{name="air", prob=0, param2=0},
		{name="air", prob=0, param2=0},
		{name="air", prob=0, param2=0},
		{name="stairs:slab_crystal_forest_deep_ocean_sandstone_block", prob=254, param2=3},
		{name="air", prob=0, param2=0},
		{name="air", prob=0, param2=0},
		{name="air", prob=0, param2=0},
		{name="air", prob=0, param2=0},
		{name="air", prob=0, param2=0},
		{name="air", prob=0, param2=0},
		{name="air", prob=0, param2=0},
		{name="air", prob=0, param2=0},
		{name="air", prob=0, param2=0},
		{name="air", prob=0, param2=0},
		{name="air", prob=0, param2=0},
		{name="air", prob=0, param2=0},
		{name="air", prob=0, param2=0},
		{name="air", prob=0, param2=0},
		{name="air", prob=0, param2=0},
		{name="air", prob=0, param2=0},
		{name="air", prob=0, param2=0},
		{name="air", prob=0, param2=0},
		{name="air", prob=0, param2=0},
		{name="air", prob=0, param2=0},
		{name="everness:crystal_forest_deep_ocean_sandstone_brick", prob=126, param2=0},
		{name="everness:crystal_forest_deep_ocean_sandstone_brick", prob=254, param2=0},
		{name="everness:crystal_forest_deep_ocean_sandstone_brick", prob=254, param2=0},
		{name="everness:crystal_forest_deep_ocean_sandstone_brick", prob=254, param2=0},
		{name="everness:crystal_forest_deep_ocean_sandstone_brick", prob=254, param2=0},
		{name="everness:crystal_forest_deep_ocean_sandstone_brick", prob=254, param2=0},
		{name="everness:crystal_forest_deep_ocean_sandstone_brick", prob=254, param2=0},
		{name="everness:crystal_forest_deep_ocean_sandstone_brick", prob=254, param2=0},
		{name="everness:crystal_forest_deep_ocean_sandstone_brick", prob=254, param2=0},
		{name="everness:crystal_forest_deep_ocean_sandstone_block", prob=254, param2=0},
		{name="everness:crystal_forest_deep_ocean_sandstone_block", prob=254, param2=0},
		{name="everness:crystal_forest_deep_ocean_sandstone_block", prob=254, param2=0},
		{name="everness:crystal_forest_deep_ocean_sandstone_brick", prob=254, param2=0},
		{name="everness:crystal_forest_deep_ocean_sandstone_brick", prob=126, param2=0},
		{name="air", prob=0, param2=0},
		{name="everness:crystal_forest_deep_ocean_sandstone_block", prob=254, param2=0},
		{name="everness:crystal_forest_deep_ocean_sandstone_block", prob=254, param2=0},
		{name="air", prob=0, param2=0},
		{name="air", prob=0, param2=0},
		{name="air", prob=0, param2=0},
		{name="air", prob=0, param2=0},
		{name="air", prob=0, param2=0},
		{name="everness:crystal_forest_deep_ocean_sandstone_block", prob=254, param2=0},
		{name="air", prob=0, param2=0},
		{name="air", prob=0, param2=0},
		{name="air", prob=0, param2=0},
		{name="everness:crystal_forest_deep_ocean_sandstone_brick", prob=254, param2=0},
		{name="air", prob=0, param2=0},
		{name="air", prob=0, param2=0},
		{name="stairs:stair_crystal_forest_deep_ocean_sandstone_block", prob=254, param2=0},
		{name="everness:crystal_forest_deep_ocean_sandstone_brick", prob=254, param2=0},
		{name="stairs:slab_crystal_forest_deep_ocean_sandstone_brick", prob=254, param2=21},
		{name="air", prob=0, param2=0},
		{name="air", prob=0, param2=0},
		{name="air", prob=0, param2=0},
		{name="air", prob=0, param2=0},
		{name="everness:crystal_forest_deep_ocean_sandstone_block", prob=254, param2=0},
		{name="air", prob=0, param2=0},
		{name="air", prob=0, param2=0},
		{name="air", prob=0, param2=0},
		{name="everness:crystal_forest_deep_ocean_sandstone_brick", prob=254, param2=0},
		{name="air", prob=0, param2=0},
		{name="air", prob=0, param2=0},
		{name="air", prob=0, param2=0},
		{name="everness:crystal_forest_deep_ocean_sandstone_brick", prob=254, param2=0},
		{name="air", prob=0, param2=0},
		{name="stairs:stair_crystal_forest_deep_ocean_sandstone_brick", prob=254, param2=1},
		{name="stairs:slab_crystal_forest_deep_ocean_sandstone_brick", prob=254, param2=23},
		{name="air", prob=0, param2=0},
		{name="air", prob=0, param2=0},
		{name="everness:crystal_forest_deep_ocean_sandstone_block", prob=254, param2=0},
		{name="stairs:slab_crystal_forest_deep_ocean_sandstone_block", prob=254, param2=21},
		{name="stairs:slab_crystal_forest_deep_ocean_sandstone_block", prob=254, param2=22},
		{name="stairs:slab_crystal_forest_deep_ocean_sandstone_block", prob=254, param2=22},
		{name="everness:crystal_forest_deep_ocean_sandstone_brick", prob=254, param2=0},
		{name="air", prob=0, param2=0},
		{name="air", prob=0, param2=0},
		{name="everness:crystal_forest_deep_ocean_sandstone_brick", prob=254, param2=0},
		{name="everness:crystal_forest_deep_ocean_sandstone_block", prob=254, param2=0},
		{name="air", prob=0, param2=0},
		{name="air", prob=0, param2=0},
		{name="air", prob=0, param2=0},
		{name="everness:crystal_forest_deep_ocean_sandstone_block", prob=254, param2=0},
		{name="everness:crystal_forest_deep_ocean_sandstone_brick", prob=254, param2=0},
		{name="stairs:stair_crystal_forest_deep_ocean_sandstone_block", prob=254, param2=0},
		{name="air", prob=0, param2=0},
		{name="air", prob=0, param2=0},
		{name="air", prob=0, param2=0},
		{name="stairs:stair_crystal_forest_deep_ocean_sandstone_block", prob=254, param2=0},
		{name="air", prob=0, param2=0},
		{name="air", prob=0, param2=0},
		{name="air", prob=0, param2=0},
		{name="everness:crystal_forest_deep_ocean_sandstone_block", prob=254, param2=0},
		{name="air", prob=0, param2=0},
		{name="air", prob=0, param2=0},
		{name="air", prob=0, param2=0},
		{name="everness:crystal_forest_deep_ocean_sandstone_block", prob=254, param2=0},
		{name="air", prob=0, param2=0},
		{name="air", prob=0, param2=0},
		{name="air", prob=0, param2=0},
		{name="air", prob=0, param2=0},
		{name="air", prob=0, param2=0},
		{name="air", prob=0, param2=0},
		{name="air", prob=0, param2=0},
		{name="air", prob=0, param2=0},
		{name="air", prob=0, param2=0},
		{name="everness:crystal_forest_deep_ocean_sandstone_block", prob=254, param2=0},
		{name="air", prob=0, param2=0},
		{name="air", prob=0, param2=0},
		{name="air", prob=0, param2=0},
		{name="everness:crystal_forest_deep_ocean_sandstone_block", prob=254, param2=0},
		{name="air", prob=0, param2=0},
		{name="air", prob=0, param2=0},
		{name="air", prob=0, param2=0},
		{name="air", prob=0, param2=0},
		{name="air", prob=0, param2=0},
		{name="air", prob=0, param2=0},
		{name="air", prob=0, param2=0},
		{name="air", prob=0, param2=0},
		{name="air", prob=0, param2=0},
		{name="everness:crystal_forest_deep_ocean_sandstone_block", prob=254, param2=0},
		{name="stairs:stair_crystal_forest_deep_ocean_sandstone_brick", prob=254, param2=2},
		{name="air", prob=0, param2=0},
		{name="air", prob=0, param2=0},
		{name="everness:crystal_forest_deep_ocean_sandstone_block", prob=254, param2=0},
		{name="air", prob=0, param2=0},
		{name="air", prob=0, param2=0},
		{name="air", prob=0, param2=0},
		{name="air", prob=0, param2=0},
		{name="air", prob=0, param2=0},
		{name="air", prob=0, param2=0},
		{name="air", prob=0, param2=0},
		{name="air", prob=0, param2=0},
		{name="stairs:stair_crystal_forest_deep_ocean_sandstone_brick", prob=254, param2=20},
		{name="everness:crystal_forest_deep_ocean_sandstone_block", prob=254, param2=0},
		{name="air", prob=0, param2=0},
		{name="everness:crystal_forest_deep_ocean_sandstone_block", prob=254, param2=0},
		{name="everness:crystal_forest_deep_ocean_sandstone_block", prob=254, param2=0},
		{name="everness:crystal_forest_deep_ocean_sandstone_block", prob=254, param2=0},
		{name="stairs:stair_crystal_forest_deep_ocean_sandstone_brick", prob=254, param2=20},
		{name="air", prob=0, param2=0},
		{name="air", prob=0, param2=0},
		{name="air", prob=0, param2=0},
		{name="air", prob=0, param2=0},
		{name="air", prob=0, param2=0},
		{name="air", prob=0, param2=0},
		{name="air", prob=0, param2=0},
		{name="everness:crystal_forest_deep_ocean_sandstone_brick", prob=254, param2=0},
		{name="air", prob=0, param2=0},
		{name="air", prob=0, param2=0},
		{name="air", prob=0, param2=0},
		{name="air", prob=0, param2=0},
		{name="stairs:slab_crystal_forest_deep_ocean_sandstone_brick", prob=254, param2=2},
		{name="everness:crystal_forest_deep_ocean_sandstone_brick", prob=254, param2=0},
		{name="air", prob=0, param2=0},
		{name="air", prob=0, param2=0},
		{name="air", prob=0, param2=0},
		{name="air", prob=0, param2=0},
		{name="air", prob=0, param2=0},
		{name="air", prob=0, param2=0},
		{name="air", prob=0, param2=0},
		{name="stairs:stair_crystal_forest_deep_ocean_sandstone_block", prob=254, param2=0},
		{name="air", prob=0, param2=0},
		{name="air", prob=0, param2=0},
		{name="air", prob=0, param2=0},
		{name="air", prob=0, param2=0},
		{name="air", prob=0, param2=0},
		{name="stairs:stair_crystal_forest_deep_ocean_sandstone_block", prob=254, param2=0},
		{name="air", prob=0, param2=0},
		{name="air", prob=0, param2=0},
		{name="air", prob=0, param2=0},
		{name="air", prob=0, param2=0},
		{name="air", prob=0, param2=0},
		{name="air", prob=0, param2=0},
		{name="air", prob=0, param2=0},
		{name="air", prob=0, param2=0},
		{name="air", prob=0, param2=0},
		{name="air", prob=0, param2=0},
		{name="air", prob=0, param2=0},
		{name="air", prob=0, param2=0},
		{name="air", prob=0, param2=0},
		{name="air", prob=0, param2=0},
		{name="air", prob=0, param2=0},
		{name="air", prob=0, param2=0},
		{name="air", prob=0, param2=0},
		{name="air", prob=0, param2=0},
		{name="air", prob=0, param2=0},
		{name="air", prob=0, param2=0},
		{name="everness:crystal_forest_deep_ocean_sandstone_brick", prob=126, param2=0},
		{name="everness:crystal_forest_deep_ocean_sandstone_brick", prob=254, param2=0},
		{name="everness:crystal_forest_deep_ocean_sandstone_brick", prob=254, param2=0},
		{name="everness:crystal_forest_deep_ocean_sandstone_brick", prob=254, param2=0},
		{name="everness:crystal_forest_deep_ocean_sandstone_brick", prob=254, param2=0},
		{name="everness:crystal_forest_deep_ocean_sandstone_brick", prob=254, param2=0},
		{name="everness:crystal_forest_deep_ocean_sandstone_brick", prob=254, param2=0},
		{name="everness:crystal_forest_deep_ocean_sandstone_brick", prob=254, param2=0},
		{name="everness:crystal_forest_deep_ocean_sandstone_brick", prob=254, param2=0},
		{name="everness:crystal_forest_deep_ocean_sandstone_brick", prob=254, param2=0},
		{name="everness:crystal_forest_deep_ocean_sandstone_brick", prob=254, param2=0},
		{name="everness:crystal_forest_deep_ocean_sandstone_brick", prob=254, param2=0},
		{name="everness:crystal_forest_deep_ocean_sandstone_brick", prob=254, param2=0},
		{name="everness:crystal_forest_deep_ocean_sandstone_brick", prob=126, param2=0},
		{name="air", prob=0, param2=0},
		{name="everness:crystal_forest_deep_ocean_sandstone_block", prob=254, param2=0},
		{name="everness:crystal_forest_deep_ocean_sandstone_block", prob=254, param2=0},
		{name="everness:crystal_forest_deep_ocean_ruins_marker", prob=254, param2=3},
		{name="air", prob=0, param2=0},
		{name="air", prob=0, param2=0},
		{name="air", prob=0, param2=0},
		{name="air", prob=0, param2=0},
		{name="air", prob=0, param2=0},
		{name="air", prob=0, param2=0},
		{name="air", prob=0, param2=0},
		{name="air", prob=0, param2=0},
		{name="air", prob=0, param2=0},
		{name="air", prob=0, param2=0},
		{name="air", prob=0, param2=0},
		{name="everness:crystal_forest_deep_ocean_sandstone_block", prob=254, param2=0},
		{name="everness:crystal_forest_deep_ocean_sandstone_brick", prob=254, param2=0},
		{name="stairs:stair_crystal_forest_deep_ocean_sandstone_brick", prob=254, param2=2},
		{name="air", prob=0, param2=0},
		{name="air", prob=0, param2=0},
		{name="air", prob=0, param2=0},
		{name="air", prob=0, param2=0},
		{name="air", prob=0, param2=0},
		{name="air", prob=0, param2=0},
		{name="air", prob=0, param2=0},
		{name="air", prob=0, param2=0},
		{name="air", prob=0, param2=0},
		{name="air", prob=0, param2=0},
		{name="air", prob=0, param2=0},
		{name="everness:crystal_forest_deep_ocean_sandstone_block", prob=254, param2=0},
		{name="everness:crystal_forest_deep_ocean_sandstone_brick", prob=254, param2=0},
		{name="air", prob=0, param2=0},
		{name="air", prob=0, param2=0},
		{name="air", prob=0, param2=0},
		{name="air", prob=0, param2=0},
		{name="air", prob=0, param2=0},
		{name="everness:crystal_forest_deep_ocean_sandstone_block", prob=254, param2=0},
		{name="stairs:slab_crystal_forest_deep_ocean_sandstone_block", prob=254, param2=21},
		{name="stairs:slab_crystal_forest_deep_ocean_sandstone_block", prob=254, param2=21},
		{name="stairs:slab_crystal_forest_deep_ocean_sandstone_block", prob=254, param2=21},
		{name="stairs:slab_crystal_forest_deep_ocean_sandstone_brick", prob=254, param2=20},
		{name="air", prob=0, param2=0},
		{name="air", prob=0, param2=0},
		{name="everness:crystal_forest_deep_ocean_sandstone_brick", prob=254, param2=0},
		{name="everness:crystal_forest_deep_ocean_sandstone_block", prob=254, param2=0},
		{name="air", prob=0, param2=0},
		{name="air", prob=0, param2=0},
		{name="stairs:stair_crystal_forest_deep_ocean_sandstone_brick", prob=254, param2=0},
		{name="everness:coral_forest_deep_ocean_lantern", prob=254, param2=0},
		{name="everness:crystal_forest_deep_ocean_sandstone_block", prob=254, param2=0},
		{name="everness:crystal_forest_deep_ocean_sandstone_block", prob=254, param2=0},
		{name="air", prob=0, param2=0},
		{name="air", prob=0, param2=0},
		{name="air", prob=0, param2=0},
		{name="everness:crystal_forest_deep_ocean_sandstone_brick", prob=254, param2=0},
		{name="air", prob=0, param2=0},
		{name="air", prob=0, param2=0},
		{name="everness:crystal_forest_deep_ocean_sandstone_brick", prob=254, param2=0},
		{name="everness:crystal_forest_deep_ocean_sandstone_block", prob=254, param2=0},
		{name="air", prob=0, param2=0},
		{name="air", prob=0, param2=0},
		{name="air", prob=0, param2=0},
		{name="everness:crystal_forest_deep_ocean_sandstone_block", prob=254, param2=0},
		{name="everness:crystal_forest_deep_ocean_sandstone_brick", prob=254, param2=0},
		{name="air", prob=0, param2=0},
		{name="air", prob=0, param2=0},
		{name="air", prob=0, param2=0},
		{name="air", prob=0, param2=0},
		{name="air", prob=0, param2=0},
		{name="air", prob=0, param2=0},
		{name="air", prob=0, param2=0},
		{name="everness:crystal_forest_deep_ocean_sandstone_brick", prob=254, param2=0},
		{name="everness:crystal_forest_deep_ocean_sandstone_block", prob=254, param2=0},
		{name="stairs:stair_crystal_forest_deep_ocean_sandstone_brick", prob=254, param2=2},
		{name="air", prob=0, param2=0},
		{name="air", prob=0, param2=0},
		{name="everness:crystal_forest_deep_ocean_sandstone_block", prob=254, param2=0},
		{name="everness:crystal_forest_deep_ocean_sandstone_brick", prob=254, param2=0},
		{name="air", prob=0, param2=0},
		{name="air", prob=0, param2=0},
		{name="air", prob=0, param2=0},
		{name="air", prob=0, param2=0},
		{name="air", prob=0, param2=0},
		{name="air", prob=0, param2=0},
		{name="air", prob=0, param2=0},
		{name="everness:crystal_forest_deep_ocean_sandstone_brick", prob=254, param2=0},
		{name="everness:crystal_forest_deep_ocean_sandstone_block", prob=254, param2=0},
		{name="air", prob=0, param2=0},
		{name="air", prob=0, param2=0},
		{name="air", prob=0, param2=0},
		{name="everness:crystal_forest_deep_ocean_sandstone_block", prob=254, param2=0},
		{name="everness:crystal_forest_deep_ocean_sandstone_brick", prob=254, param2=0},
		{name="air", prob=0, param2=0},
		{name="air", prob=0, param2=0},
		{name="air", prob=0, param2=0},
		{name="air", prob=0, param2=0},
		{name="air", prob=0, param2=0},
		{name="air", prob=0, param2=0},
		{name="air", prob=0, param2=0},
		{name="everness:crystal_forest_deep_ocean_sandstone_brick", prob=254, param2=0},
		{name="everness:crystal_forest_deep_ocean_sandstone_block", prob=254, param2=0},
		{name="air", prob=0, param2=0},
		{name="everness:crystal_forest_deep_ocean_sandstone_block", prob=254, param2=0},
		{name="everness:crystal_forest_deep_ocean_sandstone_block", prob=254, param2=0},
		{name="everness:crystal_forest_deep_ocean_sandstone_block", prob=254, param2=0},
		{name="everness:crystal_forest_deep_ocean_sandstone_brick", prob=254, param2=0},
		{name="air", prob=0, param2=0},
		{name="air", prob=0, param2=0},
		{name="air", prob=0, param2=0},
		{name="air", prob=0, param2=0},
		{name="air", prob=0, param2=0},
		{name="air", prob=0, param2=0},
		{name="air", prob=0, param2=0},
		{name="everness:crystal_forest_deep_ocean_sandstone_brick", prob=254, param2=0},
		{name="air", prob=0, param2=0},
		{name="air", prob=0, param2=0},
		{name="air", prob=0, param2=0},
		{name="air", prob=0, param2=0},
		{name="stairs:slab_crystal_forest_deep_ocean_sandstone_brick", prob=254, param2=2},
		{name="everness:crystal_forest_deep_ocean_sandstone_brick", prob=254, param2=0},
		{name="air", prob=0, param2=0},
		{name="air", prob=0, param2=0},
		{name="air", prob=0, param2=0},
		{name="air", prob=0, param2=0},
		{name="air", prob=0, param2=0},
		{name="air", prob=0, param2=0},
		{name="air", prob=0, param2=0},
		{name="everness:crystal_forest_deep_ocean_sandstone_block", prob=254, param2=0},
		{name="air", prob=0, param2=0},
		{name="air", prob=0, param2=0},
		{name="air", prob=0, param2=0},
		{name="air", prob=0, param2=0},
		{name="air", prob=0, param2=0},
		{name="everness:crystal_forest_deep_ocean_sandstone_block", prob=254, param2=0},
		{name="air", prob=0, param2=0},
		{name="air", prob=0, param2=0},
		{name="air", prob=0, param2=0},
		{name="air", prob=0, param2=0},
		{name="air", prob=0, param2=0},
		{name="air", prob=0, param2=0},
		{name="air", prob=0, param2=0},
		{name="stairs:slab_crystal_forest_deep_ocean_sandstone_block", prob=254, param2=1},
		{name="air", prob=0, param2=0},
		{name="air", prob=0, param2=0},
		{name="air", prob=0, param2=0},
		{name="air", prob=0, param2=0},
		{name="air", prob=0, param2=0},
		{name="stairs:slab_crystal_forest_deep_ocean_sandstone_block", prob=254, param2=2},
		{name="air", prob=0, param2=0},
		{name="air", prob=0, param2=0},
		{name="air", prob=0, param2=0},
		{name="air", prob=0, param2=0},
		{name="air", prob=0, param2=0},
		{name="air", prob=0, param2=0},
		{name="everness:crystal_forest_deep_ocean_sandstone_brick", prob=126, param2=0},
		{name="everness:crystal_forest_deep_ocean_sandstone_brick", prob=254, param2=0},
		{name="everness:crystal_forest_deep_ocean_sandstone_brick", prob=254, param2=0},
		{name="everness:crystal_forest_deep_ocean_sandstone_brick", prob=254, param2=0},
		{name="everness:crystal_forest_deep_ocean_sandstone_brick", prob=254, param2=0},
		{name="everness:crystal_forest_deep_ocean_sandstone_brick", prob=254, param2=0},
		{name="everness:crystal_forest_deep_ocean_sandstone_brick", prob=254, param2=0},
		{name="everness:crystal_forest_deep_ocean_sandstone_brick", prob=254, param2=0},
		{name="everness:crystal_forest_deep_ocean_sandstone_brick", prob=254, param2=0},
		{name="everness:crystal_forest_deep_ocean_sandstone_block", prob=254, param2=0},
		{name="everness:crystal_forest_deep_ocean_sandstone_block", prob=254, param2=0},
		{name="everness:crystal_forest_deep_ocean_sandstone_block", prob=254, param2=0},
		{name="everness:crystal_forest_deep_ocean_sandstone_brick", prob=254, param2=0},
		{name="everness:crystal_forest_deep_ocean_sandstone_brick", prob=126, param2=0},
		{name="air", prob=0, param2=0},
		{name="everness:crystal_forest_deep_ocean_sandstone_block", prob=254, param2=0},
		{name="everness:crystal_forest_deep_ocean_sandstone_block", prob=254, param2=0},
		{name="stairs:slab_crystal_forest_deep_ocean_sandstone_brick", prob=254, param2=21},
		{name="stairs:stair_crystal_forest_deep_ocean_sandstone_brick", prob=254, param2=3},
		{name="air", prob=0, param2=0},
		{name="air", prob=0, param2=0},
		{name="air", prob=0, param2=0},
		{name="everness:crystal_forest_deep_ocean_sandstone_block", prob=254, param2=0},
		{name="air", prob=0, param2=0},
		{name="air", prob=0, param2=0},
		{name="air", prob=0, param2=0},
		{name="everness:crystal_forest_deep_ocean_sandstone_brick", prob=254, param2=0},
		{name="air", prob=0, param2=0},
		{name="air", prob=0, param2=0},
		{name="stairs:stair_crystal_forest_deep_ocean_sandstone_block", prob=254, param2=2},
		{name="everness:crystal_forest_deep_ocean_sandstone_brick", prob=254, param2=0},
		{name="air", prob=0, param2=0},
		{name="air", prob=0, param2=0},
		{name="air", prob=0, param2=0},
		{name="air", prob=0, param2=0},
		{name="air", prob=0, param2=0},
		{name="everness:crystal_forest_deep_ocean_sandstone_block", prob=254, param2=0},
		{name="air", prob=0, param2=0},
		{name="air", prob=0, param2=0},
		{name="air", prob=0, param2=0},
		{name="everness:crystal_forest_deep_ocean_sandstone_brick", prob=254, param2=0},
		{name="air", prob=0, param2=0},
		{name="air", prob=0, param2=0},
		{name="air", prob=0, param2=0},
		{name="everness:crystal_forest_deep_ocean_sandstone_brick", prob=254, param2=0},
		{name="air", prob=0, param2=0},
		{name="air", prob=0, param2=0},
		{name="air", prob=0, param2=0},
		{name="air", prob=0, param2=0},
		{name="air", prob=0, param2=0},
		{name="everness:crystal_forest_deep_ocean_sandstone_block", prob=254, param2=0},
		{name="stairs:slab_crystal_forest_deep_ocean_sandstone_block", prob=254, param2=21},
		{name="stairs:slab_crystal_forest_deep_ocean_sandstone_block", prob=254, param2=20},
		{name="stairs:slab_crystal_forest_deep_ocean_sandstone_block", prob=254, param2=20},
		{name="everness:crystal_forest_deep_ocean_sandstone_brick", prob=254, param2=0},
		{name="air", prob=0, param2=0},
		{name="air", prob=0, param2=0},
		{name="everness:crystal_forest_deep_ocean_sandstone_brick", prob=254, param2=0},
		{name="everness:crystal_forest_deep_ocean_sandstone_block", prob=254, param2=0},
		{name="air", prob=0, param2=0},
		{name="air", prob=0, param2=0},
		{name="stairs:slab_crystal_forest_deep_ocean_sandstone_brick", prob=254, param2=20},
		{name="everness:crystal_forest_deep_ocean_sandstone_block", prob=254, param2=0},
		{name="everness:crystal_forest_deep_ocean_sandstone_brick", prob=254, param2=0},
		{name="stairs:stair_crystal_forest_deep_ocean_sandstone_block", prob=254, param2=2},
		{name="air", prob=0, param2=0},
		{name="air", prob=0, param2=0},
		{name="air", prob=0, param2=0},
		{name="stairs:stair_crystal_forest_deep_ocean_sandstone_block", prob=254, param2=2},
		{name="air", prob=0, param2=0},
		{name="air", prob=0, param2=0},
		{name="air", prob=0, param2=0},
		{name="everness:crystal_forest_deep_ocean_sandstone_block", prob=254, param2=0},
		{name="stairs:slab_crystal_forest_deep_ocean_sandstone_brick", prob=254, param2=21},
		{name="stairs:stair_crystal_forest_deep_ocean_sandstone_brick", prob=254, param2=3},
		{name="air", prob=0, param2=0},
		{name="everness:crystal_forest_deep_ocean_sandstone_block", prob=254, param2=0},
		{name="air", prob=0, param2=0},
		{name="air", prob=0, param2=0},
		{name="air", prob=0, param2=0},
		{name="air", prob=0, param2=0},
		{name="air", prob=0, param2=0},
		{name="air", prob=0, param2=0},
		{name="air", prob=0, param2=0},
		{name="air", prob=0, param2=0},
		{name="air", prob=0, param2=0},
		{name="everness:crystal_forest_deep_ocean_sandstone_block", prob=254, param2=0},
		{name="air", prob=0, param2=0},
		{name="air", prob=0, param2=0},
		{name="air", prob=0, param2=0},
		{name="everness:crystal_forest_deep_ocean_sandstone_block", prob=254, param2=0},
		{name="air", prob=0, param2=0},
		{name="air", prob=0, param2=0},
		{name="air", prob=0, param2=0},
		{name="air", prob=0, param2=0},
		{name="air", prob=0, param2=0},
		{name="air", prob=0, param2=0},
		{name="air", prob=0, param2=0},
		{name="air", prob=0, param2=0},
		{name="air", prob=0, param2=0},
		{name="everness:crystal_forest_deep_ocean_sandstone_block", prob=254, param2=0},
		{name="air", prob=0, param2=0},
		{name="air", prob=0, param2=0},
		{name="air", prob=0, param2=0},
		{name="everness:crystal_forest_deep_ocean_sandstone_block", prob=254, param2=0},
		{name="air", prob=0, param2=0},
		{name="air", prob=0, param2=0},
		{name="air", prob=0, param2=0},
		{name="air", prob=0, param2=0},
		{name="air", prob=0, param2=0},
		{name="air", prob=0, param2=0},
		{name="air", prob=0, param2=0},
		{name="air", prob=0, param2=0},
		{name="stairs:stair_crystal_forest_deep_ocean_sandstone_brick", prob=254, param2=22},
		{name="everness:crystal_forest_deep_ocean_sandstone_block", prob=254, param2=0},
		{name="air", prob=0, param2=0},
		{name="everness:crystal_forest_deep_ocean_sandstone_block", prob=254, param2=0},
		{name="everness:crystal_forest_deep_ocean_sandstone_block", prob=254, param2=0},
		{name="everness:crystal_forest_deep_ocean_sandstone_block", prob=254, param2=0},
		{name="stairs:stair_crystal_forest_deep_ocean_sandstone_brick", prob=254, param2=22},
		{name="air", prob=0, param2=0},
		{name="air", prob=0, param2=0},
		{name="air", prob=0, param2=0},
		{name="air", prob=0, param2=0},
		{name="air", prob=0, param2=0},
		{name="air", prob=0, param2=0},
		{name="air", prob=0, param2=0},
		{name="everness:crystal_forest_deep_ocean_sandstone_brick", prob=254, param2=0},
		{name="stairs:slab_crystal_forest_deep_ocean_sandstone_brick", prob=254, param2=2},
		{name="air", prob=0, param2=0},
		{name="air", prob=0, param2=0},
		{name="air", prob=0, param2=0},
		{name="stairs:slab_crystal_forest_deep_ocean_sandstone_brick", prob=254, param2=2},
		{name="everness:crystal_forest_deep_ocean_sandstone_brick", prob=254, param2=0},
		{name="air", prob=0, param2=0},
		{name="air", prob=0, param2=0},
		{name="air", prob=0, param2=0},
		{name="air", prob=0, param2=0},
		{name="air", prob=0, param2=0},
		{name="air", prob=0, param2=0},
		{name="air", prob=0, param2=0},
		{name="stairs:stair_crystal_forest_deep_ocean_sandstone_block", prob=254, param2=2},
		{name="air", prob=0, param2=0},
		{name="air", prob=0, param2=0},
		{name="air", prob=0, param2=0},
		{name="air", prob=0, param2=0},
		{name="air", prob=0, param2=0},
		{name="stairs:stair_crystal_forest_deep_ocean_sandstone_block", prob=254, param2=2},
		{name="air", prob=0, param2=0},
		{name="air", prob=0, param2=0},
		{name="air", prob=0, param2=0},
		{name="air", prob=0, param2=0},
		{name="air", prob=0, param2=0},
		{name="air", prob=0, param2=0},
		{name="air", prob=0, param2=0},
		{name="air", prob=0, param2=0},
		{name="air", prob=0, param2=0},
		{name="air", prob=0, param2=0},
		{name="air", prob=0, param2=0},
		{name="air", prob=0, param2=0},
		{name="air", prob=0, param2=0},
		{name="air", prob=0, param2=0},
		{name="air", prob=0, param2=0},
		{name="air", prob=0, param2=0},
		{name="air", prob=0, param2=0},
		{name="air", prob=0, param2=0},
		{name="air", prob=0, param2=0},
		{name="air", prob=0, param2=0},
		{name="everness:crystal_forest_deep_ocean_sandstone_brick", prob=126, param2=0},
		{name="everness:crystal_forest_deep_ocean_sandstone_brick", prob=254, param2=0},
		{name="everness:crystal_forest_deep_ocean_sandstone_brick", prob=254, param2=0},
		{name="everness:crystal_forest_deep_ocean_sandstone_brick", prob=254, param2=0},
		{name="everness:crystal_forest_deep_ocean_sandstone_brick", prob=254, param2=0},
		{name="everness:crystal_forest_deep_ocean_sandstone_brick", prob=254, param2=0},
		{name="everness:crystal_forest_deep_ocean_sandstone_brick", prob=254, param2=0},
		{name="everness:crystal_forest_deep_ocean_sandstone_brick", prob=254, param2=0},
		{name="everness:crystal_forest_deep_ocean_sandstone_brick", prob=254, param2=0},
		{name="everness:crystal_forest_deep_ocean_sandstone_brick", prob=254, param2=0},
		{name="everness:crystal_forest_deep_ocean_sandstone_brick", prob=254, param2=0},
		{name="everness:crystal_forest_deep_ocean_sandstone_brick", prob=254, param2=0},
		{name="everness:crystal_forest_deep_ocean_sandstone_brick", prob=254, param2=0},
		{name="everness:crystal_forest_deep_ocean_sandstone_block", prob=126, param2=0},
		{name="air", prob=0, param2=0},
		{name="everness:crystal_forest_deep_ocean_sandstone_block", prob=254, param2=0},
		{name="everness:crystal_forest_deep_ocean_sandstone_block", prob=254, param2=0},
		{name="everness:crystal_forest_deep_ocean_sandstone_block", prob=254, param2=0},
		{name="everness:crystal_forest_deep_ocean_sandstone_block", prob=254, param2=0},
		{name="everness:crystal_forest_deep_ocean_sandstone_block", prob=254, param2=0},
		{name="everness:crystal_forest_deep_ocean_sandstone_block", prob=254, param2=0},
		{name="everness:crystal_forest_deep_ocean_sandstone_block", prob=254, param2=0},
		{name="everness:crystal_forest_deep_ocean_sandstone_block", prob=254, param2=0},
		{name="everness:crystal_forest_deep_ocean_sandstone_block", prob=254, param2=0},
		{name="everness:crystal_forest_deep_ocean_sandstone_block", prob=254, param2=0},
		{name="everness:crystal_forest_deep_ocean_sandstone_block", prob=254, param2=0},
		{name="everness:crystal_forest_deep_ocean_sandstone_block", prob=254, param2=0},
		{name="air", prob=0, param2=0},
		{name="air", prob=0, param2=0},
		{name="air", prob=0, param2=0},
		{name="everness:crystal_forest_deep_ocean_sandstone_brick", prob=254, param2=0},
		{name="everness:crystal_forest_deep_ocean_sandstone_brick", prob=254, param2=0},
		{name="everness:crystal_forest_deep_ocean_sandstone_brick", prob=254, param2=0},
		{name="everness:crystal_forest_deep_ocean_sandstone_brick", prob=254, param2=0},
		{name="everness:crystal_forest_deep_ocean_sandstone_brick", prob=254, param2=0},
		{name="everness:crystal_forest_deep_ocean_sandstone_brick", prob=254, param2=0},
		{name="everness:crystal_forest_deep_ocean_sandstone_block", prob=254, param2=0},
		{name="everness:crystal_forest_deep_ocean_sandstone_block", prob=254, param2=0},
		{name="everness:crystal_forest_deep_ocean_sandstone_block", prob=254, param2=0},
		{name="everness:crystal_forest_deep_ocean_sandstone_block", prob=254, param2=0},
		{name="everness:crystal_forest_deep_ocean_sandstone_block", prob=254, param2=0},
		{name="air", prob=0, param2=0},
		{name="air", prob=0, param2=0},
		{name="air", prob=0, param2=0},
		{name="everness:crystal_forest_deep_ocean_sandstone_brick", prob=254, param2=0},
		{name="everness:crystal_forest_deep_ocean_sandstone_brick", prob=254, param2=0},
		{name="everness:crystal_forest_deep_ocean_sandstone_brick", prob=254, param2=0},
		{name="everness:crystal_forest_deep_ocean_sandstone_brick", prob=254, param2=0},
		{name="everness:crystal_forest_deep_ocean_sandstone_brick", prob=254, param2=0},
		{name="everness:crystal_forest_deep_ocean_sandstone_brick", prob=254, param2=0},
		{name="everness:crystal_forest_deep_ocean_sandstone_block", prob=254, param2=0},
		{name="everness:crystal_forest_deep_ocean_sandstone_block", prob=254, param2=0},
		{name="everness:crystal_forest_deep_ocean_sandstone_block", prob=254, param2=0},
		{name="everness:crystal_forest_deep_ocean_sandstone_block", prob=254, param2=0},
		{name="everness:crystal_forest_deep_ocean_sandstone_block", prob=254, param2=0},
		{name="air", prob=0, param2=0},
		{name="air", prob=0, param2=0},
		{name="everness:crystal_forest_deep_ocean_sandstone_brick", prob=254, param2=0},
		{name="everness:crystal_forest_deep_ocean_sandstone_block", prob=254, param2=0},
		{name="everness:crystal_forest_deep_ocean_sandstone_block", prob=254, param2=0},
		{name="everness:crystal_forest_deep_ocean_sandstone_block", prob=254, param2=0},
		{name="everness:crystal_forest_deep_ocean_sandstone_block", prob=254, param2=0},
		{name="everness:crystal_forest_deep_ocean_sandstone_block", prob=254, param2=0},
		{name="everness:crystal_forest_deep_ocean_sandstone_brick", prob=254, param2=0},
		{name="everness:crystal_forest_deep_ocean_sandstone_block", prob=254, param2=0},
		{name="stairs:stair_crystal_forest_deep_ocean_sandstone_block", prob=254, param2=1},
		{name="everness:crystal_forest_deep_ocean_sandstone_block", prob=254, param2=0},
		{name="stairs:stair_crystal_forest_deep_ocean_sandstone_block", prob=254, param2=3},
		{name="everness:crystal_forest_deep_ocean_sandstone_block", prob=254, param2=0},
		{name="air", prob=0, param2=0},
		{name="air", prob=0, param2=0},
		{name="air", prob=0, param2=0},
		{name="everness:crystal_forest_deep_ocean_sandstone_block", prob=254, param2=0},
		{name="everness:crystal_forest_deep_ocean_sandstone_block", prob=254, param2=0},
		{name="everness:crystal_forest_deep_ocean_sandstone_block", prob=254, param2=0},
		{name="everness:crystal_forest_deep_ocean_sandstone_block", prob=254, param2=0},
		{name="everness:crystal_forest_deep_ocean_sandstone_block", prob=254, param2=0},
		{name="air", prob=0, param2=0},
		{name="stairs:slab_crystal_forest_deep_ocean_sandstone_block", prob=254, param2=3},
		{name="air", prob=0, param2=0},
		{name="air", prob=0, param2=0},
		{name="air", prob=0, param2=0},
		{name="stairs:slab_crystal_forest_deep_ocean_sandstone_block", prob=254, param2=3},
		{name="air", prob=0, param2=0},
		{name="air", prob=0, param2=0},
		{name="air", prob=0, param2=0},
		{name="everness:crystal_forest_deep_ocean_sandstone_block", prob=254, param2=0},
		{name="everness:crystal_forest_deep_ocean_sandstone_block", prob=254, param2=0},
		{name="everness:crystal_forest_deep_ocean_sandstone_block", prob=254, param2=0},
		{name="everness:crystal_forest_deep_ocean_sandstone_block", prob=254, param2=0},
		{name="everness:crystal_forest_deep_ocean_sandstone_block", prob=254, param2=0},
		{name="air", prob=0, param2=0},
		{name="air", prob=0, param2=0},
		{name="air", prob=0, param2=0},
		{name="air", prob=0, param2=0},
		{name="air", prob=0, param2=0},
		{name="air", prob=0, param2=0},
		{name="air", prob=0, param2=0},
		{name="air", prob=0, param2=0},
		{name="air", prob=0, param2=0},
		{name="everness:crystal_forest_deep_ocean_sandstone_block", prob=254, param2=0},
		{name="everness:crystal_forest_deep_ocean_sandstone_block", prob=254, param2=0},
		{name="everness:crystal_forest_deep_ocean_sandstone_block", prob=254, param2=0},
		{name="everness:crystal_forest_deep_ocean_sandstone_block", prob=254, param2=0},
		{name="everness:crystal_forest_deep_ocean_sandstone_block", prob=254, param2=0},
		{name="air", prob=0, param2=0},
		{name="air", prob=0, param2=0},
		{name="air", prob=0, param2=0},
		{name="air", prob=0, param2=0},
		{name="air", prob=0, param2=0},
		{name="air", prob=0, param2=0},
		{name="air", prob=0, param2=0},
		{name="air", prob=0, param2=0},
		{name="stairs:stair_crystal_forest_deep_ocean_sandstone_brick", prob=254, param2=20},
		{name="everness:crystal_forest_deep_ocean_sandstone_block", prob=254, param2=0},
		{name="everness:crystal_forest_deep_ocean_sandstone_block", prob=254, param2=0},
		{name="everness:crystal_forest_deep_ocean_sandstone_block", prob=254, param2=0},
		{name="everness:crystal_forest_deep_ocean_sandstone_block", prob=254, param2=0},
		{name="everness:crystal_forest_deep_ocean_sandstone_block", prob=254, param2=0},
		{name="stairs:stair_crystal_forest_deep_ocean_sandstone_brick", prob=254, param2=20},
		{name="air", prob=0, param2=0},
		{name="air", prob=0, param2=0},
		{name="air", prob=0, param2=0},
		{name="air", prob=0, param2=0},
		{name="air", prob=0, param2=0},
		{name="air", prob=0, param2=0},
		{name="air", prob=0, param2=0},
		{name="everness:crystal_forest_deep_ocean_sandstone_brick", prob=254, param2=0},
		{name="stairs:slab_crystal_forest_deep_ocean_sandstone_brick", prob=254, param2=3},
		{name="stairs:slab_crystal_forest_deep_ocean_sandstone_brick", prob=254, param2=3},
		{name="stairs:slab_crystal_forest_deep_ocean_sandstone_brick", prob=254, param2=3},
		{name="stairs:slab_crystal_forest_deep_ocean_sandstone_brick", prob=254, param2=3},
		{name="stairs:slab_crystal_forest_deep_ocean_sandstone_brick", prob=254, param2=1},
		{name="everness:crystal_forest_deep_ocean_sandstone_brick", prob=254, param2=0},
		{name="air", prob=0, param2=0},
		{name="air", prob=0, param2=0},
		{name="air", prob=0, param2=0},
		{name="air", prob=0, param2=0},
		{name="air", prob=0, param2=0},
		{name="air", prob=0, param2=0},
		{name="air", prob=0, param2=0},
		{name="stairs:slab_crystal_forest_deep_ocean_sandstone_block", prob=254, param2=3},
		{name="air", prob=0, param2=0},
		{name="air", prob=0, param2=0},
		{name="air", prob=0, param2=0},
		{name="air", prob=0, param2=0},
		{name="air", prob=0, param2=0},
		{name="stairs:slab_crystal_forest_deep_ocean_sandstone_block", prob=254, param2=3},
		{name="air", prob=0, param2=0},
		{name="air", prob=0, param2=0},
		{name="air", prob=0, param2=0},
		{name="air", prob=0, param2=0},
		{name="air", prob=0, param2=0},
		{name="air", prob=0, param2=0},
		{name="air", prob=0, param2=0},
		{name="air", prob=0, param2=0},
		{name="air", prob=0, param2=0},
		{name="air", prob=0, param2=0},
		{name="air", prob=0, param2=0},
		{name="air", prob=0, param2=0},
		{name="air", prob=0, param2=0},
		{name="air", prob=0, param2=0},
		{name="air", prob=0, param2=0},
		{name="air", prob=0, param2=0},
		{name="air", prob=0, param2=0},
		{name="air", prob=0, param2=0},
		{name="air", prob=0, param2=0},
		{name="air", prob=0, param2=0},
		{name="everness:crystal_forest_deep_ocean_sandstone_brick", prob=126, param2=0},
		{name="everness:crystal_forest_deep_ocean_sandstone_brick", prob=254, param2=0},
		{name="everness:crystal_forest_deep_ocean_sandstone_brick", prob=254, param2=0},
		{name="everness:crystal_forest_deep_ocean_sandstone_brick", prob=254, param2=0},
		{name="everness:crystal_forest_deep_ocean_sandstone_brick", prob=254, param2=0},
		{name="everness:crystal_forest_deep_ocean_sandstone_brick", prob=254, param2=0},
		{name="everness:crystal_forest_deep_ocean_sandstone_brick", prob=254, param2=0},
		{name="everness:crystal_forest_deep_ocean_sandstone_brick", prob=254, param2=0},
		{name="everness:crystal_forest_deep_ocean_sandstone_brick", prob=126, param2=0},
		{name="everness:crystal_forest_deep_ocean_sandstone_brick", prob=126, param2=0},
		{name="everness:crystal_forest_deep_ocean_sandstone_brick", prob=126, param2=0},
		{name="everness:crystal_forest_deep_ocean_sandstone_brick", prob=126, param2=0},
		{name="everness:crystal_forest_deep_ocean_sandstone_block", prob=126, param2=0},
		{name="everness:crystal_forest_deep_ocean_sandstone_block", prob=126, param2=0},
		{name="air", prob=0, param2=0},
		{name="everness:crystal_forest_deep_ocean_sandstone_block", prob=254, param2=0},
		{name="everness:crystal_forest_deep_ocean_sandstone_block", prob=254, param2=0},
		{name="everness:crystal_forest_deep_ocean_sandstone_block", prob=254, param2=0},
		{name="everness:crystal_forest_deep_ocean_sandstone_block", prob=254, param2=0},
		{name="everness:crystal_forest_deep_ocean_sandstone_block", prob=254, param2=0},
		{name="everness:crystal_forest_deep_ocean_sandstone_block", prob=254, param2=0},
		{name="everness:crystal_forest_deep_ocean_sandstone_block", prob=254, param2=0},
		{name="air", prob=0, param2=0},
		{name="air", prob=0, param2=0},
		{name="air", prob=0, param2=0},
		{name="air", prob=0, param2=0},
		{name="air", prob=0, param2=0},
		{name="air", prob=0, param2=0},
		{name="air", prob=0, param2=0},
		{name="everness:crystal_forest_deep_ocean_sandstone_block", prob=254, param2=0},
		{name="air", prob=0, param2=0},
		{name="stairs:stair_crystal_forest_deep_ocean_sandstone_block", prob=254, param2=1},
		{name="everness:crystal_forest_deep_ocean_sandstone_block", prob=254, param2=0},
		{name="stairs:stair_crystal_forest_deep_ocean_sandstone_block", prob=254, param2=3},
		{name="air", prob=0, param2=0},
		{name="everness:crystal_forest_deep_ocean_sandstone_block", prob=254, param2=0},
		{name="air", prob=0, param2=0},
		{name="air", prob=0, param2=0},
		{name="air", prob=0, param2=0},
		{name="air", prob=0, param2=0},
		{name="air", prob=0, param2=0},
		{name="air", prob=0, param2=0},
		{name="air", prob=0, param2=0},
		{name="everness:crystal_forest_deep_ocean_sandstone_block", prob=254, param2=0},
		{name="air", prob=0, param2=0},
		{name="air", prob=0, param2=0},
		{name="everness:crystal_forest_deep_ocean_sandstone_block", prob=254, param2=0},
		{name="air", prob=0, param2=0},
		{name="air", prob=0, param2=0},
		{name="everness:crystal_forest_deep_ocean_sandstone_block", prob=254, param2=0},
		{name="air", prob=0, param2=0},
		{name="air", prob=0, param2=0},
		{name="air", prob=0, param2=0},
		{name="air", prob=0, param2=0},
		{name="air", prob=0, param2=0},
		{name="air", prob=0, param2=0},
		{name="air", prob=0, param2=0},
		{name="everness:crystal_forest_deep_ocean_sandstone_block", prob=254, param2=0},
		{name="everness:crystal_forest_deep_ocean_sandstone_brick", prob=254, param2=0},
		{name="everness:crystal_forest_deep_ocean_sandstone_brick", prob=254, param2=0},
		{name="everness:crystal_forest_deep_ocean_sandstone_brick", prob=254, param2=0},
		{name="everness:crystal_forest_deep_ocean_sandstone_brick", prob=254, param2=0},
		{name="everness:crystal_forest_deep_ocean_sandstone_brick", prob=254, param2=0},
		{name="everness:crystal_forest_deep_ocean_sandstone_block", prob=254, param2=0},
		{name="air", prob=0, param2=0},
		{name="air", prob=0, param2=0},
		{name="air", prob=0, param2=0},
		{name="air", prob=0, param2=0},
		{name="air", prob=0, param2=0},
		{name="air", prob=0, param2=0},
		{name="air", prob=0, param2=0},
		{name="everness:crystal_forest_deep_ocean_sandstone_block", prob=254, param2=0},
		{name="air", prob=0, param2=0},
		{name="air", prob=0, param2=0},
		{name="everness:crystal_forest_deep_ocean_sandstone_brick", prob=254, param2=0},
		{name="air", prob=0, param2=0},
		{name="air", prob=0, param2=0},
		{name="everness:crystal_forest_deep_ocean_sandstone_block", prob=254, param2=0},
		{name="air", prob=0, param2=0},
		{name="air", prob=0, param2=0},
		{name="air", prob=0, param2=0},
		{name="air", prob=0, param2=0},
		{name="air", prob=0, param2=0},
		{name="air", prob=0, param2=0},
		{name="air", prob=0, param2=0},
		{name="everness:crystal_forest_deep_ocean_sandstone_block", prob=254, param2=0},
		{name="air", prob=0, param2=0},
		{name="air", prob=0, param2=0},
		{name="everness:crystal_forest_deep_ocean_sandstone_brick", prob=254, param2=0},
		{name="air", prob=0, param2=0},
		{name="air", prob=0, param2=0},
		{name="everness:crystal_forest_deep_ocean_sandstone_block", prob=254, param2=0},
		{name="air", prob=0, param2=0},
		{name="air", prob=0, param2=0},
		{name="air", prob=0, param2=0},
		{name="air", prob=0, param2=0},
		{name="air", prob=0, param2=0},
		{name="air", prob=0, param2=0},
		{name="air", prob=0, param2=0},
		{name="everness:crystal_forest_deep_ocean_sandstone_block", prob=254, param2=0},
		{name="air", prob=0, param2=0},
		{name="air", prob=0, param2=0},
		{name="everness:crystal_forest_deep_ocean_sandstone_brick", prob=254, param2=0},
		{name="air", prob=0, param2=0},
		{name="air", prob=0, param2=0},
		{name="everness:crystal_forest_deep_ocean_sandstone_block", prob=254, param2=0},
		{name="air", prob=0, param2=0},
		{name="air", prob=0, param2=0},
		{name="air", prob=0, param2=0},
		{name="air", prob=0, param2=0},
		{name="air", prob=0, param2=0},
		{name="air", prob=0, param2=0},
		{name="air", prob=0, param2=0},
		{name="everness:crystal_forest_deep_ocean_sandstone_block", prob=254, param2=0},
		{name="stairs:stair_crystal_forest_deep_ocean_sandstone_brick", prob=254, param2=21},
		{name="stairs:stair_crystal_forest_deep_ocean_sandstone_brick", prob=254, param2=23},
		{name="everness:crystal_forest_deep_ocean_sandstone_brick", prob=254, param2=0},
		{name="stairs:stair_crystal_forest_deep_ocean_sandstone_brick", prob=254, param2=21},
		{name="stairs:stair_crystal_forest_deep_ocean_sandstone_brick", prob=254, param2=23},
		{name="everness:crystal_forest_deep_ocean_sandstone_block", prob=254, param2=0},
		{name="air", prob=0, param2=0},
		{name="air", prob=0, param2=0},
		{name="air", prob=0, param2=0},
		{name="air", prob=0, param2=0},
		{name="air", prob=0, param2=0},
		{name="air", prob=0, param2=0},
		{name="air", prob=0, param2=0},
		{name="everness:crystal_forest_deep_ocean_sandstone_block", prob=254, param2=0},
		{name="everness:crystal_forest_deep_ocean_sandstone_brick", prob=254, param2=0},
		{name="everness:crystal_forest_deep_ocean_sandstone_brick", prob=254, param2=0},
		{name="everness:crystal_forest_deep_ocean_sandstone_brick", prob=254, param2=0},
		{name="everness:crystal_forest_deep_ocean_sandstone_brick", prob=254, param2=0},
		{name="everness:crystal_forest_deep_ocean_sandstone_brick", prob=254, param2=0},
		{name="everness:crystal_forest_deep_ocean_sandstone_block", prob=254, param2=0},
		{name="air", prob=0, param2=0},
		{name="air", prob=0, param2=0},
		{name="air", prob=0, param2=0},
		{name="air", prob=0, param2=0},
		{name="air", prob=0, param2=0},
		{name="air", prob=0, param2=0},
		{name="air", prob=0, param2=0},
		{name="everness:crystal_forest_deep_ocean_sandstone_block", prob=254, param2=0},
		{name="stairs:slab_crystal_forest_deep_ocean_sandstone_block", prob=254, param2=3},
		{name="stairs:stair_crystal_forest_deep_ocean_sandstone_block", prob=254, param2=1},
		{name="everness:crystal_forest_deep_ocean_sandstone_block", prob=254, param2=0},
		{name="stairs:stair_crystal_forest_deep_ocean_sandstone_block", prob=254, param2=3},
		{name="stairs:slab_crystal_forest_deep_ocean_sandstone_block", prob=254, param2=2},
		{name="everness:crystal_forest_deep_ocean_sandstone_block", prob=254, param2=0},
		{name="air", prob=0, param2=0},
		{name="air", prob=0, param2=0},
		{name="air", prob=0, param2=0},
		{name="air", prob=0, param2=0},
		{name="air", prob=0, param2=0},
		{name="air", prob=0, param2=0},
		{name="air", prob=0, param2=0},
		{name="everness:crystal_forest_deep_ocean_sandstone_block", prob=254, param2=0},
		{name="air", prob=0, param2=0},
		{name="air", prob=0, param2=0},
		{name="stairs:slab_crystal_forest_deep_ocean_sandstone_block", prob=254, param2=0},
		{name="air", prob=0, param2=0},
		{name="air", prob=0, param2=0},
		{name="everness:crystal_forest_deep_ocean_sandstone_block", prob=254, param2=0},
		{name="air", prob=0, param2=0},
		{name="air", prob=0, param2=0},
		{name="air", prob=0, param2=0},
		{name="air", prob=0, param2=0},
		{name="air", prob=0, param2=0},
		{name="air", prob=0, param2=0},
		{name="everness:crystal_forest_deep_ocean_sandstone_brick", prob=126, param2=0},
		{name="everness:crystal_forest_deep_ocean_sandstone_brick", prob=126, param2=0},
		{name="everness:crystal_forest_deep_ocean_sandstone_brick", prob=126, param2=0},
		{name="everness:crystal_forest_deep_ocean_sandstone_brick", prob=126, param2=0},
		{name="everness:crystal_forest_deep_ocean_sandstone_brick", prob=126, param2=0},
		{name="everness:crystal_forest_deep_ocean_sandstone_brick", prob=126, param2=0},
		{name="everness:crystal_forest_deep_ocean_sandstone_brick", prob=126, param2=0},
		{name="everness:crystal_forest_deep_ocean_sandstone_brick", prob=126, param2=0},
		{name="everness:crystal_forest_deep_ocean_sandstone_brick", prob=126, param2=0},
		{name="everness:crystal_forest_deep_ocean_sandstone_brick", prob=126, param2=0},
		{name="everness:crystal_forest_deep_ocean_sandstone_brick", prob=126, param2=0},
		{name="everness:crystal_forest_deep_ocean_sandstone_brick", prob=126, param2=0},
		{name="everness:crystal_forest_deep_ocean_sandstone_brick", prob=126, param2=0},
		{name="everness:crystal_forest_deep_ocean_sandstone_brick", prob=126, param2=0},
		{name="air", prob=0, param2=0},
		{name="air", prob=0, param2=0},
		{name="air", prob=0, param2=0},
		{name="air", prob=0, param2=0},
		{name="air", prob=0, param2=0},
		{name="air", prob=0, param2=0},
		{name="air", prob=0, param2=0},
		{name="air", prob=0, param2=0},
		{name="air", prob=0, param2=0},
		{name="air", prob=0, param2=0},
		{name="air", prob=0, param2=0},
		{name="air", prob=0, param2=0},
		{name="air", prob=0, param2=0},
		{name="air", prob=0, param2=0},
		{name="air", prob=0, param2=0},
		{name="air", prob=0, param2=0},
		{name="air", prob=0, param2=0},
		{name="air", prob=0, param2=0},
		{name="air", prob=0, param2=0},
		{name="air", prob=0, param2=0},
		{name="air", prob=0, param2=0},
		{name="air", prob=0, param2=0},
		{name="air", prob=0, param2=0},
		{name="air", prob=0, param2=0},
		{name="air", prob=0, param2=0},
		{name="air", prob=0, param2=0},
		{name="air", prob=0, param2=0},
		{name="air", prob=0, param2=0},
		{name="air", prob=0, param2=0},
		{name="air", prob=0, param2=0},
		{name="air", prob=0, param2=0},
		{name="air", prob=0, param2=0},
		{name="air", prob=0, param2=0},
		{name="air", prob=0, param2=0},
		{name="air", prob=0, param2=0},
		{name="air", prob=0, param2=0},
		{name="air", prob=0, param2=0},
		{name="air", prob=0, param2=0},
		{name="air", prob=0, param2=0},
		{name="air", prob=0, param2=0},
		{name="air", prob=0, param2=0},
		{name="air", prob=0, param2=0},
		{name="air", prob=0, param2=0},
		{name="air", prob=0, param2=0},
		{name="air", prob=0, param2=0},
		{name="air", prob=0, param2=0},
		{name="air", prob=0, param2=0},
		{name="air", prob=0, param2=0},
		{name="air", prob=0, param2=0},
		{name="air", prob=0, param2=0},
		{name="air", prob=0, param2=0},
		{name="air", prob=0, param2=0},
		{name="air", prob=0, param2=0},
		{name="air", prob=0, param2=0},
		{name="air", prob=0, param2=0},
		{name="air", prob=0, param2=0},
		{name="air", prob=0, param2=0},
		{name="air", prob=0, param2=0},
		{name="air", prob=0, param2=0},
		{name="air", prob=0, param2=0},
		{name="air", prob=0, param2=0},
		{name="air", prob=0, param2=0},
		{name="air", prob=0, param2=0},
		{name="air", prob=0, param2=0},
		{name="air", prob=0, param2=0},
		{name="air", prob=0, param2=0},
		{name="air", prob=0, param2=0},
		{name="air", prob=0, param2=0},
		{name="air", prob=0, param2=0},
		{name="air", prob=0, param2=0},
		{name="air", prob=0, param2=0},
		{name="air", prob=0, param2=0},
		{name="air", prob=0, param2=0},
		{name="air", prob=0, param2=0},
		{name="air", prob=0, param2=0},
		{name="air", prob=0, param2=0},
		{name="air", prob=0, param2=0},
		{name="air", prob=0, param2=0},
		{name="air", prob=0, param2=0},
		{name="air", prob=0, param2=0},
		{name="air", prob=0, param2=0},
		{name="air", prob=0, param2=0},
		{name="air", prob=0, param2=0},
		{name="air", prob=0, param2=0},
		{name="air", prob=0, param2=0},
		{name="air", prob=0, param2=0},
		{name="air", prob=0, param2=0},
		{name="air", prob=0, param2=0},
		{name="air", prob=0, param2=0},
		{name="air", prob=0, param2=0},
		{name="air", prob=0, param2=0},
		{name="air", prob=0, param2=0},
		{name="air", prob=0, param2=0},
		{name="air", prob=0, param2=0},
		{name="air", prob=0, param2=0},
		{name="air", prob=0, param2=0},
		{name="air", prob=0, param2=0},
		{name="air", prob=0, param2=0},
		{name="air", prob=0, param2=0},
		{name="air", prob=0, param2=0},
		{name="air", prob=0, param2=0},
		{name="air", prob=0, param2=0},
		{name="air", prob=0, param2=0},
		{name="air", prob=0, param2=0},
		{name="air", prob=0, param2=0},
		{name="air", prob=0, param2=0},
		{name="air", prob=0, param2=0},
		{name="air", prob=0, param2=0},
		{name="air", prob=0, param2=0},
		{name="air", prob=0, param2=0},
		{name="air", prob=0, param2=0},
		{name="air", prob=0, param2=0},
		{name="air", prob=0, param2=0},
		{name="air", prob=0, param2=0},
		{name="air", prob=0, param2=0},
		{name="air", prob=0, param2=0},
		{name="air", prob=0, param2=0},
		{name="air", prob=0, param2=0},
		{name="air", prob=0, param2=0},
		{name="air", prob=0, param2=0},
		{name="air", prob=0, param2=0},
		{name="air", prob=0, param2=0},
		{name="air", prob=0, param2=0},
		{name="air", prob=0, param2=0},
		{name="air", prob=0, param2=0},
		{name="air", prob=0, param2=0},
		{name="air", prob=0, param2=0},
		{name="air", prob=0, param2=0},
		{name="air", prob=0, param2=0},
		{name="air", prob=0, param2=0},
		{name="air", prob=0, param2=0},
		{name="air", prob=0, param2=0},
		{name="air", prob=0, param2=0},
		{name="air", prob=0, param2=0},
		{name="air", prob=0, param2=0},
		{name="air", prob=0, param2=0},
		{name="air", prob=0, param2=0},
		{name="air", prob=0, param2=0},
		{name="air", prob=0, param2=0},
		{name="air", prob=0, param2=0},
		{name="air", prob=0, param2=0},
		{name="air", prob=0, param2=0},
		{name="air", prob=0, param2=0},
		{name="air", prob=0, param2=0},
		{name="air", prob=0, param2=0},
		{name="air", prob=0, param2=0},
		{name="air", prob=0, param2=0},
		{name="air", prob=0, param2=0},
		{name="air", prob=0, param2=0},
		{name="air", prob=0, param2=0},
		{name="air", prob=0, param2=0},
		{name="air", prob=0, param2=0},
		{name="air", prob=0, param2=0},
		{name="air", prob=0, param2=0},
	},
}
