schematic = {
	size = {x=7, y=6, z=7},
	yslice_prob = {
		{ypos=0, prob=254},
		{ypos=1, prob=254},
		{ypos=2, prob=254},
		{ypos=3, prob=254},
		{ypos=4, prob=254},
		{ypos=5, prob=254},
	},
	data = {
		{name="everness:quartz_block", prob=254, param2=0, force_place=true},
		{name="everness:quartz_block", prob=254, param2=0, force_place=true},
		{name="everness:quartz_block", prob=254, param2=0, force_place=true},
		{name="everness:quartz_block", prob=254, param2=0, force_place=true},
		{name="everness:quartz_block", prob=254, param2=0, force_place=true},
		{name="everness:quartz_block", prob=254, param2=0, force_place=true},
		{name="everness:quartz_block", prob=254, param2=0, force_place=true},
		{name="everness:quartz_block", prob=126, param2=0},
		{name="air", prob=254, param2=0},
		{name="air", prob=254, param2=0},
		{name="air", prob=254, param2=0},
		{name="air", prob=254, param2=0},
		{name="air", prob=254, param2=0},
		{name="everness:quartz_block", prob=126, param2=0},
		{name="air", prob=254, param2=0},
		{name="air", prob=254, param2=0},
		{name="air", prob=254, param2=0},
		{name="air", prob=254, param2=0},
		{name="air", prob=254, param2=0},
		{name="air", prob=254, param2=0},
		{name="air", prob=254, param2=0},
		{name="air", prob=254, param2=0},
		{name="air", prob=254, param2=0},
		{name="air", prob=254, param2=0},
		{name="air", prob=254, param2=0},
		{name="air", prob=254, param2=0},
		{name="air", prob=254, param2=0},
		{name="air", prob=254, param2=0},
		{name="air", prob=254, param2=0},
		{name="air", prob=254, param2=0},
		{name="air", prob=254, param2=0},
		{name="air", prob=254, param2=0},
		{name="air", prob=254, param2=0},
		{name="air", prob=254, param2=0},
		{name="air", prob=254, param2=0},
		{name="air", prob=254, param2=0},
		{name="everness:quartz_chiseled", prob=126, param2=0},
		{name="air", prob=254, param2=0},
		{name="air", prob=254, param2=0},
		{name="air", prob=254, param2=0},
		{name="everness:quartz_chiseled", prob=126, param2=0},
		{name="air", prob=254, param2=0},
		{name="everness:quartz_block", prob=254, param2=0, force_place=true},
		{name="everness:quartz_block", prob=254, param2=0, force_place=true},
		{name="everness:quartz_block", prob=254, param2=0, force_place=true},
		{name="everness:quartz_block", prob=254, param2=0, force_place=true},
		{name="everness:quartz_block", prob=254, param2=0, force_place=true},
		{name="everness:quartz_block", prob=254, param2=0, force_place=true},
		{name="everness:quartz_block", prob=254, param2=0, force_place=true},
		{name="air", prob=254, param2=0},
		{name="everness:quartz_pillar", prob=254, param2=1},
		{name="everness:quartz_block", prob=126, param2=0},
		{name="air", prob=254, param2=0},
		{name="air", prob=254, param2=0},
		{name="everness:quartz_pillar", prob=254, param2=3},
		{name="air", prob=254, param2=0},
		{name="air", prob=254, param2=0},
		{name="everness:quartz_pillar", prob=254, param2=1},
		{name="air", prob=254, param2=0},
		{name="air", prob=254, param2=0},
		{name="air", prob=254, param2=0},
		{name="everness:quartz_pillar", prob=254, param2=3},
		{name="air", prob=254, param2=0},
		{name="air", prob=254, param2=0},
		{name="everness:quartz_pillar", prob=254, param2=1},
		{name="air", prob=254, param2=0},
		{name="air", prob=254, param2=0},
		{name="air", prob=254, param2=0},
		{name="everness:quartz_pillar", prob=254, param2=3},
		{name="air", prob=254, param2=0},
		{name="air", prob=254, param2=0},
		{name="everness:quartz_pillar", prob=254, param2=1},
		{name="air", prob=254, param2=0},
		{name="air", prob=254, param2=0},
		{name="air", prob=254, param2=0},
		{name="everness:quartz_pillar", prob=254, param2=3},
		{name="air", prob=254, param2=0},
		{name="everness:quartz_chiseled", prob=126, param2=0},
		{name="everness:quartz_chiseled", prob=254, param2=0},
		{name="everness:quartz_chiseled", prob=126, param2=0},
		{name="everness:quartz_chiseled", prob=254, param2=0},
		{name="everness:quartz_chiseled", prob=126, param2=0},
		{name="everness:quartz_chiseled", prob=254, param2=0},
		{name="everness:quartz_chiseled", prob=126, param2=0},
		{name="everness:quartz_block", prob=254, param2=0, force_place=true},
		{name="everness:quartz_block", prob=254, param2=0, force_place=true},
		{name="everness:quartz_block", prob=254, param2=0, force_place=true},
		{name="everness:quartz_block", prob=254, param2=0, force_place=true},
		{name="everness:quartz_block", prob=254, param2=0, force_place=true},
		{name="everness:quartz_block", prob=254, param2=0, force_place=true},
		{name="everness:quartz_block", prob=254, param2=0, force_place=true},
		{name="air", prob=254, param2=0},
		{name="everness:quartz_block", prob=126, param2=0},
		{name="air", prob=254, param2=0},
		{name="air", prob=254, param2=0},
		{name="air", prob=254, param2=0},
		{name="air", prob=254, param2=0},
		{name="air", prob=254, param2=0},
		{name="air", prob=254, param2=0},
		{name="air", prob=254, param2=0},
		{name="air", prob=254, param2=0},
		{name="air", prob=254, param2=0},
		{name="air", prob=254, param2=0},
		{name="air", prob=254, param2=0},
		{name="air", prob=254, param2=0},
		{name="air", prob=254, param2=0},
		{name="air", prob=254, param2=0},
		{name="air", prob=254, param2=0},
		{name="air", prob=254, param2=0},
		{name="air", prob=254, param2=0},
		{name="air", prob=254, param2=0},
		{name="air", prob=254, param2=0},
		{name="air", prob=254, param2=0},
		{name="air", prob=254, param2=0},
		{name="air", prob=254, param2=0},
		{name="air", prob=254, param2=0},
		{name="air", prob=254, param2=0},
		{name="air", prob=254, param2=0},
		{name="air", prob=254, param2=0},
		{name="air", prob=254, param2=0},
		{name="everness:quartz_chiseled", prob=126, param2=0},
		{name="air", prob=254, param2=0},
		{name="air", prob=254, param2=0},
		{name="air", prob=254, param2=0},
		{name="everness:quartz_chiseled", prob=126, param2=0},
		{name="air", prob=254, param2=0},
		{name="everness:quartz_block", prob=254, param2=0, force_place=true},
		{name="everness:quartz_block", prob=254, param2=0, force_place=true},
		{name="everness:quartz_block", prob=254, param2=0, force_place=true},
		{name="everness:quartz_block", prob=254, param2=0, force_place=true},
		{name="everness:quartz_block", prob=254, param2=0, force_place=true},
		{name="everness:quartz_block", prob=254, param2=0, force_place=true},
		{name="everness:quartz_block", prob=254, param2=0, force_place=true},
		{name="air", prob=254, param2=0},
		{name="air", prob=254, param2=0},
		{name="air", prob=254, param2=0},
		{name="air", prob=254, param2=0},
		{name="air", prob=254, param2=0},
		{name="air", prob=254, param2=0},
		{name="air", prob=254, param2=0},
		{name="air", prob=254, param2=0},
		{name="air", prob=254, param2=0},
		{name="air", prob=254, param2=0},
		{name="air", prob=254, param2=0},
		{name="air", prob=254, param2=0},
		{name="air", prob=254, param2=0},
		{name="air", prob=254, param2=0},
		{name="air", prob=254, param2=0},
		{name="air", prob=254, param2=0},
		{name="air", prob=254, param2=0},
		{name="air", prob=254, param2=0},
		{name="air", prob=254, param2=0},
		{name="air", prob=254, param2=0},
		{name="air", prob=254, param2=0},
		{name="air", prob=254, param2=0},
		{name="air", prob=254, param2=0},
		{name="air", prob=254, param2=0},
		{name="air", prob=254, param2=0},
		{name="air", prob=254, param2=0},
		{name="air", prob=254, param2=0},
		{name="air", prob=254, param2=0},
		{name="air", prob=254, param2=0},
		{name="everness:quartz_chiseled", prob=254, param2=0},
		{name="air", prob=254, param2=0},
		{name="air", prob=254, param2=0},
		{name="air", prob=254, param2=0},
		{name="everness:quartz_chiseled", prob=254, param2=0},
		{name="air", prob=254, param2=0},
		{name="everness:quartz_block", prob=254, param2=0, force_place=true},
		{name="everness:quartz_block", prob=254, param2=0, force_place=true},
		{name="everness:quartz_block", prob=254, param2=0, force_place=true},
		{name="everness:quartz_block", prob=254, param2=0, force_place=true},
		{name="everness:quartz_block", prob=254, param2=0, force_place=true},
		{name="everness:quartz_block", prob=254, param2=0, force_place=true},
		{name="everness:quartz_block", prob=254, param2=0, force_place=true},
		{name="air", prob=254, param2=0},
		{name="air", prob=254, param2=0},
		{name="air", prob=254, param2=0},
		{name="everness:quartz_block", prob=254, param2=0},
		{name="everness:quartz_block", prob=126, param2=0},
		{name="air", prob=254, param2=0},
		{name="air", prob=254, param2=0},
		{name="air", prob=254, param2=0},
		{name="air", prob=254, param2=0},
		{name="air", prob=254, param2=0},
		{name="everness:quartz_block", prob=126, param2=0},
		{name="air", prob=254, param2=0},
		{name="air", prob=254, param2=0},
		{name="air", prob=254, param2=0},
		{name="air", prob=254, param2=0},
		{name="air", prob=254, param2=0},
		{name="air", prob=254, param2=0},
		{name="air", prob=254, param2=0},
		{name="air", prob=254, param2=0},
		{name="air", prob=254, param2=0},
		{name="air", prob=254, param2=0},
		{name="air", prob=254, param2=0},
		{name="air", prob=254, param2=0},
		{name="air", prob=254, param2=0},
		{name="air", prob=254, param2=0},
		{name="air", prob=254, param2=0},
		{name="air", prob=254, param2=0},
		{name="air", prob=254, param2=0},
		{name="air", prob=254, param2=0},
		{name="everness:quartz_chiseled", prob=126, param2=0},
		{name="air", prob=254, param2=0},
		{name="air", prob=254, param2=0},
		{name="air", prob=254, param2=0},
		{name="everness:quartz_chiseled", prob=126, param2=0},
		{name="air", prob=254, param2=0},
		{name="everness:quartz_block", prob=254, param2=0, force_place=true},
		{name="everness:quartz_block", prob=254, param2=0, force_place=true},
		{name="everness:quartz_block", prob=254, param2=0, force_place=true},
		{name="everness:quartz_block", prob=254, param2=0, force_place=true},
		{name="everness:quartz_block", prob=254, param2=0, force_place=true},
		{name="everness:quartz_block", prob=254, param2=0, force_place=true},
		{name="everness:quartz_block", prob=254, param2=0, force_place=true},
		{name="everness:quartz_block", prob=126, param2=0},
		{name="everness:quartz_pillar", prob=254, param2=0},
		{name="air", prob=254, param2=0},
		{name="air", prob=254, param2=0},
		{name="air", prob=254, param2=0},
		{name="everness:quartz_pillar", prob=254, param2=3},
		{name="everness:quartz_block", prob=126, param2=0},
		{name="air", prob=254, param2=0},
		{name="everness:quartz_pillar", prob=254, param2=0},
		{name="air", prob=254, param2=0},
		{name="air", prob=254, param2=0},
		{name="air", prob=254, param2=0},
		{name="everness:quartz_pillar", prob=254, param2=3},
		{name="air", prob=254, param2=0},
		{name="air", prob=254, param2=0},
		{name="everness:quartz_pillar", prob=254, param2=0},
		{name="air", prob=254, param2=0},
		{name="air", prob=254, param2=0},
		{name="air", prob=254, param2=0},
		{name="everness:quartz_pillar", prob=254, param2=3},
		{name="air", prob=254, param2=0},
		{name="air", prob=254, param2=0},
		{name="everness:quartz_pillar", prob=254, param2=0},
		{name="air", prob=254, param2=0},
		{name="air", prob=254, param2=0},
		{name="air", prob=254, param2=0},
		{name="everness:quartz_pillar", prob=254, param2=3},
		{name="air", prob=254, param2=0},
		{name="everness:quartz_chiseled", prob=126, param2=0},
		{name="everness:quartz_chiseled", prob=254, param2=0},
		{name="everness:quartz_chiseled", prob=126, param2=0},
		{name="everness:quartz_chiseled", prob=254, param2=0},
		{name="everness:quartz_chiseled", prob=126, param2=0},
		{name="everness:quartz_chiseled", prob=254, param2=0},
		{name="everness:quartz_chiseled", prob=126, param2=0},
		{name="everness:quartz_block", prob=254, param2=0, force_place=true},
		{name="everness:quartz_block", prob=254, param2=0, force_place=true},
		{name="everness:quartz_block", prob=254, param2=0, force_place=true},
		{name="everness:quartz_block", prob=254, param2=0, force_place=true},
		{name="everness:quartz_block", prob=254, param2=0, force_place=true},
		{name="everness:quartz_block", prob=254, param2=0, force_place=true},
		{name="everness:quartz_block", prob=254, param2=0, force_place=true},
		{name="everness:quartz_block", prob=126, param2=0},
		{name="everness:quartz_block", prob=126, param2=0},
		{name="air", prob=254, param2=0},
		{name="air", prob=254, param2=0},
		{name="air", prob=254, param2=0},
		{name="everness:quartz_block", prob=126, param2=0},
		{name="everness:quartz_block", prob=126, param2=0},
		{name="air", prob=254, param2=0},
		{name="air", prob=254, param2=0},
		{name="air", prob=254, param2=0},
		{name="air", prob=254, param2=0},
		{name="air", prob=254, param2=0},
		{name="air", prob=254, param2=0},
		{name="air", prob=254, param2=0},
		{name="air", prob=254, param2=0},
		{name="air", prob=254, param2=0},
		{name="air", prob=254, param2=0},
		{name="air", prob=254, param2=0},
		{name="air", prob=254, param2=0},
		{name="air", prob=254, param2=0},
		{name="air", prob=254, param2=0},
		{name="air", prob=254, param2=0},
		{name="air", prob=254, param2=0},
		{name="air", prob=254, param2=0},
		{name="air", prob=254, param2=0},
		{name="air", prob=254, param2=0},
		{name="air", prob=254, param2=0},
		{name="air", prob=254, param2=0},
		{name="air", prob=254, param2=0},
		{name="everness:quartz_chiseled", prob=126, param2=0},
		{name="air", prob=254, param2=0},
		{name="air", prob=254, param2=0},
		{name="air", prob=254, param2=0},
		{name="everness:quartz_chiseled", prob=126, param2=0},
		{name="air", prob=254, param2=0},
	},
}
