schematic = {
	size = {x=8, y=4, z=8},
	yslice_prob = {
		{ypos=0, prob=254},
		{ypos=1, prob=254},
		{ypos=2, prob=254},
		{ypos=3, prob=254},
	},
	data = {
		{name="everness:dirt_with_cursed_grass", prob=254, param2=0},
		{name="everness:dirt_with_cursed_grass", prob=254, param2=0},
		{name="everness:dirt_with_cursed_grass", prob=254, param2=0},
		{name="everness:dirt_with_cursed_grass", prob=254, param2=0},
		{name="everness:dirt_with_cursed_grass", prob=254, param2=0},
		{name="everness:dirt_with_cursed_grass", prob=254, param2=0},
		{name="everness:dirt_with_cursed_grass", prob=254, param2=0},
		{name="everness:dirt_with_cursed_grass", prob=254, param2=0},
		{name="air", prob=254, param2=0},
		{name="air", prob=254, param2=0},
		{name="air", prob=254, param2=0},
		{name="air", prob=254, param2=0},
		{name="air", prob=254, param2=0},
		{name="air", prob=254, param2=0},
		{name="air", prob=254, param2=0},
		{name="air", prob=254, param2=0},
		{name="air", prob=254, param2=0},
		{name="air", prob=254, param2=0},
		{name="air", prob=254, param2=0},
		{name="air", prob=254, param2=0},
		{name="air", prob=254, param2=0},
		{name="air", prob=254, param2=0},
		{name="air", prob=254, param2=0},
		{name="air", prob=254, param2=0},
		{name="air", prob=254, param2=0},
		{name="air", prob=254, param2=0},
		{name="air", prob=254, param2=0},
		{name="air", prob=254, param2=0},
		{name="air", prob=254, param2=0},
		{name="air", prob=254, param2=0},
		{name="air", prob=254, param2=0},
		{name="air", prob=254, param2=0},
		{name="everness:dirt_with_cursed_grass", prob=254, param2=0},
		{name="everness:dirt_with_cursed_grass", prob=254, param2=0},
		{name="everness:dirt_with_cursed_grass", prob=254, param2=0},
		{name="everness:dirt_with_cursed_grass", prob=254, param2=0},
		{name="everness:dirt_with_cursed_grass", prob=254, param2=0},
		{name="everness:dirt_with_cursed_grass", prob=254, param2=0},
		{name="everness:dirt_with_cursed_grass", prob=254, param2=0},
		{name="everness:dirt_with_cursed_grass", prob=254, param2=0},
		{name="air", prob=254, param2=0},
		{name="air", prob=254, param2=0},
		{name="air", prob=254, param2=0},
		{name="air", prob=254, param2=0},
		{name="air", prob=254, param2=0},
		{name="air", prob=254, param2=0},
		{name="air", prob=254, param2=0},
		{name="air", prob=254, param2=0},
		{name="air", prob=254, param2=0},
		{name="air", prob=254, param2=0},
		{name="air", prob=254, param2=0},
		{name="air", prob=254, param2=0},
		{name="air", prob=254, param2=0},
		{name="air", prob=254, param2=0},
		{name="air", prob=254, param2=0},
		{name="air", prob=254, param2=0},
		{name="air", prob=254, param2=0},
		{name="air", prob=254, param2=0},
		{name="air", prob=254, param2=0},
		{name="air", prob=254, param2=0},
		{name="air", prob=254, param2=0},
		{name="air", prob=254, param2=0},
		{name="air", prob=254, param2=0},
		{name="air", prob=254, param2=0},
		{name="everness:dirt_with_cursed_grass", prob=254, param2=0},
		{name="everness:dirt_with_cursed_grass", prob=254, param2=0},
		{name="everness:dirt_with_cursed_grass", prob=254, param2=0},
		{name="everness:dirt_with_cursed_grass", prob=254, param2=0},
		{name="everness:dirt_with_cursed_grass", prob=254, param2=0},
		{name="everness:dirt_with_cursed_grass", prob=254, param2=0},
		{name="everness:dirt_with_cursed_grass", prob=254, param2=0},
		{name="everness:dirt_with_cursed_grass", prob=254, param2=0},
		{name="air", prob=254, param2=0},
		{name="air", prob=254, param2=0},
		{name="air", prob=254, param2=0},
		{name="air", prob=254, param2=0},
		{name="default:fence_wood", prob=254, param2=0, force_place=true},
		{name="air", prob=254, param2=0},
		{name="air", prob=254, param2=0},
		{name="air", prob=254, param2=0},
		{name="air", prob=254, param2=0},
		{name="air", prob=254, param2=0},
		{name="air", prob=254, param2=0},
		{name="air", prob=254, param2=0},
		{name="air", prob=254, param2=0},
		{name="air", prob=254, param2=0},
		{name="air", prob=254, param2=0},
		{name="air", prob=254, param2=0},
		{name="air", prob=254, param2=0},
		{name="air", prob=254, param2=0},
		{name="air", prob=254, param2=0},
		{name="air", prob=254, param2=0},
		{name="air", prob=254, param2=0},
		{name="air", prob=254, param2=0},
		{name="air", prob=254, param2=0},
		{name="air", prob=254, param2=0},
		{name="everness:dirt_with_cursed_grass", prob=254, param2=0},
		{name="everness:dirt_with_cursed_grass", prob=254, param2=0},
		{name="everness:dirt_with_cursed_grass", prob=254, param2=0},
		{name="everness:dirt_with_cursed_grass", prob=254, param2=0},
		{name="everness:dirt_with_cursed_grass", prob=254, param2=0},
		{name="everness:dirt_with_cursed_grass", prob=254, param2=0},
		{name="everness:dirt_with_cursed_grass", prob=254, param2=0},
		{name="everness:dirt_with_cursed_grass", prob=254, param2=0},
		{name="default:fence_wood", prob=254, param2=0},
		{name="default:fence_wood", prob=254, param2=0},
		{name="default:fence_wood", prob=254, param2=0},
		{name="air", prob=254, param2=0},
		{name="default:fence_wood", prob=254, param2=0, force_place=true},
		{name="air", prob=254, param2=0},
		{name="air", prob=254, param2=0},
		{name="air", prob=254, param2=0},
		{name="air", prob=254, param2=0},
		{name="air", prob=254, param2=0},
		{name="air", prob=254, param2=0},
		{name="air", prob=254, param2=0},
		{name="air", prob=254, param2=0},
		{name="air", prob=254, param2=0},
		{name="air", prob=254, param2=0},
		{name="air", prob=254, param2=0},
		{name="air", prob=254, param2=0},
		{name="air", prob=254, param2=0},
		{name="air", prob=254, param2=0},
		{name="air", prob=254, param2=0},
		{name="air", prob=254, param2=0},
		{name="default:torch_wall", prob=254, param2=4, force_place=true},
		{name="air", prob=254, param2=0},
		{name="air", prob=254, param2=0},
		{name="everness:dirt_with_cursed_grass", prob=254, param2=0},
		{name="everness:dirt_with_cursed_grass", prob=254, param2=0},
		{name="everness:dirt_with_cursed_grass", prob=254, param2=0},
		{name="everness:dirt_with_cursed_grass", prob=254, param2=0},
		{name="everness:dirt_with_cursed_grass", prob=254, param2=0},
		{name="everness:dirt_with_cursed_grass", prob=254, param2=0},
		{name="everness:dirt_with_cursed_grass", prob=254, param2=0},
		{name="everness:dirt_with_cursed_grass", prob=254, param2=0},
		{name="default:fence_wood", prob=254, param2=0},
		{name="air", prob=254, param2=0},
		{name="air", prob=254, param2=0},
		{name="air", prob=254, param2=0},
		{name="default:fence_wood", prob=254, param2=0, force_place=true},
		{name="default:fence_wood", prob=254, param2=0, force_place=true},
		{name="default:fence_wood", prob=254, param2=0, force_place=true},
		{name="default:fence_wood", prob=254, param2=0, force_place=true},
		{name="air", prob=254, param2=0},
		{name="air", prob=254, param2=0},
		{name="air", prob=254, param2=0},
		{name="air", prob=254, param2=0},
		{name="air", prob=254, param2=0},
		{name="default:fence_wood", prob=254, param2=0, force_place=true},
		{name="air", prob=254, param2=0},
		{name="air", prob=254, param2=0},
		{name="air", prob=254, param2=0},
		{name="air", prob=254, param2=0},
		{name="air", prob=254, param2=0},
		{name="air", prob=254, param2=0},
		{name="air", prob=254, param2=0},
		{name="default:wood", prob=254, param2=0, force_place=true},
		{name="air", prob=254, param2=0},
		{name="air", prob=254, param2=0},
		{name="everness:dirt_with_cursed_grass", prob=254, param2=0},
		{name="everness:dirt_with_cursed_grass", prob=254, param2=0},
		{name="everness:dirt_with_cursed_grass", prob=254, param2=0},
		{name="everness:dirt_with_cursed_grass", prob=254, param2=0},
		{name="everness:dirt_with_cursed_grass", prob=254, param2=0},
		{name="everness:dirt_with_cursed_grass", prob=254, param2=0},
		{name="everness:dirt_with_cursed_grass", prob=254, param2=0},
		{name="everness:dirt_with_cursed_grass", prob=254, param2=0},
		{name="default:fence_wood", prob=254, param2=0},
		{name="air", prob=254, param2=0},
		{name="air", prob=254, param2=0},
		{name="air", prob=254, param2=0},
		{name="air", prob=254, param2=0},
		{name="air", prob=254, param2=0},
		{name="air", prob=254, param2=0},
		{name="air", prob=254, param2=0},
		{name="air", prob=254, param2=0},
		{name="air", prob=254, param2=0},
		{name="air", prob=254, param2=0},
		{name="air", prob=254, param2=0},
		{name="air", prob=254, param2=0},
		{name="air", prob=254, param2=0},
		{name="air", prob=254, param2=0},
		{name="air", prob=254, param2=0},
		{name="air", prob=254, param2=0},
		{name="air", prob=254, param2=0},
		{name="air", prob=254, param2=0},
		{name="air", prob=254, param2=0},
		{name="air", prob=254, param2=0},
		{name="air", prob=254, param2=0},
		{name="air", prob=254, param2=0},
		{name="air", prob=254, param2=0},
		{name="everness:dirt_with_cursed_grass", prob=254, param2=0},
		{name="everness:dirt_with_cursed_grass", prob=254, param2=0},
		{name="everness:dirt_with_cursed_grass", prob=254, param2=0},
		{name="everness:dirt_with_cursed_grass", prob=254, param2=0},
		{name="everness:dirt_with_cursed_grass", prob=254, param2=0},
		{name="everness:dirt_with_cursed_grass", prob=254, param2=0},
		{name="everness:dirt_with_cursed_grass", prob=254, param2=0},
		{name="everness:dirt_with_cursed_grass", prob=254, param2=0},
		{name="air", prob=254, param2=0},
		{name="air", prob=254, param2=0},
		{name="air", prob=254, param2=0},
		{name="air", prob=254, param2=0},
		{name="air", prob=254, param2=0},
		{name="air", prob=254, param2=0},
		{name="air", prob=254, param2=0},
		{name="air", prob=254, param2=0},
		{name="air", prob=254, param2=0},
		{name="air", prob=254, param2=0},
		{name="air", prob=254, param2=0},
		{name="air", prob=254, param2=0},
		{name="air", prob=254, param2=0},
		{name="air", prob=254, param2=0},
		{name="air", prob=254, param2=0},
		{name="air", prob=254, param2=0},
		{name="air", prob=254, param2=0},
		{name="air", prob=254, param2=0},
		{name="air", prob=254, param2=0},
		{name="air", prob=254, param2=0},
		{name="air", prob=254, param2=0},
		{name="air", prob=254, param2=0},
		{name="air", prob=254, param2=0},
		{name="air", prob=254, param2=0},
		{name="everness:dirt_with_cursed_grass", prob=254, param2=0},
		{name="everness:dirt_with_cursed_grass", prob=254, param2=0},
		{name="everness:dirt_with_cursed_grass", prob=254, param2=0},
		{name="everness:dirt_with_cursed_grass", prob=254, param2=0},
		{name="everness:dirt_with_cursed_grass", prob=254, param2=0},
		{name="everness:dirt_with_cursed_grass", prob=254, param2=0},
		{name="everness:dirt_with_cursed_grass", prob=254, param2=0},
		{name="everness:dirt_with_cursed_grass", prob=254, param2=0},
		{name="air", prob=254, param2=0},
		{name="air", prob=254, param2=0},
		{name="air", prob=254, param2=0},
		{name="air", prob=254, param2=0},
		{name="air", prob=254, param2=0},
		{name="air", prob=254, param2=0},
		{name="air", prob=254, param2=0},
		{name="air", prob=254, param2=0},
		{name="air", prob=254, param2=0},
		{name="air", prob=254, param2=0},
		{name="air", prob=254, param2=0},
		{name="air", prob=254, param2=0},
		{name="air", prob=254, param2=0},
		{name="air", prob=254, param2=0},
		{name="air", prob=254, param2=0},
		{name="air", prob=254, param2=0},
		{name="air", prob=254, param2=0},
		{name="air", prob=254, param2=0},
		{name="air", prob=254, param2=0},
		{name="air", prob=254, param2=0},
		{name="air", prob=254, param2=0},
		{name="air", prob=254, param2=0},
		{name="air", prob=254, param2=0},
		{name="air", prob=254, param2=0},
	},
}
