schematic = {
	size = {x=11, y=17, z=12},
	yslice_prob = {
		{ypos=0, prob=254},
		{ypos=1, prob=254},
		{ypos=2, prob=254},
		{ypos=3, prob=254},
		{ypos=4, prob=254},
		{ypos=5, prob=254},
		{ypos=6, prob=254},
		{ypos=7, prob=254},
		{ypos=8, prob=254},
		{ypos=9, prob=254},
		{ypos=10, prob=254},
		{ypos=11, prob=254},
		{ypos=12, prob=254},
		{ypos=13, prob=254},
		{ypos=14, prob=254},
		{ypos=15, prob=254},
		{ypos=16, prob=254},
	},
	data = {
		{name="everness:coral_deep_ocean_sandstone_block", prob=126, param2=0},
		{name="everness:coral_deep_ocean_sandstone_block", prob=126, param2=0},
		{name="everness:coral_deep_ocean_sandstone_block", prob=126, param2=0},
		{name="everness:coral_deep_ocean_sandstone_block", prob=126, param2=0},
		{name="everness:coral_deep_ocean_sandstone_block", prob=126, param2=0},
		{name="everness:coral_deep_ocean_sandstone_block", prob=126, param2=0},
		{name="everness:coral_deep_ocean_sandstone_block", prob=126, param2=0},
		{name="everness:coral_deep_ocean_sandstone_block", prob=126, param2=0},
		{name="everness:coral_deep_ocean_sandstone_block", prob=126, param2=0},
		{name="everness:coral_deep_ocean_sandstone_block", prob=126, param2=0},
		{name="everness:coral_deep_ocean_sandstone_block", prob=126, param2=0},
		{name="air", prob=0, param2=0},
		{name="air", prob=0, param2=0},
		{name="air", prob=0, param2=0},
		{name="air", prob=0, param2=0},
		{name="air", prob=0, param2=0},
		{name="air", prob=0, param2=0},
		{name="air", prob=0, param2=0},
		{name="air", prob=0, param2=0},
		{name="air", prob=0, param2=0},
		{name="air", prob=0, param2=0},
		{name="air", prob=0, param2=0},
		{name="air", prob=0, param2=0},
		{name="air", prob=0, param2=0},
		{name="air", prob=0, param2=0},
		{name="air", prob=0, param2=0},
		{name="air", prob=0, param2=0},
		{name="air", prob=0, param2=0},
		{name="air", prob=0, param2=0},
		{name="air", prob=0, param2=0},
		{name="air", prob=0, param2=0},
		{name="air", prob=0, param2=0},
		{name="air", prob=0, param2=0},
		{name="air", prob=0, param2=0},
		{name="air", prob=0, param2=0},
		{name="air", prob=0, param2=0},
		{name="air", prob=0, param2=0},
		{name="air", prob=0, param2=0},
		{name="air", prob=0, param2=0},
		{name="air", prob=0, param2=0},
		{name="air", prob=0, param2=0},
		{name="air", prob=0, param2=0},
		{name="air", prob=0, param2=0},
		{name="air", prob=0, param2=0},
		{name="air", prob=0, param2=0},
		{name="air", prob=0, param2=0},
		{name="air", prob=0, param2=0},
		{name="air", prob=0, param2=0},
		{name="air", prob=0, param2=0},
		{name="air", prob=0, param2=0},
		{name="air", prob=0, param2=0},
		{name="air", prob=0, param2=0},
		{name="air", prob=0, param2=0},
		{name="air", prob=0, param2=0},
		{name="air", prob=0, param2=0},
		{name="air", prob=0, param2=0},
		{name="air", prob=0, param2=0},
		{name="air", prob=0, param2=0},
		{name="air", prob=0, param2=0},
		{name="air", prob=0, param2=0},
		{name="air", prob=0, param2=0},
		{name="air", prob=0, param2=0},
		{name="air", prob=0, param2=0},
		{name="air", prob=0, param2=0},
		{name="air", prob=0, param2=0},
		{name="air", prob=0, param2=0},
		{name="air", prob=0, param2=0},
		{name="air", prob=0, param2=0},
		{name="stairs:stair_coral_white_sandstone", prob=254, param2=20},
		{name="stairs:stair_coral_white_sandstone", prob=254, param2=20},
		{name="stairs:stair_coral_white_sandstone", prob=254, param2=20},
		{name="stairs:stair_coral_white_sandstone", prob=254, param2=20},
		{name="stairs:stair_coral_white_sandstone", prob=254, param2=20},
		{name="stairs:stair_coral_white_sandstone", prob=254, param2=20},
		{name="stairs:stair_coral_white_sandstone", prob=254, param2=20},
		{name="air", prob=0, param2=0},
		{name="air", prob=0, param2=0},
		{name="air", prob=0, param2=0},
		{name="air", prob=0, param2=0},
		{name="air", prob=0, param2=0},
		{name="air", prob=0, param2=0},
		{name="air", prob=0, param2=0},
		{name="air", prob=0, param2=0},
		{name="air", prob=0, param2=0},
		{name="air", prob=0, param2=0},
		{name="air", prob=0, param2=0},
		{name="air", prob=0, param2=0},
		{name="air", prob=0, param2=0},
		{name="air", prob=0, param2=0},
		{name="air", prob=0, param2=0},
		{name="air", prob=0, param2=0},
		{name="air", prob=0, param2=0},
		{name="air", prob=0, param2=0},
		{name="air", prob=0, param2=0},
		{name="air", prob=0, param2=0},
		{name="air", prob=0, param2=0},
		{name="air", prob=0, param2=0},
		{name="air", prob=0, param2=0},
		{name="air", prob=0, param2=0},
		{name="air", prob=0, param2=0},
		{name="air", prob=0, param2=0},
		{name="air", prob=0, param2=0},
		{name="air", prob=0, param2=0},
		{name="air", prob=0, param2=0},
		{name="air", prob=0, param2=0},
		{name="air", prob=0, param2=0},
		{name="air", prob=0, param2=0},
		{name="air", prob=0, param2=0},
		{name="air", prob=0, param2=0},
		{name="air", prob=0, param2=0},
		{name="air", prob=0, param2=0},
		{name="air", prob=0, param2=0},
		{name="air", prob=0, param2=0},
		{name="air", prob=0, param2=0},
		{name="air", prob=0, param2=0},
		{name="air", prob=0, param2=0},
		{name="air", prob=0, param2=0},
		{name="air", prob=0, param2=0},
		{name="air", prob=0, param2=0},
		{name="air", prob=0, param2=0},
		{name="air", prob=0, param2=0},
		{name="air", prob=0, param2=0},
		{name="air", prob=0, param2=0},
		{name="air", prob=0, param2=0},
		{name="air", prob=0, param2=0},
		{name="air", prob=0, param2=0},
		{name="air", prob=0, param2=0},
		{name="air", prob=0, param2=0},
		{name="air", prob=0, param2=0},
		{name="air", prob=0, param2=0},
		{name="air", prob=0, param2=0},
		{name="air", prob=0, param2=0},
		{name="air", prob=0, param2=0},
		{name="air", prob=0, param2=0},
		{name="air", prob=0, param2=0},
		{name="air", prob=0, param2=0},
		{name="air", prob=0, param2=0},
		{name="air", prob=0, param2=0},
		{name="air", prob=0, param2=0},
		{name="air", prob=0, param2=0},
		{name="air", prob=0, param2=0},
		{name="air", prob=0, param2=0},
		{name="air", prob=0, param2=0},
		{name="air", prob=0, param2=0},
		{name="air", prob=0, param2=0},
		{name="air", prob=0, param2=0},
		{name="air", prob=0, param2=0},
		{name="air", prob=0, param2=0},
		{name="air", prob=0, param2=0},
		{name="air", prob=0, param2=0},
		{name="air", prob=0, param2=0},
		{name="air", prob=0, param2=0},
		{name="air", prob=0, param2=0},
		{name="air", prob=0, param2=0},
		{name="air", prob=0, param2=0},
		{name="air", prob=0, param2=0},
		{name="air", prob=0, param2=0},
		{name="air", prob=0, param2=0},
		{name="air", prob=0, param2=0},
		{name="air", prob=0, param2=0},
		{name="air", prob=0, param2=0},
		{name="air", prob=0, param2=0},
		{name="air", prob=0, param2=0},
		{name="air", prob=0, param2=0},
		{name="air", prob=0, param2=0},
		{name="air", prob=0, param2=0},
		{name="air", prob=0, param2=0},
		{name="air", prob=0, param2=0},
		{name="air", prob=0, param2=0},
		{name="air", prob=0, param2=0},
		{name="air", prob=0, param2=0},
		{name="air", prob=0, param2=0},
		{name="air", prob=0, param2=0},
		{name="air", prob=0, param2=0},
		{name="air", prob=0, param2=0},
		{name="air", prob=0, param2=0},
		{name="air", prob=0, param2=0},
		{name="air", prob=0, param2=0},
		{name="air", prob=0, param2=0},
		{name="air", prob=0, param2=0},
		{name="air", prob=0, param2=0},
		{name="air", prob=0, param2=0},
		{name="air", prob=0, param2=0},
		{name="air", prob=0, param2=0},
		{name="air", prob=0, param2=0},
		{name="air", prob=0, param2=0},
		{name="air", prob=0, param2=0},
		{name="everness:coral_deep_ocean_sandstone_block", prob=126, param2=0},
		{name="air", prob=0, param2=0},
		{name="air", prob=0, param2=0},
		{name="air", prob=0, param2=0},
		{name="air", prob=0, param2=0},
		{name="air", prob=0, param2=0},
		{name="air", prob=0, param2=0},
		{name="air", prob=0, param2=0},
		{name="air", prob=0, param2=0},
		{name="air", prob=0, param2=0},
		{name="everness:coral_deep_ocean_sandstone_block", prob=126, param2=0},
		{name="air", prob=0, param2=0},
		{name="everness:coral_deep_ocean_sandstone_block", prob=254, param2=0},
		{name="everness:coral_deep_ocean_sandstone_block", prob=254, param2=0},
		{name="everness:coral_deep_ocean_sandstone_block", prob=254, param2=0},
		{name="everness:coral_deep_ocean_sandstone_block", prob=254, param2=0},
		{name="everness:coral_deep_ocean_sandstone_block", prob=254, param2=0},
		{name="everness:coral_deep_ocean_sandstone_block", prob=254, param2=0},
		{name="everness:coral_deep_ocean_sandstone_block", prob=254, param2=0},
		{name="everness:coral_deep_ocean_sandstone_block", prob=254, param2=0},
		{name="everness:coral_deep_ocean_sandstone_block", prob=254, param2=0},
		{name="air", prob=0, param2=0},
		{name="air", prob=0, param2=0},
		{name="air", prob=0, param2=0},
		{name="everness:coral_deep_ocean_sandstone_block", prob=254, param2=0},
		{name="air", prob=0, param2=0},
		{name="air", prob=0, param2=0},
		{name="everness:coral_deep_ocean_sandstone_block", prob=254, param2=0},
		{name="air", prob=0, param2=0},
		{name="air", prob=0, param2=0},
		{name="everness:coral_deep_ocean_sandstone_block", prob=254, param2=0},
		{name="air", prob=0, param2=0},
		{name="air", prob=0, param2=0},
		{name="air", prob=0, param2=0},
		{name="air", prob=0, param2=0},
		{name="everness:coral_deep_ocean_sandstone_brick", prob=254, param2=0},
		{name="air", prob=0, param2=0},
		{name="air", prob=0, param2=0},
		{name="everness:coral_deep_ocean_sandstone_brick", prob=254, param2=0},
		{name="air", prob=0, param2=0},
		{name="air", prob=0, param2=0},
		{name="everness:coral_deep_ocean_sandstone_brick", prob=254, param2=0},
		{name="air", prob=0, param2=0},
		{name="air", prob=0, param2=0},
		{name="air", prob=0, param2=0},
		{name="air", prob=0, param2=0},
		{name="everness:coral_deep_ocean_sandstone_brick", prob=254, param2=0},
		{name="air", prob=0, param2=0},
		{name="air", prob=0, param2=0},
		{name="everness:coral_deep_ocean_sandstone_brick", prob=254, param2=0},
		{name="air", prob=0, param2=0},
		{name="air", prob=0, param2=0},
		{name="everness:coral_deep_ocean_sandstone_brick", prob=254, param2=0},
		{name="air", prob=0, param2=0},
		{name="air", prob=0, param2=0},
		{name="stairs:stair_coral_white_sandstone", prob=254, param2=23},
		{name="stairs:stair_coral_white_sandstone", prob=254, param2=21},
		{name="everness:coral_deep_ocean_sandstone_brick", prob=254, param2=0},
		{name="air", prob=0, param2=0},
		{name="air", prob=0, param2=0},
		{name="everness:coral_deep_ocean_sandstone_brick", prob=254, param2=0},
		{name="air", prob=0, param2=0},
		{name="air", prob=0, param2=0},
		{name="everness:coral_deep_ocean_sandstone_brick", prob=254, param2=0},
		{name="stairs:stair_coral_white_sandstone", prob=254, param2=23},
		{name="stairs:stair_coral_white_sandstone", prob=254, param2=21},
		{name="air", prob=0, param2=0},
		{name="stairs:slab_coral_white_sandstone", prob=254, param2=0},
		{name="everness:coral_sandstone_brick", prob=254, param2=0},
		{name="everness:coral_deep_ocean_sandstone_block", prob=254, param2=0},
		{name="everness:coral_deep_ocean_sandstone_block", prob=254, param2=0},
		{name="everness:coral_deep_ocean_sandstone_block", prob=254, param2=0},
		{name="everness:coral_deep_ocean_sandstone_block", prob=254, param2=0},
		{name="everness:coral_deep_ocean_sandstone_block", prob=254, param2=0},
		{name="everness:coral_sandstone_brick", prob=254, param2=0},
		{name="stairs:slab_coral_white_sandstone", prob=254, param2=0},
		{name="air", prob=0, param2=0},
		{name="air", prob=0, param2=0},
		{name="air", prob=0, param2=0},
		{name="air", prob=0, param2=0},
		{name="air", prob=0, param2=0},
		{name="air", prob=0, param2=0},
		{name="air", prob=0, param2=0},
		{name="air", prob=0, param2=0},
		{name="air", prob=0, param2=0},
		{name="air", prob=0, param2=0},
		{name="air", prob=0, param2=0},
		{name="air", prob=0, param2=0},
		{name="air", prob=0, param2=0},
		{name="air", prob=0, param2=0},
		{name="air", prob=0, param2=0},
		{name="air", prob=0, param2=0},
		{name="air", prob=0, param2=0},
		{name="air", prob=0, param2=0},
		{name="air", prob=0, param2=0},
		{name="air", prob=0, param2=0},
		{name="air", prob=0, param2=0},
		{name="air", prob=0, param2=0},
		{name="air", prob=0, param2=0},
		{name="air", prob=0, param2=0},
		{name="air", prob=0, param2=0},
		{name="air", prob=0, param2=0},
		{name="air", prob=0, param2=0},
		{name="air", prob=0, param2=0},
		{name="air", prob=0, param2=0},
		{name="air", prob=0, param2=0},
		{name="air", prob=0, param2=0},
		{name="air", prob=0, param2=0},
		{name="air", prob=0, param2=0},
		{name="air", prob=0, param2=0},
		{name="air", prob=0, param2=0},
		{name="air", prob=0, param2=0},
		{name="air", prob=0, param2=0},
		{name="air", prob=0, param2=0},
		{name="air", prob=0, param2=0},
		{name="air", prob=0, param2=0},
		{name="air", prob=0, param2=0},
		{name="air", prob=0, param2=0},
		{name="air", prob=0, param2=0},
		{name="air", prob=0, param2=0},
		{name="air", prob=0, param2=0},
		{name="air", prob=0, param2=0},
		{name="air", prob=0, param2=0},
		{name="air", prob=0, param2=0},
		{name="air", prob=0, param2=0},
		{name="stairs:slab_coral_white_sandstone", prob=254, param2=23},
		{name="stairs:stair_coral_white_sandstone", prob=254, param2=20},
		{name="stairs:slab_coral_white_sandstone", prob=254, param2=20},
		{name="air", prob=0, param2=0},
		{name="air", prob=0, param2=0},
		{name="air", prob=0, param2=0},
		{name="air", prob=0, param2=0},
		{name="air", prob=0, param2=0},
		{name="air", prob=0, param2=0},
		{name="air", prob=0, param2=0},
		{name="air", prob=0, param2=0},
		{name="air", prob=0, param2=0},
		{name="air", prob=0, param2=0},
		{name="air", prob=0, param2=0},
		{name="air", prob=0, param2=0},
		{name="air", prob=0, param2=0},
		{name="air", prob=0, param2=0},
		{name="air", prob=0, param2=0},
		{name="air", prob=0, param2=0},
		{name="air", prob=0, param2=0},
		{name="air", prob=0, param2=0},
		{name="air", prob=0, param2=0},
		{name="air", prob=0, param2=0},
		{name="air", prob=0, param2=0},
		{name="air", prob=0, param2=0},
		{name="air", prob=0, param2=0},
		{name="air", prob=0, param2=0},
		{name="air", prob=0, param2=0},
		{name="air", prob=0, param2=0},
		{name="air", prob=0, param2=0},
		{name="air", prob=0, param2=0},
		{name="air", prob=0, param2=0},
		{name="air", prob=0, param2=0},
		{name="air", prob=0, param2=0},
		{name="air", prob=0, param2=0},
		{name="air", prob=0, param2=0},
		{name="air", prob=0, param2=0},
		{name="air", prob=0, param2=0},
		{name="air", prob=0, param2=0},
		{name="air", prob=0, param2=0},
		{name="air", prob=0, param2=0},
		{name="air", prob=0, param2=0},
		{name="air", prob=0, param2=0},
		{name="air", prob=0, param2=0},
		{name="air", prob=0, param2=0},
		{name="air", prob=0, param2=0},
		{name="air", prob=0, param2=0},
		{name="air", prob=0, param2=0},
		{name="air", prob=0, param2=0},
		{name="air", prob=0, param2=0},
		{name="air", prob=0, param2=0},
		{name="air", prob=0, param2=0},
		{name="air", prob=0, param2=0},
		{name="air", prob=0, param2=0},
		{name="air", prob=0, param2=0},
		{name="air", prob=0, param2=0},
		{name="air", prob=0, param2=0},
		{name="air", prob=0, param2=0},
		{name="air", prob=0, param2=0},
		{name="air", prob=0, param2=0},
		{name="air", prob=0, param2=0},
		{name="air", prob=0, param2=0},
		{name="everness:coral_deep_ocean_sandstone_block", prob=126, param2=0},
		{name="air", prob=0, param2=0},
		{name="air", prob=0, param2=0},
		{name="air", prob=0, param2=0},
		{name="air", prob=0, param2=0},
		{name="air", prob=0, param2=0},
		{name="air", prob=0, param2=0},
		{name="air", prob=0, param2=0},
		{name="air", prob=0, param2=0},
		{name="air", prob=0, param2=0},
		{name="everness:coral_deep_ocean_sandstone_block", prob=126, param2=0},
		{name="air", prob=0, param2=0},
		{name="everness:coral_deep_ocean_sandstone_block", prob=254, param2=0},
		{name="everness:coral_deep_ocean_sandstone_block", prob=254, param2=0},
		{name="everness:coral_deep_ocean_sandstone_block", prob=254, param2=0},
		{name="everness:coral_deep_ocean_sandstone_block", prob=254, param2=0},
		{name="everness:coral_deep_ocean_sandstone_block", prob=254, param2=0},
		{name="everness:coral_deep_ocean_sandstone_block", prob=254, param2=0},
		{name="everness:coral_deep_ocean_sandstone_block", prob=254, param2=0},
		{name="everness:coral_deep_ocean_sandstone_block", prob=254, param2=0},
		{name="everness:coral_deep_ocean_sandstone_block", prob=254, param2=0},
		{name="air", prob=0, param2=0},
		{name="air", prob=0, param2=0},
		{name="everness:coral_deep_ocean_sandstone_block", prob=254, param2=0},
		{name="everness:coral_deep_ocean_sandstone_block", prob=254, param2=0},
		{name="everness:coral_deep_ocean_sandstone_brick", prob=126, param2=0},
		{name="air", prob=0, param2=0},
		{name="air", prob=0, param2=0},
		{name="air", prob=0, param2=0},
		{name="air", prob=0, param2=0},
		{name="everness:coral_deep_ocean_sandstone_block", prob=254, param2=0},
		{name="everness:coral_deep_ocean_sandstone_block", prob=254, param2=0},
		{name="air", prob=0, param2=0},
		{name="air", prob=0, param2=0},
		{name="everness:coral_deep_ocean_sandstone_brick", prob=254, param2=0},
		{name="everness:coral_deep_ocean_sandstone_block", prob=254, param2=0},
		{name="air", prob=0, param2=0},
		{name="air", prob=0, param2=0},
		{name="air", prob=0, param2=0},
		{name="air", prob=0, param2=0},
		{name="air", prob=0, param2=0},
		{name="everness:coral_deep_ocean_sandstone_block", prob=254, param2=0},
		{name="everness:coral_deep_ocean_sandstone_brick", prob=254, param2=0},
		{name="air", prob=0, param2=0},
		{name="air", prob=0, param2=0},
		{name="everness:coral_deep_ocean_sandstone_brick", prob=254, param2=0},
		{name="everness:coral_deep_ocean_sandstone_block", prob=254, param2=0},
		{name="air", prob=0, param2=0},
		{name="air", prob=0, param2=0},
		{name="air", prob=0, param2=0},
		{name="air", prob=0, param2=0},
		{name="air", prob=0, param2=0},
		{name="everness:coral_deep_ocean_sandstone_block", prob=254, param2=0},
		{name="everness:coral_deep_ocean_sandstone_brick", prob=254, param2=0},
		{name="air", prob=0, param2=0},
		{name="stairs:stair_coral_white_sandstone", prob=254, param2=23},
		{name="everness:coral_deep_ocean_sandstone_brick", prob=254, param2=0},
		{name="everness:coral_deep_ocean_sandstone_block", prob=254, param2=0},
		{name="air", prob=0, param2=0},
		{name="air", prob=0, param2=0},
		{name="air", prob=0, param2=0},
		{name="air", prob=0, param2=0},
		{name="air", prob=0, param2=0},
		{name="everness:coral_deep_ocean_sandstone_block", prob=254, param2=0},
		{name="everness:coral_deep_ocean_sandstone_brick", prob=254, param2=0},
		{name="stairs:stair_coral_white_sandstone", prob=254, param2=21},
		{name="air", prob=0, param2=0},
		{name="everness:coral_sandstone_brick", prob=254, param2=0},
		{name="everness:coral_deep_ocean_sandstone_block", prob=254, param2=0},
		{name="everness:coral_deep_ocean_sandstone_block", prob=254, param2=0},
		{name="everness:coral_deep_ocean_sandstone_block", prob=254, param2=0},
		{name="everness:coral_deep_ocean_sandstone_block", prob=254, param2=0},
		{name="everness:coral_deep_ocean_sandstone_block", prob=254, param2=0},
		{name="everness:coral_deep_ocean_sandstone_block", prob=254, param2=0},
		{name="everness:coral_deep_ocean_sandstone_block", prob=254, param2=0},
		{name="everness:coral_sandstone_brick", prob=254, param2=0},
		{name="air", prob=0, param2=0},
		{name="air", prob=0, param2=0},
		{name="air", prob=0, param2=0},
		{name="air", prob=0, param2=0},
		{name="air", prob=0, param2=0},
		{name="air", prob=0, param2=0},
		{name="everness:coral_sandstone_brick", prob=254, param2=0},
		{name="air", prob=0, param2=0},
		{name="air", prob=0, param2=0},
		{name="air", prob=0, param2=0},
		{name="air", prob=0, param2=0},
		{name="air", prob=0, param2=0},
		{name="air", prob=0, param2=0},
		{name="air", prob=0, param2=0},
		{name="air", prob=0, param2=0},
		{name="air", prob=0, param2=0},
		{name="air", prob=0, param2=0},
		{name="everness:coral_deep_ocean_sandstone_block", prob=254, param2=0},
		{name="air", prob=0, param2=0},
		{name="air", prob=0, param2=0},
		{name="air", prob=0, param2=0},
		{name="air", prob=0, param2=0},
		{name="air", prob=0, param2=0},
		{name="air", prob=0, param2=0},
		{name="air", prob=0, param2=0},
		{name="air", prob=0, param2=0},
		{name="air", prob=0, param2=0},
		{name="air", prob=0, param2=0},
		{name="everness:coral_deep_ocean_sandstone_brick", prob=254, param2=0},
		{name="air", prob=0, param2=0},
		{name="air", prob=0, param2=0},
		{name="air", prob=0, param2=0},
		{name="air", prob=0, param2=0},
		{name="air", prob=0, param2=0},
		{name="air", prob=0, param2=0},
		{name="air", prob=0, param2=0},
		{name="air", prob=0, param2=0},
		{name="air", prob=0, param2=0},
		{name="air", prob=0, param2=0},
		{name="everness:coral_deep_ocean_sandstone_brick", prob=254, param2=0},
		{name="air", prob=0, param2=0},
		{name="air", prob=0, param2=0},
		{name="air", prob=0, param2=0},
		{name="air", prob=0, param2=0},
		{name="air", prob=0, param2=0},
		{name="air", prob=0, param2=0},
		{name="air", prob=0, param2=0},
		{name="stairs:slab_coral_white_sandstone", prob=254, param2=20},
		{name="stairs:stair_coral_white_sandstone", prob=254, param2=20},
		{name="stairs:slab_coral_white_sandstone", prob=254, param2=23},
		{name="everness:coral_deep_ocean_sandstone_block", prob=254, param2=0},
		{name="stairs:slab_coral_white_sandstone", prob=254, param2=20},
		{name="stairs:stair_coral_white_sandstone", prob=254, param2=20},
		{name="stairs:slab_coral_white_sandstone", prob=254, param2=21},
		{name="air", prob=0, param2=0},
		{name="air", prob=0, param2=0},
		{name="air", prob=0, param2=0},
		{name="air", prob=0, param2=0},
		{name="air", prob=0, param2=0},
		{name="air", prob=0, param2=0},
		{name="everness:coral_deep_ocean_sandstone_block", prob=254, param2=0},
		{name="everness:coral_sandstone_brick", prob=254, param2=0},
		{name="everness:coral_sandstone_brick", prob=254, param2=0},
		{name="air", prob=0, param2=0},
		{name="air", prob=0, param2=0},
		{name="air", prob=0, param2=0},
		{name="air", prob=0, param2=0},
		{name="air", prob=0, param2=0},
		{name="air", prob=0, param2=0},
		{name="air", prob=0, param2=0},
		{name="air", prob=0, param2=0},
		{name="air", prob=0, param2=0},
		{name="everness:coral_sandstone_brick", prob=254, param2=0},
		{name="air", prob=0, param2=0},
		{name="air", prob=0, param2=0},
		{name="air", prob=0, param2=0},
		{name="air", prob=0, param2=0},
		{name="air", prob=0, param2=0},
		{name="air", prob=0, param2=0},
		{name="air", prob=0, param2=0},
		{name="air", prob=0, param2=0},
		{name="air", prob=0, param2=0},
		{name="air", prob=0, param2=0},
		{name="air", prob=0, param2=0},
		{name="air", prob=0, param2=0},
		{name="air", prob=0, param2=0},
		{name="air", prob=0, param2=0},
		{name="air", prob=0, param2=0},
		{name="air", prob=0, param2=0},
		{name="air", prob=0, param2=0},
		{name="air", prob=0, param2=0},
		{name="air", prob=0, param2=0},
		{name="air", prob=0, param2=0},
		{name="air", prob=0, param2=0},
		{name="air", prob=0, param2=0},
		{name="air", prob=0, param2=0},
		{name="air", prob=0, param2=0},
		{name="air", prob=0, param2=0},
		{name="air", prob=0, param2=0},
		{name="air", prob=0, param2=0},
		{name="air", prob=0, param2=0},
		{name="air", prob=0, param2=0},
		{name="air", prob=0, param2=0},
		{name="air", prob=0, param2=0},
		{name="air", prob=0, param2=0},
		{name="air", prob=0, param2=0},
		{name="air", prob=0, param2=0},
		{name="air", prob=0, param2=0},
		{name="air", prob=0, param2=0},
		{name="air", prob=0, param2=0},
		{name="air", prob=0, param2=0},
		{name="everness:coral_deep_ocean_sandstone_block", prob=126, param2=0},
		{name="air", prob=0, param2=0},
		{name="air", prob=0, param2=0},
		{name="air", prob=0, param2=0},
		{name="air", prob=0, param2=0},
		{name="air", prob=0, param2=0},
		{name="air", prob=0, param2=0},
		{name="air", prob=0, param2=0},
		{name="air", prob=0, param2=0},
		{name="air", prob=0, param2=0},
		{name="everness:coral_deep_ocean_sandstone_block", prob=126, param2=0},
		{name="air", prob=0, param2=0},
		{name="everness:coral_deep_ocean_sandstone_block", prob=254, param2=0},
		{name="everness:coral_deep_ocean_sandstone_block", prob=254, param2=0},
		{name="everness:baobab_wood", prob=254, param2=0},
		{name="everness:baobab_wood", prob=254, param2=0},
		{name="everness:baobab_wood", prob=254, param2=0},
		{name="everness:baobab_wood", prob=254, param2=0},
		{name="everness:baobab_wood", prob=254, param2=0},
		{name="everness:coral_deep_ocean_sandstone_block", prob=254, param2=0},
		{name="everness:coral_deep_ocean_sandstone_block", prob=254, param2=0},
		{name="air", prob=0, param2=0},
		{name="air", prob=0, param2=0},
		{name="air", prob=0, param2=0},
		{name="air", prob=0, param2=0},
		{name="air", prob=0, param2=0},
		{name="air", prob=0, param2=0},
		{name="air", prob=0, param2=0},
		{name="air", prob=0, param2=0},
		{name="everness:coral_deep_ocean_sandstone_block", prob=126, param2=0},
		{name="air", prob=0, param2=0},
		{name="air", prob=0, param2=0},
		{name="air", prob=0, param2=0},
		{name="air", prob=0, param2=0},
		{name="air", prob=0, param2=0},
		{name="air", prob=0, param2=0},
		{name="air", prob=0, param2=0},
		{name="air", prob=0, param2=0},
		{name="air", prob=0, param2=0},
		{name="air", prob=0, param2=0},
		{name="air", prob=0, param2=0},
		{name="air", prob=0, param2=0},
		{name="air", prob=0, param2=0},
		{name="air", prob=0, param2=0},
		{name="air", prob=0, param2=0},
		{name="stairs:stair_coral_deep_ocean_sandstone_block", prob=254, param2=22},
		{name="air", prob=0, param2=0},
		{name="air", prob=0, param2=0},
		{name="air", prob=0, param2=0},
		{name="air", prob=0, param2=0},
		{name="air", prob=0, param2=0},
		{name="air", prob=0, param2=0},
		{name="air", prob=0, param2=0},
		{name="stairs:stair_coral_deep_ocean_sandstone_block", prob=254, param2=22},
		{name="air", prob=0, param2=0},
		{name="stairs:stair_coral_white_sandstone", prob=254, param2=23},
		{name="everness:coral_deep_ocean_sandstone_brick", prob=254, param2=0},
		{name="air", prob=0, param2=0},
		{name="air", prob=0, param2=0},
		{name="air", prob=0, param2=0},
		{name="air", prob=0, param2=0},
		{name="air", prob=0, param2=0},
		{name="air", prob=0, param2=0},
		{name="air", prob=0, param2=0},
		{name="everness:coral_deep_ocean_sandstone_brick", prob=254, param2=0},
		{name="stairs:stair_coral_white_sandstone", prob=254, param2=21},
		{name="air", prob=0, param2=0},
		{name="everness:coral_deep_ocean_sandstone_block", prob=254, param2=0},
		{name="everness:coral_deep_ocean_sandstone_block", prob=254, param2=0},
		{name="everness:coral_deep_ocean_sandstone_block", prob=254, param2=0},
		{name="everness:baobab_wood", prob=254, param2=0},
		{name="everness:baobab_wood", prob=254, param2=0},
		{name="everness:baobab_wood", prob=254, param2=0},
		{name="everness:coral_deep_ocean_sandstone_block", prob=254, param2=0},
		{name="everness:coral_deep_ocean_sandstone_block", prob=254, param2=0},
		{name="everness:coral_deep_ocean_sandstone_block", prob=254, param2=0},
		{name="air", prob=0, param2=0},
		{name="air", prob=0, param2=0},
		{name="air", prob=0, param2=0},
		{name="air", prob=0, param2=0},
		{name="everness:coral_sandstone_brick", prob=254, param2=0},
		{name="air", prob=0, param2=0},
		{name="air", prob=0, param2=0},
		{name="air", prob=0, param2=0},
		{name="everness:coral_sandstone_brick", prob=254, param2=0},
		{name="air", prob=0, param2=0},
		{name="air", prob=0, param2=0},
		{name="air", prob=0, param2=0},
		{name="air", prob=0, param2=0},
		{name="air", prob=0, param2=0},
		{name="air", prob=0, param2=0},
		{name="everness:coral_deep_ocean_sandstone_block", prob=254, param2=0},
		{name="air", prob=0, param2=0},
		{name="air", prob=0, param2=0},
		{name="air", prob=0, param2=0},
		{name="everness:coral_deep_ocean_sandstone_block", prob=254, param2=0},
		{name="air", prob=0, param2=0},
		{name="air", prob=0, param2=0},
		{name="air", prob=0, param2=0},
		{name="air", prob=0, param2=0},
		{name="air", prob=0, param2=0},
		{name="air", prob=0, param2=0},
		{name="everness:coral_deep_ocean_sandstone_brick", prob=254, param2=0},
		{name="air", prob=0, param2=0},
		{name="air", prob=0, param2=0},
		{name="air", prob=0, param2=0},
		{name="everness:coral_deep_ocean_sandstone_brick", prob=254, param2=0},
		{name="air", prob=0, param2=0},
		{name="air", prob=0, param2=0},
		{name="air", prob=0, param2=0},
		{name="air", prob=0, param2=0},
		{name="air", prob=0, param2=0},
		{name="air", prob=0, param2=0},
		{name="everness:coral_deep_ocean_sandstone_brick", prob=254, param2=0},
		{name="air", prob=0, param2=0},
		{name="air", prob=0, param2=0},
		{name="air", prob=0, param2=0},
		{name="everness:coral_deep_ocean_sandstone_brick", prob=254, param2=0},
		{name="air", prob=0, param2=0},
		{name="air", prob=0, param2=0},
		{name="air", prob=0, param2=0},
		{name="air", prob=0, param2=0},
		{name="air", prob=0, param2=0},
		{name="stairs:stair_coral_white_sandstone", prob=254, param2=23},
		{name="everness:coral_deep_ocean_sandstone_block", prob=254, param2=0},
		{name="stairs:slab_coral_white_sandstone", prob=254, param2=20},
		{name="air", prob=0, param2=0},
		{name="stairs:slab_coral_white_sandstone", prob=254, param2=20},
		{name="everness:coral_deep_ocean_sandstone_block", prob=254, param2=0},
		{name="stairs:stair_coral_white_sandstone", prob=254, param2=21},
		{name="air", prob=0, param2=0},
		{name="air", prob=0, param2=0},
		{name="air", prob=0, param2=0},
		{name="air", prob=0, param2=0},
		{name="air", prob=0, param2=0},
		{name="everness:coral_sandstone_brick", prob=254, param2=0},
		{name="everness:coral_sandstone_chiseled", prob=254, param2=0},
		{name="everness:coral_sandstone_carved_1", prob=254, param2=0},
		{name="everness:coral_sandstone_chiseled", prob=254, param2=0},
		{name="everness:coral_sandstone_brick", prob=254, param2=0},
		{name="air", prob=0, param2=0},
		{name="air", prob=0, param2=0},
		{name="air", prob=0, param2=0},
		{name="air", prob=0, param2=0},
		{name="air", prob=0, param2=0},
		{name="air", prob=0, param2=0},
		{name="everness:coral_deep_ocean_sandstone_block", prob=254, param2=0},
		{name="everness:coral_deep_ocean_sandstone_block", prob=254, param2=0},
		{name="everness:coral_forest_deep_ocean_house_marker", prob=254, param2=2},
		{name="everness:coral_deep_ocean_sandstone_block", prob=254, param2=0},
		{name="everness:coral_deep_ocean_sandstone_block", prob=254, param2=0},
		{name="air", prob=0, param2=0},
		{name="air", prob=0, param2=0},
		{name="air", prob=0, param2=0},
		{name="air", prob=0, param2=0},
		{name="air", prob=0, param2=0},
		{name="air", prob=0, param2=0},
		{name="air", prob=0, param2=0},
		{name="everness:coral_sandstone_brick", prob=254, param2=0},
		{name="everness:coral_sandstone_brick", prob=254, param2=0},
		{name="everness:coral_sandstone_brick", prob=254, param2=0},
		{name="air", prob=0, param2=0},
		{name="air", prob=0, param2=0},
		{name="air", prob=0, param2=0},
		{name="air", prob=0, param2=0},
		{name="air", prob=0, param2=0},
		{name="air", prob=0, param2=0},
		{name="air", prob=0, param2=0},
		{name="air", prob=0, param2=0},
		{name="air", prob=0, param2=0},
		{name="air", prob=0, param2=0},
		{name="air", prob=0, param2=0},
		{name="air", prob=0, param2=0},
		{name="air", prob=0, param2=0},
		{name="air", prob=0, param2=0},
		{name="air", prob=0, param2=0},
		{name="air", prob=0, param2=0},
		{name="air", prob=0, param2=0},
		{name="air", prob=0, param2=0},
		{name="air", prob=0, param2=0},
		{name="air", prob=0, param2=0},
		{name="air", prob=0, param2=0},
		{name="air", prob=0, param2=0},
		{name="air", prob=0, param2=0},
		{name="air", prob=0, param2=0},
		{name="air", prob=0, param2=0},
		{name="air", prob=0, param2=0},
		{name="everness:coral_deep_ocean_sandstone_block", prob=126, param2=0},
		{name="air", prob=0, param2=0},
		{name="air", prob=0, param2=0},
		{name="air", prob=0, param2=0},
		{name="air", prob=0, param2=0},
		{name="air", prob=0, param2=0},
		{name="air", prob=0, param2=0},
		{name="air", prob=0, param2=0},
		{name="air", prob=0, param2=0},
		{name="air", prob=0, param2=0},
		{name="everness:coral_deep_ocean_sandstone_block", prob=126, param2=0},
		{name="air", prob=0, param2=0},
		{name="everness:coral_deep_ocean_sandstone_block", prob=254, param2=0},
		{name="everness:coral_deep_ocean_sandstone_block", prob=254, param2=0},
		{name="everness:baobab_wood", prob=254, param2=0},
		{name="everness:baobab_wood", prob=254, param2=0},
		{name="everness:baobab_wood", prob=254, param2=0},
		{name="everness:baobab_wood", prob=254, param2=0},
		{name="everness:baobab_wood", prob=254, param2=0},
		{name="everness:coral_deep_ocean_sandstone_block", prob=254, param2=0},
		{name="everness:coral_deep_ocean_sandstone_block", prob=254, param2=0},
		{name="air", prob=0, param2=0},
		{name="air", prob=0, param2=0},
		{name="air", prob=0, param2=0},
		{name="air", prob=0, param2=0},
		{name="air", prob=0, param2=0},
		{name="air", prob=0, param2=0},
		{name="air", prob=0, param2=0},
		{name="air", prob=0, param2=0},
		{name="air", prob=0, param2=0},
		{name="air", prob=0, param2=0},
		{name="air", prob=0, param2=0},
		{name="air", prob=0, param2=0},
		{name="air", prob=0, param2=0},
		{name="air", prob=0, param2=0},
		{name="air", prob=0, param2=0},
		{name="air", prob=0, param2=0},
		{name="air", prob=0, param2=0},
		{name="air", prob=0, param2=0},
		{name="air", prob=0, param2=0},
		{name="air", prob=0, param2=0},
		{name="air", prob=0, param2=0},
		{name="air", prob=0, param2=0},
		{name="air", prob=0, param2=0},
		{name="air", prob=0, param2=0},
		{name="stairs:stair_coral_deep_ocean_sandstone_block", prob=254, param2=20},
		{name="air", prob=0, param2=0},
		{name="air", prob=0, param2=0},
		{name="air", prob=0, param2=0},
		{name="air", prob=0, param2=0},
		{name="air", prob=0, param2=0},
		{name="air", prob=0, param2=0},
		{name="air", prob=0, param2=0},
		{name="stairs:stair_coral_deep_ocean_sandstone_block", prob=254, param2=20},
		{name="air", prob=0, param2=0},
		{name="stairs:stair_coral_white_sandstone", prob=254, param2=23},
		{name="everness:coral_deep_ocean_sandstone_brick", prob=254, param2=0},
		{name="air", prob=0, param2=0},
		{name="air", prob=0, param2=0},
		{name="air", prob=0, param2=0},
		{name="air", prob=0, param2=0},
		{name="air", prob=0, param2=0},
		{name="air", prob=0, param2=0},
		{name="air", prob=0, param2=0},
		{name="everness:coral_deep_ocean_sandstone_brick", prob=254, param2=0},
		{name="stairs:stair_coral_white_sandstone", prob=254, param2=21},
		{name="air", prob=0, param2=0},
		{name="everness:coral_deep_ocean_sandstone_block", prob=254, param2=0},
		{name="everness:coral_deep_ocean_sandstone_block", prob=254, param2=0},
		{name="everness:baobab_wood", prob=254, param2=0},
		{name="air", prob=0, param2=0},
		{name="everness:baobab_wood", prob=254, param2=0},
		{name="everness:baobab_wood", prob=254, param2=0},
		{name="everness:baobab_wood", prob=254, param2=0},
		{name="everness:coral_deep_ocean_sandstone_block", prob=254, param2=0},
		{name="everness:coral_deep_ocean_sandstone_block", prob=254, param2=0},
		{name="air", prob=0, param2=0},
		{name="air", prob=0, param2=0},
		{name="air", prob=0, param2=0},
		{name="air", prob=0, param2=0},
		{name="air", prob=0, param2=0},
		{name="air", prob=0, param2=0},
		{name="air", prob=0, param2=0},
		{name="air", prob=0, param2=0},
		{name="air", prob=0, param2=0},
		{name="air", prob=0, param2=0},
		{name="air", prob=0, param2=0},
		{name="air", prob=0, param2=0},
		{name="air", prob=0, param2=0},
		{name="air", prob=0, param2=0},
		{name="air", prob=0, param2=0},
		{name="air", prob=0, param2=0},
		{name="air", prob=0, param2=0},
		{name="air", prob=0, param2=0},
		{name="air", prob=0, param2=0},
		{name="air", prob=0, param2=0},
		{name="air", prob=0, param2=0},
		{name="air", prob=0, param2=0},
		{name="air", prob=0, param2=0},
		{name="air", prob=0, param2=0},
		{name="air", prob=0, param2=0},
		{name="air", prob=0, param2=0},
		{name="air", prob=0, param2=0},
		{name="air", prob=0, param2=0},
		{name="air", prob=0, param2=0},
		{name="air", prob=0, param2=0},
		{name="air", prob=0, param2=0},
		{name="air", prob=0, param2=0},
		{name="air", prob=0, param2=0},
		{name="air", prob=0, param2=0},
		{name="air", prob=0, param2=0},
		{name="air", prob=0, param2=0},
		{name="air", prob=0, param2=0},
		{name="air", prob=0, param2=0},
		{name="air", prob=0, param2=0},
		{name="air", prob=0, param2=0},
		{name="air", prob=0, param2=0},
		{name="air", prob=0, param2=0},
		{name="air", prob=0, param2=0},
		{name="air", prob=0, param2=0},
		{name="air", prob=0, param2=0},
		{name="air", prob=0, param2=0},
		{name="stairs:slab_coral_white_sandstone", prob=254, param2=21},
		{name="stairs:slab_coral_white_sandstone", prob=254, param2=21},
		{name="stairs:slab_coral_white_sandstone", prob=254, param2=21},
		{name="air", prob=0, param2=0},
		{name="air", prob=0, param2=0},
		{name="air", prob=0, param2=0},
		{name="stairs:slab_coral_white_sandstone", prob=254, param2=23},
		{name="stairs:slab_coral_white_sandstone", prob=254, param2=21},
		{name="stairs:slab_coral_white_sandstone", prob=254, param2=21},
		{name="air", prob=0, param2=0},
		{name="air", prob=0, param2=0},
		{name="air", prob=0, param2=0},
		{name="everness:coral_sandstone_brick", prob=254, param2=0},
		{name="everness:coral_sandstone_chiseled", prob=254, param2=0},
		{name="air", prob=0, param2=0},
		{name="air", prob=0, param2=0},
		{name="air", prob=0, param2=0},
		{name="everness:coral_sandstone_chiseled", prob=254, param2=0},
		{name="everness:coral_deep_ocean_sandstone_block", prob=254, param2=0},
		{name="air", prob=0, param2=0},
		{name="air", prob=0, param2=0},
		{name="air", prob=0, param2=0},
		{name="air", prob=0, param2=0},
		{name="air", prob=0, param2=0},
		{name="everness:coral_deep_ocean_sandstone_block", prob=254, param2=0},
		{name="air", prob=0, param2=0},
		{name="air", prob=0, param2=0},
		{name="air", prob=0, param2=0},
		{name="everness:coral_sandstone_brick", prob=254, param2=0},
		{name="air", prob=0, param2=0},
		{name="air", prob=0, param2=0},
		{name="air", prob=0, param2=0},
		{name="air", prob=0, param2=0},
		{name="air", prob=0, param2=0},
		{name="air", prob=0, param2=0},
		{name="everness:coral_deep_ocean_sandstone_block", prob=254, param2=0},
		{name="everness:coral_deep_ocean_sandstone_block", prob=254, param2=0},
		{name="air", prob=0, param2=0},
		{name="everness:coral_deep_ocean_sandstone_block", prob=254, param2=0},
		{name="everness:coral_deep_ocean_sandstone_block", prob=254, param2=0},
		{name="air", prob=0, param2=0},
		{name="air", prob=0, param2=0},
		{name="air", prob=0, param2=0},
		{name="air", prob=0, param2=0},
		{name="air", prob=0, param2=0},
		{name="air", prob=0, param2=0},
		{name="air", prob=0, param2=0},
		{name="air", prob=0, param2=0},
		{name="everness:coral_deep_ocean_sandstone_block", prob=254, param2=0},
		{name="air", prob=0, param2=0},
		{name="air", prob=0, param2=0},
		{name="air", prob=0, param2=0},
		{name="air", prob=0, param2=0},
		{name="air", prob=0, param2=0},
		{name="air", prob=0, param2=0},
		{name="air", prob=0, param2=0},
		{name="air", prob=0, param2=0},
		{name="air", prob=0, param2=0},
		{name="air", prob=0, param2=0},
		{name="air", prob=0, param2=0},
		{name="air", prob=0, param2=0},
		{name="air", prob=0, param2=0},
		{name="air", prob=0, param2=0},
		{name="air", prob=0, param2=0},
		{name="air", prob=0, param2=0},
		{name="everness:coral_deep_ocean_sandstone_block", prob=126, param2=0},
		{name="air", prob=0, param2=0},
		{name="air", prob=0, param2=0},
		{name="air", prob=0, param2=0},
		{name="air", prob=0, param2=0},
		{name="air", prob=0, param2=0},
		{name="air", prob=0, param2=0},
		{name="air", prob=0, param2=0},
		{name="air", prob=0, param2=0},
		{name="air", prob=0, param2=0},
		{name="everness:coral_deep_ocean_sandstone_block", prob=126, param2=0},
		{name="air", prob=0, param2=0},
		{name="everness:coral_deep_ocean_sandstone_block", prob=254, param2=0},
		{name="everness:coral_deep_ocean_sandstone_block", prob=254, param2=0},
		{name="everness:baobab_wood", prob=254, param2=0},
		{name="stairs:slab_coral_deep_ocean_sandstone_block", prob=254, param2=2},
		{name="stairs:slab_coral_deep_ocean_sandstone_block", prob=254, param2=2},
		{name="stairs:slab_coral_deep_ocean_sandstone_block", prob=254, param2=2},
		{name="everness:baobab_wood", prob=254, param2=0},
		{name="everness:coral_deep_ocean_sandstone_block", prob=254, param2=0},
		{name="everness:coral_deep_ocean_sandstone_block", prob=254, param2=0},
		{name="air", prob=0, param2=0},
		{name="air", prob=0, param2=0},
		{name="everness:coral_deep_ocean_sandstone_block", prob=254, param2=0},
		{name="everness:coral_deep_ocean_sandstone_block", prob=254, param2=0},
		{name="air", prob=0, param2=0},
		{name="air", prob=0, param2=0},
		{name="air", prob=0, param2=0},
		{name="air", prob=0, param2=0},
		{name="air", prob=0, param2=0},
		{name="everness:coral_deep_ocean_sandstone_block", prob=254, param2=0},
		{name="everness:coral_deep_ocean_sandstone_block", prob=254, param2=0},
		{name="air", prob=0, param2=0},
		{name="air", prob=0, param2=0},
		{name="everness:coral_deep_ocean_sandstone_brick", prob=254, param2=0},
		{name="stairs:stair_coral_deep_ocean_sandstone_block", prob=254, param2=3},
		{name="air", prob=0, param2=0},
		{name="air", prob=0, param2=0},
		{name="air", prob=0, param2=0},
		{name="air", prob=0, param2=0},
		{name="air", prob=0, param2=0},
		{name="stairs:stair_coral_deep_ocean_sandstone_block", prob=254, param2=1},
		{name="everness:coral_deep_ocean_sandstone_brick", prob=254, param2=0},
		{name="air", prob=0, param2=0},
		{name="air", prob=0, param2=0},
		{name="everness:coral_deep_ocean_sandstone_brick", prob=254, param2=0},
		{name="air", prob=0, param2=0},
		{name="air", prob=0, param2=0},
		{name="air", prob=0, param2=0},
		{name="air", prob=0, param2=0},
		{name="air", prob=0, param2=0},
		{name="air", prob=0, param2=0},
		{name="air", prob=0, param2=0},
		{name="everness:coral_deep_ocean_sandstone_brick", prob=254, param2=0},
		{name="air", prob=0, param2=0},
		{name="stairs:stair_coral_white_sandstone", prob=254, param2=23},
		{name="everness:coral_deep_ocean_sandstone_brick", prob=254, param2=0},
		{name="air", prob=0, param2=0},
		{name="air", prob=0, param2=0},
		{name="air", prob=0, param2=0},
		{name="air", prob=0, param2=0},
		{name="air", prob=0, param2=0},
		{name="air", prob=0, param2=0},
		{name="air", prob=0, param2=0},
		{name="everness:coral_deep_ocean_sandstone_brick", prob=254, param2=0},
		{name="stairs:stair_coral_white_sandstone", prob=254, param2=21},
		{name="air", prob=0, param2=0},
		{name="everness:coral_deep_ocean_sandstone_block", prob=254, param2=0},
		{name="everness:coral_deep_ocean_sandstone_block", prob=254, param2=0},
		{name="everness:baobab_wood", prob=254, param2=0},
		{name="air", prob=0, param2=0},
		{name="air", prob=0, param2=0},
		{name="everness:baobab_wood", prob=254, param2=0},
		{name="everness:baobab_wood", prob=254, param2=0},
		{name="everness:coral_deep_ocean_sandstone_block", prob=254, param2=0},
		{name="everness:coral_deep_ocean_sandstone_block", prob=254, param2=0},
		{name="air", prob=0, param2=0},
		{name="air", prob=0, param2=0},
		{name="air", prob=0, param2=0},
		{name="everness:coral_sandstone_brick", prob=254, param2=0},
		{name="air", prob=0, param2=0},
		{name="air", prob=0, param2=0},
		{name="air", prob=0, param2=0},
		{name="air", prob=0, param2=0},
		{name="air", prob=0, param2=0},
		{name="everness:coral_sandstone_brick", prob=254, param2=0},
		{name="air", prob=0, param2=0},
		{name="air", prob=0, param2=0},
		{name="air", prob=0, param2=0},
		{name="air", prob=0, param2=0},
		{name="everness:coral_deep_ocean_sandstone_block", prob=254, param2=0},
		{name="air", prob=0, param2=0},
		{name="air", prob=0, param2=0},
		{name="air", prob=0, param2=0},
		{name="air", prob=0, param2=0},
		{name="air", prob=0, param2=0},
		{name="everness:coral_deep_ocean_sandstone_block", prob=254, param2=0},
		{name="air", prob=0, param2=0},
		{name="air", prob=0, param2=0},
		{name="air", prob=0, param2=0},
		{name="air", prob=0, param2=0},
		{name="everness:coral_deep_ocean_sandstone_brick", prob=254, param2=0},
		{name="air", prob=0, param2=0},
		{name="air", prob=0, param2=0},
		{name="air", prob=0, param2=0},
		{name="air", prob=0, param2=0},
		{name="air", prob=0, param2=0},
		{name="everness:coral_deep_ocean_sandstone_brick", prob=254, param2=0},
		{name="air", prob=0, param2=0},
		{name="air", prob=0, param2=0},
		{name="air", prob=0, param2=0},
		{name="air", prob=0, param2=0},
		{name="everness:coral_deep_ocean_sandstone_brick", prob=254, param2=0},
		{name="air", prob=0, param2=0},
		{name="air", prob=0, param2=0},
		{name="air", prob=0, param2=0},
		{name="air", prob=0, param2=0},
		{name="air", prob=0, param2=0},
		{name="everness:coral_deep_ocean_sandstone_brick", prob=254, param2=0},
		{name="air", prob=0, param2=0},
		{name="air", prob=0, param2=0},
		{name="air", prob=0, param2=0},
		{name="stairs:stair_coral_white_sandstone", prob=254, param2=23},
		{name="everness:coral_deep_ocean_sandstone_block", prob=254, param2=0},
		{name="air", prob=0, param2=0},
		{name="air", prob=0, param2=0},
		{name="air", prob=0, param2=0},
		{name="air", prob=0, param2=0},
		{name="air", prob=0, param2=0},
		{name="everness:coral_deep_ocean_sandstone_block", prob=254, param2=0},
		{name="stairs:stair_coral_white_sandstone", prob=254, param2=21},
		{name="air", prob=0, param2=0},
		{name="air", prob=0, param2=0},
		{name="air", prob=0, param2=0},
		{name="everness:coral_deep_ocean_sandstone_block", prob=254, param2=0},
		{name="everness:coral_sandstone_carved_1", prob=254, param2=0},
		{name="air", prob=0, param2=0},
		{name="air", prob=0, param2=0},
		{name="air", prob=0, param2=0},
		{name="everness:coral_sandstone_carved_1", prob=254, param2=0},
		{name="everness:coral_deep_ocean_sandstone_block", prob=254, param2=0},
		{name="air", prob=0, param2=0},
		{name="air", prob=0, param2=0},
		{name="air", prob=0, param2=0},
		{name="air", prob=0, param2=0},
		{name="everness:coral_deep_ocean_sandstone_block", prob=254, param2=0},
		{name="everness:coral_forest_deep_ocean_lantern", prob=126, param2=0},
		{name="air", prob=0, param2=0},
		{name="air", prob=0, param2=0},
		{name="air", prob=0, param2=0},
		{name="everness:coral_forest_deep_ocean_lantern", prob=126, param2=0},
		{name="everness:coral_deep_ocean_sandstone_block", prob=254, param2=0},
		{name="air", prob=0, param2=0},
		{name="air", prob=0, param2=0},
		{name="air", prob=0, param2=0},
		{name="air", prob=0, param2=0},
		{name="air", prob=0, param2=0},
		{name="everness:coral_deep_ocean_sandstone_block", prob=254, param2=0},
		{name="air", prob=0, param2=0},
		{name="air", prob=0, param2=0},
		{name="air", prob=0, param2=0},
		{name="everness:coral_deep_ocean_sandstone_block", prob=254, param2=0},
		{name="air", prob=0, param2=0},
		{name="air", prob=0, param2=0},
		{name="air", prob=0, param2=0},
		{name="air", prob=0, param2=0},
		{name="air", prob=0, param2=0},
		{name="air", prob=0, param2=0},
		{name="air", prob=0, param2=0},
		{name="everness:coral_deep_ocean_sandstone_block", prob=254, param2=0},
		{name="everness:coral_deep_ocean_sandstone_block", prob=254, param2=0},
		{name="everness:coral_deep_ocean_sandstone_block", prob=254, param2=0},
		{name="air", prob=0, param2=0},
		{name="air", prob=0, param2=0},
		{name="air", prob=0, param2=0},
		{name="air", prob=0, param2=0},
		{name="air", prob=0, param2=0},
		{name="air", prob=0, param2=0},
		{name="air", prob=0, param2=0},
		{name="air", prob=0, param2=0},
		{name="air", prob=0, param2=0},
		{name="everness:coral_deep_ocean_sandstone_block", prob=254, param2=0},
		{name="air", prob=0, param2=0},
		{name="air", prob=0, param2=0},
		{name="air", prob=0, param2=0},
		{name="air", prob=0, param2=0},
		{name="air", prob=0, param2=0},
		{name="everness:coral_deep_ocean_sandstone_block", prob=126, param2=0},
		{name="air", prob=0, param2=0},
		{name="air", prob=0, param2=0},
		{name="air", prob=0, param2=0},
		{name="air", prob=0, param2=0},
		{name="air", prob=0, param2=0},
		{name="air", prob=0, param2=0},
		{name="air", prob=0, param2=0},
		{name="air", prob=0, param2=0},
		{name="air", prob=0, param2=0},
		{name="everness:coral_deep_ocean_sandstone_block", prob=126, param2=0},
		{name="air", prob=0, param2=0},
		{name="everness:coral_deep_ocean_sandstone_block", prob=254, param2=0},
		{name="everness:coral_deep_ocean_sandstone_block", prob=254, param2=0},
		{name="everness:baobab_wood", prob=254, param2=0},
		{name="everness:baobab_wood", prob=254, param2=0},
		{name="everness:baobab_wood", prob=254, param2=0},
		{name="stairs:slab_coral_deep_ocean_sandstone_block", prob=254, param2=2},
		{name="everness:baobab_wood", prob=254, param2=0},
		{name="everness:coral_deep_ocean_sandstone_block", prob=254, param2=0},
		{name="everness:coral_deep_ocean_sandstone_block", prob=254, param2=0},
		{name="air", prob=0, param2=0},
		{name="air", prob=0, param2=0},
		{name="air", prob=0, param2=0},
		{name="air", prob=0, param2=0},
		{name="air", prob=0, param2=0},
		{name="air", prob=0, param2=0},
		{name="air", prob=0, param2=0},
		{name="air", prob=0, param2=0},
		{name="air", prob=0, param2=0},
		{name="air", prob=0, param2=0},
		{name="air", prob=0, param2=0},
		{name="air", prob=0, param2=0},
		{name="air", prob=0, param2=0},
		{name="air", prob=0, param2=0},
		{name="air", prob=0, param2=0},
		{name="air", prob=0, param2=0},
		{name="air", prob=0, param2=0},
		{name="air", prob=0, param2=0},
		{name="air", prob=0, param2=0},
		{name="air", prob=0, param2=0},
		{name="air", prob=0, param2=0},
		{name="air", prob=0, param2=0},
		{name="air", prob=0, param2=0},
		{name="air", prob=0, param2=0},
		{name="stairs:stair_coral_deep_ocean_sandstone_block", prob=254, param2=22},
		{name="air", prob=0, param2=0},
		{name="air", prob=0, param2=0},
		{name="air", prob=0, param2=0},
		{name="air", prob=0, param2=0},
		{name="air", prob=0, param2=0},
		{name="air", prob=0, param2=0},
		{name="air", prob=0, param2=0},
		{name="stairs:stair_coral_deep_ocean_sandstone_block", prob=254, param2=22},
		{name="air", prob=0, param2=0},
		{name="stairs:stair_coral_white_sandstone", prob=254, param2=23},
		{name="everness:coral_deep_ocean_sandstone_brick", prob=254, param2=0},
		{name="air", prob=0, param2=0},
		{name="air", prob=0, param2=0},
		{name="air", prob=0, param2=0},
		{name="air", prob=0, param2=0},
		{name="air", prob=0, param2=0},
		{name="air", prob=0, param2=0},
		{name="air", prob=0, param2=0},
		{name="everness:coral_deep_ocean_sandstone_brick", prob=254, param2=0},
		{name="stairs:stair_coral_white_sandstone", prob=254, param2=21},
		{name="air", prob=0, param2=0},
		{name="everness:coral_deep_ocean_sandstone_block", prob=254, param2=0},
		{name="everness:coral_deep_ocean_sandstone_block", prob=254, param2=0},
		{name="everness:baobab_wood", prob=254, param2=0},
		{name="everness:baobab_wood", prob=254, param2=0},
		{name="air", prob=0, param2=0},
		{name="air", prob=0, param2=0},
		{name="everness:baobab_wood", prob=254, param2=0},
		{name="everness:coral_deep_ocean_sandstone_block", prob=254, param2=0},
		{name="everness:coral_deep_ocean_sandstone_block", prob=254, param2=0},
		{name="air", prob=0, param2=0},
		{name="air", prob=0, param2=0},
		{name="air", prob=0, param2=0},
		{name="air", prob=0, param2=0},
		{name="air", prob=0, param2=0},
		{name="air", prob=0, param2=0},
		{name="air", prob=0, param2=0},
		{name="air", prob=0, param2=0},
		{name="air", prob=0, param2=0},
		{name="air", prob=0, param2=0},
		{name="air", prob=0, param2=0},
		{name="air", prob=0, param2=0},
		{name="air", prob=0, param2=0},
		{name="air", prob=0, param2=0},
		{name="air", prob=0, param2=0},
		{name="air", prob=0, param2=0},
		{name="air", prob=0, param2=0},
		{name="air", prob=0, param2=0},
		{name="air", prob=0, param2=0},
		{name="air", prob=0, param2=0},
		{name="air", prob=0, param2=0},
		{name="air", prob=0, param2=0},
		{name="air", prob=0, param2=0},
		{name="air", prob=0, param2=0},
		{name="air", prob=0, param2=0},
		{name="air", prob=0, param2=0},
		{name="air", prob=0, param2=0},
		{name="air", prob=0, param2=0},
		{name="air", prob=0, param2=0},
		{name="air", prob=0, param2=0},
		{name="air", prob=0, param2=0},
		{name="air", prob=0, param2=0},
		{name="air", prob=0, param2=0},
		{name="air", prob=0, param2=0},
		{name="air", prob=0, param2=0},
		{name="air", prob=0, param2=0},
		{name="air", prob=0, param2=0},
		{name="air", prob=0, param2=0},
		{name="air", prob=0, param2=0},
		{name="air", prob=0, param2=0},
		{name="air", prob=0, param2=0},
		{name="air", prob=0, param2=0},
		{name="air", prob=0, param2=0},
		{name="air", prob=0, param2=0},
		{name="air", prob=0, param2=0},
		{name="air", prob=0, param2=0},
		{name="stairs:slab_coral_white_sandstone", prob=254, param2=23},
		{name="stairs:slab_coral_white_sandstone", prob=254, param2=23},
		{name="stairs:slab_coral_white_sandstone", prob=254, param2=21},
		{name="air", prob=0, param2=0},
		{name="air", prob=0, param2=0},
		{name="air", prob=0, param2=0},
		{name="stairs:slab_coral_white_sandstone", prob=254, param2=20},
		{name="stairs:slab_coral_white_sandstone", prob=254, param2=22},
		{name="stairs:slab_coral_white_sandstone", prob=254, param2=22},
		{name="air", prob=0, param2=0},
		{name="air", prob=0, param2=0},
		{name="air", prob=0, param2=0},
		{name="everness:coral_deep_ocean_sandstone_block", prob=254, param2=0},
		{name="everness:coral_sandstone_chiseled", prob=254, param2=0},
		{name="air", prob=0, param2=0},
		{name="air", prob=0, param2=0},
		{name="air", prob=0, param2=0},
		{name="everness:coral_sandstone_chiseled", prob=254, param2=0},
		{name="everness:coral_sandstone_brick", prob=254, param2=0},
		{name="air", prob=0, param2=0},
		{name="air", prob=0, param2=0},
		{name="air", prob=0, param2=0},
		{name="air", prob=0, param2=0},
		{name="air", prob=0, param2=0},
		{name="everness:coral_deep_ocean_sandstone_block", prob=254, param2=0},
		{name="air", prob=0, param2=0},
		{name="air", prob=0, param2=0},
		{name="air", prob=0, param2=0},
		{name="everness:coral_sandstone_brick", prob=254, param2=0},
		{name="air", prob=0, param2=0},
		{name="air", prob=0, param2=0},
		{name="air", prob=0, param2=0},
		{name="air", prob=0, param2=0},
		{name="air", prob=0, param2=0},
		{name="air", prob=0, param2=0},
		{name="everness:coral_deep_ocean_sandstone_block", prob=254, param2=0},
		{name="everness:coral_deep_ocean_sandstone_block", prob=254, param2=0},
		{name="air", prob=0, param2=0},
		{name="everness:coral_deep_ocean_sandstone_block", prob=254, param2=0},
		{name="everness:coral_deep_ocean_sandstone_block", prob=254, param2=0},
		{name="air", prob=0, param2=0},
		{name="air", prob=0, param2=0},
		{name="air", prob=0, param2=0},
		{name="air", prob=0, param2=0},
		{name="air", prob=0, param2=0},
		{name="air", prob=0, param2=0},
		{name="air", prob=0, param2=0},
		{name="air", prob=0, param2=0},
		{name="everness:coral_deep_ocean_sandstone_block", prob=254, param2=0},
		{name="air", prob=0, param2=0},
		{name="air", prob=0, param2=0},
		{name="air", prob=0, param2=0},
		{name="air", prob=0, param2=0},
		{name="air", prob=0, param2=0},
		{name="air", prob=0, param2=0},
		{name="air", prob=0, param2=0},
		{name="air", prob=0, param2=0},
		{name="air", prob=0, param2=0},
		{name="air", prob=0, param2=0},
		{name="air", prob=0, param2=0},
		{name="air", prob=0, param2=0},
		{name="air", prob=0, param2=0},
		{name="air", prob=0, param2=0},
		{name="air", prob=0, param2=0},
		{name="air", prob=0, param2=0},
		{name="everness:coral_deep_ocean_sandstone_block", prob=126, param2=0},
		{name="air", prob=0, param2=0},
		{name="air", prob=0, param2=0},
		{name="air", prob=0, param2=0},
		{name="air", prob=0, param2=0},
		{name="air", prob=0, param2=0},
		{name="air", prob=0, param2=0},
		{name="air", prob=0, param2=0},
		{name="air", prob=0, param2=0},
		{name="air", prob=0, param2=0},
		{name="everness:coral_deep_ocean_sandstone_block", prob=126, param2=0},
		{name="air", prob=0, param2=0},
		{name="everness:coral_deep_ocean_sandstone_block", prob=254, param2=0},
		{name="everness:coral_deep_ocean_sandstone_block", prob=254, param2=0},
		{name="everness:baobab_wood", prob=254, param2=0},
		{name="everness:baobab_wood", prob=254, param2=0},
		{name="everness:baobab_wood", prob=254, param2=0},
		{name="everness:baobab_wood", prob=254, param2=0},
		{name="everness:baobab_wood", prob=254, param2=0},
		{name="everness:coral_deep_ocean_sandstone_block", prob=254, param2=0},
		{name="everness:coral_deep_ocean_sandstone_block", prob=254, param2=0},
		{name="air", prob=0, param2=0},
		{name="air", prob=0, param2=0},
		{name="air", prob=0, param2=0},
		{name="air", prob=0, param2=0},
		{name="air", prob=0, param2=0},
		{name="air", prob=0, param2=0},
		{name="air", prob=0, param2=0},
		{name="air", prob=0, param2=0},
		{name="air", prob=0, param2=0},
		{name="air", prob=0, param2=0},
		{name="air", prob=0, param2=0},
		{name="air", prob=0, param2=0},
		{name="air", prob=0, param2=0},
		{name="air", prob=0, param2=0},
		{name="air", prob=0, param2=0},
		{name="air", prob=0, param2=0},
		{name="air", prob=0, param2=0},
		{name="air", prob=0, param2=0},
		{name="air", prob=0, param2=0},
		{name="air", prob=0, param2=0},
		{name="air", prob=0, param2=0},
		{name="air", prob=0, param2=0},
		{name="air", prob=0, param2=0},
		{name="air", prob=0, param2=0},
		{name="stairs:stair_coral_deep_ocean_sandstone_block", prob=254, param2=20},
		{name="air", prob=0, param2=0},
		{name="air", prob=0, param2=0},
		{name="air", prob=0, param2=0},
		{name="air", prob=0, param2=0},
		{name="air", prob=0, param2=0},
		{name="air", prob=0, param2=0},
		{name="air", prob=0, param2=0},
		{name="stairs:stair_coral_deep_ocean_sandstone_block", prob=254, param2=20},
		{name="air", prob=0, param2=0},
		{name="stairs:stair_coral_white_sandstone", prob=254, param2=23},
		{name="everness:coral_deep_ocean_sandstone_brick", prob=254, param2=0},
		{name="air", prob=0, param2=0},
		{name="air", prob=0, param2=0},
		{name="air", prob=0, param2=0},
		{name="air", prob=0, param2=0},
		{name="air", prob=0, param2=0},
		{name="air", prob=0, param2=0},
		{name="air", prob=0, param2=0},
		{name="everness:coral_deep_ocean_sandstone_brick", prob=254, param2=0},
		{name="stairs:stair_coral_white_sandstone", prob=254, param2=21},
		{name="air", prob=0, param2=0},
		{name="everness:coral_deep_ocean_sandstone_block", prob=254, param2=0},
		{name="everness:coral_deep_ocean_sandstone_block", prob=254, param2=0},
		{name="everness:coral_deep_ocean_sandstone_block", prob=254, param2=0},
		{name="everness:baobab_wood", prob=254, param2=0},
		{name="everness:baobab_wood", prob=254, param2=0},
		{name="everness:baobab_wood", prob=254, param2=0},
		{name="everness:coral_deep_ocean_sandstone_block", prob=254, param2=0},
		{name="everness:coral_deep_ocean_sandstone_block", prob=254, param2=0},
		{name="everness:coral_deep_ocean_sandstone_block", prob=254, param2=0},
		{name="air", prob=0, param2=0},
		{name="air", prob=0, param2=0},
		{name="air", prob=0, param2=0},
		{name="air", prob=0, param2=0},
		{name="everness:coral_sandstone_brick", prob=254, param2=0},
		{name="air", prob=0, param2=0},
		{name="air", prob=0, param2=0},
		{name="air", prob=0, param2=0},
		{name="everness:coral_sandstone_brick", prob=254, param2=0},
		{name="air", prob=0, param2=0},
		{name="air", prob=0, param2=0},
		{name="air", prob=0, param2=0},
		{name="air", prob=0, param2=0},
		{name="air", prob=0, param2=0},
		{name="air", prob=0, param2=0},
		{name="everness:coral_deep_ocean_sandstone_block", prob=254, param2=0},
		{name="air", prob=0, param2=0},
		{name="air", prob=0, param2=0},
		{name="air", prob=0, param2=0},
		{name="everness:coral_deep_ocean_sandstone_block", prob=254, param2=0},
		{name="air", prob=0, param2=0},
		{name="air", prob=0, param2=0},
		{name="air", prob=0, param2=0},
		{name="air", prob=0, param2=0},
		{name="air", prob=0, param2=0},
		{name="air", prob=0, param2=0},
		{name="everness:coral_deep_ocean_sandstone_brick", prob=254, param2=0},
		{name="air", prob=0, param2=0},
		{name="air", prob=0, param2=0},
		{name="air", prob=0, param2=0},
		{name="everness:coral_deep_ocean_sandstone_brick", prob=254, param2=0},
		{name="air", prob=0, param2=0},
		{name="air", prob=0, param2=0},
		{name="air", prob=0, param2=0},
		{name="air", prob=0, param2=0},
		{name="air", prob=0, param2=0},
		{name="air", prob=0, param2=0},
		{name="everness:coral_deep_ocean_sandstone_brick", prob=254, param2=0},
		{name="air", prob=0, param2=0},
		{name="air", prob=0, param2=0},
		{name="air", prob=0, param2=0},
		{name="everness:coral_deep_ocean_sandstone_brick", prob=254, param2=0},
		{name="air", prob=0, param2=0},
		{name="air", prob=0, param2=0},
		{name="air", prob=0, param2=0},
		{name="air", prob=0, param2=0},
		{name="air", prob=0, param2=0},
		{name="stairs:stair_coral_white_sandstone", prob=254, param2=23},
		{name="everness:coral_deep_ocean_sandstone_block", prob=254, param2=0},
		{name="stairs:slab_coral_white_sandstone", prob=254, param2=20},
		{name="air", prob=0, param2=0},
		{name="stairs:slab_coral_white_sandstone", prob=254, param2=22},
		{name="everness:coral_deep_ocean_sandstone_block", prob=254, param2=0},
		{name="stairs:stair_coral_white_sandstone", prob=254, param2=21},
		{name="air", prob=0, param2=0},
		{name="air", prob=0, param2=0},
		{name="air", prob=0, param2=0},
		{name="air", prob=0, param2=0},
		{name="air", prob=0, param2=0},
		{name="everness:coral_deep_ocean_sandstone_block", prob=254, param2=0},
		{name="everness:coral_sandstone_chiseled", prob=254, param2=0},
		{name="everness:coral_sandstone_carved_1", prob=254, param2=0},
		{name="everness:coral_sandstone_chiseled", prob=254, param2=0},
		{name="everness:coral_deep_ocean_sandstone_block", prob=254, param2=0},
		{name="air", prob=0, param2=0},
		{name="air", prob=0, param2=0},
		{name="air", prob=0, param2=0},
		{name="air", prob=0, param2=0},
		{name="air", prob=0, param2=0},
		{name="air", prob=0, param2=0},
		{name="everness:coral_sandstone_brick", prob=254, param2=0},
		{name="everness:coral_deep_ocean_sandstone_block", prob=254, param2=0},
		{name="everness:coral_forest_deep_ocean_lantern", prob=126, param2=0},
		{name="everness:coral_deep_ocean_sandstone_block", prob=254, param2=0},
		{name="everness:coral_deep_ocean_sandstone_block", prob=254, param2=0},
		{name="air", prob=0, param2=0},
		{name="air", prob=0, param2=0},
		{name="air", prob=0, param2=0},
		{name="air", prob=0, param2=0},
		{name="air", prob=0, param2=0},
		{name="air", prob=0, param2=0},
		{name="air", prob=0, param2=0},
		{name="everness:coral_sandstone_brick", prob=254, param2=0},
		{name="everness:coral_sandstone_brick", prob=254, param2=0},
		{name="everness:coral_sandstone_brick", prob=254, param2=0},
		{name="air", prob=0, param2=0},
		{name="air", prob=0, param2=0},
		{name="air", prob=0, param2=0},
		{name="air", prob=0, param2=0},
		{name="air", prob=0, param2=0},
		{name="air", prob=0, param2=0},
		{name="air", prob=0, param2=0},
		{name="air", prob=0, param2=0},
		{name="air", prob=0, param2=0},
		{name="air", prob=0, param2=0},
		{name="air", prob=0, param2=0},
		{name="air", prob=0, param2=0},
		{name="air", prob=0, param2=0},
		{name="air", prob=0, param2=0},
		{name="air", prob=0, param2=0},
		{name="air", prob=0, param2=0},
		{name="air", prob=0, param2=0},
		{name="air", prob=0, param2=0},
		{name="air", prob=0, param2=0},
		{name="air", prob=0, param2=0},
		{name="air", prob=0, param2=0},
		{name="air", prob=0, param2=0},
		{name="air", prob=0, param2=0},
		{name="air", prob=0, param2=0},
		{name="air", prob=0, param2=0},
		{name="air", prob=0, param2=0},
		{name="everness:coral_deep_ocean_sandstone_block", prob=126, param2=0},
		{name="air", prob=0, param2=0},
		{name="air", prob=0, param2=0},
		{name="air", prob=0, param2=0},
		{name="air", prob=0, param2=0},
		{name="air", prob=0, param2=0},
		{name="air", prob=0, param2=0},
		{name="air", prob=0, param2=0},
		{name="air", prob=0, param2=0},
		{name="air", prob=0, param2=0},
		{name="everness:coral_deep_ocean_sandstone_block", prob=126, param2=0},
		{name="air", prob=0, param2=0},
		{name="everness:coral_deep_ocean_sandstone_block", prob=254, param2=0},
		{name="everness:coral_deep_ocean_sandstone_block", prob=254, param2=0},
		{name="everness:coral_deep_ocean_sandstone_block", prob=254, param2=0},
		{name="everness:coral_deep_ocean_sandstone_block", prob=254, param2=0},
		{name="everness:coral_deep_ocean_sandstone_block", prob=254, param2=0},
		{name="everness:coral_deep_ocean_sandstone_block", prob=254, param2=0},
		{name="everness:coral_deep_ocean_sandstone_block", prob=254, param2=0},
		{name="everness:coral_deep_ocean_sandstone_block", prob=254, param2=0},
		{name="everness:coral_deep_ocean_sandstone_block", prob=254, param2=0},
		{name="air", prob=0, param2=0},
		{name="air", prob=0, param2=0},
		{name="everness:coral_deep_ocean_sandstone_block", prob=254, param2=0},
		{name="everness:coral_deep_ocean_sandstone_block", prob=254, param2=0},
		{name="air", prob=0, param2=0},
		{name="air", prob=0, param2=0},
		{name="air", prob=0, param2=0},
		{name="air", prob=0, param2=0},
		{name="air", prob=0, param2=0},
		{name="everness:coral_deep_ocean_sandstone_block", prob=254, param2=0},
		{name="everness:coral_deep_ocean_sandstone_block", prob=254, param2=0},
		{name="air", prob=0, param2=0},
		{name="air", prob=0, param2=0},
		{name="everness:coral_deep_ocean_sandstone_brick", prob=254, param2=0},
		{name="everness:coral_deep_ocean_sandstone_block", prob=254, param2=0},
		{name="air", prob=0, param2=0},
		{name="air", prob=0, param2=0},
		{name="air", prob=0, param2=0},
		{name="air", prob=0, param2=0},
		{name="air", prob=0, param2=0},
		{name="everness:coral_deep_ocean_sandstone_block", prob=254, param2=0},
		{name="everness:coral_deep_ocean_sandstone_brick", prob=254, param2=0},
		{name="air", prob=0, param2=0},
		{name="air", prob=0, param2=0},
		{name="everness:coral_deep_ocean_sandstone_brick", prob=254, param2=0},
		{name="everness:coral_deep_ocean_sandstone_block", prob=254, param2=0},
		{name="air", prob=0, param2=0},
		{name="air", prob=0, param2=0},
		{name="air", prob=0, param2=0},
		{name="air", prob=0, param2=0},
		{name="air", prob=0, param2=0},
		{name="everness:coral_deep_ocean_sandstone_block", prob=254, param2=0},
		{name="everness:coral_deep_ocean_sandstone_brick", prob=254, param2=0},
		{name="air", prob=0, param2=0},
		{name="stairs:stair_coral_white_sandstone", prob=254, param2=23},
		{name="everness:coral_deep_ocean_sandstone_brick", prob=254, param2=0},
		{name="everness:coral_deep_ocean_sandstone_block", prob=254, param2=0},
		{name="air", prob=0, param2=0},
		{name="air", prob=0, param2=0},
		{name="air", prob=0, param2=0},
		{name="air", prob=0, param2=0},
		{name="air", prob=0, param2=0},
		{name="everness:coral_deep_ocean_sandstone_block", prob=254, param2=0},
		{name="everness:coral_deep_ocean_sandstone_brick", prob=254, param2=0},
		{name="stairs:stair_coral_white_sandstone", prob=254, param2=21},
		{name="air", prob=0, param2=0},
		{name="everness:coral_sandstone_brick", prob=254, param2=0},
		{name="everness:coral_deep_ocean_sandstone_block", prob=254, param2=0},
		{name="everness:coral_deep_ocean_sandstone_block", prob=254, param2=0},
		{name="everness:coral_deep_ocean_sandstone_block", prob=254, param2=0},
		{name="everness:coral_deep_ocean_sandstone_block", prob=254, param2=0},
		{name="everness:coral_deep_ocean_sandstone_block", prob=254, param2=0},
		{name="everness:coral_deep_ocean_sandstone_block", prob=254, param2=0},
		{name="everness:coral_deep_ocean_sandstone_block", prob=254, param2=0},
		{name="everness:coral_sandstone_brick", prob=254, param2=0},
		{name="air", prob=0, param2=0},
		{name="air", prob=0, param2=0},
		{name="air", prob=0, param2=0},
		{name="air", prob=0, param2=0},
		{name="air", prob=0, param2=0},
		{name="air", prob=0, param2=0},
		{name="everness:coral_sandstone_brick", prob=254, param2=0},
		{name="air", prob=0, param2=0},
		{name="air", prob=0, param2=0},
		{name="air", prob=0, param2=0},
		{name="air", prob=0, param2=0},
		{name="air", prob=0, param2=0},
		{name="air", prob=0, param2=0},
		{name="air", prob=0, param2=0},
		{name="air", prob=0, param2=0},
		{name="air", prob=0, param2=0},
		{name="air", prob=0, param2=0},
		{name="everness:coral_deep_ocean_sandstone_block", prob=254, param2=0},
		{name="air", prob=0, param2=0},
		{name="air", prob=0, param2=0},
		{name="air", prob=0, param2=0},
		{name="air", prob=0, param2=0},
		{name="air", prob=0, param2=0},
		{name="air", prob=0, param2=0},
		{name="air", prob=0, param2=0},
		{name="air", prob=0, param2=0},
		{name="air", prob=0, param2=0},
		{name="air", prob=0, param2=0},
		{name="everness:coral_deep_ocean_sandstone_brick", prob=254, param2=0},
		{name="air", prob=0, param2=0},
		{name="air", prob=0, param2=0},
		{name="air", prob=0, param2=0},
		{name="air", prob=0, param2=0},
		{name="air", prob=0, param2=0},
		{name="air", prob=0, param2=0},
		{name="air", prob=0, param2=0},
		{name="air", prob=0, param2=0},
		{name="air", prob=0, param2=0},
		{name="air", prob=0, param2=0},
		{name="everness:coral_deep_ocean_sandstone_brick", prob=254, param2=0},
		{name="air", prob=0, param2=0},
		{name="air", prob=0, param2=0},
		{name="air", prob=0, param2=0},
		{name="air", prob=0, param2=0},
		{name="air", prob=0, param2=0},
		{name="air", prob=0, param2=0},
		{name="air", prob=0, param2=0},
		{name="stairs:slab_coral_white_sandstone", prob=254, param2=23},
		{name="stairs:stair_coral_white_sandstone", prob=254, param2=22},
		{name="stairs:slab_coral_white_sandstone", prob=254, param2=20},
		{name="everness:coral_deep_ocean_sandstone_block", prob=254, param2=0},
		{name="stairs:slab_coral_white_sandstone", prob=254, param2=22},
		{name="stairs:stair_coral_white_sandstone", prob=254, param2=22},
		{name="stairs:slab_coral_white_sandstone", prob=254, param2=22},
		{name="air", prob=0, param2=0},
		{name="air", prob=0, param2=0},
		{name="air", prob=0, param2=0},
		{name="air", prob=0, param2=0},
		{name="air", prob=0, param2=0},
		{name="air", prob=0, param2=0},
		{name="everness:coral_deep_ocean_sandstone_block", prob=254, param2=0},
		{name="everness:coral_sandstone_brick", prob=254, param2=0},
		{name="everness:coral_sandstone_brick", prob=254, param2=0},
		{name="air", prob=0, param2=0},
		{name="air", prob=0, param2=0},
		{name="air", prob=0, param2=0},
		{name="air", prob=0, param2=0},
		{name="air", prob=0, param2=0},
		{name="air", prob=0, param2=0},
		{name="air", prob=0, param2=0},
		{name="air", prob=0, param2=0},
		{name="air", prob=0, param2=0},
		{name="everness:coral_sandstone_brick", prob=254, param2=0},
		{name="air", prob=0, param2=0},
		{name="air", prob=0, param2=0},
		{name="air", prob=0, param2=0},
		{name="air", prob=0, param2=0},
		{name="air", prob=0, param2=0},
		{name="air", prob=0, param2=0},
		{name="air", prob=0, param2=0},
		{name="air", prob=0, param2=0},
		{name="air", prob=0, param2=0},
		{name="air", prob=0, param2=0},
		{name="air", prob=0, param2=0},
		{name="air", prob=0, param2=0},
		{name="air", prob=0, param2=0},
		{name="air", prob=0, param2=0},
		{name="air", prob=0, param2=0},
		{name="air", prob=0, param2=0},
		{name="air", prob=0, param2=0},
		{name="air", prob=0, param2=0},
		{name="air", prob=0, param2=0},
		{name="air", prob=0, param2=0},
		{name="air", prob=0, param2=0},
		{name="air", prob=0, param2=0},
		{name="air", prob=0, param2=0},
		{name="air", prob=0, param2=0},
		{name="air", prob=0, param2=0},
		{name="air", prob=0, param2=0},
		{name="air", prob=0, param2=0},
		{name="air", prob=0, param2=0},
		{name="air", prob=0, param2=0},
		{name="air", prob=0, param2=0},
		{name="air", prob=0, param2=0},
		{name="air", prob=0, param2=0},
		{name="air", prob=0, param2=0},
		{name="air", prob=0, param2=0},
		{name="air", prob=0, param2=0},
		{name="air", prob=0, param2=0},
		{name="air", prob=0, param2=0},
		{name="air", prob=0, param2=0},
		{name="everness:coral_deep_ocean_sandstone_block", prob=126, param2=0},
		{name="air", prob=0, param2=0},
		{name="air", prob=0, param2=0},
		{name="air", prob=0, param2=0},
		{name="air", prob=0, param2=0},
		{name="air", prob=0, param2=0},
		{name="air", prob=0, param2=0},
		{name="air", prob=0, param2=0},
		{name="air", prob=0, param2=0},
		{name="air", prob=0, param2=0},
		{name="everness:coral_deep_ocean_sandstone_block", prob=126, param2=0},
		{name="air", prob=0, param2=0},
		{name="everness:coral_deep_ocean_sandstone_block", prob=254, param2=0},
		{name="everness:coral_deep_ocean_sandstone_block", prob=254, param2=0},
		{name="everness:coral_deep_ocean_sandstone_block", prob=254, param2=0},
		{name="everness:coral_deep_ocean_sandstone_block", prob=254, param2=0},
		{name="everness:coral_deep_ocean_sandstone_block", prob=254, param2=0},
		{name="everness:coral_deep_ocean_sandstone_block", prob=254, param2=0},
		{name="everness:coral_deep_ocean_sandstone_block", prob=254, param2=0},
		{name="everness:coral_deep_ocean_sandstone_block", prob=254, param2=0},
		{name="everness:coral_deep_ocean_sandstone_block", prob=254, param2=0},
		{name="air", prob=0, param2=0},
		{name="air", prob=0, param2=0},
		{name="air", prob=0, param2=0},
		{name="everness:coral_deep_ocean_sandstone_block", prob=254, param2=0},
		{name="everness:coral_deep_ocean_sandstone_block", prob=254, param2=0},
		{name="air", prob=0, param2=0},
		{name="air", prob=0, param2=0},
		{name="air", prob=0, param2=0},
		{name="everness:coral_deep_ocean_sandstone_block", prob=254, param2=0},
		{name="everness:coral_deep_ocean_sandstone_block", prob=254, param2=0},
		{name="air", prob=0, param2=0},
		{name="air", prob=0, param2=0},
		{name="air", prob=0, param2=0},
		{name="air", prob=0, param2=0},
		{name="everness:coral_deep_ocean_sandstone_brick", prob=254, param2=0},
		{name="air", prob=0, param2=0},
		{name="air", prob=0, param2=0},
		{name="air", prob=0, param2=0},
		{name="air", prob=0, param2=0},
		{name="air", prob=0, param2=0},
		{name="everness:coral_deep_ocean_sandstone_brick", prob=254, param2=0},
		{name="air", prob=0, param2=0},
		{name="air", prob=0, param2=0},
		{name="air", prob=0, param2=0},
		{name="air", prob=0, param2=0},
		{name="everness:coral_deep_ocean_sandstone_brick", prob=254, param2=0},
		{name="air", prob=0, param2=0},
		{name="air", prob=0, param2=0},
		{name="air", prob=0, param2=0},
		{name="air", prob=0, param2=0},
		{name="air", prob=0, param2=0},
		{name="everness:coral_deep_ocean_sandstone_brick", prob=254, param2=0},
		{name="air", prob=0, param2=0},
		{name="air", prob=0, param2=0},
		{name="stairs:stair_coral_white_sandstone", prob=254, param2=23},
		{name="stairs:stair_coral_white_sandstone", prob=254, param2=21},
		{name="everness:coral_deep_ocean_sandstone_brick", prob=254, param2=0},
		{name="stairs:slab_coral_deep_ocean_sandstone_brick", prob=254, param2=22},
		{name="air", prob=0, param2=0},
		{name="air", prob=0, param2=0},
		{name="air", prob=0, param2=0},
		{name="stairs:slab_coral_deep_ocean_sandstone_brick", prob=254, param2=22},
		{name="everness:coral_deep_ocean_sandstone_brick", prob=254, param2=0},
		{name="stairs:stair_coral_white_sandstone", prob=254, param2=23},
		{name="stairs:stair_coral_white_sandstone", prob=254, param2=21},
		{name="air", prob=0, param2=0},
		{name="stairs:slab_coral_white_sandstone", prob=254, param2=2},
		{name="everness:coral_sandstone_brick", prob=254, param2=0},
		{name="everness:coral_deep_ocean_sandstone_brick", prob=254, param2=0},
		{name="everness:coral_deep_ocean_sandstone_brick", prob=254, param2=0},
		{name="stairs:slab_coral_deep_ocean_sandstone_brick", prob=254, param2=22},
		{name="everness:coral_deep_ocean_sandstone_brick", prob=254, param2=0},
		{name="everness:coral_deep_ocean_sandstone_brick", prob=254, param2=0},
		{name="everness:coral_sandstone_brick", prob=254, param2=0},
		{name="stairs:slab_coral_white_sandstone", prob=254, param2=2},
		{name="air", prob=0, param2=0},
		{name="air", prob=0, param2=0},
		{name="air", prob=0, param2=0},
		{name="air", prob=0, param2=0},
		{name="air", prob=0, param2=0},
		{name="air", prob=0, param2=0},
		{name="everness:coral_sandstone_brick", prob=254, param2=0},
		{name="air", prob=0, param2=0},
		{name="air", prob=0, param2=0},
		{name="air", prob=0, param2=0},
		{name="air", prob=0, param2=0},
		{name="air", prob=0, param2=0},
		{name="air", prob=0, param2=0},
		{name="air", prob=0, param2=0},
		{name="air", prob=0, param2=0},
		{name="air", prob=0, param2=0},
		{name="air", prob=0, param2=0},
		{name="stairs:slab_coral_sandstone_brick", prob=254, param2=1},
		{name="air", prob=0, param2=0},
		{name="air", prob=0, param2=0},
		{name="air", prob=0, param2=0},
		{name="air", prob=0, param2=0},
		{name="air", prob=0, param2=0},
		{name="air", prob=0, param2=0},
		{name="air", prob=0, param2=0},
		{name="air", prob=0, param2=0},
		{name="air", prob=0, param2=0},
		{name="air", prob=0, param2=0},
		{name="air", prob=0, param2=0},
		{name="air", prob=0, param2=0},
		{name="air", prob=0, param2=0},
		{name="air", prob=0, param2=0},
		{name="air", prob=0, param2=0},
		{name="air", prob=0, param2=0},
		{name="air", prob=0, param2=0},
		{name="air", prob=0, param2=0},
		{name="air", prob=0, param2=0},
		{name="air", prob=0, param2=0},
		{name="air", prob=0, param2=0},
		{name="air", prob=0, param2=0},
		{name="air", prob=0, param2=0},
		{name="air", prob=0, param2=0},
		{name="air", prob=0, param2=0},
		{name="air", prob=0, param2=0},
		{name="air", prob=0, param2=0},
		{name="air", prob=0, param2=0},
		{name="air", prob=0, param2=0},
		{name="air", prob=0, param2=0},
		{name="air", prob=0, param2=0},
		{name="stairs:slab_coral_white_sandstone", prob=254, param2=20},
		{name="stairs:stair_coral_white_sandstone", prob=254, param2=22},
		{name="stairs:slab_coral_white_sandstone", prob=254, param2=22},
		{name="air", prob=0, param2=0},
		{name="air", prob=0, param2=0},
		{name="air", prob=0, param2=0},
		{name="air", prob=0, param2=0},
		{name="air", prob=0, param2=0},
		{name="air", prob=0, param2=0},
		{name="air", prob=0, param2=0},
		{name="air", prob=0, param2=0},
		{name="air", prob=0, param2=0},
		{name="air", prob=0, param2=0},
		{name="air", prob=0, param2=0},
		{name="air", prob=0, param2=0},
		{name="air", prob=0, param2=0},
		{name="air", prob=0, param2=0},
		{name="air", prob=0, param2=0},
		{name="air", prob=0, param2=0},
		{name="air", prob=0, param2=0},
		{name="air", prob=0, param2=0},
		{name="air", prob=0, param2=0},
		{name="air", prob=0, param2=0},
		{name="air", prob=0, param2=0},
		{name="air", prob=0, param2=0},
		{name="air", prob=0, param2=0},
		{name="air", prob=0, param2=0},
		{name="air", prob=0, param2=0},
		{name="air", prob=0, param2=0},
		{name="air", prob=0, param2=0},
		{name="air", prob=0, param2=0},
		{name="air", prob=0, param2=0},
		{name="air", prob=0, param2=0},
		{name="air", prob=0, param2=0},
		{name="air", prob=0, param2=0},
		{name="air", prob=0, param2=0},
		{name="air", prob=0, param2=0},
		{name="air", prob=0, param2=0},
		{name="air", prob=0, param2=0},
		{name="air", prob=0, param2=0},
		{name="air", prob=0, param2=0},
		{name="air", prob=0, param2=0},
		{name="air", prob=0, param2=0},
		{name="air", prob=0, param2=0},
		{name="air", prob=0, param2=0},
		{name="air", prob=0, param2=0},
		{name="air", prob=0, param2=0},
		{name="air", prob=0, param2=0},
		{name="air", prob=0, param2=0},
		{name="air", prob=0, param2=0},
		{name="air", prob=0, param2=0},
		{name="air", prob=0, param2=0},
		{name="air", prob=0, param2=0},
		{name="air", prob=0, param2=0},
		{name="air", prob=0, param2=0},
		{name="air", prob=0, param2=0},
		{name="air", prob=0, param2=0},
		{name="air", prob=0, param2=0},
		{name="air", prob=0, param2=0},
		{name="air", prob=0, param2=0},
		{name="air", prob=0, param2=0},
		{name="air", prob=0, param2=0},
		{name="everness:coral_deep_ocean_sandstone_block", prob=126, param2=0},
		{name="air", prob=0, param2=0},
		{name="air", prob=0, param2=0},
		{name="air", prob=0, param2=0},
		{name="air", prob=0, param2=0},
		{name="air", prob=0, param2=0},
		{name="air", prob=0, param2=0},
		{name="air", prob=0, param2=0},
		{name="air", prob=0, param2=0},
		{name="air", prob=0, param2=0},
		{name="everness:coral_deep_ocean_sandstone_block", prob=126, param2=0},
		{name="air", prob=0, param2=0},
		{name="everness:coral_deep_ocean_sandstone_block", prob=254, param2=0},
		{name="everness:coral_deep_ocean_sandstone_block", prob=254, param2=0},
		{name="everness:coral_deep_ocean_sandstone_brick", prob=254, param2=0},
		{name="stairs:stair_coral_deep_ocean_sandstone_brick", prob=126, param2=2},
		{name="stairs:stair_coral_deep_ocean_sandstone_brick", prob=126, param2=2},
		{name="stairs:stair_coral_deep_ocean_sandstone_brick", prob=126, param2=2},
		{name="everness:coral_deep_ocean_sandstone_brick", prob=254, param2=0},
		{name="everness:coral_deep_ocean_sandstone_block", prob=254, param2=0},
		{name="everness:coral_deep_ocean_sandstone_block", prob=254, param2=0},
		{name="air", prob=0, param2=0},
		{name="air", prob=0, param2=0},
		{name="air", prob=0, param2=0},
		{name="air", prob=0, param2=0},
		{name="stairs:stair_coral_deep_ocean_sandstone_block", prob=254, param2=2},
		{name="air", prob=0, param2=0},
		{name="air", prob=0, param2=0},
		{name="air", prob=0, param2=0},
		{name="stairs:stair_coral_deep_ocean_sandstone_block", prob=254, param2=2},
		{name="air", prob=0, param2=0},
		{name="air", prob=0, param2=0},
		{name="air", prob=0, param2=0},
		{name="air", prob=0, param2=0},
		{name="air", prob=0, param2=0},
		{name="air", prob=0, param2=0},
		{name="air", prob=0, param2=0},
		{name="air", prob=0, param2=0},
		{name="air", prob=0, param2=0},
		{name="air", prob=0, param2=0},
		{name="air", prob=0, param2=0},
		{name="air", prob=0, param2=0},
		{name="air", prob=0, param2=0},
		{name="air", prob=0, param2=0},
		{name="air", prob=0, param2=0},
		{name="air", prob=0, param2=0},
		{name="air", prob=0, param2=0},
		{name="air", prob=0, param2=0},
		{name="air", prob=0, param2=0},
		{name="air", prob=0, param2=0},
		{name="air", prob=0, param2=0},
		{name="air", prob=0, param2=0},
		{name="air", prob=0, param2=0},
		{name="air", prob=0, param2=0},
		{name="air", prob=0, param2=0},
		{name="air", prob=0, param2=0},
		{name="air", prob=0, param2=0},
		{name="stairs:slab_coral_white_sandstone", prob=254, param2=22},
		{name="air", prob=0, param2=0},
		{name="air", prob=0, param2=0},
		{name="air", prob=0, param2=0},
		{name="air", prob=0, param2=0},
		{name="air", prob=0, param2=0},
		{name="stairs:slab_coral_white_sandstone", prob=254, param2=22},
		{name="air", prob=0, param2=0},
		{name="air", prob=0, param2=0},
		{name="air", prob=0, param2=0},
		{name="air", prob=0, param2=0},
		{name="stairs:slab_coral_white_sandstone", prob=254, param2=2},
		{name="everness:coral_white_sandstone", prob=254, param2=0},
		{name="stairs:slab_coral_white_sandstone", prob=254, param2=22},
		{name="air", prob=0, param2=0},
		{name="stairs:slab_coral_white_sandstone", prob=254, param2=22},
		{name="everness:coral_white_sandstone", prob=254, param2=0},
		{name="stairs:slab_coral_white_sandstone", prob=254, param2=2},
		{name="air", prob=0, param2=0},
		{name="air", prob=0, param2=0},
		{name="air", prob=0, param2=0},
		{name="air", prob=0, param2=0},
		{name="air", prob=0, param2=0},
		{name="air", prob=0, param2=0},
		{name="stairs:slab_coral_white_sandstone", prob=254, param2=2},
		{name="everness:coral_white_sandstone", prob=254, param2=0},
		{name="stairs:slab_coral_white_sandstone", prob=254, param2=2},
		{name="air", prob=0, param2=0},
		{name="air", prob=0, param2=0},
		{name="air", prob=0, param2=0},
		{name="air", prob=0, param2=0},
		{name="air", prob=0, param2=0},
		{name="air", prob=0, param2=0},
		{name="air", prob=0, param2=0},
		{name="air", prob=0, param2=0},
		{name="air", prob=0, param2=0},
		{name="air", prob=0, param2=0},
		{name="air", prob=0, param2=0},
		{name="air", prob=0, param2=0},
		{name="air", prob=0, param2=0},
		{name="air", prob=0, param2=0},
		{name="air", prob=0, param2=0},
		{name="air", prob=0, param2=0},
		{name="air", prob=0, param2=0},
		{name="air", prob=0, param2=0},
		{name="air", prob=0, param2=0},
		{name="air", prob=0, param2=0},
		{name="air", prob=0, param2=0},
		{name="air", prob=0, param2=0},
		{name="air", prob=0, param2=0},
		{name="air", prob=0, param2=0},
		{name="air", prob=0, param2=0},
		{name="air", prob=0, param2=0},
		{name="air", prob=0, param2=0},
		{name="air", prob=0, param2=0},
		{name="air", prob=0, param2=0},
		{name="air", prob=0, param2=0},
		{name="air", prob=0, param2=0},
		{name="air", prob=0, param2=0},
		{name="air", prob=0, param2=0},
		{name="air", prob=0, param2=0},
		{name="air", prob=0, param2=0},
		{name="air", prob=0, param2=0},
		{name="air", prob=0, param2=0},
		{name="air", prob=0, param2=0},
		{name="air", prob=0, param2=0},
		{name="air", prob=0, param2=0},
		{name="air", prob=0, param2=0},
		{name="air", prob=0, param2=0},
		{name="air", prob=0, param2=0},
		{name="air", prob=0, param2=0},
		{name="air", prob=0, param2=0},
		{name="air", prob=0, param2=0},
		{name="air", prob=0, param2=0},
		{name="air", prob=0, param2=0},
		{name="air", prob=0, param2=0},
		{name="air", prob=0, param2=0},
		{name="air", prob=0, param2=0},
		{name="air", prob=0, param2=0},
		{name="air", prob=0, param2=0},
		{name="air", prob=0, param2=0},
		{name="air", prob=0, param2=0},
		{name="air", prob=0, param2=0},
		{name="air", prob=0, param2=0},
		{name="air", prob=0, param2=0},
		{name="air", prob=0, param2=0},
		{name="air", prob=0, param2=0},
		{name="air", prob=0, param2=0},
		{name="air", prob=0, param2=0},
		{name="air", prob=0, param2=0},
		{name="air", prob=0, param2=0},
		{name="air", prob=0, param2=0},
		{name="air", prob=0, param2=0},
		{name="air", prob=0, param2=0},
		{name="air", prob=0, param2=0},
		{name="air", prob=0, param2=0},
		{name="air", prob=0, param2=0},
		{name="air", prob=0, param2=0},
		{name="air", prob=0, param2=0},
		{name="air", prob=0, param2=0},
		{name="air", prob=0, param2=0},
		{name="air", prob=0, param2=0},
		{name="air", prob=0, param2=0},
		{name="air", prob=0, param2=0},
		{name="air", prob=0, param2=0},
		{name="air", prob=0, param2=0},
		{name="air", prob=0, param2=0},
		{name="air", prob=0, param2=0},
		{name="air", prob=0, param2=0},
		{name="air", prob=0, param2=0},
		{name="air", prob=0, param2=0},
		{name="air", prob=0, param2=0},
		{name="air", prob=0, param2=0},
		{name="air", prob=0, param2=0},
		{name="air", prob=0, param2=0},
		{name="air", prob=0, param2=0},
		{name="air", prob=0, param2=0},
		{name="air", prob=0, param2=0},
		{name="air", prob=0, param2=0},
		{name="air", prob=0, param2=0},
		{name="air", prob=0, param2=0},
		{name="air", prob=0, param2=0},
		{name="air", prob=0, param2=0},
		{name="air", prob=0, param2=0},
		{name="air", prob=0, param2=0},
		{name="air", prob=0, param2=0},
		{name="air", prob=0, param2=0},
		{name="air", prob=0, param2=0},
		{name="air", prob=0, param2=0},
		{name="air", prob=0, param2=0},
		{name="everness:coral_deep_ocean_sandstone_block", prob=126, param2=0},
		{name="everness:coral_deep_ocean_sandstone_block", prob=126, param2=0},
		{name="everness:coral_deep_ocean_sandstone_block", prob=126, param2=0},
		{name="everness:coral_deep_ocean_sandstone_block", prob=126, param2=0},
		{name="everness:coral_deep_ocean_sandstone_block", prob=126, param2=0},
		{name="everness:coral_deep_ocean_sandstone_block", prob=126, param2=0},
		{name="everness:coral_deep_ocean_sandstone_block", prob=126, param2=0},
		{name="everness:coral_deep_ocean_sandstone_block", prob=126, param2=0},
		{name="everness:coral_deep_ocean_sandstone_block", prob=126, param2=0},
		{name="everness:coral_deep_ocean_sandstone_block", prob=126, param2=0},
		{name="everness:coral_deep_ocean_sandstone_block", prob=126, param2=0},
		{name="air", prob=0, param2=0},
		{name="air", prob=0, param2=0},
		{name="air", prob=0, param2=0},
		{name="air", prob=0, param2=0},
		{name="air", prob=0, param2=0},
		{name="air", prob=0, param2=0},
		{name="air", prob=0, param2=0},
		{name="air", prob=0, param2=0},
		{name="air", prob=0, param2=0},
		{name="air", prob=0, param2=0},
		{name="air", prob=0, param2=0},
		{name="air", prob=0, param2=0},
		{name="air", prob=0, param2=0},
		{name="air", prob=0, param2=0},
		{name="air", prob=0, param2=0},
		{name="air", prob=0, param2=0},
		{name="air", prob=0, param2=0},
		{name="air", prob=0, param2=0},
		{name="air", prob=0, param2=0},
		{name="air", prob=0, param2=0},
		{name="air", prob=0, param2=0},
		{name="air", prob=0, param2=0},
		{name="air", prob=0, param2=0},
		{name="air", prob=0, param2=0},
		{name="air", prob=0, param2=0},
		{name="air", prob=0, param2=0},
		{name="air", prob=0, param2=0},
		{name="air", prob=0, param2=0},
		{name="air", prob=0, param2=0},
		{name="air", prob=0, param2=0},
		{name="air", prob=0, param2=0},
		{name="air", prob=0, param2=0},
		{name="air", prob=0, param2=0},
		{name="air", prob=0, param2=0},
		{name="air", prob=0, param2=0},
		{name="air", prob=0, param2=0},
		{name="air", prob=0, param2=0},
		{name="air", prob=0, param2=0},
		{name="air", prob=0, param2=0},
		{name="air", prob=0, param2=0},
		{name="air", prob=0, param2=0},
		{name="air", prob=0, param2=0},
		{name="air", prob=0, param2=0},
		{name="air", prob=0, param2=0},
		{name="air", prob=0, param2=0},
		{name="air", prob=0, param2=0},
		{name="air", prob=0, param2=0},
		{name="air", prob=0, param2=0},
		{name="air", prob=0, param2=0},
		{name="air", prob=0, param2=0},
		{name="air", prob=0, param2=0},
		{name="air", prob=0, param2=0},
		{name="air", prob=0, param2=0},
		{name="air", prob=0, param2=0},
		{name="air", prob=0, param2=0},
		{name="air", prob=0, param2=0},
		{name="air", prob=0, param2=0},
		{name="air", prob=0, param2=0},
		{name="air", prob=0, param2=0},
		{name="air", prob=0, param2=0},
		{name="air", prob=0, param2=0},
		{name="air", prob=0, param2=0},
		{name="air", prob=0, param2=0},
		{name="air", prob=0, param2=0},
		{name="air", prob=0, param2=0},
		{name="air", prob=0, param2=0},
		{name="air", prob=0, param2=0},
		{name="air", prob=0, param2=0},
		{name="air", prob=0, param2=0},
		{name="air", prob=0, param2=0},
		{name="air", prob=0, param2=0},
		{name="air", prob=0, param2=0},
		{name="air", prob=0, param2=0},
		{name="air", prob=0, param2=0},
		{name="air", prob=0, param2=0},
		{name="air", prob=0, param2=0},
		{name="air", prob=0, param2=0},
		{name="air", prob=0, param2=0},
		{name="air", prob=0, param2=0},
		{name="air", prob=0, param2=0},
		{name="air", prob=0, param2=0},
		{name="air", prob=0, param2=0},
		{name="air", prob=0, param2=0},
		{name="air", prob=0, param2=0},
		{name="air", prob=0, param2=0},
		{name="air", prob=0, param2=0},
		{name="air", prob=0, param2=0},
		{name="air", prob=0, param2=0},
		{name="air", prob=0, param2=0},
		{name="air", prob=0, param2=0},
		{name="air", prob=0, param2=0},
		{name="air", prob=0, param2=0},
		{name="air", prob=0, param2=0},
		{name="air", prob=0, param2=0},
		{name="air", prob=0, param2=0},
		{name="air", prob=0, param2=0},
		{name="air", prob=0, param2=0},
		{name="air", prob=0, param2=0},
		{name="air", prob=0, param2=0},
		{name="air", prob=0, param2=0},
		{name="air", prob=0, param2=0},
		{name="air", prob=0, param2=0},
		{name="air", prob=0, param2=0},
		{name="air", prob=0, param2=0},
		{name="air", prob=0, param2=0},
		{name="air", prob=0, param2=0},
		{name="air", prob=0, param2=0},
		{name="air", prob=0, param2=0},
		{name="air", prob=0, param2=0},
		{name="air", prob=0, param2=0},
		{name="air", prob=0, param2=0},
		{name="air", prob=0, param2=0},
		{name="air", prob=0, param2=0},
		{name="air", prob=0, param2=0},
		{name="air", prob=0, param2=0},
		{name="air", prob=0, param2=0},
		{name="air", prob=0, param2=0},
		{name="air", prob=0, param2=0},
		{name="air", prob=0, param2=0},
		{name="air", prob=0, param2=0},
		{name="air", prob=0, param2=0},
		{name="air", prob=0, param2=0},
		{name="air", prob=0, param2=0},
		{name="air", prob=0, param2=0},
		{name="air", prob=0, param2=0},
		{name="air", prob=0, param2=0},
		{name="air", prob=0, param2=0},
		{name="air", prob=0, param2=0},
		{name="air", prob=0, param2=0},
		{name="air", prob=0, param2=0},
		{name="air", prob=0, param2=0},
		{name="air", prob=0, param2=0},
		{name="air", prob=0, param2=0},
		{name="air", prob=0, param2=0},
		{name="air", prob=0, param2=0},
		{name="air", prob=0, param2=0},
		{name="air", prob=0, param2=0},
		{name="air", prob=0, param2=0},
		{name="air", prob=0, param2=0},
		{name="air", prob=0, param2=0},
		{name="air", prob=0, param2=0},
		{name="air", prob=0, param2=0},
		{name="air", prob=0, param2=0},
		{name="air", prob=0, param2=0},
		{name="air", prob=0, param2=0},
		{name="air", prob=0, param2=0},
		{name="air", prob=0, param2=0},
		{name="air", prob=0, param2=0},
		{name="air", prob=0, param2=0},
		{name="air", prob=0, param2=0},
		{name="air", prob=0, param2=0},
		{name="air", prob=0, param2=0},
		{name="air", prob=0, param2=0},
		{name="air", prob=0, param2=0},
		{name="air", prob=0, param2=0},
		{name="air", prob=0, param2=0},
		{name="air", prob=0, param2=0},
		{name="air", prob=0, param2=0},
		{name="air", prob=0, param2=0},
		{name="air", prob=0, param2=0},
		{name="air", prob=0, param2=0},
		{name="air", prob=0, param2=0},
		{name="air", prob=0, param2=0},
		{name="air", prob=0, param2=0},
		{name="air", prob=0, param2=0},
		{name="air", prob=0, param2=0},
		{name="air", prob=0, param2=0},
		{name="air", prob=0, param2=0},
		{name="air", prob=0, param2=0},
		{name="air", prob=0, param2=0},
		{name="air", prob=0, param2=0},
		{name="air", prob=0, param2=0},
		{name="air", prob=0, param2=0},
		{name="air", prob=0, param2=0},
		{name="air", prob=0, param2=0},
		{name="air", prob=0, param2=0},
	},
}
